Workbook
Name Access_Control: [1]Elec_Est!#REF!
Name AREAS: #REF!
Name AREAS: [1]ML_Sum!$X$1:$AD$16
Name AREAS: ML_Sum!$X$1:$AD$16
Name CCTV: [1]Elec_Est!#REF!
Name Data: [1]Elec_Est!#REF!
Name Fire_Alarm: [1]Elec_Est!#REF!
Name FO: [1]Elec_Est!#REF!
Name Guard: [1]Elec_Est!#REF!
Name Intercom: [1]Elec_Est!#REF!
Name Intruder_Alarm: [1]Elec_Est!#REF!

Sheet Elec_Rates
B1: CLIENT: | C1: =ML_Sum!$C1 -> 1 | D1: =ML_Sum!$D1 -> Quintano Foods Ltd. | F1: =ML_Sum!$F1 -> 0 | I1: 1 | J1: =ML_Sum!$J1 -> 1 | K1: =ML_Sum!$K1 -> 1 | L1: =ML_Sum!$L1 -> 1 | M1: =ML_Sum!$M1 -> 1 | N1: =ML_Sum!$N1 -> 1 | O1: =ML_Sum!$O1 -> 1 | Q1: =ML_Sum!$Q1 -> € | R1: R/Lab Cont | S1: =ML_Sum!$S1 -> R | T1: =ML_Sum!$T1 -> 1 | U1: =ML_Sum!W1 -> BOQ | V1: INCL | W1: MULT | X1: AREA | Y1: BOQ | Z1: TDWG | AA1: ACT | AB1: DIFF
B2: PROJECT: | C2: =ML_Sum!$C2 -> 1 | D2: =ML_Sum!$D2 -> Warehouse at tal-Handaq, Qormi | F2: =ML_Sum!$F2 -> Electrical | I2: 2 | J2: =ML_Sum!$J2 -> 1 | K2: =ML_Sum!$K2 -> 1 | L2: =ML_Sum!$L2 -> 1 | M2: =ML_Sum!$M2 -> 1 | N2: =ML_Sum!$N2 -> 1 | O2: =ML_Sum!$O2 -> 1 | Q2: =ML_Sum!$Q2 -> 0 | R2: mu_A | S2: =ML_Sum!$S2 -> 1 | T2: =ML_Sum!$T2 -> 27.46
B3: JOB DESC: | C3: =ML_Sum!$C3 -> 1 | D3: =ML_Sum!$D3 -> Electrical installation for Mechanical (HVAC) - Revision B | F3: =ML_Sum!$F3 -> ECA | I3: 3 | J3: =ML_Sum!$J3 -> 1 | K3: =ML_Sum!$K3 -> 1 | L3: =ML_Sum!$L3 -> 1 | M3: =ML_Sum!$M3 -> 1 | N3: =ML_Sum!$N3 -> 1 | O3: =ML_Sum!$O3 -> 1 | Q3: =ML_Sum!$Q3 -> 0 | R3: mu_B | S3: =ML_Sum!$S3 -> 1 | T3: =ML_Sum!$T3 -> 27.46
B4: QUOTE No: | C4: =ML_Sum!$C4 -> 1 | D4: =ML_Sum!$D4 -> ELM-25-0085B | F4: =ML_Sum!$F4 -> 0 | I4: 4 | J4: =ML_Sum!$J4 -> 1 | K4: =ML_Sum!$K4 -> 1 | L4: =ML_Sum!$L4 -> 1 | M4: =ML_Sum!$M4 -> 1 | N4: =ML_Sum!$N4 -> 1 | O4: =ML_Sum!$O4 -> 1 | Q4: =ML_Sum!$Q4 -> 0 | R4: mu_C | S4: =ML_Sum!$S4 -> 1 | T4: =ML_Sum!$T4 -> 27.46
B5: CLIENTs REF: | C5: =ML_Sum!$C5 -> 1 | D5: =ML_Sum!$D5 -> Tender | F5: =ML_Sum!$F5 -> 0 | I5: 5 | J5: =ML_Sum!$J5 -> 1 | K5: =ML_Sum!$K5 -> 1 | L5: =ML_Sum!$L5 -> 1 | M5: =ML_Sum!$M5 -> 1 | N5: =ML_Sum!$N5 -> 1 | O5: =ML_Sum!$O5 -> 1 | Q5: =ML_Sum!$Q5 -> 0 | R5: mu_D | S5: =ML_Sum!$S5 -> 1 | T5: =ML_Sum!$T5 -> 27.46
B6: VAT/DUTIES: | C6: =ML_Sum!$C6 -> 1 | D6: =ML_Sum!$D6 -> VAT EXCL. | F6: =ML_Sum!$F6 -> 0 | I6: 6 | J6: =ML_Sum!$J6 -> 1 | K6: =ML_Sum!$K6 -> 1 | L6: =ML_Sum!$L6 -> 1 | M6: =ML_Sum!$M6 -> 1 | N6: =ML_Sum!$N6 -> 1 | O6: =ML_Sum!$O6 -> 1 | Q6: =ML_Sum!$Q6 -> 0 | R6: mu_E | S6: =ML_Sum!$S6 -> 1 | T6: =ML_Sum!$T6 -> 27.46
B7: SAVED ON: | C7: =ML_Sum!$C7 -> 1 | D7: 39364 | F7: =ML_Sum!$F7 -> 0 | I7: 7 | J7: =ML_Sum!$J7 -> 1 | K7: =ML_Sum!$K7 -> 1 | L7: =ML_Sum!$L7 -> 1 | M7: =ML_Sum!$M7 -> 1 | N7: =ML_Sum!$N7 -> 1 | O7: =ML_Sum!$O7 -> 0 | Q7: =ML_Sum!$Q7 -> 0 | R7: mu_F | S7: =ML_Sum!$S7 -> 1 | T7: =ML_Sum!$T7 -> 27.46
B8: ESTIMATOR: | C8: =ML_Sum!$C8 -> 1 | D8: =ML_Sum!$D8 -> T.Sammut | F8: =ML_Sum!$F8 -> 0 | I8: 8 | J8: =ML_Sum!$J8 -> 1 | K8: =ML_Sum!$K8 -> 1 | L8: =ML_Sum!$L8 -> 1 | M8: =ML_Sum!$M8 -> 1 | N8: =ML_Sum!$N8 -> 1 | O8: =ML_Sum!$O8 -> 0 | Q8: =ML_Sum!$Q8 -> 0 | R8: mu_G | S8: =ML_Sum!$S8 -> 1 | T8: =ML_Sum!$T8 -> 27.46
B9: LABOUR RATE: | C9: =ML_Sum!$C9 -> 1 | D9: =ML_Sum!$D9 -> 27.46 | F9: =ML_Sum!$F9 -> 0 | I9: 9 | J9: =ML_Sum!$J9 -> 1 | K9: =ML_Sum!$K9 -> 1 | L9: =ML_Sum!$L9 -> 1 | M9: =ML_Sum!$M9 -> 1 | N9: =ML_Sum!$N9 -> 1 | O9: =ML_Sum!$O9 -> 0 | Q9: =ML_Sum!$Q9 -> 0 | R9: mu_H | S9: =ML_Sum!$S9 -> 1 | T9: =ML_Sum!$T9 -> 27.46
C10: =ML_Sum!$C10 -> 1 | F10: =ML_Sum!$F10 -> 0 | I10: 10 | J10: =ML_Sum!$J10 -> 1 | K10: =ML_Sum!$K10 -> 1 | L10: =ML_Sum!$L10 -> 1 | M10: =ML_Sum!$M10 -> 1 | N10: =ML_Sum!$N10 -> 1 | O10: =ML_Sum!$O10 -> 1 | Q10: =ML_Sum!$Q10 -> 0 | R10: mu_I | S10: =ML_Sum!$S10 -> 1 | T10: =ML_Sum!$T10 -> 27.46
C11: =ML_Sum!$C11 -> 1 | F11: =ML_Sum!$F11 -> 0 | Q11: =ML_Sum!$Q11 -> 0 | R11: mu_J | S11: =ML_Sum!$S11 -> 1 | T11: =ML_Sum!$T11 -> 27.46
C12: =ML_Sum!$C12 -> 1 | F12: =ML_Sum!$F12 -> 0 | Q12: =ML_Sum!$Q12 -> 0 | R12: MIXED | S12: =ML_Sum!$S12 -> MAT MU | T12: =ML_Sum!$T12 -> LAB RATE
G13: I_CODE | H13: C_CODE | I13: MAKE | J13: PART_NO | K13: MARKUP | L13: TYPE | M13: LIST_P | N13: P_FACT | O13: FIX | P13: DATE | Q13: %Dsct in BOQ | R13: MU TYPE | S13: MAT MU | T13: LAB RATE
C15: t | D15: Item:
D16: Start Typing Header
Q18: Multip
A19: 1 | B19: =Elec_Est!B2140 -> 4 | D19: 037# 5 x 16mm2 F120 Fire Resistant Cable (BS7846) - XLPE/SWA/LSZH | K19: RATE | L19: RATE | Q19: =B19/A19 -> 4 | R19: =IF($B19=0,0,IF($S$1="R",ROUND(R30/$B19,2),R30/$B19)) -> 166.5 | T19: =IF($B19=0,0,IF($S$1="R",ROUND(T30/$B19,2),T30/$B19)) -> 2.86
D20: Based on:
A21: =$Q$19 *(3) -> 12 | B21: m | D21: Power Cable 5c 16 mm2 XLPE SWA-PVC | E21: Fire Rated | F21: Cleveland | G21: CAMC_087 | H21: 616 | I21: (__) | J21: 16mm2 | O21: 2 | P21: 38371 | Q21: 26.22 | R21: =$A21*Q21 -> 314.64 | S21: 0.1 | T21: =$A21*S21*$T$1 -> 1.2
A22: =$Q$19 *(3) -> 12 | B22: No | D22: Cable Tie 225mm | G22: CONS_009 | H22: 875 | I22: (__) | K22: 01-003 | O22: 1 | P22: 34669 | Q22: 0.05 | R22: =$A22*Q22 -> 0.6 | T22: =$A22*S22*$T$1 -> 0
A23: =$Q$19 *(2) -> 8 | B23: No | D23: Gland Indoor 25 BWL 4*10/16mm2 | G23: CAAC_043 | H23: 620 | I23: CMP | O23: 2 | P23: 35431 | Q23: 7.66 | R23: =$A23*Q23 -> 61.28 | S23: 0.4 | T23: =$A23*S23*$T$1 -> 3.2
A24: =$Q$19 *(2) -> 8 | B24: m | D24: Cable Marker 8 digit c/w Carrier Strip | G24: CAAC_091 | H24: 620 | I24: (__) | O24: 2 | P24: 38148 | Q24: 1.5 | R24: =$A24*Q24 -> 12 | S24: 0.08 | T24: =$A24*S24*$T$1 -> 0.64
A25: =$Q$19 *(2*5) -> 40 | B25: No | D25: Cable Lug 16 mm2 | G25: CAAC_009 | H25: 620 | I25: CTT | O25: 2 | P25: 34669 | Q25: 0.14 | R25: =$A25*Q25 -> 5.6 | S25: 0.06 | T25: =$A25*S25*$T$1 -> 2.4
A26: =$Q$19 *(1) -> 4 | B26: No | D26: Labour to connect Mech Equip (FIX 3) | F26: equipment | G26: LABO_009 | H26: 900 | I26: MISC | O26: 1 | R26: =$A26*Q26 -> 0 | S26: 1 | T26: =$A26*S26*$T$1 -> 4 | U26: NoMat?
A27: =$Q$19 *(1/4) -> 1 | B27: LS | D27: Crainage & Transportation | F27: Scissors Lift | G27: CRAI_002 | H27: 962 | I27: MISC | O27: 2 | P27: 38129 | Q27: =1.25 *(12/8*125) -> 234.375 | R27: =$A27*Q27 -> 234.375 | T27: =$A27*S27*$T$1 -> 0
A28: =$Q$19 *(1/4) -> 1 | B28: No | D28: Diesel Fuel | F28: Approx €25/daily - info from Godwin by phone | G28: GENS_022 | H28: 845 | I28: (__) | O28: 3 | P28: 39713 | Q28: =12/8*25 -> 37.5 | R28: =$A28*Q28 -> 37.5 | T28: =$A28*S28*$T$1 -> 0
C29: << ==== TOTAL UNITS | R29: =$A29*Q29 -> 0 | T29: =$A29*S29*$T$1 -> 0
A30: d> | B30: =(R29+T29) -> 0 | D30: Sell_A | E30: =IF($B19=0,0,ROUND(ROUND(($R30*$S$2+($T30*$T$2))/$B19, 2)*$C$2,2)) -> 245.03 | F30: =ROUND($B19*$E30,2) -> 980.12 | K30: ITEM | L30: ITEM | R30: =SUM(R20:R29) -> 665.995 | T30: =SUM(T20:T29) -> 11.44
Q31: Multip
A32: 1 | B32: =Elec_Est!B2141 -> 3 | D32: 039# 5 x 10mm2 F120 Fire Resistant Cable (BS7846) - XLPE/SWA/LSZH | K32: RATE | L32: RATE | Q32: =B32/A32 -> 3 | R32: =IF($B32=0,0,IF($S$1="R",ROUND(R41/$B32,2),R41/$B32)) -> 80.2 | T32: =IF($B32=0,0,IF($S$1="R",ROUND(T41/$B32,2),T41/$B32)) -> 2.58
D33: Based on:
A34: =$Q$32 *(3) -> 9 | B34: m | D34: Power Cable 5c 10 mm2 XLPE SWA-PVC | E34: Fire Rated | F34: Cleveland | G34: CAMC_086 | H34: 616 | I34: (__) | J34: 10mm2 | O34: 2 | P34: 38371 | Q34: 20.11 | R34: =$A34*Q34 -> 180.99 | S34: 0.09 | T34: =$A34*S34*$T$1 -> 0.81
A35: =$Q$32 *(3) -> 9 | B35: No | D35: Cable Tie 225mm | G35: CONS_009 | H35: 875 | I35: (__) | K35: 01-003 | O35: 1 | P35: 34669 | Q35: 0.05 | R35: =$A35*Q35 -> 0.45 | T35: =$A35*S35*$T$1 -> 0
A36: =$Q$32 *(2) -> 6 | B36: No | D36: Gland Indoor 25 BWL 4*10/16mm2 | G36: CAAC_043 | H36: 620 | I36: CMP | O36: 2 | P36: 35431 | Q36: 7.66 | R36: =$A36*Q36 -> 45.96 | S36: 0.4 | T36: =$A36*S36*$T$1 -> 2.4
A37: =$Q$32 *(2) -> 6 | B37: m | D37: Cable Marker 8 digit c/w Carrier Strip | G37: CAAC_091 | H37: 620 | I37: (__) | O37: 2 | P37: 38148 | Q37: 1.5 | R37: =$A37*Q37 -> 9 | S37: 0.08 | T37: =$A37*S37*$T$1 -> 0.48
A38: =$Q$32 *(10) -> 30 | B38: No | D38: Cable Lug 10 mm2 | G38: CAAC_008 | H38: 620 | I38: CTT | O38: 2 | P38: 34669 | Q38: 0.14 | R38: =$A38*Q38 -> 4.2 | S38: 0.06 | T38: =$A38*S38*$T$1 -> 1.8
A39: =$Q$32 *(1) -> 3 | B39: No | D39: Labour to connect Mech Equip (FIX 3) | F39: equipment | G39: LABO_009 | H39: 900 | I39: MISC | O39: 1 | R39: =$A39*Q39 -> 0 | S39: 0.75 | T39: =$A39*S39*$T$1 -> 2.25 | U39: NoMat?
C40: << ==== TOTAL UNITS | R40: =$A40*Q40 -> 0 | T40: =$A40*S40*$T$1 -> 0
A41: d> | B41: =(R40+T40) -> 0 | D41: Sell_A | E41: =IF($B32=0,0,ROUND(ROUND(($R41*$S$2+($T41*$T$2))/$B32, 2)*$C$2,2)) -> 151.05 | F41: =ROUND($B32*$E41,2) -> 453.15 | K41: ITEM | L41: ITEM | R41: =SUM(R33:R40) -> 240.6 | T41: =SUM(T33:T40) -> 7.74
Q42: Multip
...

Sheet Elec_Est
B1: CLIENT: | C1: =ML_Sum!$C1 -> 1 | D1: =ML_Sum!$D1 -> Quintano Foods Ltd. | F1: =ML_Sum!$F1 -> 0 | I1: 1 | J1: =ML_Sum!$J1 -> 1 | K1: =ML_Sum!$K1 -> 1 | L1: =ML_Sum!$L1 -> 1 | M1: =ML_Sum!$M1 -> 1 | N1: =ML_Sum!$N1 -> 1 | O1: =ML_Sum!$O1 -> 1 | Q1: =ML_Sum!$Q1 -> € | R1: R/Lab Cont | S1: =ML_Sum!$S1 -> R | T1: =ML_Sum!$T1 -> 1 | U1: =ML_Sum!W1 -> BOQ | V1: INCL | W1: MULT | X1: AREA | Y1: BOQ | Z1: TDWG | AA1: ACT | AB1: DIFF
B2: PROJECT: | C2: =ML_Sum!$C2 -> 1 | D2: =ML_Sum!$D2 -> Warehouse at tal-Handaq, Qormi | F2: =ML_Sum!$F2 -> Electrical | I2: 2 | J2: =ML_Sum!$J2 -> 1 | K2: =ML_Sum!$K2 -> 1 | L2: =ML_Sum!$L2 -> 1 | M2: =ML_Sum!$M2 -> 1 | N2: =ML_Sum!$N2 -> 1 | O2: =ML_Sum!$O2 -> 1 | Q2: =ML_Sum!$Q2 -> 0 | R2: mu_A | S2: =ML_Sum!$S2 -> 1 | T2: =ML_Sum!$T2 -> 27.46
B3: JOB DESC: | C3: =ML_Sum!$C3 -> 1 | D3: =ML_Sum!$D3 -> Electrical installation for Mechanical (HVAC) - Revision B | F3: =ML_Sum!$F3 -> ECA | I3: 3 | J3: =ML_Sum!$J3 -> 1 | K3: =ML_Sum!$K3 -> 1 | L3: =ML_Sum!$L3 -> 1 | M3: =ML_Sum!$M3 -> 1 | N3: =ML_Sum!$N3 -> 1 | O3: =ML_Sum!$O3 -> 1 | Q3: =ML_Sum!$Q3 -> 0 | R3: mu_B | S3: =ML_Sum!$S3 -> 1 | T3: =ML_Sum!$T3 -> 27.46
B4: QUOTE No: | C4: =ML_Sum!$C4 -> 1 | D4: =ML_Sum!$D4 -> ELM-25-0085B | F4: =ML_Sum!$F4 -> 0 | I4: 4 | J4: =ML_Sum!$J4 -> 1 | K4: =ML_Sum!$K4 -> 1 | L4: =ML_Sum!$L4 -> 1 | M4: =ML_Sum!$M4 -> 1 | N4: =ML_Sum!$N4 -> 1 | O4: =ML_Sum!$O4 -> 1 | Q4: =ML_Sum!$Q4 -> 0 | R4: mu_C | S4: =ML_Sum!$S4 -> 1 | T4: =ML_Sum!$T4 -> 27.46
B5: CLIENTs REF: | C5: =ML_Sum!$C5 -> 1 | D5: =ML_Sum!$D5 -> Tender | F5: =ML_Sum!$F5 -> 0 | I5: 5 | J5: =ML_Sum!$J5 -> 1 | K5: =ML_Sum!$K5 -> 1 | L5: =ML_Sum!$L5 -> 1 | M5: =ML_Sum!$M5 -> 1 | N5: =ML_Sum!$N5 -> 1 | O5: =ML_Sum!$O5 -> 1 | Q5: =ML_Sum!$Q5 -> 0 | R5: mu_D | S5: =ML_Sum!$S5 -> 1 | T5: =ML_Sum!$T5 -> 27.46
B6: VAT/DUTIES: | C6: =ML_Sum!$C6 -> 1 | D6: =ML_Sum!$D6 -> VAT EXCL. | F6: =ML_Sum!$F6 -> 0 | I6: 6 | J6: =ML_Sum!$J6 -> 1 | K6: =ML_Sum!$K6 -> 1 | L6: =ML_Sum!$L6 -> 1 | M6: =ML_Sum!$M6 -> 1 | N6: =ML_Sum!$N6 -> 1 | O6: =ML_Sum!$O6 -> 1 | Q6: =ML_Sum!$Q6 -> 0 | R6: mu_E | S6: =ML_Sum!$S6 -> 1 | T6: =ML_Sum!$T6 -> 27.46
B7: SAVED ON: | C7: =ML_Sum!$C7 -> 1 | D7: 39364 | F7: =ML_Sum!$F7 -> 0 | I7: 7 | J7: =ML_Sum!$J7 -> 1 | K7: =ML_Sum!$K7 -> 1 | L7: =ML_Sum!$L7 -> 1 | M7: =ML_Sum!$M7 -> 1 | N7: =ML_Sum!$N7 -> 1 | O7: =ML_Sum!$O7 -> 0 | Q7: =ML_Sum!$Q7 -> 0 | R7: mu_F | S7: =ML_Sum!$S7 -> 1 | T7: =ML_Sum!$T7 -> 27.46
B8: ESTIMATOR: | C8: =ML_Sum!$C8 -> 1 | D8: =ML_Sum!$D8 -> T.Sammut | F8: =ML_Sum!$F8 -> 0 | I8: 8 | J8: =ML_Sum!$J8 -> 1 | K8: =ML_Sum!$K8 -> 1 | L8: =ML_Sum!$L8 -> 1 | M8: =ML_Sum!$M8 -> 1 | N8: =ML_Sum!$N8 -> 1 | O8: =ML_Sum!$O8 -> 0 | Q8: =ML_Sum!$Q8 -> 0 | R8: mu_G | S8: =ML_Sum!$S8 -> 1 | T8: =ML_Sum!$T8 -> 27.46
B9: LABOUR RATE: | C9: =ML_Sum!$C9 -> 1 | D9: =ML_Sum!$D9 -> 27.46 | F9: =ML_Sum!$F9 -> 0 | I9: 9 | J9: =ML_Sum!$J9 -> 1 | K9: =ML_Sum!$K9 -> 1 | L9: =ML_Sum!$L9 -> 1 | M9: =ML_Sum!$M9 -> 1 | N9: =ML_Sum!$N9 -> 1 | O9: =ML_Sum!$O9 -> 0 | Q9: =ML_Sum!$Q9 -> 0 | R9: mu_H | S9: =ML_Sum!$S9 -> 1 | T9: =ML_Sum!$T9 -> 27.46
C10: =ML_Sum!$C10 -> 1 | F10: =ML_Sum!$F10 -> 0 | I10: 10 | J10: =ML_Sum!$J10 -> 1 | K10: =ML_Sum!$K10 -> 1 | L10: =ML_Sum!$L10 -> 1 | M10: =ML_Sum!$M10 -> 1 | N10: =ML_Sum!$N10 -> 1 | O10: =ML_Sum!$O10 -> 1 | Q10: =ML_Sum!$Q10 -> 0 | R10: mu_I | S10: =ML_Sum!$S10 -> 1 | T10: =ML_Sum!$T10 -> 27.46
C11: =ML_Sum!$C11 -> 1 | F11: =ML_Sum!$F11 -> 0 | Q11: =ML_Sum!$Q11 -> 0 | R11: mu_J | S11: =ML_Sum!$S11 -> 1 | T11: =ML_Sum!$T11 -> 27.46
C12: =ML_Sum!$C12 -> 1 | F12: =ML_Sum!$F12 -> 0 | Q12: =ML_Sum!$Q12 -> 0 | R12: MIXED | S12: =ML_Sum!$S12 -> MAT MU | T12: =ML_Sum!$T12 -> LAB RATE
G13: ISELL | H13: C_CODE | I13: MAKE | J13: PART_NO | K13: MARKUP | L13: TYPE | M13: LIST_P | N13: P_FACT | O13: FIX | P13: DATE | Q13: %Dsct in BOQ | R13: MU TYPE | S13: MAT MU | T13: LAB RATE | AM13: Tot Mat Cost | AN13: Unit Lab phr. | AO13: Tot Lab phr. | AP13: < for ELM / MEE
K14: TB
C15: t | D15: Item: 2
D16: VENTILATION SYSTEM
K18: TB
C19: t
D20: FANS - BASEMENT LEVEL -1
K22: TB
C23: t
D24: Supply, install and connect the following In-line type extract fans c/w 2 silencers - one upstream and one downstream from the fan, variable speed controllers, anti-vibration mountings, chamfered bird screen, transformation pieces etc for a complete system inclusive of connecting up of fans to electrical supply.
E26: Sell Rate | F26: Sell Total | K26: IB | AG26: U_M_Sell | AH26: T_M_Sell | AI26: U_L_Sell | AJ26: T_L_Sell | AK26: Total_Sell | AM26: T_M_Cost | AN26: T_L_Phr | AO26: Mat/Lab=1
A27: 2 | B27: No. | D27: Item: 2.001 | E27: =IF(AND($A27=0,$A$1="DIF"),0, ROUND(ROUND(SUMIF($L29:$L35,"SUBI",$E29:$E35)/$A27,2)*$C$12,2)) -> 245.04 | F27: =ROUND($A27*$E27,2) -> 490.08 | G27: ISELL | L27: ITEM | T27: =IF(AND($R41=0,$T41=0),"0.00","mu :" & ROUND($F27/$C$12/($R41+$T41*$D$9),2)) -> mu :1 | AG27: =IF(A27=0,0,ROUND(SUM(AG29:AG41)/A27,2)) -> 166.5 | AH27: =$AG27*$A27 -> 333 | AI27: =$E27-$AG27 -> 78.54 | AJ27: =$A27*$AI27 -> 157.08 | AK27: =ROUND(($AG27+$AI27)*$A27,2) -> 490.08 | AM27: =ROUND(R41,2) -> 333 | AN27: =ROUND(T41,2) -> 5.72 | AO27: =ROUND(AM27+AN27,2)*A27 -> 677.44
D28: EF-B1U-01 F300 Extract Fan - Norm: 33,000m3/hr at 200Pa; Fire: 55,000m3/hr at 200Pa - installed at Level 0
E29: =F27/$C$12-SUMIF($L26:$L41,"SUBI",$E26:$E41) -> 0.01 | F29: Discrepancy
D30: =$F$2 -> Electrical | E30: =ROUND(($R34*$S$2 + ($T34*$T$2)), 2) -> 490.07 | F30: =$E30*$C$12 -> 490.07 | K30: mu_A | L30: SUBI
C31: h | D31: =CELL("Address",Elec_Rates!D$19) -> [ELM25_0085_Quintano_Elec_Mech_HVAC_Est_Rev_B.xlsx]Elec_Rates!$D$19 | G31: RATE_AAA
A32: 2 | B32: 1 | C32: =$A32*$B32 -> 2 | D32: =Elec_Rates!$D$19 -> 037# 5 x 16mm2 F120 Fire Resistant Cable (BS7846) - XLPE/SWA/LSZH | F32: Local Rate | G32: RTLO_001 | Q32: =$B32*Elec_Rates!$R$19 -> 166.5 | R32: =$A32*Q32 -> 333 | S32: =$B32*Elec_Rates!$T$19 -> 2.86 | T32: =$A32*S32 -> 5.72
R33: =$A33*Q33 -> 0 | T33: =$A33*S33*$T$1 -> 0
A34: d> | B34: =(R33+T33) -> 0 | K34: mu_A | L34: SUBI | R34: =SUM(R30:R33) -> 333 | T34: =SUM(T30:T33) -> 5.72 | AG34: =ROUND($R34*$S$2,2) -> 333
D35: =$F$3 -> ECA | E35: =ROUND(($R39*$S$3 + ($T39*$T$3)), 2) -> 0 | F35: =$F27-SUMIF($L29:$P32,"SUBI",$F29:$F32) -> 0.01 | K35: mu_B | L35: SUBI
B36: >>> mu_B material here >>> | R36: =$A36*Q36 -> 0 | T36: =$A36*S36*$T$1 -> 0
R37: =$A37*Q37 -> 0 | T37: =$A37*S37*$T$1 -> 0
R38: =$A38*Q38 -> 0 | T38: =$A38*S38*$T$1 -> 0
A39: d> | B39: =(R38+T38) -> 0 | K39: mu_B | L39: SUBI | R39: =SUM(R35:R38) -> 0 | T39: =SUM(T35:T38) -> 0 | AG39: =ROUND($R39*$S$3,2) -> 0
G41: ICOST | L41: ITEM | R41: =SUMIF($L28:$L40,"SUBI",R28:R40) -> 333 | T41: =SUMIF($L28:$L40,"SUBI",T28:T40) -> 5.72
E42: Sell Rate | F42: Sell Total | K42: IB | AG42: U_M_Sell | AH42: T_M_Sell | AI42: U_L_Sell | AJ42: T_L_Sell | AK42: Total_Sell | AM42: T_M_Cost | AN42: T_L_Phr | AO42: Mat/Lab=1
A43: 2 | B43: No. | D43: Item: 2.002 | E43: =IF(AND($A43=0,$A$1="DIF"),0, ROUND(ROUND(SUMIF($L45:$L51,"SUBI",$E45:$E51)/$A43,2)*$C$12,2)) -> 245.04 | F43: =ROUND($A43*$E43,2) -> 490.08 | G43: ISELL | L43: ITEM | T43: =IF(AND($R57=0,$T57=0),"0.00","mu :" & ROUND($F43/$C$12/($R57+$T57*$D$9),2)) -> mu :1 | AG43: =IF(A43=0,0,ROUND(SUM(AG45:AG57)/A43,2)) -> 166.5 | AH43: =$AG43*$A43 -> 333 | AI43: =$E43-$AG43 -> 78.54 | AJ43: =$A43*$AI43 -> 157.08 | AK43: =ROUND(($AG43+$AI43)*$A43,2) -> 490.08 | AM43: =ROUND(R57,2) -> 333 | AN43: =ROUND(T57,2) -> 5.72 | AO43: =ROUND(AM43+AN43,2)*A43 -> 677.44
D44: EF-B1L-01 F300 Extract Fan - Norm: 42,800m3/hr at 200Pa; Fire: 71,000m3/hr at 200Pa - installed at Level 0
...

Sheet HVAC_BOQ
B2: SECTION 2 - HVAC
A4: ITEM | B4: DESCRIPTION | C4: QTY | D4: UNIT | E4: RATE Euro (Exc of VAT) | F4: TOTAL Euro (Exc of VAT) | G4: Material cost to Panta Ex VAT | H4: Labour pair hours @ €27.46per pair hour | I4: Labour pair hours @ €52.92per pair hour
A5: 1 | B5: PRELIMINARIES
B6: All equipment to be used within this contract is to be approved prior to delivery to site.
A7: =IFERROR(IF(OFFSET(A7,-1,0)>0,OFFSET(A7,-1,0)+0.001,ERROR.TYPE(0)),IFERROR(IF(OFFSET(A7,-2,0)>0,OFFSET(A7,-2,0)+0.001,ERROR.TYPE(0)),IFERROR(IF(OFFSET(A7,-3,0)>0,OFFSET(A7,-3,0)+0.001,ERROR.TYPE(0)),IFERROR(IF(OFFSET(A7,-4,0)>0,OFFSET(A7,-4,0)+0.001,ERROR.TYPE(0)),IFERROR(IF(OFFSET(A7,-5,0)>0,OFFSET(A7,-5,0)+0.001,ERROR.TYPE(0)),IFERROR(IF(OFFSET(A7,-6,0)>0,OFFSET(A7,-6,0)+0.001,ERROR.TYPE(0)),IFERROR(IF(OFFSET(A7,-7,0)>0,OFFSET(A7,-7,0)+0.001,ERROR.TYPE(0)),IFERROR(IF(OFFSET(A7,-8,0)>0,OFFSET(A7,-8,0)+0.001,ERROR.TYPE(0)),IFERROR(IF(OFFSET(A7,-9,0)>0,OFFSET(A7,-9,0)+0.001,ERROR.TYPE(0)),IFERROR(IF(OFFSET(A7,-10,0)>0,OFFSET(A7,-10,0)+0.001,ERROR.TYPE(0)),ERROR.TYPE(0))))))))))) -> 1.001 | B7: Mobilisation of site including the setting up of Storage facilities for materials, Sanitary facilities for the employees, Setting up of temporary site office, etc required to undertake the works | C7: 1 | D7: L.S. | F7: =IFERROR($C7*E7,E7) -> 0
A8: =IFERROR(IF(OFFSET(A8,-1,0)>0,OFFSET(A8,-1,0)+0.001,ERROR.TYPE(0)),IFERROR(IF(OFFSET(A8,-2,0)>0,OFFSET(A8,-2,0)+0.001,ERROR.TYPE(0)),IFERROR(IF(OFFSET(A8,-3,0)>0,OFFSET(A8,-3,0)+0.001,ERROR.TYPE(0)),IFERROR(IF(OFFSET(A8,-4,0)>0,OFFSET(A8,-4,0)+0.001,ERROR.TYPE(0)),IFERROR(IF(OFFSET(A8,-5,0)>0,OFFSET(A8,-5,0)+0.001,ERROR.TYPE(0)),IFERROR(IF(OFFSET(A8,-6,0)>0,OFFSET(A8,-6,0)+0.001,ERROR.TYPE(0)),IFERROR(IF(OFFSET(A8,-7,0)>0,OFFSET(A8,-7,0)+0.001,ERROR.TYPE(0)),IFERROR(IF(OFFSET(A8,-8,0)>0,OFFSET(A8,-8,0)+0.001,ERROR.TYPE(0)),IFERROR(IF(OFFSET(A8,-9,0)>0,OFFSET(A8,-9,0)+0.001,ERROR.TYPE(0)),IFERROR(IF(OFFSET(A8,-10,0)>0,OFFSET(A8,-10,0)+0.001,ERROR.TYPE(0)),ERROR.TYPE(0))))))))))) -> 1.002 | B8: Provision of insurance cover in the joint names of the Client and Contractor insure the Works against loss or damage by fire, storm, tempest, lightning, flood, earthquake, aircraft or anything dropped there from, aerial objects, riot and civil commotion for the full reinstatement value thereof plus 15% of all the Works executed and all unfixed materials and goods so insured until the completion of the Works. The Contractor shall affect a policy of insurance against third party risks to cover an amount of not less than Euro 500,000 (five hundred thousand Euros) for any one accident. The policy shall be in joint names of the Client and Contractor and shall include cross liability clauses. In respect of liability for the death or injury to any person employed by the Contractor and arising out of and in the course of such person's employment by the Contractor the amount insured by the Contractor shall be such as to indemnify the Client against all damages as compensation payable. The Contractor shall comply with and be subject to the terms, exclusions, exceptions, conditions and limitations of the insurance policies and shall bear the amount of the retained liabilities stated therein The Contractor shall deposit with the Client copies of the policy or policies and a copy of the receipt in respect of premiums paid before starting the Works | C8: 1 | D8: L.S. | F8: =IFERROR($C8*E8,E8) -> 0
A9: =IFERROR(IF(OFFSET(A9,-1,0)>0,OFFSET(A9,-1,0)+0.001,ERROR.TYPE(0)),IFERROR(IF(OFFSET(A9,-2,0)>0,OFFSET(A9,-2,0)+0.001,ERROR.TYPE(0)),IFERROR(IF(OFFSET(A9,-3,0)>0,OFFSET(A9,-3,0)+0.001,ERROR.TYPE(0)),IFERROR(IF(OFFSET(A9,-4,0)>0,OFFSET(A9,-4,0)+0.001,ERROR.TYPE(0)),IFERROR(IF(OFFSET(A9,-5,0)>0,OFFSET(A9,-5,0)+0.001,ERROR.TYPE(0)),IFERROR(IF(OFFSET(A9,-6,0)>0,OFFSET(A9,-6,0)+0.001,ERROR.TYPE(0)),IFERROR(IF(OFFSET(A9,-7,0)>0,OFFSET(A9,-7,0)+0.001,ERROR.TYPE(0)),IFERROR(IF(OFFSET(A9,-8,0)>0,OFFSET(A9,-8,0)+0.001,ERROR.TYPE(0)),IFERROR(IF(OFFSET(A9,-9,0)>0,OFFSET(A9,-9,0)+0.001,ERROR.TYPE(0)),IFERROR(IF(OFFSET(A9,-10,0)>0,OFFSET(A9,-10,0)+0.001,ERROR.TYPE(0)),ERROR.TYPE(0))))))))))) -> 1.003 | B9: Implementation of health and safety measures on site including personal safety (e.g safety shoes, helmets scaffolding, harnesses etc) as well as those to render the site safe for employees (e.g staircase handrails, closing of lift shaft openings etc) | C9: 1 | D9: L.S. | F9: =IFERROR($C9*E9,E9) -> 0
A10: =IFERROR(IF(OFFSET(A10,-1,0)>0,OFFSET(A10,-1,0)+0.001,ERROR.TYPE(0)),IFERROR(IF(OFFSET(A10,-2,0)>0,OFFSET(A10,-2,0)+0.001,ERROR.TYPE(0)),IFERROR(IF(OFFSET(A10,-3,0)>0,OFFSET(A10,-3,0)+0.001,ERROR.TYPE(0)),IFERROR(IF(OFFSET(A10,-4,0)>0,OFFSET(A10,-4,0)+0.001,ERROR.TYPE(0)),IFERROR(IF(OFFSET(A10,-5,0)>0,OFFSET(A10,-5,0)+0.001,ERROR.TYPE(0)),IFERROR(IF(OFFSET(A10,-6,0)>0,OFFSET(A10,-6,0)+0.001,ERROR.TYPE(0)),IFERROR(IF(OFFSET(A10,-7,0)>0,OFFSET(A10,-7,0)+0.001,ERROR.TYPE(0)),IFERROR(IF(OFFSET(A10,-8,0)>0,OFFSET(A10,-8,0)+0.001,ERROR.TYPE(0)),IFERROR(IF(OFFSET(A10,-9,0)>0,OFFSET(A10,-9,0)+0.001,ERROR.TYPE(0)),IFERROR(IF(OFFSET(A10,-10,0)>0,OFFSET(A10,-10,0)+0.001,ERROR.TYPE(0)),ERROR.TYPE(0))))))))))) -> 1.004 | B10: Prepare a risk assessment report outlining all risks involved and measures to be taken to minimise or eliminate potential risks. The report is to be prepared and signed by a competent person and to be submitted within three weeks from commencement of works. | C10: 1 | D10: L.S. | F10: =IFERROR($C10*E10,E10) -> 0
A11: =IFERROR(IF(OFFSET(A11,-1,0)>0,OFFSET(A11,-1,0)+0.001,ERROR.TYPE(0)),IFERROR(IF(OFFSET(A11,-2,0)>0,OFFSET(A11,-2,0)+0.001,ERROR.TYPE(0)),IFERROR(IF(OFFSET(A11,-3,0)>0,OFFSET(A11,-3,0)+0.001,ERROR.TYPE(0)),IFERROR(IF(OFFSET(A11,-4,0)>0,OFFSET(A11,-4,0)+0.001,ERROR.TYPE(0)),IFERROR(IF(OFFSET(A11,-5,0)>0,OFFSET(A11,-5,0)+0.001,ERROR.TYPE(0)),IFERROR(IF(OFFSET(A11,-6,0)>0,OFFSET(A11,-6,0)+0.001,ERROR.TYPE(0)),IFERROR(IF(OFFSET(A11,-7,0)>0,OFFSET(A11,-7,0)+0.001,ERROR.TYPE(0)),IFERROR(IF(OFFSET(A11,-8,0)>0,OFFSET(A11,-8,0)+0.001,ERROR.TYPE(0)),IFERROR(IF(OFFSET(A11,-9,0)>0,OFFSET(A11,-9,0)+0.001,ERROR.TYPE(0)),IFERROR(IF(OFFSET(A11,-10,0)>0,OFFSET(A11,-10,0)+0.001,ERROR.TYPE(0)),ERROR.TYPE(0))))))))))) -> 1.005 | B11: Allow for carrying out all surveys, setting out of works unless included elsewhere in the Bills of Quantities. | C11: 1 | D11: L.S. | F11: =IFERROR($C11*E11,E11) -> 0
A12: P | B12: TOTAL FOR PAGE 01 | C12: Euro Exc VAT | F12: =SUM(F7:F11) -> 0 | G12: =SUM(G7:G11) -> 0 | H12: =SUM(H7:H11) -> 0 | I12: =SUM(I7:I11) -> 0
A15: ITEM | B15: DESCRIPTION | C15: QTY | D15: UNIT | E15: RATE Euro (Exc of VAT) | F15: TOTAL Euro (Exc of VAT) | G15: Material cost to Panta Ex VAT | H15: Labour pair hours @ €27.46per pair hour | I15: Labour pair hours @ €52.92per pair hour
A16: =IFERROR(IF(OFFSET(A16,-1,0)>0,OFFSET(A16,-1,0)+0.001,ERROR.TYPE(0)),IFERROR(IF(OFFSET(A16,-2,0)>0,OFFSET(A16,-2,0)+0.001,ERROR.TYPE(0)),IFERROR(IF(OFFSET(A16,-3,0)>0,OFFSET(A16,-3,0)+0.001,ERROR.TYPE(0)),IFERROR(IF(OFFSET(A16,-4,0)>0,OFFSET(A16,-4,0)+0.001,ERROR.TYPE(0)),IFERROR(IF(OFFSET(A16,-5,0)>0,OFFSET(A16,-5,0)+0.001,ERROR.TYPE(0)),IFERROR(IF(OFFSET(A16,-6,0)>0,OFFSET(A16,-6,0)+0.001,ERROR.TYPE(0)),IFERROR(IF(OFFSET(A16,-7,0)>0,OFFSET(A16,-7,0)+0.001,ERROR.TYPE(0)),IFERROR(IF(OFFSET(A16,-8,0)>0,OFFSET(A16,-8,0)+0.001,ERROR.TYPE(0)),IFERROR(IF(OFFSET(A16,-9,0)>0,OFFSET(A16,-9,0)+0.001,ERROR.TYPE(0)),IFERROR(IF(OFFSET(A16,-10,0)>0,OFFSET(A16,-10,0)+0.001,ERROR.TYPE(0)),ERROR.TYPE(0))))))))))) -> 1.006 | B16: Provision for attending to site to take all relevant measurements in order to ascertain the exact quantities of the individual and measured items to be procured as well as keeping of all relevant records of personnel attendance, stock control etc | C16: 1 | D16: L.S. | F16: =IFERROR($C16*E16,E16) -> 0
A17: =IFERROR(IF(OFFSET(A17,-1,0)>0,OFFSET(A17,-1,0)+0.001,ERROR.TYPE(0)),IFERROR(IF(OFFSET(A17,-2,0)>0,OFFSET(A17,-2,0)+0.001,ERROR.TYPE(0)),IFERROR(IF(OFFSET(A17,-3,0)>0,OFFSET(A17,-3,0)+0.001,ERROR.TYPE(0)),IFERROR(IF(OFFSET(A17,-4,0)>0,OFFSET(A17,-4,0)+0.001,ERROR.TYPE(0)),IFERROR(IF(OFFSET(A17,-5,0)>0,OFFSET(A17,-5,0)+0.001,ERROR.TYPE(0)),IFERROR(IF(OFFSET(A17,-6,0)>0,OFFSET(A17,-6,0)+0.001,ERROR.TYPE(0)),IFERROR(IF(OFFSET(A17,-7,0)>0,OFFSET(A17,-7,0)+0.001,ERROR.TYPE(0)),IFERROR(IF(OFFSET(A17,-8,0)>0,OFFSET(A17,-8,0)+0.001,ERROR.TYPE(0)),IFERROR(IF(OFFSET(A17,-9,0)>0,OFFSET(A17,-9,0)+0.001,ERROR.TYPE(0)),IFERROR(IF(OFFSET(A17,-10,0)>0,OFFSET(A17,-10,0)+0.001,ERROR.TYPE(0)),ERROR.TYPE(0))))))))))) -> 1.007 | B17: Provision of security measures on site both as regards the storage facilities as well as to safeguard the materials installed during the latter stages of the project. | C17: 1 | D17: L.S. | F17: =IFERROR($C17*E17,E17) -> 0
A18: =IFERROR(IF(OFFSET(A18,-1,0)>0,OFFSET(A18,-1,0)+0.001,ERROR.TYPE(0)),IFERROR(IF(OFFSET(A18,-2,0)>0,OFFSET(A18,-2,0)+0.001,ERROR.TYPE(0)),IFERROR(IF(OFFSET(A18,-3,0)>0,OFFSET(A18,-3,0)+0.001,ERROR.TYPE(0)),IFERROR(IF(OFFSET(A18,-4,0)>0,OFFSET(A18,-4,0)+0.001,ERROR.TYPE(0)),IFERROR(IF(OFFSET(A18,-5,0)>0,OFFSET(A18,-5,0)+0.001,ERROR.TYPE(0)),IFERROR(IF(OFFSET(A18,-6,0)>0,OFFSET(A18,-6,0)+0.001,ERROR.TYPE(0)),IFERROR(IF(OFFSET(A18,-7,0)>0,OFFSET(A18,-7,0)+0.001,ERROR.TYPE(0)),IFERROR(IF(OFFSET(A18,-8,0)>0,OFFSET(A18,-8,0)+0.001,ERROR.TYPE(0)),IFERROR(IF(OFFSET(A18,-9,0)>0,OFFSET(A18,-9,0)+0.001,ERROR.TYPE(0)),IFERROR(IF(OFFSET(A18,-10,0)>0,OFFSET(A18,-10,0)+0.001,ERROR.TYPE(0)),ERROR.TYPE(0))))))))))) -> 1.008 | B18: Provision for the supply and delivery to site of samples as may be requested by the client / engineer | C18: 1 | D18: L.S. | F18: =IFERROR($C18*E18,E18) -> 0
A19: =IFERROR(IF(OFFSET(A19,-1,0)>0,OFFSET(A19,-1,0)+0.001,ERROR.TYPE(0)),IFERROR(IF(OFFSET(A19,-2,0)>0,OFFSET(A19,-2,0)+0.001,ERROR.TYPE(0)),IFERROR(IF(OFFSET(A19,-3,0)>0,OFFSET(A19,-3,0)+0.001,ERROR.TYPE(0)),IFERROR(IF(OFFSET(A19,-4,0)>0,OFFSET(A19,-4,0)+0.001,ERROR.TYPE(0)),IFERROR(IF(OFFSET(A19,-5,0)>0,OFFSET(A19,-5,0)+0.001,ERROR.TYPE(0)),IFERROR(IF(OFFSET(A19,-6,0)>0,OFFSET(A19,-6,0)+0.001,ERROR.TYPE(0)),IFERROR(IF(OFFSET(A19,-7,0)>0,OFFSET(A19,-7,0)+0.001,ERROR.TYPE(0)),IFERROR(IF(OFFSET(A19,-8,0)>0,OFFSET(A19,-8,0)+0.001,ERROR.TYPE(0)),IFERROR(IF(OFFSET(A19,-9,0)>0,OFFSET(A19,-9,0)+0.001,ERROR.TYPE(0)),IFERROR(IF(OFFSET(A19,-10,0)>0,OFFSET(A19,-10,0)+0.001,ERROR.TYPE(0)),ERROR.TYPE(0))))))))))) -> 1.009 | B19: Allow for continuously keeping the site and building clean and in a workman type condition free from debris, surplus materials and any other type of loose matter arising from works, which will disturb the proper conditions of any internal and external areas, roads and/or adjoining structures. Site Cleaning is to take place during the whole duration of works. Client reserves the right to employ cleaning companies at the contractor's expense if the contractor fails to keep the site clean. | C19: 1 | D19: L.S. | F19: =IFERROR($C19*E19,E19) -> 0
A20: =IFERROR(IF(OFFSET(A20,-1,0)>0,OFFSET(A20,-1,0)+0.001,ERROR.TYPE(0)),IFERROR(IF(OFFSET(A20,-2,0)>0,OFFSET(A20,-2,0)+0.001,ERROR.TYPE(0)),IFERROR(IF(OFFSET(A20,-3,0)>0,OFFSET(A20,-3,0)+0.001,ERROR.TYPE(0)),IFERROR(IF(OFFSET(A20,-4,0)>0,OFFSET(A20,-4,0)+0.001,ERROR.TYPE(0)),IFERROR(IF(OFFSET(A20,-5,0)>0,OFFSET(A20,-5,0)+0.001,ERROR.TYPE(0)),IFERROR(IF(OFFSET(A20,-6,0)>0,OFFSET(A20,-6,0)+0.001,ERROR.TYPE(0)),IFERROR(IF(OFFSET(A20,-7,0)>0,OFFSET(A20,-7,0)+0.001,ERROR.TYPE(0)),IFERROR(IF(OFFSET(A20,-8,0)>0,OFFSET(A20,-8,0)+0.001,ERROR.TYPE(0)),IFERROR(IF(OFFSET(A20,-9,0)>0,OFFSET(A20,-9,0)+0.001,ERROR.TYPE(0)),IFERROR(IF(OFFSET(A20,-10,0)>0,OFFSET(A20,-10,0)+0.001,ERROR.TYPE(0)),ERROR.TYPE(0))))))))))) -> 1.01 | B20: Provision for hauling of equipment on site, including cranage, permits and all necessary fees. | C20: 1 | D20: L.S. | F20: =IFERROR($C20*E20,E20) -> 0
A21: =IFERROR(IF(OFFSET(A21,-1,0)>0,OFFSET(A21,-1,0)+0.001,ERROR.TYPE(0)),IFERROR(IF(OFFSET(A21,-2,0)>0,OFFSET(A21,-2,0)+0.001,ERROR.TYPE(0)),IFERROR(IF(OFFSET(A21,-3,0)>0,OFFSET(A21,-3,0)+0.001,ERROR.TYPE(0)),IFERROR(IF(OFFSET(A21,-4,0)>0,OFFSET(A21,-4,0)+0.001,ERROR.TYPE(0)),IFERROR(IF(OFFSET(A21,-5,0)>0,OFFSET(A21,-5,0)+0.001,ERROR.TYPE(0)),IFERROR(IF(OFFSET(A21,-6,0)>0,OFFSET(A21,-6,0)+0.001,ERROR.TYPE(0)),IFERROR(IF(OFFSET(A21,-7,0)>0,OFFSET(A21,-7,0)+0.001,ERROR.TYPE(0)),IFERROR(IF(OFFSET(A21,-8,0)>0,OFFSET(A21,-8,0)+0.001,ERROR.TYPE(0)),IFERROR(IF(OFFSET(A21,-9,0)>0,OFFSET(A21,-9,0)+0.001,ERROR.TYPE(0)),IFERROR(IF(OFFSET(A21,-10,0)>0,OFFSET(A21,-10,0)+0.001,ERROR.TYPE(0)),ERROR.TYPE(0))))))))))) -> 1.011 | B21: Provision for working at height, including scaffolding, cherry pickers etc. All equipment shall be fully certified. | C21: 1 | D21: L.S. | F21: =IFERROR($C21*E21,E21) -> 0
A22: =IFERROR(IF(OFFSET(A22,-1,0)>0,OFFSET(A22,-1,0)+0.001,ERROR.TYPE(0)),IFERROR(IF(OFFSET(A22,-2,0)>0,OFFSET(A22,-2,0)+0.001,ERROR.TYPE(0)),IFERROR(IF(OFFSET(A22,-3,0)>0,OFFSET(A22,-3,0)+0.001,ERROR.TYPE(0)),IFERROR(IF(OFFSET(A22,-4,0)>0,OFFSET(A22,-4,0)+0.001,ERROR.TYPE(0)),IFERROR(IF(OFFSET(A22,-5,0)>0,OFFSET(A22,-5,0)+0.001,ERROR.TYPE(0)),IFERROR(IF(OFFSET(A22,-6,0)>0,OFFSET(A22,-6,0)+0.001,ERROR.TYPE(0)),IFERROR(IF(OFFSET(A22,-7,0)>0,OFFSET(A22,-7,0)+0.001,ERROR.TYPE(0)),IFERROR(IF(OFFSET(A22,-8,0)>0,OFFSET(A22,-8,0)+0.001,ERROR.TYPE(0)),IFERROR(IF(OFFSET(A22,-9,0)>0,OFFSET(A22,-9,0)+0.001,ERROR.TYPE(0)),IFERROR(IF(OFFSET(A22,-10,0)>0,OFFSET(A22,-10,0)+0.001,ERROR.TYPE(0)),ERROR.TYPE(0))))))))))) -> 1.012 | B22: Provision for Builders Work in order to prepare all openings required to install conduits, pipework, ductwork, etc., and making good and reinstatement of all openings. | C22: 1 | D22: L.S. | F22: =IFERROR($C22*E22,E22) -> 0
A23: =IFERROR(IF(OFFSET(A23,-1,0)>0,OFFSET(A23,-1,0)+0.001,ERROR.TYPE(0)),IFERROR(IF(OFFSET(A23,-2,0)>0,OFFSET(A23,-2,0)+0.001,ERROR.TYPE(0)),IFERROR(IF(OFFSET(A23,-3,0)>0,OFFSET(A23,-3,0)+0.001,ERROR.TYPE(0)),IFERROR(IF(OFFSET(A23,-4,0)>0,OFFSET(A23,-4,0)+0.001,ERROR.TYPE(0)),IFERROR(IF(OFFSET(A23,-5,0)>0,OFFSET(A23,-5,0)+0.001,ERROR.TYPE(0)),IFERROR(IF(OFFSET(A23,-6,0)>0,OFFSET(A23,-6,0)+0.001,ERROR.TYPE(0)),IFERROR(IF(OFFSET(A23,-7,0)>0,OFFSET(A23,-7,0)+0.001,ERROR.TYPE(0)),IFERROR(IF(OFFSET(A23,-8,0)>0,OFFSET(A23,-8,0)+0.001,ERROR.TYPE(0)),IFERROR(IF(OFFSET(A23,-9,0)>0,OFFSET(A23,-9,0)+0.001,ERROR.TYPE(0)),IFERROR(IF(OFFSET(A23,-10,0)>0,OFFSET(A23,-10,0)+0.001,ERROR.TYPE(0)),ERROR.TYPE(0))))))))))) -> 1.013 | B23: Provision for Openings in Insulation Panelling in order to prepare all openings required to install conduits, pipework, ductwork, etc., and making good and reinstatement of all openings. | C23: 1 | D23: L.S. | F23: =IFERROR($C23*E23,E23) -> 0
A24: P | B24: TOTAL FOR PAGE 02 | C24: Euro Exc VAT | F24: =SUM(F16:F23) -> 0 | G24: =SUM(G16:G23) -> 0 | H24: =SUM(H16:H23) -> 0 | I24: =SUM(I16:I23) -> 0
B26: TOTAL FOR PRELIMINARIES | C26: Euro Exc VAT | F26: =F24+F12 -> 0 | G26: =G24+G12 -> 0 | H26: =H24+H12 -> 0 | I26: =I24+I12 -> 0
A29: ITEM | B29: DESCRIPTION | C29: QTY | D29: UNIT | E29: RATE Euro (Exc of VAT) | F29: TOTAL Euro (Exc of VAT) | G29: Material cost to Panta Ex VAT | H29: Labour pair hours @ €27.46per pair hour | I29: Labour pair hours @ €52.92per pair hour
A30: 2T | B30: VENTILATION SYSTEM
A31: T | B31: FANS - BASEMENT LEVEL -1
A32: T | B32: Supply, install and connect the following In-line type extract fans c/w 2 silencers - one upstream and one downstream from the fan, variable speed controllers, anti-vibration mountings, chamfered bird screen, transformation pieces etc for a complete system inclusive of connecting up of fans to electrical supply.
A33: 2.001 | B33: EF-B1U-01 F300 Extract Fan - Norm: 33,000m3/hr at 200Pa; Fire: 55,000m3/hr at 200Pa - installed at Level 0 | C33: 2 | D33: No. | E33: =Elec_Est!E27 -> 245.04 | F33: =IFERROR($C33*E33,E33) -> 490.08 | G33: =Elec_Est!AM27 -> 333 | H33: =Elec_Est!AN27 -> 5.72
A34: =IFERROR(IF(OFFSET(A34,-1,0,1,1)>0,OFFSET(A34,-1,0,1,1)+0.001,ERROR.TYPE(0)),IFERROR(IF(OFFSET(A34,-2,0,1,1)>0,OFFSET(A34,-2,0,1,1)+0.001,ERROR.TYPE(0)),IFERROR(IF(OFFSET(A34,-3,0,1,1)>0,OFFSET(A34,-3,0,1,1)+0.001,ERROR.TYPE(0)),IFERROR(IF(OFFSET(A34,-4,0,1,1)>0,OFFSET(A34,-4,0,1,1)+0.001,ERROR.TYPE(0)),IFERROR(IF(OFFSET(A34,-5,0,1,1)>0,OFFSET(A34,-5,0,1,1)+0.001,ERROR.TYPE(0)),IFERROR(IF(OFFSET(A34,-6,0,1,1)>0,OFFSET(A34,-6,0,1,1)+0.001,ERROR.TYPE(0)),IFERROR(IF(OFFSET(A34,-7,0,1,1)>0,OFFSET(A34,-7,0,1,1)+0.001,ERROR.TYPE(0)),IFERROR(IF(OFFSET(A34,-8,0,1,1)>0,OFFSET(A34,-8,0,1,1)+0.001,ERROR.TYPE(0)),IFERROR(IF(OFFSET(A34,-9,0,1,1)>0,OFFSET(A34,-9,0,1,1)+0.001,ERROR.TYPE(0)),IFERROR(IF(OFFSET(A34,-10,0,1,1)>0,OFFSET(A34,-10,0,1,1)+0.001,ERROR.TYPE(0)),ERROR.TYPE(0))))))))))) -> 2.002 | B34: EF-B1L-01 F300 Extract Fan - Norm: 42,800m3/hr at 200Pa; Fire: 71,000m3/hr at 200Pa - installed at Level 0 | C34: 2 | D34: No. | E34: =Elec_Est!E43 -> 245.04 | F34: =IFERROR($C34*E34,E34) -> 490.08 | G34: =Elec_Est!AM43 -> 333 | H34: =Elec_Est!AN43 -> 5.72
A35: =IFERROR(IF(OFFSET(A35,-1,0,1,1)>0,OFFSET(A35,-1,0,1,1)+0.001,ERROR.TYPE(0)),IFERROR(IF(OFFSET(A35,-2,0,1,1)>0,OFFSET(A35,-2,0,1,1)+0.001,ERROR.TYPE(0)),IFERROR(IF(OFFSET(A35,-3,0,1,1)>0,OFFSET(A35,-3,0,1,1)+0.001,ERROR.TYPE(0)),IFERROR(IF(OFFSET(A35,-4,0,1,1)>0,OFFSET(A35,-4,0,1,1)+0.001,ERROR.TYPE(0)),IFERROR(IF(OFFSET(A35,-5,0,1,1)>0,OFFSET(A35,-5,0,1,1)+0.001,ERROR.TYPE(0)),IFERROR(IF(OFFSET(A35,-6,0,1,1)>0,OFFSET(A35,-6,0,1,1)+0.001,ERROR.TYPE(0)),IFERROR(IF(OFFSET(A35,-7,0,1,1)>0,OFFSET(A35,-7,0,1,1)+0.001,ERROR.TYPE(0)),IFERROR(IF(OFFSET(A35,-8,0,1,1)>0,OFFSET(A35,-8,0,1,1)+0.001,ERROR.TYPE(0)),IFERROR(IF(OFFSET(A35,-9,0,1,1)>0,OFFSET(A35,-9,0,1,1)+0.001,ERROR.TYPE(0)),IFERROR(IF(OFFSET(A35,-10,0,1,1)>0,OFFSET(A35,-10,0,1,1)+0.001,ERROR.TYPE(0)),ERROR.TYPE(0))))))))))) -> 2.003 | B35: EF-B1U-02 Extract Fan - 1300m3/hr at 125Pa - installed at Level 0 | C35: 1 | D35: No. | E35: =Elec_Est!E59 -> 65.62 | F35: =IFERROR($C35*E35,E35) -> 65.62 | G35: =Elec_Est!AM59 -> 20.04 | H35: =Elec_Est!AN59 -> 1.66
A36: =IFERROR(IF(OFFSET(A36,-1,0,1,1)>0,OFFSET(A36,-1,0,1,1)+0.001,ERROR.TYPE(0)),IFERROR(IF(OFFSET(A36,-2,0,1,1)>0,OFFSET(A36,-2,0,1,1)+0.001,ERROR.TYPE(0)),IFERROR(IF(OFFSET(A36,-3,0,1,1)>0,OFFSET(A36,-3,0,1,1)+0.001,ERROR.TYPE(0)),IFERROR(IF(OFFSET(A36,-4,0,1,1)>0,OFFSET(A36,-4,0,1,1)+0.001,ERROR.TYPE(0)),IFERROR(IF(OFFSET(A36,-5,0,1,1)>0,OFFSET(A36,-5,0,1,1)+0.001,ERROR.TYPE(0)),IFERROR(IF(OFFSET(A36,-6,0,1,1)>0,OFFSET(A36,-6,0,1,1)+0.001,ERROR.TYPE(0)),IFERROR(IF(OFFSET(A36,-7,0,1,1)>0,OFFSET(A36,-7,0,1,1)+0.001,ERROR.TYPE(0)),IFERROR(IF(OFFSET(A36,-8,0,1,1)>0,OFFSET(A36,-8,0,1,1)+0.001,ERROR.TYPE(0)),IFERROR(IF(OFFSET(A36,-9,0,1,1)>0,OFFSET(A36,-9,0,1,1)+0.001,ERROR.TYPE(0)),IFERROR(IF(OFFSET(A36,-10,0,1,1)>0,OFFSET(A36,-10,0,1,1)+0.001,ERROR.TYPE(0)),ERROR.TYPE(0))))))))))) -> 2.004 | B36: EF-B1L-02 Extract Fan - 32,000m3/hr at 250Pa - installed at Level 1 | C36: 1 | D36: No. | E36: =Elec_Est!E75 -> 73.04 | F36: =IFERROR($C36*E36,E36) -> 73.04 | G36: =Elec_Est!AM75 -> 24.44 | H36: =Elec_Est!AN75 -> 1.77
A37: =IFERROR(IF(OFFSET(A37,-1,0,1,1)>0,OFFSET(A37,-1,0,1,1)+0.001,ERROR.TYPE(0)),IFERROR(IF(OFFSET(A37,-2,0,1,1)>0,OFFSET(A37,-2,0,1,1)+0.001,ERROR.TYPE(0)),IFERROR(IF(OFFSET(A37,-3,0,1,1)>0,OFFSET(A37,-3,0,1,1)+0.001,ERROR.TYPE(0)),IFERROR(IF(OFFSET(A37,-4,0,1,1)>0,OFFSET(A37,-4,0,1,1)+0.001,ERROR.TYPE(0)),IFERROR(IF(OFFSET(A37,-5,0,1,1)>0,OFFSET(A37,-5,0,1,1)+0.001,ERROR.TYPE(0)),IFERROR(IF(OFFSET(A37,-6,0,1,1)>0,OFFSET(A37,-6,0,1,1)+0.001,ERROR.TYPE(0)),IFERROR(IF(OFFSET(A37,-7,0,1,1)>0,OFFSET(A37,-7,0,1,1)+0.001,ERROR.TYPE(0)),IFERROR(IF(OFFSET(A37,-8,0,1,1)>0,OFFSET(A37,-8,0,1,1)+0.001,ERROR.TYPE(0)),IFERROR(IF(OFFSET(A37,-9,0,1,1)>0,OFFSET(A37,-9,0,1,1)+0.001,ERROR.TYPE(0)),IFERROR(IF(OFFSET(A37,-10,0,1,1)>0,OFFSET(A37,-10,0,1,1)+0.001,ERROR.TYPE(0)),ERROR.TYPE(0))))))))))) -> 2.005 | B37: SF-B1L-01 Supply Fan - 35,000m3/hr at 250Pa - installed at Basement Level -1 | C37: 1 | D37: No. | E37: =Elec_Est!E91 -> 73.04 | F37: =IFERROR($C37*E37,E37) -> 73.04 | G37: =Elec_Est!AM91 -> 24.44 | H37: =Elec_Est!AN91 -> 1.77
A38: =IFERROR(IF(OFFSET(A38,-1,0,1,1)>0,OFFSET(A38,-1,0,1,1)+0.001,ERROR.TYPE(0)),IFERROR(IF(OFFSET(A38,-2,0,1,1)>0,OFFSET(A38,-2,0,1,1)+0.001,ERROR.TYPE(0)),IFERROR(IF(OFFSET(A38,-3,0,1,1)>0,OFFSET(A38,-3,0,1,1)+0.001,ERROR.TYPE(0)),IFERROR(IF(OFFSET(A38,-4,0,1,1)>0,OFFSET(A38,-4,0,1,1)+0.001,ERROR.TYPE(0)),IFERROR(IF(OFFSET(A38,-5,0,1,1)>0,OFFSET(A38,-5,0,1,1)+0.001,ERROR.TYPE(0)),IFERROR(IF(OFFSET(A38,-6,0,1,1)>0,OFFSET(A38,-6,0,1,1)+0.001,ERROR.TYPE(0)),IFERROR(IF(OFFSET(A38,-7,0,1,1)>0,OFFSET(A38,-7,0,1,1)+0.001,ERROR.TYPE(0)),IFERROR(IF(OFFSET(A38,-8,0,1,1)>0,OFFSET(A38,-8,0,1,1)+0.001,ERROR.TYPE(0)),IFERROR(IF(OFFSET(A38,-9,0,1,1)>0,OFFSET(A38,-9,0,1,1)+0.001,ERROR.TYPE(0)),IFERROR(IF(OFFSET(A38,-10,0,1,1)>0,OFFSET(A38,-10,0,1,1)+0.001,ERROR.TYPE(0)),ERROR.TYPE(0))))))))))) -> 2.006 | B38: Supply and install differential pressure alarm complete with remote visual and audible indicators including all cabling etc for a complete system | C38: 1 | D38: No. | E38: =Elec_Est!E108 -> 309.67 | F38: =IFERROR($C38*E38,E38) -> 309.67 | G38: =Elec_Est!AM108 -> 114.98 | H38: =Elec_Est!AN108 -> 7.09
B39: Supply, install and connect the following In-line type extract fans c/w 2 silencers - one upstream and one downstream from the fan, variable speed controllers, anti-vibration mountings, chamfered bird screen, transformation pieces etc for a complete system inclusive of connecting up of fans to electrical supply.
A40: 2.006a | B40: EF-GEN-01 F300 Extract Fan - 9,700m3/hr at 250Pa - installed at Basement Level -1 | C40: 1 | D40: No. | F40: =IFERROR($C40*E40,E40) -> 0 | G40: =Elec_Est!AM123 -> 24.44 | H40: =Elec_Est!AN123 -> 1.77
A41: 2.006b | B41: SF-GEN-01 F300 Supply Fan - 9,700m3/hr at 250Pa - installed at Basement Level -1 | C41: 1 | D41: No. | F41: =IFERROR($C41*E41,E41) -> 0 | G41: =Elec_Est!AM139 -> 24.44 | H41: =Elec_Est!AN139 -> 1.77
A42: T | B42: Supply, install and connect the following Induction Jet fans c/w transformation pieces etc and including the connecting up to the electrical supply for a complete system
A43: =IFERROR(IF(OFFSET(A43,-1,0,1,1)>0,OFFSET(A43,-1,0,1,1)+0.001,ERROR.TYPE(0)),IFERROR(IF(OFFSET(A43,-2,0,1,1)>0,OFFSET(A43,-2,0,1,1)+0.001,ERROR.TYPE(0)),IFERROR(IF(OFFSET(A43,-3,0,1,1)>0,OFFSET(A43,-3,0,1,1)+0.001,ERROR.TYPE(0)),IFERROR(IF(OFFSET(A43,-4,0,1,1)>0,OFFSET(A43,-4,0,1,1)+0.001,ERROR.TYPE(0)),IFERROR(IF(OFFSET(A43,-5,0,1,1)>0,OFFSET(A43,-5,0,1,1)+0.001,ERROR.TYPE(0)),IFERROR(IF(OFFSET(A43,-6,0,1,1)>0,OFFSET(A43,-6,0,1,1)+0.001,ERROR.TYPE(0)),IFERROR(IF(OFFSET(A43,-7,0,1,1)>0,OFFSET(A43,-7,0,1,1)+0.001,ERROR.TYPE(0)),IFERROR(IF(OFFSET(A43,-8,0,1,1)>0,OFFSET(A43,-8,0,1,1)+0.001,ERROR.TYPE(0)),IFERROR(IF(OFFSET(A43,-9,0,1,1)>0,OFFSET(A43,-9,0,1,1)+0.001,ERROR.TYPE(0)),IFERROR(IF(OFFSET(A43,-10,0,1,1)>0,OFFSET(A43,-10,0,1,1)+0.001,ERROR.TYPE(0)),ERROR.TYPE(0))))))))))) -> 2.007 | B43: JF-B1U-01 to 07 Jet Fan - Normal: 3500m3/hr; Fire: 5800m3/hr - installed at Basement Level -1 | C43: 7 | D43: No. | E43: =Elec_Est!E159 -> 89.37 | F43: =IFERROR($C43*E43,E43) -> 625.59 | G43: =Elec_Est!AM159 -> 310.38 | H43: =Elec_Est!AN159 -> 11.48
A44: =IFERROR(IF(OFFSET(A44,-1,0,1,1)>0,OFFSET(A44,-1,0,1,1)+0.001,ERROR.TYPE(0)),IFERROR(IF(OFFSET(A44,-2,0,1,1)>0,OFFSET(A44,-2,0,1,1)+0.001,ERROR.TYPE(0)),IFERROR(IF(OFFSET(A44,-3,0,1,1)>0,OFFSET(A44,-3,0,1,1)+0.001,ERROR.TYPE(0)),IFERROR(IF(OFFSET(A44,-4,0,1,1)>0,OFFSET(A44,-4,0,1,1)+0.001,ERROR.TYPE(0)),IFERROR(IF(OFFSET(A44,-5,0,1,1)>0,OFFSET(A44,-5,0,1,1)+0.001,ERROR.TYPE(0)),IFERROR(IF(OFFSET(A44,-6,0,1,1)>0,OFFSET(A44,-6,0,1,1)+0.001,ERROR.TYPE(0)),IFERROR(IF(OFFSET(A44,-7,0,1,1)>0,OFFSET(A44,-7,0,1,1)+0.001,ERROR.TYPE(0)),IFERROR(IF(OFFSET(A44,-8,0,1,1)>0,OFFSET(A44,-8,0,1,1)+0.001,ERROR.TYPE(0)),IFERROR(IF(OFFSET(A44,-9,0,1,1)>0,OFFSET(A44,-9,0,1,1)+0.001,ERROR.TYPE(0)),IFERROR(IF(OFFSET(A44,-10,0,1,1)>0,OFFSET(A44,-10,0,1,1)+0.001,ERROR.TYPE(0)),ERROR.TYPE(0))))))))))) -> 2.008 | B44: JF-B1L-01 to 08 Jet Fan - Normal: 3500m3/hr; Fire: 5800m3/hr - installed at Basement Level -1 | C44: 8 | D44: No. | E44: =Elec_Est!E175 -> 89.38 | F44: =IFERROR($C44*E44,E44) -> 715.04 | G44: =Elec_Est!AM175 -> 354.72 | H44: =Elec_Est!AN175 -> 13.12
A45: T | B45: FANS - UPPER LEVELS
A46: T | B46: Supply, install and connect the following In-line type extract fans c/w 2 silencers - one upstream and one downstream from the fan, variable speed controllers, anti-vibration mountings, chamfered bird screen, transformation pieces etc for a complete system inclusive of connecting up of fans to electrical supply.
A47: =IFERROR(IF(OFFSET(A47,-1,0,1,1)>0,OFFSET(A47,-1,0,1,1)+0.001,ERROR.TYPE(0)),IFERROR(IF(OFFSET(A47,-2,0,1,1)>0,OFFSET(A47,-2,0,1,1)+0.001,ERROR.TYPE(0)),IFERROR(IF(OFFSET(A47,-3,0,1,1)>0,OFFSET(A47,-3,0,1,1)+0.001,ERROR.TYPE(0)),IFERROR(IF(OFFSET(A47,-4,0,1,1)>0,OFFSET(A47,-4,0,1,1)+0.001,ERROR.TYPE(0)),IFERROR(IF(OFFSET(A47,-5,0,1,1)>0,OFFSET(A47,-5,0,1,1)+0.001,ERROR.TYPE(0)),IFERROR(IF(OFFSET(A47,-6,0,1,1)>0,OFFSET(A47,-6,0,1,1)+0.001,ERROR.TYPE(0)),IFERROR(IF(OFFSET(A47,-7,0,1,1)>0,OFFSET(A47,-7,0,1,1)+0.001,ERROR.TYPE(0)),IFERROR(IF(OFFSET(A47,-8,0,1,1)>0,OFFSET(A47,-8,0,1,1)+0.001,ERROR.TYPE(0)),IFERROR(IF(OFFSET(A47,-9,0,1,1)>0,OFFSET(A47,-9,0,1,1)+0.001,ERROR.TYPE(0)),IFERROR(IF(OFFSET(A47,-10,0,1,1)>0,OFFSET(A47,-10,0,1,1)+0.001,ERROR.TYPE(0)),ERROR.TYPE(0))))))))))) -> 2.009 | B47: EF-OF-01 Extract Fan - 540m3/hr at 125Pa - installed at Level 0 | C47: 1 | D47: No. | E47: =Elec_Est!E199 -> 65.62 | F47: =IFERROR($C47*E47,E47) -> 65.62 | G47: =Elec_Est!AM199 -> 20.04 | H47: =Elec_Est!AN199 -> 1.66
...

Sheet Notes
A1: NOTES | C1: Rev: 235
C2: checkdesc
A3: ELECTRICAL | C3: Elec_Rates
C4: Elec_Est
A5: Dist Boards | C5: Elv_Rates
A6: 1 | C6: ELV_Est
A7: 2 | C7: Ext_Quote
C8: Int_Quote
A9: Wiring Accessories | C9: Est_BOQ
A10: 1
A11: 2 | C11: Camilleri&Cuschieri Tenders
C12: Conduit
A13: ELV | C13: Wiring
C14: Supply
A15: Fire Alarm
A16: 1
A17: 2
A18: 3
A20: Data
A21: 1
A22: 2
A23: 3

Sheet Quote
A1: =IF(AND(UPPER(LEFT(TRIM($D$8),11))="01",UPPER(LEFT(TRIM($D$9),3))<>"ELM"),"PANTA RETAIL LTD.","PANTA CONTRACTING LIMITED") -> PANTA CONTRACTING LIMITED
A2: =IF(UPPER(LEFT(TRIM($D$9),3))="ELM","ELEC-FOR-MECH INTERNAL QUOTATION","ELECTRICAL INTERNAL QUOTATION") -> ELEC-FOR-MECH INTERNAL QUOTATION
B5: ATT: | D5: =IF(A2="Internal Quotation", "Mechanical Division","") | R5: Dated: | S5: =NOW() -> 45821.462
B6: CLIENT: | C6: Link to ML_SUM $D1 | D6: =ML_Sum!D1 -> Quintano Foods Ltd.
B7: PROJECT: | C7: Link to ML_SUM $D2 | D7: =ML_Sum!D2 -> Warehouse at tal-Handaq, Qormi
B8: JOB DESC: | C8: Link to ML_SUM $D3 | D8: =ML_Sum!D3 -> Electrical installation for Mechanical (HVAC) - Revision B
B9: QUOTE No: | C9: Link to ML_SUM $D4 | D9: =ML_Sum!D4 -> ELM-25-0085B
B10: CLIENT's Ref: | C10: Link to ML_SUM $D5 | D10: =ML_Sum!D5 -> Tender
D21: Material Cost (€) : | E21: =ML_Sum!R35 -> 59910.035 | F21: =ML_Sum!D6 -> VAT EXCL. | G21: VAT EXCLUDED. | H21: VAT EXCLUDED. | I21: VAT EXCLUDED. | J21: VAT EXCLUDED. | K21: VAT EXCLUDED. | L21: VAT EXCLUDED. | M21: VAT EXCLUDED. | N21: VAT EXCLUDED. | O21: VAT EXCLUDED. | P21: VAT EXCLUDED.
D22: Labour Pair Hours : | E22: =ML_Sum!T23 -> 626.36 | F22: at €27.46 Ex VAT cost to Panta
D23: Labour Pair Hours : | E23: =ML_Sum!T24 -> 106 | F23: at €52.92 Ex VAT cost to Panta
A51: Signed for and on behalf of | Q51: Signed for and on behalf of
A52: Electrical Division | Q52: Division
Q54: Records
Q55: Mr. A. Sciberras
Q57: File

Sheet ML_Sum
B1: CLIENT: | C1: 1 | D1: Quintano Foods Ltd. | G1: TRUE | H1: TRUE | I1: 1 | J1: =$Q109 -> 1 | K1: =$Q119 -> 1 | L1: =$Q129 -> 1 | M1: =$Q139 -> 1 | N1: =$Q149 -> 1 | O1: =$Q159 -> 1 | Q1: =IF(C1=1,"€","Curr?") -> € | R1: Recon /Lab.Cont >> | S1: =IF($S$39="PRINT","R","Do Not Print") -> R | T1: 1 | V1: {=IF(OR(X1=AREAS),1,0)} -> 1 | W1: BOQ | X1: x | Y1: x | Z1: x | AA1: x | AB1: x | AC1: x | AD1: x
B2: PROJECT: | C2: =IF($D$6="VAT INCLUDED",1.18,1)*(1-$Q2)*$C$1 -> 1 | D2: Warehouse at tal-Handaq, Qormi | F2: Electrical | G2: TRUE | I2: 2 | J2: =$Q110 -> 1 | K2: =$Q120 -> 1 | L2: =$Q130 -> 1 | M2: =$Q140 -> 1 | N2: =$Q150 -> 1 | O2: =$Q160 -> 1 | R2: ="A) " & IF($S2=0,"",ROUND($S2,2) & "-" & ROUND($T2/$D$9,2)) -> A) 1-1 | S2: 1 | T2: =$S2*$D$9 -> 27.46 | X2: x | Y2: x | Z2: x | AA2: x | AB2: x | AC2: x | AD2: x
B3: JOB DESC: | C3: =IF($D$6="VAT INCLUDED",1.18,1)*(1-$Q3)*$C$1 -> 1 | D3: Electrical installation for Mechanical (HVAC) - Revision B | F3: ECA | G3: TRUE | I3: 3 | J3: =$Q111 -> 1 | K3: =$Q121 -> 1 | L3: =$Q131 -> 1 | M3: =$Q141 -> 1 | N3: =$Q151 -> 1 | O3: =$Q161 -> 1 | R3: ="B) " & IF($S3=0,"",ROUND($S3,2) & "-" & ROUND($T3/$D$9,2)) -> B) 1-1 | S3: 1 | T3: =$S3*$D$9 -> 27.46 | X3: x | Y3: x | Z3: x | AA3: x | AB3: x | AC3: x | AD3: x
B4: INT. QUOT No: | C4: =IF($D$6="VAT INCLUDED",1.18,1)*(1-$Q4)*$C$1 -> 1 | D4: ELM-25-0085B | G4: TRUE | I4: 4 | J4: =$Q112 -> 1 | K4: =$Q122 -> 1 | L4: =$Q132 -> 1 | M4: =$Q142 -> 1 | N4: =$Q152 -> 1 | O4: =$Q162 -> 1 | R4: ="C) " & IF($S4=0,"",ROUND($S4,2) & "-" & ROUND($T4/$D$9,2)) -> C) 1-1 | S4: 1 | T4: =$S4*$D$9 -> 27.46 | X4: x | Y4: x | Z4: x | AA4: x | AB4: x | AC4: x | AD4: x
B5: CLIENTs REF: | C5: =IF($D$6="VAT INCLUDED",1.18,1)*(1-$Q5)*$C$1 -> 1 | D5: Tender | G5: TRUE | I5: 5 | J5: =$Q113 -> 1 | K5: =$Q123 -> 1 | L5: =$Q133 -> 1 | M5: =$Q143 -> 1 | N5: =$Q153 -> 1 | O5: =$Q163 -> 1 | R5: ="D) " & IF($S5=0,"",ROUND($S5,2) & "-" & ROUND($T5/$D$9,2)) -> D) 1-1 | S5: 1 | T5: =$S5*$D$9 -> 27.46 | X5: x | Y5: x | Z5: x | AA5: x | AB5: x | AC5: x | AD5: x
B6: VAT: | C6: =IF($D$6="VAT INCLUDED",1.18,1)*(1-$Q6)*$C$1 -> 1 | D6: VAT EXCL. | G6: TRUE | I6: 6 | J6: =$Q114 -> 1 | K6: =$Q124 -> 1 | L6: =$Q134 -> 1 | M6: =$Q144 -> 1 | N6: =$Q154 -> 1 | O6: =$Q164 -> 1 | R6: ="E) " & IF($S6=0,"",ROUND($S6,2) & "-" & ROUND($T6/$D$9,2)) -> E) 1-1 | S6: 1 | T6: =$S6*$D$9 -> 27.46 | X6: x | Y6: x | Z6: x | AA6: x | AB6: x | AC6: x | AD6: x
B7: SAVED ON: | C7: =IF($D$6="VAT INCLUDED",1.18,1)*(1-$Q7)*$C$1 -> 1 | D7: 13.02.2025 | G7: TRUE | I7: 7 | J7: =$Q115 -> 1 | K7: =$Q125 -> 1 | L7: =$Q135 -> 1 | M7: =$Q145 -> 1 | N7: =$Q155 -> 1 | R7: ="F) " & IF($S7=0,"",ROUND($S7,2) & "-" & ROUND($T7/$D$9,2)) -> F) 1-1 | S7: 1 | T7: =$S7*$D$9 -> 27.46 | X7: x | Y7: x | Z7: x | AA7: x | AB7: x | AC7: x | AD7: x
B8: ESTIMATOR: | C8: =IF($D$6="VAT INCLUDED",1.18,1)*(1-$Q8)*$C$1 -> 1 | D8: T.Sammut | G8: TRUE | I8: 8 | J8: =$Q116 -> 1 | K8: =$Q126 -> 1 | L8: =$Q136 -> 1 | M8: =$Q146 -> 1 | N8: =$Q156 -> 1 | R8: ="G) " & IF($S8=0,"",ROUND($S8,2) & "-" & ROUND($T8/$D$9,2)) -> G) 1-1 | S8: 1 | T8: =$S8*$D$9 -> 27.46 | X8: x | Y8: x | Z8: x | AA8: x | AB8: x | AC8: x | AD8: x
B9: LAB. COST: | C9: =IF($D$6="VAT INCLUDED",1.18,1)*(1-$Q9)*$C$1 -> 1 | D9: 27.46 | G9: TRUE | I9: 9 | J9: =$Q117 -> 1 | K9: =$Q127 -> 1 | L9: =$Q137 -> 1 | M9: =$Q147 -> 1 | N9: =$Q157 -> 1 | R9: ="H) " & IF($S9=0,"",ROUND($S9,2) & "-" & ROUND($T9/$D$9,2)) -> H) 1-1 | S9: 1 | T9: =$S9*$D$9 -> 27.46 | X9: x | Y9: x | Z9: x | AA9: x | AB9: x | AC9: x | AD9: x
C10: =IF($D$6="VAT INCLUDED",1.18,1)*(1-$Q10)*$C$1 -> 1 | G10: TRUE | I10: 10 | J10: =$Q118 -> 1 | K10: =$Q128 -> 1 | L10: =$Q138 -> 1 | M10: =$Q148 -> 1 | N10: =$Q158 -> 1 | O10: =Q108 -> 1 | R10: =" I) " & IF($S10=0,"",ROUND($S10,2) & "-" & ROUND($T10/$D$9,2)) -> I) 1-1 | S10: 1 | T10: =$S10*$D$9 -> 27.46 | X10: x | Y10: x | Z10: x | AA10: x | AB10: x | AC10: x | AD10: x
C11: =IF($D$6="VAT INCLUDED",1.18,1)*(1-$Q11)*$C$1 -> 1 | R11: ="J) " & IF($S11=0,"",ROUND($S11,2) & "-" & ROUND($T11/$D$9,2)) -> J) 1-1 | S11: 1 | T11: =$S11*$D$9 -> 27.46 | X11: x | Y11: x | Z11: x | AA11: x | AB11: x | AC11: x | AD11: x
C12: =IF($D$6="VAT INCLUDED",1.18,1)*(1-$Q12)*$C$1 -> 1 | G12: SYSTEMS | H12: SYSTEMS | I12: SYSTEMS | J12: SYSTEMS | K12: SYSTEMS | L12: SYSTEMS | M12: SYSTEMS | N12: SYSTEMS | O12: SYSTEMS | P12: SYSTEMS | R12: MIXED - X,Y ) | S12: MAT MU | T12: LAB RATE | X12: x | Y12: x | Z12: x | AA12: x | AB12: x | AC12: x | AD12: x
B13: MATERIAL & LABOUR SUMMARY | G13: ItemCode | H13: CostCode | I13: MAKE | J13: PART_NO | K13: MARKUP | L13: TYPE | M13: LIST_P | N13: SET | O13: FIX | P13: DATE | Q13: %Dsct in BOQ | R13: MATMU-LABMU | S13: MAT CONT >> | T13: =SUM(Q108:Q164)/57 -> 1
B14: =IF($D$6<>"VAT EXCL.", "QUOTE ISSUED WITH VAT INCLUDED", "") | X14: x | Y14: x | Z14: x | AA14: x | AB14: x | AC14: x | AD14: x
Q15: =(C72-F35)/C72 -> 0 | R15: Average Discount applied in BOQ (Q2-Q12) | X15: x | Y15: x | Z15: x | AA15: x | AB15: x | AC15: x | AD15: x
B16: =IF($W$1<>"BOQ", "DIFF SET TO " & W1,"") | Q16: =(F35-E35)/F35 -> 0.59118043 | R16: Average Discount applied on Totals (Q23-Q32) | X16: x | Y16: x | Z16: x | AA16: x | AB16: x | AC16: x | AD16: x
Q17: =F74 -> 0.59118043 | R17: Overall Discount
B18: =IF(AND(G1,G2,G3,G4,G5,G6,G7,G8,G9,G10,H1)=TRUE, "", "CHECKLIST INCOMPLETE !" )
B19: =IF(ABS(SUM(A23:A32))>100,"[Discy A-J] are high, Check it out."," ") | Q19: =R83 -> 0.40883225 | R19: Overall Markup (Final Selling Excl.VAT/Total Cost )
E21: DISCOUNTED | F21: SELLING | Q21: % Discnt | R21: MATERIAL | T21: LABOUR
A22: Discy.A-J | B22: Markup/LRate | E22: ="SELLING " & $Q$1 -> SELLING € | F22: =$Q$1 -> € | G22: VAT/DISC | H22: MU | I22: LABRATE | J22: LABCOST | Q22: on Totals | R22: € | T22: Pair Hrs.
A23: =IF($F23=0,"",($F23/$C2)-($R23*$S2+$T23*$T2)) -> 0.0094 | B23: =IF(F23=0,"",IF(R23=0,"A) "&"---, "&ROUND(($F23/$C2-($R23*$S2))/$T23,2),IF(T23=0,"A) "&ROUND(($F23/$C2)/$R23,2),"A) "&ROUND(($F23/$C2-($T23*$T2))/$R23,2)&", " &ROUND(($F23/$C2-($R23*$S2))/$T23,2)))) -> A) 1, 27.46 | D23: =IF($F2="","",$F2) -> Electrical | F23: =Elec_Est!F2055 -> 47306.66 | G23: =C2 -> 1 | H23: =$S2 -> 1 | I23: =$T2 -> 27.46 | J23: =$D$9 -> 27.46 | R23: =Elec_Est!R2055 -> 30106.805 | T23: =Elec_Est!T2055 -> 626.36
A24: =IF($F24=0,"",($F24/$C3)-($R24*$S3+$T24*$T3)) -> -0.09 | B24: =IF(F24=0,"",IF(R24=0,"A) "&"---, "&ROUND(($F24/$C3-($R24*$S3))/$T24,2),IF(T24=0,"A) "&ROUND(($F24/$C3)/$R24,2),"A) "&ROUND(($F24/$C3-($T24*$T3))/$R24,2)&", " &ROUND(($F24/$C3-($R24*$S3))/$T24,2)))) -> A) 1, 27.46 | D24: =IF($F3="","",$F3) -> ECA | E24: =F24*(1-Q24) -> 32713.9 | F24: =Elec_Est!F2056 -> 32713.9 | G24: =C3 -> 1 | H24: =$S3 -> 1 | I24: =$T3 -> 27.46 | J24: =$D$9 -> 27.46 | R24: =Elec_Est!R2056 -> 29803.23 | T24: =Elec_Est!T2056 -> 106
A25: =IF($F25=0,"",($F25/$C4)-($R25*$S4+$T25*$T4)) -> 0.12 | B25: =IF(F25=0,"",IF(R25=0,"A) "&"---, "&ROUND(($F25/$C4-($R25*$S4))/$T25,2),IF(T25=0,"A) "&ROUND(($F25/$C4)/$R25,2),"A) "&ROUND(($F25/$C4-($T25*$T4))/$R25,2)&", " &ROUND(($F25/$C4-($R25*$S4))/$T25,2)))) -> #DIV/0! | D25: =IF($F4="","",$F4) | E25: =F25*(1-Q25) -> 0.12 | F25: =Elec_Est!F2057 -> 0.12 | G25: =C4 -> 1 | H25: =$S4 -> 1 | I25: =$T4 -> 27.46 | J25: =$D$9 -> 27.46 | R25: =Elec_Est!R2057 -> 0 | T25: =Elec_Est!T2057 -> 0
A26: =IF($F26=0,"",($F26/$C5)-($R26*$S5+$T26*$T5)) | B26: =IF(F26=0,"",IF(R26=0,"A) "&"---, "&ROUND(($F26/$C5-($R26*$S5))/$T26,2),IF(T26=0,"A) "&ROUND(($F26/$C5)/$R26,2),"A) "&ROUND(($F26/$C5-($T26*$T5))/$R26,2)&", " &ROUND(($F26/$C5-($R26*$S5))/$T26,2)))) | D26: =IF($F5="","",$F5) | E26: =F26*(1-Q26) -> 0 | F26: =Elec_Est!F2058 -> 0 | G26: =C5 -> 1 | H26: =$S5 -> 1 | I26: =$T5 -> 27.46 | J26: =$D$9 -> 27.46 | R26: =Elec_Est!R2058 -> 0 | T26: =Elec_Est!T2058 -> 0
A27: =IF($F27=0,"",($F27/$C6)-($R27*$S6+$T27*$T6)) | B27: =IF(F27=0,"",IF(R27=0,"A) "&"---, "&ROUND(($F27/$C6-($R27*$S6))/$T27,2),IF(T27=0,"A) "&ROUND(($F27/$C6)/$R27,2),"A) "&ROUND(($F27/$C6-($T27*$T6))/$R27,2)&", " &ROUND(($F27/$C6-($R27*$S6))/$T27,2)))) | D27: =IF($F6="","",$F6) | E27: =F27*(1-Q27) -> 0 | F27: =Elec_Est!F2059 -> 0 | G27: =C6 -> 1 | H27: =$S6 -> 1 | I27: =$T6 -> 27.46 | J27: =$D$9 -> 27.46 | R27: =Elec_Est!R2059 -> 0 | T27: =Elec_Est!T2059 -> 0
A28: =IF($F28=0,"",($F28/$C7)-($R28*$S7+$T28*$T7)) | B28: =IF(F28=0,"",IF(R28=0,"A) "&"---, "&ROUND(($F28/$C7-($R28*$S7))/$T28,2),IF(T28=0,"A) "&ROUND(($F28/$C7)/$R28,2),"A) "&ROUND(($F28/$C7-($T28*$T7))/$R28,2)&", " &ROUND(($F28/$C7-($R28*$S7))/$T28,2)))) | D28: =IF($F7="","",$F7) | E28: =F28*(1-Q28) -> 0 | F28: =Elec_Est!F2060 -> 0 | G28: =C7 -> 1 | H28: =$S7 -> 1 | I28: =$T7 -> 27.46 | J28: =$D$9 -> 27.46 | R28: =Elec_Est!R2060 -> 0 | T28: =Elec_Est!T2060 -> 0
A29: =IF($F29=0,"",($F29/$C8)-($R29*$S8+$T29*$T8)) | B29: =IF(F29=0,"",IF(R29=0,"A) "&"---, "&ROUND(($F29/$C8-($R29*$S8))/$T29,2),IF(T29=0,"A) "&ROUND(($F29/$C8)/$R29,2),"A) "&ROUND(($F29/$C8-($T29*$T8))/$R29,2)&", " &ROUND(($F29/$C8-($R29*$S8))/$T29,2)))) | D29: =IF($F8="","",$F8) | E29: =F29*(1-Q29) -> 0 | F29: =Elec_Est!F2061 -> 0 | G29: =C8 -> 1 | H29: =$S8 -> 1 | I29: =$T8 -> 27.46 | J29: =$D$9 -> 27.46 | R29: =Elec_Est!R2061 -> 0 | T29: =Elec_Est!T2061 -> 0
A30: =IF($F30=0,"",($F30/$C9)-($R30*$S9+$T30*$T9)) | B30: =IF(F30=0,"",IF(R30=0,"A) "&"---, "&ROUND(($F30/$C9-($R30*$S9))/$T30,2),IF(T30=0,"A) "&ROUND(($F30/$C9)/$R30,2),"A) "&ROUND(($F30/$C9-($T30*$T9))/$R30,2)&", " &ROUND(($F30/$C9-($R30*$S9))/$T30,2)))) | D30: =IF($F9="","",$F9) | E30: =F30*(1-Q30) -> 0 | F30: =Elec_Est!F2062 -> 0 | G30: =C9 -> 1 | H30: =$S9 -> 1 | I30: =$T9 -> 27.46 | J30: =$D$9 -> 27.46 | R30: =Elec_Est!R2062 -> 0 | T30: =Elec_Est!T2062 -> 0
A31: =IF($F31=0,"",($F31/$C10)-($R31*$S10+$T31*$T10)) | B31: =IF(F31=0,"",IF(R31=0,"A) "&"---, "&ROUND(($F31/$C10-($R31*$S10))/$T31,2),IF(T31=0,"A) "&ROUND(($F31/$C10)/$R31,2),"A) "&ROUND(($F31/$C10-($T31*$T10))/$R31,2)&", " &ROUND(($F31/$C10-($R31*$S10))/$T31,2)))) | D31: =IF($F10="","",$F10) | E31: =F31*(1-Q31) -> 0 | F31: =Elec_Est!F2063 -> 0 | G31: =C10 -> 1 | H31: =$S10 -> 1 | I31: =$T10 -> 27.46 | J31: =$D$9 -> 27.46 | R31: =Elec_Est!R2063 -> 0 | T31: =Elec_Est!T2063 -> 0
A32: =IF($F32=0,"",($F32/$C11)-($R32*$S11+$T32*$T11)) | B32: =IF(F32=0,"",IF(R32=0,"A) "&"---, "&ROUND(($F32/$C11-($R32*$S11))/$T32,2),IF(T32=0,"A) "&ROUND(($F32/$C11)/$R32,2),"A) "&ROUND(($F32/$C11-($T32*$T11))/$R32,2)&", " &ROUND(($F32/$C11-($R32*$S11))/$T32,2)))) | D32: =IF($F11="","",$F11) | E32: =F32*(1-Q32) -> 0 | F32: =Elec_Est!F2064 -> 0 | G32: =C11 -> 1 | H32: =$S11 -> 1 | I32: =$T11 -> 27.46 | J32: =$D$9 -> 27.46 | R32: =Elec_Est!R2064 -> 0 | T32: =Elec_Est!T2064 -> 0
C33: MIXED | W33: Mat Cost | X33: Lab Hours | Y33: Lab Hours
V34: HVAC | W34: =HVAC_BOQ!G514 -> 59910.04 | X34: =HVAC_BOQ!H514 -> 626.36 | Y34: =HVAC_BOQ!I514 -> 106
A35: Discy.L | B35: =E_BOQ!F56 -> 0 | E35: =SUM(E23:E32) -> 32714.02 | F35: =SUM(F23:F32) -> 80020.68 | R35: =SUM(R23:R32) -> 59910.035 | T35: =SUM(T23:T32) -> 732.36 | V35: Sprinklers
A36: =IF(A39=0,"0.00",A39-(A38*A37)) -> 0.00 | B36: BOQ TOTAL | E36: ="ESTIM TOTAL (" & $Q$1 & ")" -> ESTIM TOTAL (€) | V36: Plumbing
A37: 1.125 | B37: <1 Actual LabCont | R37: =R165 -> 59910.019 | S37: C.C.Totals | T37: =T165 -> 732.27167 | W37: =SUM(W34:W36) -> 59910.04 | X37: =SUM(X34:X36) -> 626.36 | Y37: =SUM(Y34:Y36) -> 106
B38: <2 Phrs @ 1.00
B39: <3 Phrs @ Actual | Q39: Discy.T >> | R39: =R37-R35 -> -0.0165 | S39: PRINT | T39: =T37-T35 -> -0.088333333
B41: Values Only on : | D41: 45701 | R41: 65637.555 | T41: 858.12
B42: Values Only on : | D42: 45757 | R42: 57581.675 | T42: 715.19 | U42: Rev A - Inverrters in VCPs
...

Sheet E_BOQ
A1: ITEM NO. | B1: DESCRIPTION | C1: QTY | D1: UNIT | E1: RATE | F1: TOTAL | G1: Mat Cost | H1: Lab Pair
A2: checkdesc | E2: € | F2: € | G2: € | H2: Hrs
B52: Page Total -
B54: Contract Discount -
A56: SB | B56: Discounted Page Total - | D56: =ML_Sum!D6 -> VAT EXCL. | E56: € | F56: =SUM(F3:F55) -> 0 | G56: =SUM(G3:G55) -> 0 | H56: =SUM(H3:H55) -> 0 | I56: =SUM(I3:I55) -> 0 | J56: =SUM(J3:J55) -> 0 | K56: =SUM(K3:K55) -> 0 | L56: =SUM(L3:L55) -> 0 | M56: =SUM(M3:M55) -> 0 | ... R56: =SUM(R3:R55) -> 0
A57: ITEM NO. | B57: DESCRIPTION | C57: QTY | D57: UNIT | E57: RATE | F57: TOTAL | G57: Mat Cost | H57: Lab Pair
E58: € | F58: € | G58: € | H58: Hrs
A112: SB | E112: System total - carried forward to summary page : | F112: =SUM(F59:F111) -> 0 | G112: =SUM(G51:G107) -> 0 | H112: =SUM(H51:H107) -> 0
A113: ITEM NO. | B113: DESCRIPTION | C113: QTY | D113: UNIT | E113: RATE | F113: TOTAL
E114: € | F114: €
A168: SB | E168: System total - carried forward to summary page : | F168: =SUM(F115:F167) -> 0
A169: ITEM NO. | B169: DESCRIPTION | C169: QTY | D169: UNIT | E169: RATE | F169: TOTAL
E170: € | F170: €
A224: SB | E224: System total - carried forward to summary page : | F224: =SUM(F171:F223) -> 0
A225: ITEM NO. | B225: DESCRIPTION | C225: QTY | D225: UNIT | E225: RATE | F225: TOTAL
E226: € | F226: €
A280: SB | E280: System total - carried forward to summary page : | F280: =SUM(F227:F279) -> 0
A281: ITEM NO. | B281: DESCRIPTION | C281: QTY | D281: UNIT | E281: RATE | F281: TOTAL
E282: € | F282: €
A337: SB | E337: System total - carried forward to summary page : | F337: =SUM(F283:F336) -> 0
A338: ITEM NO. | B338: DESCRIPTION | C338: QTY | D338: UNIT | E338: RATE | F338: TOTAL
E339: € | F339: €
A394: SB | E394: System total - carried forward to summary page : | F394: =SUM(F340:F393) -> 0
A395: ITEM NO. | B395: DESCRIPTION | C395: QTY | D395: UNIT | E395: RATE | F395: TOTAL
E396: € | F396: €
A451: SB | E451: System total - carried forward to summary page : | F451: =SUM(F397:F450) -> 0
A452: ITEM NO. | B452: DESCRIPTION | C452: QTY | D452: UNIT | E452: RATE | F452: TOTAL
E453: € | F453: €
A508: SB | E508: System total - carried forward to summary page : | F508: =SUM(F454:F507) -> 0
A509: ITEM NO. | B509: DESCRIPTION | C509: QTY | D509: UNIT | E509: RATE | F509: TOTAL
E510: € | F510: €
A565: SB | E565: System total - carried forward to summary page : | F565: =SUM(F511:F564) -> 0

Sheet E_DBOQ
A1: ITEM | B1: DESCRIPTION | C1: QTY | G1: UNIT | H1: RATE | I1: TOTAL | J1: Unit | K1: Total
C2: BOQ | D2: TDWG | E2: ACT | F2: DIFF | H2: € | I2: € | J2: Hrs | K2: Hrs
A54: SB | F54: System total - carried forward to summary page : | H54: VAT EXCL. | I54: =SUM(I3:I53) -> 0 | K54: =SUM(K3:K53) -> 0
A55: ITEM | B55: DESCRIPTION | C55: QTY | G55: UNIT | H55: RATE | I55: TOTAL | J55: Unit | K55: Total
C56: BOQ | D56: TDWG | E56: ACT | F56: DIFF | H56: € | I56: € | J56: Hrs | K56: Hrs
A111: SB | F111: System total - carried forward to summary page : | H111: VAT EXCL. | I111: =SUM(I57:I110) -> 0 | K111: =SUM(K57:K110) -> 0
A112: ITEM | B112: DESCRIPTION | C112: QTY | G112: UNIT | H112: RATE | I112: TOTAL | J112: Unit | K112: Total
C113: BOQ | D113: TDWG | E113: ACT | F113: DIFF | H113: € | I113: € | J113: Hrs | K113: Hrs
A168: SB | F168: System total - carried forward to summary page : | H168: VAT EXCL. | I168: =SUM(I114:I167) -> 0 | K168: =SUM(K114:K167) -> 0
A169: ITEM | B169: DESCRIPTION | C169: QTY | G169: UNIT | H169: RATE | I169: TOTAL | J169: Unit | K169: Total
C170: BOQ | D170: TDWG | E170: ACT | F170: DIFF | H170: € | I170: € | J170: Hrs | K170: Hrs
A225: SB | F225: System total - carried forward to summary page : | H225: VAT EXCL. | I225: =SUM(I171:I224) -> 0 | K225: =SUM(K171:K224) -> 0
A226: ITEM | B226: DESCRIPTION | C226: QTY | G226: UNIT | H226: RATE | I226: TOTAL | J226: Unit | K226: Total
C227: BOQ | D227: TDWG | E227: ACT | F227: DIFF | H227: € | I227: € | J227: Hrs | K227: Hrs
A282: SB | F282: System total - carried forward to summary page : | H282: VAT EXCL. | I282: =SUM(I228:I281) -> 0 | K282: =SUM(K228:K281) -> 0
A283: ITEM | B283: DESCRIPTION | C283: QTY | G283: UNIT | H283: RATE | I283: TOTAL | J283: Unit | K283: Total
C284: BOQ | D284: TDWG | E284: ACT | F284: DIFF | H284: € | I284: € | J284: Hrs | K284: Hrs
A339: SB | F339: System total - carried forward to summary page : | H339: VAT EXCL. | I339: =SUM(I285:I338) -> 0 | K339: =SUM(K285:K338) -> 0
A340: ITEM | B340: DESCRIPTION | C340: QTY | G340: UNIT | H340: RATE | I340: TOTAL | J340: Unit | K340: Total
C341: BOQ | D341: TDWG | E341: ACT | F341: DIFF | H341: € | I341: € | J341: Hrs | K341: Hrs
A396: SB | F396: System total - carried forward to summary page : | H396: VAT EXCL. | I396: =SUM(I342:I395) -> 0 | K396: =SUM(K342:K395) -> 0
