Workbook
Name Access_Control: #REF!
Name Access_Control: #REF!
Name Access_Control: #REF!
Name AREAS: ML_Sum!$X$1:$AD$16
Name AREAS: #REF!
Name AREAS: ML_Sum!$X$1:$AD$16
Name CCTV: #REF!
Name CCTV: #REF!
Name CCTV: #REF!
Name Commissioning: Elec_Est!#REF!
Name Commissioning: Old_Est!$A$1146
Name Commissioning: Elec_Est!#REF!
Name Data: #REF!
Name Data: #REF!
Name Data: #REF!
Name Electrical: Elec_Est!#REF!
Name Electrical: Old_Est!$A$16
Name Electrical: Elec_Est!#REF!
Name Fire_Alarm: #REF!
Name Fire_Alarm: #REF!
Name Fire_Alarm: #REF!
Name Fire_Barriers: Elec_Est!#REF!
Name Fire_Barriers: Old_Est!$A$1120
Name Fire_Barriers: Elec_Est!#REF!
Name FO: #REF!
Name FO: #REF!
Name FO: #REF!
Name Guard: #REF!
Name Guard: #REF!
Name Guard: #REF!
Name Intercom: #REF!
Name Intercom: #REF!
Name Intercom: #REF!
Name Intruder_Alarm: #REF!
Name Intruder_Alarm: #REF!
Name Intruder_Alarm: #REF!
Name Preliminaries: Old_Est!#REF!
Name Preliminaries: Elec_Est!#REF!

Sheet Notes
A1: NOTES | C1: Rev: 235
C2: checkdesc
A3: ELECTRICAL | C3: Elec_Rates
C4: Elec_Est
A5: Dist Boards | C5: Elv_Rates
A6: 1 | C6: ELV_Est
A7: 2 | C7: Ext_Quote
C8: Int_Quote
A9: Wiring Accessories | C9: Est_BOQ
A10: 1
A11: 2 | C11: Camilleri&Cuschieri Tenders
C12: Conduit
A13: ELV | C13: Wiring
C14: Supply
A15: Fire Alarm
A16: 1
A17: 2
A18: 3
A20: Data
A21: 1
A22: 2
A23: 3

Sheet ML_Sum
B1: CLIENT: | C1: 1 | D1: Eden Lesuire Group | G1: TRUE | H1: TRUE | I1: 1 | J1: =$Q109 -> 1 | K1: =$Q119 -> 1 | L1: =$Q129 -> 1 | M1: =$Q139 -> 1 | N1: =$Q149 -> 1 | O1: =$Q159 -> 1 | Q1: =IF(C1=1,"€","Curr?") -> € | R1: Recon /Lab.Cont >> | S1: =IF($S$39="PRINT","R","Do Not Print") -> R | T1: 1 | V1: {=IF(OR(X1=AREAS),1,0)} -> 1 | W1: BOQ | X1: x | Y1: x | Z1: x | AA1: x | AB1: x | AC1: x | AD1: x
B2: PROJECT: | C2: =IF($D$6="VAT INCLUDED",1.18,1)*(1-$Q2)*$C$1 -> 0.97379223 | D2: Intercontinental - Plant Retrofit | F2: Electrical | G2: TRUE | I2: 2 | J2: =$Q110 -> 1 | K2: =$Q120 -> 1 | L2: =$Q130 -> 1 | M2: =$Q140 -> 1 | N2: =$Q150 -> 1 | O2: =$Q160 -> 1 | Q2: 0.026207766 | R2: ="A) " & IF($S2=0,"",ROUND($S2,2) & "-" & ROUND($T2/$D$9,2)) -> A) 1.35-1.35 | S2: 1.35 | T2: =$S2*$D$9 -> 37.071 | U2: Mark up as advised by Alexei on 11/09.2025 | X2: x | Y2: x | Z2: x | AA2: x | AB2: x | AC2: x | AD2: x
B3: JOB DESC: | C3: =IF($D$6="VAT INCLUDED",1.18,1)*(1-$Q3)*$C$1 -> 0.97379223 | D3: Retrofitting works for the Electrical Installations | F3: ECA (Technician) | G3: TRUE | I3: 3 | J3: =$Q111 -> 1 | K3: =$Q121 -> 1 | L3: =$Q131 -> 1 | M3: =$Q141 -> 1 | N3: =$Q151 -> 1 | O3: =$Q161 -> 1 | Q3: 0.026207766 | R3: ="B) " & IF($S3=0,"",ROUND($S3,2) & "-" & ROUND($T3/$D$9,2)) -> B) 1.35-1.66 | S3: 1.35 | T3: =$S3*33.73 -> 45.5355 | U3: Mark up as advised by Alexei on 11/09.2026 | X3: x | Y3: x | Z3: x | AA3: x | AB3: x | AC3: x | AD3: x
B4: INT. QUOT No: | C4: =IF($D$6="VAT INCLUDED",1.18,1)*(1-$Q4)*$C$1 -> 0.97379223 | D4: EL25-0477 | F4: ECA (Engineer) | G4: TRUE | I4: 4 | J4: =$Q112 -> 1 | K4: =$Q122 -> 1 | L4: =$Q132 -> 1 | M4: =$Q142 -> 1 | N4: =$Q152 -> 1 | O4: =$Q162 -> 1 | Q4: 0.026207766 | R4: ="C) " & IF($S4=0,"",ROUND($S4,2) & "-" & ROUND($T4/$D$9,2)) -> C) 1.35-1.47 | S4: 1.35 | T4: =$S4*30 -> 40.5 | U4: Mark up as advised by Alexei on 11/09.2027 | X4: x | Y4: x | Z4: x | AA4: x | AB4: x | AC4: x | AD4: x
B5: CLIENTs REF: | C5: =IF($D$6="VAT INCLUDED",1.18,1)*(1-$Q5)*$C$1 -> 1 | D5: Tender | F5: Megaline | G5: TRUE | I5: 5 | J5: =$Q113 -> 1 | K5: =$Q123 -> 1 | L5: =$Q133 -> 1 | M5: =$Q143 -> 1 | N5: =$Q153 -> 1 | O5: =$Q163 -> 1 | R5: ="D) " & IF($S5=0,"",ROUND($S5,2) & "-" & ROUND($T5/$D$9,2)) -> D) 1-1.35 | S5: 1 | T5: =$S2*$D$9 -> 37.071 | X5: x | Y5: x | Z5: x | AA5: x | AB5: x | AC5: x | AD5: x
B6: VAT: | C6: =IF($D$6="VAT INCLUDED",1.18,1)*(1-$Q6)*$C$1 -> 1 | D6: VAT EXCL. | G6: TRUE | I6: 6 | J6: =$Q114 -> 1 | K6: =$Q124 -> 1 | L6: =$Q134 -> 1 | M6: =$Q144 -> 1 | N6: =$Q154 -> 1 | O6: =$Q164 -> 1 | R6: ="E) " & IF($S6=0,"",ROUND($S6,2) & "-" & ROUND($T6/$D$9,2)) -> E) | X6: x | Y6: x | Z6: x | AA6: x | AB6: x | AC6: x | AD6: x
B7: SAVED ON: | C7: =IF($D$6="VAT INCLUDED",1.18,1)*(1-$Q7)*$C$1 -> 1 | D7: 45866 | G7: TRUE | I7: 7 | J7: =$Q115 -> 1 | K7: =$Q125 -> 1 | L7: =$Q135 -> 1 | M7: =$Q145 -> 1 | N7: =$Q155 -> 1 | R7: ="F) " & IF($S7=0,"",ROUND($S7,2) & "-" & ROUND($T7/$D$9,2)) -> F) | X7: x | Y7: x | Z7: x | AA7: x | AB7: x | AC7: x | AD7: x
B8: ESTIMATOR: | C8: =IF($D$6="VAT INCLUDED",1.18,1)*(1-$Q8)*$C$1 -> 1 | D8: M.Scicluna | G8: TRUE | I8: 8 | J8: =$Q116 -> 1 | K8: =$Q126 -> 1 | L8: =$Q136 -> 1 | M8: =$Q146 -> 1 | N8: =$Q156 -> 1 | R8: ="G) " & IF($S8=0,"",ROUND($S8,2) & "-" & ROUND($T8/$D$9,2)) -> G) | X8: x | Y8: x | Z8: x | AA8: x | AB8: x | AC8: x | AD8: x
B9: LAB. COST: | C9: =IF($D$6="VAT INCLUDED",1.18,1)*(1-$Q9)*$C$1 -> 1 | D9: 27.46 | E9: Cost for 2025 | G9: TRUE | I9: 9 | J9: =$Q117 -> 1 | K9: =$Q127 -> 1 | L9: =$Q137 -> 1 | M9: =$Q147 -> 1 | N9: =$Q157 -> 1 | R9: ="H) " & IF($S9=0,"",ROUND($S9,2) & "-" & ROUND($T9/$D$9,2)) -> H) | X9: x | Y9: x | Z9: x | AA9: x | AB9: x | AC9: x | AD9: x
C10: =IF($D$6="VAT INCLUDED",1.18,1)*(1-$Q10)*$C$1 -> 1 | G10: TRUE | I10: 10 | J10: =$Q118 -> 1 | K10: =$Q128 -> 1 | L10: =$Q138 -> 1 | M10: =$Q148 -> 1 | N10: =$Q158 -> 1 | O10: =Q108 -> 1 | R10: =" I) " & IF($S10=0,"",ROUND($S10,2) & "-" & ROUND($T10/$D$9,2)) -> I) | X10: x | Y10: x | Z10: x | AA10: x | AB10: x | AC10: x | AD10: x
C11: =IF($D$6="VAT INCLUDED",1.18,1)*(1-$Q11)*$C$1 -> 1 | R11: ="J) " & IF($S11=0,"",ROUND($S11,2) & "-" & ROUND($T11/$D$9,2)) -> J) | X11: x | Y11: x | Z11: x | AA11: x | AB11: x | AC11: x | AD11: x
C12: =IF($D$6="VAT INCLUDED",1.18,1)*(1-$Q12)*$C$1 -> 0.97379223 | G12: SYSTEMS | H12: SYSTEMS | I12: SYSTEMS | J12: SYSTEMS | K12: SYSTEMS | L12: SYSTEMS | M12: SYSTEMS | N12: SYSTEMS | O12: SYSTEMS | P12: SYSTEMS | Q12: 0.026207766 | R12: MIXED - X,Y ) | S12: MAT MU | T12: LAB RATE | X12: x | Y12: x | Z12: x | AA12: x | AB12: x | AC12: x | AD12: x
B13: MATERIAL & LABOUR SUMMARY | G13: ItemCode | H13: CostCode | I13: MAKE | J13: PART_NO | K13: MARKUP | L13: TYPE | M13: LIST_P | N13: SET | O13: FIX | P13: DATE | Q13: %Dsct in BOQ | R13: MATMU-LABMU | S13: MAT CONT >> | T13: =SUM(Q108:Q164)/57 -> 1
B14: =IF($D$6<>"VAT EXCL.", "QUOTE ISSUED WITH VAT INCLUDED", "") | X14: x | Y14: x | Z14: x | AA14: x | AB14: x | AC14: x | AD14: x
Q15: =(C72-F35)/C72 -> 0.013791728 | R15: Average Discount applied in BOQ (Q2-Q12) | X15: x | Y15: x | Z15: x | AA15: x | AB15: x | AC15: x | AD15: x
B16: =IF($W$1<>"BOQ", "DIFF SET TO " & W1,"") | Q16: =(F35-E35)/F35 -> 0 | R16: Average Discount applied on Totals (Q23-Q32) | X16: x | Y16: x | Z16: x | AA16: x | AB16: x | AC16: x | AD16: x
Q17: =F74 -> 0.013791728 | R17: Overall Discount
B18: =IF(AND(G1,G2,G3,G4,G5,G6,G7,G8,G9,G10,H1)=TRUE, "", "CHECKLIST INCOMPLETE !" )
B19: =IF(ABS(SUM(A23:A32))>100,"[Discy A-J] are high, Check it out."," ") | Q19: =R83 -> 1.1482431 | R19: Overall Markup (Final Selling Excl.VAT/Total Cost )
E21: DISCOUNTED | F21: SELLING | Q21: % Discnt | R21: MATERIAL | T21: LABOUR
A22: Discy.A-J | B22: Markup/LRate | E22: ="SELLING " & $Q$1 -> SELLING € | F22: =$Q$1 -> € | G22: VAT/DISC | H22: MU | I22: LABRATE | J22: LABCOST | Q22: on Totals | R22: € | T22: Pair Hrs. | W22: Undiscounted values | AC22: Discounted Values
A23: =IF($F23=0,"",($F23/$C2)-($R23*$S2+$T23*$T2)) -> -0.0025902801 | B23: =IF(F23=0,"",IF(R23=0,"A) "&"---, "&ROUND(($F23/$C2-($R23*$S2))/$T23,2),IF(T23=0,"A) "&ROUND(($F23/$C2)/$R23,2),"A) "&ROUND(($F23/$C2-($T23*$T2))/$R23,2)&", " &ROUND(($F23/$C2-($R23*$S2))/$T23,2)))) -> A) 1.35, 37.07 | D23: =IF($F2="","",$F2) -> Electrical | E23: =F23*(1-Q23) -> 147372.97 | F23: =Elec_Est!F953 -> 147372.97 | G23: =C2 -> 0.97379223 | H23: =$S2 -> 1.35 | I23: =$T2 -> 37.071 | J23: =$D$9 -> 27.46 | R23: =Elec_Est!R953 -> 40888.73 | T23: =Elec_Est!T953 -> 2593.387 | W23: 151339.24 | X23: 151339.24 | Y23: 40888.73 | AA23: 2593.387 | AC23: =W23*C2 -> 147372.98
A24: =IF($F24=0,"",($F24/$C3)-($R24*$S3+$T24*$T3)) -> -0.007578436 | B24: =IF(F24=0,"",IF(R24=0,"A) "&"---, "&ROUND(($F24/$C3-($R24*$S3))/$T24,2),IF(T24=0,"A) "&ROUND(($F24/$C3)/$R24,2),"A) "&ROUND(($F24/$C3-($T24*$T3))/$R24,2)&", " &ROUND(($F24/$C3-($R24*$S3))/$T24,2)))) -> A) 1.35, 45.54 | D24: =IF($F3="","",$F3) -> ECA (Technician) | E24: =F24*(1-Q24) -> 42268.427 | F24: =Elec_Est!F954 -> 42268.427 | G24: =C3 -> 0.97379223 | H24: =$S3 -> 1.35 | I24: =$T3 -> 45.5355 | J24: =$D$9 -> 27.46 | R24: =Elec_Est!R954 -> 24878.05 | T24: =Elec_Est!T954 -> 215.67 | W24: 43406.01 | X24: 43406.01 | Y24: 24878.05 | AA24: 215.67 | AC24: =W24*C3 -> 42268.435
A25: =IF($F25=0,"",($F25/$C4)-($R25*$S4+$T25*$T4)) -> 0.004501782 | B25: =IF(F25=0,"",IF(R25=0,"A) "&"---, "&ROUND(($F25/$C4-($R25*$S4))/$T25,2),IF(T25=0,"A) "&ROUND(($F25/$C4)/$R25,2),"A) "&ROUND(($F25/$C4-($T25*$T4))/$R25,2)&", " &ROUND(($F25/$C4-($R25*$S4))/$T25,2)))) -> A) 1.35, 40.5 | D25: =IF($F4="","",$F4) -> ECA (Engineer) | E25: =F25*(1-Q25) -> 11447.054 | F25: =Elec_Est!F955 -> 11447.054 | G25: =C4 -> 0.97379223 | H25: =$S4 -> 1.35 | I25: =$T4 -> 40.5 | J25: =$D$9 -> 27.46 | R25: =Elec_Est!R955 -> 3000 | T25: =Elec_Est!T955 -> 190.25 | W25: 11755.13 | X25: 11755.13 | Y25: 3000 | AA25: 190.25 | AC25: =W25*C4 -> 11447.054
A26: =IF($F26=0,"",($F26/$C5)-($R26*$S5+$T26*$T5)) -> 0 | B26: =IF(F26=0,"",IF(R26=0,"A) "&"---, "&ROUND(($F26/$C5-($R26*$S5))/$T26,2),IF(T26=0,"A) "&ROUND(($F26/$C5)/$R26,2),"A) "&ROUND(($F26/$C5-($T26*$T5))/$R26,2)&", " &ROUND(($F26/$C5-($R26*$S5))/$T26,2)))) -> A) 1 | D26: =IF($F5="","",$F5) -> Megaline | E26: =F26*(1-Q26) -> 185902.47 | F26: =Elec_Est!F956 -> 185902.47 | G26: =C5 -> 1 | H26: =$S5 -> 1 | I26: =$T5 -> 37.071 | J26: =$D$9 -> 27.46 | R26: =Elec_Est!R956 -> 185902.47 | T26: =Elec_Est!T956 -> 0 | W26: 185902.47 | X26: 185902.47 | Y26: 185902.47 | AA26: 0 | AC26: =W26*C5 -> 185902.47
A27: =IF($F27=0,"",($F27/$C6)-($R27*$S6+$T27*$T6)) | B27: =IF(F27=0,"",IF(R27=0,"A) "&"---, "&ROUND(($F27/$C6-($R27*$S6))/$T27,2),IF(T27=0,"A) "&ROUND(($F27/$C6)/$R27,2),"A) "&ROUND(($F27/$C6-($T27*$T6))/$R27,2)&", " &ROUND(($F27/$C6-($R27*$S6))/$T27,2)))) | D27: =IF($F6="","",$F6) | E27: =F27*(1-Q27) -> 0 | F27: =Elec_Est!F957 -> 0 | G27: =C6 -> 1 | H27: =$S6 -> 0 | I27: =$T6 -> 0 | J27: =$D$9 -> 27.46 | R27: =Elec_Est!R957 -> 0 | T27: =Elec_Est!T957 -> 0 | W27: The above costs do not include Preliminaires, Fire stopping, commissioning and maintenance
A28: =IF($F28=0,"",($F28/$C7)-($R28*$S7+$T28*$T7)) | B28: =IF(F28=0,"",IF(R28=0,"A) "&"---, "&ROUND(($F28/$C7-($R28*$S7))/$T28,2),IF(T28=0,"A) "&ROUND(($F28/$C7)/$R28,2),"A) "&ROUND(($F28/$C7-($T28*$T7))/$R28,2)&", " &ROUND(($F28/$C7-($R28*$S7))/$T28,2)))) | D28: =IF($F7="","",$F7) | E28: =F28*(1-Q28) -> 0 | F28: =Elec_Est!F958 -> 0 | G28: =C7 -> 1 | H28: =$S7 -> 0 | I28: =$T7 -> 0 | J28: =$D$9 -> 27.46 | R28: =Elec_Est!R958 -> 0 | T28: =Elec_Est!T958 -> 0
A29: =IF($F29=0,"",($F29/$C8)-($R29*$S8+$T29*$T8)) | B29: =IF(F29=0,"",IF(R29=0,"A) "&"---, "&ROUND(($F29/$C8-($R29*$S8))/$T29,2),IF(T29=0,"A) "&ROUND(($F29/$C8)/$R29,2),"A) "&ROUND(($F29/$C8-($T29*$T8))/$R29,2)&", " &ROUND(($F29/$C8-($R29*$S8))/$T29,2)))) | D29: =IF($F8="","",$F8) | E29: =F29*(1-Q29) -> 0 | F29: =Elec_Est!F959 -> 0 | G29: =C8 -> 1 | H29: =$S8 -> 0 | I29: =$T8 -> 0 | J29: =$D$9 -> 27.46 | R29: =Elec_Est!R959 -> 0 | T29: =Elec_Est!T959 -> 0
A30: =IF($F30=0,"",($F30/$C9)-($R30*$S9+$T30*$T9)) | B30: =IF(F30=0,"",IF(R30=0,"A) "&"---, "&ROUND(($F30/$C9-($R30*$S9))/$T30,2),IF(T30=0,"A) "&ROUND(($F30/$C9)/$R30,2),"A) "&ROUND(($F30/$C9-($T30*$T9))/$R30,2)&", " &ROUND(($F30/$C9-($R30*$S9))/$T30,2)))) | D30: =IF($F9="","",$F9) | E30: =F30*(1-Q30) -> 0 | F30: =Elec_Est!F960 -> 0 | G30: =C9 -> 1 | H30: =$S9 -> 0 | I30: =$T9 -> 0 | J30: =$D$9 -> 27.46 | R30: =Elec_Est!R960 -> 0 | T30: =Elec_Est!T960 -> 0
A31: =IF($F31=0,"",($F31/$C10)-($R31*$S10+$T31*$T10)) | B31: =IF(F31=0,"",IF(R31=0,"A) "&"---, "&ROUND(($F31/$C10-($R31*$S10))/$T31,2),IF(T31=0,"A) "&ROUND(($F31/$C10)/$R31,2),"A) "&ROUND(($F31/$C10-($T31*$T10))/$R31,2)&", " &ROUND(($F31/$C10-($R31*$S10))/$T31,2)))) | D31: =IF($F10="","",$F10) | E31: =F31*(1-Q31) -> 0 | F31: =Elec_Est!F961 -> 0 | G31: =C10 -> 1 | H31: =$S10 -> 0 | I31: =$T10 -> 0 | J31: =$D$9 -> 27.46 | R31: =Elec_Est!R961 -> 0 | T31: =Elec_Est!T961 -> 0
A32: =IF($F32=0,"",($F32/$C11)-($R32*$S11+$T32*$T11)) | B32: =IF(F32=0,"",IF(R32=0,"A) "&"---, "&ROUND(($F32/$C11-($R32*$S11))/$T32,2),IF(T32=0,"A) "&ROUND(($F32/$C11)/$R32,2),"A) "&ROUND(($F32/$C11-($T32*$T11))/$R32,2)&", " &ROUND(($F32/$C11-($R32*$S11))/$T32,2)))) | D32: =IF($F11="","",$F11) | E32: =F32*(1-Q32) -> 0 | F32: =Elec_Est!F962 -> 0 | G32: =C11 -> 1 | H32: =$S11 -> 0 | I32: =$T11 -> 0 | J32: =$D$9 -> 27.46 | R32: =Elec_Est!R962 -> 0 | T32: =Elec_Est!T962 -> 0
C33: MIXED
A35: Discy.L | B35: ='SUMM PG '!H200 -> 386990.92 | E35: =SUM(E23:E32) -> 386990.92 | F35: =SUM(F23:F32) -> 386990.92 | R35: =SUM(R23:R32) -> 254669.25 | T35: =SUM(T23:T32) -> 2999.307
A36: =IF(A39=0,"0.00",A39-(A38*A37)) -> 0.00 | B36: BOQ TOTAL | E36: ="ESTIM TOTAL (" & $Q$1 & ")" -> ESTIM TOTAL (€)
A37: 1.125 | B37: <1 Actual LabCont | R37: =R165 -> 254667.68 | S37: C.C.Totals | T37: =T165 -> 2999.31
B38: <2 Phrs @ 1.00
B39: <3 Phrs @ Actual | Q39: Discy.T >> | R39: =R37-R35 -> -1.5711019 | S39: PRINT | T39: =T37-T35 -> 0.003
B41: Values Only on : | D41: 45911 | E41: 429609.01 | F41: 429609.01 | R41: 283529.33 | T41: 3027.307
B42: Values Only on : | D42: 45918 | E42: 431430.43 | F42: 431430.43 | R42: 283529.33 | T42: 3067.307 | U42: This includes 40 hours for the take over of the Trane controller as advised by Guy on 18.09.2025. This was submitted. It also includes preliminaries, fire stopping, commissioning and maintenance. These were transferred to ELM by Mech Div.
B43: Values Only on : | D43: 45930 | E43: 386990.92 | F43: 386990.92 | R43: 254669.25 | T43: 2999.307 | U43: As awarded excluding preliminaries, fire stopping, commissioning and maintenance.
...

Sheet Quote
A1: =IF(AND(UPPER(LEFT(TRIM($D$8),11))="01",UPPER(LEFT(TRIM($D$9),3))<>"ELM"),"PANTA RETAIL LTD.","PANTA CONTRACTING LIMITED") -> PANTA CONTRACTING LIMITED
A2: =IF(UPPER(LEFT(TRIM($D$9),3))="ELM","ELEC-FOR-MECH INTERNAL QUOTATION","ELECTRICAL INTERNAL QUOTATION") -> ELECTRICAL INTERNAL QUOTATION
B5: ATT: | D5: =IF(A2="Internal Quotation", "Mechanical Division","") | R5: Dated: | S5: =NOW() -> 46030.6
B6: CLIENT: | C6: Link to ML_SUM $D1 | D6: =ML_Sum!D1 -> Eden Lesuire Group
B7: PROJECT: | C7: Link to ML_SUM $D2 | D7: =ML_Sum!D2 -> Intercontinental - Plant Retrofit
B8: JOB DESC: | C8: Link to ML_SUM $D3 | D8: =ML_Sum!D3 -> Retrofitting works for the Electrical Installations
B9: QUOTE No: | C9: Link to ML_SUM $D4 | D9: =ML_Sum!D4 -> EL25-0477
B10: CLIENT's Ref: | C10: Link to ML_SUM $D5 | D10: =ML_Sum!D5 -> Tender
D22: Selling Price (€) : | E22: =ML_Sum!E35 -> 386990.92 | F22: =ML_Sum!D6 -> VAT EXCL. | G22: VAT EXCLUDED. | H22: VAT EXCLUDED. | I22: VAT EXCLUDED. | J22: VAT EXCLUDED. | K22: VAT EXCLUDED. | L22: VAT EXCLUDED. | M22: VAT EXCLUDED. | N22: VAT EXCLUDED. | O22: VAT EXCLUDED. | P22: VAT EXCLUDED.
A51: Signed for and on behalf of | Q51: Signed for and on behalf of
A52: Electrical Division | Q52: Division
Q54: Records
Q55: Mr. A. Sciberras
Q57: File

Sheet Elec_Rates
B1: CLIENT: | C1: =ML_Sum!$C1 -> 1 | D1: =ML_Sum!$D1 -> Eden Lesuire Group | F1: =ML_Sum!$F1 -> 0 | I1: 1 | J1: =ML_Sum!$J1 -> 1 | K1: =ML_Sum!$K1 -> 1 | L1: =ML_Sum!$L1 -> 1 | M1: =ML_Sum!$M1 -> 1 | N1: =ML_Sum!$N1 -> 1 | O1: =ML_Sum!$O1 -> 1 | Q1: =ML_Sum!$Q1 -> € | R1: R/Lab Cont | S1: =ML_Sum!$S1 -> R | T1: =ML_Sum!$T1 -> 1 | U1: =ML_Sum!W1 -> BOQ | V1: INCL | W1: MULT | X1: AREA | Y1: BOQ | Z1: TDWG | AA1: ACT | AB1: DIFF
B2: PROJECT: | C2: =ML_Sum!$C2 -> 0.97379223 | D2: =ML_Sum!$D2 -> Intercontinental - Plant Retrofit | F2: =ML_Sum!$F2 -> Electrical | I2: 2 | J2: =ML_Sum!$J2 -> 1 | K2: =ML_Sum!$K2 -> 1 | L2: =ML_Sum!$L2 -> 1 | M2: =ML_Sum!$M2 -> 1 | N2: =ML_Sum!$N2 -> 1 | O2: =ML_Sum!$O2 -> 1 | Q2: =ML_Sum!$Q2 -> 0.026207766 | R2: mu_A | S2: =ML_Sum!$S2 -> 1.35 | T2: =ML_Sum!$T2 -> 37.071
B3: JOB DESC: | C3: =ML_Sum!$C3 -> 0.97379223 | D3: =ML_Sum!$D3 -> Retrofitting works for the Electrical Installations | F3: =ML_Sum!$F3 -> ECA (Technician) | I3: 3 | J3: =ML_Sum!$J3 -> 1 | K3: =ML_Sum!$K3 -> 1 | L3: =ML_Sum!$L3 -> 1 | M3: =ML_Sum!$M3 -> 1 | N3: =ML_Sum!$N3 -> 1 | O3: =ML_Sum!$O3 -> 1 | Q3: =ML_Sum!$Q3 -> 0.026207766 | R3: mu_B | S3: =ML_Sum!$S3 -> 1.35 | T3: =ML_Sum!$T3 -> 45.5355
B4: QUOTE No: | C4: =ML_Sum!$C4 -> 0.97379223 | D4: =ML_Sum!$D4 -> EL25-0477 | F4: =ML_Sum!$F4 -> ECA (Engineer) | I4: 4 | J4: =ML_Sum!$J4 -> 1 | K4: =ML_Sum!$K4 -> 1 | L4: =ML_Sum!$L4 -> 1 | M4: =ML_Sum!$M4 -> 1 | N4: =ML_Sum!$N4 -> 1 | O4: =ML_Sum!$O4 -> 1 | Q4: =ML_Sum!$Q4 -> 0.026207766 | R4: mu_C | S4: =ML_Sum!$S4 -> 1.35 | T4: =ML_Sum!$T4 -> 40.5
B5: CLIENTs REF: | C5: =ML_Sum!$C5 -> 1 | D5: =ML_Sum!$D5 -> Tender | F5: =ML_Sum!$F5 -> Megaline | I5: 5 | J5: =ML_Sum!$J5 -> 1 | K5: =ML_Sum!$K5 -> 1 | L5: =ML_Sum!$L5 -> 1 | M5: =ML_Sum!$M5 -> 1 | N5: =ML_Sum!$N5 -> 1 | O5: =ML_Sum!$O5 -> 1 | Q5: =ML_Sum!$Q5 -> 0 | R5: mu_D | S5: =ML_Sum!$S5 -> 1 | T5: =ML_Sum!$T5 -> 37.071
B6: VAT/DUTIES: | C6: =ML_Sum!$C6 -> 1 | D6: =ML_Sum!$D6 -> VAT EXCL. | F6: =ML_Sum!$F6 -> 0 | I6: 6 | J6: =ML_Sum!$J6 -> 1 | K6: =ML_Sum!$K6 -> 1 | L6: =ML_Sum!$L6 -> 1 | M6: =ML_Sum!$M6 -> 1 | N6: =ML_Sum!$N6 -> 1 | O6: =ML_Sum!$O6 -> 1 | Q6: =ML_Sum!$Q6 -> 0 | R6: mu_E | S6: =ML_Sum!$S6 -> 0 | T6: =ML_Sum!$T6 -> 0
B7: SAVED ON: | C7: =ML_Sum!$C7 -> 1 | D7: 39364 | F7: =ML_Sum!$F7 -> 0 | I7: 7 | J7: =ML_Sum!$J7 -> 1 | K7: =ML_Sum!$K7 -> 1 | L7: =ML_Sum!$L7 -> 1 | M7: =ML_Sum!$M7 -> 1 | N7: =ML_Sum!$N7 -> 1 | O7: =ML_Sum!$O7 -> 0 | Q7: =ML_Sum!$Q7 -> 0 | R7: mu_F | S7: =ML_Sum!$S7 -> 0 | T7: =ML_Sum!$T7 -> 0
B8: ESTIMATOR: | C8: =ML_Sum!$C8 -> 1 | D8: =ML_Sum!$D8 -> M.Scicluna | F8: =ML_Sum!$F8 -> 0 | I8: 8 | J8: =ML_Sum!$J8 -> 1 | K8: =ML_Sum!$K8 -> 1 | L8: =ML_Sum!$L8 -> 1 | M8: =ML_Sum!$M8 -> 1 | N8: =ML_Sum!$N8 -> 1 | O8: =ML_Sum!$O8 -> 0 | Q8: =ML_Sum!$Q8 -> 0 | R8: mu_G | S8: =ML_Sum!$S8 -> 0 | T8: =ML_Sum!$T8 -> 0
B9: LABOUR RATE: | C9: =ML_Sum!$C9 -> 1 | D9: =ML_Sum!$D9 -> 27.46 | F9: =ML_Sum!$F9 -> 0 | I9: 9 | J9: =ML_Sum!$J9 -> 1 | K9: =ML_Sum!$K9 -> 1 | L9: =ML_Sum!$L9 -> 1 | M9: =ML_Sum!$M9 -> 1 | N9: =ML_Sum!$N9 -> 1 | O9: =ML_Sum!$O9 -> 0 | Q9: =ML_Sum!$Q9 -> 0 | R9: mu_H | S9: =ML_Sum!$S9 -> 0 | T9: =ML_Sum!$T9 -> 0
C10: =ML_Sum!$C10 -> 1 | F10: =ML_Sum!$F10 -> 0 | I10: 10 | J10: =ML_Sum!$J10 -> 1 | K10: =ML_Sum!$K10 -> 1 | L10: =ML_Sum!$L10 -> 1 | M10: =ML_Sum!$M10 -> 1 | N10: =ML_Sum!$N10 -> 1 | O10: =ML_Sum!$O10 -> 1 | Q10: =ML_Sum!$Q10 -> 0 | R10: mu_I | S10: =ML_Sum!$S10 -> 0 | T10: =ML_Sum!$T10 -> 0
C11: =ML_Sum!$C11 -> 1 | F11: =ML_Sum!$F11 -> 0 | Q11: =ML_Sum!$Q11 -> 0 | R11: mu_J | S11: =ML_Sum!$S11 -> 0 | T11: =ML_Sum!$T11 -> 0
C12: =ML_Sum!$C12 -> 0.97379223 | F12: =ML_Sum!$F12 -> 0 | Q12: =ML_Sum!$Q12 -> 0.026207766 | R12: MIXED | S12: =ML_Sum!$S12 -> MAT MU | T12: =ML_Sum!$T12 -> LAB RATE
G13: I_CODE | H13: C_CODE | I13: MAKE | J13: PART_NO | K13: MARKUP | L13: TYPE | M13: LIST_P | N13: P_FACT | O13: FIX | P13: DATE | Q13: %Dsct in BOQ | R13: MU TYPE | S13: MAT MU | T13: LAB RATE
K14: TB
C15: t | D15: Item:
D16: BMS points wiring
Q18: Multip
A19: 1 | B19: =Elec_Est!B1039 -> 202 | D19: 004# BMS point (Low level - Digital and Analogue) - Level 2 | K19: RATE | L19: RATE | Q19: =B19/A19 -> 202 | R19: =IF($B19=0,0,IF($S$1="R",ROUND(R28/$B19,2),R28/$B19)) -> 56.85 | T19: =IF($B19=0,0,IF($S$1="R",ROUND(T28/$B19,2),T28/$B19)) -> 4.39
D20: Based on: Level 2
A21: =$Q$19 *(7) -> 1414 | B21: m | D21: Conduit Galv. 20mm RATE | G21: COGV_011 | H21: 690 | I21: BAR | J21: 20mm | O21: 1 | P21: 34669 | Q21: 3.66 | R21: =$A21*Q21 -> 5175.24 | S21: =1.1 *(0.2) -> 0.22 | T21: =$A21*S21*$T$1 -> 311.08
A22: =$Q$19 *(35) -> 7070 | B22: m | D22: Indoor Screened 3c Cable 1.0mm | G22: CASP_018 | H22: 617 | I22: LAPP | J22: 110CY | O22: 2 | Q22: =0.62*1.25 -> 0.775 | R22: =$A22*Q22 -> 5479.25 | S22: =1.1 *(0.05) -> 0.055 | T22: =$A22*S22*$T$1 -> 388.85
A23: =$Q$19 *(2) -> 404 | B23: No | D23: Gland Skintop EExeII 16 x 1.0 (2-4core) | G23: CAAC_086 | H23: 620 | I23: (__) | O23: 2 | P23: 38148 | Q23: =1.1*1.5 -> 1.65 | R23: =$A23*Q23 -> 666.6 | S23: =1.1 *(0.1) -> 0.11 | T23: =$A23*S23*$T$1 -> 44.44
A24: =$Q$19 *(2) -> 404 | B24: No | D24: Cable Marker Wrap Around Type | G24: CAAC_025 | H24: 620 | I24: (__) | O24: 2 | Q24: 0.2 | R24: =$A24*Q24 -> 80.8 | S24: =1.1 *(0.03) -> 0.033 | T24: =$A24*S24*$T$1 -> 13.332
A25: =$Q$19 *(2*4) -> 1616 | B25: No | D25: Cable Lug 1.5 mm2 | G25: CAAC_004 | H25: 620 | I25: CTT | O25: 2 | P25: 34669 | Q25: 0.05 | R25: =$A25*Q25 -> 80.8 | S25: =1.1 *(0.01) -> 0.011 | T25: =$A25*S25*$T$1 -> 17.776
A26: =$Q$19 *(1) -> 202 | B26: No | D26: Labour to connect Mech Equip (FIX 3) | F26: Device | G26: LABO_009 | H26: 900 | I26: MISC | O26: 1 | R26: =$A26*Q26 -> 0 | S26: =1.1 *(0.5) -> 0.55 | T26: =$A26*S26*$T$1 -> 111.1 | U26: NoMat?
C27: << ==== TOTAL UNITS | R27: =$A27*Q27 -> 0 | T27: =$A27*S27*$T$1 -> 0
A28: d> | B28: =(R27+T27) -> 0 | D28: Sell_A | E28: =IF($B19=0,0,ROUND(ROUND(($R28*$S$2+($T28*$T$2))/$B19, 2)*$C$2,2)) -> 233.17 | F28: =ROUND($B19*$E28,2) -> 47100.34 | K28: ITEM | L28: ITEM | R28: =SUM(R20:R27) -> 11482.69 | T28: =SUM(T20:T27) -> 886.578
Q29: Multip
A30: 1 | B30: =Elec_Est!B1040 -> 72 | D30: 005# BMS point (High level Modbus RTU/BACnet) - Level 2 | K30: RATE | L30: RATE | Q30: =B30/A30 -> 72 | R30: =IF($B30=0,0,IF($S$1="R",ROUND(R40/$B30,2),R40/$B30)) -> 60.69 | T30: =IF($B30=0,0,IF($S$1="R",ROUND(T40/$B30,2),T40/$B30)) -> 4.29
D31: Based on: Level 2
A32: =$Q$30 *(10) -> 720 | B32: m | D32: Conduit Galv. 20mm RATE | G32: COGV_011 | H32: 690 | I32: BAR | J32: 20mm | O32: 1 | P32: 34669 | Q32: 3.66 | R32: =$A32*Q32 -> 2635.2 | S32: =1.1 *(0.2) -> 0.22 | T32: =$A32*S32*$T$1 -> 158.4
A33: =$Q$30 *(20) -> 1440 | B33: m | C33: =3000*1.1 -> 3300 | D33: Indoor Screened 2c Cable 1.0mm (MODBUS) | F33: See Working by Rinoy | G33: CASP_018 | H33: 617 | I33: LAPP | J33: 110CY | O33: 2 | Q33: =228/305*1.25 -> 0.93442623 | R33: =$A33*Q33 -> 1345.5738 | S33: =1.1 *(0.05) -> 0.055 | T33: =$A33*S33*$T$1 -> 79.2
A34: =$Q$30 *(25*1.2) -> 2160 | B34: No | D34: Cable Tie 225mm | G34: CONS_009 | H34: 875 | I34: (__) | O34: 1 | P34: 34669 | Q34: 0.05 | R34: =$A34*Q34 -> 108 | T34: =$A34*S34*$T$1 -> 0
A35: =$Q$30 *(2) -> 144 | B35: No | D35: Gland Skintop EExeII 16 x 1.0 (2-4core) | G35: CAAC_086 | H35: 620 | I35: (__) | O35: 2 | P35: 38148 | Q35: =1.1*1.5 -> 1.65 | R35: =$A35*Q35 -> 237.6 | S35: =1.1 *(0.15) -> 0.165 | T35: =$A35*S35*$T$1 -> 23.76
A36: =$Q$30 *(2) -> 144 | B36: No | D36: Cable Marker Wrap Around Type | G36: CAAC_025 | H36: 620 | I36: (__) | O36: 2 | Q36: 0.2 | R36: =$A36*Q36 -> 28.8 | S36: =1.1 *(0.03) -> 0.033 | T36: =$A36*S36*$T$1 -> 4.752
A37: =$Q$30 *(4) -> 288 | B37: No | D37: Cable Lug 1.5 mm2 | G37: CAAC_004 | H37: 620 | I37: CTT | O37: 2 | P37: 34669 | Q37: 0.05 | R37: =$A37*Q37 -> 14.4 | S37: =1.1 *(0.01) -> 0.011 | T37: =$A37*S37*$T$1 -> 3.168
A38: =$Q$30 *(1) -> 72 | B38: No | D38: Labour to connect Mech Equip (FIX 3) | F38: Device | G38: LABO_009 | H38: 900 | I38: MISC | O38: 1 | R38: =$A38*Q38 -> 0 | S38: =1.1 *(0.5) -> 0.55 | T38: =$A38*S38*$T$1 -> 39.6 | U38: NoMat?
C39: << ==== TOTAL UNITS | R39: =$A39*Q39 -> 0 | T39: =$A39*S39*$T$1 -> 0
A40: d> | B40: =(R39+T39) -> 0 | D40: Sell_A | E40: =IF($B30=0,0,ROUND(ROUND(($R40*$S$2+($T40*$T$2))/$B30, 2)*$C$2,2)) -> 234.64 | F40: =ROUND($B30*$E40,2) -> 16894.08 | K40: ITEM | L40: ITEM | R40: =SUM(R31:R39) -> 4369.5738 | T40: =SUM(T31:T39) -> 308.88
Q41: Multip
...

Sheet Elec_Est
B1: CLIENT: | C1: =ML_Sum!$C1 -> 1 | D1: =ML_Sum!$D1 -> Eden Lesuire Group | F1: =ML_Sum!$F1 -> 0 | I1: 1 | J1: =ML_Sum!$J1 -> 1 | K1: =ML_Sum!$K1 -> 1 | L1: =ML_Sum!$L1 -> 1 | M1: =ML_Sum!$M1 -> 1 | N1: =ML_Sum!$N1 -> 1 | O1: =ML_Sum!$O1 -> 1 | Q1: =ML_Sum!$Q1 -> € | R1: R/Lab Cont | S1: =ML_Sum!$S1 -> R | T1: =ML_Sum!$T1 -> 1 | U1: =ML_Sum!W1 -> BOQ | V1: INCL | W1: MULT | X1: AREA | Y1: BOQ | Z1: TDWG | AA1: ACT | AB1: DIFF
B2: PROJECT: | C2: =ML_Sum!$C2 -> 0.97379223 | D2: =ML_Sum!$D2 -> Intercontinental - Plant Retrofit | F2: =ML_Sum!$F2 -> Electrical | I2: 2 | J2: =ML_Sum!$J2 -> 1 | K2: =ML_Sum!$K2 -> 1 | L2: =ML_Sum!$L2 -> 1 | M2: =ML_Sum!$M2 -> 1 | N2: =ML_Sum!$N2 -> 1 | O2: =ML_Sum!$O2 -> 1 | Q2: =ML_Sum!$Q2 -> 0.026207766 | R2: mu_A | S2: =ML_Sum!$S2 -> 1.35 | T2: =ML_Sum!$T2 -> 37.071
B3: JOB DESC: | C3: =ML_Sum!$C3 -> 0.97379223 | D3: =ML_Sum!$D3 -> Retrofitting works for the Electrical Installations | F3: =ML_Sum!$F3 -> ECA (Technician) | I3: 3 | J3: =ML_Sum!$J3 -> 1 | K3: =ML_Sum!$K3 -> 1 | L3: =ML_Sum!$L3 -> 1 | M3: =ML_Sum!$M3 -> 1 | N3: =ML_Sum!$N3 -> 1 | O3: =ML_Sum!$O3 -> 1 | Q3: =ML_Sum!$Q3 -> 0.026207766 | R3: mu_B | S3: =ML_Sum!$S3 -> 1.35 | T3: =ML_Sum!$T3 -> 45.5355
B4: QUOTE No: | C4: =ML_Sum!$C4 -> 0.97379223 | D4: =ML_Sum!$D4 -> EL25-0477 | F4: =ML_Sum!$F4 -> ECA (Engineer) | I4: 4 | J4: =ML_Sum!$J4 -> 1 | K4: =ML_Sum!$K4 -> 1 | L4: =ML_Sum!$L4 -> 1 | M4: =ML_Sum!$M4 -> 1 | N4: =ML_Sum!$N4 -> 1 | O4: =ML_Sum!$O4 -> 1 | Q4: =ML_Sum!$Q4 -> 0.026207766 | R4: mu_C | S4: =ML_Sum!$S4 -> 1.35 | T4: =ML_Sum!$T4 -> 40.5
B5: CLIENTs REF: | C5: =ML_Sum!$C5 -> 1 | D5: =ML_Sum!$D5 -> Tender | F5: =ML_Sum!$F5 -> Megaline | I5: 5 | J5: =ML_Sum!$J5 -> 1 | K5: =ML_Sum!$K5 -> 1 | L5: =ML_Sum!$L5 -> 1 | M5: =ML_Sum!$M5 -> 1 | N5: =ML_Sum!$N5 -> 1 | O5: =ML_Sum!$O5 -> 1 | Q5: =ML_Sum!$Q5 -> 0 | R5: mu_D | S5: =ML_Sum!$S5 -> 1 | T5: =ML_Sum!$T5 -> 37.071
B6: VAT/DUTIES: | C6: =ML_Sum!$C6 -> 1 | D6: =ML_Sum!$D6 -> VAT EXCL. | F6: =ML_Sum!$F6 -> 0 | I6: 6 | J6: =ML_Sum!$J6 -> 1 | K6: =ML_Sum!$K6 -> 1 | L6: =ML_Sum!$L6 -> 1 | M6: =ML_Sum!$M6 -> 1 | N6: =ML_Sum!$N6 -> 1 | O6: =ML_Sum!$O6 -> 1 | Q6: =ML_Sum!$Q6 -> 0 | R6: mu_E | S6: =ML_Sum!$S6 -> 0 | T6: =ML_Sum!$T6 -> 0
B7: SAVED ON: | C7: =ML_Sum!$C7 -> 1 | D7: 39364 | F7: =ML_Sum!$F7 -> 0 | I7: 7 | J7: =ML_Sum!$J7 -> 1 | K7: =ML_Sum!$K7 -> 1 | L7: =ML_Sum!$L7 -> 1 | M7: =ML_Sum!$M7 -> 1 | N7: =ML_Sum!$N7 -> 1 | O7: =ML_Sum!$O7 -> 0 | Q7: =ML_Sum!$Q7 -> 0 | R7: mu_F | S7: =ML_Sum!$S7 -> 0 | T7: =ML_Sum!$T7 -> 0
B8: ESTIMATOR: | C8: =ML_Sum!$C8 -> 1 | D8: =ML_Sum!$D8 -> M.Scicluna | F8: =ML_Sum!$F8 -> 0 | I8: 8 | J8: =ML_Sum!$J8 -> 1 | K8: =ML_Sum!$K8 -> 1 | L8: =ML_Sum!$L8 -> 1 | M8: =ML_Sum!$M8 -> 1 | N8: =ML_Sum!$N8 -> 1 | O8: =ML_Sum!$O8 -> 0 | Q8: =ML_Sum!$Q8 -> 0 | R8: mu_G | S8: =ML_Sum!$S8 -> 0 | T8: =ML_Sum!$T8 -> 0
B9: LABOUR RATE: | C9: =ML_Sum!$C9 -> 1 | D9: =ML_Sum!$D9 -> 27.46 | F9: =ML_Sum!$F9 -> 0 | I9: 9 | J9: =ML_Sum!$J9 -> 1 | K9: =ML_Sum!$K9 -> 1 | L9: =ML_Sum!$L9 -> 1 | M9: =ML_Sum!$M9 -> 1 | N9: =ML_Sum!$N9 -> 1 | O9: =ML_Sum!$O9 -> 0 | Q9: =ML_Sum!$Q9 -> 0 | R9: mu_H | S9: =ML_Sum!$S9 -> 0 | T9: =ML_Sum!$T9 -> 0
C10: =ML_Sum!$C10 -> 1 | F10: =ML_Sum!$F10 -> 0 | I10: 10 | J10: =ML_Sum!$J10 -> 1 | K10: =ML_Sum!$K10 -> 1 | L10: =ML_Sum!$L10 -> 1 | M10: =ML_Sum!$M10 -> 1 | N10: =ML_Sum!$N10 -> 1 | O10: =ML_Sum!$O10 -> 1 | Q10: =ML_Sum!$Q10 -> 0 | R10: mu_I | S10: =ML_Sum!$S10 -> 0 | T10: =ML_Sum!$T10 -> 0
C11: =ML_Sum!$C11 -> 1 | F11: =ML_Sum!$F11 -> 0 | Q11: =ML_Sum!$Q11 -> 0 | R11: mu_J | S11: =ML_Sum!$S11 -> 0 | T11: =ML_Sum!$T11 -> 0
C12: =ML_Sum!$C12 -> 0.97379223 | F12: =ML_Sum!$F12 -> 0 | Q12: =ML_Sum!$Q12 -> 0.026207766 | R12: MIXED | S12: =ML_Sum!$S12 -> MAT MU | T12: =ML_Sum!$T12 -> LAB RATE
G13: ISELL | H13: C_CODE | I13: MAKE | J13: PART_NO | K13: MARKUP | L13: TYPE | M13: LIST_P | N13: P_FACT | O13: FIX | P13: DATE | Q13: %Dsct in BOQ | R13: MU TYPE | S13: MAT MU | T13: LAB RATE | AM13: Tot Mat Cost | AN13: Unit Lab phr. | AO13: Tot Lab phr. | AP13: < for ELM / MEE
K14: TB
C15: t
D16: MAIN ELECTRICAL INFRASTRUCTURE
K18: TB
C19: t
D20: SWITCHGEAR AND OTHER ACCESSORIES
K22: TB
C23: t | D23: Item: 1
D24: Supply only the following switchgear and other accessories.
E26: Sell Rate | F26: Sell Total | K26: IB | AG26: U_M_Sell | AH26: T_M_Sell | AI26: U_L_Sell | AJ26: T_L_Sell | AK26: Total_Sell | AM26: T_M_Cost | AN26: T_L_Phr | AO26: Mat/Lab=1
A27: 1 | B27: No. | D27: Item: 1.0a | E27: =IF(AND($A27=0,$A$1="DIF"),0, ROUND(ROUND(($R31*$S$5+($T31*$T$5))/$A27,2)*$C$5,2)) -> 989.85 | F27: =ROUND($A27*$E27,2) -> 989.85 | G27: ISELL | K27: mu_D | L27: ITEM | T27: =IF(AND($R31=0,$T31=0),"0.00","mu: "& ROUND(F27/$C$5/($R31+$T31*$D$9),2)) -> mu: 1 | AG27: =IF($E27=0,0,ROUND($R31*$S$5*$C$5/$A27,2)) -> 989.85 | AH27: =$AG27*$A27 -> 989.85 | AI27: =$E27-$AG27 -> 0 | AJ27: =$A27*$AI27 -> 0 | AK27: =ROUND(($AG27+$AI27)*$A27,2) -> 989.85 | AM27: =ROUND(R31,2) -> 989.85 | AN27: =ROUND(T31,2) -> 0 | AO27: =ROUND(AM27+AN27,2)*A27 -> 989.85
D28: Distribution Board DB-L2PR (metalclad enclosure) | K28: n
A29: 1 | B29: LS | D29: Subcontracting Works (Specify Contractor Name) | F29: Megaline | G29: SUBC_007 | H29: 960 | I29: MISC | O29: 4 | P29: 38594 | Q29: 989.85 | R29: =$A29*Q29 -> 989.85 | T29: =$A29*S29*$T$1 -> 0
R30: =$A30*Q30 -> 0 | T30: =$A30*S30*$T$1 -> 0
A31: d> | B31: =(R30+T30) -> 0 | G31: ICOST | K31: mu_D | L31: ITEM | R31: =SUM(R28:R30) -> 989.85 | T31: =SUM(T28:T30) -> 0
E32: Sell Rate | F32: Sell Total | K32: IB | AG32: U_M_Sell | AH32: T_M_Sell | AI32: U_L_Sell | AJ32: T_L_Sell | AK32: Total_Sell | AM32: T_M_Cost | AN32: T_L_Phr | AO32: Mat/Lab=1
A33: 1 | B33: No. | D33: Item: 1.0b | E33: =IF(AND($A33=0,$A$1="DIF"),0, ROUND(ROUND(($R37*$S$5+($T37*$T$5))/$A33,2)*$C$5,2)) -> 232.28 | F33: =ROUND($A33*$E33,2) -> 232.28 | G33: ISELL | K33: mu_D | L33: ITEM | T33: =IF(AND($R37=0,$T37=0),"0.00","mu: "& ROUND(F33/$C$5/($R37+$T37*$D$9),2)) -> mu: 1 | AG33: =IF($E33=0,0,ROUND($R37*$S$5*$C$5/$A33,2)) -> 232.28 | AH33: =$AG33*$A33 -> 232.28 | AI33: =$E33-$AG33 -> 0 | AJ33: =$A33*$AI33 -> 0 | AK33: =ROUND(($AG33+$AI33)*$A33,2) -> 232.28 | AM33: =ROUND(R37,2) -> 232.28 | AN33: =ROUND(T37,2) -> 0 | AO33: =ROUND(AM33+AN33,2)*A33 -> 232.28
D34: Equipotential earth bonding busbar EB1, rated at 600A or more, wall mounted to the wall on plastic insulators. (approx. 400mm x 50mm x 6mm).
A35: 1 | B35: LS | D35: Subcontracting Works (Specify Contractor Name) | F35: Megaline | G35: SUBC_007 | H35: 960 | I35: MISC | O35: 4 | P35: 38594 | Q35: 232.28 | R35: =$A35*Q35 -> 232.28 | T35: =$A35*S35*$T$1 -> 0
R36: =$A36*Q36 -> 0 | T36: =$A36*S36*$T$1 -> 0
A37: d> | B37: =(R36+T36) -> 0 | G37: ICOST | K37: mu_D | L37: ITEM | R37: =SUM(R34:R36) -> 232.28 | T37: =SUM(T34:T36) -> 0
K38: TB
C39: t | D39: Item: 2
D40: Install and connect only the following switchgear and other accessories.
E42: Sell Rate | F42: Sell Total | K42: IB | AG42: U_M_Sell | AH42: T_M_Sell | AI42: U_L_Sell | AJ42: T_L_Sell | AK42: Total_Sell | AM42: T_M_Cost | AN42: T_L_Phr | AO42: Mat/Lab=1
A43: 1 | B43: No. | D43: Item: 2.0a | E43: =IF(AND($A43=0,$A$1="DIF"),0, ROUND(ROUND(($R47*$S$5+($T47*$T$5))/$A43,2)*$C$5,2)) -> 343.15 | F43: =ROUND($A43*$E43,2) -> 343.15 | G43: ISELL | K43: mu_D | L43: ITEM | T43: =IF(AND($R47=0,$T47=0),"0.00","mu: "& ROUND(F43/$C$5/($R47+$T47*$D$9),2)) -> mu: 1 | AG43: =IF($E43=0,0,ROUND($R47*$S$5*$C$5/$A43,2)) -> 343.15 | AH43: =$AG43*$A43 -> 343.15 | AI43: =$E43-$AG43 -> 0 | AJ43: =$A43*$AI43 -> 0 | AK43: =ROUND(($AG43+$AI43)*$A43,2) -> 343.15 | AM43: =ROUND(R47,2) -> 343.15 | AN43: =ROUND(T47,2) -> 0 | AO43: =ROUND(AM43+AN43,2)*A43 -> 343.15
D44: Distribution Board DB-L2PR (metalclad enclosure) | K44: n
...

Sheet AsAwarded_Discount
A1: As awarded Estimate workings
A3: Electrical Estimate (Rev A) | B3: 392402.85 | C3: Excluding Prelims, Fire stopping, Commissioning and Maintenance
A4: Electrical (Megaline) | B4: =ML_Sum!R26 -> 185902.47
A5: Electrical less Megaline | B5: =B3-B4 -> 206500.38
A7: Quoted value including Mechanical | B7: 1792000.9 | C7: Excluding Maintenance and Provisional Sums
A8: 2.34% discount | B8: 42092.252 | C8: Value as per submitted BOQ
A9: Contract value less discount | B9: =B7-B8 -> 1749908.7
A13: Contract value less Megaline | B13: =B7-B4 -> 1606098.5
A14: 2.34% discount | B14: 42092.252
A15: Percentage discount on value less Megaline | B15: =B14/B13 -> 0.026207766

Sheet BMS_Points
B1: Qty | C1: Low Level points | D1: High level points | G1: DDC
C2: Per Unit | E2: Total
A3: Centralised Controller | B3: 1 | C3: 0 | D3: 1 | E3: =C3*B3 -> 0 | F3: =D3*B3 -> 1 | G3: 2
A4: EC Net Trends Alarms | B4: 1 | C4: 0 | D4: 1 | E4: =C4*B4 -> 0 | F4: =D4*B4 -> 1 | G4: 2
B5: 4 | C5: 0 | D5: 1 | E5: =C5*B5 -> 0 | F5: =D5*B5 -> 4 | G5: 2
A6: Pressurisation Units | B6: 3 | C6: 4 | D6: 1 | E6: =C6*B6 -> 12 | F6: =D6*B6 -> 3 | G6: 2
A7: Tanks | B7: 2 | C7: 3 | D7: 0 | E7: =C7*B7 -> 6 | F7: =D7*B7 -> 0 | G7: 2
A8: AC Unit | B8: 1 | C8: 4 | D8: 1 | E8: =C8*B8 -> 4 | F8: =D8*B8 -> 1 | G8: 2
A9: AHUs | B9: 26 | C9: 0 | D9: 1 | E9: =C9*B9 -> 0 | F9: =D9*B9 -> 26 | G9: 4
A10: Pump P301 | B10: 1 | C10: 4 | D10: 1 | E10: =C10*B10 -> 4 | F10: =D10*B10 -> 1 | G10: 4 | H10: BMS
A11: Pump P302 | B11: 1 | C11: 4 | D11: 1 | E11: =C11*B11 -> 4 | F11: =D11*B11 -> 1 | G11: 4 | H11: BMS
A12: Pump P303 | B12: 1 | C12: 4 | D12: 1 | E12: =C12*B12 -> 4 | F12: =D12*B12 -> 1 | G12: 4 | H12: BMS
A13: Pump P304 | B13: 1 | C13: 4 | D13: 1 | E13: =C13*B13 -> 4 | F13: =D13*B13 -> 1 | G13: 4 | H13: BMS
A14: Pump P305 | B14: 1 | C14: 4 | D14: 1 | E14: =C14*B14 -> 4 | F14: =D14*B14 -> 1 | G14: 4 | H14: BMS
A15: Pump P306 | B15: 1 | C15: 4 | D15: 1 | E15: =C15*B15 -> 4 | F15: =D15*B15 -> 1 | G15: 4 | H15: BMS
A16: Pump P307 | B16: 1 | C16: 4 | D16: 1 | E16: =C16*B16 -> 4 | F16: =D16*B16 -> 1 | G16: 4 | H16: BMS
A17: Pump P308 | B17: 1 | C17: 4 | D17: 1 | E17: =C17*B17 -> 4 | F17: =D17*B17 -> 1 | G17: 4 | H17: BMS
A18: Pump P309 | B18: 1 | C18: 4 | D18: 1 | E18: =C18*B18 -> 4 | F18: =D18*B18 -> 1 | G18: 4 | H18: BMS
A19: Pump P310 | B19: 1 | C19: 4 | D19: 1 | E19: =C19*B19 -> 4 | F19: =D19*B19 -> 1 | G19: 4 | H19: BMS
A20: Pump P401 | B20: 1 | C20: 4 | D20: 1 | E20: =C20*B20 -> 4 | F20: =D20*B20 -> 1 | G20: 4 | H20: BMS
A21: Pump P402 | B21: 1 | C21: 4 | D21: 1 | E21: =C21*B21 -> 4 | F21: =D21*B21 -> 1 | G21: 4 | H21: BMS
... A30: Temperature sensor | B30: 16 | C30: 1 | D30: 0 | E30: =C30*B30 -> 16 | F30: =D30*B30 -> 0 | G30: 2 | H30: Chillers C-1, C-2 and C-3
A31: Flow switch | B31: =20-14 -> 6 | C31: 1 | D31: 0 | E31: =C31*B31 -> 6 | F31: =D31*B31 -> 0 | G31: 2 | H31: Chillers C-1, C-2 and C-3
A32: Differnetial Pressure switch | B32: 14 | C32: 1 | D32: 0 | E32: =C32*B32 -> 14 | F32: =D32*B32 -> 0 | G32: 2 | H32: Chillers C-1, C-2 and C-3
A33: Valves | B33: 3 | C33: 2 | D33: 0 | E33: =C33*B33 -> 6 | F33: =D33*B33 -> 0 | G33: 2 | H33: Chillers C-1, C-2 and C-3
A34: Energy meters | B34: 6 | C34: 1 | D34: 1 | E34: =C34*B34 -> 6 | F34: =D34*B34 -> 6 | G34: 2 | H34: Chillers C-1, C-2 and C-3
A35: Temperature sensor | B35: 3 | C35: 1 | D35: 0 | E35: =C35*B35 -> 3 | F35: =D35*B35 -> 0 | G35: 2 | H35: Chiller C-4
A36: Flow switch | B36: =5-2 -> 3 | C36: 1 | D36: 0 | E36: =C36*B36 -> 3 | F36: =D36*B36 -> 0 | G36: 2 | H36: Chiller C-4
A37: Energy meters | B37: 1 | C37: 1 | D37: 1 | E37: =C37*B37 -> 1 | F37: =D37*B37 -> 1 | G37: 2 | H37: Chiller C-4
A38: Differnetial Pressure switch | B38: 2 | C38: 1 | D38: 0 | E38: =C38*B38 -> 2 | F38: =D38*B38 -> 0 | G38: 2 | H38: Chiller C-4
A39: Extract Fan EF/1 | B39: 1 | C39: 4 | D39: 1 | E39: =C39*B39 -> 4 | F39: =D39*B39 -> 1 | G39: 2
A40: Extract Fan EF/2 | B40: 1 | C40: 4 | D40: 1 | E40: =C40*B40 -> 4 | F40: =D40*B40 -> 1 | G40: 2
A41: Extract Fan EF/3 | B41: 1 | C41: 4 | D41: 1 | E41: =C41*B41 -> 4 | F41: =D41*B41 -> 1 | G41: 2
A42: Refrigerant Leakage control panel | B42: 1 | C42: 7 | D42: 1 | E42: =C42*B42 -> 7 | F42: =D42*B42 -> 1 | G42: 2
A43: 3way valves | B43: 12 | C43: 2 | D43: 2 | E43: =C43*B43 -> 24 | F43: =D43*B43 -> 24 | G43: 2
E48: =SUM(E3:E43) -> 202 | F48: =SUM(F3:F43) -> 91 | G48: =SUM(E48:F48) -> 293
E50: Low Level points | F50: High level points
D51: Level 2 | E51: =SUMIF(G3:G43,2,E3:E43) -> 122 | F51: =SUMIF(G3:G43,2,F3:F43) -> 45
D52: Level 4 | E52: =SUMIF(G3:G43,4,E3:E43) -> 80 | F52: =SUMIF(G3:G43,4,F3:F43) -> 46 | G52: =SUM(E51:F52) -> 293
A57: Tracer Points
...

Sheet Elec_BOQ
A1: BILL OF QUANTITIES
A2: ELECTRICAL INSTALLATION WORKS
A5: Item | C5: Qty | D5: Unit | E5: Rate in € | F5: Total
A7: T | B7: MAIN ELECTRICAL INFRASTRUCTURE
A9: T | B9: SWITCHGEAR AND OTHER ACCESSORIES
A11: 1T | B11: Supply only the following switchgear and other accessories.
A13: 1.0a | B13: Distribution Board DB-L2PR (metalclad enclosure) | C13: 1 | D13: No. | E13: =Elec_Est!E27 -> 989.85 | F13: =E13*C13 -> 989.85
A15: 1.0b | B15: Equipotential earth bonding busbar EB1, rated at 600A or more, wall mounted to the wall on plastic insulators. (approx. 400mm x 50mm x 6mm). | C15: 1 | D15: No. | E15: =Elec_Est!E33 -> 232.28 | F15: =E15*C15 -> 232.28
A18: 2T | B18: Install and connect only the following switchgear and other accessories.
A20: 2.0a | B20: Distribution Board DB-L2PR (metalclad enclosure) | C20: 1 | D20: No. | E20: =Elec_Est!E43 -> 343.15 | F20: =E20*C20 -> 343.15
A22: 2.0b | B22: Equipotential earth bonding busbar EB1, rated at 600A or more, wall mounted to the wall on plastic insulators. (approx. 400mm x 50mm x 6mm). | C22: 1 | D22: No. | E22: =Elec_Est!E49 -> 232.28 | F22: =E22*C22 -> 232.28
A25: T | B25: CABLE MANAGEMENT
A27: 3T | B27: Supply and install the following galvanized steel cable tray, from MSG-1 to SPB-PR in the new Plant Room. Cost is to include all cantilever bracketing to wall or suspension bracketing to the ceiling as necessary.
A28: 3.0a | B28: 500mm x 50mm. | C28: 155 | D28: m | E28: =Elec_Est!E63 -> 123.09 | F28: =E28*C28 -> 19078.95
A31: 4T | B31: Supply and install the following galvanized steel cable ladder above SPB-PR. Cost is to include all the support bracketing to wall or ceiling as necessary.
A33: 4.0a | B33: 500mm x 100mm. | C33: 4 | D33: m | E33: =Elec_Est!E73 -> 126.04 | F33: =E33*C33 -> 504.16
A49: P | B49: Total carried forward to summary page | F49: =SUM(F7:F47) -> 21380.67
A55: Item | C55: Qty | D55: Unit | E55: Rate in € | F55: Total
A57: T | B57: POWER CABLING
A59: 5T | B59: Supply, install and connect the following power cables. Cost is to include all cable installation and termination accessories as necessary. Cables installed on low level (less than 2.5 metres from FFL) cable trays are to be mechanically protected by cable tray covers.
A61: 5.0a | B61: 1600A MCCB in existing Main Switchgear Panel MSG-1 to the new Switchgear Panel SPB-PR (Plant Room).
B62: 6 x (5core x 120.0 mm2 FG16(0)M16). | C62: 160 | D62: mr | E62: =Elec_Est!E93 -> 745.77 | F62: =E62*C62 -> 119323.2
A64: 5.0b | B64: Switchgear Panel SPB-PR (Plant Room) to Motor Control Centre MCC-PR (Plant Room).
B65: 2 x (5core x 95.0 mm2 FG16(0)M16). | C65: 12 | D65: mr | E65: =Elec_Est!E99 -> 153.33 | F65: =E65*C65 -> 1839.96
A67: 5.0c | B67: Earth bar in Switchgear Panel SPB-PR (Plant Room) to Equipotential earth bonding busbar EB1.
B68: 2 x (1core x 95.0 mm2 LSZH/Cu). | C68: 5 | D68: mr | E68: =Elec_Est!E105 -> 69.3 | F68: =E68*C68 -> 346.5
A71: T | B71: LIGHTING INSTALLATION
A73: 6T | B73: Supply and install the following lighting points in the electrical switchroom for the Plant Room (PR), as specified. (Metalclad Installation)
A75: 6.0a | B75: Two lighting points controlled by one switch. | C75: 2 | D75: No. | E75: =Elec_Est!E119 -> 106.06 | F75: =E75*C75 -> 212.12
A77: 6.0b | B77: Non-maintained emergency lighting points (Fittings Type E4). | C77: 3 | D77: No. | E77: =Elec_Est!E125 -> 106.06 | F77: =E77*C77 -> 318.18
A80: 7T | B80: Supply only the following light fittings and accessories.
A82: 7.0a | B82: Type A | C82: 4 | D82: No. | E82: =Elec_Est!E135 -> 39.59 | F82: =E82*C82 -> 158.36
A84: 7.0b | B84: Type E4 | C84: 3 | D84: No. | E84: =Elec_Est!E141 -> 65.99 | F84: =E84*C84 -> 197.97
A87: 8T | B87: Install and connect only the following light fittings and accessories.
A89: 8.0a | B89: Type A | C89: 4 | D89: No. | E89: =Elec_Est!E151 -> 34.31 | F89: =E89*C89 -> 137.24
A91: 8.0b | B91: Type E4 | C91: 3 | D91: No. | E91: =Elec_Est!E157 -> 34.31 | F91: =E91*C91 -> 102.93
A98: P | B98: Total carried forward to summary page | F98: =SUM(F57:F96) -> 122636.46
A104: Item | C104: Qty | D104: Unit | E104: Rate in € | F104: Total
A106: T | B106: POWER INSTALLATION
A108: 9T | B108: Supply, install and connect the following power points. (Metalclad Installation)
...

Sheet Central_Controller_BOQ
A1: BILL OF QUANTITIES
A2: CENTRAL CONTROLLER
A5: Item | B5: Description | D5: Unit | E5: Qty | F5: Rate in € | G5: Total
A7: 1 | C7: Take delivery at site of Trane EPC Tracer SC+ control system procured by client, liaise with supplier, engineer, install and set to work all systems listed below and as described in the specifications. | D7: LS | E7: 1 | F7: =Elec_Est!E467 -> 1773.68 | G7: =F7*E7 -> 1773.68
C8: Controlled Items: -
C9: Chillers C-1, C-2 and C-3 - 3 x RTWD 170 HSE R1234ze (HMS Hydronic Multiple System)
C10: C-4 - 1 x GVWF 140 XSE R1234ze
C11: HTHP-1, HTHP-2, HTHP-3 - 3 x RTWF 125 HE R1234ze
C12: Primary circuits pumps
C13: Primary circuits valves
C15: Included in Trane Supply: -
C16: Tracer SC+ controller
C17: UC600 controller
C18: Tracer XM70 expansion modules
C19: TD7 display
C20: Probes
... C32: SWITCHGEAR AND OTHER ACCESSORIES
A34: =A7+1 -> 2 | C34: Supply and install the following switchgear and other accessories.
B36: a. | C36: Motor Control Centre MCC-PR (Pump Room) | D36: No. | E36: 1 | F36: =Elec_Est!E491 -> 8499.86 | G36: =E36*F36 -> 8499.86
C37: MCC-PR to include power and control section and all required wiring to interface with Trane EPC Tracer SC+ control system procured by client
C50: Total carried forward to summary page | G50: =SUM(G7:G48) -> 10273.54
A56: Item | B56: Description | D56: Unit | E56: Qty | F56: Rate in € | G56: Total
C58: POWER AND CONTROL CABLING FROM THE MOTOR CONTROL CENTRE (MCC)
A60: =A34+1 -> 3 | C60: Supply and install the following cables. Cost is to include all cable termination accessories where necessary.
B62: a. | C62: All the power cables from the Motor Control Centre MCC-PR (Pump Room) to all equipment being supplied power from MCC-PR (Refer to schedule) at Level 2. Cost is to include all the necessary metalclad cable management, local multi-pole maintenance isolators on floor brackets or to wall, next to the equipment and all cable termination accessories as necessary.
C64: Power supply cables, using XLPE/SWA/LSZH/Cu cables | D64: LS | E64: 1 | F64: =Elec_Est!E519 -> 15347.06 | G64: =F64*E64 -> 15347.06
B67: b. | C67: All the control cables from the Motor Control Centre MCC-PR (Pump Room) to all equipment being controlled by MCC-PR. Cost is to include all the necessary metalclad cable management.
C69: Control cables (where necessary), using multicore sheathed cables | D69: LS | E69: 1 | F69: =Elec_Est!Q737 -> Included with BMS
C98: Total carried forward to summary page | G98: =SUM(G58:G96) -> 15347.06

Sheet BMS_BOQ
A1: BILL OF QUANTITIES
A2: BUILDING MANAGEMENT SYSTEM
A5: Item | C5: Qty | D5: Unit | E5: Rate in € | F5: Total
A7: T | B7: Supply, deliver to site, install, test and commission the following as specified and as shown on the drawings, unless otherwise noted.
A12: T | B12: BMS Supervisor Software
A14: 1 | B14: Supply, Installation and configuration of the BMS supervisory software, complete with all the implementation of the UI and strategy into a complete solution as per tender document, schedules and BoQ requirements. | C14: 1 | D14: LS | E14: =Elec_Est!E773 -> 4452.57 | F14: =E14*C14 -> 4452.57
A17: T | B17: BMS Server
A19: =A14+1 -> 2 | B19: Supply, installation and configuration of the BMS Windows server. | C19: 1 | D19: LS | E19: =Elec_Est!E798 -> 4259.37 | F19: =E19*C19 -> 4259.37
A22: T | B22: Engineering IP Network
A24: =A19+1 -> 3 | B24: Design, supply and installation of a complete IP network that connects all the MCC's to the main BMS server and other third party systems | C24: 1 | D24: LS | E24: =Elec_Est!E818 -> 6299.5 | F24: =E24*C24 -> 6299.5
A27: T | B27: BMS Alarms
A29: =A24+1 -> 4 | B29: Design, and configuration of alarms per data point as required by project engineer. | C29: 1 | D29: LS | E29: =Elec_Est!E850 -> 2902.99 | F29: =E29*C29 -> 2902.99
A32: T | B32: BMS Trends
A34: =A29+1 -> 5 | B34: The configuration and upkeep of the trends and logs for all the project data points included in the project. | C34: 1 | D34: LS | E34: =Elec_Est!E869 -> 2267.64 | F34: =E34*C34 -> 2267.64
A37: T | B37: Complete working system
A39: =A34+1 -> 6 | B39: All wiring, containment, field devices etc. for a complete working systems | C39: 1 | D39: LS | E39: =Elec_Est!E888 -> 152433.92 | F39: =E39*C39 -> 152433.92
A50: P | B50: Total carried forward to summary page | F50: =SUM(F7:F48) -> 172615.99
A55: END!

Sheet SUMM PG 
A1: SUMMARY OF BILLS
F4: € | H4: €
A6: PRELIMINARIES
A8: Collection from page 2
A10: Collection from page 3 | H10: =SUM(F7:F10) -> 0
A13: ELECTRICAL INFRASTRUCTURE
A15: Collection from page 4 | F15: =Elec_BOQ!F49 -> 21380.67
A17: Collection from page 5 | F17: =Elec_BOQ!F98 -> 122636.46
A19: Collection from page 6 | F19: =Elec_BOQ!F150 -> 10327.91
A21: Collection from page 7 | F21: =Elec_BOQ!F187 -> 19003.54
A23: Collection from page 8 | F23: =Elec_BOQ!F222 -> 13763.91
A25: Collection from page 9 | F25: =Elec_BOQ!F269 -> 1641.84 | H25: =SUM(F15:F25) -> 188754.33 | J25: =Elec_Est!F458 -> 181972.18
A28: FIRE STOPPING
A30: Collection from page 10 | H30: =SUM(F30:G30) -> 0
A33: DISMANTLING EXISTING SERVICES
A35: Collection from page 11 | H35: =SUM(F35:G35) -> 0
A38: CHILLERS DISMANTLING
A40: Collection from page 12 | H40: =SUM(F40:G40) -> 0
A43: BOILERS DISMANTLING
A45: Collection from page 13 | H45: =SUM(F45:G45) -> 0
A48: CHILLERS NEW
A50: Collection from page 14
A52: Collection from page 15
A54: Collection from page 16
A56: Collection from page 17
A58: Collection from page 18
A60: Collection from page 19
A62: Collection from page 20
A64: Collection from page 21
A66: Collection from page 22 | H66: =SUM(F50:F66) -> 0
A69: HTHP NEW
A71: Collection from page 23
A73: Collection from page 24
A75: Collection from page 25
A77: Collection from page 26
A79: Collection from page 27
A81: Collection from page 28
A83: Collection from page 29 | H83: =SUM(F71:F83) -> 0
A86: PUMPS DISMANTLING
A88: Collection from page 30
...

Sheet Old_Est
B1: CLIENT: | C1: =ML_Sum!$C1 -> 1 | D1: =ML_Sum!$D1 -> Eden Lesuire Group | F1: =ML_Sum!$F1 -> 0 | I1: 1 | J1: =ML_Sum!$J1 -> 1 | K1: =ML_Sum!$K1 -> 1 | L1: =ML_Sum!$L1 -> 1 | M1: =ML_Sum!$M1 -> 1 | N1: =ML_Sum!$N1 -> 1 | O1: =ML_Sum!$O1 -> 1 | Q1: =ML_Sum!$Q1 -> € | R1: R/Lab Cont | S1: =ML_Sum!$S1 -> R | T1: =ML_Sum!$T1 -> 1 | U1: =ML_Sum!W1 -> BOQ | V1: INCL | W1: MULT | X1: AREA | Y1: BOQ | Z1: TDWG | AA1: ACT | AB1: DIFF
B2: PROJECT: | C2: =ML_Sum!$C2 -> 0.97379223 | D2: =ML_Sum!$D2 -> Intercontinental - Plant Retrofit | F2: =ML_Sum!$F2 -> Electrical | I2: 2 | J2: =ML_Sum!$J2 -> 1 | K2: =ML_Sum!$K2 -> 1 | L2: =ML_Sum!$L2 -> 1 | M2: =ML_Sum!$M2 -> 1 | N2: =ML_Sum!$N2 -> 1 | O2: =ML_Sum!$O2 -> 1 | Q2: =ML_Sum!$Q2 -> 0.026207766 | R2: mu_A | S2: =ML_Sum!$S2 -> 1.35 | T2: =ML_Sum!$T2 -> 37.071
B3: JOB DESC: | C3: =ML_Sum!$C3 -> 0.97379223 | D3: =ML_Sum!$D3 -> Retrofitting works for the Electrical Installations | F3: =ML_Sum!$F3 -> ECA (Technician) | I3: 3 | J3: =ML_Sum!$J3 -> 1 | K3: =ML_Sum!$K3 -> 1 | L3: =ML_Sum!$L3 -> 1 | M3: =ML_Sum!$M3 -> 1 | N3: =ML_Sum!$N3 -> 1 | O3: =ML_Sum!$O3 -> 1 | Q3: =ML_Sum!$Q3 -> 0.026207766 | R3: mu_B | S3: =ML_Sum!$S3 -> 1.35 | T3: =ML_Sum!$T3 -> 45.5355
B4: QUOTE No: | C4: =ML_Sum!$C4 -> 0.97379223 | D4: =ML_Sum!$D4 -> EL25-0477 | F4: =ML_Sum!$F4 -> ECA (Engineer) | I4: 4 | J4: =ML_Sum!$J4 -> 1 | K4: =ML_Sum!$K4 -> 1 | L4: =ML_Sum!$L4 -> 1 | M4: =ML_Sum!$M4 -> 1 | N4: =ML_Sum!$N4 -> 1 | O4: =ML_Sum!$O4 -> 1 | Q4: =ML_Sum!$Q4 -> 0.026207766 | R4: mu_C | S4: =ML_Sum!$S4 -> 1.35 | T4: =ML_Sum!$T4 -> 40.5
B5: CLIENTs REF: | C5: =ML_Sum!$C5 -> 1 | D5: =ML_Sum!$D5 -> Tender | F5: =ML_Sum!$F5 -> Megaline | I5: 5 | J5: =ML_Sum!$J5 -> 1 | K5: =ML_Sum!$K5 -> 1 | L5: =ML_Sum!$L5 -> 1 | M5: =ML_Sum!$M5 -> 1 | N5: =ML_Sum!$N5 -> 1 | O5: =ML_Sum!$O5 -> 1 | Q5: =ML_Sum!$Q5 -> 0 | R5: mu_D | S5: =ML_Sum!$S5 -> 1 | T5: =ML_Sum!$T5 -> 37.071
B6: VAT/DUTIES: | C6: =ML_Sum!$C6 -> 1 | D6: =ML_Sum!$D6 -> VAT EXCL. | F6: =ML_Sum!$F6 -> 0 | I6: 6 | J6: =ML_Sum!$J6 -> 1 | K6: =ML_Sum!$K6 -> 1 | L6: =ML_Sum!$L6 -> 1 | M6: =ML_Sum!$M6 -> 1 | N6: =ML_Sum!$N6 -> 1 | O6: =ML_Sum!$O6 -> 1 | Q6: =ML_Sum!$Q6 -> 0 | R6: mu_E | S6: =ML_Sum!$S6 -> 0 | T6: =ML_Sum!$T6 -> 0
B7: SAVED ON: | C7: =ML_Sum!$C7 -> 1 | D7: 39364 | F7: =ML_Sum!$F7 -> 0 | I7: 7 | J7: =ML_Sum!$J7 -> 1 | K7: =ML_Sum!$K7 -> 1 | L7: =ML_Sum!$L7 -> 1 | M7: =ML_Sum!$M7 -> 1 | N7: =ML_Sum!$N7 -> 1 | O7: =ML_Sum!$O7 -> 0 | Q7: =ML_Sum!$Q7 -> 0 | R7: mu_F | S7: =ML_Sum!$S7 -> 0 | T7: =ML_Sum!$T7 -> 0
B8: ESTIMATOR: | C8: =ML_Sum!$C8 -> 1 | D8: =ML_Sum!$D8 -> M.Scicluna | F8: =ML_Sum!$F8 -> 0 | I8: 8 | J8: =ML_Sum!$J8 -> 1 | K8: =ML_Sum!$K8 -> 1 | L8: =ML_Sum!$L8 -> 1 | M8: =ML_Sum!$M8 -> 1 | N8: =ML_Sum!$N8 -> 1 | O8: =ML_Sum!$O8 -> 0 | Q8: =ML_Sum!$Q8 -> 0 | R8: mu_G | S8: =ML_Sum!$S8 -> 0 | T8: =ML_Sum!$T8 -> 0
B9: LABOUR RATE: | C9: =ML_Sum!$C9 -> 1 | D9: =ML_Sum!$D9 -> 27.46 | F9: =ML_Sum!$F9 -> 0 | I9: 9 | J9: =ML_Sum!$J9 -> 1 | K9: =ML_Sum!$K9 -> 1 | L9: =ML_Sum!$L9 -> 1 | M9: =ML_Sum!$M9 -> 1 | N9: =ML_Sum!$N9 -> 1 | O9: =ML_Sum!$O9 -> 0 | Q9: =ML_Sum!$Q9 -> 0 | R9: mu_H | S9: =ML_Sum!$S9 -> 0 | T9: =ML_Sum!$T9 -> 0
C10: =ML_Sum!$C10 -> 1 | F10: =ML_Sum!$F10 -> 0 | I10: 10 | J10: =ML_Sum!$J10 -> 1 | K10: =ML_Sum!$K10 -> 1 | L10: =ML_Sum!$L10 -> 1 | M10: =ML_Sum!$M10 -> 1 | N10: =ML_Sum!$N10 -> 1 | O10: =ML_Sum!$O10 -> 1 | Q10: =ML_Sum!$Q10 -> 0 | R10: mu_I | S10: =ML_Sum!$S10 -> 0 | T10: =ML_Sum!$T10 -> 0
C11: =ML_Sum!$C11 -> 1 | F11: =ML_Sum!$F11 -> 0 | Q11: =ML_Sum!$Q11 -> 0 | R11: mu_J | S11: =ML_Sum!$S11 -> 0 | T11: =ML_Sum!$T11 -> 0
C12: =ML_Sum!$C12 -> 0.97379223 | F12: =ML_Sum!$F12 -> 0 | Q12: =ML_Sum!$Q12 -> 0.026207766 | R12: MIXED | S12: =ML_Sum!$S12 -> MAT MU | T12: =ML_Sum!$T12 -> LAB RATE
G13: ISELL | H13: C_CODE | I13: MAKE | J13: PART_NO | K13: MARKUP | L13: TYPE | M13: LIST_P | N13: P_FACT | O13: FIX | P13: DATE | Q13: %Dsct in BOQ | R13: MU TYPE | S13: MAT MU | T13: LAB RATE | AM13: Tot Mat Cost | AN13: Unit Lab phr. | AO13: Tot Lab phr. | AP13: < for ELM / MEE
K14: TB
C15: t | D15: Item:
D16: Electrical
K18: TB
C19: t
D20: MODIFICATIONS TO THE EXISTING MAIN SWITCHGEAR AND OTHER PANELS
K22: TB
C23: t
D24: Supply, install and connect the following switchgear and other accessories, to achieve a complete and fully functional works package.
E26: Sell Rate | F26: Sell Total | K26: IB | AG26: U_M_Sell | AH26: T_M_Sell | AI26: U_L_Sell | AJ26: T_L_Sell | AK26: Total_Sell | AM26: T_M_Cost | AN26: T_L_Phr | AO26: Mat/Lab=1
A27: 1 | B27: LS | D27: Item: 1.0a | E27: =IF(AND($A27=0,$A$1="DIF"),0, ROUND(ROUND(($R33*$S$2+($T33*$T$2))/A27,2)*$C$2,2)) -> 420.26 | F27: =ROUND($A27*$E27,2) -> 420.26 | G27: ISELL | K27: mu_A | L27: ITEM | T27: =IF(AND($R33=0,$T33=0),"0.00","mu :" & ROUND($F27/$C$2/($R33+$T33*$D$9),2)) -> mu :1.35 | AG27: =IF($E27=0,0,ROUND($R33*$S$2*$C$2/$A27,2)) -> 131.46 | AH27: =$AG27*$A27 -> 131.46 | AI27: =$E27-$AG27 -> 288.8 | AJ27: =$A27*$AI27 -> 288.8 | AK27: =ROUND(($AG27+$AI27)*$A27,2) -> 420.26 | AM27: =ROUND(R33,2) -> 100 | AN27: =ROUND(T33,2) -> 8 | AO27: =ROUND(AM27+AN27,2)*A27 -> 108
D28: 1250A TPN (4-pole) MCCB, fixed-mounting type, complete within an extension column to the existing Main Switchgear Panel MSG-1, as specified.
A29: 1 | B29: No | D29: Switchgear Arrangement Custom__1 | F29: 1250Amp 4pole MCCB | G29: SWLV_221 | H29: 510 | I29: (__) | K29: 11001 | O29: 2 | R29: =$A29*Q29 -> 0 | T29: =$A29*S29*$T$1 -> 0
A30: 1 | B30: No | D30: Erection Material | G30: EMAT_063 | H30: 501 | I30: (__) | K30: 01-002 | O30: 1 | Q30: 100 | R30: =$A30*Q30 -> 100 | T30: =$A30*S30*$T$1 -> 0
A31: 1 | B31: No | D31: Labour only (FIX 3) | G31: LABO_007 | H31: 900 | I31: MISC | O31: 3 | R31: =$A31*Q31 -> 0 | S31: 8 | T31: =$A31*S31*$T$1 -> 8
R32: =$A32*Q32 -> 0 | T32: =$A32*S32*$T$1 -> 0
A33: d> | B33: =(R32+T32) -> 0 | G33: ICOST | K33: mu_A | L33: ITEM | R33: =SUM(R28:R32) -> 100 | T33: =SUM(T28:T32) -> 8
E34: Sell Rate | K34: IB | AG34: U_M_Sell | AI34: U_L_Sell | AM34: T_M_Cost | AN34: T_L_Phr | AO34: Mat/Lab=1
A35: 1 | B35: LS | D35: Item: 1.0b | E35: =IF(AND($A35=0,$A$1="DIF"),0, ROUND(ROUND(($R41*$S$2+($T41*$T$2))/A35,2)*$C$2,2)) -> 420.26 | G35: ISELL | K35: BRATE | L35: ITEM | T35: =IF(AND($R41=0,$T41=0),"0.00","mu :" & ROUND($A35*$E35/$C$2/($R41+$T41*$D$9),2)) -> mu :1.35 | AG35: =IF($E35=0,0,ROUND($R41*$S$2*$C$2/$A35,2)) -> 131.46 | AI35: =$E35-$AG35 -> 288.8 | AM35: =ROUND(R41,2) -> 100 | AN35: =ROUND(T41,2) -> 8 | AO35: =ROUND(AM35+AN35,2)*A35 -> 108
D36: 1250A TPN (4-pole) MCCB, withdrawable-mounting type, complete within an extension column to the existing Main Switchgear Panel MSG-1, as specified. (Option)
A37: 1 | B37: No | D37: Switchgear Arrangement Custom__1 | E37: RATE_ONLY | F37: 1250Amp 4pole MCCB | G37: SWLV_221 | H37: RTONLY | I37: (__) | K37: 11001 | L37: RTONLY | O37: 2 | R37: =$A37*Q37 -> 0 | T37: =$A37*S37*$T$1 -> 0
A38: 1 | B38: No | D38: Erection Material | E38: RATE_ONLY | G38: EMAT_063 | H38: RTONLY | I38: (__) | K38: 01-002 | L38: RTONLY | O38: 1 | Q38: 100 | R38: =$A38*Q38 -> 100 | T38: =$A38*S38*$T$1 -> 0
A39: 1 | B39: No | D39: Labour only (FIX 3) | E39: RATE_ONLY | G39: LABO_007 | H39: RTONLY | I39: MISC | L39: RTONLY | O39: 3 | R39: =$A39*Q39 -> 0 | S39: 8 | T39: =$A39*S39*$T$1 -> 8
R40: =$A40*Q40 -> 0 | T40: =$A40*S40*$T$1 -> 0
A41: d> | B41: =(R40+T40) -> 0 | G41: ICOST | L41: BRATE | R41: =SUM(R36:R40) -> 100 | T41: =SUM(T36:T40) -> 8
E42: Sell Rate | F42: Sell Total | K42: IB | AG42: U_M_Sell | AH42: T_M_Sell | AI42: U_L_Sell | AJ42: T_L_Sell | AK42: Total_Sell | AM42: T_M_Cost | AN42: T_L_Phr | AO42: Mat/Lab=1
A43: 1 | B43: LS | D43: Item: 2.0a | E43: =IF(AND($A43=0,$A$1="DIF"),0, ROUND(ROUND(($R49*$S$2+($T49*$T$2))/A43,2)*$C$2,2)) -> 420.26 | F43: =ROUND($A43*$E43,2) -> 420.26 | G43: ISELL | K43: mu_A | L43: ITEM | T43: =IF(AND($R49=0,$T49=0),"0.00","mu :" & ROUND($F43/$C$2/($R49+$T49*$D$9),2)) -> mu :1.35 | AG43: =IF($E43=0,0,ROUND($R49*$S$2*$C$2/$A43,2)) -> 131.46 | AH43: =$AG43*$A43 -> 131.46 | AI43: =$E43-$AG43 -> 288.8 | AJ43: =$A43*$AI43 -> 288.8 | AK43: =ROUND(($AG43+$AI43)*$A43,2) -> 420.26 | AM43: =ROUND(R49,2) -> 100 | AN43: =ROUND(T49,2) -> 8 | AO43: =ROUND(AM43+AN43,2)*A43 -> 108
...
