Workbook
Name Access_Control: #REF!
Name Access_Control: #REF!
Name Access_Control: #REF!
Name Access_Control: #REF!
Name Access_Control: [1]Elec_Est!#REF!
Name AREAS: [2]ML_Sum!$X$1:$AD$16
Name AREAS: [2]ML_Sum!$X$1:$AD$16
Name AREAS: [2]ML_Sum!$X$1:$AD$16
Name AREAS: [2]ML_Sum!$X$1:$AD$16
Name AREAS: [1]ML_Sum!$X$1:$AD$16
Name AREAS: ML_Sum!$X$1:$AD$16
Name CCTV: #REF!
Name CCTV: #REF!
Name CCTV: #REF!
Name CCTV: #REF!
Name CCTV: [1]Elec_Est!#REF!
Name Commissioning: [2]Elec_Est!#REF!
Name Data: #REF!
Name Data: #REF!
Name Data: #REF!
Name Data: #REF!
Name Data: [1]Elec_Est!#REF!
Name Electrical: [2]Elec_Est!#REF!
Name Fire_Alarm: #REF!
Name Fire_Alarm: #REF!
Name Fire_Alarm: #REF!
Name Fire_Alarm: #REF!
Name Fire_Alarm: [1]Elec_Est!#REF!
Name Fire_Barriers: [2]Elec_Est!#REF!
Name FO: #REF!
Name FO: #REF!
Name FO: #REF!
Name FO: #REF!
Name FO: [1]Elec_Est!#REF!
Name Guard: #REF!
Name Guard: #REF!
Name Guard: #REF!
Name Guard: #REF!
Name Guard: [1]Elec_Est!#REF!
Name Intercom: #REF!
Name Intercom: #REF!
Name Intercom: #REF!
Name Intercom: #REF!
Name Intercom: [1]Elec_Est!#REF!
Name Intruder_Alarm: #REF!
Name Intruder_Alarm: #REF!
Name Intruder_Alarm: #REF!
Name Intruder_Alarm: #REF!
Name Intruder_Alarm: [1]Elec_Est!#REF!

Sheet SUMM PG
A1: SUMMARY OF BILLS
F4: € | H4: €
A6: PRELIMINARIES
A8: Collection from page 2
A10: Collection from page 3 | H10: =SUM(F7:F10) -> 0
A13: ELECTRICAL INFRASTRUCTURE
A15: Collection from page 4
A17: Collection from page 5
A19: Collection from page 6
A21: Collection from page 7
A23: Collection from page 8
A25: Collection from page 9 | H25: =SUM(F15:F25) -> 0
A28: FIRE STOPPING
A30: Collection from page 10 | H30: =SUM(F30:G30) -> 0
A33: DISMANTLING EXISTING SERVICES
A35: Collection from page 11 | H35: =SUM(F35:G35) -> 0
A38: CHILLERS DISMANTLING
A40: Collection from page 12 | F40: =Chillers_Dismantling_BOQ!F51 -> 0 | H40: =SUM(F40:G40) -> 0
A43: BOILERS DISMANTLING
A45: Collection from page 13 | F45: =Boilers_Dismantling_BOQ!F53 -> 283.28 | H45: =SUM(F45:G45) -> 283.28
A48: CHILLERS NEW
A50: Collection from page 14 | F50: =Chillers_New_BOQ!G51 -> 17970.63
A52: Collection from page 15 | F52: =Chillers_New_BOQ!G109 -> 14968.5
A54: Collection from page 16 | F54: =Chillers_New_BOQ!G163 -> 14194.89
A56: Collection from page 17 | F56: =Chillers_New_BOQ!G221 -> 15236.34
A58: Collection from page 18 | F58: =Chillers_New_BOQ!G280 -> 136.56
A60: Collection from page 19 | F60: =Chillers_New_BOQ!G332 -> 4769.23
A62: Collection from page 20 | F62: =Chillers_New_BOQ!G389 -> 138.28
A64: Collection from page 21 | F64: =Chillers_New_BOQ!G447 -> 76.62
A66: Collection from page 22 | F66: =Chillers_New_BOQ!G503 -> 0 | H66: =SUM(F50:F66) -> 67491.05
A69: HTHP NEW
A71: Collection from page 23 | F71: =HTHP_New_BOQ!Q54 -> 62.88
A73: Collection from page 24 | F73: =HTHP_New_BOQ!Q106 -> 153.92
A75: Collection from page 25 | F75: =HTHP_New_BOQ!Q162 -> 458.73
A77: Collection from page 26 | F77: =HTHP_New_BOQ!Q211 -> 2791.26
A79: Collection from page 27 | F79: =HTHP_New_BOQ!Q267 -> 0
A81: Collection from page 28 | F81: =HTHP_New_BOQ!Q320 -> 331.8
A83: Collection from page 29 | F83: =HTHP_New_BOQ!Q378 -> 0 | H83: =SUM(F71:F83) -> 3798.59
A86: PUMPS DISMANTLING
A88: Collection from page 30 | F88: =Pumps_Dismantling_BOQ!F52 -> 0
...

Sheet Notes
A1: NOTES
A3: ELECTRICAL
B5: General
A6: 1 | B6: Dismantling works - We covered disconnecting of equipment and dismantling of any related controls installations. Dismantling of power cables is excluded. No carting away of electrical material is being allowed as we assume this can be carted away along with the equipment in your quotation.
B8: Chiller New Installation
A9: 1 | B9: Rate includes for installation of a flow switch and pump/chiller interlocks. Connection of power supplies to chillers is included in the electrical BOQ
A11: 2 | B11: Energy Meters and Motorised valves - Any unions / reducers that may be required to fit the device are excluded
B13: High temperature heat pumps
A14: 1 | B14: Rate includes for installation of a flow switch and heat pump/chiller interlocks. Connection of power supplies to chillers is included in the electrical BOQ
A15: 2 | B15: Pumps - rate include connecting of pumps to local power supplies where quoted.
A16: 3 | B16: Energy Meters and Motorised valves - Any unions / reducers that may be required to fit the device are excluded
B18: New Pumps
A19: 1 | B19: New pumps will be connected to the existing power cables. We assume these are adequatly sized and long enough to reach the new pump location.
A20: 2 | B20: Any modifcations and upgrading of the MCC supplying the new pumps is excluded.

Sheet Quote
A1: =IF(AND(UPPER(LEFT(TRIM($D$8),11))="01",UPPER(LEFT(TRIM($D$9),3))<>"ELM"),"PANTA RETAIL LTD.","PANTA CONTRACTING LIMITED") -> PANTA CONTRACTING LIMITED
A2: =IF(UPPER(LEFT(TRIM($D$9),3))="ELM","ELEC-FOR-MECH INTERNAL QUOTATION","ELECTRICAL INTERNAL QUOTATION") -> ELEC-FOR-MECH INTERNAL QUOTATION
B5: ATT: | D5: =IF(A2="Internal Quotation", "Mechanical Division","") | R5: Dated: | S5: =NOW() -> 45925.648
B6: CLIENT: | C6: Link to ML_SUM $D1 | D6: =ML_Sum!D1 -> Eden Lesuire Group
B7: PROJECT: | C7: Link to ML_SUM $D2 | D7: =ML_Sum!D2 -> Intercontinental - Plant Retrofit
B8: JOB DESC: | C8: Link to ML_SUM $D3 | D8: =ML_Sum!D3 -> Retrofitting works for the HVAC plant at Intercontinental Revision A
B9: QUOTE No: | C9: Link to ML_SUM $D4 | D9: =ML_Sum!D4 -> ELM25-0465A
B10: CLIENT's Ref: | C10: Link to ML_SUM $D5 | D10: =ML_Sum!D5 -> Tender
D21: Material Cost (€) : | E21: =ML_Sum!R35 -> 129825.13 | F21: =ML_Sum!D6 -> VAT EXCL. | G21: VAT EXCLUDED. | H21: VAT EXCLUDED. | I21: VAT EXCLUDED. | J21: VAT EXCLUDED. | K21: VAT EXCLUDED. | L21: VAT EXCLUDED. | M21: VAT EXCLUDED. | N21: VAT EXCLUDED. | O21: VAT EXCLUDED. | P21: VAT EXCLUDED.
D22: Labour Pair Hours : | E22: =ML_Sum!T35 -> 949.23
A53: Signed for and on behalf of | Q53: Signed for and on behalf of
A54: Electrical Division | Q54: Division
Q56: Records
Q57: Mr. K. Micallef
Q59: File

Sheet ML_Sum
B1: CLIENT: | C1: 1 | D1: Eden Lesuire Group | G1: TRUE | H1: TRUE | I1: 1 | J1: =$Q109 -> 1 | K1: =$Q119 -> 1 | L1: =$Q129 -> 1 | M1: =$Q139 -> 1 | N1: =$Q149 -> 1 | O1: =$Q159 -> 1 | Q1: =IF(C1=1,"€","Curr?") -> € | R1: Recon /Lab.Cont >> | S1: =IF($S$39="PRINT","R","Do Not Print") -> R | T1: 1 | V1: {=IF(OR(X1=AREAS),1,0)} -> 1 | W1: BOQ | X1: x | Y1: x | Z1: x | AA1: x | AB1: x | AC1: x | AD1: x
B2: PROJECT: | C2: =IF($D$6="VAT INCLUDED",1.18,1)*(1-$Q2)*$C$1 -> 1 | D2: Intercontinental - Plant Retrofit | F2: Electrical | G2: TRUE | I2: 2 | J2: =$Q110 -> 1 | K2: =$Q120 -> 1 | L2: =$Q130 -> 1 | M2: =$Q140 -> 1 | N2: =$Q150 -> 1 | O2: =$Q160 -> 1 | R2: ="A) " & IF($S2=0,"",ROUND($S2,2) & "-" & ROUND($T2/$D$9,2)) -> A) 1.35-1.35 | S2: 1.35 | T2: =$S2*$D9 -> 37.071 | X2: x | Y2: x | Z2: x | AA2: x | AB2: x | AC2: x | AD2: x
B3: JOB DESC: | C3: =IF($D$6="VAT INCLUDED",1.18,1)*(1-$Q3)*$C$1 -> 1 | D3: Retrofitting works for the HVAC plant at Intercontinental Revision A | F3: Technician | G3: TRUE | I3: 3 | J3: =$Q111 -> 1 | K3: =$Q121 -> 1 | L3: =$Q131 -> 1 | M3: =$Q141 -> 1 | N3: =$Q151 -> 1 | O3: =$Q161 -> 1 | R3: ="B) " & IF($S3=0,"",ROUND($S3,2) & "-" & ROUND($T3/$D$9,2)) -> B) 1.35-1.66 | S3: 1.35 | T3: =$S3*$D10 -> 45.522 | X3: x | Y3: x | Z3: x | AA3: x | AB3: x | AC3: x | AD3: x
B4: INT. QUOT No: | C4: =IF($D$6="VAT INCLUDED",1.18,1)*(1-$Q4)*$C$1 -> 1 | D4: ELM25-0465A | F4: Engineer (Man Hours) | G4: TRUE | I4: 4 | J4: =$Q112 -> 1 | K4: =$Q122 -> 1 | L4: =$Q132 -> 1 | M4: =$Q142 -> 1 | N4: =$Q152 -> 1 | O4: =$Q162 -> 1 | R4: ="C) " & IF($S4=0,"",ROUND($S4,2) & "-" & ROUND($T4/$D$9,2)) -> C) 1.35-1.47 | S4: 1.35 | T4: =$S4*$D11 -> 40.5 | X4: x | Y4: x | Z4: x | AA4: x | AB4: x | AC4: x | AD4: x
B5: CLIENTs REF: | C5: =IF($D$6="VAT INCLUDED",1.18,1)*(1-$Q5)*$C$1 -> 1 | D5: Tender | F5: Megaline | G5: TRUE | I5: 5 | J5: =$Q113 -> 1 | K5: =$Q123 -> 1 | L5: =$Q133 -> 1 | M5: =$Q143 -> 1 | N5: =$Q153 -> 1 | O5: =$Q163 -> 1 | R5: ="D) " & IF($S5=0,"",ROUND($S5,2) & "-" & ROUND($T5/$D$9,2)) -> D) 1-1.35 | S5: 1 | T5: =S2*D9 -> 37.071 | X5: x | Y5: x | Z5: x | AA5: x | AB5: x | AC5: x | AD5: x
B6: VAT: | C6: =IF($D$6="VAT INCLUDED",1.18,1)*(1-$Q6)*$C$1 -> 1 | D6: VAT EXCL. | G6: TRUE | I6: 6 | J6: =$Q114 -> 1 | K6: =$Q124 -> 1 | L6: =$Q134 -> 1 | M6: =$Q144 -> 1 | N6: =$Q154 -> 1 | O6: =$Q164 -> 1 | R6: ="E) " & IF($S6=0,"",ROUND($S6,2) & "-" & ROUND($T6/$D$9,2)) -> E) | X6: x | Y6: x | Z6: x | AA6: x | AB6: x | AC6: x | AD6: x
B7: SAVED ON: | C7: =IF($D$6="VAT INCLUDED",1.18,1)*(1-$Q7)*$C$1 -> 1 | D7: 45862 | G7: TRUE | I7: 7 | J7: =$Q115 -> 1 | K7: =$Q125 -> 1 | L7: =$Q135 -> 1 | M7: =$Q145 -> 1 | N7: =$Q155 -> 1 | R7: ="F) " & IF($S7=0,"",ROUND($S7,2) & "-" & ROUND($T7/$D$9,2)) -> F) | X7: x | Y7: x | Z7: x | AA7: x | AB7: x | AC7: x | AD7: x
B8: ESTIMATOR: | C8: =IF($D$6="VAT INCLUDED",1.18,1)*(1-$Q8)*$C$1 -> 1 | D8: T.Sammut | G8: TRUE | I8: 8 | J8: =$Q116 -> 1 | K8: =$Q126 -> 1 | L8: =$Q136 -> 1 | M8: =$Q146 -> 1 | N8: =$Q156 -> 1 | R8: ="G) " & IF($S8=0,"",ROUND($S8,2) & "-" & ROUND($T8/$D$9,2)) -> G) | X8: x | Y8: x | Z8: x | AA8: x | AB8: x | AC8: x | AD8: x
B9: LAB. COST: | C9: =IF($D$6="VAT INCLUDED",1.18,1)*(1-$Q9)*$C$1 -> 1 | D9: 27.46 | E9: Electrician Pairs | G9: TRUE | I9: 9 | J9: =$Q117 -> 1 | K9: =$Q127 -> 1 | L9: =$Q137 -> 1 | M9: =$Q147 -> 1 | N9: =$Q157 -> 1 | R9: ="H) " & IF($S9=0,"",ROUND($S9,2) & "-" & ROUND($T9/$D$9,2)) -> H) | X9: x | Y9: x | Z9: x | AA9: x | AB9: x | AC9: x | AD9: x
C10: =IF($D$6="VAT INCLUDED",1.18,1)*(1-$Q10)*$C$1 -> 1 | D10: 33.72 | E10: Technician Pairs - By Guy 25.07.2025 | G10: TRUE | I10: 10 | J10: =$Q118 -> 1 | K10: =$Q128 -> 1 | L10: =$Q138 -> 1 | M10: =$Q148 -> 1 | N10: =$Q158 -> 1 | O10: =Q108 -> 1 | R10: =" I) " & IF($S10=0,"",ROUND($S10,2) & "-" & ROUND($T10/$D$9,2)) -> I) | X10: x | Y10: x | Z10: x | AA10: x | AB10: x | AC10: x | AD10: x
C11: =IF($D$6="VAT INCLUDED",1.18,1)*(1-$Q11)*$C$1 -> 1 | D11: 30 | E11: Engineer Man Hours - By Guy 25.07.2025 | R11: ="J) " & IF($S11=0,"",ROUND($S11,2) & "-" & ROUND($T11/$D$9,2)) -> J) | X11: x | Y11: x | Z11: x | AA11: x | AB11: x | AC11: x | AD11: x
C12: =IF($D$6="VAT INCLUDED",1.18,1)*(1-$Q12)*$C$1 -> 1 | G12: SYSTEMS | H12: SYSTEMS | I12: SYSTEMS | J12: SYSTEMS | K12: SYSTEMS | L12: SYSTEMS | M12: SYSTEMS | N12: SYSTEMS | O12: SYSTEMS | P12: SYSTEMS | R12: MIXED - X,Y ) | S12: MAT MU | T12: LAB RATE | X12: x | Y12: x | Z12: x | AA12: x | AB12: x | AC12: x | AD12: x
B13: MATERIAL & LABOUR SUMMARY | G13: ItemCode | H13: CostCode | I13: MAKE | J13: PART_NO | K13: MARKUP | L13: TYPE | M13: LIST_P | N13: SET | O13: FIX | P13: DATE | Q13: %Dsct in BOQ | R13: MATMU-LABMU | S13: MAT CONT >> | T13: =SUM(Q108:Q164)/57 -> 1
B14: =IF($D$6<>"VAT EXCL.", "QUOTE ISSUED WITH VAT INCLUDED", "") | X14: x | Y14: x | Z14: x | AA14: x | AB14: x | AC14: x | AD14: x
Q15: =(C72-F35)/C72 -> 1 | R15: Average Discount applied in BOQ (Q2-Q12) | X15: x | Y15: x | Z15: x | AA15: x | AB15: x | AC15: x | AD15: x
B16: =IF($W$1<>"BOQ", "DIFF SET TO " & W1,"") | Q16: =(F35-E35)/F35 -> #DIV/0! | R16: Average Discount applied on Totals (Q23-Q32) | X16: x | Y16: x | Z16: x | AA16: x | AB16: x | AC16: x | AD16: x
Q17: =F74 -> 0 | R17: Overall Discount
B18: =IF(AND(G1,G2,G3,G4,G5,G6,G7,G8,G9,G10,H1)=TRUE, "", "CHECKLIST INCOMPLETE !" )
B19: =IF(ABS(SUM(A23:A32))>100,"[Discy A-J] are high, Check it out."," ") | Q19: =R83 -> 1.3431072 | R19: Overall Markup (Final Selling Excl.VAT/Total Cost )
E21: DISCOUNTED | F21: SELLING | Q21: % Discnt | R21: MATERIAL | T21: LABOUR
A22: Discy.A-J | B22: Markup/LRate | E22: ="SELLING " & $Q$1 -> SELLING € | F22: =$Q$1 -> € | G22: VAT/DISC | H22: MU | I22: LABRATE | J22: LABCOST | Q22: on Totals | R22: € | T22: Pair Hrs.
A23: =IF($F23=0,"",($F23/$C2)-($R23*$S2+$T23*$T2)) -> 0.045045 | B23: =IF(F23=0,"",IF(R23=0,"A) "&"---, "&ROUND(($F23/$C2-($R23*$S2))/$T23,2),IF(T23=0,"A) "&ROUND(($F23/$C2)/$R23,2),"A) "&ROUND(($F23/$C2-($T23*$T2))/$R23,2)&", " &ROUND(($F23/$C2-($R23*$S2))/$T23,2)))) -> A) 1.35, 37.07 | D23: =IF($F2="","",$F2) -> Electrical | E23: =F23*(1-Q23) -> 59159.25 | F23: =Elec_Est!F3130 -> 59159.25 | G23: =C2 -> 1 | H23: =$S2 -> 1.35 | I23: =$T2 -> 37.071 | J23: =$D$9 -> 27.46 | R23: =Elec_Est!R3130 -> 24030.388 | T23: =Elec_Est!T3130 -> 720.73
A24: =IF($F24=0,"",($F24/$C3)-($R24*$S3+$T24*$T3)) -> 0.048 | B24: =IF(F24=0,"",IF(R24=0,"A) "&"---, "&ROUND(($F24/$C3-($R24*$S3))/$T24,2),IF(T24=0,"A) "&ROUND(($F24/$C3)/$R24,2),"A) "&ROUND(($F24/$C3-($T24*$T3))/$R24,2)&", " &ROUND(($F24/$C3-($R24*$S3))/$T24,2)))) -> A) 1.35, 45.52 | D24: =IF($F3="","",$F3) -> Technician | E24: =F24*(1-Q24) -> 139537.56 | F24: =Elec_Est!F3131 -> 139537.56 | G24: =C3 -> 1 | H24: =$S3 -> 1.35 | I24: =$T3 -> 45.522 | J24: =$D$9 -> 27.46 | R24: =Elec_Est!R3131 -> 98353.7 | T24: =Elec_Est!T3131 -> 148.5
A25: =IF($F25=0,"",($F25/$C4)-($R25*$S4+$T25*$T4)) -> 0.01 | B25: =IF(F25=0,"",IF(R25=0,"A) "&"---, "&ROUND(($F25/$C4-($R25*$S4))/$T25,2),IF(T25=0,"A) "&ROUND(($F25/$C4)/$R25,2),"A) "&ROUND(($F25/$C4-($T25*$T4))/$R25,2)&", " &ROUND(($F25/$C4-($R25*$S4))/$T25,2)))) -> A) ---, 40.5 | D25: =IF($F4="","",$F4) -> Engineer (Man Hours) | E25: =F25*(1-Q25) -> 3240.01 | F25: =Elec_Est!F3132 -> 3240.01 | G25: =C4 -> 1 | H25: =$S4 -> 1.35 | I25: =$T4 -> 40.5 | J25: =$D$9 -> 27.46 | R25: =Elec_Est!R3132 -> 0 | T25: =Elec_Est!T3132 -> 80
A26: =IF($F26=0,"",($F26/$C5)-($R26*$S5+$T26*$T5)) -> 0 | B26: =IF(F26=0,"",IF(R26=0,"A) "&"---, "&ROUND(($F26/$C5-($R26*$S5))/$T26,2),IF(T26=0,"A) "&ROUND(($F26/$C5)/$R26,2),"A) "&ROUND(($F26/$C5-($T26*$T5))/$R26,2)&", " &ROUND(($F26/$C5-($R26*$S5))/$T26,2)))) -> A) 1 | D26: =IF($F5="","",$F5) -> Megaline | E26: =F26*(1-Q26) -> 7441.04 | F26: =Elec_Est!F3133 -> 7441.04 | G26: =C5 -> 1 | H26: =$S5 -> 1 | I26: =$T5 -> 37.071 | J26: =$D$9 -> 27.46 | R26: =Elec_Est!R3133 -> 7441.04 | T26: =Elec_Est!T3133 -> 0
A27: =IF($F27=0,"",($F27/$C6)-($R27*$S6+$T27*$T6)) | B27: =IF(F27=0,"",IF(R27=0,"A) "&"---, "&ROUND(($F27/$C6-($R27*$S6))/$T27,2),IF(T27=0,"A) "&ROUND(($F27/$C6)/$R27,2),"A) "&ROUND(($F27/$C6-($T27*$T6))/$R27,2)&", " &ROUND(($F27/$C6-($R27*$S6))/$T27,2)))) | D27: =IF($F6="","",$F6) | E27: =F27*(1-Q27) -> 0 | F27: =Elec_Est!F3134 -> 0 | G27: =C6 -> 1 | H27: =$S6 -> 0 | I27: =$T6 -> 0 | J27: =$D$9 -> 27.46 | R27: =Elec_Est!R3134 -> 0 | T27: =Elec_Est!T3134 -> 0
A28: =IF($F28=0,"",($F28/$C7)-($R28*$S7+$T28*$T7)) | B28: =IF(F28=0,"",IF(R28=0,"A) "&"---, "&ROUND(($F28/$C7-($R28*$S7))/$T28,2),IF(T28=0,"A) "&ROUND(($F28/$C7)/$R28,2),"A) "&ROUND(($F28/$C7-($T28*$T7))/$R28,2)&", " &ROUND(($F28/$C7-($R28*$S7))/$T28,2)))) | D28: =IF($F7="","",$F7) | E28: =F28*(1-Q28) -> 0 | F28: =Elec_Est!F3135 -> 0 | G28: =C7 -> 1 | H28: =$S7 -> 0 | I28: =$T7 -> 0 | J28: =$D$9 -> 27.46 | R28: =Elec_Est!R3135 -> 0 | T28: =Elec_Est!T3135 -> 0
A29: =IF($F29=0,"",($F29/$C8)-($R29*$S8+$T29*$T8)) | B29: =IF(F29=0,"",IF(R29=0,"A) "&"---, "&ROUND(($F29/$C8-($R29*$S8))/$T29,2),IF(T29=0,"A) "&ROUND(($F29/$C8)/$R29,2),"A) "&ROUND(($F29/$C8-($T29*$T8))/$R29,2)&", " &ROUND(($F29/$C8-($R29*$S8))/$T29,2)))) | D29: =IF($F8="","",$F8) | E29: =F29*(1-Q29) -> 0 | F29: =Elec_Est!F3136 -> 0 | G29: =C8 -> 1 | H29: =$S8 -> 0 | I29: =$T8 -> 0 | J29: =$D$9 -> 27.46 | R29: =Elec_Est!R3136 -> 0 | T29: =Elec_Est!T3136 -> 0
A30: =IF($F30=0,"",($F30/$C9)-($R30*$S9+$T30*$T9)) | B30: =IF(F30=0,"",IF(R30=0,"A) "&"---, "&ROUND(($F30/$C9-($R30*$S9))/$T30,2),IF(T30=0,"A) "&ROUND(($F30/$C9)/$R30,2),"A) "&ROUND(($F30/$C9-($T30*$T9))/$R30,2)&", " &ROUND(($F30/$C9-($R30*$S9))/$T30,2)))) | D30: =IF($F9="","",$F9) | E30: =F30*(1-Q30) -> 0 | F30: =Elec_Est!F3137 -> 0 | G30: =C9 -> 1 | H30: =$S9 -> 0 | I30: =$T9 -> 0 | J30: =$D$9 -> 27.46 | R30: =Elec_Est!R3137 -> 0 | T30: =Elec_Est!T3137 -> 0
A31: =IF($F31=0,"",($F31/$C10)-($R31*$S10+$T31*$T10)) | B31: =IF(F31=0,"",IF(R31=0,"A) "&"---, "&ROUND(($F31/$C10-($R31*$S10))/$T31,2),IF(T31=0,"A) "&ROUND(($F31/$C10)/$R31,2),"A) "&ROUND(($F31/$C10-($T31*$T10))/$R31,2)&", " &ROUND(($F31/$C10-($R31*$S10))/$T31,2)))) | D31: =IF($F10="","",$F10) | E31: =F31*(1-Q31) -> 0 | F31: =Elec_Est!F3138 -> 0 | G31: =C10 -> 1 | H31: =$S10 -> 0 | I31: =$T10 -> 0 | J31: =$D$9 -> 27.46 | R31: =Elec_Est!R3138 -> 0 | T31: =Elec_Est!T3138 -> 0
A32: =IF($F32=0,"",($F32/$C11)-($R32*$S11+$T32*$T11)) | B32: =IF(F32=0,"",IF(R32=0,"A) "&"---, "&ROUND(($F32/$C11-($R32*$S11))/$T32,2),IF(T32=0,"A) "&ROUND(($F32/$C11)/$R32,2),"A) "&ROUND(($F32/$C11-($T32*$T11))/$R32,2)&", " &ROUND(($F32/$C11-($R32*$S11))/$T32,2)))) | D32: =IF($F11="","",$F11) | E32: =F32*(1-Q32) -> 0 | F32: =Elec_Est!F3139 -> 0 | G32: =C11 -> 1 | H32: =$S11 -> 0 | I32: =$T11 -> 0 | J32: =$D$9 -> 27.46 | R32: =Elec_Est!R3139 -> 0 | T32: =Elec_Est!T3139 -> 0
C33: MIXED
A35: Discy.L | E35: =SUM(E23:E32) -> 209377.86 | R35: =SUM(R23:R32) -> 129825.13 | T35: =SUM(T23:T32) -> 949.23
A36: =IF(A39=0,"0.00",A39-(A38*A37)) -> 0.00 | B36: BOQ TOTAL | E36: ="ESTIM TOTAL (" & $Q$1 & ")" -> ESTIM TOTAL (€)
A37: 1.125 | B37: <1 Actual LabCont | R37: =R165 -> 129825.08 | S37: C.C.Totals | T37: =T165 -> 949.22
B38: <2 Phrs @ 1.00
B39: <3 Phrs @ Actual | Q39: Discy.T >> | R39: =R37-R35 -> -0.049 | S39: PRINT | T39: =T37-T35 -> -0.01
B41: Values Only on : | D41: 45911 | R41: 100965.05 | T41: 881.23
A46: REMARKS:
A47: 1) VAT and Duties as above.
...

Sheet Elec_Rates
B1: CLIENT: | C1: =ML_Sum!$C1 -> 1 | D1: =ML_Sum!$D1 -> Eden Lesuire Group | F1: =ML_Sum!$F1 -> 0 | I1: 1 | J1: =ML_Sum!$J1 -> 1 | K1: =ML_Sum!$K1 -> 1 | L1: =ML_Sum!$L1 -> 1 | M1: =ML_Sum!$M1 -> 1 | N1: =ML_Sum!$N1 -> 1 | O1: =ML_Sum!$O1 -> 1 | Q1: =ML_Sum!$Q1 -> € | R1: R/Lab Cont | S1: =ML_Sum!$S1 -> R | T1: =ML_Sum!$T1 -> 1 | U1: =ML_Sum!W1 -> BOQ | V1: INCL | W1: MULT | X1: AREA | Y1: BOQ | Z1: TDWG | AA1: ACT | AB1: DIFF
B2: PROJECT: | C2: =ML_Sum!$C2 -> 1 | D2: =ML_Sum!$D2 -> Intercontinental - Plant Retrofit | F2: =ML_Sum!$F2 -> Electrical | I2: 2 | J2: =ML_Sum!$J2 -> 1 | K2: =ML_Sum!$K2 -> 1 | L2: =ML_Sum!$L2 -> 1 | M2: =ML_Sum!$M2 -> 1 | N2: =ML_Sum!$N2 -> 1 | O2: =ML_Sum!$O2 -> 1 | Q2: =ML_Sum!$Q2 -> 0 | R2: mu_A | S2: =ML_Sum!$S2 -> 1.35 | T2: =ML_Sum!$T2 -> 37.071
B3: JOB DESC: | C3: =ML_Sum!$C3 -> 1 | D3: =ML_Sum!$D3 -> Retrofitting works for the HVAC plant at Intercontinental Revision A | F3: =ML_Sum!$F3 -> Technician | I3: 3 | J3: =ML_Sum!$J3 -> 1 | K3: =ML_Sum!$K3 -> 1 | L3: =ML_Sum!$L3 -> 1 | M3: =ML_Sum!$M3 -> 1 | N3: =ML_Sum!$N3 -> 1 | O3: =ML_Sum!$O3 -> 1 | Q3: =ML_Sum!$Q3 -> 0 | R3: mu_B | S3: =ML_Sum!$S3 -> 1.35 | T3: =ML_Sum!$T3 -> 45.522
B4: QUOTE No: | C4: =ML_Sum!$C4 -> 1 | D4: =ML_Sum!$D4 -> ELM25-0465A | F4: =ML_Sum!$F4 -> Engineer (Man Hours) | I4: 4 | J4: =ML_Sum!$J4 -> 1 | K4: =ML_Sum!$K4 -> 1 | L4: =ML_Sum!$L4 -> 1 | M4: =ML_Sum!$M4 -> 1 | N4: =ML_Sum!$N4 -> 1 | O4: =ML_Sum!$O4 -> 1 | Q4: =ML_Sum!$Q4 -> 0 | R4: mu_C | S4: =ML_Sum!$S4 -> 1.35 | T4: =ML_Sum!$T4 -> 40.5
B5: CLIENTs REF: | C5: =ML_Sum!$C5 -> 1 | D5: =ML_Sum!$D5 -> Tender | F5: =ML_Sum!$F5 -> Megaline | I5: 5 | J5: =ML_Sum!$J5 -> 1 | K5: =ML_Sum!$K5 -> 1 | L5: =ML_Sum!$L5 -> 1 | M5: =ML_Sum!$M5 -> 1 | N5: =ML_Sum!$N5 -> 1 | O5: =ML_Sum!$O5 -> 1 | Q5: =ML_Sum!$Q5 -> 0 | R5: mu_D | S5: =ML_Sum!$S5 -> 1 | T5: =ML_Sum!$T5 -> 37.071
B6: VAT/DUTIES: | C6: =ML_Sum!$C6 -> 1 | D6: =ML_Sum!$D6 -> VAT EXCL. | F6: =ML_Sum!$F6 -> 0 | I6: 6 | J6: =ML_Sum!$J6 -> 1 | K6: =ML_Sum!$K6 -> 1 | L6: =ML_Sum!$L6 -> 1 | M6: =ML_Sum!$M6 -> 1 | N6: =ML_Sum!$N6 -> 1 | O6: =ML_Sum!$O6 -> 1 | Q6: =ML_Sum!$Q6 -> 0 | R6: mu_E | S6: =ML_Sum!$S6 -> 0 | T6: =ML_Sum!$T6 -> 0
B7: SAVED ON: | C7: =ML_Sum!$C7 -> 1 | D7: 39364 | F7: =ML_Sum!$F7 -> 0 | I7: 7 | J7: =ML_Sum!$J7 -> 1 | K7: =ML_Sum!$K7 -> 1 | L7: =ML_Sum!$L7 -> 1 | M7: =ML_Sum!$M7 -> 1 | N7: =ML_Sum!$N7 -> 1 | O7: =ML_Sum!$O7 -> 0 | Q7: =ML_Sum!$Q7 -> 0 | R7: mu_F | S7: =ML_Sum!$S7 -> 0 | T7: =ML_Sum!$T7 -> 0
B8: ESTIMATOR: | C8: =ML_Sum!$C8 -> 1 | D8: =ML_Sum!$D8 -> T.Sammut | F8: =ML_Sum!$F8 -> 0 | I8: 8 | J8: =ML_Sum!$J8 -> 1 | K8: =ML_Sum!$K8 -> 1 | L8: =ML_Sum!$L8 -> 1 | M8: =ML_Sum!$M8 -> 1 | N8: =ML_Sum!$N8 -> 1 | O8: =ML_Sum!$O8 -> 0 | Q8: =ML_Sum!$Q8 -> 0 | R8: mu_G | S8: =ML_Sum!$S8 -> 0 | T8: =ML_Sum!$T8 -> 0
B9: LABOUR RATE: | C9: =ML_Sum!$C9 -> 1 | D9: =ML_Sum!$D9 -> 27.46 | F9: =ML_Sum!$F9 -> 0 | I9: 9 | J9: =ML_Sum!$J9 -> 1 | K9: =ML_Sum!$K9 -> 1 | L9: =ML_Sum!$L9 -> 1 | M9: =ML_Sum!$M9 -> 1 | N9: =ML_Sum!$N9 -> 1 | O9: =ML_Sum!$O9 -> 0 | Q9: =ML_Sum!$Q9 -> 0 | R9: mu_H | S9: =ML_Sum!$S9 -> 0 | T9: =ML_Sum!$T9 -> 0
C10: =ML_Sum!$C10 -> 1 | F10: =ML_Sum!$F10 -> 0 | I10: 10 | J10: =ML_Sum!$J10 -> 1 | K10: =ML_Sum!$K10 -> 1 | L10: =ML_Sum!$L10 -> 1 | M10: =ML_Sum!$M10 -> 1 | N10: =ML_Sum!$N10 -> 1 | O10: =ML_Sum!$O10 -> 1 | Q10: =ML_Sum!$Q10 -> 0 | R10: mu_I | S10: =ML_Sum!$S10 -> 0 | T10: =ML_Sum!$T10 -> 0
C11: =ML_Sum!$C11 -> 1 | F11: =ML_Sum!$F11 -> 0 | Q11: =ML_Sum!$Q11 -> 0 | R11: mu_J | S11: =ML_Sum!$S11 -> 0 | T11: =ML_Sum!$T11 -> 0
C12: =ML_Sum!$C12 -> 1 | F12: =ML_Sum!$F12 -> 0 | Q12: =ML_Sum!$Q12 -> 0 | R12: MIXED | S12: =ML_Sum!$S12 -> MAT MU | T12: =ML_Sum!$T12 -> LAB RATE
G13: I_CODE | H13: C_CODE | I13: MAKE | J13: PART_NO | K13: MARKUP | L13: TYPE | M13: LIST_P | N13: P_FACT | O13: FIX | P13: DATE | Q13: %Dsct in BOQ | R13: MU TYPE | S13: MAT MU | T13: LAB RATE
C15: t | D15: Item:
D16: Start Typing Header
Q18: Multip
A19: 1 | B19: =Elec_Est!B3215 -> 2 | D19: 001# Connecting up of 3.0 kW 400Volt motor (Standard) | K19: RATE | L19: RATE | Q19: =B19/A19 -> 2 | R19: =IF($B19=0,0,IF($S$1="R",ROUND(R26/$B19,2),R26/$B19)) -> 11.12 | T19: =IF($B19=0,0,IF($S$1="R",ROUND(T26/$B19,2),T26/$B19)) -> 1.46
D20: Based on: Star/Delta Starting
A21: =$Q$19 *(2) -> 4 | B21: No | D21: Gland Indoor 20S BWL 4*1.5/2.5mm2 | G21: CAAC_042 | H21: 620 | I21: CMP | O21: 2 | P21: 35431 | Q21: 3.56 | R21: =$A21*Q21 -> 14.24 | S21: 0.3 | T21: =$A21*S21*$T$1 -> 1.2
A22: =$Q$19 *(2) -> 4 | B22: m | D22: Cable Marker 8 digit c/w Carrier Strip | G22: CAAC_091 | H22: 620 | I22: (__) | O22: 2 | P22: 38148 | Q22: 1.5 | R22: =$A22*Q22 -> 6 | S22: 0.08 | T22: =$A22*S22*$T$1 -> 0.32
A23: =$Q$19 *(10) -> 20 | B23: No | D23: Cable Lug 2.5 mm2 | G23: CAAC_005 | H23: 620 | I23: CTT | O23: 2 | P23: 34669 | Q23: 0.1 | R23: =$A23*Q23 -> 2 | S23: 0.02 | T23: =$A23*S23*$T$1 -> 0.4
A24: =$Q$19 *(1) -> 2 | B24: No | D24: Labour to Connect Up (FIX 3) | G24: LABO_003 | H24: 900 | I24: MISC | O24: 3 | P24: 34790 | R24: =$A24*Q24 -> 0 | S24: 0.5 | T24: =$A24*S24*$T$1 -> 1
C25: << ==== TOTAL UNITS | R25: =$A25*Q25 -> 0 | T25: =$A25*S25*$T$1 -> 0
A26: d> | B26: =(R25+T25) -> 0 | D26: Sell_A | E26: =IF($B19=0,0,ROUND(ROUND(($R26*$S$2+($T26*$T$2))/$B19, 2)*$C$2,2)) -> 69.14 | F26: =ROUND($B19*$E26,2) -> 138.28 | K26: ITEM | L26: ITEM | R26: =SUM(R20:R25) -> 22.24 | T26: =SUM(T20:T25) -> 2.92
Q27: Multip
A28: 1 | B28: =Elec_Est!B3216 -> 4 | D28: 002# Connecting up of 7.5 kW 400Volt motor (Standard) | K28: RATE | L28: RATE | Q28: =B28/A28 -> 4 | R28: =IF($B28=0,0,IF($S$1="R",ROUND(R35/$B28,2),R35/$B28)) -> 13.92 | T28: =IF($B28=0,0,IF($S$1="R",ROUND(T35/$B28,2),T35/$B28)) -> 1.56
D29: Based on: Star/Delta Starting
A30: =$Q$28 *(2) -> 8 | B30: No | D30: Gland Indoor 20 BWL 4*4/6mm2 | G30: CAAC_040 | H30: 620 | I30: CMP | O30: 2 | P30: 35431 | Q30: 4.71 | R30: =$A30*Q30 -> 37.68 | S30: 0.35 | T30: =$A30*S30*$T$1 -> 2.8
A31: =$Q$28 *(2) -> 8 | B31: m | D31: Cable Marker 8 digit c/w Carrier Strip | G31: CAAC_091 | H31: 620 | I31: (__) | O31: 2 | P31: 38148 | Q31: 1.5 | R31: =$A31*Q31 -> 12 | S31: 0.08 | T31: =$A31*S31*$T$1 -> 0.64
A32: =$Q$28 *(10) -> 40 | B32: No | D32: Cable Lug 4.0 mm2 | G32: CAAC_006 | H32: 620 | I32: CTT | O32: 2 | P32: 34669 | Q32: 0.15 | R32: =$A32*Q32 -> 6 | S32: 0.02 | T32: =$A32*S32*$T$1 -> 0.8
A33: =$Q$28 *(1) -> 4 | B33: No | D33: Labour to Connect Up (FIX 3) | G33: LABO_003 | H33: 900 | I33: MISC | O33: 3 | P33: 34790 | R33: =$A33*Q33 -> 0 | S33: 0.5 | T33: =$A33*S33*$T$1 -> 2
C34: << ==== TOTAL UNITS | R34: =$A34*Q34 -> 0 | T34: =$A34*S34*$T$1 -> 0
A35: d> | B35: =(R34+T34) -> 0 | D35: Sell_A | E35: =IF($B28=0,0,ROUND(ROUND(($R35*$S$2+($T35*$T$2))/$B28, 2)*$C$2,2)) -> 76.62 | F35: =ROUND($B28*$E35,2) -> 306.48 | K35: ITEM | L35: ITEM | R35: =SUM(R29:R34) -> 55.68 | T35: =SUM(T29:T34) -> 6.24
Q36: Multip
A37: 1 | B37: =Elec_Est!B3217 -> 3 | D37: 003# Connecting up of 11.0 kW 400Volt motor (Standard) | K37: RATE | L37: RATE | Q37: =B37/A37 -> 3 | R37: =IF($B37=0,0,IF($S$1="R",ROUND(R44/$B37,2),R44/$B37)) -> 14.42 | T37: =IF($B37=0,0,IF($S$1="R",ROUND(T44/$B37,2),T44/$B37)) -> 1.66
D38: Based on: Star/Delta Starting
A39: =$Q$37 *(2) -> 6 | B39: No | D39: Gland Indoor 20 BWL 4*4/6mm2 | G39: CAAC_040 | H39: 620 | I39: CMP | O39: 2 | P39: 35431 | Q39: 4.71 | R39: =$A39*Q39 -> 28.26 | S39: 0.35 | T39: =$A39*S39*$T$1 -> 2.1
A40: =$Q$37 *(2) -> 6 | B40: m | D40: Cable Marker 8 digit c/w Carrier Strip | G40: CAAC_091 | H40: 620 | I40: (__) | O40: 2 | P40: 38148 | Q40: 1.5 | R40: =$A40*Q40 -> 9 | S40: 0.08 | T40: =$A40*S40*$T$1 -> 0.48
A41: =$Q$37 *(10) -> 30 | B41: No | D41: Cable Lug 6.0 mm2 | G41: CAAC_007 | H41: 620 | I41: CTT | O41: 2 | P41: 34669 | Q41: 0.2 | R41: =$A41*Q41 -> 6 | S41: 0.03 | T41: =$A41*S41*$T$1 -> 0.9
A42: =$Q$37 *(1) -> 3 | B42: No | D42: Labour to Connect Up (FIX 3) | G42: LABO_003 | H42: 900 | I42: MISC | O42: 3 | P42: 34790 | R42: =$A42*Q42 -> 0 | S42: 0.5 | T42: =$A42*S42*$T$1 -> 1.5
...

Sheet Elec_Est
B1: CLIENT: | C1: =ML_Sum!$C1 -> 1 | D1: =ML_Sum!$D1 -> Eden Lesuire Group | F1: =ML_Sum!$F1 -> 0 | I1: 1 | J1: =ML_Sum!$J1 -> 1 | K1: =ML_Sum!$K1 -> 1 | L1: =ML_Sum!$L1 -> 1 | M1: =ML_Sum!$M1 -> 1 | N1: =ML_Sum!$N1 -> 1 | O1: =ML_Sum!$O1 -> 1 | Q1: =ML_Sum!$Q1 -> € | R1: R/Lab Cont | S1: =ML_Sum!$S1 -> R | T1: =ML_Sum!$T1 -> 1 | U1: =ML_Sum!W1 -> BOQ | V1: INCL | W1: MULT | X1: AREA | Y1: BOQ | Z1: TDWG | AA1: ACT | AB1: DIFF
B2: PROJECT: | C2: =ML_Sum!$C2 -> 1 | D2: =ML_Sum!$D2 -> Intercontinental - Plant Retrofit | F2: =ML_Sum!$F2 -> Electrical | I2: 2 | J2: =ML_Sum!$J2 -> 1 | K2: =ML_Sum!$K2 -> 1 | L2: =ML_Sum!$L2 -> 1 | M2: =ML_Sum!$M2 -> 1 | N2: =ML_Sum!$N2 -> 1 | O2: =ML_Sum!$O2 -> 1 | Q2: =ML_Sum!$Q2 -> 0 | R2: mu_A | S2: =ML_Sum!$S2 -> 1.35 | T2: =ML_Sum!$T2 -> 37.071
B3: JOB DESC: | C3: =ML_Sum!$C3 -> 1 | D3: =ML_Sum!$D3 -> Retrofitting works for the HVAC plant at Intercontinental Revision A | F3: =ML_Sum!$F3 -> Technician | I3: 3 | J3: =ML_Sum!$J3 -> 1 | K3: =ML_Sum!$K3 -> 1 | L3: =ML_Sum!$L3 -> 1 | M3: =ML_Sum!$M3 -> 1 | N3: =ML_Sum!$N3 -> 1 | O3: =ML_Sum!$O3 -> 1 | Q3: =ML_Sum!$Q3 -> 0 | R3: mu_B | S3: =ML_Sum!$S3 -> 1.35 | T3: =ML_Sum!$T3 -> 45.522
B4: QUOTE No: | C4: =ML_Sum!$C4 -> 1 | D4: =ML_Sum!$D4 -> ELM25-0465A | F4: =ML_Sum!$F4 -> Engineer (Man Hours) | I4: 4 | J4: =ML_Sum!$J4 -> 1 | K4: =ML_Sum!$K4 -> 1 | L4: =ML_Sum!$L4 -> 1 | M4: =ML_Sum!$M4 -> 1 | N4: =ML_Sum!$N4 -> 1 | O4: =ML_Sum!$O4 -> 1 | Q4: =ML_Sum!$Q4 -> 0 | R4: mu_C | S4: =ML_Sum!$S4 -> 1.35 | T4: =ML_Sum!$T4 -> 40.5
B5: CLIENTs REF: | C5: =ML_Sum!$C5 -> 1 | D5: =ML_Sum!$D5 -> Tender | F5: =ML_Sum!$F5 -> Megaline | I5: 5 | J5: =ML_Sum!$J5 -> 1 | K5: =ML_Sum!$K5 -> 1 | L5: =ML_Sum!$L5 -> 1 | M5: =ML_Sum!$M5 -> 1 | N5: =ML_Sum!$N5 -> 1 | O5: =ML_Sum!$O5 -> 1 | Q5: =ML_Sum!$Q5 -> 0 | R5: mu_D | S5: =ML_Sum!$S5 -> 1 | T5: =ML_Sum!$T5 -> 37.071
B6: VAT/DUTIES: | C6: =ML_Sum!$C6 -> 1 | D6: =ML_Sum!$D6 -> VAT EXCL. | F6: =ML_Sum!$F6 -> 0 | I6: 6 | J6: =ML_Sum!$J6 -> 1 | K6: =ML_Sum!$K6 -> 1 | L6: =ML_Sum!$L6 -> 1 | M6: =ML_Sum!$M6 -> 1 | N6: =ML_Sum!$N6 -> 1 | O6: =ML_Sum!$O6 -> 1 | Q6: =ML_Sum!$Q6 -> 0 | R6: mu_E | S6: =ML_Sum!$S6 -> 0 | T6: =ML_Sum!$T6 -> 0
B7: SAVED ON: | C7: =ML_Sum!$C7 -> 1 | D7: 39364 | F7: =ML_Sum!$F7 -> 0 | I7: 7 | J7: =ML_Sum!$J7 -> 1 | K7: =ML_Sum!$K7 -> 1 | L7: =ML_Sum!$L7 -> 1 | M7: =ML_Sum!$M7 -> 1 | N7: =ML_Sum!$N7 -> 1 | O7: =ML_Sum!$O7 -> 0 | Q7: =ML_Sum!$Q7 -> 0 | R7: mu_F | S7: =ML_Sum!$S7 -> 0 | T7: =ML_Sum!$T7 -> 0
B8: ESTIMATOR: | C8: =ML_Sum!$C8 -> 1 | D8: =ML_Sum!$D8 -> T.Sammut | F8: =ML_Sum!$F8 -> 0 | I8: 8 | J8: =ML_Sum!$J8 -> 1 | K8: =ML_Sum!$K8 -> 1 | L8: =ML_Sum!$L8 -> 1 | M8: =ML_Sum!$M8 -> 1 | N8: =ML_Sum!$N8 -> 1 | O8: =ML_Sum!$O8 -> 0 | Q8: =ML_Sum!$Q8 -> 0 | R8: mu_G | S8: =ML_Sum!$S8 -> 0 | T8: =ML_Sum!$T8 -> 0
B9: LABOUR RATE: | C9: =ML_Sum!$C9 -> 1 | D9: =ML_Sum!$D9 -> 27.46 | F9: =ML_Sum!$F9 -> 0 | I9: 9 | J9: =ML_Sum!$J9 -> 1 | K9: =ML_Sum!$K9 -> 1 | L9: =ML_Sum!$L9 -> 1 | M9: =ML_Sum!$M9 -> 1 | N9: =ML_Sum!$N9 -> 1 | O9: =ML_Sum!$O9 -> 0 | Q9: =ML_Sum!$Q9 -> 0 | R9: mu_H | S9: =ML_Sum!$S9 -> 0 | T9: =ML_Sum!$T9 -> 0
C10: =ML_Sum!$C10 -> 1 | F10: =ML_Sum!$F10 -> 0 | I10: 10 | J10: =ML_Sum!$J10 -> 1 | K10: =ML_Sum!$K10 -> 1 | L10: =ML_Sum!$L10 -> 1 | M10: =ML_Sum!$M10 -> 1 | N10: =ML_Sum!$N10 -> 1 | O10: =ML_Sum!$O10 -> 1 | Q10: =ML_Sum!$Q10 -> 0 | R10: mu_I | S10: =ML_Sum!$S10 -> 0 | T10: =ML_Sum!$T10 -> 0
C11: =ML_Sum!$C11 -> 1 | F11: =ML_Sum!$F11 -> 0 | Q11: =ML_Sum!$Q11 -> 0 | R11: mu_J | S11: =ML_Sum!$S11 -> 0 | T11: =ML_Sum!$T11 -> 0
C12: =ML_Sum!$C12 -> 1 | F12: =ML_Sum!$F12 -> 0 | Q12: =ML_Sum!$Q12 -> 0 | R12: MIXED | S12: =ML_Sum!$S12 -> MAT MU | T12: =ML_Sum!$T12 -> LAB RATE
G13: ISELL | H13: C_CODE | I13: MAKE | J13: PART_NO | K13: MARKUP | L13: TYPE | M13: LIST_P | N13: P_FACT | O13: FIX | P13: DATE | Q13: %Dsct in BOQ | R13: MU TYPE | S13: MAT MU | T13: LAB RATE | AM13: Tot Mat Cost | AN13: Unit Lab phr. | AO13: Tot Lab phr. | AP13: < for ELM / MEE
K14: TB
C15: t
D16: CHILLER DISMANTLING
K18: TB
C19: t
D20: CHILLERS - EDEN ARENA
E22: Sell Rate | F22: Sell Total | K22: IB | AG22: U_M_Sell | AH22: T_M_Sell | AI22: U_L_Sell | AJ22: T_L_Sell | AK22: Total_Sell | AM22: T_M_Cost | AN22: T_L_Phr | AO22: Mat/Lab=1
A23: 1 | B23: LS | D23: Item: 3 | E23: =IF(AND($A23=0,$A$1="DIF"),0, ROUND(ROUND(($R27*$S$2+($T27*$T$2))/A23,2)*$C$2,2)) -> 0 | F23: =ROUND($A23*$E23,2) -> 0 | G23: ISELL | K23: mu_A | L23: ITEM | Q23: Included in Electrical - Note by Megaline | T23: =IF(AND($R27=0,$T27=0),"0.00","mu :" & ROUND($F23/$C$2/($R27+$T27*$D$9),2)) -> 0.00 | AG23: =IF($E23=0,0,ROUND($R27*$S$2*$C$2/$A23,2)) -> 0 | AH23: =$AG23*$A23 -> 0 | AI23: =$E23-$AG23 -> 0 | AJ23: =$A23*$AI23 -> 0 | AK23: =ROUND(($AG23+$AI23)*$A23,2) -> 0 | AM23: =ROUND(R27,2) -> 0 | AN23: =ROUND(T27,2) -> 0 | AO23: =ROUND(AM23+AN23,2)*A23 -> 0
D24: Allow for disconnection of all existing power, control and piping connections, draining down of existing chillers and making safe including dismantling and removal of existing piping from adjacent isolating valves. To include for disposal of chillers and refrigerant gas in accordance with all current legislation.
A25: 1 | B25: LS | D25: Subcontracting Works (Specify Contractor Name) | F25: Megaline | G25: SUBC_007 | H25: 960 | I25: MISC | O25: 4 | P25: 38594 | R25: =$A25*Q25 -> 0 | T25: =$A25*S25*$T$1 -> 0
R26: =$A26*Q26 -> 0 | T26: =$A26*S26*$T$1 -> 0
A27: d> | B27: =(R26+T26) -> 0 | G27: ICOST | K27: mu_A | L27: ITEM | R27: =SUM(R24:R26) -> 0 | T27: =SUM(T24:T26) -> 0
E28: Sell Rate | F28: Sell Total | K28: IB | AG28: U_M_Sell | AH28: T_M_Sell | AI28: U_L_Sell | AJ28: T_L_Sell | AK28: Total_Sell | AM28: T_M_Cost | AN28: T_L_Phr | AO28: Mat/Lab=1
A29: 1 | B29: LS | D29: Item: 4 | E29: =IF(AND($A29=0,$A$1="DIF"),0, ROUND(ROUND(($R33*$S$2+($T33*$T$2))/A29,2)*$C$2,2)) -> 0 | F29: =ROUND($A29*$E29,2) -> 0 | G29: ISELL | K29: mu_A | L29: ITEM | Q29: Included in Electrical - Note by Megaline | T29: =IF(AND($R33=0,$T33=0),"0.00","mu :" & ROUND($F29/$C$2/($R33+$T33*$D$9),2)) -> 0.00 | AG29: =IF($E29=0,0,ROUND($R33*$S$2*$C$2/$A29,2)) -> 0 | AH29: =$AG29*$A29 -> 0 | AI29: =$E29-$AG29 -> 0 | AJ29: =$A29*$AI29 -> 0 | AK29: =ROUND(($AG29+$AI29)*$A29,2) -> 0 | AM29: =ROUND(R33,2) -> 0 | AN29: =ROUND(T33,2) -> 0 | AO29: =ROUND(AM29+AN29,2)*A29 -> 0
D30: Allow for dismantling and carting away all existing power, cable containment, control and piping services in plantroom at Level 2 and all piping, insulation and brackets between level 2 and level 4 plantrooms
A31: 1 | B31: LS | D31: Subcontracting Works (Specify Contractor Name) | F31: Megaline | G31: SUBC_007 | H31: 960 | I31: MISC | O31: 4 | P31: 38594 | R31: =$A31*Q31 -> 0 | T31: =$A31*S31*$T$1 -> 0
R32: =$A32*Q32 -> 0 | T32: =$A32*S32*$T$1 -> 0
A33: d> | B33: =(R32+T32) -> 0 | G33: ICOST | K33: mu_A | L33: ITEM | R33: =SUM(R30:R32) -> 0 | T33: =SUM(T30:T32) -> 0
A34: SB
B36: =$F36/$C$2-($R36*$S$2+$T36*$T$2) -> 0 | D36: PAGE: | F36: =SUMIF($L27:$L34,"ITEM",F27:F34) -> 0 | L36: PAGE | R36: =SUMIF($L27:$L34,"ITEM",R27:R34) -> 0 | T36: =SUMIF($L27:$L34,"ITEM",T27:T34) -> 0
B37: Discy: | F37: PAGE SELL | R37: PAGE MAT | T37: PAGE LAB
K40: TB
C41: t
D42: CHILLERS - NEW INSTALLATION
K44: TB
C45: t
D46: Take delivery at site inside Car Park of Trane chillers procured by client, hoist into place, install and set to work all systems listed below and as described in the specifications.
...

Sheet Chillers_Dismantling_BOQ
A1: BILL OF QUANTITIES
A2: CHILLERS
A3: DISMANTLING
A5: Item | C5: Qty | D5: Unit | E5: Rate in € | F5: Total
A7: T | B7: Dismantle and cart away all systems listed below and as described in the specifications.
A9: T | B9: CHILLERS - HOTEL
A11: 1 | B11: Screw type chillers ref. C-1, C-2 and C-3 inclusive of flow switches, controls, etc. as specified. | C11: 3 | D11: No. | F11: =E11*C11 -> 0
A14: T | B14: CHILLERS - EDEN ARENA
A16: =A11+1 -> 2 | B16: Screw type chillers ref. C-4 inclusive of flow switches, controls, etc. as specified. | C16: 1 | D16: No. | F16: =E16*C16 -> 0
A19: =A16+1 -> 3 | B19: Allow for disconnection of all existing power, control and piping connections, draining down of existing chillers and making safe including dismantling and removal of existing piping from adjacent isolating valves. To include for disposal of chillers and refrigerant gas in accordance with all current legislation. | C19: 1 | D19: LS | E19: =Elec_Est!Q23 -> Included in Electrical - Note by Megaline | G19: Megaline
A21: =A19+1 -> 4 | B21: Allow for dismantling and carting away all existing power, cable containment, control and piping services in plantroom at Level 2 and all piping, insulation and brackets between level 2 and level 4 plantrooms | C21: 1 | D21: LS | E21: =Elec_Est!Q29 -> Included in Electrical - Note by Megaline | G21: Megaline
B22: NB Chiller power cables to be retained and reused
A51: S | B51: Total carried forward to summary page | F51: =SUM(F11:F49) -> 0

Sheet Chillers_New_BOQ
A1: BILL OF QUANTITIES
A2: CHILLERS
A3: NEW INSTALLATION
A5: Item | B5: Description | D5: Qty | E5: Unit | F5: Rate in € | G5: Total
C7: Take delivery at site inside Car Park of Trane chillers procured by client, hoist into place, install and set to work all systems listed below and as described in the specifications.
C9: CHILLERS - HOTEL
A11: 1 | C11: Install only Screw type reversible chillers ref. C-1, C-2 and C-3 inclusive of flexible bellows, AVM's, flow switches, controls, etc. as specified. | D11: 3 | E11: No. | F11: =Elec_Est!E53 -> 777.51 | G11: =F11*D11 -> 2332.53
A14: =A11+1 -> 2 | C14: Allow for assisting factory-trained employee of the manufacturer to carry out all start up and commissioning of all chillers. | D14: 1 | E14: LS | G14: =F14*D14 -> 0
C17: CHILLED WATER SIDE
A19: =A14+1 -> 3 | C19: Black steel piping to chilled water headers, complete with insulation, brackets, etc.
B21: a. | C21: 6" dia. | D21: =5*2*3 -> 30 | E21: m | G21: =F21*D21 -> 0
A24: =A19+1 -> 4 | C24: Butterfly valves with insulation
B26: a. | C26: DN150 | D26: =4*3 -> 12 | E26: No. | G26: =F26*D26 -> 0
A29: =A24+1 -> 5 | C29: Energy Meter with M-Bus output
B31: a. | C31: DN150 | D31: 3 | E31: No. | F31: =Elec_Est!E89 -> 3991.72 | G31: =F31*D31 -> 11975.16
A34: =A29+1 -> 6 | C34: Motorised Valve
B36: a. | C36: DN150 | D36: 3 | E36: No. | F36: =Elec_Est!E108 -> 1220.98 | G36: =F36*D36 -> 3662.94
A39: =A34+1 -> 7 | C39: Pressure Independent Flow Limiting Valve
B41: a. | C41: DN150 | D41: 3 | E41: No. | G41: =F41*D41 -> 0
A44: =A39+1 -> 8 | C44: Commissioning valves with insulation
B46: a. | C46: DN150 | D46: 3 | E46: No. | G46: =F46*D46 -> 0
C51: Total carried forward to summary page | G51: =SUM(G7:G49) -> 17970.63
A57: Item | B57: Description | D57: Qty | E57: Unit | F57: Rate in € | G57: Total
A59: =A44+1 -> 9 | C59: 3- way motorised valve modulating 0-10V
B61: a. | C61: DN150 | D61: =3*2 -> 6 | E61: No. | F61: =Elec_Est!E127 -> 2368.98 | G61: =F61*D61 -> 14213.88
A64: =A59+1 -> 10 | C64: Flow switch | D64: 3 | E64: No. | F64: =Elec_Est!E142 -> 129.4 | G64: =F64*D64 -> 388.2
A67: =A64+1 -> 11 | C67: Install only temperature sensors (free issued by Trane) | D67: =2*3 -> 6 | E67: No. | F67: =Elec_Est!E156 -> 22.76 | G67: =F67*D67 -> 136.56
A70: =A67+1 -> 12 | C70: Pressure gauges c/w siphon and cock | D70: =2*3 -> 6 | E70: No. | G70: =F70*D70 -> 0
A73: =A70+1 -> 13 | C73: Thermometers | D73: =2*3 -> 6 | E73: No. | G73: =F73*D73 -> 0
A76: =A73+1 -> 14 | C76: Drain cocks | D76: 3 | E76: No. | G76: =F76*D76 -> 0
A79: =A76+1 -> 15 | C79: Chilled water circulating pumps, complete with anti-vibration mountings, differential pressure switch connected to BMS, and pipe flexible connections, etc. as specified.
B81: a. | C81: P-201 | D81: 1 | E81: No. | F81: =Elec_Est!E174 -> 76.62 | G81: =F81*D81 -> 76.62
B83: b. | C83: P-202 | D83: 1 | E83: No. | F83: =Elec_Est!E195 -> 76.62 | G83: =F83*D83 -> 76.62
B85: c. | C85: P-203 | D85: 1 | E85: No. | F85: =Elec_Est!E216 -> 76.62 | G85: =F85*D85 -> 76.62
A88: =A79+1 -> 16 | C88: Butterfly valves with insulation
B90: a. | C90: DN150 | D90: 3 | E90: No. | G90: =F90*D90 -> 0
A93: =A88+1 -> 17 | C93: Strainers with insulation
B95: a. | C95: DN150 | D95: =1*3 -> 3 | E95: No. | G95: =F95*D95 -> 0
A98: =A93+1 -> 18 | C98: Non return valves with insulation
B100: a. | C100: DN150 | D100: =1*3 -> 3 | E100: No. | G100: =F100*D100 -> 0
...

Sheet Boilers_Dismantling_BOQ
A1: BILL OF QUANTITIES
A2: BOILERS
A3: DISMANTLING
A5: Item | C5: Qty | D5: Unit | E5: Rate in € | F5: Total
A7: T | B7: Dismantle and cart away all systems listed below and as described in the specifications.
A9: T | B9: PLANTROOM (LEVEL 4)
A10: T | B10: BOILERS
A12: 1 | B12: Shell and tube boilers complete as specified. | C12: 2 | D12: No. | F12: =E12*C12 -> 0
A15: =A12+1 -> 2 | B15: Allow for disconnection of all existing power, control and piping connections, draining down of existing boilers and making safe including dismantling and removal of existing piping from adjacent isolating valves. To include for adjustment and blanking off of chimney and disposal of boilers in accordance with all current legislation. | C15: 1 | D15: LS | E15: =Elec_Est!E559 -> 283.28 | F15: =E15*C15 -> 283.28 | G15: 2
A53: S | B53: Total carried forward to summary page | F53: =SUM(F12:F51) -> 283.28

Sheet HTHP_New_BOQ
A1: BILL OF QUANTITIES | K1: BILL OF QUANTITIES
A2: HIGH TEMPERATURE HEAT PUMPS | K2: HIGH TEMPERATURE HEAT PUMPS
A3: NEW INSTALLATION | K3: NEW INSTALLATION
A5: Item | C5: Qty | D5: Unit | E5: Rate in € | F5: Total | K5: Item | L5: Description | N5: Unit | O5: Qty | P5: Rate in € | Q5: Total
A7: T | B7: HEATING SIDE | M7: HEATING HEADERS
A9: 1.0T | B9: Black steel piping to heating water headers, complete with insulation, brackets, etc. | K9: 1 | M9: 10" heating flow and return headers (33/28C) (approx. 4m length each) manufactured from black mild steel heavy gauge complete with insulation, brackets and having:
A11: a. | B11: 8" dia. | C11: =10*2*3 -> 60 | D11: m | F11: =E11*C11 -> 0 | M11: - 3 x 6" flanged connections | N11: No. | O11: 2 | Q11: =P11*O11 -> 0
M12: - 1 x 10" flanged connections
M13: - 1 x 1" drain connections
A14: 2.0T | B14: Butterfly valves with insulation | M14: - 1 x 1" AAV
A16: a. | B16: DN200 | C16: =2*3 -> 6 | D16: No. | F16: =E16*C16 -> 0
K17: =K9+1 -> 2 | M17: Pressure gauges c/w siphon and cock | N17: No. | O17: 2 | Q17: =P17*O17 -> 0
A19: 3.0T | B19: Energy Meter with M-Bus output
K20: =K17+1 -> 3 | M20: Thermometers | N20: No. | O20: 2 | Q20: =P20*O20 -> 0
A21: a. | B21: DN200 | C21: 3 | D21: No. | E21: =Elec_Est!#REF! -> #REF! | F21: =E21*C21 -> #REF! | G21: 2
K23: =K20+1 -> 4 | M23: 1,000 litre make up and expansion tank c/w isolating valve | N23: No. | O23: 1 | Q23: =P23*O23 -> 0
A24: 4 | B24: Pressure gauges c/w siphon and cock | C24: =3*3 -> 9 | D24: No. | F24: =E24*C24 -> 0
K26: =K23+1 -> 5 | M26: Packaged pressurisation unit c/w expansion vessel & safety valve
A27: 5 | B27: Thermometers | C27: =2*3 -> 6 | D27: No. | F27: =E27*C27 -> 0
L28: a. | M28: PU-HTW1 | N28: No. | O28: 1 | P28: =Elec_Est!E586 -> 62.88 | Q28: =P28*O28 -> 62.88
A30: 6.0T | B30: Heating circulating pumps, complete with anti-vibration mountings, differential pressure switch connected to BMS, and pipe flexible connections, etc. as specified.
K31: =K26+1 -> 6 | M31: PPR piping from packaged pressurisation unit to heating return header
A32: a. | B32: P-206 | C32: 1 | D32: No. | E32: =Elec_Est!#REF! -> #REF! | G32: 2
L33: a. | M33: 32mm | N33: m | O33: 30 | Q33: =P33*O33 -> 0
A34: b. | B34: P-207 | C34: 1 | D34: No. | E34: =Elec_Est!#REF! -> #REF! | G34: 2
A36: c. | B36: P-208 | C36: 1 | D36: No. | E36: =Elec_Est!#REF! -> #REF! | G36: 2 | K36: =K31+1 -> 7 | M36: PPR ball valve
L38: a. | M38: 32mm | N38: No. | O38: 1 | Q38: =P38*O38 -> 0
A39: 7.0T | B39: Butterfly valves with insulation
A41: a. | B41: DN200 | C41: =2*3 -> 6 | D41: No. | F41: =E41*C41 -> 0 | K41: =K36+1 -> 8 | M41: Black steel piping from heating flow and return headers to hot water tank, complete with insulation, brackets, etc.
L43: a. | M43: 10" dia. | N43: m | O43: =25*2 -> 50 | Q43: =P43*O43 -> 0
A44: 8.0T | B44: Commissioning Valves with insulation
A46: a. | B46: DN200 | C46: =1*3 -> 3 | D46: No. | F46: =E46*C46 -> 0 | K46: =K41+1 -> 9 | M46: Butterfly valves with insulation
L48: a. | M48: DN250 | N48: No. | O48: 4 | Q48: =P48*O48 -> 0
A49: 9.0T | B49: Strainers with insulation
A51: a. | B51: DN200 | C51: =1*3 -> 3 | D51: No. | F51: =E51*C51 -> 0
M54: Total carried forward to summary page | Q54: =SUM(Q11:Q52) -> 62.88
A56: P | B56: Total carried forward to summary page | F56: =SUM(F11:F54) -> #REF!
K60: Item | L60: Description | N60: Unit | O60: Qty | P60: Rate in € | Q60: Total
A62: Item | C62: Qty | D62: Unit | E62: Rate in € | F62: Total | K62: =K46+1 -> 10 | M62: 3,000 litres vertical hot water tanks (33C) with 4 x 10" connections, air vent, drain, insulation, inspection manhole etc. | N62: No. | O62: 1 | Q62: =P62*O62 -> 0
A64: 10.0T | B64: Non return valves with insulation
...

Sheet Pumps_Dismantling_BOQ
A1: BILL OF QUANTITIES
A2: PUMPS
A3: DISMANTLING
A5: Item | C5: Qty | D5: Unit | E5: Rate in € | F5: Total
A7: T | B7: Dismantle and cart away all systems listed below and as described in the specifications.
A8: T | B8: Dismantling to include 2 x isolating valves, strainers, non return valve, strainers and pipe flexible connections and piping from isolating valves to pumps.
A10: T | B10: PUMPS
A12: 1.0T | B12: Heat exchanger to chiller condenser circulating pumps, complete with anti-vibration mountings and pipe flexible connections, etc. as specified.
A14: a. | B14: a. P-101 | C14: 1 | D14: No. | F14: =E14*C14 -> 0
A16: b. | B16: b. P-102 | C16: 1 | D16: No. | F16: =E16*C16 -> 0
A18: c. | B18: c. P-103 | C18: 1 | D18: No. | F18: =E18*C18 -> 0
A20: d. | B20: d. P-104 | C20: 1 | D20: No. | F20: =E20*C20 -> 0
A23: 2.0T | B23: Primary chilled water pumps complete with anti-vibration mountings and pipe flexible connections, etc. as specified.
A25: a. | B25: a. P-201 | C25: 1 | D25: No. | F25: =E25*C25 -> 0
A27: b. | B27: b. P-202 | C27: 1 | D27: No. | F27: =E27*C27 -> 0
A29: c. | B29: c. P-203 | C29: 1 | D29: No. | F29: =E29*C29 -> 0
A31: d. | B31: d. P-204 | C31: 1 | D31: No. | F31: =E31*C31 -> 0
A33: e. | B33: e. P-205 | C33: 1 | D33: No. | F33: =E33*C33 -> 0
A52: P | B52: Total carried forward to summary page | F52: =SUM(F14:F50) -> 0
A58: Item | C58: Qty | D58: Unit | E58: Rate in € | F58: Total
A60: 3.0T | B60: Cooling / heating secondary pumps complete with anti-vibration mounting and pipe flexible connections as specified.
A62: a. | B62: a. P-301 | C62: 1 | D62: No. | F62: =E62*C62 -> 0
A64: b. | B64: b. P-302 | C64: 1 | D64: No. | F64: =E64*C64 -> 0
A66: c. | B66: c. P-303 | C66: 1 | D66: No. | F66: =E66*C66 -> 0
A68: d. | B68: d. P-304 | C68: 1 | D68: No. | F68: =E68*C68 -> 0
A70: e. | B70: e. P-305 | C70: 1 | D70: No. | F70: =E70*C70 -> 0
A72: f. | B72: f. P-306 | C72: 1 | D72: No. | F72: =E72*C72 -> 0
A74: g. | B74: g. P-307 | C74: 1 | D74: No. | F74: =E74*C74 -> 0
A76: h. | B76: h. P-308 | C76: 1 | D76: No. | F76: =E76*C76 -> 0
A78: i. | B78: i. P-309 | C78: 1 | D78: No. | F78: =E78*C78 -> 0
A80: j. | B80: j. P-310 | C80: 1 | D80: No. | F80: =E80*C80 -> 0
A108: P | B108: Total carried forward to summary page | F108: =SUM(F62:F106) -> 0
A114: Item | C114: Qty | D114: Unit | E114: Rate in € | F114: Total
A116: 4.0T | B116: Cooling water secondary pumps complete with anti-vibration mountings, differential pressure switch connected to BMS and pipe flexible connections, etc. as specified.
A118: a. | B118: a. P-401 | C118: 1 | D118: No. | F118: =E118*C118 -> 0
A120: b. | B120: b. P-402 | C120: 1 | D120: No. | F120: =E120*C120 -> 0
A122: c. | B122: c. P-403 | C122: 1 | D122: No. | F122: =E122*C122 -> 0
A124: d. | B124: d. P-404 | C124: 1 | D124: No. | F124: =E124*C124 -> 0
A126: e. | B126: e. P-405 | C126: 1 | D126: No. | F126: =E126*C126 -> 0
A128: f. | B128: f. P-406 | C128: 1 | D128: No. | F128: =E128*C128 -> 0
...

Sheet Pumps_New_BOQ
A1: BILL OF QUANTITIES | K1: BILL OF QUANTITIES
A2: PUMPS | K2: PUMPS
A3: NEW | K3: NEW
A5: Item | C5: Qty | D5: Unit | E5: Rate in € | F5: Total | K5: Item | L5: Description | N5: Unit | O5: Qty | P5: Rate in € | Q5: Total
A7: T | B7: Supply, deliver to site, install and set to work all systems listed below and as described in the specifications.
K8: 1 | M8: Cooling / heating secondary pumps complete with anti-vibration mounting and pipe flexible connections as specified.
A9: T | B9: PUMPS
M10: a. P-301 | N10: No. | O10: 1 | P10: =Elec_Est!E923 -> 61.84 | Q10: =P10*O10 -> 61.84
A11: 1.0T | B11: Heat exchanger to chiller condenser circulating pumps, complete with anti-vibration mountings, differential pressure switch connected to BMS and pipe flexible connections, etc. as specified.
M12: b. P-302 | N12: No. | O12: 1 | P12: =Elec_Est!E930 -> 61.84 | Q12: =P12*O12 -> 61.84
A13: a. | B13: a. P-101 | C13: 1 | D13: No. | F13: =E13*C13 -> 0
M14: c. P-303 | N14: No. | O14: 1 | P14: =Elec_Est!E937 -> 47.58 | Q14: =P14*O14 -> 47.58
A15: b. | B15: b. P-102 | C15: 1 | D15: No. | F15: =E15*C15 -> 0
M16: d. P-304 | N16: No. | O16: 1 | P16: =Elec_Est!E944 -> 47.58 | Q16: =P16*O16 -> 47.58
A17: c. | B17: c. P-103 | C17: 1 | D17: No. | F17: =E17*C17 -> 0
M18: e. P-305 | N18: No. | O18: 1 | P18: =Elec_Est!E951 -> 61.84 | Q18: =P18*O18 -> 61.84
A19: d. | B19: d. P-104 | C19: 1 | D19: No. | F19: =E19*C19 -> 0
M20: f. P-306 | N20: No. | O20: 1 | P20: =Elec_Est!E958 -> 61.84 | Q20: =P20*O20 -> 61.84
A22: 2.0T | B22: Primary chilled water pumps complete with anti-vibration mountings, differential pressure switch connected to BMS and pipe flexible connections, etc. as specified. | M22: g. P-307 | N22: No. | O22: 1 | P22: =Elec_Est!E965 -> 43.84 | Q22: =P22*O22 -> 43.84
A24: a. | B24: a. P-201 | C24: 1 | D24: No. | E24: =Elec_Est!#REF! -> #REF! | G24: 3 | M24: h. P-308 | N24: No. | O24: 1 | P24: =Elec_Est!E972 -> 43.84 | Q24: =P24*O24 -> 43.84
A26: b. | B26: b. P-202 | C26: 1 | D26: No. | E26: =Elec_Est!#REF! -> #REF! | G26: 3 | M26: i. P-309 | N26: No. | O26: 1 | P26: =Elec_Est!E979 -> 43.84 | Q26: =P26*O26 -> 43.84
A28: c. | B28: c. P-203 | C28: 1 | D28: No. | E28: =Elec_Est!#REF! -> #REF! | G28: 3 | M28: j. P-310 | N28: No. | O28: 1 | P28: =Elec_Est!E986 -> 43.84 | Q28: =P28*O28 -> 43.84
A30: d. | B30: d. P-204 | C30: 1 | D30: No. | E30: =Elec_Est!#REF! -> #REF! | G30: 3
A32: e. | B32: e. P-205 | C32: 1 | D32: No. | E32: =Elec_Est!#REF! -> #REF! | G32: 3
A35: 3.0T | B35: Primary heating water pumps complete with anti-vibration mountings, differential pressure switch connected to BMS and pipe flexible connections, etc. as specified.
A37: a. | B37: a. P-206 | C37: 1 | D37: No. | E37: =Elec_Est!#REF! -> #REF! | G37: 3
A39: b. | B39: b. P-207 | C39: 1 | D39: No. | E39: =Elec_Est!#REF! -> #REF! | G39: 3
A41: c. | B41: c. P-208 | C41: 1 | D41: No. | E41: =Elec_Est!#REF! -> #REF! | G41: 3
A50: P | B50: Total carried forward to summary page | F50: =SUM(F6:F48) -> 0
A56: Item | C56: Qty | D56: Unit | E56: Rate in € | F56: Total
M57: Total carried forward to summary page | Q57: =SUM(Q6:Q55) -> 517.88
A58: 4.0T | B58: Primary heating water pumps complete with anti-vibration mountings, differential pressure switch connected to BMS and pipe flexible connections, etc. as specified.
A60: a. | B60: a. P-209 | C60: 1 | D60: No. | E60: =Elec_Est!#REF! -> #REF! | G60: 3
A62: b. | B62: b. P-210 | C62: 1 | D62: No. | E62: =Elec_Est!#REF! -> #REF! | G62: 3
K63: Item | L63: Description | N63: Unit | O63: Qty | P63: Rate in € | Q63: Total
A65: 5.0T | B65: Cooling / heating secondary pumps complete with anti-vibration mounting and pipe flexible connections as specified. | K65: =K8+1 -> 2 | M65: Cooling water secondary pumps complete with anti-vibration mountings, differential pressure switch connected to BMS and pipe flexible connections, etc. as specified.
A67: a. | B67: a. P-301 | C67: 1 | D67: No. | E67: =Elec_Est!#REF! -> #REF! | G67: 3 | M67: a. P-401 | N67: No. | O67: 1 | P67: =Elec_Est!E997 -> 61.84 | Q67: =P67*O67 -> 61.84
A69: b. | B69: b. P-302 | C69: 1 | D69: No. | E69: =Elec_Est!#REF! -> #REF! | G69: 3 | M69: b. P-402 | N69: No. | O69: 1 | P69: =Elec_Est!E1018 -> 61.84 | Q69: =P69*O69 -> 61.84
A71: c. | B71: c. P-303 | C71: 1 | D71: No. | E71: =Elec_Est!#REF! -> #REF! | G71: 3 | M71: c. P-403 | N71: No. | O71: 1 | P71: =Elec_Est!E1039 -> 61.84 | Q71: =P71*O71 -> 61.84
A73: d. | B73: d. P-304 | C73: 1 | D73: No. | E73: =Elec_Est!#REF! -> #REF! | G73: 3 | M73: d. P-404 | N73: No. | O73: 1 | P73: =Elec_Est!E1060 -> 61.84 | Q73: =P73*O73 -> 61.84
...

Sheet AHU_Motors_New_BOQ
A1: BILL OF QUANTITIES
A2: AHU'S - NEW FAN MOTORS AND CONTROLS
A5: Item | C5: Qty | D5: Unit | E5: Rate in € | F5: Total
A7: T | B7: Dismantle and remove existing AHU motors, and replace with new high efficiency EC fans with all wiring controls, etc. for a complete working system. System will allow variable speed control based on load requirements. System will be capable of working independently of existing BMS and include facility to interface with existing or future BMS.
A9: T | B9: SYSTEM ON AHU/1
A11: 1 | B11: Air handling unit AHU/1 EC fan complete with all wiring controls, etc. for a complete working system. | C11: 1 | D11: No. | E11: =Elec_Est!R1903 -> Included in PCQ-25-0440 | G11: 3
A13: T | B13: SYSTEM ON AHU/2
A15: 2 | B15: Air handling unit AHU/2 EC fan complete with all wiring controls, etc. for a complete working system. | C15: 1 | D15: No. | E15: =Elec_Est!R1934 -> Not existing on site | G15: 3
A17: T | B17: SYSTEM ON AHU/3
A19: 3 | B19: Air handling unit AHU/3 EC fan complete with all wiring controls, etc. for a complete working system. | C19: 1 | D19: No. | E19: =Elec_Est!R1959 -> Included in PCQ-25-0440 | G19: 3
A21: T | B21: SYSTEM ON AHU/4
A23: 4 | B23: Air handling unit AHU/4 EC fan complete with all wiring controls, etc. for a complete working system. | C23: 1 | D23: No. | E23: =Elec_Est!R1990 -> Included in PCQ-25-0440 | G23: 3
A25: T | B25: SYSTEM ON AHU/5
A27: 5 | B27: Air handling unit AHU/5 EC fan complete with all wiring controls, etc. for a complete working system. | C27: 1 | D27: No. | E27: =Elec_Est!R2021 -> Included in PCQ-25-0440 | G27: 3
A29: T | B29: SYSTEM ON AHU/6
A31: 6 | B31: Air handling unit AHU/6 EC fan complete with all wiring controls, etc. for a complete working system. | C31: 1 | D31: No. | E31: =Elec_Est!R2052 -> Included in PCQ-25-0440 | G31: 3
A33: T | B33: SYSTEM ON AHU/7
A35: 7 | B35: Air handling unit AHU/7 EC fan complete with all wiring controls, etc. for a complete working system. | C35: 1 | D35: No. | E35: =Elec_Est!E2083 -> 5699.05 | F35: =E35*C35 -> 5699.05 | G35: 3
A37: T | B37: SYSTEM ON AHU/8
A39: 8 | B39: Air handling unit AHU/8 EC fan complete with all wiring controls, etc. for a complete working system. | C39: 1 | D39: No. | E39: =Elec_Est!R2114 -> Not existing on site | G39: 3
A42: P | B42: Total carried forward to summary page | F42: =SUM(F11:F40) -> 5699.05
A47: Item | C47: Qty | D47: Unit | E47: Rate in € | F47: Total
A49: T | B49: SYSTEM ON AHU/9
A51: 9 | B51: Air handling unit AHU/9 EC fan complete with all wiring controls, etc. for a complete working system. | C51: 1 | D51: No. | E51: =Elec_Est!E2137 -> 5570.91 | F51: =E51*C51 -> 5570.91 | G51: 3
A54: T | B54: SYSTEM ON AHU/10
A56: 10 | B56: Air handling unit AHU/10 EC fan complete with all wiring controls, etc. for a complete working system. | C56: 1 | D56: No. | E56: =Elec_Est!E2168 -> 5533.83 | F56: =E56*C56 -> 5533.83 | G56: 3
A59: T | B59: SYSTEM ON AHU/11
A61: 11 | B61: Air handling unit AHU/8 EC fan complete with all wiring controls, etc. for a complete working system. | C61: 1 | D61: No. | E61: =Elec_Est!E2199 -> 5570.91 | F61: =E61*C61 -> 5570.91 | G61: 3
A64: T | B64: SYSTEM ON AHU12
A66: 12 | B66: Air handling unit AHU/9 EC fan complete with all wiring controls, etc. for a complete working system. | C66: 1 | D66: No. | E66: =Elec_Est!E2230 -> 6127.44 | F66: =E66*C66 -> 6127.44 | G66: 3
A69: T | B69: SYSTEM ON AHU/13
A71: 13 | B71: Air handling unit AHU/10 EC fan complete with all wiring controls, etc. for a complete working system. | C71: 1 | D71: No. | E71: =Elec_Est!E2261 -> 5570.91 | F71: =E71*C71 -> 5570.91 | G71: 3
A74: T | B74: SYSTEM ON AHU/14
A76: 14 | B76: Air handling unit AHU/14 EC fan complete with all wiring controls, etc. for a complete working system. | C76: 1 | D76: No. | E76: =Elec_Est!R2292 -> Included in PCQ-25-0440 | G76: 3
A79: T | B79: SYSTEM ON AHU/15
A81: 15 | B81: Air handling unit AHU/15 EC fan complete with all wiring controls, etc. for a complete working system. | C81: 1 | D81: No. | E81: =Elec_Est!R2323 -> Included in PCQ-25-0440 | G81: 3
A84: T | B84: SYSTEM ON AHU/16
A86: 16 | B86: Air handling unit AHU/16 EC fan complete with all wiring controls, etc. for a complete working system. | C86: 1 | D86: No. | E86: =Elec_Est!R2354 -> Included in PCQ-25-0440 | G86: 3
A89: T | B89: SYSTEM ON AHU/17
A91: 17 | B91: Air handling unit AHU/17 EC fan complete with all wiring controls, etc. for a complete working system. | C91: 1 | D91: No. | E91: =Elec_Est!E2385 -> 5570.91 | F91: =E91*C91 -> 5570.91 | G91: 3
...

Sheet EF_BOQ
A1: BILL OF QUANTITIES | I1: BILL OF QUANTITIES
A2: EXTRACT FANS | I2: EXTRACT FANS
A5: Item | C5: Qty | D5: Unit | E5: Rate in € | F5: Total | I5: Item | J5: Description | L5: Unit | M5: Qty | N5: Rate in € | O5: Total
A7: T | B7: SYSTEM ON EF/1 | K7: SYSTEM ON EF/2
A9: 1 | B9: Extract fan reference EF/1 complete with mounting hardware, speed controller, flexible duct connections, supports, A.V.M. power supplies etc., as specified. | C9: 1 | D9: No. | E9: =Elec_Est!#REF! -> #REF! | F9: =E9*C9 -> #REF! | G9: 2 | I9: 1 | K9: Extract fan reference EF/2 complete with mounting hardware, speed controller, flexible duct connections, supports, A.V.M. power supplies etc., as specified. | L9: No. | M9: 1 | N9: =Elec_Est!E2691 -> 126.58 | O9: =N9*M9 -> 126.58
A12: 2.T | B12: Weather louvre WL/x | K12: SYSTEM ON EF/3
A14: a. | B14: a. 800 x 600 | C14: 1 | D14: No. | F14: =E14*C14 -> 0 | I14: =I9+1 -> 2 | K14: Extract fan reference EF/3 complete with mounting hardware, speed controller, flexible duct connections, supports, A.V.M. power supplies etc., as specified. | L14: No. | M14: 1 | N14: =Elec_Est!E2717 -> 126.58 | O14: =N14*M14 -> 126.58
A17: T | B17: SYSTEM ON EF/2 | K17: REFRIGERANT LEAK DETECTION
A19: 3 | B19: Extract fan reference EF/2 complete with mounting hardware, speed controller, flexible duct connections, supports, A.V.M. power supplies etc., as specified. | C19: 1 | D19: No. | E19: =Elec_Est!#REF! -> #REF! | F19: =E19*C19 -> #REF! | G19: 2 | I19: =I14+1 -> 3 | K19: Refrigerant leak detectors to detect when refrigerant concentration exceeds 25% of LFL for R1234ze. Detectors must be positioned a maximum of 30 cm from the floor and 1 m from the refrigerator | L19: No. | M19: 7 | N19: =Elec_Est!E2743 -> 1198.92 | O19: =N19*M19 -> 8392.44
A22: T | B22: SYSTEM ON EF/3 | I22: =I19+1 -> 4 | K22: Refrigerant leak control system which automatically triggers visual and audible alarms inside the refrigeration plant room and outside each entrance to the refrigeration plant room, starts mechanical ventilation, and shuts down the system when activated. | L22: L/S | M22: 1 | N22: =Elec_Est!E2764 -> 6720.5 | O22: =N22*M22 -> 6720.5
K23: A remote (emergency) switching device for stopping the refrigeration system must be provided outside the room (near the door). A similarly functioning switch must be placed in a suitable location within the room.
A24: 4 | B24: Extract fan reference EF/3 complete with mounting hardware, speed controller, flexible duct connections, supports, A.V.M. power supplies etc., as specified. | C24: 1 | D24: No. | E24: =Elec_Est!#REF! -> #REF! | F24: =E24*C24 -> #REF! | G24: 2
K44: Total carried forward to summary page | O44: =SUM(O7:O42) -> 15366.1
A53: S | B53: Total carried forward to summary page | F53: =SUM(F7:F51) -> #REF!

Sheet AC_Split_Unit_BOQ
A1: BILL OF QUANTITIES
A2: AC SPLIT UNIT
A5: Item | C5: Qty | D5: Unit | E5: Rate in € | F5: Total
A7: 1.0T | B7: Air cooled packaged heat pump air-conditioning units for Electrical switchgear room, wall mounted type complete with condensing units, controls and power wiring between indoor and outdoor unit, supporting brackets, refrigerant piping, drain pump, insulation, drains, etc
A9: a. | B9: a. AC/1 | C9: 1 | D9: No | E9: =Elec_Est!E2808 -> 58 | F9: =E9*C9 -> 58 | G9: 3
A55: S | B55: Total carried forward to summary page | F55: =SUM(F7:F53) -> 58

Sheet Commissioning_BOQ
A1: BILL OF QUANTITIES
A2: COMMISSIONING AND DOCUMENTATION
A5: Item | C5: Qty | D5: Unit | E5: Rate in € | F5: Total
A7: 1 | B7: Carry out all necessary testing and commissioning to the satisfaction of the Client's Engineer. All commissioning documentation is to be certified for correctness and signed by a Malta accredited Warranted Electrical Engineer, also holding a locally accredited Authorization B, on behalf of the appointed contractor. | C7: 1 | D7: LS | E7: =Elec_Est!Q2842 -> Included with electrical quotation
B9: All costs associated with phasing of works related to chilled water plant and phasing of commissioning to ensure continuous supply of chilled water to the Hotel are to be included in the quoted rates.
A12: =A7+1 -> 2 | B12: Provide sufficient training on the operation and maintenance of all plant and systems to the Employer's representatives as specified. | C12: 1 | D12: LS | F12: =E12*C12 -> 0
A15: =A12+1 -> 3 | B15: Supply and hand-over two complete sets of operation and maintenance manuals together with drawings of works "As Fitted". These shall include: wiring diagrams; test / commissioning data and certificates; equipment data, including manufacturer's details, schedules, specifications and selection / performance data and parts lists. In addition an electronic copy of the "As Fitted" drawings and manuals are to be furnished in both ACAD and pdf format. | C15: 1 | D15: LS | F15: =E15*C15 -> 0
A42: P | B42: Total carried forward to summary page | F42: =SUM(F7:F40) -> 0
A47: END!

Sheet Maintenance_BOQ
A1: BILL OF QUANTITIES
A2: MAINTENANCE
A5: Item | B5: Description | D5: Unit | E5: Qty | F5: Rate in € | G5: Total
A7: 1 | C7: Allow for 3 years preventative maintenance for all contract scope including remote monitoring by factory engineers using cloud based software | D7: Years | E7: 3 | G7: =F7*E7 -> 0
A10: =A7+1 -> 2 | C10: Rate for additional 1 years preventative maintenance for all contract scope including remote monitoring by factory engineers using cloud based software | D10: Rate only | E10: 1 | G10: Rate only
