Workbook

Sheet TotalCosts (Hrs)
D2: =MID(CELL("filename"),SEARCH("[",CELL("filename"))+1, SEARCH("]",CELL("filename"))-SEARCH("[",CELL("filename"))-1) -> Dolmen Carpark Panels(SJ574 R0.1).xlsx
I3: Min. Hrs | J3: 8 | AL3: Sell Rate: | AM3: 59.36 | AN3: 41.91
C4: Part No. | D4: Description | E4: Material | F4: Drives | G4: LL points | H4: HL nodes | I4: Panel Building | L4: Panel Testing | N4: Panel Design | P4: Programming | S4: Point Testing | V4: Functional Testing | Y4: Others (Technician) | AA4: Others (Engineer) | AB4: Qty | AC4: Unit Price (excl. VAT) | AD4: TOTAL (excl.VAT) | AE4: TOTAL (Excl. VAT) | AF4: TOTAL (Excl. VAT) | AG4: M.U. | AI4: Tradesman rate PAIR HRS | AJ4: Technician rate PAIR HRS | AK4: Engineer rate MAN HRS | AM4: Labour (Selling) | AN4: Engineer (Selling) | AP4: Qty | AQ4: Unit Price (with Mark-up) | AR4: TOTAL (with Mark-up)
I5: Pair hrs | K5: Rate: | L5: Man hrs | M5: Rate: | N5: Man hrs | O5: Rate: | P5: Man hrs | R5: Rate: | S5: Pair hrs | U5: Rate: | V5: Man hrs | X5: Rate: | Y5: Pair hrs | Z5: Rate: | AA5: Man hrs | AG5: 1.1
F6: 15 | G6: 0.5 | H6: 5 | J6: ON/OFF | K6: 0 | M6: 0 | O6: 0 | Q6: ON/OFF | R6: 0 | T6: ON/OFF | U6: 0 | W6: ON/OFF | X6: 0 | Z6: 0
F7: 0.25 | G7: 0.25 | H7: 1
G8: 1
B9: ='MaterialCosts Summary'!B9 -> 1 | D9: ='MaterialCosts Summary'!D9 -> Car Park Panels | E9: ='MaterialCosts Summary'!E9 -> 1710.0825 | F9: 0 | G9: 0 | H9: 0 | I9: =(MAX((F9*$F$6)+(G9*$G$6),$J$3)*J9) -> 0 | K9: =IF(AND(I9*$K$6<150, I9<>0), (I9*$K$6)+0, I9*$K$6) -> 0 | L9: 0 | M9: =L9*$M$6 -> 0 | N9: 0 | O9: =N9*$O$6 -> 0 | P9: =(IF(H9<>0,MAX((G9*$G$8)+(H9*0.1*$H$6)+(H9*0.9*$H$7),24),(G9*$G$8)+(H9*0.1*$H$6)+(H9*0.9*$H$7)))*Q9 -> 0 | R9: =P9*$R$6 -> 0 | S9: =G9*$G$6*T9 -> 0 | U9: =S9*$U$6 -> 0 | V9: =(((G9+H9)*$G$7)+(F9*$F$7))*W9 -> 0 | X9: =V9*$X$6 -> 0 | Y9: 0 | Z9: =Y9*$X$6 -> 0 | AA9: 0 | AB9: 1 | AC9: =AD9/AB9 -> 1710.0825 | AD9: =E9+K9+M9+O9+R9+U9+X9+Z9 -> 1710.0825 | AE9: =AC9*$AG$5 -> 1881.0908 | AF9: =AD9*$AG$5 -> 1881.0908 | AI9: =CEILING(0/2, 4) -> 0 | AJ9: 0 | AK9: =CEILING((L9+N9+P9+V9+AA9), 4) -> 0 | AM9: =AJ9*$AM$3 -> 0 | AN9: =AK9*$AN$3 -> 0 | AP9: =AB9 -> 1 | AQ9: =AR9/AP9 -> 1881.0908 | AR9: =AF9+AM9+AN9 -> 1881.0908
B10: ='MaterialCosts Summary'!B10 -> 2 | D10: ='MaterialCosts Summary'!D10 -> B | E10: ='MaterialCosts Summary'!E10 -> 0 | F10: 0 | G10: 0 | H10: 0 | I10: =(MAX((F10*$F$6)+(G10*$G$6),$J$3)*J10) -> 0 | K10: =IF(AND(I10*$K$6<150, I10<>0), (I10*$K$6)+0, I10*$K$6) -> 0 | L10: 0 | M10: =L10*$M$6 -> 0 | N10: 0 | O10: =N10*$O$6 -> 0 | P10: =(IF(H10<>0,MAX((G10*$G$8)+(H10*0.1*$H$6)+(H10*0.9*$H$7),24),(G10*$G$8)+(H10*0.1*$H$6)+(H10*0.9*$H$7)))*Q10 -> 0 | R10: =P10*$R$6 -> 0 | S10: =G10*$G$6*T10 -> 0 | U10: =S10*$U$6 -> 0 | V10: =(((G10+H10)*$G$7)+(F10*$F$7))*W10 -> 0 | X10: =V10*$X$6 -> 0 | Y10: 0 | Z10: =Y10*$X$6 -> 0 | AA10: 0 | AB10: 1 | AC10: =AD10/AB10 -> 0 | AD10: =E10+K10+M10+O10+R10+U10+X10+Z10 -> 0 | AE10: =AC10*$AG$5 -> 0 | AF10: =AD10*$AG$5 -> 0 | AI10: =CEILING(0/2, 4) -> 0 | AJ10: =CEILING((I10+S10+Y10), 1) -> 0 | AK10: =CEILING((L10+N10+P10+V10+AA10), 4) -> 0 | AM10: =AJ10*$AM$3 -> 0 | AN10: =AK10*$AN$3 -> 0 | AP10: =AB10 -> 1 | AQ10: =AR10/AP10 -> 0 | AR10: =AF10+AM10+AN10 -> 0
B11: ='MaterialCosts Summary'!B11 -> 3 | D11: ='MaterialCosts Summary'!D11 -> 0 | E11: ='MaterialCosts Summary'!E11 -> 0 | F11: 0 | G11: 0 | H11: 0 | I11: =(MAX((F11*$F$6)+(G11*$G$6),$J$3)*J11) -> 0 | K11: =IF(AND(I11*$K$6<150, I11<>0), (I11*$K$6)+0, I11*$K$6) -> 0 | L11: 0 | M11: =L11*$M$6 -> 0 | N11: 0 | O11: =N11*$O$6 -> 0 | P11: =(IF(H11<>0,MAX((G11*$G$8)+(H11*0.1*$H$6)+(H11*0.9*$H$7),24),(G11*$G$8)+(H11*0.1*$H$6)+(H11*0.9*$H$7)))*Q11 -> 0 | R11: =P11*$R$6 -> 0 | S11: =G11*$G$6*T11 -> 0 | U11: =S11*$U$6 -> 0 | V11: =(((G11+H11)*$G$7)+(F11*$F$7))*W11 -> 0 | X11: =V11*$X$6 -> 0 | Y11: 0 | Z11: =Y11*$X$6 -> 0 | AA11: 0 | AB11: 1 | AC11: =AD11/AB11 -> 0 | AD11: =E11+K11+M11+O11+R11+U11+X11+Z11 -> 0 | AE11: =AC11*$AG$5 -> 0 | AF11: =AD11*$AG$5 -> 0 | AI11: =CEILING(0/2, 4) -> 0 | AJ11: =CEILING((I11+S11+Y11), 1) -> 0 | AK11: =CEILING((L11+N11+P11+V11+AA11), 4) -> 0 | AM11: =AJ11*$AM$3 -> 0 | AN11: =AK11*$AN$3 -> 0 | AP11: =AB11 -> 1 | AQ11: =AR11/AP11 -> 0 | AR11: =AF11+AM11+AN11 -> 0
B12: ='MaterialCosts Summary'!B12 -> 4 | D12: ='MaterialCosts Summary'!D12 -> 0 | E12: ='MaterialCosts Summary'!E12 -> 0 | F12: 0 | G12: 0 | H12: 0 | I12: =(MAX((F12*$F$6)+(G12*$G$6),$J$3)*J12) -> 0 | K12: =IF(AND(I12*$K$6<150, I12<>0), (I12*$K$6)+0, I12*$K$6) -> 0 | L12: 0 | M12: =L12*$M$6 -> 0 | N12: 0 | O12: =N12*$O$6 -> 0 | P12: =(IF(H12<>0,MAX((G12*$G$8)+(H12*0.1*$H$6)+(H12*0.9*$H$7),24),(G12*$G$8)+(H12*0.1*$H$6)+(H12*0.9*$H$7)))*Q12 -> 0 | R12: =P12*$R$6 -> 0 | S12: =G12*$G$6*T12 -> 0 | U12: =S12*$U$6 -> 0 | V12: =(((G12+H12)*$G$7)+(F12*$F$7))*W12 -> 0 | X12: =V12*$X$6 -> 0 | Y12: 0 | Z12: =Y12*$X$6 -> 0 | AA12: 0 | AB12: 1 | AC12: =AD12/AB12 -> 0 | AD12: =E12+K12+M12+O12+R12+U12+X12+Z12 -> 0 | AE12: =AC12*$AG$5 -> 0 | AF12: =AD12*$AG$5 -> 0 | AI12: =CEILING(0/2, 4) -> 0 | AJ12: =CEILING((I12+S12+Y12), 1) -> 0 | AK12: =CEILING((L12+N12+P12+V12+AA12), 4) -> 0 | AM12: =AJ12*$AM$3 -> 0 | AN12: =AK12*$AN$3 -> 0 | AP12: =AB12 -> 1 | AQ12: =AR12/AP12 -> 0 | AR12: =AF12+AM12+AN12 -> 0
B13: ='MaterialCosts Summary'!B13 -> 5 | D13: ='MaterialCosts Summary'!D13 -> 0 | E13: ='MaterialCosts Summary'!E13 -> 0 | F13: 0 | G13: 0 | H13: 0 | I13: =(MAX((F13*$F$6)+(G13*$G$6),$J$3)*J13) -> 0 | K13: =IF(AND(I13*$K$6<150, I13<>0), (I13*$K$6)+0, I13*$K$6) -> 0 | L13: 0 | M13: =L13*$M$6 -> 0 | N13: 0 | O13: =N13*$O$6 -> 0 | P13: =(IF(H13<>0,MAX((G13*$G$8)+(H13*0.1*$H$6)+(H13*0.9*$H$7),24),(G13*$G$8)+(H13*0.1*$H$6)+(H13*0.9*$H$7)))*Q13 -> 0 | R13: =P13*$R$6 -> 0 | S13: =G13*$G$6*T13 -> 0 | U13: =S13*$U$6 -> 0 | V13: =(((G13+H13)*$G$7)+(F13*$F$7))*W13 -> 0 | X13: =V13*$X$6 -> 0 | Y13: 0 | Z13: =Y13*$X$6 -> 0 | AA13: 0 | AB13: 1 | AC13: =AD13/AB13 -> 0 | AD13: =E13+K13+M13+O13+R13+U13+X13+Z13 -> 0 | AE13: =AC13*$AG$5 -> 0 | AF13: =AD13*$AG$5 -> 0 | AI13: =CEILING(0/2, 4) -> 0 | AJ13: =CEILING((I13+S13+Y13), 1) -> 0 | AK13: =CEILING((L13+N13+P13+V13+AA13), 4) -> 0 | AM13: =AJ13*$AM$3 -> 0 | AN13: =AK13*$AN$3 -> 0 | AP13: =AB13 -> 1 | AQ13: =AR13/AP13 -> 0 | AR13: =AF13+AM13+AN13 -> 0
B14: ='MaterialCosts Summary'!B14 -> 6 | D14: ='MaterialCosts Summary'!D14 -> 0 | E14: ='MaterialCosts Summary'!E14 -> 0 | F14: 0 | G14: 0 | H14: 0 | I14: =(MAX((F14*$F$6)+(G14*$G$6),$J$3)*J14) -> 0 | K14: =IF(AND(I14*$K$6<150, I14<>0), (I14*$K$6)+0, I14*$K$6) -> 0 | L14: 0 | M14: =L14*$M$6 -> 0 | N14: 0 | O14: =N14*$O$6 -> 0 | P14: =(IF(H14<>0,MAX((G14*$G$8)+(H14*0.1*$H$6)+(H14*0.9*$H$7),24),(G14*$G$8)+(H14*0.1*$H$6)+(H14*0.9*$H$7)))*Q14 -> 0 | R14: =P14*$R$6 -> 0 | S14: =G14*$G$6*T14 -> 0 | U14: =S14*$U$6 -> 0 | V14: =(((G14+H14)*$G$7)+(F14*$F$7))*W14 -> 0 | X14: =V14*$X$6 -> 0 | Y14: 0 | Z14: =Y14*$X$6 -> 0 | AA14: 0 | AB14: 1 | AC14: =AD14/AB14 -> 0 | AD14: =E14+K14+M14+O14+R14+U14+X14+Z14 -> 0 | AE14: =AC14*$AG$5 -> 0 | AF14: =AD14*$AG$5 -> 0 | AI14: =CEILING(0/2, 4) -> 0 | AJ14: =CEILING((I14+S14+Y14), 1) -> 0 | AK14: =CEILING((L14+N14+P14+V14+AA14), 4) -> 0 | AM14: =AJ14*$AM$3 -> 0 | AN14: =AK14*$AN$3 -> 0 | AP14: =AB14 -> 1 | AQ14: =AR14/AP14 -> 0 | AR14: =AF14+AM14+AN14 -> 0
B15: ='MaterialCosts Summary'!B15 -> 7 | D15: ='MaterialCosts Summary'!D15 -> 0 | E15: ='MaterialCosts Summary'!E15 -> 0 | F15: 0 | G15: 0 | H15: 0 | I15: =(MAX((F15*$F$6)+(G15*$G$6),$J$3)*J15) -> 0 | K15: =IF(AND(I15*$K$6<150, I15<>0), (I15*$K$6)+0, I15*$K$6) -> 0 | L15: 0 | M15: =L15*$M$6 -> 0 | N15: 0 | O15: =N15*$O$6 -> 0 | P15: =(IF(H15<>0,MAX((G15*$G$8)+(H15*0.1*$H$6)+(H15*0.9*$H$7),24),(G15*$G$8)+(H15*0.1*$H$6)+(H15*0.9*$H$7)))*Q15 -> 0 | R15: =P15*$R$6 -> 0 | S15: =G15*$G$6*T15 -> 0 | U15: =S15*$U$6 -> 0 | V15: =(((G15+H15)*$G$7)+(F15*$F$7))*W15 -> 0 | X15: =V15*$X$6 -> 0 | Y15: 0 | Z15: =Y15*$X$6 -> 0 | AA15: 0 | AB15: 1 | AC15: =AD15/AB15 -> 0 | AD15: =E15+K15+M15+O15+R15+U15+X15+Z15 -> 0 | AE15: =AC15*$AG$5 -> 0 | AF15: =AD15*$AG$5 -> 0 | AI15: =CEILING(0/2, 4) -> 0 | AJ15: =CEILING((I15+S15+Y15), 1) -> 0 | AK15: =CEILING((L15+N15+P15+V15+AA15), 4) -> 0 | AM15: =AJ15*$AM$3 -> 0 | AN15: =AK15*$AN$3 -> 0 | AP15: =AB15 -> 1 | AQ15: =AR15/AP15 -> 0 | AR15: =AF15+AM15+AN15 -> 0
B16: ='MaterialCosts Summary'!B16 -> 8 | D16: ='MaterialCosts Summary'!D16 -> 0 | E16: ='MaterialCosts Summary'!E16 -> 0 | F16: 0 | G16: 0 | H16: 0 | I16: =(MAX((F16*$F$6)+(G16*$G$6),$J$3)*J16) -> 0 | K16: =IF(AND(I16*$K$6<150, I16<>0), (I16*$K$6)+0, I16*$K$6) -> 0 | L16: 0 | M16: =L16*$M$6 -> 0 | N16: 0 | O16: =N16*$O$6 -> 0 | P16: =(IF(H16<>0,MAX((G16*$G$8)+(H16*0.1*$H$6)+(H16*0.9*$H$7),24),(G16*$G$8)+(H16*0.1*$H$6)+(H16*0.9*$H$7)))*Q16 -> 0 | R16: =P16*$R$6 -> 0 | S16: =G16*$G$6*T16 -> 0 | U16: =S16*$U$6 -> 0 | V16: =(((G16+H16)*$G$7)+(F16*$F$7))*W16 -> 0 | X16: =V16*$X$6 -> 0 | Y16: 0 | Z16: =Y16*$X$6 -> 0 | AA16: 0 | AB16: 1 | AC16: =AD16/AB16 -> 0 | AD16: =E16+K16+M16+O16+R16+U16+X16+Z16 -> 0 | AE16: =AC16*$AG$5 -> 0 | AF16: =AD16*$AG$5 -> 0 | AI16: =CEILING(0/2, 4) -> 0 | AJ16: =CEILING((I16+S16+Y16), 1) -> 0 | AK16: =CEILING((L16+N16+P16+V16+AA16), 4) -> 0 | AM16: =AJ16*$AM$3 -> 0 | AN16: =AK16*$AN$3 -> 0 | AP16: =AB16 -> 1 | AQ16: =AR16/AP16 -> 0 | AR16: =AF16+AM16+AN16 -> 0
B17: ='MaterialCosts Summary'!B17 -> 9 | D17: ='MaterialCosts Summary'!D17 -> 0 | E17: ='MaterialCosts Summary'!E17 -> 0 | F17: 0 | G17: 0 | H17: 0 | I17: =(MAX((F17*$F$6)+(G17*$G$6),$J$3)*J17) -> 0 | K17: =IF(AND(I17*$K$6<150, I17<>0), (I17*$K$6)+0, I17*$K$6) -> 0 | L17: 0 | M17: =L17*$M$6 -> 0 | N17: 0 | O17: =N17*$O$6 -> 0 | P17: =(IF(H17<>0,MAX((G17*$G$8)+(H17*0.1*$H$6)+(H17*0.9*$H$7),24),(G17*$G$8)+(H17*0.1*$H$6)+(H17*0.9*$H$7)))*Q17 -> 0 | R17: =P17*$R$6 -> 0 | S17: =G17*$G$6*T17 -> 0 | U17: =S17*$U$6 -> 0 | V17: =(((G17+H17)*$G$7)+(F17*$F$7))*W17 -> 0 | X17: =V17*$X$6 -> 0 | Y17: 0 | Z17: =Y17*$X$6 -> 0 | AA17: 0 | AB17: 1 | AC17: =AD17/AB17 -> 0 | AD17: =E17+K17+M17+O17+R17+U17+X17+Z17 -> 0 | AE17: =AC17*$AG$5 -> 0 | AF17: =AD17*$AG$5 -> 0 | AI17: =CEILING(0/2, 4) -> 0 | AJ17: =CEILING((I17+S17+Y17), 1) -> 0 | AK17: =CEILING((L17+N17+P17+V17+AA17), 4) -> 0 | AM17: =AJ17*$AM$3 -> 0 | AN17: =AK17*$AN$3 -> 0 | AP17: =AB17 -> 1 | AQ17: =AR17/AP17 -> 0 | AR17: =AF17+AM17+AN17 -> 0
B18: ='MaterialCosts Summary'!B18 -> 10 | D18: ='MaterialCosts Summary'!D18 -> 0 | E18: ='MaterialCosts Summary'!E18 -> 0 | F18: 0 | G18: 0 | H18: 0 | I18: =(MAX((F18*$F$6)+(G18*$G$6),$J$3)*J18) -> 0 | K18: =IF(AND(I18*$K$6<150, I18<>0), (I18*$K$6)+0, I18*$K$6) -> 0 | L18: 0 | M18: =L18*$M$6 -> 0 | N18: 0 | O18: =N18*$O$6 -> 0 | P18: =(IF(H18<>0,MAX((G18*$G$8)+(H18*0.1*$H$6)+(H18*0.9*$H$7),24),(G18*$G$8)+(H18*0.1*$H$6)+(H18*0.9*$H$7)))*Q18 -> 0 | R18: =P18*$R$6 -> 0 | S18: =G18*$G$6*T18 -> 0 | U18: =S18*$U$6 -> 0 | V18: =(((G18+H18)*$G$7)+(F18*$F$7))*W18 -> 0 | X18: =V18*$X$6 -> 0 | Y18: 0 | Z18: =Y18*$X$6 -> 0 | AA18: 0 | AB18: 1 | AC18: =AD18/AB18 -> 0 | AD18: =E18+K18+M18+O18+R18+U18+X18+Z18 -> 0 | AE18: =AC18*$AG$5 -> 0 | AF18: =AD18*$AG$5 -> 0 | AI18: =CEILING(0/2, 4) -> 0 | AJ18: =CEILING((I18+S18+Y18), 1) -> 0 | AK18: =CEILING((L18+N18+P18+V18+AA18), 4) -> 0 | AM18: =AJ18*$AM$3 -> 0 | AN18: =AK18*$AN$3 -> 0 | AP18: =AB18 -> 1 | AQ18: =AR18/AP18 -> 0 | AR18: =AF18+AM18+AN18 -> 0
B19: ='MaterialCosts Summary'!B19 -> 11 | D19: ='MaterialCosts Summary'!D19 -> 0 | E19: ='MaterialCosts Summary'!E19 -> 0 | F19: 0 | G19: 0 | H19: 0 | I19: =(MAX((F19*$F$6)+(G19*$G$6),$J$3)*J19) -> 0 | K19: =IF(AND(I19*$K$6<150, I19<>0), (I19*$K$6)+0, I19*$K$6) -> 0 | L19: 0 | M19: =L19*$M$6 -> 0 | N19: 0 | O19: =N19*$O$6 -> 0 | P19: =(IF(H19<>0,MAX((G19*$G$8)+(H19*0.1*$H$6)+(H19*0.9*$H$7),24),(G19*$G$8)+(H19*0.1*$H$6)+(H19*0.9*$H$7)))*Q19 -> 0 | R19: =P19*$R$6 -> 0 | S19: =G19*$G$6*T19 -> 0 | U19: =S19*$U$6 -> 0 | V19: =(((G19+H19)*$G$7)+(F19*$F$7))*W19 -> 0 | X19: =V19*$X$6 -> 0 | Y19: 0 | Z19: =Y19*$X$6 -> 0 | AA19: 0 | AB19: 1 | AC19: =AD19/AB19 -> 0 | AD19: =E19+K19+M19+O19+R19+U19+X19+Z19 -> 0 | AE19: =AC19*$AG$5 -> 0 | AF19: =AD19*$AG$5 -> 0 | AI19: =CEILING(0/2, 4) -> 0 | AJ19: =CEILING((I19+S19+Y19), 1) -> 0 | AK19: =CEILING((L19+N19+P19+V19+AA19), 4) -> 0 | AM19: =AJ19*$AM$3 -> 0 | AN19: =AK19*$AN$3 -> 0 | AP19: =AB19 -> 1 | AQ19: =AR19/AP19 -> 0 | AR19: =AF19+AM19+AN19 -> 0
B20: ='MaterialCosts Summary'!B20 -> 12 | D20: ='MaterialCosts Summary'!D20 -> 0 | E20: ='MaterialCosts Summary'!E20 -> 0 | F20: 0 | G20: 0 | H20: 0 | I20: =(MAX((F20*$F$6)+(G20*$G$6),$J$3)*J20) -> 0 | K20: =IF(AND(I20*$K$6<150, I20<>0), (I20*$K$6)+0, I20*$K$6) -> 0 | L20: 0 | M20: =L20*$M$6 -> 0 | N20: 0 | O20: =N20*$O$6 -> 0 | P20: =(IF(H20<>0,MAX((G20*$G$8)+(H20*0.1*$H$6)+(H20*0.9*$H$7),24),(G20*$G$8)+(H20*0.1*$H$6)+(H20*0.9*$H$7)))*Q20 -> 0 | R20: =P20*$R$6 -> 0 | S20: =G20*$G$6*T20 -> 0 | U20: =S20*$U$6 -> 0 | V20: =(((G20+H20)*$G$7)+(F20*$F$7))*W20 -> 0 | X20: =V20*$X$6 -> 0 | Y20: 0 | Z20: =Y20*$X$6 -> 0 | AA20: 0 | AB20: 1 | AC20: =AD20/AB20 -> 0 | AD20: =E20+K20+M20+O20+R20+U20+X20+Z20 -> 0 | AE20: =AC20*$AG$5 -> 0 | AF20: =AD20*$AG$5 -> 0 | AI20: =CEILING(0/2, 4) -> 0 | AJ20: =CEILING((I20+S20+Y20), 1) -> 0 | AK20: =CEILING((L20+N20+P20+V20+AA20), 4) -> 0 | AM20: =AJ20*$AM$3 -> 0 | AN20: =AK20*$AN$3 -> 0 | AP20: =AB20 -> 1 | AQ20: =AR20/AP20 -> 0 | AR20: =AF20+AM20+AN20 -> 0
B21: ='MaterialCosts Summary'!B21 -> 13 | D21: ='MaterialCosts Summary'!D21 -> 0 | E21: ='MaterialCosts Summary'!E21 -> 0 | F21: 0 | G21: 0 | H21: 0 | I21: =(MAX((F21*$F$6)+(G21*$G$6),$J$3)*J21) -> 0 | K21: =IF(AND(I21*$K$6<150, I21<>0), (I21*$K$6)+0, I21*$K$6) -> 0 | L21: 0 | M21: =L21*$M$6 -> 0 | N21: 0 | O21: =N21*$O$6 -> 0 | P21: =(IF(H21<>0,MAX((G21*$G$8)+(H21*0.1*$H$6)+(H21*0.9*$H$7),24),(G21*$G$8)+(H21*0.1*$H$6)+(H21*0.9*$H$7)))*Q21 -> 0 | R21: =P21*$R$6 -> 0 | S21: =G21*$G$6*T21 -> 0 | U21: =S21*$U$6 -> 0 | V21: =(((G21+H21)*$G$7)+(F21*$F$7))*W21 -> 0 | X21: =V21*$X$6 -> 0 | Y21: 0 | Z21: =Y21*$X$6 -> 0 | AA21: 0 | AB21: 1 | AC21: =AD21/AB21 -> 0 | AD21: =E21+K21+M21+O21+R21+U21+X21+Z21 -> 0 | AE21: =AC21*$AG$5 -> 0 | AF21: =AD21*$AG$5 -> 0 | AI21: =CEILING(0/2, 4) -> 0 | AJ21: =CEILING((I21+S21+Y21), 1) -> 0 | AK21: =CEILING((L21+N21+P21+V21+AA21), 4) -> 0 | AM21: =AJ21*$AM$3 -> 0 | AN21: =AK21*$AN$3 -> 0 | AP21: =AB21 -> 1 | AQ21: =AR21/AP21 -> 0 | AR21: =AF21+AM21+AN21 -> 0
... B141: ='MaterialCosts Summary'!B141 -> 133 | D141: ='MaterialCosts Summary'!D141 -> 0 | E141: ='MaterialCosts Summary'!E141 -> 0 | F141: 0 | G141: 0 | H141: 0 | I141: =(MAX((F141*$F$6)+(G141*$G$6),$J$3)*J141) -> 0 | K141: =IF(AND(I141*$K$6<150, I141<>0), (I141*$K$6)+0, I141*$K$6) -> 0 | L141: 0 | M141: =L141*$M$6 -> 0 | N141: 0 | O141: =N141*$O$6 -> 0 | P141: =(IF(H141<>0,MAX((G141*$G$8)+(H141*0.1*$H$6)+(H141*0.9*$H$7),24),(G141*$G$8)+(H141*0.1*$H$6)+(H141*0.9*$H$7)))*Q141 -> 0 | R141: =P141*$R$6 -> 0 | S141: =G141*$G$6*T141 -> 0 | U141: =S141*$U$6 -> 0 | V141: =(((G141+H141)*$G$7)+(F141*$F$7))*W141 -> 0 | X141: =V141*$X$6 -> 0 | Y141: 0 | Z141: =Y141*$X$6 -> 0 | AA141: 0 | AB141: 1 | AC141: =AD141/AB141 -> 0 | AD141: =E141+K141+M141+O141+R141+U141+X141+Z141 -> 0 | AE141: =AC141*$AG$5 -> 0 | AF141: =AD141*$AG$5 -> 0 | AI141: =CEILING(0/2, 4) -> 0 | AJ141: =CEILING((I141+S141+Y141), 1) -> 0 | AK141: =CEILING((L141+N141+P141+V141+AA141), 4) -> 0 | AM141: =AJ141*$AM$3 -> 0 | AN141: =AK141*$AN$3 -> 0 | AP141: =AB141 -> 1 | AQ141: =AR141/AP141 -> 0 | AR141: =AF141+AM141+AN141 -> 0
D142: ='MaterialCosts Summary'!D142 -> ---
D144: TOTAL (Excl. VAT) | E144: =SUBTOTAL(9, E9:E142) -> 1710.0825 | I144: =SUBTOTAL(9, I9:I142) -> 0 | K144: =SUBTOTAL(9, K9:K142) -> 0 | L144: =SUBTOTAL(9, L9:L142) -> 0 | M144: =SUBTOTAL(9, M9:M142) -> 0 | N144: =SUBTOTAL(9, N9:N142) -> 0 | O144: =SUBTOTAL(9, O9:O142) -> 0 | P144: =SUBTOTAL(9, P9:P142) -> 0 | R144: =SUBTOTAL(9, R9:R142) -> 0 | S144: =SUBTOTAL(9, S9:S142) -> 0 | U144: =SUBTOTAL(9, U9:U142) -> 0 | V144: =SUBTOTAL(9, V9:V142) -> 0 | X144: =SUBTOTAL(9, X9:X142) -> 0 | Y144: =SUBTOTAL(9, Y9:Y142) -> 0 | Z144: =SUBTOTAL(9, Z9:Z142) -> 0 | AA144: =SUBTOTAL(9, AA9:AA142) -> 0 | AD144: =SUBTOTAL(9, AD9:AD142) -> 1710.0825 | AF144: =SUBTOTAL(9, AF9:AF142) -> 1881.0908 | AI144: =SUM(AI9:AI142) -> 0 | AJ144: =SUM(AJ9:AJ142) -> 0 | AK144: =SUM(AK9:AK142) -> 0 | AM144: =SUM(AM9:AM142) -> 0 | AN144: =SUM(AN9:AN142) -> 0 | AR144: =SUM(AR9:AR142) -> 1881.0908
D148: TOTAL MATERIAL COST | E148: =E144 -> 1710.0825
D149: Tradesman rate PAIR HRS | E149: =ROUNDUP((I144+V144)/2, 0) -> 0
D150: Technician rate PAIR HRS | E150: =ROUNDUP((#REF!+S144)/2, 0) -> #REF!
D151: Engineer rate PAIR HRS | E151: =ROUNDUP((L144+N144+P144)/2, 0) -> 0
B153: Notes:
B155: 1. | D155: Cost includes:
B156: a.
B157: b.
B158: c.
B160: 2. | D160: Cost excludes:
B161: a.
B162: b.
B163: c.
B164: d.
B165: e.

Sheet MaterialCosts Summary
D2: =MID(CELL("filename"),SEARCH("[",CELL("filename"))+1, SEARCH("]",CELL("filename"))-SEARCH("[",CELL("filename"))-1) -> Dolmen Carpark Panels(SJ574 R0.1).xlsx | E2: =E144 -> 1710.0825
D3: Rev. 0
C4: Part No. | D4: Description | E4: Material | G4: Mark-up | H4: TOTAL
B9: 1 | D9: {=TRANSPOSE('Bill of Materials'!G3:AB3)} -> Car Park Panels | E9: {=TRANSPOSE('Bill of Materials'!AM144:BH144)} -> 1710.0825 | H9: =#REF!*G9 -> #REF!
B10: 2 | D10: B | E10: 0
B11: 3
B12: 4
B13: 5
B14: 6
B15: 7
B16: 8
B17: 9
B18: 10
B19: 11
B20: 12
B21: 13
B22: 14
... B141: 133
D142: --- | H142: =#REF!*G142 -> #REF!
D144: TOTAL | E144: =SUM(E9:E142) -> 1710.0825 | G144: TOTAL | H144: =SUM(H9:H142) -> #REF!
D148: TOTAL MATERIAL COST | E148: =E144 -> 1710.0825
D149: Tradesman rate PAIR HRS | E149: =ROUNDUP((#REF!+#REF!)/2, 0) -> #REF!
D150: Technician rate PAIR HRS | E150: =ROUNDUP((#REF!+#REF!)/2, 0) -> #REF!
D151: Engineer rate PAIR HRS | E151: =ROUNDUP((#REF!+#REF!+#REF!)/2, 0) -> #REF!

Sheet Bill of Materials
D1: =AI144 -> 1710.0825 | G1: =COUNTA(G3:AB3)+COUNTBLANK(G3:AB3) -> 22 | AI1: =AI144 -> 1710.0825 | AM1: =COUNTA(AM3:BH3)+COUNTBLANK(AM3:BH3) -> 22
D2: =AI145 -> 1710.0825 | AI2: =AI145 -> 1710.0825
A3: Item No. | B3: Supplier | C3: Item | D3: Part Number | E3: Description | F3: Unit Price (ex-VAT) | G3: Car Park Panels | H3: B | I3: C | J3: D | K3: E | L3: F | M3: G | N3: H | O3: I | P3: J | Q3: K | R3: L | S3: M | T3: N | U3: O | V3: P | W3: Q | X3: R | Y3: S | Z3: T | AA3: U | AB3: -- | AC3: Quantity | AD3: Factor | AE3: FINAL QTY | AF3: Unit Price (ex-VAT) | AG3: Added material % | AH3: Contingency / Shipping | AI3: Total price (EUR) | AJ3: Comments | AM3: =G3 -> Car Park Panels | AN3: =H3 -> B | AO3: =I3 -> C | AP3: =J3 -> D | AQ3: =K3 -> E | AR3: =L3 -> F | AS3: =M3 -> G | AT3: =N3 -> H | ... BH3: =AB3 -> --
A4: 1 | D4: XCSU5220W024V AA | E4: DC UPS, DC input, 26...27Vdc in, 10.0 A (24 Vdc) out, 4…40 Ah Lead-acid battery. | F4: 68.06 | G4: 3 | AC4: =SUM(G4:AB4) -> 3 | AD4: 1 | AE4: =ROUNDUP(AC4*AD4, 0) -> 3 | AF4: =F4 -> 68.06 | AG4: 0 | AH4: 0.05 | AI4: =((AF4*(1+AG4))*(1+AH4))*AE4 -> 214.389 | AM4: =(($AF4*(1+$AG4))*(1+$AH4))*G4 -> 214.389 | AN4: =(($AF4*(1+$AG4))*(1+$AH4))*H4 -> 0 | AO4: =(($AF4*(1+$AG4))*(1+$AH4))*I4 -> 0 | AP4: =(($AF4*(1+$AG4))*(1+$AH4))*J4 -> 0 | AQ4: =(($AF4*(1+$AG4))*(1+$AH4))*K4 -> 0 | AR4: =(($AF4*(1+$AG4))*(1+$AH4))*L4 -> 0 | AS4: =(($AF4*(1+$AG4))*(1+$AH4))*M4 -> 0 | AT4: =(($AF4*(1+$AG4))*(1+$AH4))*N4 -> 0 | ... BH4: =(($AF4*(1+$AG4))*(1+$AH4))*AB4 -> 0 | BJ4: =SUM(AM4:BH4) -> 214.389 | BK4: =EXACT(BJ4,AI4) -> TRUE | BL4: =BJ4-AI4 -> 0
A5: 2 | D5: XCSF240C | E5: CSF240C SMPS, 120 & 230Vac, out 24Vdc 10A. | F5: 125.49 | G5: 3 | AC5: =SUM(G5:AB5) -> 3 | AD5: 1 | AE5: =ROUNDUP(AC5*AD5, 0) -> 3 | AF5: =F5 -> 125.49 | AG5: 0 | AH5: 0.05 | AI5: =((AF5*(1+AG5))*(1+AH5))*AE5 -> 395.2935 | AM5: =(($AF5*(1+$AG5))*(1+$AH5))*G5 -> 395.2935 | AN5: =(($AF5*(1+$AG5))*(1+$AH5))*H5 -> 0 | AO5: =(($AF5*(1+$AG5))*(1+$AH5))*I5 -> 0 | AP5: =(($AF5*(1+$AG5))*(1+$AH5))*J5 -> 0 | AQ5: =(($AF5*(1+$AG5))*(1+$AH5))*K5 -> 0 | AR5: =(($AF5*(1+$AG5))*(1+$AH5))*L5 -> 0 | AS5: =(($AF5*(1+$AG5))*(1+$AH5))*M5 -> 0 | AT5: =(($AF5*(1+$AG5))*(1+$AH5))*N5 -> 0 | ... BH5: =(($AF5*(1+$AG5))*(1+$AH5))*AB5 -> 0 | BJ5: =SUM(AM5:BH5) -> 395.2935 | BK5: =EXACT(BJ5,AI5) -> TRUE | BL5: =BJ5-AI5 -> 0
A6: 3 | D6: CB25-12 | E6: Unibat Sealed Lead-Acid Battery, 12 Vm 25 Ahr, 16.7cm c 17.5cm x 12.5cm(ht), | F6: 108 | G6: 6 | AC6: =SUM(G6:AB6) -> 6 | AD6: 1 | AE6: =ROUNDUP(AC6*AD6, 0) -> 6 | AF6: =F6 -> 108 | AG6: 0 | AH6: 0.05 | AI6: =((AF6*(1+AG6))*(1+AH6))*AE6 -> 680.4 | AM6: =(($AF6*(1+$AG6))*(1+$AH6))*G6 -> 680.4 | AN6: =(($AF6*(1+$AG6))*(1+$AH6))*H6 -> 0 | AO6: =(($AF6*(1+$AG6))*(1+$AH6))*I6 -> 0 | AP6: =(($AF6*(1+$AG6))*(1+$AH6))*J6 -> 0 | AQ6: =(($AF6*(1+$AG6))*(1+$AH6))*K6 -> 0 | AR6: =(($AF6*(1+$AG6))*(1+$AH6))*L6 -> 0 | AS6: =(($AF6*(1+$AG6))*(1+$AH6))*M6 -> 0 | AT6: =(($AF6*(1+$AG6))*(1+$AH6))*N6 -> 0 | ... BH6: =(($AF6*(1+$AG6))*(1+$AH6))*AB6 -> 0 | BJ6: =SUM(AM6:BH6) -> 680.4 | BK6: =EXACT(BJ6,AI6) -> TRUE | BL6: =BJ6-AI6 -> 0
A7: 4 | D7: CO Sensor | F7: 100 | G7: 1 | AC7: =SUM(G7:AB7) -> 1 | AD7: 1 | AE7: =ROUNDUP(AC7*AD7, 0) -> 1 | AF7: =F7 -> 100 | AG7: 0 | AH7: 0.05 | AI7: =((AF7*(1+AG7))*(1+AH7))*AE7 -> 105 | AM7: =(($AF7*(1+$AG7))*(1+$AH7))*G7 -> 105 | AN7: =(($AF7*(1+$AG7))*(1+$AH7))*H7 -> 0 | AO7: =(($AF7*(1+$AG7))*(1+$AH7))*I7 -> 0 | AP7: =(($AF7*(1+$AG7))*(1+$AH7))*J7 -> 0 | AQ7: =(($AF7*(1+$AG7))*(1+$AH7))*K7 -> 0 | AR7: =(($AF7*(1+$AG7))*(1+$AH7))*L7 -> 0 | AS7: =(($AF7*(1+$AG7))*(1+$AH7))*M7 -> 0 | AT7: =(($AF7*(1+$AG7))*(1+$AH7))*N7 -> 0 | ... BH7: =(($AF7*(1+$AG7))*(1+$AH7))*AB7 -> 0 | BJ7: =SUM(AM7:BH7) -> 105 | BK7: =EXACT(BJ7,AI7) -> TRUE | BL7: =BJ7-AI7 -> 0
A8: 5 | E8: Testing and any other material | F8: 300 | G8: 1 | AC8: =SUM(G8:AB8) -> 1 | AD8: 1 | AE8: =ROUNDUP(AC8*AD8, 0) -> 1 | AF8: =F8 -> 300 | AG8: 0 | AH8: 0.05 | AI8: =((AF8*(1+AG8))*(1+AH8))*AE8 -> 315 | AM8: =(($AF8*(1+$AG8))*(1+$AH8))*G8 -> 315 | AN8: =(($AF8*(1+$AG8))*(1+$AH8))*H8 -> 0 | AO8: =(($AF8*(1+$AG8))*(1+$AH8))*I8 -> 0 | AP8: =(($AF8*(1+$AG8))*(1+$AH8))*J8 -> 0 | AQ8: =(($AF8*(1+$AG8))*(1+$AH8))*K8 -> 0 | AR8: =(($AF8*(1+$AG8))*(1+$AH8))*L8 -> 0 | AS8: =(($AF8*(1+$AG8))*(1+$AH8))*M8 -> 0 | AT8: =(($AF8*(1+$AG8))*(1+$AH8))*N8 -> 0 | ... BH8: =(($AF8*(1+$AG8))*(1+$AH8))*AB8 -> 0 | BJ8: =SUM(AM8:BH8) -> 315 | BK8: =EXACT(BJ8,AI8) -> TRUE | BL8: =BJ8-AI8 -> 0
A9: 6 | AC9: =SUM(G9:AB9) -> 0 | AD9: 1 | AE9: =ROUNDUP(AC9*AD9, 0) -> 0 | AF9: =F9 -> 0 | AG9: 0 | AH9: 0.05 | AI9: =((AF9*(1+AG9))*(1+AH9))*AE9 -> 0 | AM9: =(($AF9*(1+$AG9))*(1+$AH9))*G9 -> 0 | AN9: =(($AF9*(1+$AG9))*(1+$AH9))*H9 -> 0 | AO9: =(($AF9*(1+$AG9))*(1+$AH9))*I9 -> 0 | AP9: =(($AF9*(1+$AG9))*(1+$AH9))*J9 -> 0 | AQ9: =(($AF9*(1+$AG9))*(1+$AH9))*K9 -> 0 | AR9: =(($AF9*(1+$AG9))*(1+$AH9))*L9 -> 0 | AS9: =(($AF9*(1+$AG9))*(1+$AH9))*M9 -> 0 | AT9: =(($AF9*(1+$AG9))*(1+$AH9))*N9 -> 0 | ... BH9: =(($AF9*(1+$AG9))*(1+$AH9))*AB9 -> 0 | BJ9: =SUM(AM9:BH9) -> 0 | BK9: =EXACT(BJ9,AI9) -> TRUE | BL9: =BJ9-AI9 -> 0
A10: 7 | AC10: =SUM(G10:AB10) -> 0 | AD10: 1 | AE10: =ROUNDUP(AC10*AD10, 0) -> 0 | AF10: =F10 -> 0 | AG10: 0 | AH10: 0.05 | AI10: =((AF10*(1+AG10))*(1+AH10))*AE10 -> 0 | AM10: =(($AF10*(1+$AG10))*(1+$AH10))*G10 -> 0 | AN10: =(($AF10*(1+$AG10))*(1+$AH10))*H10 -> 0 | AO10: =(($AF10*(1+$AG10))*(1+$AH10))*I10 -> 0 | AP10: =(($AF10*(1+$AG10))*(1+$AH10))*J10 -> 0 | AQ10: =(($AF10*(1+$AG10))*(1+$AH10))*K10 -> 0 | AR10: =(($AF10*(1+$AG10))*(1+$AH10))*L10 -> 0 | AS10: =(($AF10*(1+$AG10))*(1+$AH10))*M10 -> 0 | AT10: =(($AF10*(1+$AG10))*(1+$AH10))*N10 -> 0 | ... BH10: =(($AF10*(1+$AG10))*(1+$AH10))*AB10 -> 0 | BJ10: =SUM(AM10:BH10) -> 0 | BK10: =EXACT(BJ10,AI10) -> TRUE | BL10: =BJ10-AI10 -> 0
A11: 8 | AC11: =SUM(G11:AB11) -> 0 | AD11: 1 | AE11: =ROUNDUP(AC11*AD11, 0) -> 0 | AF11: =F11 -> 0 | AG11: 0 | AH11: 0.05 | AI11: =((AF11*(1+AG11))*(1+AH11))*AE11 -> 0 | AM11: =(($AF11*(1+$AG11))*(1+$AH11))*G11 -> 0 | AN11: =(($AF11*(1+$AG11))*(1+$AH11))*H11 -> 0 | AO11: =(($AF11*(1+$AG11))*(1+$AH11))*I11 -> 0 | AP11: =(($AF11*(1+$AG11))*(1+$AH11))*J11 -> 0 | AQ11: =(($AF11*(1+$AG11))*(1+$AH11))*K11 -> 0 | AR11: =(($AF11*(1+$AG11))*(1+$AH11))*L11 -> 0 | AS11: =(($AF11*(1+$AG11))*(1+$AH11))*M11 -> 0 | AT11: =(($AF11*(1+$AG11))*(1+$AH11))*N11 -> 0 | ... BH11: =(($AF11*(1+$AG11))*(1+$AH11))*AB11 -> 0 | BJ11: =SUM(AM11:BH11) -> 0 | BK11: =EXACT(BJ11,AI11) -> TRUE | BL11: =BJ11-AI11 -> 0
A12: 9 | AC12: =SUM(G12:AB12) -> 0 | AD12: 1 | AE12: =ROUNDUP(AC12*AD12, 0) -> 0 | AF12: =F12 -> 0 | AG12: 0 | AH12: 0.05 | AI12: =((AF12*(1+AG12))*(1+AH12))*AE12 -> 0 | AM12: =(($AF12*(1+$AG12))*(1+$AH12))*G12 -> 0 | AN12: =(($AF12*(1+$AG12))*(1+$AH12))*H12 -> 0 | AO12: =(($AF12*(1+$AG12))*(1+$AH12))*I12 -> 0 | AP12: =(($AF12*(1+$AG12))*(1+$AH12))*J12 -> 0 | AQ12: =(($AF12*(1+$AG12))*(1+$AH12))*K12 -> 0 | AR12: =(($AF12*(1+$AG12))*(1+$AH12))*L12 -> 0 | AS12: =(($AF12*(1+$AG12))*(1+$AH12))*M12 -> 0 | AT12: =(($AF12*(1+$AG12))*(1+$AH12))*N12 -> 0 | ... BH12: =(($AF12*(1+$AG12))*(1+$AH12))*AB12 -> 0 | BJ12: =SUM(AM12:BH12) -> 0 | BK12: =EXACT(BJ12,AI12) -> TRUE | BL12: =BJ12-AI12 -> 0
A13: 10 | AC13: =SUM(G13:AB13) -> 0 | AD13: 1 | AE13: =ROUNDUP(AC13*AD13, 0) -> 0 | AF13: =F13 -> 0 | AG13: 0 | AH13: 0.05 | AI13: =((AF13*(1+AG13))*(1+AH13))*AE13 -> 0 | AM13: =(($AF13*(1+$AG13))*(1+$AH13))*G13 -> 0 | AN13: =(($AF13*(1+$AG13))*(1+$AH13))*H13 -> 0 | AO13: =(($AF13*(1+$AG13))*(1+$AH13))*I13 -> 0 | AP13: =(($AF13*(1+$AG13))*(1+$AH13))*J13 -> 0 | AQ13: =(($AF13*(1+$AG13))*(1+$AH13))*K13 -> 0 | AR13: =(($AF13*(1+$AG13))*(1+$AH13))*L13 -> 0 | AS13: =(($AF13*(1+$AG13))*(1+$AH13))*M13 -> 0 | AT13: =(($AF13*(1+$AG13))*(1+$AH13))*N13 -> 0 | ... BH13: =(($AF13*(1+$AG13))*(1+$AH13))*AB13 -> 0 | BJ13: =SUM(AM13:BH13) -> 0 | BK13: =EXACT(BJ13,AI13) -> TRUE | BL13: =BJ13-AI13 -> 0
A14: 11 | AC14: =SUM(G14:AB14) -> 0 | AD14: 1 | AE14: =ROUNDUP(AC14*AD14, 0) -> 0 | AF14: =F14 -> 0 | AG14: 0 | AH14: 0.05 | AI14: =((AF14*(1+AG14))*(1+AH14))*AE14 -> 0 | AM14: =(($AF14*(1+$AG14))*(1+$AH14))*G14 -> 0 | AN14: =(($AF14*(1+$AG14))*(1+$AH14))*H14 -> 0 | AO14: =(($AF14*(1+$AG14))*(1+$AH14))*I14 -> 0 | AP14: =(($AF14*(1+$AG14))*(1+$AH14))*J14 -> 0 | AQ14: =(($AF14*(1+$AG14))*(1+$AH14))*K14 -> 0 | AR14: =(($AF14*(1+$AG14))*(1+$AH14))*L14 -> 0 | AS14: =(($AF14*(1+$AG14))*(1+$AH14))*M14 -> 0 | AT14: =(($AF14*(1+$AG14))*(1+$AH14))*N14 -> 0 | ... BH14: =(($AF14*(1+$AG14))*(1+$AH14))*AB14 -> 0 | BJ14: =SUM(AM14:BH14) -> 0 | BK14: =EXACT(BJ14,AI14) -> TRUE | BL14: =BJ14-AI14 -> 0
A15: 12 | AC15: =SUM(G15:AB15) -> 0 | AD15: 1 | AE15: =ROUNDUP(AC15*AD15, 0) -> 0 | AF15: =F15 -> 0 | AG15: 0 | AH15: 0.05 | AI15: =((AF15*(1+AG15))*(1+AH15))*AE15 -> 0 | AM15: =(($AF15*(1+$AG15))*(1+$AH15))*G15 -> 0 | AN15: =(($AF15*(1+$AG15))*(1+$AH15))*H15 -> 0 | AO15: =(($AF15*(1+$AG15))*(1+$AH15))*I15 -> 0 | AP15: =(($AF15*(1+$AG15))*(1+$AH15))*J15 -> 0 | AQ15: =(($AF15*(1+$AG15))*(1+$AH15))*K15 -> 0 | AR15: =(($AF15*(1+$AG15))*(1+$AH15))*L15 -> 0 | AS15: =(($AF15*(1+$AG15))*(1+$AH15))*M15 -> 0 | AT15: =(($AF15*(1+$AG15))*(1+$AH15))*N15 -> 0 | ... BH15: =(($AF15*(1+$AG15))*(1+$AH15))*AB15 -> 0 | BJ15: =SUM(AM15:BH15) -> 0 | BK15: =EXACT(BJ15,AI15) -> TRUE | BL15: =BJ15-AI15 -> 0
A16: 13 | AC16: =SUM(G16:AB16) -> 0 | AD16: 1 | AE16: =ROUNDUP(AC16*AD16, 0) -> 0 | AF16: =F16 -> 0 | AG16: 0 | AH16: 0.05 | AI16: =((AF16*(1+AG16))*(1+AH16))*AE16 -> 0 | AM16: =(($AF16*(1+$AG16))*(1+$AH16))*G16 -> 0 | AN16: =(($AF16*(1+$AG16))*(1+$AH16))*H16 -> 0 | AO16: =(($AF16*(1+$AG16))*(1+$AH16))*I16 -> 0 | AP16: =(($AF16*(1+$AG16))*(1+$AH16))*J16 -> 0 | AQ16: =(($AF16*(1+$AG16))*(1+$AH16))*K16 -> 0 | AR16: =(($AF16*(1+$AG16))*(1+$AH16))*L16 -> 0 | AS16: =(($AF16*(1+$AG16))*(1+$AH16))*M16 -> 0 | AT16: =(($AF16*(1+$AG16))*(1+$AH16))*N16 -> 0 | ... BH16: =(($AF16*(1+$AG16))*(1+$AH16))*AB16 -> 0 | BJ16: =SUM(AM16:BH16) -> 0 | BK16: =EXACT(BJ16,AI16) -> TRUE | BL16: =BJ16-AI16 -> 0
A17: 14 | AC17: =SUM(G17:AB17) -> 0 | AD17: 1 | AE17: =ROUNDUP(AC17*AD17, 0) -> 0 | AF17: =F17 -> 0 | AG17: 0 | AH17: 0.05 | AI17: =((AF17*(1+AG17))*(1+AH17))*AE17 -> 0 | AM17: =(($AF17*(1+$AG17))*(1+$AH17))*G17 -> 0 | AN17: =(($AF17*(1+$AG17))*(1+$AH17))*H17 -> 0 | AO17: =(($AF17*(1+$AG17))*(1+$AH17))*I17 -> 0 | AP17: =(($AF17*(1+$AG17))*(1+$AH17))*J17 -> 0 | AQ17: =(($AF17*(1+$AG17))*(1+$AH17))*K17 -> 0 | AR17: =(($AF17*(1+$AG17))*(1+$AH17))*L17 -> 0 | AS17: =(($AF17*(1+$AG17))*(1+$AH17))*M17 -> 0 | AT17: =(($AF17*(1+$AG17))*(1+$AH17))*N17 -> 0 | ... BH17: =(($AF17*(1+$AG17))*(1+$AH17))*AB17 -> 0 | BJ17: =SUM(AM17:BH17) -> 0 | BK17: =EXACT(BJ17,AI17) -> TRUE | BL17: =BJ17-AI17 -> 0
A18: 15 | AC18: =SUM(G18:AB18) -> 0 | AD18: 1 | AE18: =ROUNDUP(AC18*AD18, 0) -> 0 | AF18: =F18 -> 0 | AG18: 0 | AH18: 0.05 | AI18: =((AF18*(1+AG18))*(1+AH18))*AE18 -> 0 | AM18: =(($AF18*(1+$AG18))*(1+$AH18))*G18 -> 0 | AN18: =(($AF18*(1+$AG18))*(1+$AH18))*H18 -> 0 | AO18: =(($AF18*(1+$AG18))*(1+$AH18))*I18 -> 0 | AP18: =(($AF18*(1+$AG18))*(1+$AH18))*J18 -> 0 | AQ18: =(($AF18*(1+$AG18))*(1+$AH18))*K18 -> 0 | AR18: =(($AF18*(1+$AG18))*(1+$AH18))*L18 -> 0 | AS18: =(($AF18*(1+$AG18))*(1+$AH18))*M18 -> 0 | AT18: =(($AF18*(1+$AG18))*(1+$AH18))*N18 -> 0 | ... BH18: =(($AF18*(1+$AG18))*(1+$AH18))*AB18 -> 0 | BJ18: =SUM(AM18:BH18) -> 0 | BK18: =EXACT(BJ18,AI18) -> TRUE | BL18: =BJ18-AI18 -> 0
A19: 16 | AC19: =SUM(G19:AB19) -> 0 | AD19: 1 | AE19: =ROUNDUP(AC19*AD19, 0) -> 0 | AF19: =F19 -> 0 | AG19: 0 | AH19: 0.05 | AI19: =((AF19*(1+AG19))*(1+AH19))*AE19 -> 0 | AM19: =(($AF19*(1+$AG19))*(1+$AH19))*G19 -> 0 | AN19: =(($AF19*(1+$AG19))*(1+$AH19))*H19 -> 0 | AO19: =(($AF19*(1+$AG19))*(1+$AH19))*I19 -> 0 | AP19: =(($AF19*(1+$AG19))*(1+$AH19))*J19 -> 0 | AQ19: =(($AF19*(1+$AG19))*(1+$AH19))*K19 -> 0 | AR19: =(($AF19*(1+$AG19))*(1+$AH19))*L19 -> 0 | AS19: =(($AF19*(1+$AG19))*(1+$AH19))*M19 -> 0 | AT19: =(($AF19*(1+$AG19))*(1+$AH19))*N19 -> 0 | ... BH19: =(($AF19*(1+$AG19))*(1+$AH19))*AB19 -> 0 | BJ19: =SUM(AM19:BH19) -> 0 | BK19: =EXACT(BJ19,AI19) -> TRUE | BL19: =BJ19-AI19 -> 0
A20: 17 | AC20: =SUM(G20:AB20) -> 0 | AD20: 1 | AE20: =ROUNDUP(AC20*AD20, 0) -> 0 | AF20: =F20 -> 0 | AG20: 0 | AH20: 0.05 | AI20: =((AF20*(1+AG20))*(1+AH20))*AE20 -> 0 | AM20: =(($AF20*(1+$AG20))*(1+$AH20))*G20 -> 0 | AN20: =(($AF20*(1+$AG20))*(1+$AH20))*H20 -> 0 | AO20: =(($AF20*(1+$AG20))*(1+$AH20))*I20 -> 0 | AP20: =(($AF20*(1+$AG20))*(1+$AH20))*J20 -> 0 | AQ20: =(($AF20*(1+$AG20))*(1+$AH20))*K20 -> 0 | AR20: =(($AF20*(1+$AG20))*(1+$AH20))*L20 -> 0 | AS20: =(($AF20*(1+$AG20))*(1+$AH20))*M20 -> 0 | AT20: =(($AF20*(1+$AG20))*(1+$AH20))*N20 -> 0 | ... BH20: =(($AF20*(1+$AG20))*(1+$AH20))*AB20 -> 0 | BJ20: =SUM(AM20:BH20) -> 0 | BK20: =EXACT(BJ20,AI20) -> TRUE | BL20: =BJ20-AI20 -> 0
... A139: 136 | AC139: =SUM(G139:AB139) -> 0 | AD139: 1 | AE139: =ROUNDUP(AC139*AD139, 0) -> 0 | AF139: =F139 -> 0 | AG139: 0 | AH139: 0.05 | AI139: =((AF139*(1+AG139))*(1+AH139))*AE139 -> 0 | AM139: =(($AF139*(1+$AG139))*(1+$AH139))*G139 -> 0 | AN139: =(($AF139*(1+$AG139))*(1+$AH139))*H139 -> 0 | AO139: =(($AF139*(1+$AG139))*(1+$AH139))*I139 -> 0 | AP139: =(($AF139*(1+$AG139))*(1+$AH139))*J139 -> 0 | AQ139: =(($AF139*(1+$AG139))*(1+$AH139))*K139 -> 0 | AR139: =(($AF139*(1+$AG139))*(1+$AH139))*L139 -> 0 | AS139: =(($AF139*(1+$AG139))*(1+$AH139))*M139 -> 0 | AT139: =(($AF139*(1+$AG139))*(1+$AH139))*N139 -> 0 | ... BH139: =(($AF139*(1+$AG139))*(1+$AH139))*AB139 -> 0 | BJ139: =SUM(AM139:BH139) -> 0 | BK139: =EXACT(BJ139,AI139) -> TRUE | BL139: =BJ139-AI139 -> 0
C140: ---
AF144: Sub-total | AI144: =SUBTOTAL(9, AI4:AI140) -> 1710.0825 | AL144: Sub-total | AM144: =SUM(AM4:AM140)-$BL$144 -> 1710.0825 | AN144: =SUM(AN4:AN140)-$BL$144 -> 0 | AO144: =SUM(AO4:AO140)-$BL$144 -> 0 | AP144: =SUM(AP4:AP140)-$BL$144 -> 0 | AQ144: =SUM(AQ4:AQ140)-$BL$144 -> 0 | AR144: =SUM(AR4:AR140)-$BL$144 -> 0 | AS144: =SUM(AS4:AS140)-$BL$144 -> 0 | AT144: =SUM(AT4:AT140)-$BL$144 -> 0 | ... BH144: =SUM(BH4:BH140)-$BL$144 -> 0 | BK144: DIFF: | BL144: =SUM(BL4:BL140)/COUNTA(AM3:BH3) -> 0
AF145: TOTAL | AI145: =SUM(AI4:AI140) -> 1710.0825 | AL145: TOTAL | AM145: =SUBTOTAL(9, AM4:AM140)-$BL$144 -> 1710.0825 | AN145: =SUBTOTAL(9, AN4:AN140)-$BL$144 -> 0 | AO145: =SUBTOTAL(9, AO4:AO140)-$BL$144 -> 0 | AP145: =SUBTOTAL(9, AP4:AP140)-$BL$144 -> 0 | AQ145: =SUBTOTAL(9, AQ4:AQ140)-$BL$144 -> 0 | AR145: =SUBTOTAL(9, AR4:AR140)-$BL$144 -> 0 | AS145: =SUBTOTAL(9, AS4:AS140)-$BL$144 -> 0 | AT145: =SUBTOTAL(9, AT4:AT140)-$BL$144 -> 0 | ... BH145: =SUBTOTAL(9, BH4:BH140)-$BL$144 -> 0
G253: Cubicle 2000x1000x400 (HxWxD) with cable compartment.
G254: Motor circuit breaker, 30A
G255: Miniature Circuit breaker 1 x 10A
G256: Miniature Circuit breaker 1 x 6A
G257: Terminals, 4q
G258: PE -Terminals, 4q
G259: Cable ducts 40x80 mm
G260: Bus bars for screen connection, 500 mm
G261: EMC screen connectors for bus bar,
G262: Installing of switch board
G263: Labelling of equipments
G264: Labelling of cubicles
... G275: --

Sheet Components
A1: Components drop-down list
A2: Enclosures
A3: Components
A4: Fan + Filter
A5: Thermostat
A6: Busbar
A7: Isolator
A8: Terminal Board
A9: Power Supply
A10: MPCB
A11: MCB
A12: Contactor
... A39: Consumables

Sheet Monitoring
B1: Estimated | C1: Actual | D1: Profit | E1: % difference
A2: Material | B2: ='TotalCosts (Hrs)'!AF144 -> 1881.0908 | C2: =B16+B27 -> 0 | D2: =B2-C2 -> 1881.0908 | E2: =D2/B2 -> 1
A3: Labour | B3: ='TotalCosts (Hrs)'!AJ144*45 -> 0 | C3: =B38*32 -> 0 | D3: =B3-C3 -> 0 | E3: =D3/B3 -> #DIV/0!
A4: TOTAL | B4: =SUM(B2:B3) -> 1881.0908 | C4: =SUM(C2:C3) -> 0 | D4: =B4-C4 -> 1881.0908 | E4: =D4/B4 -> 1
A7: POs | B7: Value
A15: --- | B15: ---
A16: TOTAL | B16: =SUM(B8:B14) -> 0
A18: Reqs | B18: Value
A26: --- | B26: ---
A27: TOTAL | B27: =SUM(B19:B25) -> 0
A29: Labour | B29: Hours
A37: --- | B37: ---
A38: TOTAL | B38: =SUM(B30:B36) -> 0

Sheet Shipping Costs
A1: SUPPLIER | B1: COUNTRY of ORIGIN | E1: PO value Range / € | F1: Shipping Cost / € | H1: PO value Range / € | I1: Shipping Cost / € | K1: PO value Range / € | L1: Shipping Cost / €
A2: A.N.WALLIS & CO.LTD | B2: UNITED KINGDOM. | C2: E | E2: <1,000 | F2: min.100 | H2: 2,500-7,000 | I2: 0.07 | K2: >7,000 | L2: 0.055
A3: ARDIC ELEKTRIK SAN VE TIC LTD STI. | B3: TURKEY | C3: E | H3: 15,000-25,000 | I3: 0.05 | K3: >25,000 | L3: 0.035
A4: BATT CABLES | B4: UNITED KINGDOM. | C4: E | E4: <1,000 | F4: min.100 | H4: 1,000-2,000 | I4: 0.1 | K4: 2,000-7,000 | L4: 7%
A5: BATT CABLES | B5: UNITED KINGDOM. | C5: E | E5: 7,000-10,000 | F5: 0.06 | H5: 10,000-20,000 | I5: 0.05 | K5: >40,000 | L5: 0.04
A6: BEGHELLI - ELPLAST A.S. | B6: CZECH REPUBLIC | C6: E | E6: <1,000 | F6: min.100 | H6: 1,000-2,000 | I6: 0.08
A7: BEGHELLI - ELPLAST A.S. | B7: CZECH REPUBLIC | C7: E | E7: 2,000-4,000 | F7: 6% | H7: 10,000-16,000 | I7: 0.05 | K7: >25,000 | L7: 0.035
A8: CLEVELAND CABLE CO. LTD | B8: UNITED KINGDOM | C8: E | E8: <1,000 | F8: min.100 | H8: 3,000-5,000 | I8: 0.07 | K8: >7,000 | L8: 0.055
A9: COMAT | B9: TURKEY | C9: E | E9: 550 | F9: 380 | H9: 2000 | I9: 550 | K9: >25,000 | L9: 0.08
A10: IGUZZINI | B10: ITALY | C10: E | F10: CIF
A11: IM.E.B SRL | B11: ITALY | C11: E | E11: <1,000 | F11: min.70 | H11: 1,000-5000 | I11: 8 | K11: >28,000 | L11: 0.035
A12: IMPLEX EXPORT LIMITED | B12: UNITED KINGDOM. | C12: E | E12: <1,000 | F12: min.100 | H12: 3,000-8,000 | I12: 0.07 | K12: >8,000 | L12: 0.055
A13: INTERSWITCH SRL | B13: ITALY | C13: E | E13: <1,000 | F13: min.85 | H13: 1,000-5,000 | I13: 0.06 | K13: >10,000 | L13: 0.045
A14: MARSHALL TUFFLEX INT.LTD | B14: UNITED KINGDOM. | C14: E | E14: <1,000 | F14: min.100 | H14: 1,000-4,000 | I14: 0.07 | K14: >20,000 | L14: 0.05
A15: N.C.M | B15: ITALY | C15: E | E15: <2,000 | F15: min.200
A16: NUOVA CARPENTERIA MECCANICA SNC | B16: ITALY | C16: E | E16: <1,500 | F16: min.110 | H16: 1,500-3,000 | I16: 0.06
A17: SADA CAVI S.P.A. | B17: ITALY | C17: E | E17: <1,000 | F17: min.85 | H17: 3,000-6,000 | I17: 0.06 | K17: >90,000 | L17: 0.035
A18: SEVAL KABLO A.S. | B18: TURKEY | C18: E | F18: CIF
A19: SPECIAL CAVI | B19: ITALY | C19: E | E19: <2,000 | F19: min.130 | H19: 2,000-10,000 | I19: 0.07 | K19: >20,000 | L19: 0.03
A20: TEKOM PUK | B20: TURKEY | C20: E | H20: 5,000-15,0000 | I20: 0.13 | K20: >20,000 | L20: 0.15
A21: VATAN KABLO | B21: TURKEY | C21: E | K21: >50,000 | L21: 0.04
A22: ZUCCHINI SpA | B22: ITALY | C22: E | E22: <1,000 | F22: min.100 | H22: 1,000-6,000 | I22: 0.06 | K22: >100,000 | L22: 0.035
A24: SUPPLIER | B24: COUNTRY of ORIGIN | E24: PO value Range / € | F24: Shipping Cost / € | H24: PO value Range / € | I24: Shipping Cost / € | K24: PO value Range / € | L24: Shipping Cost / €
A25: 3I INTERNATIONAL INNOVATIVE INDUSTRIES S.A. | B25: GREECE | C25: M | E25: <5,000 | F25: 6% | H25: 5,000 - 15,000 | I25: 0.05 | K25: >15,000 | L25: 0.04
A26: ACTIONCLIMA SRL | B26: ITALY | C26: M | E26: <2,000 | F26: min.100
A27: ADVANCED AIR (UK) LTD | B27: UNITED KINGDOM. | C27: M | E27: <4,000 | F27: 9% | H27: 4,000 - 8,000 | I27: 0.07 | K27: >8,000 | L27: 0.06
A28: AIREDALE INTERNATIONAL, | B28: UNITED KINGDOM. | C28: M | E28: <1,000 | F28: min.85 | K28: >15,000 | L28: 0.045
A29: ALNOR SYSTEMY WENTYLACJI SP. Z O.O. | B29: POLAND | C29: M | E29: <7,000 | F29: 9% | H29: 7,000 - 20,000 | I29: 0.05 | K29: >20,000 | L29: (5%) 3.5%
A30: ATS ISOLANTI SRL | B30: ITALY | C30: M | E30: <1,000 | F30: 10% | H30: 2,000 - 10,000 | I30: 0.06 | K30: >10,000 | L30: 0.05
A31: BRODBECK S.R.L | B31: SICILY | C31: M | E31: <1,000 | F31: min.85 | H31: 1,000-2,300 | I31: 0.08 | K31: >2,300 | L31: 0.06
A32: CALEFFI | B32: ITALY | C32: M | H32: >5000 (P.O.10967) | I32: min.100
A33: CENTRAL TUBI | B33: ITALY | C33: M | E33: <1,000 | F33: min.85 | H33: 1,000-10,000 | I33: 0.06 | K33: >10,000 | L33: 0.05
A34: CHEMINEES POUJOULAT | B34: FRANCE | C34: M | K34: >4,000 | L34: 0.06
A35: DAB PUMPS SPA | B35: ITALY | C35: M | E35: <1,000 | F35: min.90 | K35: >15,000 | L35: 0.045
A36: DANTHERM AIR HANDLING A/S | B36: DENMARK | C36: M | K36: >30,000 | L36: 0.035
A37: DINAK S.A., | B37: SPAIN. | C37: M | E37: <1,500 | F37: min.100 | H37: 1,500-10,000 | I37: 0.06 | K37: >10,000 | L37: 0.045
A38: DM SRL | B38: ITALY | C38: M | K38: >10,000 | L38: 0.045
A39: DOGU IKLIMLENDIRME SAN.VE TIC.A.S. | B39: TURKEY | C39: M | E39: <1,000 | F39: min.100 | H39: 1,000-10,000 | I39: 0.06 | K39: >10,000 | L39: 0.05
A40: DUYAR VANA MAK. SAN. VE TIC. A.S. | B40: TURKEY | C40: M | H40: 6,000-10,000 | I40: 0.05 | K40: >10,000 | L40: 0.045
A41: ELTA FANS LIMITED | B41: UNITED KINGDOM. | C41: M | E41: <1,000 | F41: min.100 | H41: 1,000-2,500 | I41: 0.1 | K41: >2,500 | L41: 0.06
...
