Workbook
Name _N: #REF!
Name _N: #REF!
Name A: #REF!
Name A: #REF!
Name Access_BMS: [2]BMS_Estimate!#REF!
Name Access_BMS: [2]BMS_Estimate!#REF!
Name Access_Control: [3]Elec_Est!#REF!
Name Access_Control: [4]Elec_Est!#REF!
Name Access_Supply: [2]BMS_Estimate!#REF!
Name Access_Supply: [2]BMS_Estimate!#REF!
Name Access_Wiring: [2]BMS_Estimate!#REF!
Name Access_Wiring: [2]BMS_Estimate!#REF!
Name ANS: #REF!
Name ANS: #REF!
Name AREAS: #REF!
Name AREAS: [4]ML_Sum!$X$1:$AD$16
Name AREAS: ML_Sum!$X$1:$AD$16
Name C_: #REF!
Name C_: #REF!
Name CCTV: [3]Elec_Est!#REF!
Name CCTV: [4]Elec_Est!#REF!
Name Data: [3]Elec_Est!#REF!
Name Data: [4]Elec_Est!#REF!
Name DATA_SYSTEM: #REF!
Name DD_Head_Foot: [5]!T_HeadFoot[Head-Foot]
Name FIRE_ALARM: #REF!
Name Fire_Alarm: [4]Elec_Est!#REF!
Name FO: [3]Elec_Est!#REF!
Name FO: [4]Elec_Est!#REF!
Name Guard: [3]Elec_Est!#REF!
Name Guard: [4]Elec_Est!#REF!
Name Intercom: [3]Elec_Est!#REF!
Name Intercom: [4]Elec_Est!#REF!
Name Intruder_Alarm: [3]Elec_Est!#REF!
Name Intruder_Alarm: [4]Elec_Est!#REF!
Name LIGHTNING_PROTECTION: #REF!
Name Persons: [6]Estimate!#REF!
Name Persons: [6]Estimate!#REF!
Name RAMON: #REF!
Name T: #REF!
Name T: #REF!
Name Traffic_Barriers: [2]BMS_Estimate!#REF!
Name Traffic_Barriers: [2]BMS_Estimate!#REF!
Name Z: #REF!
Name Z: #REF!

Sheet Notes
A1: NOTES:
A3: PRELIMINARIES BOQ:
A5: 1 | B5: BOQ Item 11 | C5: We have allowed for wall penetrations up to 300x300mm. For safety reason, larger openings are to be carried out by the building contractor.
A7: 2 | B7: BOQ Item 15 | C7: Submittal forms for materials are included. However, samples if required will be charged at cost.
A9: 3 | B9: BOQ Item 17 | C9: Provision of Local Council Permits will be charged at cost against receipts.
A12: ELECTRICAL BOQ:
A14: 1 | B14: BOQ Item 6.0d | C14: We have not quoted to supply the Battery Backup Kit for the light fittings supplied by others Type 'LT-02' and Type 'LT-15'. Also because, for other floors there are only BOQ items for installation and connect only.
A16: 2 | B16: BOQ Item 19.0c | C16: We have allowed for two floor outlet boxes, 1No 3 Compartment and 1No 2 Compartment. The floor outlet boxes are suitable for cleaning with a damp cloth.
A18: 3 | B18: BOQ Item 77 | C18: Since in the tender documents the bonding points to the metallic structures are not indicated, we have allowed for 20No bonding points. Each bond consists of 2m x 10sqmm LSZH Single core cable complete with cable termination.
A20: 4 | B20: Various BOQ Items | C20: Cable containment Tray and Trunking. The tray and trunking fittings will be fabricated on site because the building contour in general is not at a 90deg angle.
A23: EMERGENCY STANDBY GENERATOR BOQ BOQ:
A25: 1 | B25: Emergency Standby Generator BOQ Itemes 1 & 2 | C25: The Generator support structure or plinth is excluded.
C26: We have allowed for the diesel for the commissioning and for filling the day tank after the commissioning.

Sheet LSZH_Conduit
A1: KOUVIDIS - MEDISOL HF CONDUIT (For MFA Project)
E2: KOUVIDS HF Conduit System
E3: FCA | F3: 0.95
A4: Item | B4: Description | C4: Unit | D4: Qty | E4: Unit Price | G4: Total Price
A5: 1 | B5: 3m x 20mm HF Medium type Conduit (Ref. 1005020) | C5: Lenghts | D5: 3600 | E5: =0.595*2.9 -> 1.7255 | F5: =E5*$F$3 -> 1.639225 | G5: =D5*F5 -> 5901.21
A6: 2 | B6: 20mm HF Coupler (Ref. 4001020) | C6: No | D6: 1000 | E6: 0.084 | F6: =E6*$F$3 -> 0.0798 | G6: =D6*F6 -> 79.8
A7: 3 | B7: 20mm HF Bend (Ref. 4015020) | C7: No | D7: 500 | E7: 0.545 | F7: =E7*$F$3 -> 0.51775 | G7: =D7*F7 -> 258.875
A8: 4 | B8: 82x82x43mm HF Watertight Box (Ref. 3001020) | C8: No | D8: 300 | E8: 1.174 | F8: =E8*$F$3 -> 1.1153 | G8: =D8*F8 -> 334.59
A9: 5 | B9: 20mm HF Adaptor for Watertight Box (Ref. 4005020) | C9: No | D9: 500 | E9: 0.074 | F9: =E9*$F$3 -> 0.0703 | G9: =D9*F9 -> 35.15
A10: 6 | B10: 20mm HF Conduit Clip (Ref. 4003020) | C10: No | D10: 700 | E10: 0.096 | F10: =E10*$F$3 -> 0.0912 | G10: =D10*F10 -> 63.84
A11: 7 | B11: 3m x 25mm HF Medium type Conduit (Ref. 1005025) | C11: Lenghts | D11: 120 | E11: =0.889*2.9 -> 2.5781 | F11: =E11*$F$3 -> 2.449195 | G11: =D11*F11 -> 293.9034
A12: 8 | B12: 25mm HF Coupler (Ref. 4001025) | C12: No | D12: 50 | E12: 0.116 | F12: =E12*$F$3 -> 0.1102 | G12: =D12*F12 -> 5.51
A13: 9 | B13: 25mm HF Bend (Ref. 4015025) | C13: No | D13: 50 | E13: 0.983 | F13: =E13*$F$3 -> 0.93385 | G13: =D13*F13 -> 46.6925
A14: 10 | B14: 101x101x51mm HF Watertight Box (Ref. 3001025) | C14: No | D14: 50 | E14: 1.916 | F14: =E14*$F$3 -> 1.8202 | G14: =D14*F14 -> 91.01
A15: 11 | B15: 25mm HF Adaptor for Watertight Box (Ref. 4005025) | C15: No | D15: 150 | E15: 0.167 | F15: =E15*$F$3 -> 0.15865 | G15: =D15*F15 -> 23.7975
A16: 12 | B16: 25mm HF Conduit Clip (Ref. 4003025) | C16: No | D16: 200 | E16: 0.148 | F16: =E16*$F$3 -> 0.1406 | G16: =D16*F16 -> 28.12
A17: 13 | B17: 20mm Flexible Conduit (MEDIFLEX HF 33442) Part No. 2005020 | C17: m | D17: 300 | E17: 0.414 | F17: =E17*$F$3 -> 0.3933 | G17: =D17*F17 -> 117.99
A18: 14 | B18: 25mm Flexible Conduit (MEDIFLEX HF 33442) Part No. 2005025 | C18: m | D18: 100 | E18: 0.616 | F18: =E18*$F$3 -> 0.5852 | G18: =D18*F18 -> 58.52
G20: =SUM(G5:G19) -> 7339.0084
D24: cost/total | E24: m | F24: cost/m
C25: 20mm HF Medium type Conduit | D25: =SUM(G5:G10) -> 6673.465 | E25: =3600*2.9 -> 10440 | F25: =D25/E25 -> 0.63922079 | G25: =F25*$G$35 -> 0.67216064 | H25: /m
C26: 25mm HF Medium type Conduit | D26: =SUM(G11:G16) -> 489.0334 | E26: =120*2.9 -> 348 | F26: =D26/E26 -> 1.4052684 | G26: =F26*$G$35 -> 1.4776836 | H26: /m
C27: 20mm Flexible Conduit (MEDIFLEX HF 33442) Part No. 2005020 | D27: =G17 -> 117.99 | E27: 300 | F27: =D27/E27 -> 0.3933 | G27: =F27*$G$35 -> 0.41356725 | H27: /m
C28: 25mm Flexible Conduit (MEDIFLEX HF 33442) Part No. 2005025 | D28: =G18 -> 58.52 | E28: 100 | F28: =D28/E28 -> 0.5852 | G28: =F28*$G$35 -> 0.61535609 | H28: /m
D30: Stock Order | G30: For MFA
C31: KOUVIDIS PO 100033 | D31: 33183.74 | G31: 7339.01 | H31: Cost excluding the shipping
C32: Shipping and Delivery Cost | D32: 1710 | G32: =G31/D31*D32 -> 378.18845 | H32: Shipping cost
C33: Total | D33: =D31+D32 -> 34893.74 | G33: =G31+G32 -> 7717.1984 | H33: Total Cost
F35: Multiplying factor for the shipping | G35: =G33/G31 -> 1.0515313

Sheet Material_List
A1: QTY | B1: UNIT | C1: MATERIAL DESCRIPTION | D1: C/CODE
A2: 163.07692 | B2: No | C2: Anchor 8mm HKD M8X30 376959 | D2: 501
A3: =SUBTOTAL(9,A2:A2) -> 163.07692 | B3: No | C3: Anchor 8mm HKD M8X30 376959 | D3: 501
A4: 209.67033 | B4: No | C4: Channel 40x20 Endcap MQZ-E21 370598 | D4: 501
A5: =SUBTOTAL(9,A4:A4) -> 209.67033 | B5: No | C5: Channel 40x20 Endcap MQZ-E21 370598 | D5: 501
A6: 93.186813 | B6: No | C6: Channel 40x40 Endcap MQZ-E41 369685 | D6: 501
A7: =SUBTOTAL(9,A6:A6) -> 93.186813 | B7: No | C7: Channel 40x40 Endcap MQZ-E41 369685 | D7: 501
A8: 25.626374 | B8: m | C8: Channel DEEP MQ-41-F 3m 304099 | D8: 501
A9: =SUBTOTAL(9,A8:A8) -> 25.626374 | B9: m | C9: Channel DEEP MQ-41-F 3m 304099 | D9: 501
A10: 43.098901 | B10: m | C10: Channel SHALLOW MQ-21-F 3m 304096 | D10: 501
A11: =SUBTOTAL(9,A10:A10) -> 43.098901 | B11: m | C11: Channel SHALLOW MQ-21-F 3m 304096 | D11: 501
A12: 244.61538 | B12: No | C12: Galv. Nut 8mm M8-F 304764 | D12: 501
A13: =SUBTOTAL(9,A12:A12) -> 244.61538 | B13: No | C13: Galv. Nut 8mm M8-F 304764 | D13: 501
A14: 244.61538 | B14: No | C14: Hex.Set Screw M8x25 216448 | D14: 501
A15: =SUBTOTAL(9,A14:A14) -> 244.61538 | B15: No | C15: Hex.Set Screw M8x25 216448 | D15: 501
A16: 93.186813 | B16: No | C16: HLC Sleeve Anchor 10mm HLC 10x50/15 385820 | D16: 501
A17: =SUBTOTAL(9,A16:A16) -> 93.186813 | B17: No | C17: HLC Sleeve Anchor 10mm HLC 10x50/15 385820 | D17: 501
A18: 163.07692 | B18: No | C18: Pipe Ring Saddle MQA-M 8-F 304138 | D18: 501
A19: =SUBTOTAL(9,A18:A18) -> 163.07692 | B19: No | C19: Pipe Ring Saddle MQA-M 8-F 304138 | D19: 501
A20: 69.89011 | B20: No | C20: Push Button Hilti M10 MQN-F 304130 | D20: 501
A21: =SUBTOTAL(9,A20:A20) -> 69.89011 | B21: No | C21: Push Button Hilti M10 MQN-F 304130 | D21: 501
A22: 81.538462 | B22: m | C22: Threaded Rod Galv. 8mm 339793 | D22: 501
A23: =SUBTOTAL(9,A22:A22) -> 81.538462 | B23: m | C23: Threaded Rod Galv. 8mm 339793 | D23: 501
A24: 23.296703 | B24: No | C24: Three hole angle Hilti 90deg MQW-3-F 304172 | D24: 501
A25: =SUBTOTAL(9,A24:A24) -> 23.296703 | B25: No | C25: Three hole angle Hilti 90deg MQW-3-F 304172 | D25: 501
A26: 244.61538 | B26: No | C26: Tray Washers M8 304769 | D26: 501
A27: =SUBTOTAL(9,A26:A26) -> 244.61538 | B27: No | C27: Tray Washers M8 304769 | D27: 501
A28: 244.61538 | B28: No | C28: Wing Nut Hilti M8 MQM-M8-F 304132 | D28: 501
A29: =SUBTOTAL(9,A28:A28) -> 244.61538 | B29: No | C29: Wing Nut Hilti M8 MQM-M8-F 304132 | D29: 501
A30: 1 | B30: No | C30: 18M KAEDRA ENCLOSURE 1X18 IP65 | D30: 510
A31: 1 | B31: No | C31: 18M KAEDRA ENCLOSURE 1X18 IP65 | D31: 510
A32: =SUBTOTAL(9,A30:A31) -> 2 | B32: No | C32: 18M KAEDRA ENCLOSURE 1X18 IP65 | D32: 510
A33: 1 | B33: No | C33: 60kVAR Power Factor Correction Unit (PFCU) | D33: 510
A34: =SUBTOTAL(9,A33:A33) -> 1 | B34: No | C34: 60kVAR Power Factor Correction Unit (PFCU) | D34: 510
A35: 1 | B35: No | C35: GS DELAY ALARM | D35: 510
A36: 1 | B36: No | C36: GS DELAY ALARM | D36: 510
A37: =SUBTOTAL(9,A35:A36) -> 2 | B37: No | C37: GS DELAY ALARM | D37: 510
A38: 1 | B38: No | C38: MODULAR AUTO CHANGE OVER 63A 4P | D38: 510
A39: 1 | B39: No | C39: MODULAR AUTO CHANGE OVER 63A 4P | D39: 510
A40: =SUBTOTAL(9,A38:A39) -> 2 | B40: No | C40: MODULAR AUTO CHANGE OVER 63A 4P | D40: 510
...

Sheet HDG_Tray_Brackets
A1: TRAY BRACKETS CALCULATOR
B4: PROJECT: | C4: Britannia Hotel
B6: AREA: | C6: All Areas
C10: Wall (W) | F10: Ceiling (C) | I10: Floor (F) | L10: Riser (R)
B11: Brackets intervals @ (M) | C11: 1 | F11: 1 | I11: 1 | L11: 1
B13: Distance from tray side to wall (M) | C13: 0.2 | D13: =IF($C$13<0.31,0,1) -> 0
B15: Distance from ceiling (M) | F15: 0.5
B17: Distance from floor (M) | I17: 0.1
R21: LABOUR FACTOR
C22: Wall (W) | D22: Wall (W) | E22: Wall (W) | F22: Ceiling (C) | G22: Ceiling (C) | H22: Ceiling (C) | I22: Floor (F) | J22: Floor (F) | K22: Floor (F) | L22: Riser (R) | P22: Total (M) | R22: Unit | S22: Total
E23: Labour | H23: Labour | K23: Labour | N23: Labour
B24: 900mm Tray (Length M) | D24: =1+0.3+$C$13*2 -> 1.7 | E24: 0.6 | G24: =1*$F$15*2 -> 1 | H24: 0.75 | J24: =1+$I$17*2 -> 1.2 | K24: 0.75 | M24: 1 | N24: 0.3 | P24: =C24+F24+I24+L24 -> 0 | R24: 2.6 | S24: =R24*(C24+F24+I24+L24) -> 0
B26: 700mm Tray (Length M) | D26: =0.8+0.3+$C$13*2 -> 1.5 | E26: 0.6 | G26: =0.8*$F$15*2 -> 0.8 | H26: 0.75 | J26: =0.8+$I$17*2 -> 1 | K26: 0.75 | M26: 0.8 | N26: 0.3 | P26: =C26+F26+I26+L26 -> 0 | R26: 2.4 | S26: =R26*(C26+F26+I26+L26) -> 0
B28: 600mm Tray (Length M) | D28: =0.7+0.3+$C$13*2 -> 1.4 | E28: 0.5 | G28: =0.7*$F$15*2 -> 0.7 | H28: 0.65 | J28: =0.7+$I$17*2 -> 0.9 | K28: 0.65 | M28: 0.7 | N28: 0.3 | P28: =C28+F28+I28+L28 -> 0 | R28: 2.2 | S28: =R28*(C28+F28+I28+L28) -> 0
B30: 500mm Tray (Length M) | D30: =0.6+0.3+$C$13*2 -> 1.3 | E30: 0.5 | F30: 10 | G30: =0.6*$F$15*2 -> 0.6 | H30: 0.65 | J30: =0.6+$I$17*2 -> 0.8 | K30: 0.65 | L30: 10 | M30: 0.6 | N30: 0.3 | P30: =C30+F30+I30+L30 -> 20 | R30: 2 | S30: =R30*(C30+F30+I30+L30) -> 40
B32: 400mm Tray (Length M) | D32: =0.5+0.3+$C$13*2 -> 1.2 | E32: 0.4 | F32: 10 | G32: =0.5*$F$15*2 -> 0.5 | H32: 0.5 | J32: =0.5+$I$17*2 -> 0.7 | K32: 0.5 | L32: 20 | M32: 0.5 | N32: 0.25 | P32: =C32+F32+I32+L32 -> 30 | R32: 1.8 | S32: =R32*(C32+F32+I32+L32) -> 54
B34: 300mm Tray (Length M) | D34: =0.41+0.25+$C$13*2 -> 1.06 | E34: 0.4 | F34: 10 | G34: =0.4*$F$15*2 -> 0.4 | H34: 0.5 | J34: =0.4+$I$17*2 -> 0.6 | K34: 0.5 | M34: 0.4 | N34: 0.25 | P34: =C34+F34+I34+L34 -> 10 | R34: 1.6 | S34: =R34*(C34+F34+I34+L34) -> 16
B36: 200mm Tray (Length M) | D36: =0.3+0.25+$C$13*2 -> 0.95 | E36: 0.3 | F36: 30 | G36: =0.3*$F$15*2 -> 0.3 | H36: 0.35 | J36: =0.3+$I$17*2 -> 0.5 | K36: 0.35 | M36: 0.3 | N36: 0.25 | P36: =C36+F36+I36+L36 -> 30 | R36: 1.4 | S36: =R36*(C36+F36+I36+L36) -> 42
B38: 150mm Tray (Length M) | D38: =0.25+0.25+$C$13*2 -> 0.9 | E38: 0.25 | G38: =0.25*$F$15*2 -> 0.25 | H38: 0.35 | J38: =0.25+$I$17*2 -> 0.45 | K38: 0.35 | M38: 0.25 | N38: 0.2 | P38: =C38+F38+I38+L38 -> 0 | R38: 1.2 | S38: =R38*(C38+F38+I38+L38) -> 0
B40: 100mm Tray (Length M) | C40: 20 | D40: =0.2+0.25+$C$13*2 -> 0.85 | E40: 0.25 | F40: 10 | G40: =0.2*$F$15*2 -> 0.2 | H40: 0.3 | J40: =0.2+$I$17*2 -> 0.4 | K40: 0.35 | M40: 0.2 | N40: 0.2 | P40: =C40+F40+I40+L40 -> 30 | R40: 1 | S40: =R40*(C40+F40+I40+L40) -> 30
P42: =SUM(P24:P40) -> 120 | S42: =SUM(S24:S40) -> 182
B46: HILTI Material Description | C46: Part No. | F46: Total Qty | I46: Unit Cost € | L46: Total Cost €
I47: Per M / Each
B48: Channel DEEP MQ-41-F 3m | C48: 304099 | F48: =(((C24*D24)/C11)+((F24*G24)/F11)+((I24*J24)/I11)+((L24*M24)/L11))+(((C26*D26)/C11)+((F26*G26)/F11)+((I26*J26)/I11)+((L26*M26)/L11))+(((C28*D28)/C11)+((F28*G28)/F11)+((I28*J28)/I11)+((L28*M28)/L11))+(((C30*D30)/C11)+((F30*G30)/F11)+((I30*J30)/I11)+((L30*M30)/L11)+((L32*M32)/L11)+((L34*M34)/L11)+((L36*M36)/L11)+((L38*M38)/L11)+((L40*M40)/L11)+((I32*J32)/I11)+((I34*J34)/I11)+((I36*J36)/I11)+((I38*J38)/I11)+((I40*J40)/I11)) -> 22 | I48: 5.05 | L48: =I48*F48 -> 111.1
B49: Channel SHALLOW MQ-21-F 3m | C49: 304096 | F49: =((C32*D32)/C11)+((F32*G32)/F11)+((C34*D34)/C11)+((F34*G34)/F11)+((C36*D36)/C11)+((F36*G36)/F11)+((C38*D38)/C11)+((F38*G38)/F11)+((C40*D40)/C11)+((F40*G40)/F11) -> 37 | I49: 4.05 | L49: =I49*F49 -> 149.85
B50: Channel 40x20 Endcap MQZ-E21 | C50: 370598 | F50: =(((C32/C11)*3)+((F32/F11)*2)+((C34/C11)*3)+((F34/F11)*2)+((C36/C11)*3)+((F36/F11)*2)+((C38/C11)*3)+((F38/F11)*2)+((C40/C11)*3)+((F40/F11)*2)) -> 180 | I50: 0.0524 | L50: =I50*F50 -> 9.432
B51: Channel 40x40 Endcap MQZ-E41 | C51: 369685 | F51: =(((C24/C11)*3)+((F24/F11)*2)+((L24/L11)*2))+(((C26/C11)*3)+((F26/F11)*2)+((L26/L11)*2))+(((C28/C11)*3)+((F28/F11)*2)+((L28/L11)*2))+(((C30/C11)*3)+((F30/F11)*2)+((L30/L11)*2)+((L32/L11)*2)+((L34/L11)*2)+((L36/L11)*2)+((L38/L11)*2)+((L40/L11)*2)) -> 80 | I51: 0.0533 | L51: =I51*F51 -> 4.264
B52: Three hole angle Hilti 90deg MQW-3-F | C52: 304172 | F52: =((C24/C11)+((F24/F11)*4)+((I24/I11)*2))+((C26/C11)+((F26/F11)*4)+((I26/I11)*2))+(((C28/C11)*2)+((I28/I11)*2))+(((C30/C11)*2)+((I30/I11)*2))+(((C32/C11)*1)+((I32/I11)*2))+(((C34/C11)*1)+((I34/I11)*2))+(((C36/C11)*1)+((I36/I11)*2))+(((C38/C11)*1)+((I38/I11)*2))+(((C40/C11)*1)+((I40/I11)*2)) -> 20 | I52: 0.68 | L52: =I52*F52 -> 13.6
B53: Two Hole Angle Hilti 90deg MQW-2-F | C53: 304171 | F53: =(((I24/I11)*2))+(((I26/I11)*2))+(((I28/I11)*2))+(((I30/I11)*2))+(((I32/I11)*2))+(((I34/I11)*2))+(((I36/I11)*2))+(((I38/I11)*2))+(((I40/I11)*2)) -> 0 | I53: 0.53 | L53: =I53*F53 -> 0
B54: Long Angle Brace MQK-SL-F | C54: 304128 | F54: =ROUND(($D$13/$C$11)*(C30+C32+C34+C36+C38+C40)+((C24+C26+C28)/C11),0) -> 0 | I54: 7.03 | L54: =I54*F54 -> 0
B55: HLC Sleeve Anchor 10mm HLC 10x50/15 | C55: 385820 | F55: =(((C24/C11)*2)+((F24/F11)*2)+((I24/I11)*2)+((L24/L11)*2))+(((C26/C11)*2)+((F26/F11)*2)+((I26/I11)*2)+((L26/L11)*2))+((C28/C11)+(L28/L11)*2)+((C30/C11)+(L30/L11)*2)+((C32/C11)+(L32/L11)*2)+((C34/C11)+(L34/L11)*2)+((C36/C11)+(L36/L11)*2)+((C38/C11)+(L38/L11)*2)+((C40/C11)+(L40/L11)*2)+F54+((I24/I11)*2)+((I26/I11)*2)+((I28/I11)*2)+((I30/I11)*2)+((I32/I11)*2)+((I34/I11)*2)+((I36/I11)*2)+((I38/I11)*2)+((I40/I11)*2) -> 80 | I55: 0.1516 | L55: =I55*F55 -> 12.128
B56: Push Button Hilti M10 MQN-F | C56: 304130 | F56: =(((C24/C11)*3)+((F24/F11)*10)+((I24/I11)*6))+(((C26/C11)*3)+((F26/F11)*10)+((I26/I11)*6))+(((C28/C11)*3)+((I28/I11)*6))+(((C30/C11)*3)+((I30/I11)*6))+(((C32/C11)*3)+((I32/I11)*6))+(((C34/C11)*3)+((I34/I11)*6))+(((C36/C11)*3)+((I36/I11)*6))+(((C38/C11)*3)+((I38/I11)*6))+(((C40/C11)*3)+((I40/I11)*6)) -> 60 | I56: 0.91 | L56: =I56*F56 -> 54.6
B57: Pipe Ring Saddle MQA-M 8-F | C57: 304138 | F57: =((F28/F11)*2)+((F30/F11)*2)+((F32/F11)*2)+((F34/F11)*2)+((F36/F11)*2)+((F38/F11)*2)+((F40/F11)*2) -> 140 | I57: 0.8 | L57: =I57*F57 -> 112
B58: Anchor 8mm HKD M8X30 | C58: 376959 | F58: =F57 -> 140 | I58: 0.0943 | L58: =I58*F58 -> 13.202
B59: Wing Nut Hilti M8 MQM-M8-F | C59: 304132 | F59: =(((C24/C11)+(F24/F11)+(I24/I11)+(L24/L11))*2)+(((C26/C11)+(F26/F11)+(I26/I11)+(L26/L11))*2)+(((C28/C11)+(F28/F11)+(I28/I11)+(L28/L11))*2)+(((C30/C11)+(F30/F11)+(I30/I11)+(L30/L11))*2)+(((C32/C11)+(F32/F11)+(I32/I11)+(L32/L11))*2)+(((C34/C11)+(F34/F11)+(I34/I11)+(L34/L11))*2)+(((C36/C11)+(F36/F11)+(I36/I11)+(L36/L11))*2)+(((C38/C11)+(F38/F11)+(I38/I11)+(L38/L11))*1)+(((C40/C11)+(F40/F11)+(I40/I11)+(L40/L11))*1) -> 210 | I59: 0.65 | L59: =I59*F59 -> 136.5
B60: Hex.Set Screw M8x25 | C60: 216448 | F60: =F59 -> 210 | I60: 0.03614 | L60: =I60*F60 -> 7.5894
B61: Threaded Rod Galv. 8mm | C61: 339793 | F61: =(((F28/F11)*F15)*2)+(((F30/F11)*F15)*2)+(((F32/F11)*F15)*2)+(((F34/F11)*F15)*2)+(((F36/F11)*F15)*2)+(((F38/F11)*F15)*2)+(((F40/F11)*F15)*2) -> 70 | I61: 0.47799 | L61: =I61*F61 -> 33.4593
B62: Hex.Set Screw M10x25-F | C62: 304788 | F62: =F54 -> 0 | I62: 0.07683 | L62: =I62*F62 -> 0
B63: Galv. Nut 10mm M10-F | C63: 304765 | F63: =F62 -> 0 | I63: 0.03209 | L63: =I63*F63 -> 0
B64: Washer M10 | C64: 304770 | F64: =F63 -> 0 | I64: 0.02034 | L64: =I64*F64 -> 0
...

Sheet Elec_Rates
B1: CLIENT: | C1: =ML_Sum!$C1 -> 1 | D1: =ML_Sum!$D1 -> Battery Street Limited | F1: =ML_Sum!$F1 -> 0 | I1: 1 | J1: =ML_Sum!$J1 -> 1 | K1: =ML_Sum!$K1 -> 1 | L1: =ML_Sum!$L1 -> 1 | M1: =ML_Sum!$M1 -> 1 | N1: =ML_Sum!$N1 -> 1 | O1: =ML_Sum!$O1 -> 1 | Q1: =ML_Sum!$Q1 -> € | R1: R/Lab Cont | S1: =ML_Sum!$S1 -> R | T1: =ML_Sum!$T1 -> 1.05 | U1: =ML_Sum!W1 -> BOQ | V1: INCL | W1: MULT | X1: AREA | Y1: BOQ | Z1: TDWG | AA1: ACT | AB1: DIFF
B2: PROJECT: | C2: =ML_Sum!$C2 -> 1 | D2: =ML_Sum!$D2 -> MEP Works British Hotel | F2: =ML_Sum!$F2 -> Electrical | I2: 2 | J2: =ML_Sum!$J2 -> 1 | K2: =ML_Sum!$K2 -> 1 | L2: =ML_Sum!$L2 -> 1 | M2: =ML_Sum!$M2 -> 1 | N2: =ML_Sum!$N2 -> 1 | O2: =ML_Sum!$O2 -> 1 | Q2: =ML_Sum!$Q2 -> 0 | R2: mu_A | S2: =ML_Sum!$S2 -> 1.22 | T2: =ML_Sum!$T2 -> 35.17626
B3: JOB DESC: | C3: =ML_Sum!$C3 -> 1 | D3: =ML_Sum!$D3 -> Electrical and ELV Systems | F3: =ML_Sum!$F3 -> Controls Section (DALI) | I3: 3 | J3: =ML_Sum!$J3 -> 1 | K3: =ML_Sum!$K3 -> 1 | L3: =ML_Sum!$L3 -> 1 | M3: =ML_Sum!$M3 -> 1 | N3: =ML_Sum!$N3 -> 1 | O3: =ML_Sum!$O3 -> 1 | Q3: =ML_Sum!$Q3 -> 0 | R3: mu_B | S3: =ML_Sum!$S3 -> 1.22 | T3: =ML_Sum!$T3 -> 86.64
B4: QUOTE No: | C4: =ML_Sum!$C4 -> 1 | D4: =ML_Sum!$D4 -> EL25-0662B | F4: =ML_Sum!$F4 -> Controls Section Engineer (DALI) | I4: 4 | J4: =ML_Sum!$J4 -> 1 | K4: =ML_Sum!$K4 -> 1 | L4: =ML_Sum!$L4 -> 1 | M4: =ML_Sum!$M4 -> 1 | N4: =ML_Sum!$N4 -> 1 | O4: =ML_Sum!$O4 -> 1 | Q4: =ML_Sum!$Q4 -> 0 | R4: mu_C | S4: =ML_Sum!$S4 -> 1.22 | T4: =ML_Sum!$T4 -> 51.41
B5: CLIENTs REF: | C5: =ML_Sum!$C5 -> 1 | D5: =ML_Sum!$D5 -> MEP REVISED | F5: =ML_Sum!$F5 -> ELV Sub-Contractor - APCO | I5: 5 | J5: =ML_Sum!$J5 -> 1 | K5: =ML_Sum!$K5 -> 1 | L5: =ML_Sum!$L5 -> 1 | M5: =ML_Sum!$M5 -> 1 | N5: =ML_Sum!$N5 -> 1 | O5: =ML_Sum!$O5 -> 1 | Q5: =ML_Sum!$Q5 -> 0 | R5: mu_D | S5: =ML_Sum!$S5 -> 1.075 | T5: =ML_Sum!$T5 -> 30.995475
B6: VAT/DUTIES: | C6: =ML_Sum!$C6 -> 1 | D6: =ML_Sum!$D6 -> VAT EXCL. | F6: =ML_Sum!$F6 -> ELV Sub-Contractor - DATA | I6: 6 | J6: =ML_Sum!$J6 -> 1 | K6: =ML_Sum!$K6 -> 1 | L6: =ML_Sum!$L6 -> 1 | M6: =ML_Sum!$M6 -> 1 | N6: =ML_Sum!$N6 -> 1 | O6: =ML_Sum!$O6 -> 1 | Q6: =ML_Sum!$Q6 -> 0 | R6: mu_E | S6: =ML_Sum!$S6 -> 1.1 | T6: =ML_Sum!$T6 -> 31.7163
B7: SAVED ON: | C7: =ML_Sum!$C7 -> 1 | D7: 39364 | F7: =ML_Sum!$F7 -> 0 | I7: 7 | J7: =ML_Sum!$J7 -> 1 | K7: =ML_Sum!$K7 -> 1 | L7: =ML_Sum!$L7 -> 1 | M7: =ML_Sum!$M7 -> 1 | N7: =ML_Sum!$N7 -> 1 | O7: =ML_Sum!$O7 -> 0 | Q7: =ML_Sum!$Q7 -> 0 | R7: mu_F | S7: =ML_Sum!$S7 -> 0 | T7: =ML_Sum!$T7 -> 0
B8: ESTIMATOR: | C8: =ML_Sum!$C8 -> 1 | D8: =ML_Sum!$D8 -> R.Farrugia | F8: =ML_Sum!$F8 -> 0 | I8: 8 | J8: =ML_Sum!$J8 -> 1 | K8: =ML_Sum!$K8 -> 1 | L8: =ML_Sum!$L8 -> 1 | M8: =ML_Sum!$M8 -> 1 | N8: =ML_Sum!$N8 -> 1 | O8: =ML_Sum!$O8 -> 0 | Q8: =ML_Sum!$Q8 -> 0 | R8: mu_G | S8: =ML_Sum!$S8 -> 0 | T8: =ML_Sum!$T8 -> 0
B9: LABOUR RATE: | C9: =ML_Sum!$C9 -> 1 | D9: =ML_Sum!$D9 -> 28.833 | F9: =ML_Sum!$F9 -> 0 | I9: 9 | J9: =ML_Sum!$J9 -> 1 | K9: =ML_Sum!$K9 -> 1 | L9: =ML_Sum!$L9 -> 1 | M9: =ML_Sum!$M9 -> 1 | N9: =ML_Sum!$N9 -> 1 | O9: =ML_Sum!$O9 -> 0 | Q9: =ML_Sum!$Q9 -> 0 | R9: mu_H | S9: =ML_Sum!$S9 -> 0 | T9: =ML_Sum!$T9 -> 0
C10: =ML_Sum!$C10 -> 1 | F10: =ML_Sum!$F10 -> Enemalta 3Ph Application | I10: 10 | J10: =ML_Sum!$J10 -> 1 | K10: =ML_Sum!$K10 -> 1 | L10: =ML_Sum!$L10 -> 1 | M10: =ML_Sum!$M10 -> 1 | N10: =ML_Sum!$N10 -> 1 | O10: =ML_Sum!$O10 -> 1 | Q10: =ML_Sum!$Q10 -> 0 | R10: mu_I | S10: =ML_Sum!$S10 -> 1.1 | T10: =ML_Sum!$T10 -> 31.7163
C11: =ML_Sum!$C11 -> 1 | F11: =ML_Sum!$F11 -> 0 | Q11: =ML_Sum!$Q11 -> 0 | R11: mu_J | S11: =ML_Sum!$S11 -> 0 | T11: =ML_Sum!$T11 -> 0
C12: =ML_Sum!$C12 -> 1 | F12: =ML_Sum!$F12 -> 0 | Q12: =ML_Sum!$Q12 -> 0 | R12: MIXED | S12: =ML_Sum!$S12 -> MAT MU | T12: =ML_Sum!$T12 -> LAB RATE
G13: I_CODE | H13: C_CODE | I13: MAKE | J13: PART_NO | K13: MARKUP | L13: TYPE | M13: LIST_P | N13: P_FACT | O13: FIX | P13: DATE | Q13: %Dsct in BOQ | R13: MU TYPE | S13: MAT MU | T13: LAB RATE
Q14: Multip
A15: 70 | B15: =Elec_Est!B5539 -> 70 | D15: 001# 5 core x 70 mm2 XLPE/SWA/LSZH/Cu Cable | K15: RATE | L15: RATE | Q15: =B15/A15 -> 1 | R15: =IF($B15=0,0,IF($S$1="R",ROUND(R23/$B15,2),R23/$B15)) -> 43.37 | T15: =IF($B15=0,0,IF($S$1="R",ROUND(T23/$B15,2),T23/$B15)) -> 0.26
D16: Based on:
A17: =$Q$15 *(70) -> 70 | B17: m | D17: 5 core x 70 mm2 XLPE/SWA/LSZH/Cu Cable | F17: AJQ41321 | G17: CAMC_028 | H17: 616 | I17: CRO | J17: 70mm2 | O17: 2 | P17: 40767 | Q17: 41.55 | R17: =$A17*Q17 -> 2908.5 | S17: 0.18 | T17: =$A17*S17*$T$1 -> 13.23
A18: =$Q$15 *(4) -> 4 | B18: No | D18: Gland Indoor 50S BWL 4*95mm2 | G18: CAAC_047 | H18: 620 | I18: CMP | O18: 2 | P18: 35431 | Q18: 25.46 | R18: =$A18*Q18 -> 101.84 | S18: 0.7 | T18: =$A18*S18*$T$1 -> 2.94
A19: =$Q$15 *(4*5) -> 20 | B19: No | D19: Cable Lug 70 mm2 | G19: CAAC_013 | H19: 620 | I19: CTT | O19: 2 | P19: 34669 | Q19: 1 | R19: =$A19*Q19 -> 20 | S19: 0.1 | T19: =$A19*S19*$T$1 -> 2.1
A20: =$Q$15 *(4) -> 4 | B20: No | D20: Cable Marker Wrap Around Type | G20: CAAC_025 | H20: 620 | I20: (__) | O20: 2 | Q20: 0.5 | R20: =$A20*Q20 -> 2 | T20: =$A20*S20*$T$1 -> 0
A21: =$Q$15 *(70) -> 70 | B21: No | D21: Cable Tie 225mm | G21: CONS_009 | H21: 875 | I21: (__) | K21: 01-003 | O21: 1 | P21: 34669 | Q21: 0.05 | R21: =$A21*Q21 -> 3.5 | T21: =$A21*S21*$T$1 -> 0
C22: << ==== TOTAL UNITS | R22: =$A22*Q22 -> 0 | T22: =$A22*S22*$T$1 -> 0
A23: d> | B23: =(R23+T23)-SUM(R16:R22,T16:T22) -> 0 | D23: Sell_A | E23: =IF($B15=0,0,ROUND(ROUND(($R23*$S$2+($T23*$T$2))/$B15, 2)*$C$2,2)) -> 62.09 | F23: =ROUND($B15*$E23,2) -> 4346.3 | K23: ITEM | L23: ITEM | R23: =SUM(R16:R22) -> 3035.84 | T23: =SUM(T16:T22) -> 18.27
Q24: Multip
A25: 10 | B25: =Elec_Est!B5540 -> 10 | D25: 002# 5 core x 70 mm2 FG16(O)M16 Cable | K25: RATE | L25: RATE | Q25: =B25/A25 -> 1 | R25: =IF($B25=0,0,IF($S$1="R",ROUND(R33/$B25,2),R33/$B25)) -> 46.17 | T25: =IF($B25=0,0,IF($S$1="R",ROUND(T33/$B25,2),T33/$B25)) -> 0.48
D26: Based on:
A27: =$Q$25 *(10) -> 10 | B27: m | D27: 5 core x 70 mm2 FG16(O)M16 Cable | G27: CAMC_029 | H27: 616 | I27: CRO | J27: 95mm2 | O27: 2 | P27: 40767 | Q27: 44.2 | R27: =$A27*Q27 -> 442 | S27: 0.18 | T27: =$A27*S27*$T$1 -> 1.89
A28: =$Q$25 *(2) -> 2 | B28: No | D28: M63 PVC Gland | G28: CAAC_027 | H28: 620 | I28: (__) | O28: 2 | P28: 35431 | Q28: 4.51 | R28: =$A28*Q28 -> 9.02 | S28: 0.9 | T28: =$A28*S28*$T$1 -> 1.89
A29: =$Q$25 *(10) -> 10 | B29: No | D29: Cable Lug 70 mm2 | G29: CAAC_013 | H29: 620 | I29: CTT | O29: 2 | P29: 34669 | Q29: 1 | R29: =$A29*Q29 -> 10 | S29: 0.1 | T29: =$A29*S29*$T$1 -> 1.05
A30: =$Q$25 *(2) -> 2 | B30: No | D30: Cable Marker Wrap Around Type | G30: CAAC_025 | H30: 620 | I30: (__) | O30: 2 | Q30: 0.1 | R30: =$A30*Q30 -> 0.2 | T30: =$A30*S30*$T$1 -> 0
A31: =$Q$25 *(10) -> 10 | B31: No | D31: Cable Tie 225mm | G31: CONS_009 | H31: 875 | I31: (__) | K31: 01-003 | O31: 1 | P31: 34669 | Q31: 0.05 | R31: =$A31*Q31 -> 0.5 | T31: =$A31*S31*$T$1 -> 0
C32: << ==== TOTAL UNITS | R32: =$A32*Q32 -> 0 | T32: =$A32*S32*$T$1 -> 0
A33: d> | B33: =(R32+T32) -> 0 | D33: Sell_A | E33: =IF($B25=0,0,ROUND(ROUND(($R33*$S$2+($T33*$T$2))/$B25, 2)*$C$2,2)) -> 73.32 | F33: =ROUND($B25*$E33,2) -> 733.2 | K33: ITEM | L33: ITEM | R33: =SUM(R26:R32) -> 461.72 | T33: =SUM(T26:T32) -> 4.83
Q34: Multip
A35: 170 | B35: =Elec_Est!B5541 -> 170 | D35: 003# 5 core x 50 mm2 FG16(O)M16 Cable | K35: RATE | L35: RATE | Q35: =B35/A35 -> 1 | R35: =IF($B35=0,0,IF($S$1="R",ROUND(R43/$B35,2),R43/$B35)) -> 31.01 | T35: =IF($B35=0,0,IF($S$1="R",ROUND(T43/$B35,2),T43/$B35)) -> 0.29
D36: Based on:
A37: =$Q$35 *(170) -> 170 | B37: m | D37: 5 core x 50 mm2 FG16(O)M16 Cable | G37: CAMC_029 | H37: 616 | I37: CRO | J37: 95mm2 | O37: 2 | P37: 40767 | Q37: 30.41 | R37: =$A37*Q37 -> 5169.7 | S37: 0.18 | T37: =$A37*S37*$T$1 -> 32.13
A38: =$Q$35 *(12) -> 12 | B38: No | D38: M63 PVC Gland | G38: CAAC_027 | H38: 620 | I38: (__) | O38: 2 | P38: 35431 | Q38: 4.51 | R38: =$A38*Q38 -> 54.12 | S38: 0.9 | T38: =$A38*S38*$T$1 -> 11.34
A39: =$Q$35 *(12*5) -> 60 | B39: No | D39: Cable Lug 50 mm2 | G39: CAAC_012 | H39: 620 | I39: CTT | O39: 2 | P39: 34669 | Q39: 0.65 | R39: =$A39*Q39 -> 39 | S39: 0.1 | T39: =$A39*S39*$T$1 -> 6.3
A40: =$Q$35 *(12) -> 12 | B40: No | D40: Cable Marker Wrap Around Type | G40: CAAC_025 | H40: 620 | I40: (__) | O40: 2 | Q40: 0.1 | R40: =$A40*Q40 -> 1.2 | T40: =$A40*S40*$T$1 -> 0
...

Sheet Elec_Est
B1: CLIENT: | C1: =ML_Sum!$C1 -> 1 | D1: =ML_Sum!$D1 -> Battery Street Limited | F1: =ML_Sum!$F1 -> 0 | I1: 1 | J1: =ML_Sum!$J1 -> 1 | K1: =ML_Sum!$K1 -> 1 | L1: =ML_Sum!$L1 -> 1 | M1: =ML_Sum!$M1 -> 1 | N1: =ML_Sum!$N1 -> 1 | O1: =ML_Sum!$O1 -> 1 | Q1: =ML_Sum!$Q1 -> € | R1: R/Lab Cont | S1: =ML_Sum!$S1 -> R | T1: =ML_Sum!$T1 -> 1.05 | U1: =ML_Sum!W1 -> BOQ | V1: INCL | W1: MULT | X1: AREA | Y1: BOQ | Z1: TDWG | AA1: ACT | AB1: DIFF
B2: PROJECT: | C2: =ML_Sum!$C2 -> 1 | D2: =ML_Sum!$D2 -> MEP Works British Hotel | F2: =ML_Sum!$F2 -> Electrical | I2: 2 | J2: =ML_Sum!$J2 -> 1 | K2: =ML_Sum!$K2 -> 1 | L2: =ML_Sum!$L2 -> 1 | M2: =ML_Sum!$M2 -> 1 | N2: =ML_Sum!$N2 -> 1 | O2: =ML_Sum!$O2 -> 1 | Q2: =ML_Sum!$Q2 -> 0 | R2: mu_A | S2: =ML_Sum!$S2 -> 1.22 | T2: =ML_Sum!$T2 -> 35.17626
B3: JOB DESC: | C3: =ML_Sum!$C3 -> 1 | D3: =ML_Sum!$D3 -> Electrical and ELV Systems | F3: =ML_Sum!$F3 -> Controls Section (DALI) | I3: 3 | J3: =ML_Sum!$J3 -> 1 | K3: =ML_Sum!$K3 -> 1 | L3: =ML_Sum!$L3 -> 1 | M3: =ML_Sum!$M3 -> 1 | N3: =ML_Sum!$N3 -> 1 | O3: =ML_Sum!$O3 -> 1 | Q3: =ML_Sum!$Q3 -> 0 | R3: mu_B | S3: =ML_Sum!$S3 -> 1.22 | T3: =ML_Sum!$T3 -> 86.64
B4: QUOTE No: | C4: =ML_Sum!$C4 -> 1 | D4: =ML_Sum!$D4 -> EL25-0662B | F4: =ML_Sum!$F4 -> Controls Section Engineer (DALI) | I4: 4 | J4: =ML_Sum!$J4 -> 1 | K4: =ML_Sum!$K4 -> 1 | L4: =ML_Sum!$L4 -> 1 | M4: =ML_Sum!$M4 -> 1 | N4: =ML_Sum!$N4 -> 1 | O4: =ML_Sum!$O4 -> 1 | Q4: =ML_Sum!$Q4 -> 0 | R4: mu_C | S4: =ML_Sum!$S4 -> 1.22 | T4: =ML_Sum!$T4 -> 51.41
B5: CLIENTs REF: | C5: =ML_Sum!$C5 -> 1 | D5: =ML_Sum!$D5 -> MEP REVISED | F5: =ML_Sum!$F5 -> ELV Sub-Contractor - APCO | I5: 5 | J5: =ML_Sum!$J5 -> 1 | K5: =ML_Sum!$K5 -> 1 | L5: =ML_Sum!$L5 -> 1 | M5: =ML_Sum!$M5 -> 1 | N5: =ML_Sum!$N5 -> 1 | O5: =ML_Sum!$O5 -> 1 | Q5: =ML_Sum!$Q5 -> 0 | R5: mu_D | S5: =ML_Sum!$S5 -> 1.075 | T5: =ML_Sum!$T5 -> 30.995475
B6: VAT/DUTIES: | C6: =ML_Sum!$C6 -> 1 | D6: =ML_Sum!$D6 -> VAT EXCL. | F6: =ML_Sum!$F6 -> ELV Sub-Contractor - DATA | I6: 6 | J6: =ML_Sum!$J6 -> 1 | K6: =ML_Sum!$K6 -> 1 | L6: =ML_Sum!$L6 -> 1 | M6: =ML_Sum!$M6 -> 1 | N6: =ML_Sum!$N6 -> 1 | O6: =ML_Sum!$O6 -> 1 | Q6: =ML_Sum!$Q6 -> 0 | R6: mu_E | S6: =ML_Sum!$S6 -> 1.1 | T6: =ML_Sum!$T6 -> 31.7163
B7: SAVED ON: | C7: =ML_Sum!$C7 -> 1 | D7: 39364 | F7: =ML_Sum!$F7 -> 0 | I7: 7 | J7: =ML_Sum!$J7 -> 1 | K7: =ML_Sum!$K7 -> 1 | L7: =ML_Sum!$L7 -> 1 | M7: =ML_Sum!$M7 -> 1 | N7: =ML_Sum!$N7 -> 1 | O7: =ML_Sum!$O7 -> 0 | Q7: =ML_Sum!$Q7 -> 0 | R7: mu_F | S7: =ML_Sum!$S7 -> 0 | T7: =ML_Sum!$T7 -> 0
B8: ESTIMATOR: | C8: =ML_Sum!$C8 -> 1 | D8: =ML_Sum!$D8 -> R.Farrugia | F8: =ML_Sum!$F8 -> 0 | I8: 8 | J8: =ML_Sum!$J8 -> 1 | K8: =ML_Sum!$K8 -> 1 | L8: =ML_Sum!$L8 -> 1 | M8: =ML_Sum!$M8 -> 1 | N8: =ML_Sum!$N8 -> 1 | O8: =ML_Sum!$O8 -> 0 | Q8: =ML_Sum!$Q8 -> 0 | R8: mu_G | S8: =ML_Sum!$S8 -> 0 | T8: =ML_Sum!$T8 -> 0
B9: LABOUR RATE: | C9: =ML_Sum!$C9 -> 1 | D9: =ML_Sum!$D9 -> 28.833 | F9: =ML_Sum!$F9 -> 0 | I9: 9 | J9: =ML_Sum!$J9 -> 1 | K9: =ML_Sum!$K9 -> 1 | L9: =ML_Sum!$L9 -> 1 | M9: =ML_Sum!$M9 -> 1 | N9: =ML_Sum!$N9 -> 1 | O9: =ML_Sum!$O9 -> 0 | Q9: =ML_Sum!$Q9 -> 0 | R9: mu_H | S9: =ML_Sum!$S9 -> 0 | T9: =ML_Sum!$T9 -> 0
C10: =ML_Sum!$C10 -> 1 | F10: =ML_Sum!$F10 -> Enemalta 3Ph Application | I10: 10 | J10: =ML_Sum!$J10 -> 1 | K10: =ML_Sum!$K10 -> 1 | L10: =ML_Sum!$L10 -> 1 | M10: =ML_Sum!$M10 -> 1 | N10: =ML_Sum!$N10 -> 1 | O10: =ML_Sum!$O10 -> 1 | Q10: =ML_Sum!$Q10 -> 0 | R10: mu_I | S10: =ML_Sum!$S10 -> 1.1 | T10: =ML_Sum!$T10 -> 31.7163
C11: =ML_Sum!$C11 -> 1 | F11: =ML_Sum!$F11 -> 0 | Q11: =ML_Sum!$Q11 -> 0 | R11: mu_J | S11: =ML_Sum!$S11 -> 0 | T11: =ML_Sum!$T11 -> 0
C12: =ML_Sum!$C12 -> 1 | F12: =ML_Sum!$F12 -> 0 | Q12: =ML_Sum!$Q12 -> 0 | R12: MIXED | S12: =ML_Sum!$S12 -> MAT MU | T12: =ML_Sum!$T12 -> LAB RATE
G13: ISELL | H13: C_CODE | I13: MAKE | J13: PART_NO | K13: MARKUP | L13: TYPE | M13: LIST_P | N13: P_FACT | O13: FIX | P13: DATE | Q13: %Dsct in BOQ | R13: MU TYPE | S13: MAT MU | T13: LAB RATE | AM13: Tot Mat Cost | AN13: Unit Lab phr. | AO13: Tot Lab phr. | AP13: < for ELM / MEE
K14: TB
C15: t
D16: PRELIMINARIES
E18: Sell Rate | F18: Sell Total | K18: IB | AG18: U_M_Sell | AH18: T_M_Sell | AI18: U_L_Sell | AJ18: T_L_Sell | AK18: Total_Sell | AM18: T_M_Cost | AN18: T_L_Phr | AO18: Mat/Lab=1
A19: 1 | B19: LS | D19: Item: 1 | E19: =IF(AND($A19=0,$A$1="DIF"),0, ROUND(ROUND(($R23*$S$2+($T23*$T$2))/A19,2)*$C$2,2)) -> 610 | F19: =ROUND($A19*$E19,2) -> 610 | G19: ISELL | K19: mu_A | L19: ITEM | T19: =IF(AND($R23=0,$T23=0),"0.00","mu :" & ROUND($F19/$C$2/($R23+$T23*$D$9),2)) -> mu :1.22 | AG19: =IF($E19=0,0,ROUND($R23*$S$2*$C$2/$A19,2)) -> 610 | AH19: =$AG19*$A19 -> 610 | AI19: =$E19-$AG19 -> 0 | AJ19: =$A19*$AI19 -> 0 | AK19: =ROUND(($AG19+$AI19)*$A19,2) -> 610 | AM19: =ROUND(R23,2) -> 500 | AN19: =ROUND(T23,2) -> 0 | AO19: =ROUND(AM19+AN19,2)*A19 -> 500
D20: Mobilisation and demobilisation including setting up of workshop storage facilities and their security.
A21: 1 | B21: No | D21: Mobilisation and demobilisation | G21: CONS_001 | H21: 875 | I21: (__) | K21: 01-001 | O21: 1 | Q21: 500 | R21: =$A21*Q21 -> 500 | T21: =$A21*S21*$T$1 -> 0
R22: =$A22*Q22 -> 0 | T22: =$A22*S22*$T$1 -> 0
A23: d> | B23: =(R22+T22) -> 0 | G23: ICOST | K23: mu_A | L23: ITEM | R23: =SUM(R20:R22) -> 500 | T23: =SUM(T20:T22) -> 0
E24: Sell Rate | F24: Sell Total | K24: IB | AG24: U_M_Sell | AH24: T_M_Sell | AI24: U_L_Sell | AJ24: T_L_Sell | AK24: Total_Sell | AM24: T_M_Cost | AN24: T_L_Phr | AO24: Mat/Lab=1
A25: 1 | B25: LS | D25: Item: 2 | E25: =IF(AND($A25=0,$A$1="DIF"),0, ROUND(ROUND(($R30*$S$2+($T30*$T$2))/A25,2)*$C$2,2)) -> 0 | F25: =ROUND($A25*$E25,2) -> 0 | G25: ISELL | K25: mu_A | L25: ITEM | Q25: Included | T25: =IF(AND($R30=0,$T30=0),"0.00","mu :" & ROUND($F25/$C$2/($R30+$T30*$D$9),2)) -> 0.00 | AG25: =IF($E25=0,0,ROUND($R30*$S$2*$C$2/$A25,2)) -> 0 | AH25: =$AG25*$A25 -> 0 | AI25: =$E25-$AG25 -> 0 | AJ25: =$A25*$AI25 -> 0 | AK25: =ROUND(($AG25+$AI25)*$A25,2) -> 0 | AM25: =ROUND(R30,2) -> 0 | AN25: =ROUND(T30,2) -> 0 | AO25: =ROUND(AM25+AN25,2)*A25 -> 0
D26: Safety clothing for all site personnel in accordance with statutory requirements. | K26: n
R27: =$A27*Q27 -> 0 | T27: =$A27*S27*$T$1 -> 0
D28: Included | R28: =$A28*Q28 -> 0 | T28: =$A28*S28*$T$1 -> 0
R29: =$A29*Q29 -> 0 | T29: =$A29*S29*$T$1 -> 0
A30: d> | B30: =(R29+T29) -> 0 | G30: ICOST | K30: mu_A | L30: ITEM | R30: =SUM(R26:R29) -> 0 | T30: =SUM(T26:T29) -> 0
E31: Sell Rate | F31: Sell Total | K31: IB | AG31: U_M_Sell | AH31: T_M_Sell | AI31: U_L_Sell | AJ31: T_L_Sell | AK31: Total_Sell | AM31: T_M_Cost | AN31: T_L_Phr | AO31: Mat/Lab=1
A32: 1 | B32: LS | D32: Item: 3 | E32: =IF(AND($A32=0,$A$1="DIF"),0, ROUND(ROUND(($R36*$S$2+($T36*$T$2))/A32,2)*$C$2,2)) -> 0 | F32: =ROUND($A32*$E32,2) -> 0 | G32: ISELL | K32: mu_A | L32: ITEM | Q32: Included | T32: =IF(AND($R36=0,$T36=0),"0.00","mu :" & ROUND($F32/$C$2/($R36+$T36*$D$9),2)) -> 0.00 | AG32: =IF($E32=0,0,ROUND($R36*$S$2*$C$2/$A32,2)) -> 0 | AH32: =$AG32*$A32 -> 0 | AI32: =$E32-$AG32 -> 0 | AJ32: =$A32*$AI32 -> 0 | AK32: =ROUND(($AG32+$AI32)*$A32,2) -> 0 | AM32: =ROUND(R36,2) -> 0 | AN32: =ROUND(T36,2) -> 0 | AO32: =ROUND(AM32+AN32,2)*A32 -> 0
D33: Allowance for weekly progress meetings within project execution period. | K33: n
B34: Trips | D34: Bolt car service for office employees for attending site meetings | G34: PROV_001 | H34: 970 | I34: MISC | O34: 4 | P34: 38129 | Q34: 10 | R34: =$A34*Q34 -> 0 | S34: 1 | T34: =$A34*S34*$T$1 -> 0 | U34: 20
R35: =$A35*Q35 -> 0 | T35: =$A35*S35*$T$1 -> 0
A36: d> | B36: =(R35+T35) -> 0 | G36: ICOST | K36: mu_A | L36: ITEM | R36: =SUM(R33:R35) -> 0 | T36: =SUM(T33:T35) -> 0
E37: Sell Rate | F37: Sell Total | K37: IB | AG37: U_M_Sell | AH37: T_M_Sell | AI37: U_L_Sell | AJ37: T_L_Sell | AK37: Total_Sell | AM37: T_M_Cost | AN37: T_L_Phr | AO37: Mat/Lab=1
A38: 1 | B38: LS | D38: Item: 4 | E38: =IF(AND($A38=0,$A$1="DIF"),0, ROUND(ROUND(($R43*$S$2+($T43*$T$2))/A38,2)*$C$2,2)) -> 0 | F38: =ROUND($A38*$E38,2) -> 0 | G38: ISELL | K38: mu_A | L38: ITEM | Q38: Included | T38: =IF(AND($R43=0,$T43=0),"0.00","mu :" & ROUND($F38/$C$2/($R43+$T43*$D$9),2)) -> 0.00 | AG38: =IF($E38=0,0,ROUND($R43*$S$2*$C$2/$A38,2)) -> 0 | AH38: =$AG38*$A38 -> 0 | AI38: =$E38-$AG38 -> 0 | AJ38: =$A38*$AI38 -> 0 | AK38: =ROUND(($AG38+$AI38)*$A38,2) -> 0 | AM38: =ROUND(R43,2) -> 0 | AN38: =ROUND(T43,2) -> 0 | AO38: =ROUND(AM38+AN38,2)*A38 -> 0
D39: Provision of instrumentation used for commissioning purposes including evidence of associated valid calibration certificates.
R40: =$A40*Q40 -> 0 | T40: =$A40*S40*$T$1 -> 0
D41: Included | R41: =$A41*Q41 -> 0 | T41: =$A41*S41*$T$1 -> 0
...

Sheet ML_Sum
B1: CLIENT: | C1: 1 | D1: Battery Street Limited | G1: TRUE | H1: TRUE | I1: 1 | J1: =$Q110 -> 1 | K1: =$Q120 -> 1 | L1: =$Q130 -> 1 | M1: =$Q140 -> 1 | N1: =$Q150 -> 1 | O1: =$Q160 -> 1 | Q1: =IF(C1=1,"€","Curr?") -> € | R1: Recon /Lab.Cont >> | S1: =IF($S$39="PRINT","R","Do Not Print") -> R | T1: 1.05 | V1: {=IF(OR(X1=AREAS),1,0)} -> 1 | W1: BOQ | X1: x | Y1: x | Z1: x | AA1: x | AB1: x | AC1: x | AD1: x
B2: PROJECT: | C2: =IF($D$6="VAT INCLUDED",1.18,1)*(1-$Q2)*$C$1 -> 1 | D2: MEP Works British Hotel | F2: Electrical | G2: TRUE | I2: 2 | J2: =$Q111 -> 1 | K2: =$Q121 -> 1 | L2: =$Q131 -> 1 | M2: =$Q141 -> 1 | N2: =$Q151 -> 1 | O2: =$Q161 -> 1 | R2: ="A) " & IF($S2=0,"",ROUND($S2,2) & "-" & ROUND($T2/$D$9,2)) -> A) 1.22-1.22 | S2: 1.22 | T2: =$S2*$D$9 -> 35.17626 | U2: 1.26 | X2: x | Y2: x | Z2: x | AA2: x | AB2: x | AC2: x | AD2: x
B3: JOB DESC: | C3: =IF($D$6="VAT INCLUDED",1.18,1)*(1-$Q3)*$C$1 -> 1 | D3: Electrical and ELV Systems | F3: Controls Section (DALI) | G3: TRUE | I3: 3 | J3: =$Q112 -> 1 | K3: =$Q122 -> 1 | L3: =$Q132 -> 1 | M3: =$Q142 -> 1 | N3: =$Q152 -> 1 | O3: =$Q162 -> 1 | R3: ="B) " & IF($S3=0,"",ROUND($S3,2) & "-" & ROUND($T3/$D$9,2)) -> B) 1.22-3 | S3: 1.22 | T3: =$D$11 -> 86.64 | U3: 1.26 | X3: x | Y3: x | Z3: x | AA3: x | AB3: x | AC3: x | AD3: x
B4: INT. QUOT No: | C4: =IF($D$6="VAT INCLUDED",1.18,1)*(1-$Q4)*$C$1 -> 1 | D4: EL25-0662B | F4: Controls Section Engineer (DALI) | G4: TRUE | I4: 4 | J4: =$Q113 -> 1 | K4: =$Q123 -> 1 | L4: =$Q133 -> 1 | M4: =$Q143 -> 1 | N4: =$Q153 -> 1 | O4: =$Q163 -> 1 | R4: ="C) " & IF($S4=0,"",ROUND($S4,2) & "-" & ROUND($T4/$D$9,2)) -> C) 1.22-1.78 | S4: 1.22 | T4: =D10 -> 51.41 | U4: 1.26 | X4: x | Y4: x | Z4: x | AA4: x | AB4: x | AC4: x | AD4: x
B5: CLIENTs REF: | C5: =IF($D$6="VAT INCLUDED",1.18,1)*(1-$Q5)*$C$1 -> 1 | D5: MEP REVISED | F5: ELV Sub-Contractor - APCO | G5: TRUE | I5: 5 | J5: =$Q114 -> 1 | K5: =$Q124 -> 1 | L5: =$Q134 -> 1 | M5: =$Q144 -> 1 | N5: =$Q154 -> 1 | O5: =$Q164 -> 1 | R5: ="D) " & IF($S5=0,"",ROUND($S5,2) & "-" & ROUND($T5/$D$9,2)) -> D) 1.08-1.08 | S5: 1.075 | T5: =$S5*$D$9 -> 30.995475 | U5: =1.1 -> 1.1 | X5: x | Y5: x | Z5: x | AA5: x | AB5: x | AC5: x | AD5: x
B6: VAT: | C6: =IF($D$6="VAT INCLUDED",1.18,1)*(1-$Q6)*$C$1 -> 1 | D6: VAT EXCL. | F6: ELV Sub-Contractor - DATA | G6: TRUE | I6: 6 | J6: =$Q115 -> 1 | K6: =$Q125 -> 1 | L6: =$Q135 -> 1 | M6: =$Q145 -> 1 | N6: =$Q155 -> 1 | O6: =$Q165 -> 1 | R6: ="E) " & IF($S6=0,"",ROUND($S6,2) & "-" & ROUND($T6/$D$9,2)) -> E) 1.1-1.1 | S6: 1.1 | T6: =$S6*$D$9 -> 31.7163 | U6: =1.15 -> 1.15 | X6: x | Y6: x | Z6: x | AA6: x | AB6: x | AC6: x | AD6: x
B7: SAVED ON: | C7: =IF($D$6="VAT INCLUDED",1.18,1)*(1-$Q7)*$C$1 -> 1 | D7: 46034 | G7: TRUE | I7: 7 | J7: =$Q116 -> 1 | K7: =$Q126 -> 1 | L7: =$Q136 -> 1 | M7: =$Q146 -> 1 | N7: =$Q156 -> 1 | R7: ="F) " & IF($S7=0,"",ROUND($S7,2) & "-" & ROUND($T7/$D$9,2)) -> F) | X7: x | Y7: x | Z7: x | AA7: x | AB7: x | AC7: x | AD7: x
B8: ESTIMATOR: | C8: =IF($D$6="VAT INCLUDED",1.18,1)*(1-$Q8)*$C$1 -> 1 | D8: R.Farrugia | G8: TRUE | I8: 8 | J8: =$Q117 -> 1 | K8: =$Q127 -> 1 | L8: =$Q137 -> 1 | M8: =$Q147 -> 1 | N8: =$Q157 -> 1 | R8: ="G) " & IF($S8=0,"",ROUND($S8,2) & "-" & ROUND($T8/$D$9,2)) -> G) | X8: x | Y8: x | Z8: x | AA8: x | AB8: x | AC8: x | AD8: x
B9: LAB. COST: | C9: =IF($D$6="VAT INCLUDED",1.18,1)*(1-$Q9)*$C$1 -> 1 | D9: 28.833 | E9: Cost for 2026 | G9: TRUE | I9: 9 | J9: =$Q118 -> 1 | K9: =$Q128 -> 1 | L9: =$Q138 -> 1 | M9: =$Q148 -> 1 | N9: =$Q158 -> 1 | R9: ="H) " & IF($S9=0,"",ROUND($S9,2) & "-" & ROUND($T9/$D$9,2)) -> H) | X9: x | Y9: x | Z9: x | AA9: x | AB9: x | AC9: x | AD9: x
C10: =IF($D$6="VAT INCLUDED",1.18,1)*(1-$Q10)*$C$1 -> 1 | D10: 51.41 | E10: Single Engineer | F10: Enemalta 3Ph Application | G10: TRUE | I10: 10 | J10: =$Q119 -> 1 | K10: =$Q129 -> 1 | L10: =$Q139 -> 1 | M10: =$Q149 -> 1 | N10: =$Q159 -> 1 | O10: =Q109 -> 1 | R10: =" I) " & IF($S10=0,"",ROUND($S10,2) & "-" & ROUND($T10/$D$9,2)) -> I) 1.1-1.1 | S10: =1.1 -> 1.1 | T10: =$S10*$D$9 -> 31.7163 | U10: =1.1 -> 1.1 | X10: x | Y10: x | Z10: x | AA10: x | AB10: x | AC10: x | AD10: x
C11: =IF($D$6="VAT INCLUDED",1.18,1)*(1-$Q11)*$C$1 -> 1 | D11: =43.32*2 -> 86.64 | E11: Pair Technician | R11: ="J) " & IF($S11=0,"",ROUND($S11,2) & "-" & ROUND($T11/$D$9,2)) -> J) | X11: x | Y11: x | Z11: x | AA11: x | AB11: x | AC11: x | AD11: x
C12: =IF($D$6="VAT INCLUDED",1.18,1)*(1-$Q12)*$C$1 -> 1 | G12: SYSTEMS | H12: SYSTEMS | I12: SYSTEMS | J12: SYSTEMS | K12: SYSTEMS | L12: SYSTEMS | M12: SYSTEMS | N12: SYSTEMS | O12: SYSTEMS | P12: SYSTEMS | R12: MIXED - X,Y ) | S12: MAT MU | T12: LAB RATE | X12: x | Y12: x | Z12: x | AA12: x | AB12: x | AC12: x | AD12: x
B13: MATERIAL & LABOUR SUMMARY | G13: ItemCode | H13: CostCode | I13: MAKE | J13: PART_NO | K13: MARKUP | L13: TYPE | M13: LIST_P | N13: SET | O13: FIX | P13: DATE | Q13: %Dsct in BOQ | R13: MATMU-LABMU | S13: MAT CONT >> | T13: =SUM(Q109:Q165)/57 -> 1
B14: =IF($D$6<>"VAT EXCL.", "QUOTE ISSUED WITH VAT INCLUDED", "") | X14: x | Y14: x | Z14: x | AA14: x | AB14: x | AC14: x | AD14: x
Q15: =(C73-F35)/C73 -> 0 | R15: Average Discount applied in BOQ (Q2-Q12) | X15: x | Y15: x | Z15: x | AA15: x | AB15: x | AC15: x | AD15: x
B16: =IF($W$1<>"BOQ", "DIFF SET TO " & W1,"") | Q16: =(F35-E35)/F35 -> 0 | R16: Average Discount applied on Totals (Q23-Q32) | X16: x | Y16: x | Z16: x | AA16: x | AB16: x | AC16: x | AD16: x
Q17: =F75 -> 0 | R17: Overall Discount
B18: =IF(AND(G1,G2,G3,G4,G5,G6,G7,G8,G9,G10,H1)=TRUE, "", "CHECKLIST INCOMPLETE !" )
B19: =IF(ABS(SUM(A23:A32))>100,"[Discy A-J] are high, Check it out."," ") | Q19: =R84 -> 1.2039064 | R19: Overall Markup (Final Selling Excl.VAT/Total Cost )
E21: DISCOUNTED | F21: SELLING | Q21: % Discnt | R21: MATERIAL | T21: LABOUR
A22: Discy.A-J | B22: Markup/LRate | E22: ="SELLING " & $Q$1 -> SELLING € | F22: =$Q$1 -> € | G22: VAT/DISC | H22: MU | I22: LABRATE | J22: LABCOST | Q22: on Totals | R22: € | T22: Pair Hrs.
A23: =IF($F23=0,"",($F23/$C2)-($R23*$S2+$T23*$T2)) -> -2.0069441 | B23: =IF(F23=0,"",IF(R23=0,"A) "&"---, "&ROUND(($F23/$C2-($R23*$S2))/$T23,2),IF(T23=0,"A) "&ROUND(($F23/$C2)/$R23,2),"A) "&ROUND(($F23/$C2-($T23*$T2))/$R23,2)&", " &ROUND(($F23/$C2-($R23*$S2))/$T23,2)))) -> A) 1.22, 35.18 | D23: =IF($F2="","",$F2) -> Electrical | E23: =F23*(1-Q23) -> 225676.34 | F23: =Elec_Est!F5454 -> 225676.34 | G23: =C2 -> 1 | H23: =$S2 -> 1.22 | I23: =$T2 -> 35.17626 | J23: =$D$9 -> 28.833 | R23: =Elec_Est!R5454 -> 113304.29 | T23: =Elec_Est!T5454 -> 2485.9695
A24: =IF($F24=0,"",($F24/$C3)-($R24*$S3+$T24*$T3)) -> 0.0626 | B24: =IF(F24=0,"",IF(R24=0,"A) "&"---, "&ROUND(($F24/$C3-($R24*$S3))/$T24,2),IF(T24=0,"A) "&ROUND(($F24/$C3)/$R24,2),"A) "&ROUND(($F24/$C3-($T24*$T3))/$R24,2)&", " &ROUND(($F24/$C3-($R24*$S3))/$T24,2)))) -> A) 1.22, 86.64 | D24: =IF($F3="","",$F3) -> Controls Section (DALI) | E24: =F24*(1-Q24) -> 5699.92 | F24: =Elec_Est!F5455 -> 5699.92 | G24: =C3 -> 1 | H24: =$S3 -> 1.22 | I24: =$T3 -> 86.64 | J24: =$D$9 -> 28.833 | R24: =Elec_Est!R5455 -> 3180.67 | T24: =Elec_Est!T5455 -> 21
A25: =IF($F25=0,"",($F25/$C4)-($R25*$S4+$T25*$T4)) -> 0.003 | B25: =IF(F25=0,"",IF(R25=0,"A) "&"---, "&ROUND(($F25/$C4-($R25*$S4))/$T25,2),IF(T25=0,"A) "&ROUND(($F25/$C4)/$R25,2),"A) "&ROUND(($F25/$C4-($T25*$T4))/$R25,2)&", " &ROUND(($F25/$C4-($R25*$S4))/$T25,2)))) -> A) ---, 51.41 | D25: =IF($F4="","",$F4) -> Controls Section Engineer (DALI) | E25: =F25*(1-Q25) -> 5074.17 | F25: =Elec_Est!F5456 -> 5074.17 | G25: =C4 -> 1 | H25: =$S4 -> 1.22 | I25: =$T4 -> 51.41 | J25: =$D$9 -> 28.833 | R25: =Elec_Est!R5456 -> 0 | T25: =Elec_Est!T5456 -> 98.7
A26: =IF($F26=0,"",($F26/$C5)-($R26*$S5+$T26*$T5)) -> -1.62875 | B26: =IF(F26=0,"",IF(R26=0,"A) "&"---, "&ROUND(($F26/$C5-($R26*$S5))/$T26,2),IF(T26=0,"A) "&ROUND(($F26/$C5)/$R26,2),"A) "&ROUND(($F26/$C5-($T26*$T5))/$R26,2)&", " &ROUND(($F26/$C5-($R26*$S5))/$T26,2)))) -> A) 1.07 | D26: =IF($F5="","",$F5) -> ELV Sub-Contractor - APCO | E26: =F26*(1-Q26) -> 42819.76 | F26: =Elec_Est!F5457 -> 42819.76 | G26: =C5 -> 1 | H26: =$S5 -> 1.075 | I26: =$T5 -> 30.995475 | J26: =$D$9 -> 28.833 | R26: =Elec_Est!R5457 -> 39833.85 | T26: =Elec_Est!T5457 -> 0
A27: =IF($F27=0,"",($F27/$C6)-($R27*$S6+$T27*$T6)) -> -9.094947e-13 | B27: =IF(F27=0,"",IF(R27=0,"A) "&"---, "&ROUND(($F27/$C6-($R27*$S6))/$T27,2),IF(T27=0,"A) "&ROUND(($F27/$C6)/$R27,2),"A) "&ROUND(($F27/$C6-($T27*$T6))/$R27,2)&", " &ROUND(($F27/$C6-($R27*$S6))/$T27,2)))) -> A) 1.1 | D27: =IF($F6="","",$F6) -> ELV Sub-Contractor - DATA | E27: =F27*(1-Q27) -> 6072 | F27: =Elec_Est!F5458 -> 6072 | G27: =C6 -> 1 | H27: =$S6 -> 1.1 | I27: =$T6 -> 31.7163 | J27: =$D$9 -> 28.833 | R27: =Elec_Est!R5458 -> 5520 | T27: =Elec_Est!T5458 -> 0
A28: =IF($F28=0,"",($F28/$C7)-($R28*$S7+$T28*$T7)) | B28: =IF(F28=0,"",IF(R28=0,"A) "&"---, "&ROUND(($F28/$C7-($R28*$S7))/$T28,2),IF(T28=0,"A) "&ROUND(($F28/$C7)/$R28,2),"A) "&ROUND(($F28/$C7-($T28*$T7))/$R28,2)&", " &ROUND(($F28/$C7-($R28*$S7))/$T28,2)))) | D28: =IF($F7="","",$F7) | E28: =F28*(1-Q28) -> 0 | F28: =Elec_Est!F5459 -> 0 | G28: =C7 -> 1 | H28: =$S7 -> 0 | I28: =$T7 -> 0 | J28: =$D$9 -> 28.833 | R28: =Elec_Est!R5459 -> 0 | T28: =Elec_Est!T5459 -> 0
A29: =IF($F29=0,"",($F29/$C8)-($R29*$S8+$T29*$T8)) | B29: =IF(F29=0,"",IF(R29=0,"A) "&"---, "&ROUND(($F29/$C8-($R29*$S8))/$T29,2),IF(T29=0,"A) "&ROUND(($F29/$C8)/$R29,2),"A) "&ROUND(($F29/$C8-($T29*$T8))/$R29,2)&", " &ROUND(($F29/$C8-($R29*$S8))/$T29,2)))) | D29: =IF($F8="","",$F8) | E29: =F29*(1-Q29) -> 0 | F29: =Elec_Est!F5460 -> 0 | G29: =C8 -> 1 | H29: =$S8 -> 0 | I29: =$T8 -> 0 | J29: =$D$9 -> 28.833 | R29: =Elec_Est!R5460 -> 0 | T29: =Elec_Est!T5460 -> 0
A30: =IF($F30=0,"",($F30/$C9)-($R30*$S9+$T30*$T9)) | B30: =IF(F30=0,"",IF(R30=0,"A) "&"---, "&ROUND(($F30/$C9-($R30*$S9))/$T30,2),IF(T30=0,"A) "&ROUND(($F30/$C9)/$R30,2),"A) "&ROUND(($F30/$C9-($T30*$T9))/$R30,2)&", " &ROUND(($F30/$C9-($R30*$S9))/$T30,2)))) | D30: =IF($F9="","",$F9) | E30: =F30*(1-Q30) -> 0 | F30: =Elec_Est!F5461 -> 0 | G30: =C9 -> 1 | H30: =$S9 -> 0 | I30: =$T9 -> 0 | J30: =$D$9 -> 28.833 | R30: =Elec_Est!R5461 -> 0 | T30: =Elec_Est!T5461 -> 0
A31: =IF($F31=0,"",($F31/$C10)-($R31*$S10+$T31*$T10)) -> -0.00423 | B31: =IF(F31=0,"",IF(R31=0,"A) "&"---, "&ROUND(($F31/$C10-($R31*$S10))/$T31,2),IF(T31=0,"A) "&ROUND(($F31/$C10)/$R31,2),"A) "&ROUND(($F31/$C10-($T31*$T10))/$R31,2)&", " &ROUND(($F31/$C10-($R31*$S10))/$T31,2)))) -> A) 1.1, 31.71 | D31: =IF($F10="","",$F10) -> Enemalta 3Ph Application | E31: =F31*(1-Q31) -> 1056.6 | F31: =Elec_Est!F5462 -> 1056.6 | G31: =C10 -> 1 | H31: =$S10 -> 1.1 | I31: =$T10 -> 31.7163 | J31: =$D$9 -> 28.833 | R31: =Elec_Est!R5462 -> 900 | T31: =Elec_Est!T5462 -> 2.1
A32: =IF($F32=0,"",($F32/$C11)-($R32*$S11+$T32*$T11)) | B32: =IF(F32=0,"",IF(R32=0,"A) "&"---, "&ROUND(($F32/$C11-($R32*$S11))/$T32,2),IF(T32=0,"A) "&ROUND(($F32/$C11)/$R32,2),"A) "&ROUND(($F32/$C11-($T32*$T11))/$R32,2)&", " &ROUND(($F32/$C11-($R32*$S11))/$T32,2)))) | D32: =IF($F11="","",$F11) | E32: =F32*(1-Q32) -> 0 | F32: =Elec_Est!F5463 -> 0 | G32: =C11 -> 1 | H32: =$S11 -> 0 | I32: =$T11 -> 0 | J32: =$D$9 -> 28.833 | R32: =Elec_Est!R5463 -> 0 | T32: =Elec_Est!T5463 -> 0
C33: MIXED
A35: Discy.L | B35: ='SUMMARY PG'!H233 -> 286398.79 | D35: =B35-E35 -> 0 | E35: =SUM(E23:E32) -> 286398.79 | F35: =SUM(F23:F32) -> 286398.79 | R35: =SUM(R23:R32) -> 162738.81 | T35: =SUM(T23:T32) -> 2607.7695
A36: =IF(A39=0,"0.00",A39-(A38*A37)) -> 0.00 | B36: BOQ TOTAL | E36: ="ESTIM TOTAL (" & $Q$1 & ")" -> ESTIM TOTAL (€)
A37: 1.125 | B37: <1 Actual LabCont | R37: =R166 -> 162742.86 | S37: C.C.Totals | T37: =T166 -> 2606.3322
B38: <2 Phrs @ 1.00
B39: <3 Phrs @ Actual | Q39: Discy.T >> | R39: =R37-R35 -> 4.0513703 | S39: PRINT | T39: =T37-T35 -> -1.4372621
B41: Values Only on : | D41: 45953 | E41: 315655.24 | F41: 315655.24 | R41: 173598.97 | T41: 2779.944
B42: Values Only on : | D42: 45957 | E42: 310694.81 | F42: 310694.81 | R42: 172956 | T42: 2715.044
B43: Values Only on : | D43: 46002 | E43: 310900.8 | F43: 310900.8 | R43: 173103.63 | T43: 2715.594
...

Sheet Quote
A1: =IF(AND(UPPER(LEFT(TRIM($D$8),11))="01",UPPER(LEFT(TRIM($D$9),3))<>"ELM"),"PANTA RETAIL LTD.","PANTA CONTRACTING LIMITED") -> PANTA CONTRACTING LIMITED
A2: =IF(UPPER(LEFT(TRIM($D$9),3))="ELM","ELEC-FOR-MECH INTERNAL QUOTATION","ELECTRICAL INTERNAL QUOTATION") -> ELECTRICAL INTERNAL QUOTATION
B5: ATT: | D5: =IF(A2="Internal Quotation", "Mechanical Division","") | R5: Dated: | S5: =NOW() -> 46114.408
B6: CLIENT: | C6: Link to ML_SUM $D1 | D6: =ML_Sum!D1 -> Battery Street Limited
B7: PROJECT: | C7: Link to ML_SUM $D2 | D7: =ML_Sum!D2 -> MEP Works British Hotel
B8: JOB DESC: | C8: Link to ML_SUM $D3 | D8: =ML_Sum!D3 -> Electrical and ELV Systems
B9: QUOTE No: | C9: Link to ML_SUM $D4 | D9: =ML_Sum!D4 -> EL25-0662B
B10: CLIENT's Ref: | C10: Link to ML_SUM $D5 | D10: =ML_Sum!D5 -> MEP REVISED
D22: Selling Price (€) : | E22: =ML_Sum!E35 -> 286398.79 | F22: =ML_Sum!D6 -> VAT EXCL. | G22: VAT EXCLUDED. | H22: VAT EXCLUDED. | I22: VAT EXCLUDED. | J22: VAT EXCLUDED. | K22: VAT EXCLUDED. | L22: VAT EXCLUDED. | M22: VAT EXCLUDED. | N22: VAT EXCLUDED. | O22: VAT EXCLUDED. | P22: VAT EXCLUDED.
A51: Signed for and on behalf of | Q51: Signed for and on behalf of
A52: Electrical Division | Q52: Division
Q54: Records
Q55: Mr. A. Sciberras
Q57: File

Sheet Preliminaries
A1: BILL OF QUANTITIES
A2: PRELIMINARIES
A5: Item | C5: Qty | D5: Unit | E5: Rate in € | F5: Total
A8: 1 | B8: Mobilisation and demobilisation including setting up of workshop storage facilities and their security. | C8: 1 | D8: LS | E8: =Elec_Est!E19 -> 610 | F8: =E8*C8 -> 610
A11: 2 | B11: Safety clothing for all site personnel in accordance with statutory requirements. | C11: 1 | D11: LS | E11: =Elec_Est!Q25 -> Included
A14: 3 | B14: Allowance for weekly progress meetings within project execution period. | C14: 1 | D14: LS | E14: =Elec_Est!Q32 -> Included
A17: 4 | B17: Provision of instrumentation used for commissioning purposes including evidence of associated valid calibration certificates. | C17: 1 | D17: LS | E17: =Elec_Est!Q38 -> Included
A20: 5 | B20: Two copies of a complete set of installation drawings allowing for coordination with sub-contractors, client, interior designer, etc. as applicable. | C20: 1 | D20: LS | E20: =Elec_Est!Q45 -> Included
A23: 6 | B23: Provision for a quality control engineer to ensure that the items being proposed are in accordance with technical specification and will fulfil the project requirements. | C23: 1 | D23: LS | E23: =Elec_Est!Q52 -> Included
A26: 7 | B26: Provision for a Quality Control Engineer to certify that the equipment and materials are installed, tested and commissioned in accordance with manufacturer's recommendations and / or relevant statutory requirements and / or CIBSE and / or equal and approved documents. | C26: 1 | D26: LS | E26: =Elec_Est!Q59 -> Included
A29: 8 | B29: Provision to identify access requirements for maintenance purposes in accordance with manufacturer's guidelines and common practice. | C29: 1 | D29: LS | E29: =Elec_Est!Q65 -> Included
A32: 9 | B32: Provision of signing of commissioning documentation by an independent Warranted Engineer. | C32: 1 | D32: LS | E32: =Elec_Est!E72 -> 1049.2 | F32: =E32*C32 -> 1049.2
A35: 10 | B35: Provision of signing of as-fitted drawings by an independent Warranted Engineer. | C35: 1 | D35: LS | E35: =Elec_Est!E78 -> 585.6 | F35: =E35*C35 -> 585.6
A42: P | B42: Total carried forward to summary page | F42: =SUM(F6:F40) -> 2244.8 | G42: =Elec_Est!F85 -> 2244.8
A48: Item | C48: Qty | D48: Unit | E48: Rate in € | F48: Total
A51: 11 | B51: To allow for builders works in accordance to the preamble section of the technical specifications. | C51: 1 | D51: LS | E51: =Elec_Est!Q90 -> Refer to covering letter.
A54: 12 | B54: Provision for a recognised Health and Safety Officer. | C54: 1 | D54: LS | E54: =Elec_Est!Q97 -> Included
A57: 13 | B57: Provision for completing the necessary risk assessment and method statements required. | C57: 1 | D57: LS | E57: =Elec_Est!E104 -> 2623 | F57: =E57*C57 -> 2623
A60: 14 | B60: Provision for an initial Program of Works and monthly updates | C60: 1 | D60: LS | E60: =Elec_Est!Q111 -> Included
A63: 15 | B63: Provision of Submittal Form for materials and Supply of Samples | C63: 1 | D63: LS | E63: =Elec_Est!Q118 -> Refer to covering letter.
A66: 16 | B66: Provision for Housekeeping and Waste Management | C66: 1 | D66: LS | E66: =Elec_Est!E125 -> 2913.72 | F66: =E66*C66 -> 2913.72
A69: 17 | B69: Provision of Local Council Permits to be charged at cost against receipts | C69: 1 | D69: LS | E69: =Elec_Est!Q132 -> Refer to covering letter.
A97: P | B97: Total carried forward to summary page | F97: =SUM(F49:F95) -> 5536.72 | G97: =Elec_Est!F141 -> 5536.72

Sheet Electrical
A1: BILL OF QUANTITIES
A2: ELECTRICAL SYSTEM
A5: Item | B5: Description | C5: Qty | D5: Unit | E5: Rate in € | F5: Total
A7: T | B7: MAIN INFRASTRUCTURE
A9: T | B9: SWITCHGEAR AND OTHER APPARATUS
A11: 1T | B11: Supply only the following switchgear and other accessories.
A13: a. | B13: Incomer Switchgear Panel SP-INC complete with Shunt Trip and Adjustable Earth Fault Relay | C13: 1 | D13: LS | E13: =Elec_Est!E168 -> 1256.56 | F13: =E13*C13 -> 1256.56
A15: b. | B15: Main Switchgear Panel MSP-NE including Transient Surge Protection | C15: 1 | D15: LS | E15: =Elec_Est!E174 -> 8432.71 | F15: =E15*C15 -> 8432.71
A17: c. | B17: Main Switchgear Panel MSP-ES | C17: 1 | D17: LS | E17: =Elec_Est!E181 -> 15258.49 | F17: =E17*C17 -> 15258.49
A19: d. | B19: 60kVAR Power Factor Correction Unit (PFCU) | C19: 1 | D19: LS | E19: =Elec_Est!E188 -> 4016.24 | F19: =E19*C19 -> 4016.24
A21: e. | B21: Switchgear Panel for Generator SP-GEN including Transient Surge Protection | C21: 1 | D21: LS | E21: =Elec_Est!E194 -> 7182.43 | F21: =E21*C21 -> 7182.43
A24: 2T | B24: Install and connect only the following switchgear and other accessories.
A26: a. | B26: Incomer Switchgear Panel SP-INC complete with Shunt Trip and Adjustable Earth Fault Relay | C26: 1 | D26: LS | E26: =Elec_Est!E204 -> 204.92 | F26: =E26*C26 -> 204.92
A28: b. | B28: Main Switchgear Panel MSP-NE including Transient Surge Protection | C28: 1 | D28: LS | E28: =Elec_Est!E213 -> 940.25 | F28: =E28*C28 -> 940.25
A30: c. | B30: Main Switchgear Panel MSP-ES | C30: 1 | D30: LS | E30: =Elec_Est!E226 -> 1198.79 | F30: =E30*C30 -> 1198.79
A32: d. | B32: 60kVAR Power Factor Correction Unit (PFCU) | C32: 1 | D32: LS | E32: =Elec_Est!E239 -> 462.67 | F32: =E32*C32 -> 462.67
A34: e. | B34: Switchgear Panel for Generator SP-GEN including Transient Surge Protection | C34: 1 | D34: LS | E34: =Elec_Est!E248 -> 915.41 | F34: =E34*C34 -> 915.41
A51: P | B51: Total carried forward to summary page | F51: =SUM(F6:F49) -> 39868.47 | G51: =Elec_Est!F258 -> 39868.47 | H51: =F51-G51 -> 0
A57: Item | B57: Description | C57: Qty | D57: Unit | E57: Rate in € | F57: Total
A59: T | B59: POWER CABLING
A61: 3T | B61: Supply and install the following power cables. Cost is to, include all cable terminations and fixing accessories as, necessary.
A66: a. | B66: From SP-INC to MSP-NE, 2 x (5 core x 70 mm2 ) XLPE/SWA/LSZH/Cu Cable | C66: 35 | D66: m/r | E66: =Elec_Est!E271 -> 124.11 | F66: =E66*C66 -> 4343.85
A69: b. | B69: From SP-GEN to ATS, 2 x (5 core x 50 mm2 ) FG16(O)M16 Cable | C69: 65 | D69: m/r | E69: =Elec_Est!E278 -> 96.07 | F69: =E69*C69 -> 6244.55
A72: c. | B72: From MSP-NE to ATS, 2 x (5 core x 50 mm2 ) FG16(O)M16 Cable | C72: 10 | D72: m/r | E72: =Elec_Est!E285 -> 96.07 | F72: =E72*C72 -> 960.7
A75: d. | B75: From ATS to MSP-ES, 2 x (5 core x 50 mm2 ) FG16(O)M16 Cable | C75: 10 | D75: m/r | E75: =Elec_Est!E292 -> 96.07 | F75: =E75*C75 -> 960.7
A78: e. | B78: From MSP-NE to PFCU, 5 core x 70 mm2 FG16(O)M16 Cable | C78: 10 | D78: m/r | E78: =Elec_Est!E299 -> 73.21 | F78: =E78*C78 -> 732.1
A81: f. | B81: From MSP-NE to DB-OU, 5 core x 25 mm2 FG16(O)M16 Cable | C81: 54 | D81: m/r | E81: =Elec_Est!E306 -> 24.84 | F81: =E81*C81 -> 1341.36
A84: g. | B84: From MSP-NE to Fire Fighting Lift ATS, 5 core x 6.0 mm2 Fire Rated F120 Cable | C84: 55 | D84: m/r | E84: =Elec_Est!E313 -> 23.58 | F84: =E84*C84 -> 1296.9
A87: h. | B87: From SP-GEN to Smoke Fans ATS, 5 core x 6.0 mm2 Fire Rated F120 Cable | C87: 20 | D87: m/r | E87: =Elec_Est!E320 -> 23.58 | F87: =E87*C87 -> 471.6
A90: i. | B90: From SP-GEN to Fire Fighting Lift ATS, 5 core x 6.0 mm2 Fire Rated F120 Cable | C90: 15 | D90: m/r | E90: =Elec_Est!E327 -> 23.58 | F90: =E90*C90 -> 353.7
A93: j. | B93: From MSP-ES to DB-B1, 5 core x 10 mm2 FG16(O)M16 Cable | C93: 13 | D93: m/r | E93: =Elec_Est!E334 -> 13.11 | F93: =E93*C93 -> 170.43
A96: k. | B96: From MSP-ES to DB-K, 5 core x 25 mm2 FG16(O)M16 Cable | C96: 22 | D96: m/r | E96: =Elec_Est!E341 -> 24.84 | F96: =E96*C96 -> 546.48
A99: l. | B99: From MSP-ES to DB-L0, 5 core x 10 mm2 FG16(O)M16 Cable | C99: 7 | D99: m/r | E99: =Elec_Est!E348 -> 13.11 | F99: =E99*C99 -> 91.77
A102: m. | B102: From MSP-ES to DB-L1, 5 core x 10 mm2 FG16(O)M16 Cable | C102: 38 | D102: m/r | E102: =Elec_Est!E355 -> 13.11 | F102: =E102*C102 -> 498.18
A105: n. | B105: From MSP-ES to DB-L2, 5 core x 10 mm2 FG16(O)M16 Cable | C105: 40 | D105: m/r | E105: =Elec_Est!E362 -> 13.11 | F105: =E105*C105 -> 524.4
A109: P | B109: Total carried forward to summary page | F109: =SUM(F58:F107) -> 18536.72 | G109: =Elec_Est!F370 -> 18536.72 | H109: =F109-G109 -> 0
A115: Item | B115: Description | C115: Qty | D115: Unit | E115: Rate in € | F115: Total
A118: o. | B118: From MSP-ES to DB-L3, 5 core x 10 mm2 FG16(O)M16 Cable | C118: 48 | D118: m/r | E118: =Elec_Est!E375 -> 13.11 | F118: =E118*C118 -> 629.28
A121: p. | B121: From MSP-ES to DB-L4, 5 core x 10 mm2 FG16(O)M16 Cable | C121: 51 | D121: m/r | E121: =Elec_Est!E382 -> 13.11 | F121: =E121*C121 -> 668.61
A124: q. | B124: From MSP-ES to DB-L5, 5 core x 10 mm2 FG16(O)M16 Cable | C124: 51 | D124: m/r | E124: =Elec_Est!E389 -> 13.11 | F124: =E124*C124 -> 668.61
...

Sheet Emergency Standby Generator
A1: BILL OF QUANTITIES
A2: EMERGENCY STANDBY GENERATOR
A5: Item | C5: Qty | D5: Unit | E5: Rate in € | F5: Total
A8: 1 | B8: Supply, deliver to site and place in its final location one prime rated power (PRP) 135kVA/ 400V/ 50Hz, diesel auto start stand-by generator set, complete as specified (excluding cost of ATS) | C8: 1 | D8: No. | E8: =Elec_Est!E4243 -> 24912.4 | F8: =E8*C8 -> 24912.4
A14: 2 | B14: Install, test and commission the 135kVA/ 400V/ 50Hz prime rated power (PRP) Generator Set, and associated switchgear in accordance with manufacturer's instructions and Enemalta Corporation Regulations, , Cost shall include all the necessary small power (battery charging) and control cables between the generator set and the ATS change-over panel, complete as specified., All commissioning documentation is to be certified for correctness and signed by a Warranted Engineer. | C14: 1 | D14: LS | E14: =Elec_Est!E4251 -> 1265.03 | F14: =E14*C14 -> 1265.03
A17: 3 | B17: Supply and deliver to site 250Amp TPN Automatic Transfer Switch (ATS) | C17: 1 | D17: No. | E17: =Elec_Est!E4262 -> 1220 | F17: =E17*C17 -> 1220
A20: 4 | B20: Install and connect 250Amp TPN Automatic Transfer Switch (ATS) | C20: 1 | D20: No. | E20: =Elec_Est!E4268 -> 161.74 | F20: =E20*C20 -> 161.74
A48: P | B48: Total carried forward to summary page | F48: =SUM(F6:F46) -> 27559.17 | G48: =Elec_Est!F4278 -> 27559.17

Sheet FIRE STOPPING
A1: BILL OF QUANTITIES
A2: FIRE STOPPING
A5: Item | C5: Qty | D5: Unit | E5: Rate in € | F5: Total
A7: 1 | B7: Fire barrier provisions to maintain fire compartmentation as required around and within all M&E services. Contractor to provide itemised cost breakdown under this sheet. | C7: 1 | D7: LS | E7: =Elec_Est!E4293 -> 2293.18 | F7: =E7*C7 -> 2293.18
A56: P | B56: Total carried forward to summary page | F56: =SUM(F6:F54) -> 2293.18 | G56: =Elec_Est!F4307 -> 2293.18

Sheet Fire Detection
A1: BILL OF QUANTITIES
A2: FIRE DETECTION & ALARM SYSTEM
A5: Item | C5: Qty | D5: Unit | E5: Rate in € | F5: Total
A7: T | B7: FIRE DETECTION AND ALARM
A9: T | B9: Supply, install, connect, test, commission and certify the following:
A11: T | B11: Basement Level -1
A13: 1 | B13: Analogue addressable optical smoke detectors c/w base | C13: 24 | D13: No. | E13: =Elec_Est!E4330 -> 62.88 | F13: =E13*C13 -> 1509.12
A16: =A13+1 -> 2 | B16: Analogue addressable optical smoke detectors c/w base sounder | C16: 1 | D16: No. | E16: =Elec_Est!E4336 -> 100.53 | F16: =E16*C16 -> 100.53
A19: =A16+1 -> 3 | B19: Analogue addressable heat detectors c/w base | C19: 3 | D19: No. | E19: =Elec_Est!E4342 -> 62.82 | F19: =E19*C19 -> 188.46
A22: =A19+1 -> 4 | B22: Open area sounder plus beacon | C22: 1 | D22: No. | E22: =Elec_Est!E4348 -> 162.55 | F22: =E22*C22 -> 162.55
A25: =A22+1 -> 5 | B25: Remote LED Alarm Indicators | C25: 21 | D25: No. | E25: =Elec_Est!E4354 -> 32.67 | F25: =E25*C25 -> 686.07
A28: =A25+1 -> 6 | B28: Manual call points as specified | C28: 2 | D28: No. | E28: =Elec_Est!E4360 -> 90.3 | F28: =E28*C28 -> 180.6
A31: =A28+1 -> 7 | B31: Interface modules | C31: 3 | D31: No. | E31: =Elec_Est!E4376 -> 341.21 | F31: =E31*C31 -> 1023.63
A34: =A31+1 -> 8 | B34: Cabling in 'Standard' fire alarm cable | C34: 120 | D34: m | E34: =Elec_Est!E4392 -> 10.78 | F34: =E34*C34 -> 1293.6
A37: =A34+1 -> 9 | B37: Fire Blanket | C37: 3 | D37: No. | E37: =Elec_Est!E4398 -> 23.5 | F37: =E37*C37 -> 70.5
A40: T | B40: GROUND FLOOR
A42: =A37+1 -> 10 | B42: Four loop analogue addressable fire alarm control panel, c/w auto dialer, power supply unit & backup batteries | C42: 1 | D42: No. | E42: =Elec_Est!E4408 -> 4117.53 | F42: =E42*C42 -> 4117.53
A45: =A42+1 -> 11 | B45: Analogue addressable optical smoke detectors c/w base | C45: 17 | D45: No. | E45: =Elec_Est!E4424 -> 62.88 | F45: =E45*C45 -> 1068.96
