Workbook
Name Access_Control: [1]Elec_Est!#REF!
Name AREAS: [1]ML_Sum!$X$1:$AD$16
Name AREAS: ML_Sum!$X$1:$AD$16
Name CCTV: [1]Elec_Est!#REF!
Name Data: [1]Elec_Est!#REF!
Name Fire_Alarm: [1]Elec_Est!#REF!
Name FO: [1]Elec_Est!#REF!
Name Guard: [1]Elec_Est!#REF!
Name Intercom: [1]Elec_Est!#REF!
Name Intruder_Alarm: [1]Elec_Est!#REF!

Sheet Notes
A1: NOTES

Sheet Elec_Rates
B1: CLIENT: | C1: =ML_Sum!$C1 -> 1 | D1: =ML_Sum!$D1 -> Battery Street Limited | F1: =ML_Sum!$F1 -> 0 | I1: 1 | J1: =ML_Sum!$J1 -> 1 | K1: =ML_Sum!$K1 -> 1 | L1: =ML_Sum!$L1 -> 1 | M1: =ML_Sum!$M1 -> 1 | N1: =ML_Sum!$N1 -> 1 | O1: =ML_Sum!$O1 -> 1 | Q1: =ML_Sum!$Q1 -> € | R1: R/Lab Cont | S1: =ML_Sum!$S1 -> R | T1: =ML_Sum!$T1 -> 1 | U1: =ML_Sum!W1 -> BOQ | V1: INCL | W1: MULT | X1: AREA | Y1: BOQ | Z1: TDWG | AA1: ACT | AB1: DIFF
B2: PROJECT: | C2: =ML_Sum!$C2 -> 1 | D2: =ML_Sum!$D2 -> MEP Works British Hotel | F2: =ML_Sum!$F2 -> Electrical | I2: 2 | J2: =ML_Sum!$J2 -> 1 | K2: =ML_Sum!$K2 -> 1 | L2: =ML_Sum!$L2 -> 1 | M2: =ML_Sum!$M2 -> 1 | N2: =ML_Sum!$N2 -> 1 | O2: =ML_Sum!$O2 -> 1 | Q2: =ML_Sum!$Q2 -> 0 | R2: mu_A | S2: =ML_Sum!$S2 -> 1 | T2: =ML_Sum!$T2 -> 27.46
B3: JOB DESC: | C3: =ML_Sum!$C3 -> 1 | D3: =ML_Sum!$D3 -> Electrical for Mechanical Services | F3: =ML_Sum!$F3 -> Controls | I3: 3 | J3: =ML_Sum!$J3 -> 1 | K3: =ML_Sum!$K3 -> 1 | L3: =ML_Sum!$L3 -> 1 | M3: =ML_Sum!$M3 -> 1 | N3: =ML_Sum!$N3 -> 1 | O3: =ML_Sum!$O3 -> 1 | Q3: =ML_Sum!$Q3 -> 0 | R3: mu_B | S3: =ML_Sum!$S3 -> 1 | T3: =ML_Sum!$T3 -> 27.46
B4: QUOTE No: | C4: =ML_Sum!$C4 -> 1 | D4: =ML_Sum!$D4 -> ELM25-0665 | F4: =ML_Sum!$F4 -> 0 | I4: 4 | J4: =ML_Sum!$J4 -> 1 | K4: =ML_Sum!$K4 -> 1 | L4: =ML_Sum!$L4 -> 1 | M4: =ML_Sum!$M4 -> 1 | N4: =ML_Sum!$N4 -> 1 | O4: =ML_Sum!$O4 -> 1 | Q4: =ML_Sum!$Q4 -> 0 | R4: mu_C | S4: =ML_Sum!$S4 -> 0 | T4: =ML_Sum!$T4 -> 0
B5: CLIENTs REF: | C5: =ML_Sum!$C5 -> 1 | D5: =ML_Sum!$D5 -> 0 | F5: =ML_Sum!$F5 -> 0 | I5: 5 | J5: =ML_Sum!$J5 -> 1 | K5: =ML_Sum!$K5 -> 1 | L5: =ML_Sum!$L5 -> 1 | M5: =ML_Sum!$M5 -> 1 | N5: =ML_Sum!$N5 -> 1 | O5: =ML_Sum!$O5 -> 1 | Q5: =ML_Sum!$Q5 -> 0 | R5: mu_D | S5: =ML_Sum!$S5 -> 0 | T5: =ML_Sum!$T5 -> 0
B6: VAT/DUTIES: | C6: =ML_Sum!$C6 -> 1 | D6: =ML_Sum!$D6 -> VAT EXCL. | F6: =ML_Sum!$F6 -> 0 | I6: 6 | J6: =ML_Sum!$J6 -> 1 | K6: =ML_Sum!$K6 -> 1 | L6: =ML_Sum!$L6 -> 1 | M6: =ML_Sum!$M6 -> 1 | N6: =ML_Sum!$N6 -> 1 | O6: =ML_Sum!$O6 -> 1 | Q6: =ML_Sum!$Q6 -> 0 | R6: mu_E | S6: =ML_Sum!$S6 -> 0 | T6: =ML_Sum!$T6 -> 0
B7: SAVED ON: | C7: =ML_Sum!$C7 -> 1 | D7: 39364 | F7: =ML_Sum!$F7 -> 0 | I7: 7 | J7: =ML_Sum!$J7 -> 1 | K7: =ML_Sum!$K7 -> 1 | L7: =ML_Sum!$L7 -> 1 | M7: =ML_Sum!$M7 -> 1 | N7: =ML_Sum!$N7 -> 1 | O7: =ML_Sum!$O7 -> 0 | Q7: =ML_Sum!$Q7 -> 0 | R7: mu_F | S7: =ML_Sum!$S7 -> 0 | T7: =ML_Sum!$T7 -> 0
B8: ESTIMATOR: | C8: =ML_Sum!$C8 -> 1 | D8: =ML_Sum!$D8 -> Umut Kaymak | F8: =ML_Sum!$F8 -> 0 | I8: 8 | J8: =ML_Sum!$J8 -> 1 | K8: =ML_Sum!$K8 -> 1 | L8: =ML_Sum!$L8 -> 1 | M8: =ML_Sum!$M8 -> 1 | N8: =ML_Sum!$N8 -> 1 | O8: =ML_Sum!$O8 -> 0 | Q8: =ML_Sum!$Q8 -> 0 | R8: mu_G | S8: =ML_Sum!$S8 -> 0 | T8: =ML_Sum!$T8 -> 0
B9: LABOUR RATE: | C9: =ML_Sum!$C9 -> 1 | D9: =ML_Sum!$D9 -> 27.46 | F9: =ML_Sum!$F9 -> 0 | I9: 9 | J9: =ML_Sum!$J9 -> 1 | K9: =ML_Sum!$K9 -> 1 | L9: =ML_Sum!$L9 -> 1 | M9: =ML_Sum!$M9 -> 1 | N9: =ML_Sum!$N9 -> 1 | O9: =ML_Sum!$O9 -> 0 | Q9: =ML_Sum!$Q9 -> 0 | R9: mu_H | S9: =ML_Sum!$S9 -> 0 | T9: =ML_Sum!$T9 -> 0
C10: =ML_Sum!$C10 -> 1 | F10: =ML_Sum!$F10 -> 0 | I10: 10 | J10: =ML_Sum!$J10 -> 1 | K10: =ML_Sum!$K10 -> 1 | L10: =ML_Sum!$L10 -> 1 | M10: =ML_Sum!$M10 -> 1 | N10: =ML_Sum!$N10 -> 1 | O10: =ML_Sum!$O10 -> 1 | Q10: =ML_Sum!$Q10 -> 0 | R10: mu_I | S10: =ML_Sum!$S10 -> 0 | T10: =ML_Sum!$T10 -> 0
C11: =ML_Sum!$C11 -> 1 | F11: =ML_Sum!$F11 -> 0 | Q11: =ML_Sum!$Q11 -> 0 | R11: mu_J | S11: =ML_Sum!$S11 -> 0 | T11: =ML_Sum!$T11 -> 0
C12: =ML_Sum!$C12 -> 1 | F12: =ML_Sum!$F12 -> 0 | Q12: =ML_Sum!$Q12 -> 0 | R12: MIXED | S12: =ML_Sum!$S12 -> MAT MU | T12: =ML_Sum!$T12 -> LAB RATE
G13: I_CODE | H13: C_CODE | I13: MAKE | J13: PART_NO | K13: MARKUP | L13: TYPE | M13: LIST_P | N13: P_FACT | O13: FIX | P13: DATE | Q13: %Dsct in BOQ | R13: MU TYPE | S13: MAT MU | T13: LAB RATE
Q14: Multip
A15: 1 | B15: =$A15 -> 1 | D15: 000# | K15: RATE | L15: RATE | Q15: =B15/A15 -> 1 | R15: =IF($B15=0,0,IF($S$1="R",ROUND(R23/$B15,2),R23/$B15)) -> 0 | T15: =IF($B15=0,0,IF($S$1="R",ROUND(T23/$B15,2),T23/$B15)) -> 0
D16: Based on:
R17: =$A17*Q17 -> 0 | T17: =$A17*S17*$T$1 -> 0
R18: =$A18*Q18 -> 0 | T18: =$A18*S18*$T$1 -> 0
R19: =$A19*Q19 -> 0 | T19: =$A19*S19*$T$1 -> 0
R20: =$A20*Q20 -> 0 | T20: =$A20*S20*$T$1 -> 0
R21: =$A21*Q21 -> 0 | T21: =$A21*S21*$T$1 -> 0
C22: << ==== TOTAL UNITS | R22: =$A22*Q22 -> 0 | T22: =$A22*S22*$T$1 -> 0
A23: d> | B23: =(R22+T22) -> 0 | D23: Sell_A | E23: =IF($B15=0,0,ROUND(ROUND(($R23*$S$2+($T23*$T$2))/$B15, 2)*$C$2,2)) -> 0 | F23: =ROUND($B15*$E23,2) -> 0 | K23: ITEM | L23: ITEM | R23: =SUM(R16:R22) -> 0 | T23: =SUM(T16:T22) -> 0
A24: END!
A25: END! | D25: RATE SHEET GRAND TOTAL | R25: MATERIAL | T25: LABOUR
A26: END!
A27: END! | D27: COMPONENTS | L27: COMP_RT | R27: =SUMIF($L$12:$L25,"",R$12:R25) -> 0 | T27: =SUMIF($L$12:$L25,"",T$12:T25) -> 0
A28: END! | D28: RATE SUMS (ITEMS) | L28: ITEM_RT | R28: =SUMIF($L$12:$L25,"ITEM",R$12:R25) -> 0 | T28: =SUMIF($L$12:$L25,"ITEM",T$12:T25) -> 0
A29: SB!
B30: V:56 | E30: COSTCODE TOTAL | R30: =SUM(R31:R86) -> 0 | T30: =SUM(T31:T86) -> 0
B31: 1 | C31: cc | D31: Erection materials | F31: 501 | P31: 1 | R31: =SUMIF($H$12:$H$24,$F31,R$12:R$24) -> 0 | T31: =SUMIF($H$12:$H$24,$F31,T$12:T$24) -> 0
B32: 2 | C32: cc | D32: Busbar Trunking | F32: 505 | P32: 1 | R32: =SUMIF($H$12:$H$24,$F32,R$12:R$24) -> 0 | T32: =SUMIF($H$12:$H$24,$F32,T$12:T$24) -> 0
B33: 3 | C33: cc | D33: Switchgear | F33: 510 | P33: 2 | R33: =SUMIF($H$12:$H$24,$F33,R$12:R$24) -> 0 | T33: =SUMIF($H$12:$H$24,$F33,T$12:T$24) -> 0
B34: 4 | C34: cc | D34: MCC Equipment | F34: 511 | P34: 2 | R34: =SUMIF($H$12:$H$24,$F34,R$12:R$24) -> 0 | T34: =SUMIF($H$12:$H$24,$F34,T$12:T$24) -> 0
B35: 5 | C35: cc | D35: BMS Equipment | F35: 512 | P35: 2 | R35: =SUMIF($H$12:$H$24,$F35,R$12:R$24) -> 0 | T35: =SUMIF($H$12:$H$24,$F35,T$12:T$24) -> 0
B36: 6 | C36: cc | D36: PVC Pipes / Ducts | F36: 520 | P36: 1 | R36: =SUMIF($H$12:$H$24,$F36,R$12:R$24) -> 0 | T36: =SUMIF($H$12:$H$24,$F36,T$12:T$24) -> 0
B37: 7 | C37: cc | D37: High/medium voltage switchgear | F37: 530 | P37: 2 | R37: =SUMIF($H$12:$H$24,$F37,R$12:R$24) -> 0 | T37: =SUMIF($H$12:$H$24,$F37,T$12:T$24) -> 0
B38: 8 | C38: cc | D38: Power Transformers | F38: 550 | P38: 2 | R38: =SUMIF($H$12:$H$24,$F38,R$12:R$24) -> 0 | T38: =SUMIF($H$12:$H$24,$F38,T$12:T$24) -> 0
B39: 9 | C39: cc | D39: Control Panels | F39: 570 | P39: 2 | R39: =SUMIF($H$12:$H$24,$F39,R$12:R$24) -> 0 | T39: =SUMIF($H$12:$H$24,$F39,T$12:T$24) -> 0
B40: 10 | C40: cc | D40: Electrical Single Core Cables | F40: 615 | P40: 2 | R40: =SUMIF($H$12:$H$24,$F40,R$12:R$24) -> 0 | T40: =SUMIF($H$12:$H$24,$F40,T$12:T$24) -> 0
...

Sheet Elec_Est
B1: CLIENT: | C1: =ML_Sum!$C1 -> 1 | D1: =ML_Sum!$D1 -> Battery Street Limited | F1: =ML_Sum!$F1 -> 0 | I1: 1 | J1: =ML_Sum!$J1 -> 1 | K1: =ML_Sum!$K1 -> 1 | L1: =ML_Sum!$L1 -> 1 | M1: =ML_Sum!$M1 -> 1 | N1: =ML_Sum!$N1 -> 1 | O1: =ML_Sum!$O1 -> 1 | Q1: =ML_Sum!$Q1 -> € | R1: R/Lab Cont | S1: =ML_Sum!$S1 -> R | T1: =ML_Sum!$T1 -> 1 | U1: =ML_Sum!W1 -> BOQ | V1: INCL | W1: MULT | X1: AREA | Y1: BOQ | Z1: TDWG | AA1: ACT | AB1: DIFF
B2: PROJECT: | C2: =ML_Sum!$C2 -> 1 | D2: =ML_Sum!$D2 -> MEP Works British Hotel | F2: =ML_Sum!$F2 -> Electrical | I2: 2 | J2: =ML_Sum!$J2 -> 1 | K2: =ML_Sum!$K2 -> 1 | L2: =ML_Sum!$L2 -> 1 | M2: =ML_Sum!$M2 -> 1 | N2: =ML_Sum!$N2 -> 1 | O2: =ML_Sum!$O2 -> 1 | Q2: =ML_Sum!$Q2 -> 0 | R2: mu_A | S2: =ML_Sum!$S2 -> 1 | T2: =ML_Sum!$T2 -> 27.46
B3: JOB DESC: | C3: =ML_Sum!$C3 -> 1 | D3: =ML_Sum!$D3 -> Electrical for Mechanical Services | F3: =ML_Sum!$F3 -> Controls | I3: 3 | J3: =ML_Sum!$J3 -> 1 | K3: =ML_Sum!$K3 -> 1 | L3: =ML_Sum!$L3 -> 1 | M3: =ML_Sum!$M3 -> 1 | N3: =ML_Sum!$N3 -> 1 | O3: =ML_Sum!$O3 -> 1 | Q3: =ML_Sum!$Q3 -> 0 | R3: mu_B | S3: =ML_Sum!$S3 -> 1 | T3: =ML_Sum!$T3 -> 27.46
B4: QUOTE No: | C4: =ML_Sum!$C4 -> 1 | D4: =ML_Sum!$D4 -> ELM25-0665 | F4: =ML_Sum!$F4 -> 0 | I4: 4 | J4: =ML_Sum!$J4 -> 1 | K4: =ML_Sum!$K4 -> 1 | L4: =ML_Sum!$L4 -> 1 | M4: =ML_Sum!$M4 -> 1 | N4: =ML_Sum!$N4 -> 1 | O4: =ML_Sum!$O4 -> 1 | Q4: =ML_Sum!$Q4 -> 0 | R4: mu_C | S4: =ML_Sum!$S4 -> 0 | T4: =ML_Sum!$T4 -> 0
B5: CLIENTs REF: | C5: =ML_Sum!$C5 -> 1 | D5: =ML_Sum!$D5 -> 0 | F5: =ML_Sum!$F5 -> 0 | I5: 5 | J5: =ML_Sum!$J5 -> 1 | K5: =ML_Sum!$K5 -> 1 | L5: =ML_Sum!$L5 -> 1 | M5: =ML_Sum!$M5 -> 1 | N5: =ML_Sum!$N5 -> 1 | O5: =ML_Sum!$O5 -> 1 | Q5: =ML_Sum!$Q5 -> 0 | R5: mu_D | S5: =ML_Sum!$S5 -> 0 | T5: =ML_Sum!$T5 -> 0
B6: VAT/DUTIES: | C6: =ML_Sum!$C6 -> 1 | D6: =ML_Sum!$D6 -> VAT EXCL. | F6: =ML_Sum!$F6 -> 0 | I6: 6 | J6: =ML_Sum!$J6 -> 1 | K6: =ML_Sum!$K6 -> 1 | L6: =ML_Sum!$L6 -> 1 | M6: =ML_Sum!$M6 -> 1 | N6: =ML_Sum!$N6 -> 1 | O6: =ML_Sum!$O6 -> 1 | Q6: =ML_Sum!$Q6 -> 0 | R6: mu_E | S6: =ML_Sum!$S6 -> 0 | T6: =ML_Sum!$T6 -> 0
B7: SAVED ON: | C7: =ML_Sum!$C7 -> 1 | D7: 39364 | F7: =ML_Sum!$F7 -> 0 | I7: 7 | J7: =ML_Sum!$J7 -> 1 | K7: =ML_Sum!$K7 -> 1 | L7: =ML_Sum!$L7 -> 1 | M7: =ML_Sum!$M7 -> 1 | N7: =ML_Sum!$N7 -> 1 | O7: =ML_Sum!$O7 -> 0 | Q7: =ML_Sum!$Q7 -> 0 | R7: mu_F | S7: =ML_Sum!$S7 -> 0 | T7: =ML_Sum!$T7 -> 0
B8: ESTIMATOR: | C8: =ML_Sum!$C8 -> 1 | D8: =ML_Sum!$D8 -> Umut Kaymak | F8: =ML_Sum!$F8 -> 0 | I8: 8 | J8: =ML_Sum!$J8 -> 1 | K8: =ML_Sum!$K8 -> 1 | L8: =ML_Sum!$L8 -> 1 | M8: =ML_Sum!$M8 -> 1 | N8: =ML_Sum!$N8 -> 1 | O8: =ML_Sum!$O8 -> 0 | Q8: =ML_Sum!$Q8 -> 0 | R8: mu_G | S8: =ML_Sum!$S8 -> 0 | T8: =ML_Sum!$T8 -> 0
B9: LABOUR RATE: | C9: =ML_Sum!$C9 -> 1 | D9: =ML_Sum!$D9 -> 27.46 | F9: =ML_Sum!$F9 -> 0 | I9: 9 | J9: =ML_Sum!$J9 -> 1 | K9: =ML_Sum!$K9 -> 1 | L9: =ML_Sum!$L9 -> 1 | M9: =ML_Sum!$M9 -> 1 | N9: =ML_Sum!$N9 -> 1 | O9: =ML_Sum!$O9 -> 0 | Q9: =ML_Sum!$Q9 -> 0 | R9: mu_H | S9: =ML_Sum!$S9 -> 0 | T9: =ML_Sum!$T9 -> 0
C10: =ML_Sum!$C10 -> 1 | F10: =ML_Sum!$F10 -> 0 | I10: 10 | J10: =ML_Sum!$J10 -> 1 | K10: =ML_Sum!$K10 -> 1 | L10: =ML_Sum!$L10 -> 1 | M10: =ML_Sum!$M10 -> 1 | N10: =ML_Sum!$N10 -> 1 | O10: =ML_Sum!$O10 -> 1 | Q10: =ML_Sum!$Q10 -> 0 | R10: mu_I | S10: =ML_Sum!$S10 -> 0 | T10: =ML_Sum!$T10 -> 0
C11: =ML_Sum!$C11 -> 1 | F11: =ML_Sum!$F11 -> 0 | Q11: =ML_Sum!$Q11 -> 0 | R11: mu_J | S11: =ML_Sum!$S11 -> 0 | T11: =ML_Sum!$T11 -> 0
C12: =ML_Sum!$C12 -> 1 | F12: =ML_Sum!$F12 -> 0 | Q12: =ML_Sum!$Q12 -> 0 | R12: MIXED | S12: =ML_Sum!$S12 -> MAT MU | T12: =ML_Sum!$T12 -> LAB RATE
G13: ISELL | H13: C_CODE | I13: MAKE | J13: PART_NO | K13: MARKUP | L13: TYPE | M13: LIST_P | N13: P_FACT | O13: FIX | P13: DATE | Q13: %Dsct in BOQ | R13: MU TYPE | S13: MAT MU | T13: LAB RATE | AM13: Tot Mat Cost | AN13: Unit Lab phr. | AO13: Tot Lab phr. | AP13: < for ELM / MEE
K14: TB
C15: t
D16: PLUMBING SYSTEMS
K18: TB
C19: t
D20: DOMESTIC COLD WATER SYSTEM
E22: Sell Rate | F22: Sell Total | K22: IB | AG22: U_M_Sell | AH22: T_M_Sell | AI22: U_L_Sell | AJ22: T_L_Sell | AK22: Total_Sell | AM22: T_M_Cost | AN22: T_L_Phr | AO22: Mat/Lab=1
A23: 1 | B23: No | D23: Item: 4 | E23: =IF(AND($A23=0,$A$1="DIF"),0, ROUND(ROUND(($R32*$S$2+($T32*$T$2))/A23,2)*$C$2,2)) -> 39.03 | F23: =ROUND($A23*$E23,2) -> 39.03 | G23: ISELL | K23: mu_A | L23: ITEM | T23: =IF(AND($R32=0,$T32=0),"0.00","mu :" & ROUND($F23/$C$2/($R32+$T32*$D$9),2)) -> mu :1 | AG23: =IF($E23=0,0,ROUND($R32*$S$2*$C$2/$A23,2)) -> 5.53 | AH23: =$AG23*$A23 -> 5.53 | AI23: =$E23-$AG23 -> 33.5 | AJ23: =$A23*$AI23 -> 33.5 | AK23: =ROUND(($AG23+$AI23)*$A23,2) -> 39.03 | AM23: =ROUND(R32,2) -> 5.53 | AN23: =ROUND(T32,2) -> 1.22 | AO23: =ROUND(AM23+AN23,2)*A23 -> 6.75
D24: Domestic Cold Water booster set - PDCW1/2 complete with control panel, inlet/outlet headers, isolating valves, strainers, check valves, pressure gauges, pressure vessel etc. as per specifications and equipment schedule
A25: 1 | B25: LS | D25: Connectring-up | G25: EMAT_001 | H25: 501 | I25: (__) | K25: 01-001 | O25: 1 | P25: 35705 | Q25: 0 | R25: =$A25*Q25 -> 0 | S25: 0.5 | T25: =$A25*S25*$T$1 -> 0.5
A26: 2 | B26: m | D26: 5 core x 2.5 mm2 FG16(O)M16 Cable | G26: CAMC_082 | H26: 616 | I26: (__) | K26: 07-006 | O26: 2 | P26: 38299 | Q26: 1.93 | R26: =$A26*Q26 -> 3.86 | S26: 0.06 | T26: =$A26*S26*$T$1 -> 0.12
A27: 2 | B27: No | D27: M20 PVC Gland | G27: CAAC_027 | H27: 620 | I27: (__) | O27: 2 | P27: 35431 | Q27: 0.41 | R27: =$A27*Q27 -> 0.82 | S27: 0.2 | T27: =$A27*S27*$T$1 -> 0.4
A28: 10 | B28: No | D28: Cable Lug 2.5 mm2 | G28: CAAC_005 | H28: 620 | I28: CTT | O28: 2 | P28: 34669 | Q28: 0.05 | R28: =$A28*Q28 -> 0.5 | S28: 0.02 | T28: =$A28*S28*$T$1 -> 0.2
A29: 2 | B29: No | D29: Cable Marker Wrap Around Type | G29: CAAC_025 | H29: 620 | I29: (__) | O29: 2 | Q29: 0.1 | R29: =$A29*Q29 -> 0.2 | T29: =$A29*S29*$T$1 -> 0
A30: 3 | B30: No | D30: Cable Tie 225mm | G30: CONS_009 | H30: 875 | I30: (__) | K30: 01-003 | O30: 1 | P30: 34669 | Q30: 0.05 | R30: =$A30*Q30 -> 0.15 | T30: =$A30*S30*$T$1 -> 0
D31: Pump Set with Control Panel | R31: =$A31*Q31 -> 0 | T31: =$A31*S31*$T$1 -> 0
A32: d> | B32: =(R31+T31) -> 0 | G32: ICOST | K32: mu_A | L32: ITEM | R32: =SUM(R24:R31) -> 5.53 | T32: =SUM(T24:T31) -> 1.22
K33: TB
C34: t
D35: REVERSE OSMOSIS WATER SYSTEM
E37: Sell Rate | F37: Sell Total | K37: IB | AG37: U_M_Sell | AH37: T_M_Sell | AI37: U_L_Sell | AJ37: T_L_Sell | AK37: Total_Sell | AM37: T_M_Cost | AN37: T_L_Phr | AO37: Mat/Lab=1
A38: 1 | B38: No | D38: Item: 17 | E38: =IF(AND($A38=0,$A$1="DIF"),0, ROUND(ROUND(($R47*$S$2+($T47*$T$2))/A38,2)*$C$2,2)) -> 39.03 | F38: =ROUND($A38*$E38,2) -> 39.03 | G38: ISELL | K38: mu_A | L38: ITEM | T38: =IF(AND($R47=0,$T47=0),"0.00","mu :" & ROUND($F38/$C$2/($R47+$T47*$D$9),2)) -> mu :1 | AG38: =IF($E38=0,0,ROUND($R47*$S$2*$C$2/$A38,2)) -> 5.53 | AH38: =$AG38*$A38 -> 5.53 | AI38: =$E38-$AG38 -> 33.5 | AJ38: =$A38*$AI38 -> 33.5 | AK38: =ROUND(($AG38+$AI38)*$A38,2) -> 39.03 | AM38: =ROUND(R47,2) -> 5.53 | AN38: =ROUND(T47,2) -> 1.22 | AO38: =ROUND(AM38+AN38,2)*A38 -> 6.75
D39: Reverse Osmosis Water booster set - PRO-1/2 set complete with control panel, inlet/outlet headers, isolating valves, strainers, check valves, pressure gauges, etc. as per specifications and equipment schedule
A40: 1 | B40: LS | D40: Connectring-up | G40: EMAT_001 | H40: 501 | I40: (__) | K40: 01-001 | O40: 1 | P40: 35705 | Q40: 0 | R40: =$A40*Q40 -> 0 | S40: 0.5 | T40: =$A40*S40*$T$1 -> 0.5
A41: 2 | B41: m | D41: 5 core x 2.5 mm2 FG16(O)M16 Cable | G41: CAMC_082 | H41: 616 | I41: (__) | K41: 07-006 | O41: 2 | P41: 38299 | Q41: 1.93 | R41: =$A41*Q41 -> 3.86 | S41: 0.06 | T41: =$A41*S41*$T$1 -> 0.12
A42: 2 | B42: No | D42: M20 PVC Gland | G42: CAAC_027 | H42: 620 | I42: (__) | O42: 2 | P42: 35431 | Q42: 0.41 | R42: =$A42*Q42 -> 0.82 | S42: 0.2 | T42: =$A42*S42*$T$1 -> 0.4
A43: 10 | B43: No | D43: Cable Lug 2.5 mm2 | G43: CAAC_005 | H43: 620 | I43: CTT | O43: 2 | P43: 34669 | Q43: 0.05 | R43: =$A43*Q43 -> 0.5 | S43: 0.02 | T43: =$A43*S43*$T$1 -> 0.2
...

Sheet ML_Sum
B1: CLIENT: | C1: 1 | D1: Battery Street Limited | G1: FALSE | H1: FALSE | I1: 1 | J1: =$Q109 -> 1 | K1: =$Q119 -> 1 | L1: =$Q129 -> 1 | M1: =$Q139 -> 1 | N1: =$Q149 -> 1 | O1: =$Q159 -> 1 | Q1: =IF(C1=1,"€","Curr?") -> € | R1: Recon /Lab.Cont >> | S1: =IF($S$39="PRINT","R","Do Not Print") -> R | T1: 1 | V1: {=IF(OR(X1=AREAS),1,0)} -> 1 | W1: BOQ | X1: x | Y1: x | Z1: x | AA1: x | AB1: x | AC1: x | AD1: x
B2: PROJECT: | C2: =IF($D$6="VAT INCLUDED",1.18,1)*(1-$Q2)*$C$1 -> 1 | D2: MEP Works British Hotel | F2: Electrical | G2: FALSE | I2: 2 | J2: =$Q110 -> 1 | K2: =$Q120 -> 1 | L2: =$Q130 -> 1 | M2: =$Q140 -> 1 | N2: =$Q150 -> 1 | O2: =$Q160 -> 1 | R2: ="A) " & IF($S2=0,"",ROUND($S2,2) & "-" & ROUND($T2/$D$9,2)) -> A) 1-1 | S2: 1 | T2: =$S2*$D$9 -> 27.46 | X2: x | Y2: x | Z2: x | AA2: x | AB2: x | AC2: x | AD2: x
B3: JOB DESC: | C3: =IF($D$6="VAT INCLUDED",1.18,1)*(1-$Q3)*$C$1 -> 1 | D3: Electrical for Mechanical Services | F3: Controls | G3: FALSE | I3: 3 | J3: =$Q111 -> 1 | K3: =$Q121 -> 1 | L3: =$Q131 -> 1 | M3: =$Q141 -> 1 | N3: =$Q151 -> 1 | O3: =$Q161 -> 1 | R3: ="B) " & IF($S3=0,"",ROUND($S3,2) & "-" & ROUND($T3/$D$9,2)) -> B) 1-1 | S3: 1 | T3: =$S3*$D$9 -> 27.46 | X3: x | Y3: x | Z3: x | AA3: x | AB3: x | AC3: x | AD3: x
B4: INT. QUOT No: | C4: =IF($D$6="VAT INCLUDED",1.18,1)*(1-$Q4)*$C$1 -> 1 | D4: ELM25-0665 | G4: FALSE | I4: 4 | J4: =$Q112 -> 1 | K4: =$Q122 -> 1 | L4: =$Q132 -> 1 | M4: =$Q142 -> 1 | N4: =$Q152 -> 1 | O4: =$Q162 -> 1 | R4: ="C) " & IF($S4=0,"",ROUND($S4,2) & "-" & ROUND($T4/$D$9,2)) -> C) | T4: =$S4*$D$10 -> 0 | X4: x | Y4: x | Z4: x | AA4: x | AB4: x | AC4: x | AD4: x
B5: CLIENTs REF: | C5: =IF($D$6="VAT INCLUDED",1.18,1)*(1-$Q5)*$C$1 -> 1 | G5: FALSE | I5: 5 | J5: =$Q113 -> 1 | K5: =$Q123 -> 1 | L5: =$Q133 -> 1 | M5: =$Q143 -> 1 | N5: =$Q153 -> 1 | O5: =$Q163 -> 1 | R5: ="D) " & IF($S5=0,"",ROUND($S5,2) & "-" & ROUND($T5/$D$9,2)) -> D) | T5: =$S5*$D$9 -> 0 | X5: x | Y5: x | Z5: x | AA5: x | AB5: x | AC5: x | AD5: x
B6: VAT: | C6: =IF($D$6="VAT INCLUDED",1.18,1)*(1-$Q6)*$C$1 -> 1 | D6: VAT EXCL. | G6: FALSE | I6: 6 | J6: =$Q114 -> 1 | K6: =$Q124 -> 1 | L6: =$Q134 -> 1 | M6: =$Q144 -> 1 | N6: =$Q154 -> 1 | O6: =$Q164 -> 1 | R6: ="E) " & IF($S6=0,"",ROUND($S6,2) & "-" & ROUND($T6/$D$9,2)) -> E) | T6: =$S6*$D$9 -> 0 | X6: x | Y6: x | Z6: x | AA6: x | AB6: x | AC6: x | AD6: x
B7: SAVED ON: | C7: =IF($D$6="VAT INCLUDED",1.18,1)*(1-$Q7)*$C$1 -> 1 | G7: FALSE | I7: 7 | J7: =$Q115 -> 1 | K7: =$Q125 -> 1 | L7: =$Q135 -> 1 | M7: =$Q145 -> 1 | N7: =$Q155 -> 1 | R7: ="F) " & IF($S7=0,"",ROUND($S7,2) & "-" & ROUND($T7/$D$9,2)) -> F) | T7: =$S7*$D$9 -> 0 | X7: x | Y7: x | Z7: x | AA7: x | AB7: x | AC7: x | AD7: x
B8: ESTIMATOR: | C8: =IF($D$6="VAT INCLUDED",1.18,1)*(1-$Q8)*$C$1 -> 1 | D8: Umut Kaymak | G8: FALSE | I8: 8 | J8: =$Q116 -> 1 | K8: =$Q126 -> 1 | L8: =$Q136 -> 1 | M8: =$Q146 -> 1 | N8: =$Q156 -> 1 | R8: ="G) " & IF($S8=0,"",ROUND($S8,2) & "-" & ROUND($T8/$D$9,2)) -> G) | T8: =$S8*$D$9 -> 0 | X8: x | Y8: x | Z8: x | AA8: x | AB8: x | AC8: x | AD8: x
B9: LAB. COST: | C9: =IF($D$6="VAT INCLUDED",1.18,1)*(1-$Q9)*$C$1 -> 1 | D9: 27.46 | G9: FALSE | I9: 9 | J9: =$Q117 -> 1 | K9: =$Q127 -> 1 | L9: =$Q137 -> 1 | M9: =$Q147 -> 1 | N9: =$Q157 -> 1 | R9: ="H) " & IF($S9=0,"",ROUND($S9,2) & "-" & ROUND($T9/$D$9,2)) -> H) | T9: =$S9*$D$9 -> 0 | X9: x | Y9: x | Z9: x | AA9: x | AB9: x | AC9: x | AD9: x
C10: =IF($D$6="VAT INCLUDED",1.18,1)*(1-$Q10)*$C$1 -> 1 | G10: FALSE | I10: 10 | J10: =$Q118 -> 1 | K10: =$Q128 -> 1 | L10: =$Q138 -> 1 | M10: =$Q148 -> 1 | N10: =$Q158 -> 1 | O10: =Q108 -> 1 | R10: =" I) " & IF($S10=0,"",ROUND($S10,2) & "-" & ROUND($T10/$D$9,2)) -> I) | T10: =$S10*$D$9 -> 0 | X10: x | Y10: x | Z10: x | AA10: x | AB10: x | AC10: x | AD10: x
C11: =IF($D$6="VAT INCLUDED",1.18,1)*(1-$Q11)*$C$1 -> 1 | R11: ="J) " & IF($S11=0,"",ROUND($S11,2) & "-" & ROUND($T11/$D$9,2)) -> J) | T11: =$S11*$D$9 -> 0 | X11: x | Y11: x | Z11: x | AA11: x | AB11: x | AC11: x | AD11: x
C12: =IF($D$6="VAT INCLUDED",1.18,1)*(1-$Q12)*$C$1 -> 1 | G12: SYSTEMS | H12: SYSTEMS | I12: SYSTEMS | J12: SYSTEMS | K12: SYSTEMS | L12: SYSTEMS | M12: SYSTEMS | N12: SYSTEMS | O12: SYSTEMS | P12: SYSTEMS | R12: MIXED - X,Y ) | S12: MAT MU | T12: LAB RATE | X12: x | Y12: x | Z12: x | AA12: x | AB12: x | AC12: x | AD12: x
B13: MATERIAL & LABOUR SUMMARY | G13: ItemCode | H13: CostCode | I13: MAKE | J13: PART_NO | K13: MARKUP | L13: TYPE | M13: LIST_P | N13: SET | O13: FIX | P13: DATE | Q13: %Dsct in BOQ | R13: MATMU-LABMU | S13: MAT CONT >> | T13: =SUM(Q108:Q164)/57 -> 1
B14: =IF($D$6<>"VAT EXCL.", "QUOTE ISSUED WITH VAT INCLUDED", "") | X14: x | Y14: x | Z14: x | AA14: x | AB14: x | AC14: x | AD14: x
Q15: =(C72-F35)/C72 -> 0 | R15: Average Discount applied in BOQ (Q2-Q12) | X15: x | Y15: x | Z15: x | AA15: x | AB15: x | AC15: x | AD15: x
B16: =IF($W$1<>"BOQ", "DIFF SET TO " & W1,"") | Q16: =(F35-E35)/F35 -> 0 | R16: Average Discount applied on Totals (Q23-Q32) | X16: x | Y16: x | Z16: x | AA16: x | AB16: x | AC16: x | AD16: x
Q17: =F74 -> 0 | R17: Overall Discount
B18: =IF(AND(G1,G2,G3,G4,G5,G6,G7,G8,G9,G10,H1)=TRUE, "", "CHECKLIST INCOMPLETE !" ) -> CHECKLIST INCOMPLETE !
B19: =IF(ABS(SUM(A23:A32))>100,"[Discy A-J] are high, Check it out."," ") | Q19: =R83 -> 0.99998551 | R19: Overall Markup (Final Selling Excl.VAT/Total Cost )
E21: DISCOUNTED | F21: SELLING | Q21: % Discnt | R21: MATERIAL | T21: LABOUR
A22: Discy.A-J | B22: Markup/LRate | E22: ="SELLING " & $Q$1 -> SELLING € | F22: =$Q$1 -> € | G22: VAT/DISC | H22: MU | I22: LABRATE | J22: LABCOST | Q22: on Totals | R22: € | T22: Pair Hrs.
A23: =IF($F23=0,"",($F23/$C2)-($R23*$S2+$T23*$T2)) -> -0.085745098 | B23: =IF(F23=0,"",IF(R23=0,"A) "&"---, "&ROUND(($F23/$C2-($R23*$S2))/$T23,2),IF(T23=0,"A) "&ROUND(($F23/$C2)/$R23,2),"A) "&ROUND(($F23/$C2-($T23*$T2))/$R23,2)&", " &ROUND(($F23/$C2-($R23*$S2))/$T23,2)))) -> A) 1, 27.46 | D23: =IF($F2="","",$F2) -> Electrical | E23: =F23*(1-Q23) -> 1777.17 | F23: =Elec_Est!F429 -> 1777.17 | G23: =C2 -> 1 | H23: =$S2 -> 1 | I23: =$T2 -> 27.46 | J23: =$D$9 -> 27.46 | R23: =Elec_Est!R429 -> 539.63355 | T23: =Elec_Est!T429 -> 45.07
A24: =IF($F24=0,"",($F24/$C3)-($R24*$S3+$T24*$T3)) -> 0.04 | B24: =IF(F24=0,"",IF(R24=0,"A) "&"---, "&ROUND(($F24/$C3-($R24*$S3))/$T24,2),IF(T24=0,"A) "&ROUND(($F24/$C3)/$R24,2),"A) "&ROUND(($F24/$C3-($T24*$T3))/$R24,2)&", " &ROUND(($F24/$C3-($R24*$S3))/$T24,2)))) -> A) 1 | D24: =IF($F3="","",$F3) -> Controls | E24: =F24*(1-Q24) -> 1380.77 | F24: =Elec_Est!F430 -> 1380.77 | G24: =C3 -> 1 | H24: =$S3 -> 1 | I24: =$T3 -> 27.46 | J24: =$D$9 -> 27.46 | R24: =Elec_Est!R430 -> 1380.73 | T24: =Elec_Est!T430 -> 0
A25: =IF($F25=0,"",($F25/$C4)-($R25*$S4+$T25*$T4)) | B25: =IF(F25=0,"",IF(R25=0,"A) "&"---, "&ROUND(($F25/$C4-($R25*$S4))/$T25,2),IF(T25=0,"A) "&ROUND(($F25/$C4)/$R25,2),"A) "&ROUND(($F25/$C4-($T25*$T4))/$R25,2)&", " &ROUND(($F25/$C4-($R25*$S4))/$T25,2)))) | D25: =IF($F4="","",$F4) | E25: =F25*(1-Q25) -> 0 | F25: =Elec_Est!F431 -> 0 | G25: =C4 -> 1 | H25: =$S4 -> 0 | I25: =$T4 -> 0 | J25: =$D$9 -> 27.46 | R25: =Elec_Est!R431 -> 0 | T25: =Elec_Est!T431 -> 0
A26: =IF($F26=0,"",($F26/$C5)-($R26*$S5+$T26*$T5)) | B26: =IF(F26=0,"",IF(R26=0,"A) "&"---, "&ROUND(($F26/$C5-($R26*$S5))/$T26,2),IF(T26=0,"A) "&ROUND(($F26/$C5)/$R26,2),"A) "&ROUND(($F26/$C5-($T26*$T5))/$R26,2)&", " &ROUND(($F26/$C5-($R26*$S5))/$T26,2)))) | D26: =IF($F5="","",$F5) | E26: =F26*(1-Q26) -> 0 | F26: =Elec_Est!F432 -> 0 | G26: =C5 -> 1 | H26: =$S5 -> 0 | I26: =$T5 -> 0 | J26: =$D$9 -> 27.46 | R26: =Elec_Est!R432 -> 0 | T26: =Elec_Est!T432 -> 0
A27: =IF($F27=0,"",($F27/$C6)-($R27*$S6+$T27*$T6)) | B27: =IF(F27=0,"",IF(R27=0,"A) "&"---, "&ROUND(($F27/$C6-($R27*$S6))/$T27,2),IF(T27=0,"A) "&ROUND(($F27/$C6)/$R27,2),"A) "&ROUND(($F27/$C6-($T27*$T6))/$R27,2)&", " &ROUND(($F27/$C6-($R27*$S6))/$T27,2)))) | D27: =IF($F6="","",$F6) | E27: =F27*(1-Q27) -> 0 | F27: =Elec_Est!F433 -> 0 | G27: =C6 -> 1 | H27: =$S6 -> 0 | I27: =$T6 -> 0 | J27: =$D$9 -> 27.46 | R27: =Elec_Est!R433 -> 0 | T27: =Elec_Est!T433 -> 0
A28: =IF($F28=0,"",($F28/$C7)-($R28*$S7+$T28*$T7)) | B28: =IF(F28=0,"",IF(R28=0,"A) "&"---, "&ROUND(($F28/$C7-($R28*$S7))/$T28,2),IF(T28=0,"A) "&ROUND(($F28/$C7)/$R28,2),"A) "&ROUND(($F28/$C7-($T28*$T7))/$R28,2)&", " &ROUND(($F28/$C7-($R28*$S7))/$T28,2)))) | D28: =IF($F7="","",$F7) | E28: =F28*(1-Q28) -> 0 | F28: =Elec_Est!F434 -> 0 | G28: =C7 -> 1 | H28: =$S7 -> 0 | I28: =$T7 -> 0 | J28: =$D$9 -> 27.46 | R28: =Elec_Est!R434 -> 0 | T28: =Elec_Est!T434 -> 0
A29: =IF($F29=0,"",($F29/$C8)-($R29*$S8+$T29*$T8)) | B29: =IF(F29=0,"",IF(R29=0,"A) "&"---, "&ROUND(($F29/$C8-($R29*$S8))/$T29,2),IF(T29=0,"A) "&ROUND(($F29/$C8)/$R29,2),"A) "&ROUND(($F29/$C8-($T29*$T8))/$R29,2)&", " &ROUND(($F29/$C8-($R29*$S8))/$T29,2)))) | D29: =IF($F8="","",$F8) | E29: =F29*(1-Q29) -> 0 | F29: =Elec_Est!F435 -> 0 | G29: =C8 -> 1 | H29: =$S8 -> 0 | I29: =$T8 -> 0 | J29: =$D$9 -> 27.46 | R29: =Elec_Est!R435 -> 0 | T29: =Elec_Est!T435 -> 0
A30: =IF($F30=0,"",($F30/$C9)-($R30*$S9+$T30*$T9)) | B30: =IF(F30=0,"",IF(R30=0,"A) "&"---, "&ROUND(($F30/$C9-($R30*$S9))/$T30,2),IF(T30=0,"A) "&ROUND(($F30/$C9)/$R30,2),"A) "&ROUND(($F30/$C9-($T30*$T9))/$R30,2)&", " &ROUND(($F30/$C9-($R30*$S9))/$T30,2)))) | D30: =IF($F9="","",$F9) | E30: =F30*(1-Q30) -> 0 | F30: =Elec_Est!F436 -> 0 | G30: =C9 -> 1 | H30: =$S9 -> 0 | I30: =$T9 -> 0 | J30: =$D$9 -> 27.46 | R30: =Elec_Est!R436 -> 0 | T30: =Elec_Est!T436 -> 0
A31: =IF($F31=0,"",($F31/$C10)-($R31*$S10+$T31*$T10)) | B31: =IF(F31=0,"",IF(R31=0,"A) "&"---, "&ROUND(($F31/$C10-($R31*$S10))/$T31,2),IF(T31=0,"A) "&ROUND(($F31/$C10)/$R31,2),"A) "&ROUND(($F31/$C10-($T31*$T10))/$R31,2)&", " &ROUND(($F31/$C10-($R31*$S10))/$T31,2)))) | D31: =IF($F10="","",$F10) | E31: =F31*(1-Q31) -> 0 | F31: =Elec_Est!F437 -> 0 | G31: =C10 -> 1 | H31: =$S10 -> 0 | I31: =$T10 -> 0 | J31: =$D$9 -> 27.46 | R31: =Elec_Est!R437 -> 0 | T31: =Elec_Est!T437 -> 0
A32: =IF($F32=0,"",($F32/$C11)-($R32*$S11+$T32*$T11)) | B32: =IF(F32=0,"",IF(R32=0,"A) "&"---, "&ROUND(($F32/$C11-($R32*$S11))/$T32,2),IF(T32=0,"A) "&ROUND(($F32/$C11)/$R32,2),"A) "&ROUND(($F32/$C11-($T32*$T11))/$R32,2)&", " &ROUND(($F32/$C11-($R32*$S11))/$T32,2)))) | D32: =IF($F11="","",$F11) | E32: =F32*(1-Q32) -> 0 | F32: =Elec_Est!F438 -> 0 | G32: =C11 -> 1 | H32: =$S11 -> 0 | I32: =$T11 -> 0 | J32: =$D$9 -> 27.46 | R32: =Elec_Est!R438 -> 0 | T32: =Elec_Est!T438 -> 0
C33: MIXED
A35: Discy.L | B35: =Plumbing!H45+Plumbing!H104+Plumbing!H155+Plumbing!H204+Plumbing!H254+Plumbing!H307+Plumbing!H348+Plumbing!H399+Plumbing!H449+Plumbing!H504+Plumbing!H561+Plumbing!H618+'Rain water & Drainage'!H48+'Rain water & Drainage'!H100+'Rain water & Drainage'!H148+'Rain water & Drainage'!H202+'Fire Fighting'!H54+'Fire Fighting'!H97 -> 3157.94 | D35: =B35-E35 -> 0 | E35: =SUM(E23:E32) -> 3157.94 | F35: =SUM(F23:F32) -> 3157.94 | R35: =SUM(R23:R32) -> 1920.3635 | T35: =SUM(T23:T32) -> 45.07
A36: =IF(A39=0,"0.00",A39-(A38*A37)) -> 0.00 | B36: BOQ TOTAL | E36: ="ESTIM TOTAL (" & $Q$1 & ")" -> ESTIM TOTAL (€)
A37: 1.125 | B37: <1 Actual LabCont | R37: =R165 -> 1920.3635 | S37: C.C.Totals | T37: =T165 -> 45.07
B38: <2 Phrs @ 1.00
B39: <3 Phrs @ Actual | Q39: Discy.T >> | R39: =R37-R35 -> 0 | S39: PRINT | T39: =T37-T35 -> 0
B41: Values Only on : | D41: 45573 | E41: 3171.67 | F41: 3171.67 | R41: 1920.3635 | T41: 45.57
A46: REMARKS:
A47: 1) VAT and Duties as above.
...

Sheet Quote
A1: =IF(AND(UPPER(LEFT(TRIM($D$8),11))="01",UPPER(LEFT(TRIM($D$9),3))<>"ELM"),"PANTA RETAIL LTD.","PANTA CONTRACTING LIMITED") -> PANTA CONTRACTING LIMITED
A2: =IF(UPPER(LEFT(TRIM($D$9),3))="ELM","ELEC-FOR-MECH INTERNAL QUOTATION","ELECTRICAL INTERNAL QUOTATION") -> ELEC-FOR-MECH INTERNAL QUOTATION
B5: ATT: | D5: Jason Camilleri | R5: Dated: | S5: =NOW() -> 46114.361
B6: CLIENT: | C6: Link to ML_SUM $D1 | D6: =ML_Sum!D1 -> Battery Street Limited
B7: PROJECT: | C7: Link to ML_SUM $D2 | D7: =ML_Sum!D2 -> MEP Works British Hotel
B8: JOB DESC: | C8: Link to ML_SUM $D3 | D8: =ML_Sum!D3 -> Electrical for Mechanical Services
B9: QUOTE No: | C9: Link to ML_SUM $D4 | D9: =ML_Sum!D4 -> ELM25-0665
B10: CLIENT's Ref: | C10: Link to ML_SUM $D5 | D10: =ML_Sum!D5 -> 0
D21: Material Cost (€) : | E21: =ML_Sum!R35 -> 1920.3635 | F21: =ML_Sum!D6 -> VAT EXCL. | G21: VAT EXCLUDED. | H21: VAT EXCLUDED. | I21: VAT EXCLUDED. | J21: VAT EXCLUDED. | K21: VAT EXCLUDED. | L21: VAT EXCLUDED. | M21: VAT EXCLUDED. | N21: VAT EXCLUDED. | O21: VAT EXCLUDED. | P21: VAT EXCLUDED.
D22: Labour Pair Hours : | E22: =ML_Sum!T35 -> 45.07
A53: Signed for and on behalf of | Q53: Signed for and on behalf of
A54: Electrical Division | Q54: Division
Q56: Records
Q57: Mr. K. Micallef
Q59: File

Sheet Plumbing
A1: BILL OF QUANTITIES
A2: PLUMBING SYSTEMS
A5: Item | C5: Qty | D5: Unit | E5: Total Material | F5: Total Labour | G5: Rate in € | H5: Total
B7: Supply, install, connect, test and commission the following as specified for a complete working system
B9: MAINS WATER SYSTEM
A11: 1 | B11: Incoming mains water pipework polypropylene (PPR) SDR 7.4. Cost to include for all fittings, any necessary adaptors, brackets and all accessories as necessary for a complete working installation.
B13: OD25mm | C13: 50 | D13: m | H13: =G13*C13 -> 0
B15: OD32mm | C15: 45 | D15: m | H15: =G15*C15 -> 0
A18: 2 | B18: Isolating valves in PPR on mains distribution pipework:
B20: OD25mm | C20: 5 | D20: No | H20: =G20*C20 -> 0
B22: OD32mm | C22: 3 | D22: No | H22: =G22*C22 -> 0
A25: T | B25: DOMESTIC COLD WATER SYSTEM
A27: 3 | B27: Domestic Cold Water VERTICAL storage tanks, 1500L storage capacity, complete with inlet and outlet valves, float valve and adequate supports, as required for a complete installation. | C27: 2 | D27: No | H27: =G27*C27 -> 0
A30: 4 | B30: Domestic Cold Water booster set - PDCW1/2 complete with control panel, inlet/outlet headers, isolating valves, strainers, check valves, pressure gauges, pressure vessel etc. as per specifications and equipment schedule | C30: 1 | D30: No | E30: =Elec_Est!AM23 -> 5.53 | F30: =Elec_Est!AN23 -> 1.22 | G30: =Elec_Est!E23 -> 39.03 | H30: =G30*C30 -> 39.03
A33: 5 | B33: Domestic cold water (DCW) pipework polypropylene (PPR) SDR 7.4. Cost to include for all fittings, any necessary adaptors, brackets, wall penetrations, and all accessories as necessary for a complete working installation.
B35: OD25mm | C35: 8 | D35: m | H35: =G35*C35 -> 0
B37: OD32mm | C37: 20 | D37: m | H37: =G37*C37 -> 0
B39: OD40mm | C39: 60 | D39: m | H39: =G39*C39 -> 0
B45: Total carried forward to summary page | E45: =SUM(E6:E43) -> 5.53 | F45: =SUM(F6:F43) -> 1.22 | H45: =SUM(H6:H43) -> 39.03
A51: Item | C51: Qty | D51: Unit | E51: Total Material | F51: Total Labour | G51: Rate in € | H51: Total
B53: OD50mm | C53: 30 | D53: m | H53: =G53*C53 -> 0
B55: OD63mm | C55: 30 | D55: m | H55: =G55*C55 -> 0
A58: 6 | B58: Isolating valves on the DCW distribution pipework:
B60: OD25mm | C60: 4 | D60: No | H60: =G60*C60 -> 0
B62: OD32mm | C62: 8 | D62: No | H62: =G62*C62 -> 0
B64: OD40mm | C64: 11 | D64: No | H64: =G64*C64 -> 0
B66: OD63mm | C66: 9 | D66: No | H66: =G66*C66 -> 0
A69: 7 | B69: Automatic Air Vents (AAV) on the DCW distribution pipework:
B71: OD25mm | C71: 2 | D71: No | H71: =G71*C71 -> 0
A74: 8 | B74: Drain Valves (DV) on the DCW distribution pipework:
B76: OD25mm | C76: 2 | D76: No | H76: =G76*C76 -> 0
A79: 9 | B79: Non-return valves on the DCW distribution pipework:
B81: OD32mm | C81: 2 | D81: No | H81: =G81*C81 -> 0
B83: OD63mm | C83: 2 | D83: No | H83: =G83*C83 -> 0
A86: 10 | B86: Strainers on the DCW distribution pipework:
B88: OD63mm | C88: 2 | D88: No | H88: =G88*C88 -> 0
H89: =G89*C89 -> 0
B104: Total carried forward to summary page | E104: =SUM(E52:E102) -> 0 | F104: =SUM(F52:F102) -> 0 | H104: =SUM(H52:H102) -> 0
A110: Item | C110: Qty | D110: Unit | E110: Total Material | F110: Total Labour | G110: Rate in € | H110: Total
B112: DOMESTIC COLD WATER TREATMENT PLANT
...

Sheet Rain water & Drainage
A1: BILL OF QUANTITIES
A2: DRAINAGE AND RAIN WATER SYSTEMS
A5: Item | C5: Qty | D5: Unit | E5: Total Material | F5: Total Labour | G5: Rate in € | H5: Total
B7: Supply, install and connect up the following drainage and rainwater systems allowing for all necessary fittings including bends, reducers, and galvanised steel brackets:
B9: Note: All Drainage and rainwater pipework, including related fittings, for Gravity Systems, shall be of the polypropylene (PP) silent type and suitable for hot water discharge.
B10: Any trenching below ground level, coring in slabs and making good shall form part of this scope of works and are to be included in the below rates.
B12: Drainage Installation
B14: Waste Water PP pipework from the drain points in the respective area to main stack allowing for all necessary fittings, brackets, branch-offs, etc. as required for a complete installation;
A16: 1 | B16: Low Level Horizontal Runs, laid to falls
B18: OD40 mm dia. | C18: 30 | D18: m | H18: =G18*C18 -> 0
B20: OD50 mm dia. | C20: 90 | D20: m | H20: =G20*C20 -> 0
B22: OD63 mm dia. | C22: 8 | D22: m | H22: =G22*C22 -> 0
B24: OD90 mm dia. | C24: 2 | D24: m | H24: =G24*C24 -> 0
B26: OD110 mm dia. | C26: 30 | D26: m | H26: =G26*C26 -> 0
A29: 2 | B29: High Level Horizontal Runs, laid to falls
B31: OD50 mm dia. | C31: 3 | D31: m | H31: =G31*C31 -> 0
B33: OD90 mm dia. | C33: 8 | D33: m | H33: =G33*C33 -> 0
B35: OD110 mm dia. | C35: 40 | D35: m | H35: =G35*C35 -> 0
B37: OD125 mm dia. | C37: 6 | D37: m | H37: =G37*C37 -> 0
B39: OD150 mm dia. | C39: 12 | D39: m | H39: =G39*C39 -> 0
A42: 3 | B42: Vertical Stacks, in shafts, exposed, etc.
B44: OD110 mm dia. | C44: 50 | D44: m | H44: =G44*C44 -> 0
B48: Total carried forward to summary page | E48: =SUM(E6:E46) -> 0 | F48: =SUM(F6:F46) -> 0 | H48: =SUM(H6:H46) -> 0
A54: Item | C54: Qty | D54: Unit | E54: Total Material | F54: Total Labour | G54: Rate in € | H54: Total
A56: 4 | B56: Waste Water Ventilation PP pipework from the drain points at Low Level to main vent stack at High level allowing for all necessary fittings, brackets, branch-offs, etc. including chased in walls as required for a complete installation;
B58: OD40 mm dia. | C58: 30 | D58: m | H58: =G58*C58 -> 0
B60: OD75 mm dia. | C60: 35 | D60: m | H60: =G60*C60 -> 0
A63: 5 | B63: Provision of the following waste water outlet points, run in chased down drops in PP:
B65: OD40mm Drains for wash hand basin | C65: 29 | D65: No | H65: =G65*C65 -> 0
B67: OD50mm Drains for kitchen sink/equipment | C67: 5 | D67: No | H67: =G67*C67 -> 0
B69: OD63mm Drains for kitchen equipment | C69: 1 | D69: No | H69: =G69*C69 -> 0
B71: OD110mm Drains for WC | C71: 18 | D71: No | H71: =G71*C71 -> 0
A74: 6 | B74: Drainage ancillaries, allowing for all necessary fittings, brackets, branch-offs, etc. to compliment the above listed pipework, as required for a complete installation.
B76: Aeration Valves OD75mm at the termination of the Ventilation pipework at level -01 | C76: 1 | D76: No | H76: =G76*C76 -> 0
B100: Total carried forward to summary page | E100: =SUM(E55:E98) -> 0 | F100: =SUM(F55:F98) -> 0 | H100: =SUM(H55:H98) -> 0
A106: Item | C106: Qty | D106: Unit | E106: Total Material | F106: Total Labour | G106: Rate in € | H106: Total
B108: Rainwater Installation
B110: Rainwater PP pipework from the collection points in the respective area to main stack allowing for all necessary fittings, brackets, branch-offs, etc. as required for a complete installation;
A112: 7 | B112: Low Level Horizontal Runs, laid to falls
B114: OD110 mm dia. | C114: 1 | D114: m | H114: =G114*C114 -> 0
...

Sheet Fire Fighting
A1: BILL OF QUANTITIES
A2: FIRE SAFETY AND FIRE FIGHTING SYSTEMS
A5: Item | C5: Qty | D5: Unit | E5: Total Material | F5: Total Labour | G5: Rate in € | H5: Total
B7: Design, supply, install, connect, test and commission the following as specified and as shown on the drawings, unless otherwise noted.
B9: DRY RISER INSTALLATION
A11: 1 | B11: Galvanised pipework c/w painting for a complete system, appropriate support brackets, etc. System to include all necessary accessories and ancillaries for a complete working system.
B13: DN 100 mm | C13: 40 | D13: m | H13: =G13*C13 -> 0
B15: DN 63 mm | C15: 15 | D15: m | H15: =G15*C15 -> 0
A18: 2 | B18: Landing valves c/w isolating valves and end caps.
B20: DN 63 mm | C20: 7 | D20: No | H20: =G20*C20 -> 0
A23: 3 | B23: Breaching inlet externally on façade complete with isolating valve | C23: 1 | D23: No | H23: =G23*C23 -> 0
A26: 4 | B26: Automatic Air Vent DN 63 mm | C26: 1 | D26: No | H26: =G26*C26 -> 0
A29: 5 | B29: Drain valve DN 63 mm | C29: 1 | D29: No | H29: =G29*C29 -> 0
B32: PORTABLE FIRE EXTINGUISHERS
A34: 6 | B34: Portable Fire Extinguishers:
B36: 2kg CO2 Class 34B | C36: 1 | D36: No | H36: =G36*C36 -> 0
B38: 6 Litre AFFF Class 13A | C38: 14 | D38: No | H38: =G38*C38 -> 0
B40: 6 Litre Wet Chemcial Class F | C40: 1 | D40: No | H40: =G40*C40 -> 0
A43: 7 | B43: Fire extinguisher point signs and signage | C43: 9 | D43: No | H43: =G43*C43 -> 0
B54: Total carried forward to summary page | E54: =SUM(E6:E52) -> 0 | F54: =SUM(F6:F52) -> 0 | H54: =SUM(H6:H52) -> 0
A60: Item | C60: Qty | D60: Unit | E60: Total Material | F60: Total Labour | G60: Rate in € | H60: Total
A62: T | B62: AUTOMATIC WET CHEMICAL SYSTEM
A64: 8T | B64: Automatic wet chemical system including cylinders, pipework, nozzles, interfaces to fire alarm, control panel etc. as required for a complete installation.
A66: a. | B66: 1700x1000mm Hood 1 in kitchen | C66: 1 | D66: No | G66: =Elec_Est!E368 -> 0 | H66: =G66*C66 -> 0
A68: b. | B68: 1700x1000mm Hood 2 in kitchen | C68: 1 | D68: No | G68: =Elec_Est!E374 -> 0 | H68: =G68*C68 -> 0
A71: T | B71: SMOKE CONTROL PRESSURIZATION SYSTEM
A73: 9 | B73: Smoke control pressurization system for the protected staircase, PF-01 as marked on the drawings including pressurization fan PF-01, interfaces to fire alarm, control panel, ancillaries etc. as required for a complete installation. (Tenderer is requested to visit the site prior to design of pressurization system, coordination with other services is also very important) | C73: 1 | D73: LS | E73: =Elec_Est!AM384 -> 127.89 | F73: =Elec_Est!AN384 -> 3.16 | G73: =Elec_Est!E384 -> 214.66 | H73: =G73*C73 -> 214.66
A76: 10 | B76: Smoke control pressurization system for the protected lobbies, PF-02 as marked on the drawings including pressurization fan PF-02, interfaces to fire alarm, control panel, ancillaries etc. as required for a complete installation. (Tenderer is requested to visit the site prior to design of pressurization system, coordination with other services is also very important) | C76: 1 | D76: LS | E76: =Elec_Est!AM403 -> 127.89 | F76: =Elec_Est!AN403 -> 3.16 | G76: =Elec_Est!E403 -> 214.66 | H76: =G76*C76 -> 214.66
B79: GENERAL
A81: 11 | B81: Provision and issue of full system design and hydraulic calculations for approval of each of the above systems | C81: 1 | D81: LS | H81: =G81*C81 -> 0
A84: 12 | B84: Issuing of detailed coordinated workshop drawings including pipework dimenisons, centre lines, levels, distances from wall, heights from FFL, etc. for approval prior to installations | C84: 1 | D84: LS | H84: =G84*C84 -> 0
B97: Total carried forward to summary page | E97: =SUM(E61:E95) -> 255.78 | F97: =SUM(F61:F95) -> 6.32 | H97: =SUM(H61:H95) -> 429.32
