Workbook
Name Access_Control: [1]Elec_Est!#REF!
Name AREAS: #REF!
Name AREAS: [2]ML_Sum!$X$1:$AD$16
Name AREAS: [1]ML_Sum!$X$1:$AD$16
Name AREAS: ML_Sum!$X$1:$AD$16
Name CCTV: [1]Elec_Est!#REF!
Name Data: [1]Elec_Est!#REF!
Name Fire_Alarm: [1]Elec_Est!#REF!
Name FO: [1]Elec_Est!#REF!
Name Guard: [1]Elec_Est!#REF!
Name Intercom: [1]Elec_Est!#REF!
Name Intruder_Alarm: [1]Elec_Est!#REF!

Sheet Notes
A1: NOTES | C1: Rev: 235
C2: checkdesc
A3: ELECTRICAL | C3: Elec_Rates
C4: Elec_Est
A5: Dist Boards | C5: Elv_Rates
A6: 1 | C6: ELV_Est
A7: 2 | C7: Ext_Quote
C8: Int_Quote
A9: Wiring Accessories | C9: Est_BOQ
A10: 1
A11: 2 | C11: Camilleri&Cuschieri Tenders
C12: Conduit
A13: ELV | C13: Wiring
C14: Supply
A15: Fire Alarm
A16: 1
A17: 2
A18: 3
A20: Data
A21: 1
A22: 2
A23: 3
B25: Double pole required
B26: Price includes delivery, fitting, basic power test
B27: Signal / Control wire excluded
B28: Non-Failsafe 230V Fast Running Modulating Actuator
B29: Documentation Attached
B30: Fitment comprises - installing on Damper, Connection to double pole, basic power test.
B31: 0-10V Signal for modulation. 2V closed / 10V open

Sheet ML_Sum
B1: CLIENT: | C1: 1 | D1: UMUT - Electrical Team | G1: FALSE | H1: FALSE | I1: 1 | J1: =$Q109 -> 1 | K1: =$Q119 -> 1 | L1: =$Q129 -> 1 | M1: =$Q139 -> 1 | N1: =$Q149 -> 1 | O1: =$Q159 -> 1 | Q1: =IF(C1=1,"€","Curr?") -> € | R1: Recon /Lab.Cont >> | S1: =IF($S$39="PRINT","R","Do Not Print") -> R | T1: 1.1 | V1: {=IF(OR(X1=AREAS),1,0)} -> 1 | W1: BOQ | X1: x | Y1: x | Z1: x | AA1: x | AB1: x | AC1: x | AD1: x
B2: PROJECT: | C2: =IF($D$6="VAT INCLUDED",1.18,1)*(1-$Q2)*$C$1 -> 1 | D2: Portomaso L4 Dampers | F2: Electrical Site Pair | G2: FALSE | I2: 2 | J2: =$Q110 -> 1 | K2: =$Q120 -> 1 | L2: =$Q130 -> 1 | M2: =$Q140 -> 1 | N2: =$Q150 -> 1 | O2: =$Q160 -> 1 | R2: ="A) " & IF($S2=0,"",ROUND($S2,2) & "-" & ROUND($T2/$D$9,2)) -> A) 1-1 | S2: 1 | T2: =D9*S2 -> 28.53 | X2: x | Y2: x | Z2: x | AA2: x | AB2: x | AC2: x | AD2: x
B3: JOB DESC: | C3: =IF($D$6="VAT INCLUDED",1.18,1)*(1-$Q3)*$C$1 -> 1 | D3: Damper for VAV boxes | F3: ECA/BMS Pair | G3: FALSE | I3: 3 | J3: =$Q111 -> 1 | K3: =$Q121 -> 1 | L3: =$Q131 -> 1 | M3: =$Q141 -> 1 | N3: =$Q151 -> 1 | O3: =$Q161 -> 1 | R3: ="B) " & IF($S3=0,"",ROUND($S3,2) & "-" & ROUND($T3/$D$9,2)) -> B) 1-1.18 | S3: 1 | T3: =D10*S3 -> 33.72 | X3: x | Y3: x | Z3: x | AA3: x | AB3: x | AC3: x | AD3: x
B4: INT. QUOT No: | C4: =IF($D$6="VAT INCLUDED",1.18,1)*(1-$Q4)*$C$1 -> 1 | D4: EL | F4: ECA/BMS Engineer | G4: FALSE | I4: 4 | J4: =$Q112 -> 1 | K4: =$Q122 -> 1 | L4: =$Q132 -> 1 | M4: =$Q142 -> 1 | N4: =$Q152 -> 1 | O4: =$Q162 -> 1 | R4: ="C) " & IF($S4=0,"",ROUND($S4,2) & "-" & ROUND($T4/$D$9,2)) -> C) 1-1.09 | S4: 1 | T4: =D11*S4 -> 31 | X4: x | Y4: x | Z4: x | AA4: x | AB4: x | AC4: x | AD4: x
B5: CLIENTs REF: | C5: =IF($D$6="VAT INCLUDED",1.18,1)*(1-$Q5)*$C$1 -> 1 | F5: BMS - Tech - Single | G5: FALSE | I5: 5 | J5: =$Q113 -> 1 | K5: =$Q123 -> 1 | L5: =$Q133 -> 1 | M5: =$Q143 -> 1 | N5: =$Q153 -> 1 | O5: =$Q163 -> 1 | R5: ="D) " & IF($S5=0,"",ROUND($S5,2) & "-" & ROUND($T5/$D$9,2)) -> D) 1-0.75 | S5: 1 | T5: =D12*S5 -> 21.44 | X5: x | Y5: x | Z5: x | AA5: x | AB5: x | AC5: x | AD5: x
B6: VAT: | C6: =IF($D$6="VAT INCLUDED",1.18,1)*(1-$Q6)*$C$1 -> 1 | D6: VAT EXCL. | F6: Edward/Mark + AGV | G6: FALSE | I6: 6 | J6: =$Q114 -> 1 | K6: =$Q124 -> 1 | L6: =$Q134 -> 1 | M6: =$Q144 -> 1 | N6: =$Q154 -> 1 | O6: =$Q176 -> 1 | R6: ="E) " & IF($S6=0,"",ROUND($S6,2) & "-" & ROUND($T6/$D$9,2)) -> E) 1-1.18 | S6: 1 | T6: =S6*(D12+12.28) -> 33.72 | X6: x | Y6: x | Z6: x | AA6: x | AB6: x | AC6: x | AD6: x
B7: SAVED ON: | C7: =IF($D$6="VAT INCLUDED",1.18,1)*(1-$Q7)*$C$1 -> 1 | G7: FALSE | I7: 7 | J7: =$Q115 -> 1 | K7: =$Q125 -> 1 | L7: =$Q135 -> 1 | M7: =$Q145 -> 1 | N7: =$Q155 -> 1 | R7: ="F) " & IF($S7=0,"",ROUND($S7,2) & "-" & ROUND($T7/$D$9,2)) -> F) | X7: x | Y7: x | Z7: x | AA7: x | AB7: x | AC7: x | AD7: x
B8: ESTIMATOR: | C8: =IF($D$6="VAT INCLUDED",1.18,1)*(1-$Q8)*$C$1 -> 1 | D8: G. Baranyay | G8: FALSE | I8: 8 | J8: =$Q116 -> 1 | K8: =$Q126 -> 1 | L8: =$Q136 -> 1 | M8: =$Q146 -> 1 | N8: =$Q156 -> 1 | R8: ="G) " & IF($S8=0,"",ROUND($S8,2) & "-" & ROUND($T8/$D$9,2)) -> G) | X8: x | Y8: x | Z8: x | AA8: x | AB8: x | AC8: x | AD8: x
B9: LAB. COST: | C9: =IF($D$6="VAT INCLUDED",1.18,1)*(1-$Q9)*$C$1 -> 1 | D9: 28.53 | E9: Cost for 2025 | G9: FALSE | I9: 9 | J9: =$Q117 -> 1 | K9: =$Q127 -> 1 | L9: =$Q137 -> 1 | M9: =$Q147 -> 1 | N9: =$Q157 -> 1 | R9: ="H) " & IF($S9=0,"",ROUND($S9,2) & "-" & ROUND($T9/$D$9,2)) -> H) | X9: x | Y9: x | Z9: x | AA9: x | AB9: x | AC9: x | AD9: x
C10: =IF($D$6="VAT INCLUDED",1.18,1)*(1-$Q10)*$C$1 -> 1 | D10: =12.28+21.44 -> 33.72 | E10: BMS Pair 2025 | G10: FALSE | I10: 10 | J10: =$Q118 -> 1 | K10: =$Q128 -> 1 | L10: =$Q138 -> 1 | M10: =$Q148 -> 1 | N10: =$Q158 -> 1 | O10: =Q108 -> 1 | R10: =" I) " & IF($S10=0,"",ROUND($S10,2) & "-" & ROUND($T10/$D$9,2)) -> I) | X10: x | Y10: x | Z10: x | AA10: x | AB10: x | AC10: x | AD10: x
C11: =IF($D$6="VAT INCLUDED",1.18,1)*(1-$Q11)*$C$1 -> 1 | D11: 31 | E11: BMS Engineer 2025 | R11: ="J) " & IF($S11=0,"",ROUND($S11,2) & "-" & ROUND($T11/$D$9,2)) -> J) | X11: x | Y11: x | Z11: x | AA11: x | AB11: x | AC11: x | AD11: x
C12: =IF($D$6="VAT INCLUDED",1.18,1)*(1-$Q12)*$C$1 -> 1 | D12: 21.44 | E12: BMS Tech 2025 | G12: SYSTEMS | H12: SYSTEMS | I12: SYSTEMS | J12: SYSTEMS | K12: SYSTEMS | L12: SYSTEMS | M12: SYSTEMS | N12: SYSTEMS | O12: SYSTEMS | P12: SYSTEMS | R12: MIXED - X,Y ) | S12: MAT MU | T12: LAB RATE | X12: x | Y12: x | Z12: x | AA12: x | AB12: x | AC12: x | AD12: x
B13: MATERIAL & LABOUR SUMMARY | G13: ItemCode | H13: CostCode | I13: MAKE | J13: PART_NO | K13: MARKUP | L13: TYPE | M13: LIST_P | N13: SET | O13: FIX | P13: DATE | Q13: %Dsct in BOQ | R13: MATMU-LABMU | S13: MAT CONT >> | T13: =SUM(Q108:Q176)/COUNT(Q108:Q176) -> 1
B14: =IF($D$6<>"VAT EXCL.", "QUOTE ISSUED WITH VAT INCLUDED", "") | X14: x | Y14: x | Z14: x | AA14: x | AB14: x | AC14: x | AD14: x
Q15: =(C72-F35)/C72 -> 0 | R15: Average Discount applied in BOQ (Q2-Q12) | X15: x | Y15: x | Z15: x | AA15: x | AB15: x | AC15: x | AD15: x
B16: =IF($W$1<>"BOQ", "DIFF SET TO " & W1,"") | Q16: =(F35-E35)/F35 -> 0 | R16: Average Discount applied on Totals (Q23-Q32) | X16: x | Y16: x | Z16: x | AA16: x | AB16: x | AC16: x | AD16: x
Q17: =F74 -> 0 | R17: Overall Discount
B18: =IF(AND(G1,G2,G3,G4,G5,G6,G7,G8,G9,G10,H1)=TRUE, "", "CHECKLIST INCOMPLETE !" ) -> CHECKLIST INCOMPLETE !
B19: =IF(ABS(SUM(A23:A32))>100,"[Discy A-J] are high, Check it out."," ") | Q19: =R83 -> 1.0574444 | R19: Overall Markup (Final Selling Excl.VAT/Total Cost )
E21: DISCOUNTED | F21: SELLING | Q21: % Discnt | R21: MATERIAL | T21: LABOUR
A22: Discy.A-J | B22: Markup/LRate | E22: ="SELLING " & $Q$1 -> SELLING € | F22: =$Q$1 -> € | G22: VAT/DISC | H22: MU | I22: LABRATE | J22: LABCOST | Q22: on Totals | R22: € | T22: Pair Hrs.
A23: =IF($F23=0,"",($F23/$C2)-($R23*$S2+$T23*$T2)) | B23: =IF(F23=0,"",IF(R23=0,"A) "&"---, "&ROUND(($F23/$C2-($R23*$S2))/$T23,2),IF(T23=0,"A) "&ROUND(($F23/$C2)/$R23,2),"A) "&ROUND(($F23/$C2-($T23*$T2))/$R23,2)&", " &ROUND(($F23/$C2-($R23*$S2))/$T23,2)))) | D23: =IF($F2="","",$F2) -> Electrical Site Pair | E23: =F23*(1-Q23) -> 0 | F23: =Elec_Est!F65 -> 0 | G23: =C2 -> 1 | H23: =$S2 -> 1 | I23: =$T2 -> 28.53 | J23: =$D$9 -> 28.53 | R23: =Elec_Est!R65 -> 0 | T23: =Elec_Est!T65 -> 0
A24: =IF($F24=0,"",($F24/$C3)-($R24*$S3+$T24*$T3)) -> 0 | B24: =IF(F24=0,"",IF(R24=0,"A) "&"---, "&ROUND(($F24/$C3-($R24*$S3))/$T24,2),IF(T24=0,"A) "&ROUND(($F24/$C3)/$R24,2),"A) "&ROUND(($F24/$C3-($T24*$T3))/$R24,2)&", " &ROUND(($F24/$C3-($R24*$S3))/$T24,2)))) -> A) 1, 33.72 | D24: =IF($F3="","",$F3) -> ECA/BMS Pair | E24: =F24*(1-Q24) -> 1050.92 | F24: =Elec_Est!F66 -> 1050.92 | G24: =C3 -> 1 | H24: =$S3 -> 1 | I24: =$T3 -> 33.72 | J24: =$D$9 -> 28.53 | R24: =Elec_Est!R66 -> 680 | T24: =Elec_Est!T66 -> 11
A25: =IF($F25=0,"",($F25/$C4)-($R25*$S4+$T25*$T4)) | B25: =IF(F25=0,"",IF(R25=0,"A) "&"---, "&ROUND(($F25/$C4-($R25*$S4))/$T25,2),IF(T25=0,"A) "&ROUND(($F25/$C4)/$R25,2),"A) "&ROUND(($F25/$C4-($T25*$T4))/$R25,2)&", " &ROUND(($F25/$C4-($R25*$S4))/$T25,2)))) | D25: =IF($F4="","",$F4) -> ECA/BMS Engineer | E25: =F25*(1-Q25) -> 0 | F25: =Elec_Est!F67 -> 0 | G25: =C4 -> 1 | H25: =$S4 -> 1 | I25: =$T4 -> 31 | J25: =$D$9 -> 28.53 | R25: =Elec_Est!R67 -> 0 | T25: =Elec_Est!T67 -> 0
A26: =IF($F26=0,"",($F26/$C5)-($R26*$S5+$T26*$T5)) | B26: =IF(F26=0,"",IF(R26=0,"A) "&"---, "&ROUND(($F26/$C5-($R26*$S5))/$T26,2),IF(T26=0,"A) "&ROUND(($F26/$C5)/$R26,2),"A) "&ROUND(($F26/$C5-($T26*$T5))/$R26,2)&", " &ROUND(($F26/$C5-($R26*$S5))/$T26,2)))) | D26: =IF($F5="","",$F5) -> BMS - Tech - Single | E26: =F26*(1-Q26) -> 0 | F26: =Elec_Est!F68 -> 0 | G26: =C5 -> 1 | H26: =$S5 -> 1 | I26: =$T5 -> 21.44 | J26: 21.44 | R26: =Elec_Est!R68 -> 0 | T26: =Elec_Est!T68 -> 0
A27: =IF($F27=0,"",($F27/$C6)-($R27*$S6+$T27*$T6)) | B27: =IF(F27=0,"",IF(R27=0,"A) "&"---, "&ROUND(($F27/$C6-($R27*$S6))/$T27,2),IF(T27=0,"A) "&ROUND(($F27/$C6)/$R27,2),"A) "&ROUND(($F27/$C6-($T27*$T6))/$R27,2)&", " &ROUND(($F27/$C6-($R27*$S6))/$T27,2)))) | D27: =IF($F6="","",$F6) -> Edward/Mark + AGV | E27: =F27*(1-Q27) -> 0 | F27: =Elec_Est!F69 -> 0 | G27: =C6 -> 1 | H27: =$S6 -> 1 | I27: =$T6 -> 33.72 | J27: 30 | R27: =Elec_Est!R69 -> 0 | T27: =Elec_Est!T69 -> 0
A28: =IF($F28=0,"",($F28/$C7)-($R28*$S7+$T28*$T7)) | B28: =IF(F28=0,"",IF(R28=0,"A) "&"---, "&ROUND(($F28/$C7-($R28*$S7))/$T28,2),IF(T28=0,"A) "&ROUND(($F28/$C7)/$R28,2),"A) "&ROUND(($F28/$C7-($T28*$T7))/$R28,2)&", " &ROUND(($F28/$C7-($R28*$S7))/$T28,2)))) | D28: =IF($F7="","",$F7) | E28: =F28*(1-Q28) -> 0 | F28: =Elec_Est!F70 -> 0 | G28: =C7 -> 1 | H28: =$S7 -> 0 | I28: =$T7 -> 0 | J28: =$D$9 -> 28.53 | R28: =Elec_Est!R70 -> 0 | T28: =Elec_Est!T70 -> 0
A29: =IF($F29=0,"",($F29/$C8)-($R29*$S8+$T29*$T8)) | B29: =IF(F29=0,"",IF(R29=0,"A) "&"---, "&ROUND(($F29/$C8-($R29*$S8))/$T29,2),IF(T29=0,"A) "&ROUND(($F29/$C8)/$R29,2),"A) "&ROUND(($F29/$C8-($T29*$T8))/$R29,2)&", " &ROUND(($F29/$C8-($R29*$S8))/$T29,2)))) | D29: =IF($F8="","",$F8) | E29: =F29*(1-Q29) -> 0 | F29: =Elec_Est!F71 -> 0 | G29: =C8 -> 1 | H29: =$S8 -> 0 | I29: =$T8 -> 0 | J29: =$D$9 -> 28.53 | R29: =Elec_Est!R71 -> 0 | T29: =Elec_Est!T71 -> 0
A30: =IF($F30=0,"",($F30/$C9)-($R30*$S9+$T30*$T9)) | B30: =IF(F30=0,"",IF(R30=0,"A) "&"---, "&ROUND(($F30/$C9-($R30*$S9))/$T30,2),IF(T30=0,"A) "&ROUND(($F30/$C9)/$R30,2),"A) "&ROUND(($F30/$C9-($T30*$T9))/$R30,2)&", " &ROUND(($F30/$C9-($R30*$S9))/$T30,2)))) | D30: =IF($F9="","",$F9) | E30: =F30*(1-Q30) -> 0 | F30: =Elec_Est!F72 -> 0 | G30: =C9 -> 1 | H30: =$S9 -> 0 | I30: =$T9 -> 0 | J30: =$D$9 -> 28.53 | R30: =Elec_Est!R72 -> 0 | T30: =Elec_Est!T72 -> 0
A31: =IF($F31=0,"",($F31/$C10)-($R31*$S10+$T31*$T10)) | B31: =IF(F31=0,"",IF(R31=0,"A) "&"---, "&ROUND(($F31/$C10-($R31*$S10))/$T31,2),IF(T31=0,"A) "&ROUND(($F31/$C10)/$R31,2),"A) "&ROUND(($F31/$C10-($T31*$T10))/$R31,2)&", " &ROUND(($F31/$C10-($R31*$S10))/$T31,2)))) | D31: =IF($F10="","",$F10) | E31: =F31*(1-Q31) -> 0 | F31: =Elec_Est!F73 -> 0 | G31: =C10 -> 1 | H31: =$S10 -> 0 | I31: =$T10 -> 0 | J31: =$D$9 -> 28.53 | R31: =Elec_Est!R73 -> 0 | T31: =Elec_Est!T73 -> 0
A32: =IF($F32=0,"",($F32/$C11)-($R32*$S11+$T32*$T11)) | B32: =IF(F32=0,"",IF(R32=0,"A) "&"---, "&ROUND(($F32/$C11-($R32*$S11))/$T32,2),IF(T32=0,"A) "&ROUND(($F32/$C11)/$R32,2),"A) "&ROUND(($F32/$C11-($T32*$T11))/$R32,2)&", " &ROUND(($F32/$C11-($R32*$S11))/$T32,2)))) | D32: =IF($F11="","",$F11) | E32: =F32*(1-Q32) -> 0 | F32: =Elec_Est!F74 -> 0 | G32: =C11 -> 1 | H32: =$S11 -> 0 | I32: =$T11 -> 0 | J32: =$D$9 -> 28.53 | R32: =Elec_Est!R74 -> 0 | T32: =Elec_Est!T74 -> 0
C33: MIXED
A35: Discy.L | B35: =E_BOQ!F56 -> 680 | E35: =SUM(E23:E32) -> 1050.92 | F35: =SUM(F23:F32) -> 1050.92 | R35: =SUM(R23:R32) -> 680 | T35: =SUM(T23:T32) -> 11
A36: =IF(A39=0,"0.00",A39-(A38*A37)) -> 0.00 | B36: BOQ TOTAL | E36: ="ESTIM TOTAL (" & $Q$1 & ")" -> ESTIM TOTAL (€)
A37: 1.125 | B37: <1 Actual LabCont | R37: =R177 -> 680 | S37: C.C.Totals | T37: =T177 -> 11
B38: <2 Phrs @ 1.00
B39: <3 Phrs @ Actual | Q39: Discy.T >> | R39: =R37-R35 -> 0 | S39: PRINT | T39: =T37-T35 -> 0
B41: Values Only on : | D41: 36892 | E41: values only | F41: values only | R41: values only | T41: values only
A46: REMARKS:
A47: 1) VAT and Duties as above.
...

Sheet Quote
A1: =IF(AND(UPPER(LEFT(TRIM($D$8),11))="01",UPPER(LEFT(TRIM($D$9),3))<>"ELM"),"PANTA RETAIL LTD.","PANTA CONTRACTING LIMITED") -> PANTA CONTRACTING LIMITED
A2: =IF(UPPER(LEFT(TRIM($D$9),3))="ELM","ELEC-FOR-MECH INTERNAL QUOTATION","ELECTRICAL INTERNAL QUOTATION") -> ELECTRICAL INTERNAL QUOTATION
B5: ATT: | D5: =IF(A2="Internal Quotation", "Mechanical Division","") | R5: Dated: | S5: =NOW() -> 46119.647
B6: CLIENT: | C6: Link to ML_SUM $D1 | D6: =ML_Sum!D1 -> UMUT - Electrical Team
B7: PROJECT: | C7: Link to ML_SUM $D2 | D7: =ML_Sum!D2 -> Portomaso L4 Dampers
B8: JOB DESC: | C8: Link to ML_SUM $D3 | D8: =ML_Sum!D3 -> Damper for VAV boxes
B9: QUOTE No: | C9: Link to ML_SUM $D4 | D9: =ML_Sum!D4 -> EL
B10: CLIENT's Ref: | C10: Link to ML_SUM $D5 | D10: =ML_Sum!D5 -> 0
D22: Selling Price (€) : | E22: =ML_Sum!E35 -> 1050.92 | F22: =ML_Sum!D6 -> VAT EXCL. | G22: VAT EXCLUDED. | H22: VAT EXCLUDED. | I22: VAT EXCLUDED. | J22: VAT EXCLUDED. | K22: VAT EXCLUDED. | L22: VAT EXCLUDED. | M22: VAT EXCLUDED. | N22: VAT EXCLUDED. | O22: VAT EXCLUDED. | P22: VAT EXCLUDED.
A51: Signed for and on behalf of | Q51: Signed for and on behalf of
A52: Electrical Division | Q52: Division
Q54: Records
Q55: Mr. A. Sciberras
Q57: File

Sheet Elec_Rates
B1: CLIENT: | C1: =ML_Sum!$C1 -> 1 | D1: =ML_Sum!$D1 -> UMUT - Electrical Team | F1: =ML_Sum!$F1 -> 0 | I1: 1 | J1: =ML_Sum!$J1 -> 1 | K1: =ML_Sum!$K1 -> 1 | L1: =ML_Sum!$L1 -> 1 | M1: =ML_Sum!$M1 -> 1 | N1: =ML_Sum!$N1 -> 1 | O1: =ML_Sum!$O1 -> 1 | Q1: =ML_Sum!$Q1 -> € | R1: R/Lab Cont | S1: =ML_Sum!$S1 -> R | T1: =ML_Sum!$T1 -> 1.1 | U1: =ML_Sum!W1 -> BOQ | V1: INCL | W1: MULT | X1: AREA | Y1: BOQ | Z1: TDWG | AA1: ACT | AB1: DIFF
B2: PROJECT: | C2: =ML_Sum!$C2 -> 1 | D2: =ML_Sum!$D2 -> Portomaso L4 Dampers | F2: =ML_Sum!$F2 -> Electrical Site Pair | I2: 2 | J2: =ML_Sum!$J2 -> 1 | K2: =ML_Sum!$K2 -> 1 | L2: =ML_Sum!$L2 -> 1 | M2: =ML_Sum!$M2 -> 1 | N2: =ML_Sum!$N2 -> 1 | O2: =ML_Sum!$O2 -> 1 | Q2: =ML_Sum!$Q2 -> 0 | R2: mu_A | S2: =ML_Sum!$S2 -> 1 | T2: =ML_Sum!$T2 -> 28.53
B3: JOB DESC: | C3: =ML_Sum!$C3 -> 1 | D3: =ML_Sum!$D3 -> Damper for VAV boxes | F3: =ML_Sum!$F3 -> ECA/BMS Pair | I3: 3 | J3: =ML_Sum!$J3 -> 1 | K3: =ML_Sum!$K3 -> 1 | L3: =ML_Sum!$L3 -> 1 | M3: =ML_Sum!$M3 -> 1 | N3: =ML_Sum!$N3 -> 1 | O3: =ML_Sum!$O3 -> 1 | Q3: =ML_Sum!$Q3 -> 0 | R3: mu_B | S3: =ML_Sum!$S3 -> 1 | T3: =ML_Sum!$T3 -> 33.72
B4: QUOTE No: | C4: =ML_Sum!$C4 -> 1 | D4: =ML_Sum!$D4 -> EL | F4: =ML_Sum!$F4 -> ECA/BMS Engineer | I4: 4 | J4: =ML_Sum!$J4 -> 1 | K4: =ML_Sum!$K4 -> 1 | L4: =ML_Sum!$L4 -> 1 | M4: =ML_Sum!$M4 -> 1 | N4: =ML_Sum!$N4 -> 1 | O4: =ML_Sum!$O4 -> 1 | Q4: =ML_Sum!$Q4 -> 0 | R4: mu_C | S4: =ML_Sum!$S4 -> 1 | T4: =ML_Sum!$T4 -> 31
B5: CLIENTs REF: | C5: =ML_Sum!$C5 -> 1 | D5: =ML_Sum!$D5 -> 0 | F5: =ML_Sum!$F5 -> BMS - Tech - Single | I5: 5 | J5: =ML_Sum!$J5 -> 1 | K5: =ML_Sum!$K5 -> 1 | L5: =ML_Sum!$L5 -> 1 | M5: =ML_Sum!$M5 -> 1 | N5: =ML_Sum!$N5 -> 1 | O5: =ML_Sum!$O5 -> 1 | Q5: =ML_Sum!$Q5 -> 0 | R5: mu_D | S5: =ML_Sum!$S5 -> 1 | T5: =ML_Sum!$T5 -> 21.44
B6: VAT/DUTIES: | C6: =ML_Sum!$C6 -> 1 | D6: =ML_Sum!$D6 -> VAT EXCL. | F6: =ML_Sum!$F6 -> Edward/Mark + AGV | I6: 6 | J6: =ML_Sum!$J6 -> 1 | K6: =ML_Sum!$K6 -> 1 | L6: =ML_Sum!$L6 -> 1 | M6: =ML_Sum!$M6 -> 1 | N6: =ML_Sum!$N6 -> 1 | O6: =ML_Sum!$O6 -> 1 | Q6: =ML_Sum!$Q6 -> 0 | R6: mu_E | S6: =ML_Sum!$S6 -> 1 | T6: =ML_Sum!$T6 -> 33.72
B7: SAVED ON: | C7: =ML_Sum!$C7 -> 1 | D7: 39364 | F7: =ML_Sum!$F7 -> 0 | I7: 7 | J7: =ML_Sum!$J7 -> 1 | K7: =ML_Sum!$K7 -> 1 | L7: =ML_Sum!$L7 -> 1 | M7: =ML_Sum!$M7 -> 1 | N7: =ML_Sum!$N7 -> 1 | O7: =ML_Sum!$O7 -> 0 | Q7: =ML_Sum!$Q7 -> 0 | R7: mu_F | S7: =ML_Sum!$S7 -> 0 | T7: =ML_Sum!$T7 -> 0
B8: ESTIMATOR: | C8: =ML_Sum!$C8 -> 1 | D8: =ML_Sum!$D8 -> G. Baranyay | F8: =ML_Sum!$F8 -> 0 | I8: 8 | J8: =ML_Sum!$J8 -> 1 | K8: =ML_Sum!$K8 -> 1 | L8: =ML_Sum!$L8 -> 1 | M8: =ML_Sum!$M8 -> 1 | N8: =ML_Sum!$N8 -> 1 | O8: =ML_Sum!$O8 -> 0 | Q8: =ML_Sum!$Q8 -> 0 | R8: mu_G | S8: =ML_Sum!$S8 -> 0 | T8: =ML_Sum!$T8 -> 0
B9: LABOUR RATE: | C9: =ML_Sum!$C9 -> 1 | D9: =ML_Sum!$D9 -> 28.53 | F9: =ML_Sum!$F9 -> 0 | I9: 9 | J9: =ML_Sum!$J9 -> 1 | K9: =ML_Sum!$K9 -> 1 | L9: =ML_Sum!$L9 -> 1 | M9: =ML_Sum!$M9 -> 1 | N9: =ML_Sum!$N9 -> 1 | O9: =ML_Sum!$O9 -> 0 | Q9: =ML_Sum!$Q9 -> 0 | R9: mu_H | S9: =ML_Sum!$S9 -> 0 | T9: =ML_Sum!$T9 -> 0
C10: =ML_Sum!$C10 -> 1 | F10: =ML_Sum!$F10 -> 0 | I10: 10 | J10: =ML_Sum!$J10 -> 1 | K10: =ML_Sum!$K10 -> 1 | L10: =ML_Sum!$L10 -> 1 | M10: =ML_Sum!$M10 -> 1 | N10: =ML_Sum!$N10 -> 1 | O10: =ML_Sum!$O10 -> 1 | Q10: =ML_Sum!$Q10 -> 0 | R10: mu_I | S10: =ML_Sum!$S10 -> 0 | T10: =ML_Sum!$T10 -> 0
C11: =ML_Sum!$C11 -> 1 | F11: =ML_Sum!$F11 -> 0 | Q11: =ML_Sum!$Q11 -> 0 | R11: mu_J | S11: =ML_Sum!$S11 -> 0 | T11: =ML_Sum!$T11 -> 0
C12: =ML_Sum!$C12 -> 1 | F12: =ML_Sum!$F12 -> 0 | Q12: =ML_Sum!$Q12 -> 0 | R12: MIXED | S12: =ML_Sum!$S12 -> MAT MU | T12: =ML_Sum!$T12 -> LAB RATE
G13: I_CODE | H13: C_CODE | I13: MAKE | J13: PART_NO | K13: MARKUP | L13: TYPE | M13: LIST_P | N13: P_FACT | O13: FIX | P13: DATE | Q13: %Dsct in BOQ | R13: MU TYPE | S13: MAT MU | T13: LAB RATE
C15: t | D15: Item:
D16: Start Typing Header
Q18: Multip
A19: 1 | B19: =Elec_Est!B162 -> 0 | D19: 001# Controllers | K19: RATE | L19: RATE | Q19: =B19/A19 -> 0 | R19: =IF($B19=0,0,IF($S$1="R",ROUND(R25/$B19,2),R25/$B19)) -> 0 | T19: =IF($B19=0,0,IF($S$1="R",ROUND(T25/$B19,2),T25/$B19)) -> 0
D20: Based on:
R21: =$A21*Q21 -> 0 | T21: =$A21*S21*$T$1 -> 0
A22: 1 | B22: No | D22: Controllers | G22: BMSE_001 | H22: 410 | I22: (__) | O22: 3 | R22: =$A22*Q22 -> 0 | T22: =$A22*S22*$T$1 -> 0
R23: =$A23*Q23 -> 0 | T23: =$A23*S23*$T$1 -> 0
C24: << ==== TOTAL UNITS | R24: =$A24*Q24 -> 0 | T24: =$A24*S24*$T$1 -> 0
A25: d> | B25: =(R25+T25)-SUM(R20:R24,T20:T24) -> 0 | D25: Sell_A | E25: =IF($B19=0,0,ROUND(ROUND(($R25*$S$2+($T25*$T$2))/$B19, 2)*$C$2,2)) -> 0 | F25: =ROUND($B19*$E25,2) -> 0 | K25: ITEM | L25: ITEM | R25: =SUM(R20:R24) -> 0 | T25: =SUM(T20:T24) -> 0
Q26: Multip
A27: 1 | B27: =Elec_Est!B163 -> 0 | D27: 002# Controller Modules | K27: RATE | L27: RATE | Q27: =B27/A27 -> 0 | R27: =IF($B27=0,0,IF($S$1="R",ROUND(R33/$B27,2),R33/$B27)) -> 0 | T27: =IF($B27=0,0,IF($S$1="R",ROUND(T33/$B27,2),T33/$B27)) -> 0
D28: Based on:
R29: =$A29*Q29 -> 0 | T29: =$A29*S29*$T$1 -> 0
A30: 1 | B30: No | D30: Controller Modules | G30: BMSE_001 | H30: 411 | I30: (__) | O30: 3 | R30: =$A30*Q30 -> 0 | T30: =$A30*S30*$T$1 -> 0
R31: =$A31*Q31 -> 0 | T31: =$A31*S31*$T$1 -> 0
C32: << ==== TOTAL UNITS | R32: =$A32*Q32 -> 0 | T32: =$A32*S32*$T$1 -> 0
A33: d> | B33: =(R33+T33)-SUM(R28:R32,T28:T32) -> 0 | D33: Sell_A | E33: =IF($B27=0,0,ROUND(ROUND(($R33*$S$2+($T33*$T$2))/$B27, 2)*$C$2,2)) -> 0 | F33: =ROUND($B27*$E33,2) -> 0 | K33: ITEM | L33: ITEM | R33: =SUM(R28:R32) -> 0 | T33: =SUM(T28:T32) -> 0
Q34: Multip
A35: 1 | B35: =Elec_Est!B164 -> 0 | D35: 003# Signal Cable | K35: RATE | L35: RATE | Q35: =B35/A35 -> 0 | R35: =IF($B35=0,0,IF($S$1="R",ROUND(R41/$B35,2),R41/$B35)) -> 0 | T35: =IF($B35=0,0,IF($S$1="R",ROUND(T41/$B35,2),T41/$B35)) -> 0
D36: Based on:
R37: =$A37*Q37 -> 0 | T37: =$A37*S37*$T$1 -> 0
A38: 1 | B38: No | D38: Signal Cable | G38: BMSE_001 | H38: 412 | I38: (__) | O38: 3 | R38: =$A38*Q38 -> 0 | T38: =$A38*S38*$T$1 -> 0
R39: =$A39*Q39 -> 0 | T39: =$A39*S39*$T$1 -> 0
C40: << ==== TOTAL UNITS | R40: =$A40*Q40 -> 0 | T40: =$A40*S40*$T$1 -> 0
A41: d> | B41: =(R41+T41)-SUM(R36:R40,T36:T40) -> 0 | D41: Sell_A | E41: =IF($B35=0,0,ROUND(ROUND(($R41*$S$2+($T41*$T$2))/$B35, 2)*$C$2,2)) -> 0 | F41: =ROUND($B35*$E41,2) -> 0 | K41: ITEM | L41: ITEM | R41: =SUM(R36:R40) -> 0 | T41: =SUM(T36:T40) -> 0
Q42: Multip
...

Sheet Elec_Est
B1: CLIENT: | C1: =ML_Sum!$C1 -> 1 | D1: =ML_Sum!$D1 -> UMUT - Electrical Team | F1: =ML_Sum!$F1 -> 0 | I1: 1 | J1: =ML_Sum!$J1 -> 1 | K1: =ML_Sum!$K1 -> 1 | L1: =ML_Sum!$L1 -> 1 | M1: =ML_Sum!$M1 -> 1 | N1: =ML_Sum!$N1 -> 1 | O1: =ML_Sum!$O1 -> 1 | Q1: =ML_Sum!$Q1 -> € | R1: R/Lab Cont | S1: =ML_Sum!$S1 -> R | T1: =ML_Sum!$T1 -> 1.1 | U1: =ML_Sum!W1 -> BOQ | V1: INCL | W1: MULT | X1: AREA | Y1: BOQ | Z1: TDWG | AA1: ACT | AB1: DIFF
B2: PROJECT: | C2: =ML_Sum!$C2 -> 1 | D2: =ML_Sum!$D2 -> Portomaso L4 Dampers | F2: =ML_Sum!$F2 -> Electrical Site Pair | I2: 2 | J2: =ML_Sum!$J2 -> 1 | K2: =ML_Sum!$K2 -> 1 | L2: =ML_Sum!$L2 -> 1 | M2: =ML_Sum!$M2 -> 1 | N2: =ML_Sum!$N2 -> 1 | O2: =ML_Sum!$O2 -> 1 | Q2: =ML_Sum!$Q2 -> 0 | R2: mu_A | S2: =ML_Sum!$S2 -> 1 | T2: =ML_Sum!$T2 -> 28.53
B3: JOB DESC: | C3: =ML_Sum!$C3 -> 1 | D3: =ML_Sum!$D3 -> Damper for VAV boxes | F3: =ML_Sum!$F3 -> ECA/BMS Pair | I3: 3 | J3: =ML_Sum!$J3 -> 1 | K3: =ML_Sum!$K3 -> 1 | L3: =ML_Sum!$L3 -> 1 | M3: =ML_Sum!$M3 -> 1 | N3: =ML_Sum!$N3 -> 1 | O3: =ML_Sum!$O3 -> 1 | Q3: =ML_Sum!$Q3 -> 0 | R3: mu_B | S3: =ML_Sum!$S3 -> 1 | T3: =ML_Sum!$T3 -> 33.72
B4: QUOTE No: | C4: =ML_Sum!$C4 -> 1 | D4: =ML_Sum!$D4 -> EL | F4: =ML_Sum!$F4 -> ECA/BMS Engineer | I4: 4 | J4: =ML_Sum!$J4 -> 1 | K4: =ML_Sum!$K4 -> 1 | L4: =ML_Sum!$L4 -> 1 | M4: =ML_Sum!$M4 -> 1 | N4: =ML_Sum!$N4 -> 1 | O4: =ML_Sum!$O4 -> 1 | Q4: =ML_Sum!$Q4 -> 0 | R4: mu_C | S4: =ML_Sum!$S4 -> 1 | T4: =ML_Sum!$T4 -> 31
B5: CLIENTs REF: | C5: =ML_Sum!$C5 -> 1 | D5: =ML_Sum!$D5 -> 0 | F5: =ML_Sum!$F5 -> BMS - Tech - Single | I5: 5 | J5: =ML_Sum!$J5 -> 1 | K5: =ML_Sum!$K5 -> 1 | L5: =ML_Sum!$L5 -> 1 | M5: =ML_Sum!$M5 -> 1 | N5: =ML_Sum!$N5 -> 1 | O5: =ML_Sum!$O5 -> 1 | Q5: =ML_Sum!$Q5 -> 0 | R5: mu_D | S5: =ML_Sum!$S5 -> 1 | T5: =ML_Sum!$T5 -> 21.44
B6: VAT/DUTIES: | C6: =ML_Sum!$C6 -> 1 | D6: =ML_Sum!$D6 -> VAT EXCL. | F6: =ML_Sum!$F6 -> Edward/Mark + AGV | I6: 6 | J6: =ML_Sum!$J6 -> 1 | K6: =ML_Sum!$K6 -> 1 | L6: =ML_Sum!$L6 -> 1 | M6: =ML_Sum!$M6 -> 1 | N6: =ML_Sum!$N6 -> 1 | O6: =ML_Sum!$O6 -> 1 | Q6: =ML_Sum!$Q6 -> 0 | R6: mu_E | S6: =ML_Sum!$S6 -> 1 | T6: =ML_Sum!$T6 -> 33.72
B7: SAVED ON: | C7: =ML_Sum!$C7 -> 1 | D7: 39364 | F7: =ML_Sum!$F7 -> 0 | I7: 7 | J7: =ML_Sum!$J7 -> 1 | K7: =ML_Sum!$K7 -> 1 | L7: =ML_Sum!$L7 -> 1 | M7: =ML_Sum!$M7 -> 1 | N7: =ML_Sum!$N7 -> 1 | O7: =ML_Sum!$O7 -> 0 | Q7: =ML_Sum!$Q7 -> 0 | R7: mu_F | S7: =ML_Sum!$S7 -> 0 | T7: =ML_Sum!$T7 -> 0
B8: ESTIMATOR: | C8: =ML_Sum!$C8 -> 1 | D8: =ML_Sum!$D8 -> G. Baranyay | F8: =ML_Sum!$F8 -> 0 | I8: 8 | J8: =ML_Sum!$J8 -> 1 | K8: =ML_Sum!$K8 -> 1 | L8: =ML_Sum!$L8 -> 1 | M8: =ML_Sum!$M8 -> 1 | N8: =ML_Sum!$N8 -> 1 | O8: =ML_Sum!$O8 -> 0 | Q8: =ML_Sum!$Q8 -> 0 | R8: mu_G | S8: =ML_Sum!$S8 -> 0 | T8: =ML_Sum!$T8 -> 0
B9: LABOUR RATE: | C9: =ML_Sum!$C9 -> 1 | D9: =ML_Sum!$D9 -> 28.53 | F9: =ML_Sum!$F9 -> 0 | I9: 9 | J9: =ML_Sum!$J9 -> 1 | K9: =ML_Sum!$K9 -> 1 | L9: =ML_Sum!$L9 -> 1 | M9: =ML_Sum!$M9 -> 1 | N9: =ML_Sum!$N9 -> 1 | O9: =ML_Sum!$O9 -> 0 | Q9: =ML_Sum!$Q9 -> 0 | R9: mu_H | S9: =ML_Sum!$S9 -> 0 | T9: =ML_Sum!$T9 -> 0
C10: =ML_Sum!$C10 -> 1 | F10: =ML_Sum!$F10 -> 0 | I10: 10 | J10: =ML_Sum!$J10 -> 1 | K10: =ML_Sum!$K10 -> 1 | L10: =ML_Sum!$L10 -> 1 | M10: =ML_Sum!$M10 -> 1 | N10: =ML_Sum!$N10 -> 1 | O10: =ML_Sum!$O10 -> 1 | Q10: =ML_Sum!$Q10 -> 0 | R10: mu_I | S10: =ML_Sum!$S10 -> 0 | T10: =ML_Sum!$T10 -> 0
C11: =ML_Sum!$C11 -> 1 | F11: =ML_Sum!$F11 -> 0 | Q11: =ML_Sum!$Q11 -> 0 | R11: mu_J | S11: =ML_Sum!$S11 -> 0 | T11: =ML_Sum!$T11 -> 0
C12: =ML_Sum!$C12 -> 1 | F12: =ML_Sum!$F12 -> 0 | Q12: =ML_Sum!$Q12 -> 0 | R12: MIXED | S12: =ML_Sum!$S12 -> MAT MU | T12: =ML_Sum!$T12 -> LAB RATE
G13: ISELL | H13: C_CODE | I13: MAKE | J13: PART_NO | K13: MARKUP | L13: TYPE | M13: LIST_P | N13: P_FACT | O13: FIX | P13: DATE | Q13: %Dsct in BOQ | R13: MU TYPE | S13: MAT MU | T13: LAB RATE | AM13: Tot Mat Cost | AN13: Unit Lab phr. | AO13: Tot Lab phr. | AP13: < for ELM / MEE
K14: TB
C15: t | D15: Item:
D16: Supply and Installation of the following:
E18: Sell Rate | F18: Sell Total | K18: IB | AG18: U_M_Sell | AH18: T_M_Sell | AI18: U_L_Sell | AJ18: T_L_Sell | AK18: Total_Sell | AM18: T_M_Cost | AN18: U_L_Phr | AO18: T_L_Phr | AP18: Mat/Lab=1
A19: 1 | B19: No | D19: Item: 14 | E19: =IF(AND($A19=0,$A$1="DIF"),0, ROUND(ROUND(($R27*$S$3+($T27*$T$3))/$A19,2)*$C$3,2)) -> 262.73 | F19: =ROUND($A19*$E19,2) -> 262.73 | G19: ISELL | K19: mu_B | L19: ITEM | T19: =IF(AND($R27=0,$T27=0),"0.00","mu: "& ROUND(F19/$C$3/($R27+$T27*$D$9),2)) -> mu: 1.06 | AG19: =IF($E19=0,0,ROUND($R27*$S$3*$C$3/$A19,2)) -> 170 | AH19: =$AG19*$A19 -> 170 | AI19: =$E19-$AG19 -> 92.73 | AJ19: =$A19*$AI19 -> 92.73 | AK19: =ROUND(($AG19+$AI19)*$A19,2) -> 262.73 | AM19: =ROUND(R27,2) -> 170 | AN19: =IF(A19=0,0,AO19/A19) -> 2.75 | AO19: =ROUND(T27,2) -> 2.75 | AP19: =ROUND(AM19+AO19,2)*A19 -> 172.75
D20: 230V / 0-10V - Actuator - 2NM for VAV box 350mm x 350mm | K20: n
R21: =$A21*Q21 -> 0 | T21: =$A21*S21*$T$1 -> 0
A22: 1 | B22: No | D22: Fast running rotary actuator, 2 Nm, AC 100...240 V, 2...10 V | E22: TMC230ASR | F22: Belimo | G22: BMSE_001 | H22: 416 | I22: (__) | O22: 3 | Q22: =135+20 -> 155 | R22: =$A22*Q22 -> 155 | T22: =$A22*S22*$T$1 -> 0
D23: (incl Delivery Fee and Fitment) | R23: =$A23*Q23 -> 0 | T23: =$A23*S23*$T$1 -> 0
A24: 1 | B24: No | D24: Termination, Testing, Sundries for Fitment | G24: BMSE_001 | H24: 421 | I24: (__) | O24: 3 | Q24: 15 | R24: =$A24*Q24 -> 15 | S24: 2.5 | T24: =$A24*S24*$T$1 -> 2.75
R25: =$A25*Q25 -> 0 | T25: =$A25*S25*$T$1 -> 0
R26: =$A26*Q26 -> 0 | T26: =$A26*S26*$T$1 -> 0
A27: d> | B27: =(R26+T26) -> 0 | G27: ICOST | K27: mu_B | L27: ITEM | R27: =SUM(R20:R26) -> 170 | T27: =SUM(T20:T26) -> 2.75
E28: Sell Rate | F28: Sell Total | K28: IB | AG28: U_M_Sell | AH28: T_M_Sell | AI28: U_L_Sell | AJ28: T_L_Sell | AK28: Total_Sell | AM28: T_M_Cost | AN28: U_L_Phr | AO28: T_L_Phr | AP28: Mat/Lab=1
A29: 1 | B29: No | D29: Item: 21 | E29: =IF(AND($A29=0,$A$1="DIF"),0, ROUND(ROUND(($R37*$S$3+($T37*$T$3))/$A29,2)*$C$3,2)) -> 262.73 | F29: =ROUND($A29*$E29,2) -> 262.73 | G29: ISELL | K29: mu_B | L29: ITEM | T29: =IF(AND($R37=0,$T37=0),"0.00","mu: "& ROUND(F29/$C$3/($R37+$T37*$D$9),2)) -> mu: 1.06 | AG29: =IF($E29=0,0,ROUND($R37*$S$3*$C$3/$A29,2)) -> 170 | AH29: =$AG29*$A29 -> 170 | AI29: =$E29-$AG29 -> 92.73 | AJ29: =$A29*$AI29 -> 92.73 | AK29: =ROUND(($AG29+$AI29)*$A29,2) -> 262.73 | AM29: =ROUND(R37,2) -> 170 | AN29: =IF(A29=0,0,AO29/A29) -> 2.75 | AO29: =ROUND(T37,2) -> 2.75 | AP29: =ROUND(AM29+AO29,2)*A29 -> 172.75
D30: 230V / 0-10V - Actuator - 2NM for VAV box 350mm x 350mm | K30: n
R31: =$A31*Q31 -> 0 | T31: =$A31*S31*$T$1 -> 0
A32: 1 | B32: No | D32: Fast running rotary actuator, 2 Nm, AC 100...240 V, 2...10 V | E32: TMC230ASR | F32: Belimo | G32: BMSE_001 | H32: 416 | I32: (__) | O32: 3 | Q32: =135+20 -> 155 | R32: =$A32*Q32 -> 155 | T32: =$A32*S32*$T$1 -> 0
D33: (incl Delivery Fee and Fitment) | R33: =$A33*Q33 -> 0 | T33: =$A33*S33*$T$1 -> 0
A34: 1 | B34: No | D34: Termination, Testing, Sundries for Fitment | G34: BMSE_001 | H34: 421 | I34: (__) | O34: 3 | Q34: 15 | R34: =$A34*Q34 -> 15 | S34: 2.5 | T34: =$A34*S34*$T$1 -> 2.75
R35: =$A35*Q35 -> 0 | T35: =$A35*S35*$T$1 -> 0
R36: =$A36*Q36 -> 0 | T36: =$A36*S36*$T$1 -> 0
A37: d> | B37: =(R36+T36) -> 0 | G37: ICOST | K37: mu_B | L37: ITEM | R37: =SUM(R30:R36) -> 170 | T37: =SUM(T30:T36) -> 2.75
E38: Sell Rate | F38: Sell Total | K38: IB | AG38: U_M_Sell | AH38: T_M_Sell | AI38: U_L_Sell | AJ38: T_L_Sell | AK38: Total_Sell | AM38: T_M_Cost | AN38: U_L_Phr | AO38: T_L_Phr | AP38: Mat/Lab=1
A39: 1 | B39: No | D39: Item: 27 | E39: =IF(AND($A39=0,$A$1="DIF"),0, ROUND(ROUND(($R47*$S$3+($T47*$T$3))/$A39,2)*$C$3,2)) -> 262.73 | F39: =ROUND($A39*$E39,2) -> 262.73 | G39: ISELL | K39: mu_B | L39: ITEM | T39: =IF(AND($R47=0,$T47=0),"0.00","mu: "& ROUND(F39/$C$3/($R47+$T47*$D$9),2)) -> mu: 1.06 | AG39: =IF($E39=0,0,ROUND($R47*$S$3*$C$3/$A39,2)) -> 170 | AH39: =$AG39*$A39 -> 170 | AI39: =$E39-$AG39 -> 92.73 | AJ39: =$A39*$AI39 -> 92.73 | AK39: =ROUND(($AG39+$AI39)*$A39,2) -> 262.73 | AM39: =ROUND(R47,2) -> 170 | AN39: =IF(A39=0,0,AO39/A39) -> 2.75 | AO39: =ROUND(T47,2) -> 2.75 | AP39: =ROUND(AM39+AO39,2)*A39 -> 172.75
D40: 230V / 0-10V - Actuator - 2NM for VAV box 400mm x 200mm | K40: n
R41: =$A41*Q41 -> 0 | T41: =$A41*S41*$T$1 -> 0
...

Sheet Example_Blocks
B1: CLIENT: | C1: =[2]ML_Sum!$C1 -> 1 | D1: =[2]ML_Sum!$D1 -> 0 | F1: =[2]ML_Sum!$F1 -> 0 | I1: 1 | J1: =[2]ML_Sum!$J1 -> 1 | K1: =[2]ML_Sum!$K1 -> 1 | L1: =[2]ML_Sum!$L1 -> 1 | M1: =[2]ML_Sum!$M1 -> 1 | N1: =[2]ML_Sum!$N1 -> 1 | O1: =[2]ML_Sum!$O1 -> 1 | Q1: =[2]ML_Sum!$Q1 -> € | R1: R/Lab Cont | S1: =[2]ML_Sum!$S1 -> R | T1: =[2]ML_Sum!$T1 -> 1 | U1: =[2]ML_Sum!W1 -> BOQ | V1: INCL | W1: MULT | X1: AREA | Y1: BOQ | Z1: TDWG | AA1: ACT | AB1: DIFF
B2: PROJECT: | C2: =[2]ML_Sum!$C2 -> 1 | D2: =[2]ML_Sum!$D2 -> Marsa Warehouse | F2: =[2]ML_Sum!$F2 -> Controls | I2: 2 | J2: =[2]ML_Sum!$J2 -> 1 | K2: =[2]ML_Sum!$K2 -> 1 | L2: =[2]ML_Sum!$L2 -> 1 | M2: =[2]ML_Sum!$M2 -> 1 | N2: =[2]ML_Sum!$N2 -> 1 | O2: =[2]ML_Sum!$O2 -> 1 | Q2: =[2]ML_Sum!$Q2 -> 0 | R2: mu_A | S2: =[2]ML_Sum!$S2 -> 1 | T2: =[2]ML_Sum!$T2 -> 27.46
B3: JOB DESC: | C3: =[2]ML_Sum!$C3 -> 1 | D3: =[2]ML_Sum!$D3 -> Tender | F3: =[2]ML_Sum!$F3 -> Preliminaries | I3: 3 | J3: =[2]ML_Sum!$J3 -> 1 | K3: =[2]ML_Sum!$K3 -> 1 | L3: =[2]ML_Sum!$L3 -> 1 | M3: =[2]ML_Sum!$M3 -> 1 | N3: =[2]ML_Sum!$N3 -> 1 | O3: =[2]ML_Sum!$O3 -> 1 | Q3: =[2]ML_Sum!$Q3 -> 0 | R3: mu_B | S3: =[2]ML_Sum!$S3 -> 1 | T3: =[2]ML_Sum!$T3 -> 27.46
B4: QUOTE No: | C4: =[2]ML_Sum!$C4 -> 1 | D4: =[2]ML_Sum!$D4 -> TBC | F4: =[2]ML_Sum!$F4 -> BMS - Pair | I4: 4 | J4: =[2]ML_Sum!$J4 -> 1 | K4: =[2]ML_Sum!$K4 -> 1 | L4: =[2]ML_Sum!$L4 -> 1 | M4: =[2]ML_Sum!$M4 -> 1 | N4: =[2]ML_Sum!$N4 -> 1 | O4: =[2]ML_Sum!$O4 -> 1 | Q4: =[2]ML_Sum!$Q4 -> 0 | R4: mu_C | S4: =[2]ML_Sum!$S4 -> 1.3 | T4: =[2]ML_Sum!$T4 -> 43.836
B5: CLIENTs REF: | C5: =[2]ML_Sum!$C5 -> 1 | D5: =[2]ML_Sum!$D5 -> 0 | F5: =[2]ML_Sum!$F5 -> BMS - Tech | I5: 5 | J5: =[2]ML_Sum!$J5 -> 1 | K5: =[2]ML_Sum!$K5 -> 1 | L5: =[2]ML_Sum!$L5 -> 1 | M5: =[2]ML_Sum!$M5 -> 1 | N5: =[2]ML_Sum!$N5 -> 1 | O5: =[2]ML_Sum!$O5 -> 1 | Q5: =[2]ML_Sum!$Q5 -> 0 | R5: mu_D | S5: =[2]ML_Sum!$S5 -> 1.3 | T5: =[2]ML_Sum!$T5 -> 27.872
B6: VAT/DUTIES: | C6: =[2]ML_Sum!$C6 -> 1 | D6: =[2]ML_Sum!$D6 -> VAT EXCL. | F6: =[2]ML_Sum!$F6 -> BMS - Engineer | I6: 6 | J6: =[2]ML_Sum!$J6 -> 1 | K6: =[2]ML_Sum!$K6 -> 1 | L6: =[2]ML_Sum!$L6 -> 1 | M6: =[2]ML_Sum!$M6 -> 1 | N6: =[2]ML_Sum!$N6 -> 1 | O6: =[2]ML_Sum!$O6 -> 1 | Q6: =[2]ML_Sum!$Q6 -> 0 | R6: mu_E | S6: =[2]ML_Sum!$S6 -> 1.3 | T6: =[2]ML_Sum!$T6 -> 39
B7: SAVED ON: | C7: =[2]ML_Sum!$C7 -> 1 | D7: 39364 | F7: =[2]ML_Sum!$F7 -> 0 | I7: 7 | J7: =[2]ML_Sum!$J7 -> 1 | K7: =[2]ML_Sum!$K7 -> 1 | L7: =[2]ML_Sum!$L7 -> 1 | M7: =[2]ML_Sum!$M7 -> 1 | N7: =[2]ML_Sum!$N7 -> 1 | O7: =[2]ML_Sum!$O7 -> 0 | Q7: =[2]ML_Sum!$Q7 -> 0 | R7: mu_F | S7: =[2]ML_Sum!$S7 -> 0 | T7: =[2]ML_Sum!$T7 -> 0
B8: ESTIMATOR: | C8: =[2]ML_Sum!$C8 -> 1 | D8: =[2]ML_Sum!$D8 -> G. Baranyay | F8: =[2]ML_Sum!$F8 -> 0 | I8: 8 | J8: =[2]ML_Sum!$J8 -> 1 | K8: =[2]ML_Sum!$K8 -> 1 | L8: =[2]ML_Sum!$L8 -> 1 | M8: =[2]ML_Sum!$M8 -> 1 | N8: =[2]ML_Sum!$N8 -> 1 | O8: =[2]ML_Sum!$O8 -> 0 | Q8: =[2]ML_Sum!$Q8 -> 0 | R8: mu_G | S8: =[2]ML_Sum!$S8 -> 0 | T8: =[2]ML_Sum!$T8 -> 0
B9: LABOUR RATE: | C9: =[2]ML_Sum!$C9 -> 1 | D9: =[2]ML_Sum!$D9 -> 27.46 | F9: =[2]ML_Sum!$F9 -> 0 | I9: 9 | J9: =[2]ML_Sum!$J9 -> 1 | K9: =[2]ML_Sum!$K9 -> 1 | L9: =[2]ML_Sum!$L9 -> 1 | M9: =[2]ML_Sum!$M9 -> 1 | N9: =[2]ML_Sum!$N9 -> 1 | O9: =[2]ML_Sum!$O9 -> 0 | Q9: =[2]ML_Sum!$Q9 -> 0 | R9: mu_H | S9: =[2]ML_Sum!$S9 -> 0 | T9: =[2]ML_Sum!$T9 -> 0
C10: =[2]ML_Sum!$C10 -> 1 | F10: =[2]ML_Sum!$F10 -> 0 | I10: 10 | J10: =[2]ML_Sum!$J10 -> 1 | K10: =[2]ML_Sum!$K10 -> 1 | L10: =[2]ML_Sum!$L10 -> 1 | M10: =[2]ML_Sum!$M10 -> 1 | N10: =[2]ML_Sum!$N10 -> 1 | O10: =[2]ML_Sum!$O10 -> 1 | Q10: =[2]ML_Sum!$Q10 -> 0 | R10: mu_I | S10: =[2]ML_Sum!$S10 -> 0 | T10: =[2]ML_Sum!$T10 -> 0
C11: =[2]ML_Sum!$C11 -> 1 | F11: =[2]ML_Sum!$F11 -> 0 | Q11: =[2]ML_Sum!$Q11 -> 0 | R11: mu_J | S11: =[2]ML_Sum!$S11 -> 0 | T11: =[2]ML_Sum!$T11 -> 0
C12: =[2]ML_Sum!$C12 -> 1 | F12: =[2]ML_Sum!$F12 -> 0 | Q12: =[2]ML_Sum!$Q12 -> 0 | R12: MIXED | S12: =[2]ML_Sum!$S12 -> MAT MU | T12: =[2]ML_Sum!$T12 -> LAB RATE
G13: ISELL | H13: C_CODE | I13: MAKE | J13: PART_NO | K13: MARKUP | L13: TYPE | M13: LIST_P | N13: P_FACT | O13: FIX | P13: DATE | Q13: %Dsct in BOQ | R13: MU TYPE | S13: MAT MU | T13: LAB RATE | AM13: Tot Mat Cost | AN13: Unit Lab phr. | AO13: Tot Lab phr. | AP13: < for ELM / MEE
K14: TB
C15: t | D15: Item:
D16: Supply and Installation of the following:
E18: Sell Rate | F18: Sell Total | K18: IB | AG18: U_M_Sell | AH18: T_M_Sell | AI18: U_L_Sell | AJ18: T_L_Sell | AK18: Total_Sell | AM18: T_M_Cost | AN18: U_L_Phr | AO18: T_L_Phr | AP18: Mat/Lab=1
A19: 1 | B19: No | D19: Item: 1.1 | E19: =IF(AND($A19=0,$A$1="DIF"),0, ROUND(ROUND(($R44*$S$4+($T44*$T$4))/$A19,2)*$C$4,2)) -> 645.72 | F19: =ROUND($A19*$E19,2) -> 645.72 | G19: ISELL | K19: mu_C | L19: ITEM | T19: =IF(AND($R44=0,$T44=0),"0.00","mu: "& ROUND(F19/$C$4/($R44+$T44*$D$9),2)) -> mu: 1.3 | AG19: =IF($E19=0,0,ROUND($R44*$S$4*$C$4/$A19,2)) -> 645.72 | AH19: =$AG19*$A19 -> 645.72 | AI19: =$E19-$AG19 -> 0 | AJ19: =$A19*$AI19 -> 0 | AK19: =ROUND(($AG19+$AI19)*$A19,2) -> 645.72 | AM19: =ROUND(R44,2) -> 496.71 | AN19: =IF(A19=0,0,AO19/A19) -> 0 | AO19: =ROUND(T44,2) -> 0 | AP19: =ROUND(AM19+AO19,2)*A19 -> 496.71
D20: Basic EF Control Panel - DoL | K20: n
R21: =$A21*Q21 -> 0 | T21: =$A21*S21*$T$1 -> 0
A22: 1 | B22: No | D22: Wall‑mounted enclosure 1 door IP66 H=500 W=400 D=300mm | E22: Schrack | F22: WSA5040300 | G22: BMSE_001 | H22: 415 | I22: (__) | O22: 3 | Q22: 80.91 | R22: =$A22*Q22 -> 80.91 | T22: =$A22*S22*$T$1 -> 0
A23: 1 | B23: No | D23: Wall-mounting brackets for WSA, WKT, WKA and BUS enclosures | E23: Schrack | F23: WSAWB004 | G23: BMSE_001 | H23: 415 | I23: (__) | O23: 3 | Q23: 3.43 | R23: =$A23*Q23 -> 3.43 | T23: =$A23*S23*$T$1 -> 0
A24: 1 | B24: No | D24: Knitted earthing cable 260mm long, blank | E24: Schrack | F24: WSTCUF260 | G24: BMSE_001 | H24: 415 | I24: (__) | O24: 3 | Q24: 2.55 | R24: =$A24*Q24 -> 2.55 | T24: =$A24*S24*$T$1 -> 0
A25: 1 | B25: No | D25: Selector switch, 3 pos, stay-put, clamp handle | E25: Schrack | F25: MM216872 + accessories | G25: BMSE_001 | H25: 415 | I25: (__) | O25: 3 | Q25: 8 | R25: =$A25*Q25 -> 8 | T25: =$A25*S25*$T$1 -> 0
A26: 1 | B26: No | D26: Motor Protection Circuit Breaker BE2, 3-pole, 6-10A | E26: Schrack | F26: BE201000 | G26: BMSE_001 | H26: 415 | I26: (__) | O26: 3 | Q26: 9.55 | R26: =$A26*Q26 -> 9.55 | T26: =$A26*S26*$T$1 -> 0
A27: 2 | B27: No | D27: Screw earth terminal 6/10 mm², type AVK 6/10 T | E27: Schrack | F27: IK622010 | G27: BMSE_001 | H27: 415 | I27: (__) | O27: 3 | Q27: 1.25 | R27: =$A27*Q27 -> 2.5 | T27: =$A27*S27*$T$1 -> 0
A28: 2 | B28: No | D28: Auxiliary contact, front-mounting for BE2 | E28: Schrack | F28: BE2ZAF11 | G28: BMSE_001 | H28: 415 | I28: (__) | O28: 3 | Q28: 0.094 | R28: =$A28*Q28 -> 0.188 | T28: =$A28*S28*$T$1 -> 0
A29: 1 | B29: No | D29: CAPUS Panel - Switch-disconnector 3 pole 25A | E29: Schrack | F29: SI338120 | G29: BMSE_001 | H29: 415 | I29: (__) | O29: 3 | Q29: 16.91 | R29: =$A29*Q29 -> 16.91 | T29: =$A29*S29*$T$1 -> 0
A30: 1 | B30: No | D30: CAPUS Panel - Set connection space cover | E30: Schrack | F30: SI336940 | G30: BMSE_001 | H30: 415 | I30: (__) | O30: 3 | Q30: 5.57 | R30: =$A30*Q30 -> 5.57 | T30: =$A30*S30*$T$1 -> 0
A31: 1 | B31: No | D31: CAPUS Panel - Extension shaft, length 300 mm | E31: Schrack | F31: SI336820 | G31: BMSE_001 | H31: 415 | I31: (__) | O31: 3 | Q31: 5.7 | R31: =$A31*Q31 -> 5.7 | T31: =$A31*S31*$T$1 -> 0
A32: 1 | B32: No | D32: CAPUS Panel - Rotary handle for door coupling drive, black | E32: Schrack | F32: SI336650 | G32: BMSE_001 | H32: 415 | I32: (__) | O32: 3 | Q32: 7.4 | R32: =$A32*Q32 -> 7.4 | T32: =$A32*S32*$T$1 -> 0
A33: 1 | B33: No | D33: LED-indicator monobloc 230VAC/DC red | E33: Schrack | F33: BZ501215-B | G33: BMSE_001 | H33: 415 | I33: (__) | O33: 3 | Q33: 0.98 | R33: =$A33*Q33 -> 0.98 | T33: =$A33*S33*$T$1 -> 0
... A36: 0 | B36: No | D36: Digital 1 channel day/week timer | E36: Schrack | F36: BZH14071 | G36: BMSE_001 | H36: 415 | I36: (__) | O36: 3 | Q36: 24.4 | R36: =$A36*Q36 -> 0 | T36: =$A36*S36*$T$1 -> 0
A37: =A33+A34+A35 -> 5 | B37: No | D37: Miniature Circuit Breaker (MCB) AMPARO 10kA, B 2A, 1-pole | E37: Schrack | F37: AM018102 | G37: BMSE_001 | H37: 415 | I37: (__) | O37: 3 | Q37: 2.42 | R37: =$A37*Q37 -> 12.1 | T37: =$A37*S37*$T$1 -> 0
A38: 1 | B38: No | D38: Single Phase Control Transformer 230V/24V, 100VA, IP00 | E38: Schrack | F38: LP602010T | G38: BMSE_001 | H38: 415 | I38: (__) | O38: 3 | Q38: 30 | R38: =$A38*Q38 -> 30 | T38: =$A38*S38*$T$1 -> 0
A39: 1 | B39: No | D39: Contactor 3‑pole, CUBICO Classic, 5,5kW, 12A, 1NO+1NC, 24VAC | E39: Schrack | F39: LZDC12B0 | G39: BMSE_001 | H39: 415 | I39: (__) | O39: 3 | Q39: 7 | R39: =$A39*Q39 -> 7 | T39: =$A39*S39*$T$1 -> 0
A40: 1 | B40: No | D40: Consumables | E40: Misc | G40: BMSE_001 | H40: 415 | I40: (__) | O40: 3 | Q40: 50 | R40: =$A40*Q40 -> 50 | T40: =$A40*S40*$T$1 -> 0
A41: 1 | B41: No | D41: Panel Building | E41: Catania | G41: BMSE_001 | H41: 420 | I41: (__) | O41: 3 | Q41: 250 | R41: =$A41*Q41 -> 250 | T41: =$A41*S41*$T$1 -> 0
R42: =$A42*Q42 -> 0 | T42: =$A42*S42*$T$1 -> 0
R43: =$A43*Q43 -> 0 | T43: =$A43*S43*$T$1 -> 0
...

Sheet E_BOQ
A1: ITEM NO. | B1: DESCRIPTION | C1: QTY | D1: UNIT | E1: RATE | F1: TOTAL | R1: Labour Hours
A2: checkdesc | E2: € | F2: € | R2: @ €33.72
A3: =TRIM(MID(Elec_Est!D15,6,30)) | B3: =Elec_Est!D16 -> Supply and Installation of the following:
A5: =TRIM(MID(Elec_Est!D19,6,30)) -> 14 | B5: =Elec_Est!D20 -> 230V / 0-10V - Actuator - 2NM for VAV box 350mm x 350mm | C5: =Elec_Est!A19 -> 1 | D5: =Elec_Est!B19 -> No | E5: 170 | F5: =C5*E5 -> 170 | R5: 2.5
A7: =TRIM(MID(Elec_Est!D29,6,30)) -> 21 | B7: =Elec_Est!D30 -> 230V / 0-10V - Actuator - 2NM for VAV box 350mm x 350mm | C7: =Elec_Est!A29 -> 1 | D7: =Elec_Est!B29 -> No | E7: 170 | F7: =C7*E7 -> 170 | R7: 2.5
A9: =TRIM(MID(Elec_Est!D39,6,30)) -> 27 | B9: =Elec_Est!D40 -> 230V / 0-10V - Actuator - 2NM for VAV box 400mm x 200mm | C9: =Elec_Est!A39 -> 1 | D9: =Elec_Est!B39 -> No | E9: 170 | F9: =C9*E9 -> 170 | R9: 2.5
A11: =TRIM(MID(Elec_Est!D49,6,30)) -> 34 | B11: =Elec_Est!D50 -> 230V / 0-10V - Actuator - 2NM for VAV box 400mm x 200mm | C11: =Elec_Est!A49 -> 1 | D11: =Elec_Est!B49 -> No | E11: 170 | F11: =C11*E11 -> 170 | R11: 2.5
B52: Page Total -
B54: Contract Discount -
A56: SB | B56: Discounted Page Total - | D56: =ML_Sum!D6 -> VAT EXCL. | E56: € | F56: =SUM(F3:F55) -> 680 | G56: =SUM(G3:G55) -> 0 | H56: =SUM(H3:H55) -> 0 | I56: =SUM(I3:I55) -> 0 | J56: =SUM(J3:J55) -> 0 | K56: =SUM(K3:K55) -> 0 | L56: =SUM(L3:L55) -> 0 | M56: =SUM(M3:M55) -> 0 | ... P56: =SUM(P3:P55) -> 0 | R56: €
A57: ITEM NO. | B57: DESCRIPTION | C57: QTY | D57: UNIT | E57: RATE | F57: TOTAL | R57: RATE
E58: € | F58: € | R58: €
A112: SB | E112: System total - carried forward to summary page : | F112: =SUM(F59:F111) -> 0 | R112: System total - carried forward to summary page :
A113: ITEM NO. | B113: DESCRIPTION | C113: QTY | D113: UNIT | E113: RATE | F113: TOTAL | R113: RATE
E114: € | F114: € | R114: €
A168: SB | E168: System total - carried forward to summary page : | F168: =SUM(F115:F167) -> 0 | R168: System total - carried forward to summary page :
A169: ITEM NO. | B169: DESCRIPTION | C169: QTY | D169: UNIT | E169: RATE | F169: TOTAL | R169: RATE
E170: € | F170: € | R170: €
A224: SB | E224: System total - carried forward to summary page : | F224: =SUM(F171:F223) -> 0 | R224: System total - carried forward to summary page :
A225: ITEM NO. | B225: DESCRIPTION | C225: QTY | D225: UNIT | E225: RATE | F225: TOTAL | R225: RATE
E226: € | F226: € | R226: €
A280: SB | E280: System total - carried forward to summary page : | F280: =SUM(F227:F279) -> 0 | R280: System total - carried forward to summary page :
A281: ITEM NO. | B281: DESCRIPTION | C281: QTY | D281: UNIT | E281: RATE | F281: TOTAL | R281: RATE
E282: € | F282: € | R282: €
A337: SB | E337: System total - carried forward to summary page : | F337: =SUM(F283:F336) -> 0 | R337: System total - carried forward to summary page :
A338: ITEM NO. | B338: DESCRIPTION | C338: QTY | D338: UNIT | E338: RATE | F338: TOTAL | R338: RATE
E339: € | F339: € | R339: €
A394: SB | E394: System total - carried forward to summary page : | F394: =SUM(F340:F393) -> 0 | R394: System total - carried forward to summary page :
A395: ITEM NO. | B395: DESCRIPTION | C395: QTY | D395: UNIT | E395: RATE | F395: TOTAL | R395: RATE
E396: € | F396: € | R396: €
A451: SB | E451: System total - carried forward to summary page : | F451: =SUM(F397:F450) -> 0 | R451: System total - carried forward to summary page :
A452: ITEM NO. | B452: DESCRIPTION | C452: QTY | D452: UNIT | E452: RATE | F452: TOTAL | R452: RATE
E453: € | F453: € | R453: €
A508: SB | E508: System total - carried forward to summary page : | F508: =SUM(F454:F507) -> 0 | R508: System total - carried forward to summary page :
A509: ITEM NO. | B509: DESCRIPTION | C509: QTY | D509: UNIT | E509: RATE | F509: TOTAL | R509: RATE
E510: € | F510: € | R510: €
A565: SB | E565: System total - carried forward to summary page : | F565: =SUM(F511:F564) -> 0 | R565: System total - carried forward to summary page :

Sheet E_DBOQ
A1: ITEM | B1: DESCRIPTION | C1: QTY | G1: UNIT | H1: RATE | I1: TOTAL | J1: Unit | K1: Total
C2: BOQ | D2: TDWG | E2: ACT | F2: DIFF | H2: € | I2: € | J2: Hrs | K2: Hrs
A54: SB | F54: System total - carried forward to summary page : | H54: VAT EXCL. | I54: =SUM(I3:I53) -> 0 | K54: =SUM(K3:K53) -> 0
A55: ITEM | B55: DESCRIPTION | C55: QTY | G55: UNIT | H55: RATE | I55: TOTAL | J55: Unit | K55: Total
C56: BOQ | D56: TDWG | E56: ACT | F56: DIFF | H56: € | I56: € | J56: Hrs | K56: Hrs
A111: SB | F111: System total - carried forward to summary page : | H111: VAT EXCL. | I111: =SUM(I57:I110) -> 0 | K111: =SUM(K57:K110) -> 0
A112: ITEM | B112: DESCRIPTION | C112: QTY | G112: UNIT | H112: RATE | I112: TOTAL | J112: Unit | K112: Total
C113: BOQ | D113: TDWG | E113: ACT | F113: DIFF | H113: € | I113: € | J113: Hrs | K113: Hrs
A168: SB | F168: System total - carried forward to summary page : | H168: VAT EXCL. | I168: =SUM(I114:I167) -> 0 | K168: =SUM(K114:K167) -> 0
A169: ITEM | B169: DESCRIPTION | C169: QTY | G169: UNIT | H169: RATE | I169: TOTAL | J169: Unit | K169: Total
C170: BOQ | D170: TDWG | E170: ACT | F170: DIFF | H170: € | I170: € | J170: Hrs | K170: Hrs
A225: SB | F225: System total - carried forward to summary page : | H225: VAT EXCL. | I225: =SUM(I171:I224) -> 0 | K225: =SUM(K171:K224) -> 0
A226: ITEM | B226: DESCRIPTION | C226: QTY | G226: UNIT | H226: RATE | I226: TOTAL | J226: Unit | K226: Total
C227: BOQ | D227: TDWG | E227: ACT | F227: DIFF | H227: € | I227: € | J227: Hrs | K227: Hrs
A282: SB | F282: System total - carried forward to summary page : | H282: VAT EXCL. | I282: =SUM(I228:I281) -> 0 | K282: =SUM(K228:K281) -> 0
A283: ITEM | B283: DESCRIPTION | C283: QTY | G283: UNIT | H283: RATE | I283: TOTAL | J283: Unit | K283: Total
C284: BOQ | D284: TDWG | E284: ACT | F284: DIFF | H284: € | I284: € | J284: Hrs | K284: Hrs
A339: SB | F339: System total - carried forward to summary page : | H339: VAT EXCL. | I339: =SUM(I285:I338) -> 0 | K339: =SUM(K285:K338) -> 0
A340: ITEM | B340: DESCRIPTION | C340: QTY | G340: UNIT | H340: RATE | I340: TOTAL | J340: Unit | K340: Total
C341: BOQ | D341: TDWG | E341: ACT | F341: DIFF | H341: € | I341: € | J341: Hrs | K341: Hrs
A396: SB | F396: System total - carried forward to summary page : | H396: VAT EXCL. | I396: =SUM(I342:I395) -> 0 | K396: =SUM(K342:K395) -> 0
A397: ITEM | B397: DESCRIPTION | C397: QTY | G397: UNIT | H397: RATE | I397: TOTAL | J397: Unit | K397: Total
C398: BOQ | D398: TDWG | E398: ACT | F398: DIFF | H398: € | I398: € | J398: Hrs | K398: Hrs
A453: SB | F453: System total - carried forward to summary page : | H453: VAT EXCL. | I453: =SUM(I399:I452) -> 0 | K453: =SUM(K399:K452) -> 0
A454: ITEM | B454: DESCRIPTION | C454: QTY | G454: UNIT | H454: RATE | I454: TOTAL | J454: Unit | K454: Total
C455: BOQ | D455: TDWG | E455: ACT | F455: DIFF | H455: € | I455: € | J455: Hrs | K455: Hrs
A510: SB | F510: System total - carried forward to summary page : | H510: VAT EXCL. | I510: =SUM(I456:I509) -> 0 | K510: =SUM(K456:K509) -> 0
A511: ITEM | B511: DESCRIPTION | C511: QTY | G511: UNIT | H511: RATE | I511: TOTAL | J511: Unit | K511: Total
C512: BOQ | D512: TDWG | E512: ACT | F512: DIFF | H512: € | I512: € | J512: Hrs | K512: Hrs
A567: SB | F567: System total - carried forward to summary page : | H567: VAT EXCL. | I567: =SUM(I513:I566) -> 0 | K567: =SUM(K513:K566) -> 0
