Workbook

Sheet TotalCosts (Hrs)
D2: =MID(CELL("filename"),SEARCH("[",CELL("filename"))+1, SEARCH("]",CELL("filename"))-SEARCH("[",CELL("filename"))-1) -> Crane Currency - VSD for AHU-09 (SJ572 R0.1).xlsx
I3: Min. Hrs | J3: 8 | AL3: Sell Rate: | AM3: 43.32 | AN3: 41.91
C4: Part No. | D4: Description | E4: Material | F4: Drives | G4: LL points | H4: HL nodes | I4: Panel Building | L4: Panel Testing | N4: Panel Design | P4: Programming | S4: Point Testing | V4: Functional Testing | Y4: Others (Technician) | AA4: Others (Engineer) | AB4: Qty | AC4: Unit Price (excl. VAT) | AD4: TOTAL (excl.VAT) (COST) | AE4: TOTAL (Excl. VAT) | AF4: TOTAL (Excl. VAT) (SELLING) | AG4: M.U. | AI4: Tradesman rate PAIR HRS | AJ4: Technician rate PAIR HRS | AK4: Engineer rate MAN HRS | AM4: Labour (Selling) | AN4: Engineer (Selling) | AP4: Qty | AQ4: Unit Price (with Mark-up) | AR4: TOTAL (with Mark-up)
I5: Pair hrs | K5: Rate: | L5: Man hrs | M5: Rate: | N5: Man hrs | O5: Rate: | P5: Man hrs | R5: Rate: | S5: Pair hrs | U5: Rate: | V5: Man hrs | X5: Rate: | Y5: Pair hrs | Z5: Rate: | AA5: Man hrs | AG5: 1.35
F6: 15 | G6: 0.5 | H6: 5 | J6: ON/OFF | K6: 0 | M6: 0 | O6: 0 | Q6: ON/OFF | R6: 0 | T6: ON/OFF | U6: 0 | W6: ON/OFF | X6: 0 | Z6: 0
F7: 0.25 | G7: 0.25 | H7: 1
G8: 1
B9: ='MaterialCosts Summary'!B9 -> - | D9: ='MaterialCosts Summary'!D9 -> 15kW VSD, IP55 | E9: ='MaterialCosts Summary'!E9 -> 882.4509 | F9: 0 | G9: 0 | H9: 0 | I9: =(MAX((F9*$F$6)+(G9*$G$6),$J$3)*J9) -> 0 | K9: =IF(AND(I9*$K$6<150, I9<>0), (I9*$K$6)+0, I9*$K$6) -> 0 | L9: 0 | M9: =L9*$M$6 -> 0 | N9: 0 | O9: =N9*$O$6 -> 0 | P9: =(IF(H9<>0,MAX((G9*$G$8)+(H9*0.1*$H$6)+(H9*0.9*$H$7),24),(G9*$G$8)+(H9*0.1*$H$6)+(H9*0.9*$H$7)))*Q9 -> 0 | R9: =P9*$R$6 -> 0 | S9: =G9*$G$6*T9 -> 0 | U9: =S9*$U$6 -> 0 | V9: =(((G9+H9)*$G$7)+(F9*$F$7))*W9 -> 0 | X9: =V9*$X$6 -> 0 | Y9: 0 | Z9: =Y9*$X$6 -> 0 | AA9: 0 | AB9: 1 | AC9: =AD9/AB9 -> 882.4509 | AD9: =E9+K9+M9+O9+R9+U9+X9+Z9 -> 882.4509 | AE9: =AC9*$AG$5 -> 1191.3087 | AF9: =AD9*$AG$5 -> 1191.3087 | AI9: =CEILING(0/2, 4) -> 0 | AJ9: 4 | AK9: =CEILING((L9+N9+P9+V9+AA9), 4) -> 0 | AM9: =AJ9*$AM$3 -> 173.28 | AN9: =AK9*$AN$3 -> 0 | AP9: =AB9 -> 1 | AQ9: =AR9/AP9 -> 1364.5887 | AR9: =AF9+AM9+AN9 -> 1364.5887
B10: ='MaterialCosts Summary'!B10 -> 2 | D10: ='MaterialCosts Summary'!D10 -> -- | E10: ='MaterialCosts Summary'!E10 -> 0 | F10: 0 | G10: 0 | H10: 0 | I10: =(MAX((F10*$F$6)+(G10*$G$6),$J$3)*J10) -> 0 | K10: =IF(AND(I10*$K$6<150, I10<>0), (I10*$K$6)+0, I10*$K$6) -> 0 | L10: 0 | M10: =L10*$M$6 -> 0 | N10: 0 | O10: =N10*$O$6 -> 0 | P10: =(IF(H10<>0,MAX((G10*$G$8)+(H10*0.1*$H$6)+(H10*0.9*$H$7),24),(G10*$G$8)+(H10*0.1*$H$6)+(H10*0.9*$H$7)))*Q10 -> 0 | R10: =P10*$R$6 -> 0 | S10: =G10*$G$6*T10 -> 0 | U10: =S10*$U$6 -> 0 | V10: =(((G10+H10)*$G$7)+(F10*$F$7))*W10 -> 0 | X10: =V10*$X$6 -> 0 | Y10: 0 | Z10: =Y10*$X$6 -> 0 | AA10: 0 | AB10: 1 | AC10: =AD10/AB10 -> 0 | AD10: =E10+K10+M10+O10+R10+U10+X10+Z10 -> 0 | AE10: =AC10*$AG$5 -> 0 | AF10: =AD10*$AG$5 -> 0 | AI10: =CEILING(0/2, 4) -> 0 | AJ10: =CEILING((I10+S10+Y10), 1) -> 0 | AK10: =CEILING((L10+N10+P10+V10+AA10), 4) -> 0 | AM10: =AJ10*$AM$3 -> 0 | AN10: =AK10*$AN$3 -> 0 | AP10: =AB10 -> 1 | AQ10: =AR10/AP10 -> 0 | AR10: =AF10+AM10+AN10 -> 0
B11: ='MaterialCosts Summary'!B11 -> 3 | D11: ='MaterialCosts Summary'!D11 -> 0 | E11: ='MaterialCosts Summary'!E11 -> 0 | F11: 0 | G11: 0 | H11: 0 | I11: =(MAX((F11*$F$6)+(G11*$G$6),$J$3)*J11) -> 0 | K11: =IF(AND(I11*$K$6<150, I11<>0), (I11*$K$6)+0, I11*$K$6) -> 0 | L11: 0 | M11: =L11*$M$6 -> 0 | N11: 0 | O11: =N11*$O$6 -> 0 | P11: =(IF(H11<>0,MAX((G11*$G$8)+(H11*0.1*$H$6)+(H11*0.9*$H$7),24),(G11*$G$8)+(H11*0.1*$H$6)+(H11*0.9*$H$7)))*Q11 -> 0 | R11: =P11*$R$6 -> 0 | S11: =G11*$G$6*T11 -> 0 | U11: =S11*$U$6 -> 0 | V11: =(((G11+H11)*$G$7)+(F11*$F$7))*W11 -> 0 | X11: =V11*$X$6 -> 0 | Y11: 0 | Z11: =Y11*$X$6 -> 0 | AA11: 0 | AB11: 1 | AC11: =AD11/AB11 -> 0 | AD11: =E11+K11+M11+O11+R11+U11+X11+Z11 -> 0 | AE11: =AC11*$AG$5 -> 0 | AF11: =AD11*$AG$5 -> 0 | AI11: =CEILING(0/2, 4) -> 0 | AJ11: =CEILING((I11+S11+Y11), 1) -> 0 | AK11: =CEILING((L11+N11+P11+V11+AA11), 4) -> 0 | AM11: =AJ11*$AM$3 -> 0 | AN11: =AK11*$AN$3 -> 0 | AP11: =AB11 -> 1 | AQ11: =AR11/AP11 -> 0 | AR11: =AF11+AM11+AN11 -> 0
B12: ='MaterialCosts Summary'!B12 -> 4 | D12: ='MaterialCosts Summary'!D12 -> 0 | E12: ='MaterialCosts Summary'!E12 -> 0 | F12: 0 | G12: 0 | H12: 0 | I12: =(MAX((F12*$F$6)+(G12*$G$6),$J$3)*J12) -> 0 | K12: =IF(AND(I12*$K$6<150, I12<>0), (I12*$K$6)+0, I12*$K$6) -> 0 | L12: 0 | M12: =L12*$M$6 -> 0 | N12: 0 | O12: =N12*$O$6 -> 0 | P12: =(IF(H12<>0,MAX((G12*$G$8)+(H12*0.1*$H$6)+(H12*0.9*$H$7),24),(G12*$G$8)+(H12*0.1*$H$6)+(H12*0.9*$H$7)))*Q12 -> 0 | R12: =P12*$R$6 -> 0 | S12: =G12*$G$6*T12 -> 0 | U12: =S12*$U$6 -> 0 | V12: =(((G12+H12)*$G$7)+(F12*$F$7))*W12 -> 0 | X12: =V12*$X$6 -> 0 | Y12: 0 | Z12: =Y12*$X$6 -> 0 | AA12: 0 | AB12: 1 | AC12: =AD12/AB12 -> 0 | AD12: =E12+K12+M12+O12+R12+U12+X12+Z12 -> 0 | AE12: =AC12*$AG$5 -> 0 | AF12: =AD12*$AG$5 -> 0 | AI12: =CEILING(0/2, 4) -> 0 | AJ12: =CEILING((I12+S12+Y12), 1) -> 0 | AK12: =CEILING((L12+N12+P12+V12+AA12), 4) -> 0 | AM12: =AJ12*$AM$3 -> 0 | AN12: =AK12*$AN$3 -> 0 | AP12: =AB12 -> 1 | AQ12: =AR12/AP12 -> 0 | AR12: =AF12+AM12+AN12 -> 0
B13: ='MaterialCosts Summary'!B13 -> 5 | D13: ='MaterialCosts Summary'!D13 -> 0 | E13: ='MaterialCosts Summary'!E13 -> 0 | F13: 0 | G13: 0 | H13: 0 | I13: =(MAX((F13*$F$6)+(G13*$G$6),$J$3)*J13) -> 0 | K13: =IF(AND(I13*$K$6<150, I13<>0), (I13*$K$6)+0, I13*$K$6) -> 0 | L13: 0 | M13: =L13*$M$6 -> 0 | N13: 0 | O13: =N13*$O$6 -> 0 | P13: =(IF(H13<>0,MAX((G13*$G$8)+(H13*0.1*$H$6)+(H13*0.9*$H$7),24),(G13*$G$8)+(H13*0.1*$H$6)+(H13*0.9*$H$7)))*Q13 -> 0 | R13: =P13*$R$6 -> 0 | S13: =G13*$G$6*T13 -> 0 | U13: =S13*$U$6 -> 0 | V13: =(((G13+H13)*$G$7)+(F13*$F$7))*W13 -> 0 | X13: =V13*$X$6 -> 0 | Y13: 0 | Z13: =Y13*$X$6 -> 0 | AA13: 0 | AB13: 1 | AC13: =AD13/AB13 -> 0 | AD13: =E13+K13+M13+O13+R13+U13+X13+Z13 -> 0 | AE13: =AC13*$AG$5 -> 0 | AF13: =AD13*$AG$5 -> 0 | AI13: =CEILING(0/2, 4) -> 0 | AJ13: =CEILING((I13+S13+Y13), 1) -> 0 | AK13: =CEILING((L13+N13+P13+V13+AA13), 4) -> 0 | AM13: =AJ13*$AM$3 -> 0 | AN13: =AK13*$AN$3 -> 0 | AP13: =AB13 -> 1 | AQ13: =AR13/AP13 -> 0 | AR13: =AF13+AM13+AN13 -> 0
B14: ='MaterialCosts Summary'!B14 -> 6 | D14: ='MaterialCosts Summary'!D14 -> 0 | E14: ='MaterialCosts Summary'!E14 -> 0 | F14: 0 | G14: 0 | H14: 0 | I14: =(MAX((F14*$F$6)+(G14*$G$6),$J$3)*J14) -> 0 | K14: =IF(AND(I14*$K$6<150, I14<>0), (I14*$K$6)+0, I14*$K$6) -> 0 | L14: 0 | M14: =L14*$M$6 -> 0 | N14: 0 | O14: =N14*$O$6 -> 0 | P14: =(IF(H14<>0,MAX((G14*$G$8)+(H14*0.1*$H$6)+(H14*0.9*$H$7),24),(G14*$G$8)+(H14*0.1*$H$6)+(H14*0.9*$H$7)))*Q14 -> 0 | R14: =P14*$R$6 -> 0 | S14: =G14*$G$6*T14 -> 0 | U14: =S14*$U$6 -> 0 | V14: =(((G14+H14)*$G$7)+(F14*$F$7))*W14 -> 0 | X14: =V14*$X$6 -> 0 | Y14: 0 | Z14: =Y14*$X$6 -> 0 | AA14: 0 | AB14: 1 | AC14: =AD14/AB14 -> 0 | AD14: =E14+K14+M14+O14+R14+U14+X14+Z14 -> 0 | AE14: =AC14*$AG$5 -> 0 | AF14: =AD14*$AG$5 -> 0 | AI14: =CEILING(0/2, 4) -> 0 | AJ14: =CEILING((I14+S14+Y14), 1) -> 0 | AK14: =CEILING((L14+N14+P14+V14+AA14), 4) -> 0 | AM14: =AJ14*$AM$3 -> 0 | AN14: =AK14*$AN$3 -> 0 | AP14: =AB14 -> 1 | AQ14: =AR14/AP14 -> 0 | AR14: =AF14+AM14+AN14 -> 0
B15: ='MaterialCosts Summary'!B15 -> 7 | D15: ='MaterialCosts Summary'!D15 -> 0 | E15: ='MaterialCosts Summary'!E15 -> 0 | F15: 0 | G15: 0 | H15: 0 | I15: =(MAX((F15*$F$6)+(G15*$G$6),$J$3)*J15) -> 0 | K15: =IF(AND(I15*$K$6<150, I15<>0), (I15*$K$6)+0, I15*$K$6) -> 0 | L15: 0 | M15: =L15*$M$6 -> 0 | N15: 0 | O15: =N15*$O$6 -> 0 | P15: =(IF(H15<>0,MAX((G15*$G$8)+(H15*0.1*$H$6)+(H15*0.9*$H$7),24),(G15*$G$8)+(H15*0.1*$H$6)+(H15*0.9*$H$7)))*Q15 -> 0 | R15: =P15*$R$6 -> 0 | S15: =G15*$G$6*T15 -> 0 | U15: =S15*$U$6 -> 0 | V15: =(((G15+H15)*$G$7)+(F15*$F$7))*W15 -> 0 | X15: =V15*$X$6 -> 0 | Y15: 0 | Z15: =Y15*$X$6 -> 0 | AA15: 0 | AB15: 1 | AC15: =AD15/AB15 -> 0 | AD15: =E15+K15+M15+O15+R15+U15+X15+Z15 -> 0 | AE15: =AC15*$AG$5 -> 0 | AF15: =AD15*$AG$5 -> 0 | AI15: =CEILING(0/2, 4) -> 0 | AJ15: =CEILING((I15+S15+Y15), 1) -> 0 | AK15: =CEILING((L15+N15+P15+V15+AA15), 4) -> 0 | AM15: =AJ15*$AM$3 -> 0 | AN15: =AK15*$AN$3 -> 0 | AP15: =AB15 -> 1 | AQ15: =AR15/AP15 -> 0 | AR15: =AF15+AM15+AN15 -> 0
B16: ='MaterialCosts Summary'!B16 -> 8 | D16: ='MaterialCosts Summary'!D16 -> 0 | E16: ='MaterialCosts Summary'!E16 -> 0 | F16: 0 | G16: 0 | H16: 0 | I16: =(MAX((F16*$F$6)+(G16*$G$6),$J$3)*J16) -> 0 | K16: =IF(AND(I16*$K$6<150, I16<>0), (I16*$K$6)+0, I16*$K$6) -> 0 | L16: 0 | M16: =L16*$M$6 -> 0 | N16: 0 | O16: =N16*$O$6 -> 0 | P16: =(IF(H16<>0,MAX((G16*$G$8)+(H16*0.1*$H$6)+(H16*0.9*$H$7),24),(G16*$G$8)+(H16*0.1*$H$6)+(H16*0.9*$H$7)))*Q16 -> 0 | R16: =P16*$R$6 -> 0 | S16: =G16*$G$6*T16 -> 0 | U16: =S16*$U$6 -> 0 | V16: =(((G16+H16)*$G$7)+(F16*$F$7))*W16 -> 0 | X16: =V16*$X$6 -> 0 | Y16: 0 | Z16: =Y16*$X$6 -> 0 | AA16: 0 | AB16: 1 | AC16: =AD16/AB16 -> 0 | AD16: =E16+K16+M16+O16+R16+U16+X16+Z16 -> 0 | AE16: =AC16*$AG$5 -> 0 | AF16: =AD16*$AG$5 -> 0 | AI16: =CEILING(0/2, 4) -> 0 | AJ16: =CEILING((I16+S16+Y16), 1) -> 0 | AK16: =CEILING((L16+N16+P16+V16+AA16), 4) -> 0 | AM16: =AJ16*$AM$3 -> 0 | AN16: =AK16*$AN$3 -> 0 | AP16: =AB16 -> 1 | AQ16: =AR16/AP16 -> 0 | AR16: =AF16+AM16+AN16 -> 0
B17: ='MaterialCosts Summary'!B17 -> 9 | D17: ='MaterialCosts Summary'!D17 -> 0 | E17: ='MaterialCosts Summary'!E17 -> 0 | F17: 0 | G17: 0 | H17: 0 | I17: =(MAX((F17*$F$6)+(G17*$G$6),$J$3)*J17) -> 0 | K17: =IF(AND(I17*$K$6<150, I17<>0), (I17*$K$6)+0, I17*$K$6) -> 0 | L17: 0 | M17: =L17*$M$6 -> 0 | N17: 0 | O17: =N17*$O$6 -> 0 | P17: =(IF(H17<>0,MAX((G17*$G$8)+(H17*0.1*$H$6)+(H17*0.9*$H$7),24),(G17*$G$8)+(H17*0.1*$H$6)+(H17*0.9*$H$7)))*Q17 -> 0 | R17: =P17*$R$6 -> 0 | S17: =G17*$G$6*T17 -> 0 | U17: =S17*$U$6 -> 0 | V17: =(((G17+H17)*$G$7)+(F17*$F$7))*W17 -> 0 | X17: =V17*$X$6 -> 0 | Y17: 0 | Z17: =Y17*$X$6 -> 0 | AA17: 0 | AB17: 1 | AC17: =AD17/AB17 -> 0 | AD17: =E17+K17+M17+O17+R17+U17+X17+Z17 -> 0 | AE17: =AC17*$AG$5 -> 0 | AF17: =AD17*$AG$5 -> 0 | AI17: =CEILING(0/2, 4) -> 0 | AJ17: =CEILING((I17+S17+Y17), 1) -> 0 | AK17: =CEILING((L17+N17+P17+V17+AA17), 4) -> 0 | AM17: =AJ17*$AM$3 -> 0 | AN17: =AK17*$AN$3 -> 0 | AP17: =AB17 -> 1 | AQ17: =AR17/AP17 -> 0 | AR17: =AF17+AM17+AN17 -> 0
B18: ='MaterialCosts Summary'!B18 -> 10 | D18: ='MaterialCosts Summary'!D18 -> 0 | E18: ='MaterialCosts Summary'!E18 -> 0 | F18: 0 | G18: 0 | H18: 0 | I18: =(MAX((F18*$F$6)+(G18*$G$6),$J$3)*J18) -> 0 | K18: =IF(AND(I18*$K$6<150, I18<>0), (I18*$K$6)+0, I18*$K$6) -> 0 | L18: 0 | M18: =L18*$M$6 -> 0 | N18: 0 | O18: =N18*$O$6 -> 0 | P18: =(IF(H18<>0,MAX((G18*$G$8)+(H18*0.1*$H$6)+(H18*0.9*$H$7),24),(G18*$G$8)+(H18*0.1*$H$6)+(H18*0.9*$H$7)))*Q18 -> 0 | R18: =P18*$R$6 -> 0 | S18: =G18*$G$6*T18 -> 0 | U18: =S18*$U$6 -> 0 | V18: =(((G18+H18)*$G$7)+(F18*$F$7))*W18 -> 0 | X18: =V18*$X$6 -> 0 | Y18: 0 | Z18: =Y18*$X$6 -> 0 | AA18: 0 | AB18: 1 | AC18: =AD18/AB18 -> 0 | AD18: =E18+K18+M18+O18+R18+U18+X18+Z18 -> 0 | AE18: =AC18*$AG$5 -> 0 | AF18: =AD18*$AG$5 -> 0 | AI18: =CEILING(0/2, 4) -> 0 | AJ18: =CEILING((I18+S18+Y18), 1) -> 0 | AK18: =CEILING((L18+N18+P18+V18+AA18), 4) -> 0 | AM18: =AJ18*$AM$3 -> 0 | AN18: =AK18*$AN$3 -> 0 | AP18: =AB18 -> 1 | AQ18: =AR18/AP18 -> 0 | AR18: =AF18+AM18+AN18 -> 0
B19: ='MaterialCosts Summary'!B19 -> 11 | D19: ='MaterialCosts Summary'!D19 -> 0 | E19: ='MaterialCosts Summary'!E19 -> 0 | F19: 0 | G19: 0 | H19: 0 | I19: =(MAX((F19*$F$6)+(G19*$G$6),$J$3)*J19) -> 0 | K19: =IF(AND(I19*$K$6<150, I19<>0), (I19*$K$6)+0, I19*$K$6) -> 0 | L19: 0 | M19: =L19*$M$6 -> 0 | N19: 0 | O19: =N19*$O$6 -> 0 | P19: =(IF(H19<>0,MAX((G19*$G$8)+(H19*0.1*$H$6)+(H19*0.9*$H$7),24),(G19*$G$8)+(H19*0.1*$H$6)+(H19*0.9*$H$7)))*Q19 -> 0 | R19: =P19*$R$6 -> 0 | S19: =G19*$G$6*T19 -> 0 | U19: =S19*$U$6 -> 0 | V19: =(((G19+H19)*$G$7)+(F19*$F$7))*W19 -> 0 | X19: =V19*$X$6 -> 0 | Y19: 0 | Z19: =Y19*$X$6 -> 0 | AA19: 0 | AB19: 1 | AC19: =AD19/AB19 -> 0 | AD19: =E19+K19+M19+O19+R19+U19+X19+Z19 -> 0 | AE19: =AC19*$AG$5 -> 0 | AF19: =AD19*$AG$5 -> 0 | AI19: =CEILING(0/2, 4) -> 0 | AJ19: =CEILING((I19+S19+Y19), 1) -> 0 | AK19: =CEILING((L19+N19+P19+V19+AA19), 4) -> 0 | AM19: =AJ19*$AM$3 -> 0 | AN19: =AK19*$AN$3 -> 0 | AP19: =AB19 -> 1 | AQ19: =AR19/AP19 -> 0 | AR19: =AF19+AM19+AN19 -> 0
B20: ='MaterialCosts Summary'!B20 -> 12 | D20: ='MaterialCosts Summary'!D20 -> 0 | E20: ='MaterialCosts Summary'!E20 -> 0 | F20: 0 | G20: 0 | H20: 0 | I20: =(MAX((F20*$F$6)+(G20*$G$6),$J$3)*J20) -> 0 | K20: =IF(AND(I20*$K$6<150, I20<>0), (I20*$K$6)+0, I20*$K$6) -> 0 | L20: 0 | M20: =L20*$M$6 -> 0 | N20: 0 | O20: =N20*$O$6 -> 0 | P20: =(IF(H20<>0,MAX((G20*$G$8)+(H20*0.1*$H$6)+(H20*0.9*$H$7),24),(G20*$G$8)+(H20*0.1*$H$6)+(H20*0.9*$H$7)))*Q20 -> 0 | R20: =P20*$R$6 -> 0 | S20: =G20*$G$6*T20 -> 0 | U20: =S20*$U$6 -> 0 | V20: =(((G20+H20)*$G$7)+(F20*$F$7))*W20 -> 0 | X20: =V20*$X$6 -> 0 | Y20: 0 | Z20: =Y20*$X$6 -> 0 | AA20: 0 | AB20: 1 | AC20: =AD20/AB20 -> 0 | AD20: =E20+K20+M20+O20+R20+U20+X20+Z20 -> 0 | AE20: =AC20*$AG$5 -> 0 | AF20: =AD20*$AG$5 -> 0 | AI20: =CEILING(0/2, 4) -> 0 | AJ20: =CEILING((I20+S20+Y20), 1) -> 0 | AK20: =CEILING((L20+N20+P20+V20+AA20), 4) -> 0 | AM20: =AJ20*$AM$3 -> 0 | AN20: =AK20*$AN$3 -> 0 | AP20: =AB20 -> 1 | AQ20: =AR20/AP20 -> 0 | AR20: =AF20+AM20+AN20 -> 0
B21: ='MaterialCosts Summary'!B21 -> 13 | D21: ='MaterialCosts Summary'!D21 -> 0 | E21: ='MaterialCosts Summary'!E21 -> 0 | F21: 0 | G21: 0 | H21: 0 | I21: =(MAX((F21*$F$6)+(G21*$G$6),$J$3)*J21) -> 0 | K21: =IF(AND(I21*$K$6<150, I21<>0), (I21*$K$6)+0, I21*$K$6) -> 0 | L21: 0 | M21: =L21*$M$6 -> 0 | N21: 0 | O21: =N21*$O$6 -> 0 | P21: =(IF(H21<>0,MAX((G21*$G$8)+(H21*0.1*$H$6)+(H21*0.9*$H$7),24),(G21*$G$8)+(H21*0.1*$H$6)+(H21*0.9*$H$7)))*Q21 -> 0 | R21: =P21*$R$6 -> 0 | S21: =G21*$G$6*T21 -> 0 | U21: =S21*$U$6 -> 0 | V21: =(((G21+H21)*$G$7)+(F21*$F$7))*W21 -> 0 | X21: =V21*$X$6 -> 0 | Y21: 0 | Z21: =Y21*$X$6 -> 0 | AA21: 0 | AB21: 1 | AC21: =AD21/AB21 -> 0 | AD21: =E21+K21+M21+O21+R21+U21+X21+Z21 -> 0 | AE21: =AC21*$AG$5 -> 0 | AF21: =AD21*$AG$5 -> 0 | AI21: =CEILING(0/2, 4) -> 0 | AJ21: =CEILING((I21+S21+Y21), 1) -> 0 | AK21: =CEILING((L21+N21+P21+V21+AA21), 4) -> 0 | AM21: =AJ21*$AM$3 -> 0 | AN21: =AK21*$AN$3 -> 0 | AP21: =AB21 -> 1 | AQ21: =AR21/AP21 -> 0 | AR21: =AF21+AM21+AN21 -> 0
... B141: ='MaterialCosts Summary'!B141 -> 133 | D141: ='MaterialCosts Summary'!D141 -> 0 | E141: ='MaterialCosts Summary'!E141 -> 0 | F141: 0 | G141: 0 | H141: 0 | I141: =(MAX((F141*$F$6)+(G141*$G$6),$J$3)*J141) -> 0 | K141: =IF(AND(I141*$K$6<150, I141<>0), (I141*$K$6)+0, I141*$K$6) -> 0 | L141: 0 | M141: =L141*$M$6 -> 0 | N141: 0 | O141: =N141*$O$6 -> 0 | P141: =(IF(H141<>0,MAX((G141*$G$8)+(H141*0.1*$H$6)+(H141*0.9*$H$7),24),(G141*$G$8)+(H141*0.1*$H$6)+(H141*0.9*$H$7)))*Q141 -> 0 | R141: =P141*$R$6 -> 0 | S141: =G141*$G$6*T141 -> 0 | U141: =S141*$U$6 -> 0 | V141: =(((G141+H141)*$G$7)+(F141*$F$7))*W141 -> 0 | X141: =V141*$X$6 -> 0 | Y141: 0 | Z141: =Y141*$X$6 -> 0 | AA141: 0 | AB141: 1 | AC141: =AD141/AB141 -> 0 | AD141: =E141+K141+M141+O141+R141+U141+X141+Z141 -> 0 | AE141: =AC141*$AG$5 -> 0 | AF141: =AD141*$AG$5 -> 0 | AI141: =CEILING(0/2, 4) -> 0 | AJ141: =CEILING((I141+S141+Y141), 1) -> 0 | AK141: =CEILING((L141+N141+P141+V141+AA141), 4) -> 0 | AM141: =AJ141*$AM$3 -> 0 | AN141: =AK141*$AN$3 -> 0 | AP141: =AB141 -> 1 | AQ141: =AR141/AP141 -> 0 | AR141: =AF141+AM141+AN141 -> 0
D142: ='MaterialCosts Summary'!D142 -> ---
D144: TOTAL (Excl. VAT) | E144: =SUBTOTAL(9, E9:E142) -> 882.4509 | I144: =SUBTOTAL(9, I9:I142) -> 0 | K144: =SUBTOTAL(9, K9:K142) -> 0 | L144: =SUBTOTAL(9, L9:L142) -> 0 | M144: =SUBTOTAL(9, M9:M142) -> 0 | N144: =SUBTOTAL(9, N9:N142) -> 0 | O144: =SUBTOTAL(9, O9:O142) -> 0 | P144: =SUBTOTAL(9, P9:P142) -> 0 | R144: =SUBTOTAL(9, R9:R142) -> 0 | S144: =SUBTOTAL(9, S9:S142) -> 0 | U144: =SUBTOTAL(9, U9:U142) -> 0 | V144: =SUBTOTAL(9, V9:V142) -> 0 | X144: =SUBTOTAL(9, X9:X142) -> 0 | Y144: =SUBTOTAL(9, Y9:Y142) -> 0 | Z144: =SUBTOTAL(9, Z9:Z142) -> 0 | AA144: =SUBTOTAL(9, AA9:AA142) -> 0 | AD144: =SUBTOTAL(9, AD9:AD142) -> 882.4509 | AF144: =SUBTOTAL(9, AF9:AF142) -> 1191.3087 | AI144: =SUM(AI9:AI142) -> 0 | AJ144: =SUM(AJ9:AJ142) -> 4 | AK144: =SUM(AK9:AK142) -> 0 | AM144: =SUM(AM9:AM142) -> 173.28 | AN144: =SUM(AN9:AN142) -> 0 | AR144: =SUM(AR9:AR142) -> 1364.5887
AM146: =AM144/AJ144 -> 43.32
D148: TOTAL MATERIAL COST | E148: =E144 -> 882.4509
D149: Tradesman rate PAIR HRS | E149: =ROUNDUP((I144+V144)/2, 0) -> 0
D150: Technician rate PAIR HRS | E150: =ROUNDUP((#REF!+S144)/2, 0) -> #REF!
D151: Engineer rate PAIR HRS | E151: =ROUNDUP((L144+N144+P144)/2, 0) -> 0
B153: Notes:
B155: 1. | D155: Cost includes:
B156: a. | D156: Delivery and setting-up of VSD
B157: b.
B158: c.
B160: 2. | D160: Cost excludes:
B161: a.
B162: b.
B163: c.
B164: d.
B165: e.

Sheet MaterialCosts Summary
D2: =MID(CELL("filename"),SEARCH("[",CELL("filename"))+1, SEARCH("]",CELL("filename"))-SEARCH("[",CELL("filename"))-1) -> Crane Currency - VSD for AHU-09 (SJ572 R0.1).xlsx | E2: =E144 -> 882.4509
D3: Rev. 0
C4: Part No. | D4: Description | E4: Material | G4: Mark-up | H4: TOTAL
B9: - | D9: {=TRANSPOSE('Bill of Materials'!G3:H3)} -> 15kW VSD, IP55 | E9: {=TRANSPOSE('Bill of Materials'!S144:T144)} -> 882.4509 | H9: =#REF!*G9 -> #REF!
B10: 2 | D10: -- | E10: 0
B11: 3
B12: 4
B13: 5
B14: 6
B15: 7
B16: 8
B17: 9
B18: 10
B19: 11
B20: 12
B21: 13
B22: 14
... B141: 133
D142: --- | H142: =#REF!*G142 -> #REF!
D144: TOTAL | E144: =SUM(E9:E142) -> 882.4509 | G144: TOTAL | H144: =SUM(H9:H142) -> #REF!
D148: TOTAL MATERIAL COST | E148: =E144 -> 882.4509
D149: Tradesman rate PAIR HRS | E149: =ROUNDUP((#REF!+#REF!)/2, 0) -> #REF!
D150: Technician rate PAIR HRS | E150: =ROUNDUP((#REF!+#REF!)/2, 0) -> #REF!
D151: Engineer rate PAIR HRS | E151: =ROUNDUP((#REF!+#REF!+#REF!)/2, 0) -> #REF!

Sheet Bill of Materials
D1: =O144 -> 882.4509 | G1: =COUNTA(G3:H3)+COUNTBLANK(G3:H3) -> 2 | O1: =O144 -> 882.4509 | S1: =COUNTA(S3:T3)+COUNTBLANK(S3:T3) -> 2
D2: =O145 -> 882.4509 | O2: =O145 -> 882.4509
A3: Item No. | B3: Supplier | C3: Item | D3: Part Number | E3: Description | F3: Unit Price (ex-VAT) | G3: 15kW VSD, IP55 | H3: -- | I3: Quantity | J3: Factor | K3: FINAL QTY | L3: Unit Price (ex-VAT) | M3: Added material % | N3: Contingency / Shipping | O3: Total price (EUR) | P3: Comments | S3: =G3 -> 15kW VSD, IP55 | T3: =H3 -> --
A4: 1 | B4: FUJI | C4: VSD | D4: FRN15AR1L-4E | E4: HVAC (AR1), 3ph 400V, incl. EMC-Filter, DC-reactor and operator panel, IP55, 15kW | F4: 780.93 | G4: 1 | I4: =SUM(G4:H4) -> 1 | J4: 1 | K4: =ROUNDUP(I4*J4, 0) -> 1 | L4: =F4 -> 780.93 | M4: 0 | N4: 0.13 | O4: =((L4*(1+M4))*(1+N4))*K4 -> 882.4509 | S4: =(($L4*(1+$M4))*(1+$N4))*G4 -> 882.4509 | T4: =(($L4*(1+$M4))*(1+$N4))*H4 -> 0 | V4: =SUM(S4:T4) -> 882.4509 | W4: =EXACT(V4,O4) -> TRUE | X4: =V4-O4 -> 0
A5: 2 | I5: =SUM(G5:H5) -> 0 | J5: 1 | K5: =ROUNDUP(I5*J5, 0) -> 0 | L5: =F5 -> 0 | M5: 0 | N5: 0.05 | O5: =((L5*(1+M5))*(1+N5))*K5 -> 0 | S5: =(($L5*(1+$M5))*(1+$N5))*G5 -> 0 | T5: =(($L5*(1+$M5))*(1+$N5))*H5 -> 0 | V5: =SUM(S5:T5) -> 0 | W5: =EXACT(V5,O5) -> TRUE | X5: =V5-O5 -> 0
A6: 3 | I6: =SUM(G6:H6) -> 0 | J6: 1 | K6: =ROUNDUP(I6*J6, 0) -> 0 | L6: =F6 -> 0 | M6: 0 | N6: 0.05 | O6: =((L6*(1+M6))*(1+N6))*K6 -> 0 | S6: =(($L6*(1+$M6))*(1+$N6))*G6 -> 0 | T6: =(($L6*(1+$M6))*(1+$N6))*H6 -> 0 | V6: =SUM(S6:T6) -> 0 | W6: =EXACT(V6,O6) -> TRUE | X6: =V6-O6 -> 0
A7: 4 | I7: =SUM(G7:H7) -> 0 | J7: 1 | K7: =ROUNDUP(I7*J7, 0) -> 0 | L7: =F7 -> 0 | M7: 0 | N7: 0.05 | O7: =((L7*(1+M7))*(1+N7))*K7 -> 0 | S7: =(($L7*(1+$M7))*(1+$N7))*G7 -> 0 | T7: =(($L7*(1+$M7))*(1+$N7))*H7 -> 0 | V7: =SUM(S7:T7) -> 0 | W7: =EXACT(V7,O7) -> TRUE | X7: =V7-O7 -> 0
A8: 5 | I8: =SUM(G8:H8) -> 0 | J8: 1 | K8: =ROUNDUP(I8*J8, 0) -> 0 | L8: =F8 -> 0 | M8: 0 | N8: 0.05 | O8: =((L8*(1+M8))*(1+N8))*K8 -> 0 | S8: =(($L8*(1+$M8))*(1+$N8))*G8 -> 0 | T8: =(($L8*(1+$M8))*(1+$N8))*H8 -> 0 | V8: =SUM(S8:T8) -> 0 | W8: =EXACT(V8,O8) -> TRUE | X8: =V8-O8 -> 0
A9: 6 | I9: =SUM(G9:H9) -> 0 | J9: 1 | K9: =ROUNDUP(I9*J9, 0) -> 0 | L9: =F9 -> 0 | M9: 0 | N9: 0.05 | O9: =((L9*(1+M9))*(1+N9))*K9 -> 0 | S9: =(($L9*(1+$M9))*(1+$N9))*G9 -> 0 | T9: =(($L9*(1+$M9))*(1+$N9))*H9 -> 0 | V9: =SUM(S9:T9) -> 0 | W9: =EXACT(V9,O9) -> TRUE | X9: =V9-O9 -> 0
A10: 7 | I10: =SUM(G10:H10) -> 0 | J10: 1 | K10: =ROUNDUP(I10*J10, 0) -> 0 | L10: =F10 -> 0 | M10: 0 | N10: 0.05 | O10: =((L10*(1+M10))*(1+N10))*K10 -> 0 | S10: =(($L10*(1+$M10))*(1+$N10))*G10 -> 0 | T10: =(($L10*(1+$M10))*(1+$N10))*H10 -> 0 | V10: =SUM(S10:T10) -> 0 | W10: =EXACT(V10,O10) -> TRUE | X10: =V10-O10 -> 0
A11: 8 | I11: =SUM(G11:H11) -> 0 | J11: 1 | K11: =ROUNDUP(I11*J11, 0) -> 0 | L11: =F11 -> 0 | M11: 0 | N11: 0.05 | O11: =((L11*(1+M11))*(1+N11))*K11 -> 0 | S11: =(($L11*(1+$M11))*(1+$N11))*G11 -> 0 | T11: =(($L11*(1+$M11))*(1+$N11))*H11 -> 0 | V11: =SUM(S11:T11) -> 0 | W11: =EXACT(V11,O11) -> TRUE | X11: =V11-O11 -> 0
A12: 9 | I12: =SUM(G12:H12) -> 0 | J12: 1 | K12: =ROUNDUP(I12*J12, 0) -> 0 | L12: =F12 -> 0 | M12: 0 | N12: 0.05 | O12: =((L12*(1+M12))*(1+N12))*K12 -> 0 | S12: =(($L12*(1+$M12))*(1+$N12))*G12 -> 0 | T12: =(($L12*(1+$M12))*(1+$N12))*H12 -> 0 | V12: =SUM(S12:T12) -> 0 | W12: =EXACT(V12,O12) -> TRUE | X12: =V12-O12 -> 0
A13: 10 | I13: =SUM(G13:H13) -> 0 | J13: 1 | K13: =ROUNDUP(I13*J13, 0) -> 0 | L13: =F13 -> 0 | M13: 0 | N13: 0.05 | O13: =((L13*(1+M13))*(1+N13))*K13 -> 0 | S13: =(($L13*(1+$M13))*(1+$N13))*G13 -> 0 | T13: =(($L13*(1+$M13))*(1+$N13))*H13 -> 0 | V13: =SUM(S13:T13) -> 0 | W13: =EXACT(V13,O13) -> TRUE | X13: =V13-O13 -> 0
A14: 11 | I14: =SUM(G14:H14) -> 0 | J14: 1 | K14: =ROUNDUP(I14*J14, 0) -> 0 | L14: =F14 -> 0 | M14: 0 | N14: 0.05 | O14: =((L14*(1+M14))*(1+N14))*K14 -> 0 | S14: =(($L14*(1+$M14))*(1+$N14))*G14 -> 0 | T14: =(($L14*(1+$M14))*(1+$N14))*H14 -> 0 | V14: =SUM(S14:T14) -> 0 | W14: =EXACT(V14,O14) -> TRUE | X14: =V14-O14 -> 0
A15: 12 | I15: =SUM(G15:H15) -> 0 | J15: 1 | K15: =ROUNDUP(I15*J15, 0) -> 0 | L15: =F15 -> 0 | M15: 0 | N15: 0.05 | O15: =((L15*(1+M15))*(1+N15))*K15 -> 0 | S15: =(($L15*(1+$M15))*(1+$N15))*G15 -> 0 | T15: =(($L15*(1+$M15))*(1+$N15))*H15 -> 0 | V15: =SUM(S15:T15) -> 0 | W15: =EXACT(V15,O15) -> TRUE | X15: =V15-O15 -> 0
A16: 13 | I16: =SUM(G16:H16) -> 0 | J16: 1 | K16: =ROUNDUP(I16*J16, 0) -> 0 | L16: =F16 -> 0 | M16: 0 | N16: 0.05 | O16: =((L16*(1+M16))*(1+N16))*K16 -> 0 | S16: =(($L16*(1+$M16))*(1+$N16))*G16 -> 0 | T16: =(($L16*(1+$M16))*(1+$N16))*H16 -> 0 | V16: =SUM(S16:T16) -> 0 | W16: =EXACT(V16,O16) -> TRUE | X16: =V16-O16 -> 0
... A139: 136 | I139: =SUM(G139:H139) -> 0 | J139: 1 | K139: =ROUNDUP(I139*J139, 0) -> 0 | L139: =F139 -> 0 | M139: 0 | N139: 0.05 | O139: =((L139*(1+M139))*(1+N139))*K139 -> 0 | S139: =(($L139*(1+$M139))*(1+$N139))*G139 -> 0 | T139: =(($L139*(1+$M139))*(1+$N139))*H139 -> 0 | V139: =SUM(S139:T139) -> 0 | W139: =EXACT(V139,O139) -> TRUE | X139: =V139-O139 -> 0
C140: ---
L144: Sub-total | O144: =SUBTOTAL(9, O4:O140) -> 882.4509 | R144: Sub-total | S144: =SUM(S4:S140)-$X$144 -> 882.4509 | T144: =SUM(T4:T140)-$X$144 -> 0 | W144: DIFF: | X144: =SUM(X4:X140)/COUNTA(S3:T3) -> 0
L145: TOTAL | O145: =SUM(O4:O140) -> 882.4509 | R145: TOTAL | S145: =SUBTOTAL(9, S4:S140)-$X$144 -> 882.4509 | T145: =SUBTOTAL(9, T4:T140)-$X$144 -> 0
G253: Cubicle 2000x1000x400 (HxWxD) with cable compartment.
G254: Motor circuit breaker, 30A
G255: Miniature Circuit breaker 1 x 10A
G256: Miniature Circuit breaker 1 x 6A
G257: Terminals, 4q
G258: PE -Terminals, 4q
G259: Cable ducts 40x80 mm
G260: Bus bars for screen connection, 500 mm
G261: EMC screen connectors for bus bar,
G262: Installing of switch board
G263: Labelling of equipments
G264: Labelling of cubicles
... G275: --

Sheet Components
A1: Components drop-down list
A2: Enclosures
A3: Components
A4: Fan + Filter
A5: Thermostat
A6: Busbar
A7: Isolator
A8: Terminal Board
A9: Power Supply
A10: MPCB
A11: MCB
A12: Contactor
... A39: Consumables

Sheet Monitoring
B1: Estimated | C1: Actual | D1: Profit | E1: % difference
A2: Material | B2: ='TotalCosts (Hrs)'!AF144 -> 1191.3087 | C2: =B16+B27 -> 0 | D2: =B2-C2 -> 1191.3087 | E2: =D2/B2 -> 1
A3: Labour | B3: ='TotalCosts (Hrs)'!AJ144*45 -> 180 | C3: =B38*32 -> 0 | D3: =B3-C3 -> 180 | E3: =D3/B3 -> 1
A4: TOTAL | B4: =SUM(B2:B3) -> 1371.3087 | C4: =SUM(C2:C3) -> 0 | D4: =B4-C4 -> 1371.3087 | E4: =D4/B4 -> 1
A7: POs | B7: Value
A15: --- | B15: ---
A16: TOTAL | B16: =SUM(B8:B14) -> 0
A18: Reqs | B18: Value
A26: --- | B26: ---
A27: TOTAL | B27: =SUM(B19:B25) -> 0
A29: Labour | B29: Hours
A37: --- | B37: ---
A38: TOTAL | B38: =SUM(B30:B36) -> 0

Sheet Shipping Costs
A1: SUPPLIER | B1: COUNTRY of ORIGIN | E1: PO value Range / € | F1: Shipping Cost / € | H1: PO value Range / € | I1: Shipping Cost / € | K1: PO value Range / € | L1: Shipping Cost / €
A2: A.N.WALLIS & CO.LTD | B2: UNITED KINGDOM. | C2: E | E2: <1,000 | F2: min.100 | H2: 2,500-7,000 | I2: 0.07 | K2: >7,000 | L2: 0.055
A3: ARDIC ELEKTRIK SAN VE TIC LTD STI. | B3: TURKEY | C3: E | H3: 15,000-25,000 | I3: 0.05 | K3: >25,000 | L3: 0.035
A4: BATT CABLES | B4: UNITED KINGDOM. | C4: E | E4: <1,000 | F4: min.100 | H4: 1,000-2,000 | I4: 0.1 | K4: 2,000-7,000 | L4: 7%
A5: BATT CABLES | B5: UNITED KINGDOM. | C5: E | E5: 7,000-10,000 | F5: 0.06 | H5: 10,000-20,000 | I5: 0.05 | K5: >40,000 | L5: 0.04
A6: BEGHELLI - ELPLAST A.S. | B6: CZECH REPUBLIC | C6: E | E6: <1,000 | F6: min.100 | H6: 1,000-2,000 | I6: 0.08
A7: BEGHELLI - ELPLAST A.S. | B7: CZECH REPUBLIC | C7: E | E7: 2,000-4,000 | F7: 6% | H7: 10,000-16,000 | I7: 0.05 | K7: >25,000 | L7: 0.035
A8: CLEVELAND CABLE CO. LTD | B8: UNITED KINGDOM | C8: E | E8: <1,000 | F8: min.100 | H8: 3,000-5,000 | I8: 0.07 | K8: >7,000 | L8: 0.055
A9: COMAT | B9: TURKEY | C9: E | E9: 550 | F9: 380 | H9: 2000 | I9: 550 | K9: >25,000 | L9: 0.08
A10: IGUZZINI | B10: ITALY | C10: E | F10: CIF
A11: IM.E.B SRL | B11: ITALY | C11: E | E11: <1,000 | F11: min.70 | H11: 1,000-5000 | I11: 8 | K11: >28,000 | L11: 0.035
A12: IMPLEX EXPORT LIMITED | B12: UNITED KINGDOM. | C12: E | E12: <1,000 | F12: min.100 | H12: 3,000-8,000 | I12: 0.07 | K12: >8,000 | L12: 0.055
A13: INTERSWITCH SRL | B13: ITALY | C13: E | E13: <1,000 | F13: min.85 | H13: 1,000-5,000 | I13: 0.06 | K13: >10,000 | L13: 0.045
A14: MARSHALL TUFFLEX INT.LTD | B14: UNITED KINGDOM. | C14: E | E14: <1,000 | F14: min.100 | H14: 1,000-4,000 | I14: 0.07 | K14: >20,000 | L14: 0.05
A15: N.C.M | B15: ITALY | C15: E | E15: <2,000 | F15: min.200
A16: NUOVA CARPENTERIA MECCANICA SNC | B16: ITALY | C16: E | E16: <1,500 | F16: min.110 | H16: 1,500-3,000 | I16: 0.06
A17: SADA CAVI S.P.A. | B17: ITALY | C17: E | E17: <1,000 | F17: min.85 | H17: 3,000-6,000 | I17: 0.06 | K17: >90,000 | L17: 0.035
A18: SEVAL KABLO A.S. | B18: TURKEY | C18: E | F18: CIF
A19: SPECIAL CAVI | B19: ITALY | C19: E | E19: <2,000 | F19: min.130 | H19: 2,000-10,000 | I19: 0.07 | K19: >20,000 | L19: 0.03
A20: TEKOM PUK | B20: TURKEY | C20: E | H20: 5,000-15,0000 | I20: 0.13 | K20: >20,000 | L20: 0.15
A21: VATAN KABLO | B21: TURKEY | C21: E | K21: >50,000 | L21: 0.04
A22: ZUCCHINI SpA | B22: ITALY | C22: E | E22: <1,000 | F22: min.100 | H22: 1,000-6,000 | I22: 0.06 | K22: >100,000 | L22: 0.035
A24: SUPPLIER | B24: COUNTRY of ORIGIN | E24: PO value Range / € | F24: Shipping Cost / € | H24: PO value Range / € | I24: Shipping Cost / € | K24: PO value Range / € | L24: Shipping Cost / €
A25: 3I INTERNATIONAL INNOVATIVE INDUSTRIES S.A. | B25: GREECE | C25: M | E25: <5,000 | F25: 6% | H25: 5,000 - 15,000 | I25: 0.05 | K25: >15,000 | L25: 0.04
A26: ACTIONCLIMA SRL | B26: ITALY | C26: M | E26: <2,000 | F26: min.100
A27: ADVANCED AIR (UK) LTD | B27: UNITED KINGDOM. | C27: M | E27: <4,000 | F27: 9% | H27: 4,000 - 8,000 | I27: 0.07 | K27: >8,000 | L27: 0.06
A28: AIREDALE INTERNATIONAL, | B28: UNITED KINGDOM. | C28: M | E28: <1,000 | F28: min.85 | K28: >15,000 | L28: 0.045
A29: ALNOR SYSTEMY WENTYLACJI SP. Z O.O. | B29: POLAND | C29: M | E29: <7,000 | F29: 9% | H29: 7,000 - 20,000 | I29: 0.05 | K29: >20,000 | L29: (5%) 3.5%
A30: ATS ISOLANTI SRL | B30: ITALY | C30: M | E30: <1,000 | F30: 10% | H30: 2,000 - 10,000 | I30: 0.06 | K30: >10,000 | L30: 0.05
A31: BRODBECK S.R.L | B31: SICILY | C31: M | E31: <1,000 | F31: min.85 | H31: 1,000-2,300 | I31: 0.08 | K31: >2,300 | L31: 0.06
A32: CALEFFI | B32: ITALY | C32: M | H32: >5000 (P.O.10967) | I32: min.100
A33: CENTRAL TUBI | B33: ITALY | C33: M | E33: <1,000 | F33: min.85 | H33: 1,000-10,000 | I33: 0.06 | K33: >10,000 | L33: 0.05
A34: CHEMINEES POUJOULAT | B34: FRANCE | C34: M | K34: >4,000 | L34: 0.06
A35: DAB PUMPS SPA | B35: ITALY | C35: M | E35: <1,000 | F35: min.90 | K35: >15,000 | L35: 0.045
A36: DANTHERM AIR HANDLING A/S | B36: DENMARK | C36: M | K36: >30,000 | L36: 0.035
A37: DINAK S.A., | B37: SPAIN. | C37: M | E37: <1,500 | F37: min.100 | H37: 1,500-10,000 | I37: 0.06 | K37: >10,000 | L37: 0.045
A38: DM SRL | B38: ITALY | C38: M | K38: >10,000 | L38: 0.045
A39: DOGU IKLIMLENDIRME SAN.VE TIC.A.S. | B39: TURKEY | C39: M | E39: <1,000 | F39: min.100 | H39: 1,000-10,000 | I39: 0.06 | K39: >10,000 | L39: 0.05
A40: DUYAR VANA MAK. SAN. VE TIC. A.S. | B40: TURKEY | C40: M | H40: 6,000-10,000 | I40: 0.05 | K40: >10,000 | L40: 0.045
A41: ELTA FANS LIMITED | B41: UNITED KINGDOM. | C41: M | E41: <1,000 | F41: min.100 | H41: 1,000-2,500 | I41: 0.1 | K41: >2,500 | L41: 0.06
...
