Workbook
Name Access_Control: [1]Elec_Est!#REF!
Name AREAS: #REF!
Name AREAS: [1]ML_Sum!$X$1:$AD$16
Name AREAS: ML_Sum!$X$1:$AD$16
Name CCTV: [1]Elec_Est!#REF!
Name Data: [1]Elec_Est!#REF!
Name Fire_Alarm: [1]Elec_Est!#REF!
Name FO: [1]Elec_Est!#REF!
Name Guard: [1]Elec_Est!#REF!
Name Intercom: [1]Elec_Est!#REF!
Name Intruder_Alarm: [1]Elec_Est!#REF!

Sheet Notes
A1: NOTES

Sheet ML_Sum
B1: CLIENT: | C1: 1 | D1: Panta | G1: TRUE | H1: TRUE | I1: 1 | J1: =$Q109 -> 1 | K1: =$Q119 -> 1 | L1: =$Q129 -> 1 | M1: =$Q139 -> 1 | N1: =$Q149 -> 1 | O1: =$Q159 -> 1 | Q1: =IF(C1=1,"€","Curr?") -> € | R1: Recon /Lab.Cont >> | S1: =IF($S$39="PRINT","R","Do Not Print") -> R | T1: 1 | V1: {=IF(OR(X1=AREAS),1,0)} -> 1 | W1: BOQ | X1: x | Y1: x | Z1: x | AA1: x | AB1: x | AC1: x | AD1: x
B2: PROJECT: | C2: =IF($D$6="VAT INCLUDED",1.18,1)*(1-$Q2)*$C$1 -> 1 | D2: Panta Showroom Phase 2 | F2: Electrical | G2: TRUE | I2: 2 | J2: =$Q110 -> 1 | K2: =$Q120 -> 1 | L2: =$Q130 -> 1 | M2: =$Q140 -> 1 | N2: =$Q150 -> 1 | O2: =$Q160 -> 1 | R2: ="A) " & IF($S2=0,"",ROUND($S2,2) & "-" & ROUND($T2/$D$9,2)) -> A) 1.1-1.1 | S2: 1.1 | T2: =$S2*$D$9 -> 30.206 | X2: x | Y2: x | Z2: x | AA2: x | AB2: x | AC2: x | AD2: x
B3: JOB DESC: | C3: =IF($D$6="VAT INCLUDED",1.18,1)*(1-$Q3)*$C$1 -> 1 | D3: Supply and Install Electrical requirements for Panta Showroom Phase 2 | G3: TRUE | I3: 3 | J3: =$Q111 -> 1 | K3: =$Q121 -> 1 | L3: =$Q131 -> 1 | M3: =$Q141 -> 1 | N3: =$Q151 -> 1 | O3: =$Q161 -> 1 | R3: ="B) " & IF($S3=0,"",ROUND($S3,2) & "-" & ROUND($T3/$D$9,2)) -> B) | X3: x | Y3: x | Z3: x | AA3: x | AB3: x | AC3: x | AD3: x
B4: INT. QUOT No: | C4: =IF($D$6="VAT INCLUDED",1.18,1)*(1-$Q4)*$C$1 -> 1 | D4: EL25_XXXX | G4: TRUE | I4: 4 | J4: =$Q112 -> 1 | K4: =$Q122 -> 1 | L4: =$Q132 -> 1 | M4: =$Q142 -> 1 | N4: =$Q152 -> 1 | O4: =$Q162 -> 1 | R4: ="C) " & IF($S4=0,"",ROUND($S4,2) & "-" & ROUND($T4/$D$9,2)) -> C) | X4: x | Y4: x | Z4: x | AA4: x | AB4: x | AC4: x | AD4: x
B5: CLIENTs REF: | C5: =IF($D$6="VAT INCLUDED",1.18,1)*(1-$Q5)*$C$1 -> 1 | G5: TRUE | I5: 5 | J5: =$Q113 -> 1 | K5: =$Q123 -> 1 | L5: =$Q133 -> 1 | M5: =$Q143 -> 1 | N5: =$Q153 -> 1 | O5: =$Q163 -> 1 | R5: ="D) " & IF($S5=0,"",ROUND($S5,2) & "-" & ROUND($T5/$D$9,2)) -> D) | X5: x | Y5: x | Z5: x | AA5: x | AB5: x | AC5: x | AD5: x
B6: VAT: | C6: =IF($D$6="VAT INCLUDED",1.18,1)*(1-$Q6)*$C$1 -> 1 | D6: VAT EXCL. | G6: TRUE | I6: 6 | J6: =$Q114 -> 1 | K6: =$Q124 -> 1 | L6: =$Q134 -> 1 | M6: =$Q144 -> 1 | N6: =$Q154 -> 1 | O6: =$Q164 -> 1 | R6: ="E) " & IF($S6=0,"",ROUND($S6,2) & "-" & ROUND($T6/$D$9,2)) -> E) | X6: x | Y6: x | Z6: x | AA6: x | AB6: x | AC6: x | AD6: x
B7: SAVED ON: | C7: =IF($D$6="VAT INCLUDED",1.18,1)*(1-$Q7)*$C$1 -> 1 | D7: 45904 | G7: TRUE | I7: 7 | J7: =$Q115 -> 1 | K7: =$Q125 -> 1 | L7: =$Q135 -> 1 | M7: =$Q145 -> 1 | N7: =$Q155 -> 1 | R7: ="F) " & IF($S7=0,"",ROUND($S7,2) & "-" & ROUND($T7/$D$9,2)) -> F) | X7: x | Y7: x | Z7: x | AA7: x | AB7: x | AC7: x | AD7: x
B8: ESTIMATOR: | C8: =IF($D$6="VAT INCLUDED",1.18,1)*(1-$Q8)*$C$1 -> 1 | D8: Umut Kaymak | G8: TRUE | I8: 8 | J8: =$Q116 -> 1 | K8: =$Q126 -> 1 | L8: =$Q136 -> 1 | M8: =$Q146 -> 1 | N8: =$Q156 -> 1 | R8: ="G) " & IF($S8=0,"",ROUND($S8,2) & "-" & ROUND($T8/$D$9,2)) -> G) | X8: x | Y8: x | Z8: x | AA8: x | AB8: x | AC8: x | AD8: x
B9: LAB. COST: | C9: =IF($D$6="VAT INCLUDED",1.18,1)*(1-$Q9)*$C$1 -> 1 | D9: 27.46 | E9: Cost for 2025 | G9: TRUE | I9: 9 | J9: =$Q117 -> 1 | K9: =$Q127 -> 1 | L9: =$Q137 -> 1 | M9: =$Q147 -> 1 | N9: =$Q157 -> 1 | R9: ="H) " & IF($S9=0,"",ROUND($S9,2) & "-" & ROUND($T9/$D$9,2)) -> H) | X9: x | Y9: x | Z9: x | AA9: x | AB9: x | AC9: x | AD9: x
C10: =IF($D$6="VAT INCLUDED",1.18,1)*(1-$Q10)*$C$1 -> 1 | G10: TRUE | I10: 10 | J10: =$Q118 -> 1 | K10: =$Q128 -> 1 | L10: =$Q138 -> 1 | M10: =$Q148 -> 1 | N10: =$Q158 -> 1 | O10: =Q108 -> 1 | R10: =" I) " & IF($S10=0,"",ROUND($S10,2) & "-" & ROUND($T10/$D$9,2)) -> I) | X10: x | Y10: x | Z10: x | AA10: x | AB10: x | AC10: x | AD10: x
C11: =IF($D$6="VAT INCLUDED",1.18,1)*(1-$Q11)*$C$1 -> 1 | R11: ="J) " & IF($S11=0,"",ROUND($S11,2) & "-" & ROUND($T11/$D$9,2)) -> J) | X11: x | Y11: x | Z11: x | AA11: x | AB11: x | AC11: x | AD11: x
C12: =IF($D$6="VAT INCLUDED",1.18,1)*(1-$Q12)*$C$1 -> 1 | G12: SYSTEMS | H12: SYSTEMS | I12: SYSTEMS | J12: SYSTEMS | K12: SYSTEMS | L12: SYSTEMS | M12: SYSTEMS | N12: SYSTEMS | O12: SYSTEMS | P12: SYSTEMS | R12: MIXED - X,Y ) | S12: MAT MU | T12: LAB RATE | X12: x | Y12: x | Z12: x | AA12: x | AB12: x | AC12: x | AD12: x
B13: MATERIAL & LABOUR SUMMARY | G13: ItemCode | H13: CostCode | I13: MAKE | J13: PART_NO | K13: MARKUP | L13: TYPE | M13: LIST_P | N13: SET | O13: FIX | P13: DATE | Q13: %Dsct in BOQ | R13: MATMU-LABMU | S13: MAT CONT >> | T13: =SUM(Q108:Q164)/57 -> 1
B14: =IF($D$6<>"VAT EXCL.", "QUOTE ISSUED WITH VAT INCLUDED", "") | X14: x | Y14: x | Z14: x | AA14: x | AB14: x | AC14: x | AD14: x
Q15: =(C72-F35)/C72 -> 0 | R15: Average Discount applied in BOQ (Q2-Q12) | X15: x | Y15: x | Z15: x | AA15: x | AB15: x | AC15: x | AD15: x
B16: =IF($W$1<>"BOQ", "DIFF SET TO " & W1,"") | Q16: =(F35-E35)/F35 -> 0 | R16: Average Discount applied on Totals (Q23-Q32) | X16: x | Y16: x | Z16: x | AA16: x | AB16: x | AC16: x | AD16: x
Q17: =F74 -> 0 | R17: Overall Discount
B18: =IF(AND(G1,G2,G3,G4,G5,G6,G7,G8,G9,G10,H1)=TRUE, "", "CHECKLIST INCOMPLETE !" )
B19: =IF(ABS(SUM(A23:A32))>100,"[Discy A-J] are high, Check it out."," ") | Q19: =R83 -> 1.1002651 | R19: Overall Markup (Final Selling Excl.VAT/Total Cost )
E21: DISCOUNTED | F21: SELLING | Q21: % Discnt | R21: MATERIAL | T21: LABOUR
A22: Discy.A-J | B22: Markup/LRate | E22: ="SELLING " & $Q$1 -> SELLING € | F22: =$Q$1 -> € | G22: VAT/DISC | H22: MU | I22: LABRATE | J22: LABCOST | Q22: on Totals | R22: € | T22: Pair Hrs.
A23: =IF($F23=0,"",($F23/$C2)-($R23*$S2+$T23*$T2)) -> 5.6782333 | B23: =IF(F23=0,"",IF(R23=0,"A) "&"---, "&ROUND(($F23/$C2-($R23*$S2))/$T23,2),IF(T23=0,"A) "&ROUND(($F23/$C2)/$R23,2),"A) "&ROUND(($F23/$C2-($T23*$T2))/$R23,2)&", " &ROUND(($F23/$C2-($R23*$S2))/$T23,2)))) -> A) 1.1, 30.22 | D23: =IF($F2="","",$F2) -> Electrical | E23: =F23*(1-Q23) -> 24023.49 | F23: =Elec_Est!F370 -> 24023.49 | G23: =C2 -> 1 | H23: =$S2 -> 1.1 | I23: =$T2 -> 30.206 | J23: =$D$9 -> 27.46 | R23: =Elec_Est!R370 -> 11673.123 | T23: =Elec_Est!T370 -> 370.03827
A24: =IF($F24=0,"",($F24/$C3)-($R24*$S3+$T24*$T3)) | B24: =IF(F24=0,"",IF(R24=0,"A) "&"---, "&ROUND(($F24/$C3-($R24*$S3))/$T24,2),IF(T24=0,"A) "&ROUND(($F24/$C3)/$R24,2),"A) "&ROUND(($F24/$C3-($T24*$T3))/$R24,2)&", " &ROUND(($F24/$C3-($R24*$S3))/$T24,2)))) | D24: =IF($F3="","",$F3) | E24: =F24*(1-Q24) -> 0 | F24: =Elec_Est!F371 -> 0 | G24: =C3 -> 1 | H24: =$S3 -> 0 | I24: =$T3 -> 0 | J24: =$D$9 -> 27.46 | R24: =Elec_Est!R371 -> 0 | T24: =Elec_Est!T371 -> 0
A25: =IF($F25=0,"",($F25/$C4)-($R25*$S4+$T25*$T4)) | B25: =IF(F25=0,"",IF(R25=0,"A) "&"---, "&ROUND(($F25/$C4-($R25*$S4))/$T25,2),IF(T25=0,"A) "&ROUND(($F25/$C4)/$R25,2),"A) "&ROUND(($F25/$C4-($T25*$T4))/$R25,2)&", " &ROUND(($F25/$C4-($R25*$S4))/$T25,2)))) | D25: =IF($F4="","",$F4) | E25: =F25*(1-Q25) -> 0 | F25: =Elec_Est!F372 -> 0 | G25: =C4 -> 1 | H25: =$S4 -> 0 | I25: =$T4 -> 0 | J25: =$D$9 -> 27.46 | R25: =Elec_Est!R372 -> 0 | T25: =Elec_Est!T372 -> 0
A26: =IF($F26=0,"",($F26/$C5)-($R26*$S5+$T26*$T5)) | B26: =IF(F26=0,"",IF(R26=0,"A) "&"---, "&ROUND(($F26/$C5-($R26*$S5))/$T26,2),IF(T26=0,"A) "&ROUND(($F26/$C5)/$R26,2),"A) "&ROUND(($F26/$C5-($T26*$T5))/$R26,2)&", " &ROUND(($F26/$C5-($R26*$S5))/$T26,2)))) | D26: =IF($F5="","",$F5) | E26: =F26*(1-Q26) -> 0 | F26: =Elec_Est!F373 -> 0 | G26: =C5 -> 1 | H26: =$S5 -> 0 | I26: =$T5 -> 0 | J26: =$D$9 -> 27.46 | R26: =Elec_Est!R373 -> 0 | T26: =Elec_Est!T373 -> 0
A27: =IF($F27=0,"",($F27/$C6)-($R27*$S6+$T27*$T6)) | B27: =IF(F27=0,"",IF(R27=0,"A) "&"---, "&ROUND(($F27/$C6-($R27*$S6))/$T27,2),IF(T27=0,"A) "&ROUND(($F27/$C6)/$R27,2),"A) "&ROUND(($F27/$C6-($T27*$T6))/$R27,2)&", " &ROUND(($F27/$C6-($R27*$S6))/$T27,2)))) | D27: =IF($F6="","",$F6) | E27: =F27*(1-Q27) -> 0 | F27: =Elec_Est!F374 -> 0 | G27: =C6 -> 1 | H27: =$S6 -> 0 | I27: =$T6 -> 0 | J27: =$D$9 -> 27.46 | R27: =Elec_Est!R374 -> 0 | T27: =Elec_Est!T374 -> 0
A28: =IF($F28=0,"",($F28/$C7)-($R28*$S7+$T28*$T7)) | B28: =IF(F28=0,"",IF(R28=0,"A) "&"---, "&ROUND(($F28/$C7-($R28*$S7))/$T28,2),IF(T28=0,"A) "&ROUND(($F28/$C7)/$R28,2),"A) "&ROUND(($F28/$C7-($T28*$T7))/$R28,2)&", " &ROUND(($F28/$C7-($R28*$S7))/$T28,2)))) | D28: =IF($F7="","",$F7) | E28: =F28*(1-Q28) -> 0 | F28: =Elec_Est!F375 -> 0 | G28: =C7 -> 1 | H28: =$S7 -> 0 | I28: =$T7 -> 0 | J28: =$D$9 -> 27.46 | R28: =Elec_Est!R375 -> 0 | T28: =Elec_Est!T375 -> 0
A29: =IF($F29=0,"",($F29/$C8)-($R29*$S8+$T29*$T8)) | B29: =IF(F29=0,"",IF(R29=0,"A) "&"---, "&ROUND(($F29/$C8-($R29*$S8))/$T29,2),IF(T29=0,"A) "&ROUND(($F29/$C8)/$R29,2),"A) "&ROUND(($F29/$C8-($T29*$T8))/$R29,2)&", " &ROUND(($F29/$C8-($R29*$S8))/$T29,2)))) | D29: =IF($F8="","",$F8) | E29: =F29*(1-Q29) -> 0 | F29: =Elec_Est!F376 -> 0 | G29: =C8 -> 1 | H29: =$S8 -> 0 | I29: =$T8 -> 0 | J29: =$D$9 -> 27.46 | R29: =Elec_Est!R376 -> 0 | T29: =Elec_Est!T376 -> 0
A30: =IF($F30=0,"",($F30/$C9)-($R30*$S9+$T30*$T9)) | B30: =IF(F30=0,"",IF(R30=0,"A) "&"---, "&ROUND(($F30/$C9-($R30*$S9))/$T30,2),IF(T30=0,"A) "&ROUND(($F30/$C9)/$R30,2),"A) "&ROUND(($F30/$C9-($T30*$T9))/$R30,2)&", " &ROUND(($F30/$C9-($R30*$S9))/$T30,2)))) | D30: =IF($F9="","",$F9) | E30: =F30*(1-Q30) -> 0 | F30: =Elec_Est!F377 -> 0 | G30: =C9 -> 1 | H30: =$S9 -> 0 | I30: =$T9 -> 0 | J30: =$D$9 -> 27.46 | R30: =Elec_Est!R377 -> 0 | T30: =Elec_Est!T377 -> 0
A31: =IF($F31=0,"",($F31/$C10)-($R31*$S10+$T31*$T10)) | B31: =IF(F31=0,"",IF(R31=0,"A) "&"---, "&ROUND(($F31/$C10-($R31*$S10))/$T31,2),IF(T31=0,"A) "&ROUND(($F31/$C10)/$R31,2),"A) "&ROUND(($F31/$C10-($T31*$T10))/$R31,2)&", " &ROUND(($F31/$C10-($R31*$S10))/$T31,2)))) | D31: =IF($F10="","",$F10) | E31: =F31*(1-Q31) -> 0 | F31: =Elec_Est!F378 -> 0 | G31: =C10 -> 1 | H31: =$S10 -> 0 | I31: =$T10 -> 0 | J31: =$D$9 -> 27.46 | R31: =Elec_Est!R378 -> 0 | T31: =Elec_Est!T378 -> 0 | X31: =Y70/W31=360/4 -> #DIV/0!
A32: =IF($F32=0,"",($F32/$C11)-($R32*$S11+$T32*$T11)) | B32: =IF(F32=0,"",IF(R32=0,"A) "&"---, "&ROUND(($F32/$C11-($R32*$S11))/$T32,2),IF(T32=0,"A) "&ROUND(($F32/$C11)/$R32,2),"A) "&ROUND(($F32/$C11-($T32*$T11))/$R32,2)&", " &ROUND(($F32/$C11-($R32*$S11))/$T32,2)))) | D32: =IF($F11="","",$F11) | E32: =F32*(1-Q32) -> 0 | F32: =Elec_Est!F379 -> 0 | G32: =C11 -> 1 | H32: =$S11 -> 0 | I32: =$T11 -> 0 | J32: =$D$9 -> 27.46 | R32: =Elec_Est!R379 -> 0 | T32: =Elec_Est!T379 -> 0
C33: MIXED
A35: Discy.L | B35: =E_BOQ!F147 -> 24023.49 | E35: =SUM(E23:E32) -> 24023.49 | F35: =SUM(F23:F32) -> 24023.49 | R35: =SUM(R23:R32) -> 11673.123 | T35: =SUM(T23:T32) -> 370.03827
A36: =IF(A39=0,"0.00",A39-(A38*A37)) -> 0.00 | B36: BOQ TOTAL | E36: ="ESTIM TOTAL (" & $Q$1 & ")" -> ESTIM TOTAL (€)
A37: 1.125 | B37: <1 Actual LabCont | R37: =R165 -> 11673.023 | S37: C.C.Totals | T37: =T165 -> 370.03827
B38: <2 Phrs @ 1.00
B39: <3 Phrs @ Actual | Q39: Discy.T >> | R39: =R37-R35 -> -0.1 | S39: PRINT | T39: =T37-T35 -> 0
B41: Values Only on : | D41: 45904 | E41: 24023.49 | F41: 24023.49 | R41: 11673.123 | T41: 370.03827
A46: REMARKS:
A47: 1) VAT and Duties as above.
...

Sheet Quote
A1: =IF(AND(UPPER(LEFT(TRIM($D$8),11))="01",UPPER(LEFT(TRIM($D$9),3))<>"ELM"),"PANTA RETAIL LTD.","PANTA CONTRACTING LIMITED") -> PANTA CONTRACTING LIMITED
A2: =IF(UPPER(LEFT(TRIM($D$9),3))="ELM","ELEC-FOR-MECH INTERNAL QUOTATION","ELECTRICAL INTERNAL QUOTATION") -> ELECTRICAL INTERNAL QUOTATION
B5: ATT: | D5: =IF(A2="Internal Quotation", "Mechanical Division","") | R5: Dated: | S5: =NOW() -> 46118.473
B6: CLIENT: | C6: Link to ML_SUM $D1 | D6: =ML_Sum!D1 -> Panta
B7: PROJECT: | C7: Link to ML_SUM $D2 | D7: =ML_Sum!D2 -> Panta Showroom Phase 2
B8: JOB DESC: | C8: Link to ML_SUM $D3 | D8: =ML_Sum!D3 -> Supply and Install Electrical requirements for Panta Showroom Phase 2
B9: QUOTE No: | C9: Link to ML_SUM $D4 | D9: =ML_Sum!D4 -> EL25_XXXX
B10: CLIENT's Ref: | C10: Link to ML_SUM $D5 | D10: =ML_Sum!D5 -> 0
D22: Selling Price (€) : | E22: =ML_Sum!E35 -> 24023.49 | F22: =ML_Sum!D6 -> VAT EXCL. | G22: VAT EXCLUDED. | H22: VAT EXCLUDED. | I22: VAT EXCLUDED. | J22: VAT EXCLUDED. | K22: VAT EXCLUDED. | L22: VAT EXCLUDED. | M22: VAT EXCLUDED. | N22: VAT EXCLUDED. | O22: VAT EXCLUDED. | P22: VAT EXCLUDED.
A51: Signed for and on behalf of | Q51: Signed for and on behalf of
A52: Electrical Division | Q52: Division
Q54: Records
Q55: Mr. A. Sciberras
Q57: File

Sheet Elec_Rates
B1: CLIENT: | C1: =ML_Sum!$C1 -> 1 | D1: =ML_Sum!$D1 -> Panta | F1: =ML_Sum!$F1 -> 0 | I1: 1 | J1: =ML_Sum!$J1 -> 1 | K1: =ML_Sum!$K1 -> 1 | L1: =ML_Sum!$L1 -> 1 | M1: =ML_Sum!$M1 -> 1 | N1: =ML_Sum!$N1 -> 1 | O1: =ML_Sum!$O1 -> 1 | Q1: =ML_Sum!$Q1 -> € | R1: R/Lab Cont | S1: =ML_Sum!$S1 -> R | T1: =ML_Sum!$T1 -> 1 | U1: =ML_Sum!W1 -> BOQ | V1: INCL | W1: MULT | X1: AREA | Y1: BOQ | Z1: TDWG | AA1: ACT | AB1: DIFF
B2: PROJECT: | C2: =ML_Sum!$C2 -> 1 | D2: =ML_Sum!$D2 -> Panta Showroom Phase 2 | F2: =ML_Sum!$F2 -> Electrical | I2: 2 | J2: =ML_Sum!$J2 -> 1 | K2: =ML_Sum!$K2 -> 1 | L2: =ML_Sum!$L2 -> 1 | M2: =ML_Sum!$M2 -> 1 | N2: =ML_Sum!$N2 -> 1 | O2: =ML_Sum!$O2 -> 1 | Q2: =ML_Sum!$Q2 -> 0 | R2: mu_A | S2: =ML_Sum!$S2 -> 1.1 | T2: =ML_Sum!$T2 -> 30.206
B3: JOB DESC: | C3: =ML_Sum!$C3 -> 1 | D3: =ML_Sum!$D3 -> Supply and Install Electrical requirements for Panta Showroom Phase 2 | F3: =ML_Sum!$F3 -> 0 | I3: 3 | J3: =ML_Sum!$J3 -> 1 | K3: =ML_Sum!$K3 -> 1 | L3: =ML_Sum!$L3 -> 1 | M3: =ML_Sum!$M3 -> 1 | N3: =ML_Sum!$N3 -> 1 | O3: =ML_Sum!$O3 -> 1 | Q3: =ML_Sum!$Q3 -> 0 | R3: mu_B | S3: =ML_Sum!$S3 -> 0 | T3: =ML_Sum!$T3 -> 0
B4: QUOTE No: | C4: =ML_Sum!$C4 -> 1 | D4: =ML_Sum!$D4 -> EL25_XXXX | F4: =ML_Sum!$F4 -> 0 | I4: 4 | J4: =ML_Sum!$J4 -> 1 | K4: =ML_Sum!$K4 -> 1 | L4: =ML_Sum!$L4 -> 1 | M4: =ML_Sum!$M4 -> 1 | N4: =ML_Sum!$N4 -> 1 | O4: =ML_Sum!$O4 -> 1 | Q4: =ML_Sum!$Q4 -> 0 | R4: mu_C | S4: =ML_Sum!$S4 -> 0 | T4: =ML_Sum!$T4 -> 0
B5: CLIENTs REF: | C5: =ML_Sum!$C5 -> 1 | D5: =ML_Sum!$D5 -> 0 | F5: =ML_Sum!$F5 -> 0 | I5: 5 | J5: =ML_Sum!$J5 -> 1 | K5: =ML_Sum!$K5 -> 1 | L5: =ML_Sum!$L5 -> 1 | M5: =ML_Sum!$M5 -> 1 | N5: =ML_Sum!$N5 -> 1 | O5: =ML_Sum!$O5 -> 1 | Q5: =ML_Sum!$Q5 -> 0 | R5: mu_D | S5: =ML_Sum!$S5 -> 0 | T5: =ML_Sum!$T5 -> 0
B6: VAT/DUTIES: | C6: =ML_Sum!$C6 -> 1 | D6: =ML_Sum!$D6 -> VAT EXCL. | F6: =ML_Sum!$F6 -> 0 | I6: 6 | J6: =ML_Sum!$J6 -> 1 | K6: =ML_Sum!$K6 -> 1 | L6: =ML_Sum!$L6 -> 1 | M6: =ML_Sum!$M6 -> 1 | N6: =ML_Sum!$N6 -> 1 | O6: =ML_Sum!$O6 -> 1 | Q6: =ML_Sum!$Q6 -> 0 | R6: mu_E | S6: =ML_Sum!$S6 -> 0 | T6: =ML_Sum!$T6 -> 0
B7: SAVED ON: | C7: =ML_Sum!$C7 -> 1 | D7: 39364 | F7: =ML_Sum!$F7 -> 0 | I7: 7 | J7: =ML_Sum!$J7 -> 1 | K7: =ML_Sum!$K7 -> 1 | L7: =ML_Sum!$L7 -> 1 | M7: =ML_Sum!$M7 -> 1 | N7: =ML_Sum!$N7 -> 1 | O7: =ML_Sum!$O7 -> 0 | Q7: =ML_Sum!$Q7 -> 0 | R7: mu_F | S7: =ML_Sum!$S7 -> 0 | T7: =ML_Sum!$T7 -> 0
B8: ESTIMATOR: | C8: =ML_Sum!$C8 -> 1 | D8: =ML_Sum!$D8 -> Umut Kaymak | F8: =ML_Sum!$F8 -> 0 | I8: 8 | J8: =ML_Sum!$J8 -> 1 | K8: =ML_Sum!$K8 -> 1 | L8: =ML_Sum!$L8 -> 1 | M8: =ML_Sum!$M8 -> 1 | N8: =ML_Sum!$N8 -> 1 | O8: =ML_Sum!$O8 -> 0 | Q8: =ML_Sum!$Q8 -> 0 | R8: mu_G | S8: =ML_Sum!$S8 -> 0 | T8: =ML_Sum!$T8 -> 0
B9: LABOUR RATE: | C9: =ML_Sum!$C9 -> 1 | D9: =ML_Sum!$D9 -> 27.46 | F9: =ML_Sum!$F9 -> 0 | I9: 9 | J9: =ML_Sum!$J9 -> 1 | K9: =ML_Sum!$K9 -> 1 | L9: =ML_Sum!$L9 -> 1 | M9: =ML_Sum!$M9 -> 1 | N9: =ML_Sum!$N9 -> 1 | O9: =ML_Sum!$O9 -> 0 | Q9: =ML_Sum!$Q9 -> 0 | R9: mu_H | S9: =ML_Sum!$S9 -> 0 | T9: =ML_Sum!$T9 -> 0
C10: =ML_Sum!$C10 -> 1 | F10: =ML_Sum!$F10 -> 0 | I10: 10 | J10: =ML_Sum!$J10 -> 1 | K10: =ML_Sum!$K10 -> 1 | L10: =ML_Sum!$L10 -> 1 | M10: =ML_Sum!$M10 -> 1 | N10: =ML_Sum!$N10 -> 1 | O10: =ML_Sum!$O10 -> 1 | Q10: =ML_Sum!$Q10 -> 0 | R10: mu_I | S10: =ML_Sum!$S10 -> 0 | T10: =ML_Sum!$T10 -> 0
C11: =ML_Sum!$C11 -> 1 | F11: =ML_Sum!$F11 -> 0 | Q11: =ML_Sum!$Q11 -> 0 | R11: mu_J | S11: =ML_Sum!$S11 -> 0 | T11: =ML_Sum!$T11 -> 0
C12: =ML_Sum!$C12 -> 1 | F12: =ML_Sum!$F12 -> 0 | Q12: =ML_Sum!$Q12 -> 0 | R12: MIXED | S12: =ML_Sum!$S12 -> MAT MU | T12: =ML_Sum!$T12 -> LAB RATE
G13: I_CODE | H13: C_CODE | I13: MAKE | J13: PART_NO | K13: MARKUP | L13: TYPE | M13: LIST_P | N13: P_FACT | O13: FIX | P13: DATE | Q13: %Dsct in BOQ | R13: MU TYPE | S13: MAT MU | T13: LAB RATE
C15: t | D15: Item:
D16: Start Typing Header
Q18: Multip
A19: 45 | B19: =Elec_Est!B455 -> 45 | D19: 001# Power Point | K19: RATE | L19: RATE | Q19: =B19/A19 -> 1 | R19: =IF($B19=0,0,IF($S$1="R",ROUND(R25/$B19,2),R25/$B19)) -> 22.7 | T19: =IF($B19=0,0,IF($S$1="R",ROUND(T25/$B19,2),T25/$B19)) -> 1.58
D20: Based on:
A21: 320 | B21: m | D21: Conduit PVC 25mm HG RATE | G21: COPV_007 | H21: 700 | I21: GEN | J21: 25mm | O21: 1 | P21: 42213 | Q21: =0.86*2 -> 1.72 | R21: =$A21*Q21 -> 550.4 | S21: 0.18 | T21: =$A21*S21*$T$1 -> 57.6
A22: 600 | B22: m | D22: Wiring Cable 1c 4.0 mm2 PVC Non-Arm | G22: CASC_017 | H22: 615 | I22: CRO | K22: 02-002 | O22: 2 | P22: 38988 | Q22: 0.59 | R22: =$A22*Q22 -> 354 | S22: 0.015 | T22: =$A22*S22*$T$1 -> 9
A23: 300 | B23: m | D23: Wiring Cable 1c 2.5 mm2 PVC Non-Arm | G23: CASC_017 | H23: 615 | I23: CRO | K23: 02-002 | O23: 2 | P23: 38988 | Q23: 0.39 | R23: =$A23*Q23 -> 117 | S23: 0.015 | T23: =$A23*S23*$T$1 -> 4.5
C24: << ==== TOTAL UNITS | R24: =$A24*Q24 -> 0 | T24: =$A24*S24*$T$1 -> 0
A25: d> | B25: =(R25+T25)-SUM(R20:R24,T20:T24) -> 0 | D25: Sell_A | E25: =IF($B19=0,0,ROUND(ROUND(($R25*$S$2+($T25*$T$2))/$B19, 2)*$C$2,2)) -> 72.69 | F25: =ROUND($B19*$E25,2) -> 3271.05 | K25: ITEM | L25: ITEM | R25: =SUM(R20:R24) -> 1021.4 | T25: =SUM(T20:T24) -> 71.1
A26: END!
A27: END! | D27: RATE SHEET GRAND TOTAL | R27: MATERIAL | T27: LABOUR
A28: END!
A29: END! | D29: COMPONENTS | L29: COMP_RT | R29: =SUMIF($L$12:$L27,"",R$12:R27) -> 1021.4 | T29: =SUMIF($L$12:$L27,"",T$12:T27) -> 71.1
A30: END! | D30: RATE SUMS (ITEMS) | L30: ITEM_RT | R30: =SUMIF($L$12:$L27,"ITEM",R$12:R27) -> 1021.4 | T30: =SUMIF($L$12:$L27,"ITEM",T$12:T27) -> 71.1
A31: SB!
B32: V:56 | E32: COSTCODE TOTAL | R32: =SUM(R33:R88) -> 1021.4 | T32: =SUM(T33:T88) -> 71.1
B33: 1 | C33: cc | D33: Erection materials | F33: 501 | P33: 1 | R33: =SUMIF($H$12:$H$26,$F33,R$12:R$26) -> 0 | T33: =SUMIF($H$12:$H$26,$F33,T$12:T$26) -> 0
B34: 2 | C34: cc | D34: Busbar Trunking | F34: 505 | P34: 1 | R34: =SUMIF($H$12:$H$26,$F34,R$12:R$26) -> 0 | T34: =SUMIF($H$12:$H$26,$F34,T$12:T$26) -> 0
B35: 3 | C35: cc | D35: Switchgear | F35: 510 | P35: 2 | R35: =SUMIF($H$12:$H$26,$F35,R$12:R$26) -> 0 | T35: =SUMIF($H$12:$H$26,$F35,T$12:T$26) -> 0
B36: 4 | C36: cc | D36: MCC Equipment | F36: 511 | P36: 2 | R36: =SUMIF($H$12:$H$26,$F36,R$12:R$26) -> 0 | T36: =SUMIF($H$12:$H$26,$F36,T$12:T$26) -> 0
B37: 5 | C37: cc | D37: BMS Equipment | F37: 512 | P37: 2 | R37: =SUMIF($H$12:$H$26,$F37,R$12:R$26) -> 0 | T37: =SUMIF($H$12:$H$26,$F37,T$12:T$26) -> 0
B38: 6 | C38: cc | D38: PVC Pipes / Ducts | F38: 520 | P38: 1 | R38: =SUMIF($H$12:$H$26,$F38,R$12:R$26) -> 0 | T38: =SUMIF($H$12:$H$26,$F38,T$12:T$26) -> 0
B39: 7 | C39: cc | D39: High/medium voltage switchgear | F39: 530 | P39: 2 | R39: =SUMIF($H$12:$H$26,$F39,R$12:R$26) -> 0 | T39: =SUMIF($H$12:$H$26,$F39,T$12:T$26) -> 0
B40: 8 | C40: cc | D40: Power Transformers | F40: 550 | P40: 2 | R40: =SUMIF($H$12:$H$26,$F40,R$12:R$26) -> 0 | T40: =SUMIF($H$12:$H$26,$F40,T$12:T$26) -> 0
B41: 9 | C41: cc | D41: Control Panels | F41: 570 | P41: 2 | R41: =SUMIF($H$12:$H$26,$F41,R$12:R$26) -> 0 | T41: =SUMIF($H$12:$H$26,$F41,T$12:T$26) -> 0
B42: 10 | C42: cc | D42: Electrical Single Core Cables | F42: 615 | P42: 2 | R42: =SUMIF($H$12:$H$26,$F42,R$12:R$26) -> 471 | T42: =SUMIF($H$12:$H$26,$F42,T$12:T$26) -> 13.5
...

Sheet Elec_Est
B1: CLIENT: | C1: =ML_Sum!$C1 -> 1 | D1: =ML_Sum!$D1 -> Panta | F1: =ML_Sum!$F1 -> 0 | I1: 1 | J1: =ML_Sum!$J1 -> 1 | K1: =ML_Sum!$K1 -> 1 | L1: =ML_Sum!$L1 -> 1 | M1: =ML_Sum!$M1 -> 1 | N1: =ML_Sum!$N1 -> 1 | O1: =ML_Sum!$O1 -> 1 | Q1: =ML_Sum!$Q1 -> € | R1: R/Lab Cont | S1: =ML_Sum!$S1 -> R | T1: =ML_Sum!$T1 -> 1 | U1: =ML_Sum!W1 -> BOQ | V1: INCL | W1: MULT | X1: AREA | Y1: BOQ | Z1: TDWG | AA1: ACT | AB1: DIFF
B2: PROJECT: | C2: =ML_Sum!$C2 -> 1 | D2: =ML_Sum!$D2 -> Panta Showroom Phase 2 | F2: =ML_Sum!$F2 -> Electrical | I2: 2 | J2: =ML_Sum!$J2 -> 1 | K2: =ML_Sum!$K2 -> 1 | L2: =ML_Sum!$L2 -> 1 | M2: =ML_Sum!$M2 -> 1 | N2: =ML_Sum!$N2 -> 1 | O2: =ML_Sum!$O2 -> 1 | Q2: =ML_Sum!$Q2 -> 0 | R2: mu_A | S2: =ML_Sum!$S2 -> 1.1 | T2: =ML_Sum!$T2 -> 30.206
B3: JOB DESC: | C3: =ML_Sum!$C3 -> 1 | D3: =ML_Sum!$D3 -> Supply and Install Electrical requirements for Panta Showroom Phase 2 | F3: =ML_Sum!$F3 -> 0 | I3: 3 | J3: =ML_Sum!$J3 -> 1 | K3: =ML_Sum!$K3 -> 1 | L3: =ML_Sum!$L3 -> 1 | M3: =ML_Sum!$M3 -> 1 | N3: =ML_Sum!$N3 -> 1 | O3: =ML_Sum!$O3 -> 1 | Q3: =ML_Sum!$Q3 -> 0 | R3: mu_B | S3: =ML_Sum!$S3 -> 0 | T3: =ML_Sum!$T3 -> 0
B4: QUOTE No: | C4: =ML_Sum!$C4 -> 1 | D4: =ML_Sum!$D4 -> EL25_XXXX | F4: =ML_Sum!$F4 -> 0 | I4: 4 | J4: =ML_Sum!$J4 -> 1 | K4: =ML_Sum!$K4 -> 1 | L4: =ML_Sum!$L4 -> 1 | M4: =ML_Sum!$M4 -> 1 | N4: =ML_Sum!$N4 -> 1 | O4: =ML_Sum!$O4 -> 1 | Q4: =ML_Sum!$Q4 -> 0 | R4: mu_C | S4: =ML_Sum!$S4 -> 0 | T4: =ML_Sum!$T4 -> 0
B5: CLIENTs REF: | C5: =ML_Sum!$C5 -> 1 | D5: =ML_Sum!$D5 -> 0 | F5: =ML_Sum!$F5 -> 0 | I5: 5 | J5: =ML_Sum!$J5 -> 1 | K5: =ML_Sum!$K5 -> 1 | L5: =ML_Sum!$L5 -> 1 | M5: =ML_Sum!$M5 -> 1 | N5: =ML_Sum!$N5 -> 1 | O5: =ML_Sum!$O5 -> 1 | Q5: =ML_Sum!$Q5 -> 0 | R5: mu_D | S5: =ML_Sum!$S5 -> 0 | T5: =ML_Sum!$T5 -> 0
B6: VAT/DUTIES: | C6: =ML_Sum!$C6 -> 1 | D6: =ML_Sum!$D6 -> VAT EXCL. | F6: =ML_Sum!$F6 -> 0 | I6: 6 | J6: =ML_Sum!$J6 -> 1 | K6: =ML_Sum!$K6 -> 1 | L6: =ML_Sum!$L6 -> 1 | M6: =ML_Sum!$M6 -> 1 | N6: =ML_Sum!$N6 -> 1 | O6: =ML_Sum!$O6 -> 1 | Q6: =ML_Sum!$Q6 -> 0 | R6: mu_E | S6: =ML_Sum!$S6 -> 0 | T6: =ML_Sum!$T6 -> 0
B7: SAVED ON: | C7: =ML_Sum!$C7 -> 1 | D7: 39364 | F7: =ML_Sum!$F7 -> 0 | I7: 7 | J7: =ML_Sum!$J7 -> 1 | K7: =ML_Sum!$K7 -> 1 | L7: =ML_Sum!$L7 -> 1 | M7: =ML_Sum!$M7 -> 1 | N7: =ML_Sum!$N7 -> 1 | O7: =ML_Sum!$O7 -> 0 | Q7: =ML_Sum!$Q7 -> 0 | R7: mu_F | S7: =ML_Sum!$S7 -> 0 | T7: =ML_Sum!$T7 -> 0
B8: ESTIMATOR: | C8: =ML_Sum!$C8 -> 1 | D8: =ML_Sum!$D8 -> Umut Kaymak | F8: =ML_Sum!$F8 -> 0 | I8: 8 | J8: =ML_Sum!$J8 -> 1 | K8: =ML_Sum!$K8 -> 1 | L8: =ML_Sum!$L8 -> 1 | M8: =ML_Sum!$M8 -> 1 | N8: =ML_Sum!$N8 -> 1 | O8: =ML_Sum!$O8 -> 0 | Q8: =ML_Sum!$Q8 -> 0 | R8: mu_G | S8: =ML_Sum!$S8 -> 0 | T8: =ML_Sum!$T8 -> 0
B9: LABOUR RATE: | C9: =ML_Sum!$C9 -> 1 | D9: =ML_Sum!$D9 -> 27.46 | F9: =ML_Sum!$F9 -> 0 | I9: 9 | J9: =ML_Sum!$J9 -> 1 | K9: =ML_Sum!$K9 -> 1 | L9: =ML_Sum!$L9 -> 1 | M9: =ML_Sum!$M9 -> 1 | N9: =ML_Sum!$N9 -> 1 | O9: =ML_Sum!$O9 -> 0 | Q9: =ML_Sum!$Q9 -> 0 | R9: mu_H | S9: =ML_Sum!$S9 -> 0 | T9: =ML_Sum!$T9 -> 0
C10: =ML_Sum!$C10 -> 1 | F10: =ML_Sum!$F10 -> 0 | I10: 10 | J10: =ML_Sum!$J10 -> 1 | K10: =ML_Sum!$K10 -> 1 | L10: =ML_Sum!$L10 -> 1 | M10: =ML_Sum!$M10 -> 1 | N10: =ML_Sum!$N10 -> 1 | O10: =ML_Sum!$O10 -> 1 | Q10: =ML_Sum!$Q10 -> 0 | R10: mu_I | S10: =ML_Sum!$S10 -> 0 | T10: =ML_Sum!$T10 -> 0
C11: =ML_Sum!$C11 -> 1 | F11: =ML_Sum!$F11 -> 0 | Q11: =ML_Sum!$Q11 -> 0 | R11: mu_J | S11: =ML_Sum!$S11 -> 0 | T11: =ML_Sum!$T11 -> 0
C12: =ML_Sum!$C12 -> 1 | F12: =ML_Sum!$F12 -> 0 | Q12: =ML_Sum!$Q12 -> 0 | R12: MIXED | S12: =ML_Sum!$S12 -> MAT MU | T12: =ML_Sum!$T12 -> LAB RATE
G13: ISELL | H13: C_CODE | I13: MAKE | J13: PART_NO | K13: MARKUP | L13: TYPE | M13: LIST_P | N13: P_FACT | O13: FIX | P13: DATE | Q13: %Dsct in BOQ | R13: MU TYPE | S13: MAT MU | T13: LAB RATE | AM13: Tot Mat Cost | AN13: Unit Lab phr. | AO13: Tot Lab phr. | AP13: < for ELM / MEE
K14: TB
C15: t | D15: Item: 1
D16: Supply, install & connect power supply cables.
E18: Sell Rate | F18: Sell Total | K18: IB | AG18: U_M_Sell | AH18: T_M_Sell | AI18: U_L_Sell | AJ18: T_L_Sell | AK18: Total_Sell | AM18: T_M_Cost | AN18: T_L_Phr | AO18: Mat/Lab=1
A19: 35 | B19: M | D19: Item: 1.01 | E19: =IF(AND($A19=0,$A$1="DIF"),0, ROUND(ROUND(($R26*$S$2+($T26*$T$2))/A19,2)*$C$2,2)) -> 34.29 | F19: =ROUND($A19*$E19,2) -> 1200.15 | G19: ISELL | K19: mu_A | L19: ITEM | T19: =IF(AND($R26=0,$T26=0),"0.00","mu :" & ROUND($F19/$C$2/($R26+$T26*$D$9),2)) -> mu :1.1 | AG19: =IF($E19=0,0,ROUND($R26*$S$2*$C$2/$A19,2)) -> 28.29 | AH19: =$AG19*$A19 -> 990.15 | AI19: =$E19-$AG19 -> 6 | AJ19: =$A19*$AI19 -> 210 | AK19: =ROUND(($AG19+$AI19)*$A19,2) -> 1200.15 | AM19: =ROUND(R26,2) -> 900.24 | AN19: =ROUND(T26,2) -> 6.95 | AO19: =ROUND(AM19+AN19,2)*A19 -> 31751.65
D20: 5c 35mm XLPE/SWA/LSZH cable SR.E2 | K20: n
A21: 35 | B21: m | D21: Power Cable 5c 25 mm2 XLPE SWA-LSZH | G21: CAMC_097 | H21: 616 | I21: (__) | J21: 25mm2 | O21: 2 | P21: 40767 | Q21: 25 | R21: =$A21*Q21 -> 875 | S21: 0.15 | T21: =$A21*S21*$T$1 -> 5.25
A22: 2 | B22: No | D22: Cable Marker Warning Tape | G22: CAAC_071 | H22: 620 | I22: (__) | O22: 2 | Q22: 0.5 | R22: =$A22*Q22 -> 1 | T22: =$A22*S22*$T$1 -> 0
A23: 2 | B23: No | D23: Gland Indoor 32 BWL 4*25/35mm2 | G23: CAAC_044 | H23: 620 | I23: CMP | O23: 2 | P23: 35431 | Q23: 11.32 | R23: =$A23*Q23 -> 22.64 | S23: 0.5 | T23: =$A23*S23*$T$1 -> 1
A24: 10 | B24: No | D24: Cable Lug 25 mm2 | G24: CAAC_010 | H24: 620 | I24: CTT | O24: 2 | P24: 34669 | Q24: 0.16 | R24: =$A24*Q24 -> 1.6 | S24: 0.07 | T24: =$A24*S24*$T$1 -> 0.7
R25: =$A25*Q25 -> 0 | T25: =$A25*S25*$T$1 -> 0
A26: d> | B26: =(R25+T25) -> 0 | G26: ICOST | K26: mu_A | L26: ITEM | R26: =SUM(R20:R25) -> 900.24 | T26: =SUM(T20:T25) -> 6.95
E27: Sell Rate | F27: Sell Total | K27: IB | AG27: U_M_Sell | AH27: T_M_Sell | AI27: U_L_Sell | AJ27: T_L_Sell | AK27: Total_Sell | AM27: T_M_Cost | AN27: T_L_Phr | AO27: Mat/Lab=1
A28: 50 | B28: M | D28: Item: 1.02 | E28: =IF(AND($A28=0,$A$1="DIF"),0, ROUND(ROUND(($R36*$S$2+($T36*$T$2))/A28,2)*$C$2,2)) -> 10.07 | F28: =ROUND($A28*$E28,2) -> 503.5 | G28: ISELL | K28: mu_A | L28: ITEM | T28: =IF(AND($R36=0,$T36=0),"0.00","mu :" & ROUND($F28/$C$2/($R36+$T36*$D$9),2)) -> mu :1.1 | AG28: =IF($E28=0,0,ROUND($R36*$S$2*$C$2/$A28,2)) -> 7.17 | AH28: =$AG28*$A28 -> 358.5 | AI28: =$E28-$AG28 -> 2.9 | AJ28: =$A28*$AI28 -> 145 | AK28: =ROUND(($AG28+$AI28)*$A28,2) -> 503.5 | AM28: =ROUND(R36,2) -> 325.85 | AN28: =ROUND(T36,2) -> 4.8 | AO28: =ROUND(AM28+AN28,2)*A28 -> 16532.5
D29: 5c 6.0mm XLPE/SWA/LSZH Cable | K29: n
A30: 50 | B30: m | D30: Power Cable 5c 4.0 mm2 XLPE SWA-LSZH | G30: CAMC_085 | H30: 616 | I30: (__) | J30: 4.0mm2 | O30: 2 | P30: 38371 | Q30: 6 | R30: =$A30*Q30 -> 300 | S30: 0.06 | T30: =$A30*S30*$T$1 -> 3
A31: 2 | B31: No | D31: Cable Marker Warning Tape | G31: CAAC_071 | H31: 620 | I31: (__) | O31: 2 | Q31: 0.5 | R31: =$A31*Q31 -> 1 | T31: =$A31*S31*$T$1 -> 0
A32: 1 | B32: No | D32: Gland Indoor 20 BWL 4*4/6mm2 | G32: CAAC_040 | H32: 620 | I32: CMP | O32: 2 | P32: 35431 | Q32: 4.71 | R32: =$A32*Q32 -> 4.71 | S32: 0.35 | T32: =$A32*S32*$T$1 -> 0.35
A33: 3 | B33: No | D33: Gland Outdoor 20 CW 4*4/6mm2 | G33: CAAC_053 | H33: 620 | I33: CMP | O33: 2 | P33: 35431 | Q33: 6.38 | R33: =$A33*Q33 -> 19.14 | S33: 0.35 | T33: =$A33*S33*$T$1 -> 1.05
A34: 20 | B34: No | D34: Cable Lug 4.0 mm2 | G34: CAAC_006 | H34: 620 | I34: CTT | O34: 2 | P34: 34669 | Q34: 0.05 | R34: =$A34*Q34 -> 1 | S34: 0.02 | T34: =$A34*S34*$T$1 -> 0.4
R35: =$A35*Q35 -> 0 | T35: =$A35*S35*$T$1 -> 0
A36: d> | B36: =(R35+T35) -> 0 | G36: ICOST | K36: mu_A | L36: ITEM | R36: =SUM(R29:R35) -> 325.85 | T36: =SUM(T29:T35) -> 4.8
K37: TB
C38: t | D38: Item: 2
D39: Supply, install & connect the following switchgear.
E41: Sell Rate | F41: Sell Total | K41: IB | AG41: U_M_Sell | AH41: T_M_Sell | AI41: U_L_Sell | AJ41: T_L_Sell | AK41: Total_Sell | AM41: T_M_Cost | AN41: T_L_Phr | AO41: Mat/Lab=1
A42: 1 | B42: No. | D42: Item: 2.01 | E42: =IF(AND($A42=0,$A$1="DIF"),0, ROUND(ROUND(($R46*$S$2+($T46*$T$2))/A42,2)*$C$2,2)) -> 839.15 | F42: =ROUND($A42*$E42,2) -> 839.15 | G42: ISELL | K42: mu_A | L42: ITEM | T42: =IF(AND($R46=0,$T46=0),"0.00","mu :" & ROUND($F42/$C$2/($R46+$T46*$D$9),2)) -> mu :1.1 | AG42: =IF($E42=0,0,ROUND($R46*$S$2*$C$2/$A42,2)) -> 597.5 | AH42: =$AG42*$A42 -> 597.5 | AI42: =$E42-$AG42 -> 241.65 | AJ42: =$A42*$AI42 -> 241.65 | AK42: =ROUND(($AG42+$AI42)*$A42,2) -> 839.15 | AM42: =ROUND(R46,2) -> 543.18 | AN42: =ROUND(T46,2) -> 8 | AO42: =ROUND(AM42+AN42,2)*A42 -> 551.18
...

Sheet E_BOQ
A1: ITEM NO. | B1: DESCRIPTION | C1: QTY | D1: UNIT | E1: RATE | F1: TOTAL
E2: € | F2: €
A4: =TRIM(MID(Elec_Est!D15,6,30)) -> 1 | B4: =Elec_Est!D16 -> Supply, install & connect power supply cables.
A6: =TRIM(MID(Elec_Est!D19,6,30)) -> 1.01 | B6: =Elec_Est!D20 -> 5c 35mm XLPE/SWA/LSZH cable SR.E2 | C6: =Elec_Est!A19 -> 35 | D6: =Elec_Est!B19 -> M | E6: =Elec_Est!E19 -> 34.29 | F6: =C6*E6 -> 1200.15
A8: =TRIM(MID(Elec_Est!D28,6,30)) -> 1.02 | B8: =Elec_Est!D29 -> 5c 6.0mm XLPE/SWA/LSZH Cable | C8: =Elec_Est!A28 -> 50 | D8: =Elec_Est!B28 -> M | E8: =Elec_Est!E28 -> 10.07 | F8: =C8*E8 -> 503.5
A11: =TRIM(MID(Elec_Est!D38,6,30)) -> 2 | B11: =Elec_Est!D39 -> Supply, install & connect the following switchgear.
A13: =TRIM(MID(Elec_Est!D42,6,30)) -> 2.01 | B13: =Elec_Est!D43 -> 12 Way Distrebution Board DB-SR.E2 | C13: =Elec_Est!A42 -> 1 | D13: =Elec_Est!B42 -> No. | E13: =Elec_Est!E42 -> 839.15 | F13: =C13*E13 -> 839.15
A15: =TRIM(MID(Elec_Est!D48,6,30)) -> 2.02 | B15: =Elec_Est!D49 -> 4P 63A IP65 Isolator for AC outdoor unit | C15: =Elec_Est!A48 -> 1 | D15: =Elec_Est!B48 -> No. | E15: =Elec_Est!E48 -> 85.74 | F15: =C15*E15 -> 85.74
A18: =TRIM(MID(Elec_Est!D57,6,30)) -> 3 | B18: =Elec_Est!D58 -> Supply & install the following containment
A20: =TRIM(MID(Elec_Est!D61,6,30)) -> 3.03 | B20: =Elec_Est!D62 -> 100x100mm Galvanised cable trunking | C20: =Elec_Est!A61 -> 6 | D20: =Elec_Est!B61 -> M | E20: =Elec_Est!E61 -> 43.81 | F20: =C20*E20 -> 262.86
A23: =TRIM(MID(Elec_Est!D76,6,30)) -> 4 | B23: =Elec_Est!D77 -> Supply, install & connect the following power points complete with wiring accessories.
A25: =TRIM(MID(Elec_Est!D80,6,30)) -> 4.01 | B25: =Elec_Est!D81 -> 13A Twin socket outlets | C25: =Elec_Est!A80 -> 24 | D25: =Elec_Est!B80 -> No. | E25: =Elec_Est!E80 -> 83.3 | F25: =C25*E25 -> 1999.2
A27: =TRIM(MID(Elec_Est!D91,6,30)) -> 4.02 | B27: =Elec_Est!D92 -> !3A Fuse connection unit complete with neon indicator | C27: =Elec_Est!A91 -> 14 | D27: =Elec_Est!B91 -> No. | E27: =Elec_Est!E91 -> 83.4 | F27: =C27*E27 -> 1167.6
A29: =TRIM(MID(Elec_Est!D102,6,30)) -> 4.03 | B29: =Elec_Est!D103 -> 3 Compartment Floor outlet boxes complete with 4No 13A single socket outlets & 2No. RJ45 single outlets | C29: =Elec_Est!A102 -> 7 | D29: =Elec_Est!B102 -> No. | E29: =Elec_Est!E102 -> 750.7 | F29: =C29*E29 -> 5254.9
A32: =TRIM(MID(Elec_Est!D114,6,30)) -> 5 | B32: =Elec_Est!D115 -> Supply, install & connect the following lighting points including the Dali cabling.
A34: =TRIM(MID(Elec_Est!D118,6,30)) -> 5.01 | B34: =Elec_Est!D119 -> Light points | C34: =Elec_Est!A118 -> 50 | D34: =Elec_Est!B118 -> No. | E34: =Elec_Est!E118 -> 35.55 | F34: =C34*E34 -> 1777.5
A36: =TRIM(MID(Elec_Est!D126,6,30)) -> 5.02 | B36: =Elec_Est!D127 -> Emergency light points | C36: =Elec_Est!A126 -> 9 | D36: =Elec_Est!B126 -> No. | E36: =Elec_Est!E126 -> 53.13 | F36: =C36*E36 -> 478.17
A39: =TRIM(MID(Elec_Est!D134,6,30)) -> 6 | B39: =Elec_Est!D135 -> Supply, install & connect the following light fittings.
A41: =TRIM(MID(Elec_Est!D138,6,30)) -> 6.01 | B41: =Elec_Est!D139 -> Emergency lights | C41: =Elec_Est!A138 -> 9 | D41: =Elec_Est!B138 -> No. | E41: =Elec_Est!E138 -> 70.1 | F41: =C41*E41 -> 630.9
A49: SB | E49: Page Total : | F49: =SUM(F5:F48) -> 14199.67 | G49: =SUM(G3:G48) -> 0 | H49: =SUM(H3:H48) -> 0 | I49: =SUM(I3:I48) -> 0 | J49: =SUM(J3:J48) -> 0 | K49: =SUM(K3:K48) -> 0 | L49: =SUM(L3:L48) -> 0 | M49: =SUM(M3:M48) -> 0 | N49: =SUM(N3:N48) -> 0 | ... P49: =SUM(P3:P48) -> 0
A50: ITEM NO. | B50: DESCRIPTION | C50: QTY | D50: UNIT | E50: RATE | F50: TOTAL
E51: € | F51: €
A53: =TRIM(MID(Elec_Est!D153,6,30)) -> 7 | B53: =Elec_Est!D154 -> Install and connect the following light fittings supplied by others.
A55: =TRIM(MID(Elec_Est!D157,6,30)) -> 7.01 | B55: =Elec_Est!D158 -> LED Strip Light in meeting room | C55: =Elec_Est!A157 -> 1 | D55: =Elec_Est!B157 -> No. | E55: =Elec_Est!E157 -> 33.16 | F55: =C55*E55 -> 33.16
A57: =TRIM(MID(Elec_Est!D165,6,30)) -> 7.02 | B57: =Elec_Est!D166 -> Chandelier in meeting room | C57: =Elec_Est!A165 -> 1 | D57: =Elec_Est!B165 -> No. | E57: =Elec_Est!E165 -> 52.66 | F57: =C57*E57 -> 52.66
A59: =TRIM(MID(Elec_Est!D173,6,30)) -> 7.03 | B59: =Elec_Est!D174 -> Lighting track 4.8 meteres | C59: =Elec_Est!A173 -> 2 | D59: =Elec_Est!B173 -> No. | E59: =Elec_Est!E173 -> 108.85 | F59: =C59*E59 -> 217.7
A61: =TRIM(MID(Elec_Est!D181,6,30)) -> 7.04 | B61: =Elec_Est!D182 -> Lighting track 15 meteres | C61: =Elec_Est!A181 -> 1 | D61: =Elec_Est!B181 -> No. | E61: =Elec_Est!E181 -> 324.52 | F61: =C61*E61 -> 324.52
A63: =TRIM(MID(Elec_Est!D189,6,30)) -> 7.05 | B63: =Elec_Est!D190 -> Lighting track 3.5 meteres | C63: =Elec_Est!A189 -> 1 | D63: =Elec_Est!B189 -> No. | E63: =Elec_Est!E189 -> 81.36 | F63: =C63*E63 -> 81.36
A65: =TRIM(MID(Elec_Est!D197,6,30)) -> 7.06 | B65: =Elec_Est!D198 -> Lighting track 10 meteres | C65: =Elec_Est!A197 -> 1 | D65: =Elec_Est!B197 -> No. | E65: =Elec_Est!E197 -> 218.8 | F65: =C65*E65 -> 218.8
A67: =TRIM(MID(Elec_Est!D205,6,30)) -> 7.07 | B67: =Elec_Est!D206 -> Lighting track 12 meteres | C67: =Elec_Est!A205 -> 1 | D67: =Elec_Est!B205 -> No. | E67: =Elec_Est!E205 -> 261.09 | F67: =C67*E67 -> 261.09
A69: =TRIM(MID(Elec_Est!D213,6,30)) -> 7.08 | B69: =Elec_Est!D214 -> Hexagon Lighting | C69: =Elec_Est!A213 -> 1 | D69: =Elec_Est!B213 -> No. | E69: =Elec_Est!E213 -> 28.5 | F69: =C69*E69 -> 28.5
A71: =TRIM(MID(Elec_Est!D221,6,30)) -> 7.09 | B71: =Elec_Est!D222 -> High Ceiling Lighting | C71: =Elec_Est!A221 -> 13 | D71: =Elec_Est!B221 -> No. | E71: =Elec_Est!E221 -> 33.16 | F71: =C71*E71 -> 431.08
A74: =TRIM(MID(Elec_Est!D228,6,30)) -> 8 | B74: =Elec_Est!D229 -> Supply, install & connect Dali equipment.
A76: =TRIM(MID(Elec_Est!D232,6,30)) -> 8.01 | B76: =Elec_Est!D233 -> Dali controller | C76: =Elec_Est!A232 -> 1 | D76: =Elec_Est!B232 -> No | E76: =Elec_Est!E232 -> 1283.99 | F76: =C76*E76 -> 1283.99
A78: =TRIM(MID(Elec_Est!D241,6,30)) -> 8.02 | B78: =Elec_Est!D242 -> Dali 7" Main touch screen | C78: =Elec_Est!A241 -> 1 | D78: =Elec_Est!B241 -> No. | E78: =Elec_Est!E241 -> 1151.85 | F78: =C78*E78 -> 1151.85
A80: =TRIM(MID(Elec_Est!D249,6,30)) -> 8.03 | B80: =Elec_Est!D250 -> Dali touch screen in meeting room | C80: =Elec_Est!A249 -> 1 | D80: =Elec_Est!B249 -> No. | E80: =Elec_Est!E249 -> 391.3 | F80: =C80*E80 -> 391.3
A83: =TRIM(MID(Elec_Est!D257,6,30)) -> 9 | B83: =Elec_Est!D258 -> Supply, install & connect data points
A85: =TRIM(MID(Elec_Est!D261,6,30)) -> 9.01 | B85: =Elec_Est!D262 -> 25mm PVC conduit | C85: =Elec_Est!A261 -> 27 | D85: =Elec_Est!B261 -> No. | E85: =Elec_Est!E261 -> 39.36 | F85: =C85*E85 -> 1062.72
A87: =TRIM(MID(Elec_Est!D267,6,30)) -> 9.02 | B87: =Elec_Est!D268 -> Cat6 cables | C87: =Elec_Est!A267 -> 1150 | D87: =Elec_Est!B267 -> M | E87: =Elec_Est!E267 -> 0.76 | F87: =C87*E87 -> 874
A89: =TRIM(MID(Elec_Est!D273,6,30)) -> 9.03 | B89: =Elec_Est!D274 -> Single RJ45 outlets | C89: =Elec_Est!A273 -> 6 | D89: =Elec_Est!B273 -> No. | E89: =Elec_Est!E273 -> 7.33 | F89: =C89*E89 -> 43.98
...

Sheet E_DBOQ
A1: ITEM | B1: DESCRIPTION | C1: QTY | G1: UNIT | H1: RATE | I1: TOTAL | J1: Unit | K1: Total
C2: BOQ | D2: TDWG | E2: ACT | F2: DIFF | H2: € | I2: € | J2: Hrs | K2: Hrs
A54: SB | F54: System total - carried forward to summary page : | H54: VAT EXCL. | I54: =SUM(I3:I53) -> 0 | K54: =SUM(K3:K53) -> 0
A55: ITEM | B55: DESCRIPTION | C55: QTY | G55: UNIT | H55: RATE | I55: TOTAL | J55: Unit | K55: Total
C56: BOQ | D56: TDWG | E56: ACT | F56: DIFF | H56: € | I56: € | J56: Hrs | K56: Hrs
A111: SB | F111: System total - carried forward to summary page : | H111: VAT EXCL. | I111: =SUM(I57:I110) -> 0 | K111: =SUM(K57:K110) -> 0
A112: ITEM | B112: DESCRIPTION | C112: QTY | G112: UNIT | H112: RATE | I112: TOTAL | J112: Unit | K112: Total
C113: BOQ | D113: TDWG | E113: ACT | F113: DIFF | H113: € | I113: € | J113: Hrs | K113: Hrs
A168: SB | F168: System total - carried forward to summary page : | H168: VAT EXCL. | I168: =SUM(I114:I167) -> 0 | K168: =SUM(K114:K167) -> 0
A169: ITEM | B169: DESCRIPTION | C169: QTY | G169: UNIT | H169: RATE | I169: TOTAL | J169: Unit | K169: Total
C170: BOQ | D170: TDWG | E170: ACT | F170: DIFF | H170: € | I170: € | J170: Hrs | K170: Hrs
A225: SB | F225: System total - carried forward to summary page : | H225: VAT EXCL. | I225: =SUM(I171:I224) -> 0 | K225: =SUM(K171:K224) -> 0
A226: ITEM | B226: DESCRIPTION | C226: QTY | G226: UNIT | H226: RATE | I226: TOTAL | J226: Unit | K226: Total
C227: BOQ | D227: TDWG | E227: ACT | F227: DIFF | H227: € | I227: € | J227: Hrs | K227: Hrs
A282: SB | F282: System total - carried forward to summary page : | H282: VAT EXCL. | I282: =SUM(I228:I281) -> 0 | K282: =SUM(K228:K281) -> 0
A283: ITEM | B283: DESCRIPTION | C283: QTY | G283: UNIT | H283: RATE | I283: TOTAL | J283: Unit | K283: Total
C284: BOQ | D284: TDWG | E284: ACT | F284: DIFF | H284: € | I284: € | J284: Hrs | K284: Hrs
A339: SB | F339: System total - carried forward to summary page : | H339: VAT EXCL. | I339: =SUM(I285:I338) -> 0 | K339: =SUM(K285:K338) -> 0
A340: ITEM | B340: DESCRIPTION | C340: QTY | G340: UNIT | H340: RATE | I340: TOTAL | J340: Unit | K340: Total
C341: BOQ | D341: TDWG | E341: ACT | F341: DIFF | H341: € | I341: € | J341: Hrs | K341: Hrs
A396: SB | F396: System total - carried forward to summary page : | H396: VAT EXCL. | I396: =SUM(I342:I395) -> 0 | K396: =SUM(K342:K395) -> 0
A397: ITEM | B397: DESCRIPTION | C397: QTY | G397: UNIT | H397: RATE | I397: TOTAL | J397: Unit | K397: Total
C398: BOQ | D398: TDWG | E398: ACT | F398: DIFF | H398: € | I398: € | J398: Hrs | K398: Hrs
A453: SB | F453: System total - carried forward to summary page : | H453: VAT EXCL. | I453: =SUM(I399:I452) -> 0 | K453: =SUM(K399:K452) -> 0
A454: ITEM | B454: DESCRIPTION | C454: QTY | G454: UNIT | H454: RATE | I454: TOTAL | J454: Unit | K454: Total
C455: BOQ | D455: TDWG | E455: ACT | F455: DIFF | H455: € | I455: € | J455: Hrs | K455: Hrs
A510: SB | F510: System total - carried forward to summary page : | H510: VAT EXCL. | I510: =SUM(I456:I509) -> 0 | K510: =SUM(K456:K509) -> 0
A511: ITEM | B511: DESCRIPTION | C511: QTY | G511: UNIT | H511: RATE | I511: TOTAL | J511: Unit | K511: Total
C512: BOQ | D512: TDWG | E512: ACT | F512: DIFF | H512: € | I512: € | J512: Hrs | K512: Hrs
A567: SB | F567: System total - carried forward to summary page : | H567: VAT EXCL. | I567: =SUM(I513:I566) -> 0 | K567: =SUM(K513:K566) -> 0
