Workbook
Name __tab89: '[1]Table 8 & 9'!$B$4:$D$440
Name _N: #REF!
Name _tab89: '[1]Table 8 & 9'!$B$4:$D$440
Name A: #REF!
Name aaaa: #REF!
Name abcd: #REF!
Name Access_BMS: [3]BMS_Estimate!#REF!
Name Access_Control: [4]Elec_Est!#REF!
Name Access_Supply: [3]BMS_Estimate!#REF!
Name Access_Wiring: [3]BMS_Estimate!#REF!
Name AddedMat: '[5]Data Upload D'!$E$8:$E$9
Name ANS: #REF!
Name AREAS: #REF!
Name AREAS: [4]ML_Sum!$X$1:$AD$16
Name AREAS: ML_Sum!$X$1:$AD$16
Name ASD: #REF!
Name B: #REF!
Name BILL3: [6]LIST!$B$56:$B$114
Name BILL4: [6]LIST!$B$116:$B$223
Name BILL5: [6]LIST!$B$225:$B$290
Name BILL6: [6]LIST!$B$293:$B$357
Name BILL7: [6]LIST!$B$360:$B$423
Name Bill9: [6]BoQ_1020!$B$638:$B$702
Name boq: #REF!
Name C_: #REF!
Name CCTV: [4]Elec_Est!#REF!
Name Cert: [7]Data!$A$1:$H$65536
Name CHILLERS: Elec_Est!$A$16
Name CONCRETE: #REF!
Name Contractor2: '[8]1. Cover Sheet'!$C$11
Name Data: [4]Elec_Est!#REF!
Name DATA_5: [9]Data!$A$1:$H$65536
Name DATA_SYSTEM: #REF!
Name day_works: #REF!
Name DAYWORKS: #REF!
Name Excavation: [10]List!$B$275:$B$307
Name Excel_BuiltIn__FilterDatabase_1: #REF!
Name Excel_BuiltIn__FilterDatabase_4: #REF!
Name Excel_BuiltIn_Print_Area_4: #REF!
Name Fire_Alarm: [4]Elec_Est!#REF!
Name FO: [4]Elec_Est!#REF!
Name ghuk: [11]Data!$A$1:$H$65536
Name Guard: [4]Elec_Est!#REF!
Name Intercom: [4]Elec_Est!#REF!
Name Intruder_Alarm: [4]Elec_Est!#REF!
Name LEVEL: #REF!
Name LIGHTNING_PROTECTION: #REF!
Name list: [12]workings!$K$5:$K$6
Name LIST2: #REF!
Name list3: '[13]MoW 1010'!$B$161:$B$183
Name MASONRY: #REF!
Name MISCELLANEOUS: #REF!
Name Persons: [14]Estimate!#REF!
Name Print_Area_MI: #REF!
Name Pumps: Elec_Est!#REF!
Name RAMON: #REF!
Name REINFORCEMENT: #REF!
Name ROOFING: #REF!
Name sdgdfg: [15]Data!$A$1:$H$65536
Name steel: [10]List!$B$161:$B$178

Sheet Notes
A1: NOTES:

Sheet Quote
A1: =IF(AND(UPPER(LEFT(TRIM($D$8),11))="01",UPPER(LEFT(TRIM($D$9),3))<>"ELM"),"PANTA RETAIL LTD.","PANTA CONTRACTING LIMITED") -> PANTA CONTRACTING LIMITED
A2: =IF(UPPER(LEFT(TRIM($D$9),3))="ELM","ELEC-FOR-MECH INTERNAL QUOTATION","ELECTRICAL INTERNAL QUOTATION") -> ELEC-FOR-MECH INTERNAL QUOTATION
B5: ATT: | D5: =IF(A2="Internal Quotation", "Mechanical Division","") | R5: Dated: | S5: =NOW() -> 46127.715
B6: CLIENT: | C6: Link to ML_SUM $D1 | D6: =ML_Sum!D1 -> ST Microelectronics (Malta) Ltd.
B7: PROJECT: | C7: Link to ML_SUM $D2 | D7: =ML_Sum!D2 -> KK2 General Exhaust Replacement
B8: JOB DESC: | C8: Link to ML_SUM $D3 | D8: =ML_Sum!D3 -> Electrical Supply and Installation
B9: QUOTE No: | C9: Link to ML_SUM $D4 | D9: =ML_Sum!D4 -> ELM25-0560
B10: CLIENT's Ref: | C10: Link to ML_SUM $D5 | D10: =ML_Sum!D5 -> Tender
D22: Total Material Cost (€) : | E22: =ML_Sum!R35 -> 4954.73
D23: Total Labour (hrs) | E23: =ML_Sum!T35 -> 90.254065
A51: Signed for and on behalf of | Q51: Signed for and on behalf of
A52: Electrical Division | Q52: Division
Q54: Records
Q55: Mr. K. Micallef
Q57: File

Sheet ML_Sum
B1: CLIENT: | C1: 1 | D1: ST Microelectronics (Malta) Ltd. | G1: TRUE | H1: TRUE | I1: 1 | J1: =$Q109 -> 1 | K1: =$Q119 -> 1 | L1: =$Q129 -> 1 | M1: =$Q139 -> 1 | N1: =$Q149 -> 1 | O1: =$Q159 -> 1 | Q1: =IF(C1=1,"€","Curr?") -> € | R1: Recon /Lab.Cont >> | S1: =IF($S$39="PRINT","R","Do Not Print") -> R | T1: 1.15 | V1: {=IF(OR(X1=AREAS),1,0)} -> 1 | W1: BOQ | X1: x | Y1: x | Z1: x | AA1: x | AB1: x | AC1: x | AD1: x
B2: PROJECT: | C2: =IF($D$6="VAT INCLUDED",1.18,1)*(1-$Q2)*$C$1 -> 1 | D2: KK2 General Exhaust Replacement | F2: Electrical | G2: TRUE | I2: 2 | J2: =$Q110 -> 1 | K2: =$Q120 -> 1 | L2: =$Q130 -> 1 | M2: =$Q140 -> 1 | N2: =$Q150 -> 1 | O2: =$Q160 -> 1 | R2: ="A) " & IF($S2=0,"",ROUND($S2,2) & "-" & ROUND($T2/$D$9,2)) -> A) 1-1 | S2: 1 | T2: =$S2*$D$9 -> 27.46 | X2: x | Y2: x | Z2: x | AA2: x | AB2: x | AC2: x | AD2: x
B3: JOB DESC: | C3: =IF($D$6="VAT INCLUDED",1.18,1)*(1-$Q3)*$C$1 -> 1 | D3: Electrical Supply and Installation | F3: Controls | G3: TRUE | I3: 3 | J3: =$Q111 -> 1 | K3: =$Q121 -> 1 | L3: =$Q131 -> 1 | M3: =$Q141 -> 1 | N3: =$Q151 -> 1 | O3: =$Q161 -> 1 | R3: ="B) " & IF($S3=0,"",ROUND($S3,2) & "-" & ROUND($T3/$D$9,2)) -> B) 1-1 | S3: 1 | T3: =$S3*$D$9 -> 27.46 | X3: x | Y3: x | Z3: x | AA3: x | AB3: x | AC3: x | AD3: x
B4: INT. QUOT No: | C4: =IF($D$6="VAT INCLUDED",1.18,1)*(1-$Q4)*$C$1 -> 1 | D4: ELM25-0560 | F4: Controls | G4: TRUE | I4: 4 | J4: =$Q112 -> 1 | K4: =$Q122 -> 1 | L4: =$Q132 -> 1 | M4: =$Q142 -> 1 | N4: =$Q152 -> 1 | O4: =$Q162 -> 1 | R4: ="C) " & IF($S4=0,"",ROUND($S4,2) & "-" & ROUND($T4/$D$9,2)) -> C) 1-1 | S4: 1 | T4: =$S4*$D$9 -> 27.46 | X4: x | Y4: x | Z4: x | AA4: x | AB4: x | AC4: x | AD4: x
B5: CLIENTs REF: | C5: =IF($D$6="VAT INCLUDED",1.18,1)*(1-$Q5)*$C$1 -> 1 | D5: Tender | G5: TRUE | I5: 5 | J5: =$Q113 -> 1 | K5: =$Q123 -> 1 | L5: =$Q133 -> 1 | M5: =$Q143 -> 1 | N5: =$Q153 -> 1 | O5: =$Q163 -> 1 | R5: ="D) " & IF($S5=0,"",ROUND($S5,2) & "-" & ROUND($T5/$D$9,2)) -> D) | X5: x | Y5: x | Z5: x | AA5: x | AB5: x | AC5: x | AD5: x
B6: VAT: | C6: =IF($D$6="VAT INCLUDED",1.18,1)*(1-$Q6)*$C$1 -> 1 | D6: VAT EXCL. | G6: TRUE | I6: 6 | J6: =$Q114 -> 1 | K6: =$Q124 -> 1 | L6: =$Q134 -> 1 | M6: =$Q144 -> 1 | N6: =$Q154 -> 1 | O6: =$Q164 -> 1 | R6: ="E) " & IF($S6=0,"",ROUND($S6,2) & "-" & ROUND($T6/$D$9,2)) -> E) | X6: x | Y6: x | Z6: x | AA6: x | AB6: x | AC6: x | AD6: x
B7: SAVED ON: | C7: =IF($D$6="VAT INCLUDED",1.18,1)*(1-$Q7)*$C$1 -> 1 | D7: 45902 | G7: TRUE | I7: 7 | J7: =$Q115 -> 1 | K7: =$Q125 -> 1 | L7: =$Q135 -> 1 | M7: =$Q145 -> 1 | N7: =$Q155 -> 1 | R7: ="F) " & IF($S7=0,"",ROUND($S7,2) & "-" & ROUND($T7/$D$9,2)) -> F) | X7: x | Y7: x | Z7: x | AA7: x | AB7: x | AC7: x | AD7: x
B8: ESTIMATOR: | C8: =IF($D$6="VAT INCLUDED",1.18,1)*(1-$Q8)*$C$1 -> 1 | D8: Umut Kaymak | G8: TRUE | I8: 8 | J8: =$Q116 -> 1 | K8: =$Q126 -> 1 | L8: =$Q136 -> 1 | M8: =$Q146 -> 1 | N8: =$Q156 -> 1 | R8: ="G) " & IF($S8=0,"",ROUND($S8,2) & "-" & ROUND($T8/$D$9,2)) -> G) | X8: x | Y8: x | Z8: x | AA8: x | AB8: x | AC8: x | AD8: x
B9: LAB. COST: | C9: =IF($D$6="VAT INCLUDED",1.18,1)*(1-$Q9)*$C$1 -> 1 | D9: 27.46 | G9: TRUE | I9: 9 | J9: =$Q117 -> 1 | K9: =$Q127 -> 1 | L9: =$Q137 -> 1 | M9: =$Q147 -> 1 | N9: =$Q157 -> 1 | R9: ="H) " & IF($S9=0,"",ROUND($S9,2) & "-" & ROUND($T9/$D$9,2)) -> H) | X9: x | Y9: x | Z9: x | AA9: x | AB9: x | AC9: x | AD9: x
C10: =IF($D$6="VAT INCLUDED",1.18,1)*(1-$Q10)*$C$1 -> 1 | G10: TRUE | I10: 10 | J10: =$Q118 -> 1 | K10: =$Q128 -> 1 | L10: =$Q138 -> 1 | M10: =$Q148 -> 1 | N10: =$Q158 -> 1 | O10: =Q108 -> 1 | R10: =" I) " & IF($S10=0,"",ROUND($S10,2) & "-" & ROUND($T10/$D$9,2)) -> I) | X10: x | Y10: x | Z10: x | AA10: x | AB10: x | AC10: x | AD10: x
C11: =IF($D$6="VAT INCLUDED",1.18,1)*(1-$Q11)*$C$1 -> 1 | R11: ="J) " & IF($S11=0,"",ROUND($S11,2) & "-" & ROUND($T11/$D$9,2)) -> J) | X11: x | Y11: x | Z11: x | AA11: x | AB11: x | AC11: x | AD11: x
C12: =IF($D$6="VAT INCLUDED",1.18,1)*(1-$Q12)*$C$1 -> 1 | G12: SYSTEMS | H12: SYSTEMS | I12: SYSTEMS | J12: SYSTEMS | K12: SYSTEMS | L12: SYSTEMS | M12: SYSTEMS | N12: SYSTEMS | O12: SYSTEMS | P12: SYSTEMS | R12: MIXED - X,Y ) | S12: MAT MU | T12: LAB RATE | X12: x | Y12: x | Z12: x | AA12: x | AB12: x | AC12: x | AD12: x
B13: MATERIAL & LABOUR SUMMARY | G13: ItemCode | H13: CostCode | I13: MAKE | J13: PART_NO | K13: MARKUP | L13: TYPE | M13: LIST_P | N13: SET | O13: FIX | P13: DATE | Q13: %Dsct in BOQ | R13: MATMU-LABMU | S13: MAT CONT >> | T13: =SUM(Q108:Q164)/57 -> 1
B14: =IF($D$6<>"VAT EXCL.", "QUOTE ISSUED WITH VAT INCLUDED", "") | X14: x | Y14: x | Z14: x | AA14: x | AB14: x | AC14: x | AD14: x
Q15: =(C72-F35)/C72 -> 0 | R15: Average Discount applied in BOQ (Q2-Q12) | X15: x | Y15: x | Z15: x | AA15: x | AB15: x | AC15: x | AD15: x
B16: =IF($W$1<>"BOQ", "DIFF SET TO " & W1,"") | Q16: =(F35-E35)/F35 -> 0 | R16: Average Discount applied on Totals (Q23-Q32) | X16: x | Y16: x | Z16: x | AA16: x | AB16: x | AC16: x | AD16: x
Q17: =F74 -> 0 | R17: Overall Discount
B18: =IF(AND(G1,G2,G3,G4,G5,G6,G7,G8,G9,G10,H1)=TRUE, "", "CHECKLIST INCOMPLETE !" )
B19: =IF(ABS(SUM(A23:A32))>100,"[Discy A-J] are high, Check it out."," ") | Q19: =R83 -> 1.0000299 | R19: Overall Markup (Final Selling Excl.VAT/Total Cost )
E21: DISCOUNTED | F21: SELLING | Q21: % Discnt | R21: MATERIAL | T21: LABOUR
A22: Discy.A-J | B22: Markup/LRate | E22: ="SELLING " & $Q$1 -> SELLING € | F22: =$Q$1 -> € | G22: VAT/DISC | H22: MU | I22: LABRATE | J22: LABCOST | Q22: on Totals | R22: € | T22: Pair Hrs.
A23: =IF($F23=0,"",($F23/$C2)-($R23*$S2+$T23*$T2)) -> 0.00238 | B23: =IF(F23=0,"",IF(R23=0,"A) "&"---, "&ROUND(($F23/$C2-($R23*$S2))/$T23,2),IF(T23=0,"A) "&ROUND(($F23/$C2)/$R23,2),"A) "&ROUND(($F23/$C2-($T23*$T2))/$R23,2)&", " &ROUND(($F23/$C2-($R23*$S2))/$T23,2)))) -> A) 1, 27.46 | D23: =IF($F2="","",$F2) -> Electrical | E23: =F23*(1-Q23) -> 3598.99 | F23: =Elec_Est!F127 -> 3598.99 | G23: =C2 -> 1 | H23: =$S2 -> 1 | I23: =$T2 -> 27.46 | J23: =$D$9 -> 27.46 | R23: =Elec_Est!R127 -> 1731.79 | T23: =Elec_Est!T127 -> 67.997
A24: =IF($F24=0,"",($F24/$C3)-($R24*$S3+$T24*$T3)) -> -0.009 | B24: =IF(F24=0,"",IF(R24=0,"A) "&"---, "&ROUND(($F24/$C3-($R24*$S3))/$T24,2),IF(T24=0,"A) "&ROUND(($F24/$C3)/$R24,2),"A) "&ROUND(($F24/$C3-($T24*$T3))/$R24,2)&", " &ROUND(($F24/$C3-($R24*$S3))/$T24,2)))) -> A) 1, 27.46 | D24: =IF($F3="","",$F3) -> Controls | E24: =F24*(1-Q24) -> 3834.11 | F24: =Elec_Est!F128 -> 3834.11 | G24: =C3 -> 1 | H24: =$S3 -> 1 | I24: =$T3 -> 27.46 | J24: =$D$9 -> 27.46 | R24: =Elec_Est!R128 -> 3222.94 | T24: =Elec_Est!T128 -> 22.257065
A25: =IF($F25=0,"",($F25/$C4)-($R25*$S4+$T25*$T4)) | B25: =IF(F25=0,"",IF(R25=0,"A) "&"---, "&ROUND(($F25/$C4-($R25*$S4))/$T25,2),IF(T25=0,"A) "&ROUND(($F25/$C4)/$R25,2),"A) "&ROUND(($F25/$C4-($T25*$T4))/$R25,2)&", " &ROUND(($F25/$C4-($R25*$S4))/$T25,2)))) | D25: =IF($F4="","",$F4) -> Controls | E25: =F25*(1-Q25) -> 0 | F25: =Elec_Est!F129 -> 0 | G25: =C4 -> 1 | H25: =$S4 -> 1 | I25: =$T4 -> 27.46 | J25: =$D$9 -> 27.46 | R25: =Elec_Est!R129 -> 0 | T25: =Elec_Est!T129 -> 0
A26: =IF($F26=0,"",($F26/$C5)-($R26*$S5+$T26*$T5)) | B26: =IF(F26=0,"",IF(R26=0,"A) "&"---, "&ROUND(($F26/$C5-($R26*$S5))/$T26,2),IF(T26=0,"A) "&ROUND(($F26/$C5)/$R26,2),"A) "&ROUND(($F26/$C5-($T26*$T5))/$R26,2)&", " &ROUND(($F26/$C5-($R26*$S5))/$T26,2)))) | D26: =IF($F5="","",$F5) | E26: =F26*(1-Q26) -> 0 | F26: =Elec_Est!F130 -> 0 | G26: =C5 -> 1 | H26: =$S5 -> 0 | I26: =$T5 -> 0 | J26: =$D$9 -> 27.46 | R26: =Elec_Est!R130 -> 0 | T26: =Elec_Est!T130 -> 0
A27: =IF($F27=0,"",($F27/$C6)-($R27*$S6+$T27*$T6)) | B27: =IF(F27=0,"",IF(R27=0,"A) "&"---, "&ROUND(($F27/$C6-($R27*$S6))/$T27,2),IF(T27=0,"A) "&ROUND(($F27/$C6)/$R27,2),"A) "&ROUND(($F27/$C6-($T27*$T6))/$R27,2)&", " &ROUND(($F27/$C6-($R27*$S6))/$T27,2)))) | D27: =IF($F6="","",$F6) | E27: =F27*(1-Q27) -> 0 | F27: =Elec_Est!F131 -> 0 | G27: =C6 -> 1 | H27: =$S6 -> 0 | I27: =$T6 -> 0 | J27: =$D$9 -> 27.46 | R27: =Elec_Est!R131 -> 0 | T27: =Elec_Est!T131 -> 0
A28: =IF($F28=0,"",($F28/$C7)-($R28*$S7+$T28*$T7)) | B28: =IF(F28=0,"",IF(R28=0,"A) "&"---, "&ROUND(($F28/$C7-($R28*$S7))/$T28,2),IF(T28=0,"A) "&ROUND(($F28/$C7)/$R28,2),"A) "&ROUND(($F28/$C7-($T28*$T7))/$R28,2)&", " &ROUND(($F28/$C7-($R28*$S7))/$T28,2)))) | D28: =IF($F7="","",$F7) | E28: =F28*(1-Q28) -> 0 | F28: =Elec_Est!F132 -> 0 | G28: =C7 -> 1 | H28: =$S7 -> 0 | I28: =$T7 -> 0 | J28: =$D$9 -> 27.46 | R28: =Elec_Est!R132 -> 0 | T28: =Elec_Est!T132 -> 0
A29: =IF($F29=0,"",($F29/$C8)-($R29*$S8+$T29*$T8)) | B29: =IF(F29=0,"",IF(R29=0,"A) "&"---, "&ROUND(($F29/$C8-($R29*$S8))/$T29,2),IF(T29=0,"A) "&ROUND(($F29/$C8)/$R29,2),"A) "&ROUND(($F29/$C8-($T29*$T8))/$R29,2)&", " &ROUND(($F29/$C8-($R29*$S8))/$T29,2)))) | D29: =IF($F8="","",$F8) | E29: =F29*(1-Q29) -> 0 | F29: =Elec_Est!F133 -> 0 | G29: =C8 -> 1 | H29: =$S8 -> 0 | I29: =$T8 -> 0 | J29: =$D$9 -> 27.46 | R29: =Elec_Est!R133 -> 0 | T29: =Elec_Est!T133 -> 0
A30: =IF($F30=0,"",($F30/$C9)-($R30*$S9+$T30*$T9)) | B30: =IF(F30=0,"",IF(R30=0,"A) "&"---, "&ROUND(($F30/$C9-($R30*$S9))/$T30,2),IF(T30=0,"A) "&ROUND(($F30/$C9)/$R30,2),"A) "&ROUND(($F30/$C9-($T30*$T9))/$R30,2)&", " &ROUND(($F30/$C9-($R30*$S9))/$T30,2)))) | D30: =IF($F9="","",$F9) | E30: =F30*(1-Q30) -> 0 | F30: =Elec_Est!F134 -> 0 | G30: =C9 -> 1 | H30: =$S9 -> 0 | I30: =$T9 -> 0 | J30: =$D$9 -> 27.46 | R30: =Elec_Est!R134 -> 0 | T30: =Elec_Est!T134 -> 0
A31: =IF($F31=0,"",($F31/$C10)-($R31*$S10+$T31*$T10)) | B31: =IF(F31=0,"",IF(R31=0,"A) "&"---, "&ROUND(($F31/$C10-($R31*$S10))/$T31,2),IF(T31=0,"A) "&ROUND(($F31/$C10)/$R31,2),"A) "&ROUND(($F31/$C10-($T31*$T10))/$R31,2)&", " &ROUND(($F31/$C10-($R31*$S10))/$T31,2)))) | D31: =IF($F10="","",$F10) | E31: =F31*(1-Q31) -> 0 | F31: =Elec_Est!F135 -> 0 | G31: =C10 -> 1 | H31: =$S10 -> 0 | I31: =$T10 -> 0 | J31: =$D$9 -> 27.46 | R31: =Elec_Est!R135 -> 0 | T31: =Elec_Est!T135 -> 0
A32: =IF($F32=0,"",($F32/$C11)-($R32*$S11+$T32*$T11)) | B32: =IF(F32=0,"",IF(R32=0,"A) "&"---, "&ROUND(($F32/$C11-($R32*$S11))/$T32,2),IF(T32=0,"A) "&ROUND(($F32/$C11)/$R32,2),"A) "&ROUND(($F32/$C11-($T32*$T11))/$R32,2)&", " &ROUND(($F32/$C11-($R32*$S11))/$T32,2)))) | D32: =IF($F11="","",$F11) | E32: =F32*(1-Q32) -> 0 | F32: =Elec_Est!F136 -> 0 | G32: =C11 -> 1 | H32: =$S11 -> 0 | I32: =$T11 -> 0 | J32: =$D$9 -> 27.46 | R32: =Elec_Est!R136 -> 0 | T32: =Elec_Est!T136 -> 0
C33: MIXED
A35: Discy.L | B35: =E_BOQ!F51 -> 7433.1 | E35: =SUM(E23:E32) -> 7433.1 | F35: =SUM(F23:F32) -> 7433.1 | R35: =SUM(R23:R32) -> 4954.73 | T35: =SUM(T23:T32) -> 90.254065
A36: =IF(A39=0,"0.00",A39-(A38*A37)) -> 0.00 | B36: BOQ TOTAL | E36: ="ESTIM TOTAL (" & $Q$1 & ")" -> ESTIM TOTAL (€)
A37: 1.125 | B37: <1 Actual LabCont | R37: =R165 -> 4954.7482 | S37: C.C.Totals | T37: =T165 -> 90.245065
B38: <2 Phrs @ 1.00
B39: <3 Phrs @ Actual | Q39: Discy.T >> | R39: =R37-R35 -> 0.01819 | S39: PRINT | T39: =T37-T35 -> -0.009
B41: Values Only on : | D41: 45902 | E41: 3567.42 | F41: 3567.42 | R41: 1731.79 | T41: 66.847
A46: REMARKS:
A47: 1) VAT and Duties as above.
...

Sheet Elec_Rates
B1: CLIENT: | C1: =ML_Sum!$C1 -> 1 | D1: =ML_Sum!$D1 -> ST Microelectronics (Malta) Ltd. | F1: =ML_Sum!$F1 -> 0 | I1: 1 | J1: =ML_Sum!$J1 -> 1 | K1: =ML_Sum!$K1 -> 1 | L1: =ML_Sum!$L1 -> 1 | M1: =ML_Sum!$M1 -> 1 | N1: =ML_Sum!$N1 -> 1 | O1: =ML_Sum!$O1 -> 1 | Q1: =ML_Sum!$Q1 -> € | R1: R/Lab Cont | S1: =ML_Sum!$S1 -> R | T1: =ML_Sum!$T1 -> 1.15 | U1: =ML_Sum!W1 -> BOQ | V1: INCL | W1: MULT | X1: AREA | Y1: BOQ | Z1: TDWG | AA1: ACT | AB1: DIFF
B2: PROJECT: | C2: =ML_Sum!$C2 -> 1 | D2: =ML_Sum!$D2 -> KK2 General Exhaust Replacement | F2: =ML_Sum!$F2 -> Electrical | I2: 2 | J2: =ML_Sum!$J2 -> 1 | K2: =ML_Sum!$K2 -> 1 | L2: =ML_Sum!$L2 -> 1 | M2: =ML_Sum!$M2 -> 1 | N2: =ML_Sum!$N2 -> 1 | O2: =ML_Sum!$O2 -> 1 | Q2: =ML_Sum!$Q2 -> 0 | R2: mu_A | S2: =ML_Sum!$S2 -> 1 | T2: =ML_Sum!$T2 -> 27.46
B3: JOB DESC: | C3: =ML_Sum!$C3 -> 1 | D3: =ML_Sum!$D3 -> Electrical Supply and Installation | F3: =ML_Sum!$F3 -> Controls | I3: 3 | J3: =ML_Sum!$J3 -> 1 | K3: =ML_Sum!$K3 -> 1 | L3: =ML_Sum!$L3 -> 1 | M3: =ML_Sum!$M3 -> 1 | N3: =ML_Sum!$N3 -> 1 | O3: =ML_Sum!$O3 -> 1 | Q3: =ML_Sum!$Q3 -> 0 | R3: mu_B | S3: =ML_Sum!$S3 -> 1 | T3: =ML_Sum!$T3 -> 27.46
B4: QUOTE No: | C4: =ML_Sum!$C4 -> 1 | D4: =ML_Sum!$D4 -> ELM25-0560 | F4: =ML_Sum!$F4 -> Controls | I4: 4 | J4: =ML_Sum!$J4 -> 1 | K4: =ML_Sum!$K4 -> 1 | L4: =ML_Sum!$L4 -> 1 | M4: =ML_Sum!$M4 -> 1 | N4: =ML_Sum!$N4 -> 1 | O4: =ML_Sum!$O4 -> 1 | Q4: =ML_Sum!$Q4 -> 0 | R4: mu_C | S4: =ML_Sum!$S4 -> 1 | T4: =ML_Sum!$T4 -> 27.46
B5: CLIENTs REF: | C5: =ML_Sum!$C5 -> 1 | D5: =ML_Sum!$D5 -> Tender | F5: =ML_Sum!$F5 -> 0 | I5: 5 | J5: =ML_Sum!$J5 -> 1 | K5: =ML_Sum!$K5 -> 1 | L5: =ML_Sum!$L5 -> 1 | M5: =ML_Sum!$M5 -> 1 | N5: =ML_Sum!$N5 -> 1 | O5: =ML_Sum!$O5 -> 1 | Q5: =ML_Sum!$Q5 -> 0 | R5: mu_D | S5: =ML_Sum!$S5 -> 0 | T5: =ML_Sum!$T5 -> 0
B6: VAT/DUTIES: | C6: =ML_Sum!$C6 -> 1 | D6: =ML_Sum!$D6 -> VAT EXCL. | F6: =ML_Sum!$F6 -> 0 | I6: 6 | J6: =ML_Sum!$J6 -> 1 | K6: =ML_Sum!$K6 -> 1 | L6: =ML_Sum!$L6 -> 1 | M6: =ML_Sum!$M6 -> 1 | N6: =ML_Sum!$N6 -> 1 | O6: =ML_Sum!$O6 -> 1 | Q6: =ML_Sum!$Q6 -> 0 | R6: mu_E | S6: =ML_Sum!$S6 -> 0 | T6: =ML_Sum!$T6 -> 0
B7: SAVED ON: | C7: =ML_Sum!$C7 -> 1 | D7: 39364 | F7: =ML_Sum!$F7 -> 0 | I7: 7 | J7: =ML_Sum!$J7 -> 1 | K7: =ML_Sum!$K7 -> 1 | L7: =ML_Sum!$L7 -> 1 | M7: =ML_Sum!$M7 -> 1 | N7: =ML_Sum!$N7 -> 1 | O7: =ML_Sum!$O7 -> 0 | Q7: =ML_Sum!$Q7 -> 0 | R7: mu_F | S7: =ML_Sum!$S7 -> 0 | T7: =ML_Sum!$T7 -> 0
B8: ESTIMATOR: | C8: =ML_Sum!$C8 -> 1 | D8: =ML_Sum!$D8 -> Umut Kaymak | F8: =ML_Sum!$F8 -> 0 | I8: 8 | J8: =ML_Sum!$J8 -> 1 | K8: =ML_Sum!$K8 -> 1 | L8: =ML_Sum!$L8 -> 1 | M8: =ML_Sum!$M8 -> 1 | N8: =ML_Sum!$N8 -> 1 | O8: =ML_Sum!$O8 -> 0 | Q8: =ML_Sum!$Q8 -> 0 | R8: mu_G | S8: =ML_Sum!$S8 -> 0 | T8: =ML_Sum!$T8 -> 0
B9: LABOUR RATE: | C9: =ML_Sum!$C9 -> 1 | D9: =ML_Sum!$D9 -> 27.46 | F9: =ML_Sum!$F9 -> 0 | I9: 9 | J9: =ML_Sum!$J9 -> 1 | K9: =ML_Sum!$K9 -> 1 | L9: =ML_Sum!$L9 -> 1 | M9: =ML_Sum!$M9 -> 1 | N9: =ML_Sum!$N9 -> 1 | O9: =ML_Sum!$O9 -> 0 | Q9: =ML_Sum!$Q9 -> 0 | R9: mu_H | S9: =ML_Sum!$S9 -> 0 | T9: =ML_Sum!$T9 -> 0
C10: =ML_Sum!$C10 -> 1 | F10: =ML_Sum!$F10 -> 0 | I10: 10 | J10: =ML_Sum!$J10 -> 1 | K10: =ML_Sum!$K10 -> 1 | L10: =ML_Sum!$L10 -> 1 | M10: =ML_Sum!$M10 -> 1 | N10: =ML_Sum!$N10 -> 1 | O10: =ML_Sum!$O10 -> 1 | Q10: =ML_Sum!$Q10 -> 0 | R10: mu_I | S10: =ML_Sum!$S10 -> 0 | T10: =ML_Sum!$T10 -> 0
C11: =ML_Sum!$C11 -> 1 | F11: =ML_Sum!$F11 -> 0 | Q11: =ML_Sum!$Q11 -> 0 | R11: mu_J | S11: =ML_Sum!$S11 -> 0 | T11: =ML_Sum!$T11 -> 0
C12: =ML_Sum!$C12 -> 1 | F12: =ML_Sum!$F12 -> 0 | Q12: =ML_Sum!$Q12 -> 0 | R12: MIXED | S12: =ML_Sum!$S12 -> MAT MU | T12: =ML_Sum!$T12 -> LAB RATE
G13: I_CODE | H13: C_CODE | I13: MAKE | J13: PART_NO | K13: MARKUP | L13: TYPE | M13: LIST_P | N13: P_FACT | O13: FIX | P13: DATE | Q13: %Dsct in BOQ | R13: MU TYPE | S13: MAT MU | T13: LAB RATE
C15: t | D15: Item:
D16: Start Typing Header
Q18: Multip
A19: 1850 | B19: =Elec_Est!B212 -> 0 | D19: 001# 1c x 240sqmm FG160M1 cables | K19: RATE | L19: RATE | Q19: =B19/A19 -> 0 | R19: =IF($B19=0,0,IF($S$1="R",ROUND(R24/$B19,2),R24/$B19)) -> 0 | T19: =IF($B19=0,0,IF($S$1="R",ROUND(T24/$B19,2),T24/$B19)) -> 0
D20: Based on:
D21: 1c x 240sqmm FG160M1 XLPE/LSZH cables from KK2A S/S to Chiller 3 (Quantity 9 cables)
D22: Labour for connecting up in existing switchboards and Chillers
C23: << ==== TOTAL UNITS | R23: =$A23*Q23 -> 0 | T23: =$A23*S23*$T$1 -> 0
A24: d> | B24: =(R24+T24)-SUM(R20:R23,T20:T23) -> 0 | D24: Sell_A | E24: =IF($B19=0,0,ROUND(ROUND(($R24*$S$2+($T24*$T$2))/$B19, 2)*$C$2,2)) -> 0 | F24: =ROUND($B19*$E24,2) -> 0 | K24: ITEM | L24: ITEM | R24: =SUM(R20:R23) -> 0 | T24: =SUM(T20:T23) -> 0
Q25: Multip
A26: 150 | B26: =Elec_Est!B213 -> 6 | D26: 002# 200mm galvanised steel cable tray complete with cover | K26: RATE | L26: RATE | Q26: =B26/A26 -> 0.04 | R26: =IF($B26=0,0,IF($S$1="R",ROUND(R39/$B26,2),R39/$B26)) -> 69.42 | T26: =IF($B26=0,0,IF($S$1="R",ROUND(T39/$B26,2),T39/$B26)) -> 0.79
D27: Based on:
A28: =$Q$26 *(150) -> 6 | B28: m | D28: 200x50mm Tray | F28: Cleveland | G28: TRGV_009 | H28: 650 | I28: (__) | O28: 1 | P28: 36897 | Q28: =1.477*32.11/3 -> 15.808823 | R28: =$A28*Q28 -> 94.85294 | S28: 0.3 | T28: =$A28*S28*$T$1 -> 2.07
A29: =$Q$26 *(150) -> 6 | B29: m | D29: Tray 200mm Galv. Cover | F29: Cleveland | G29: TRGV_057 | H29: 650 | I29: (__) | O29: 1 | Q29: =1.477*48.6/3 -> 23.9274 | R29: =$A29*Q29 -> 143.5644 | S29: 0.3 | T29: =$A29*S29*$T$1 -> 2.07
A30: =$Q$26 *(150*2) -> 12 | B30: m | D30: Tray 200mm Galv. Cover clamp | F30: Cleveland | G30: TRGV_057 | H30: 650 | I30: (__) | O30: 1 | Q30: =1.477*2.2 -> 3.2494 | R30: =$A30*Q30 -> 38.9928 | T30: =$A30*S30*$T$1 -> 0
A31: =$Q$26 *(150/3) -> 2 | B31: No. | D31: 200x50mm Tray Coupler | F31: Cleveland | H31: 650 | Q31: =1.477*2.48 -> 3.66296 | R31: =$A31*Q31 -> 7.32592 | S31: 0.02 | T31: =$A31*S31*$T$1 -> 0.046
A32: =$Q$26 *(15) -> 0.6 | B32: m | D32: FLAT BEND | F32: Cleveland | G32: TRGV_057 | H32: 650 | I32: (__) | O32: 1 | Q32: =1.477*26.65 -> 39.36205 | R32: =$A32*Q32 -> 23.61723 | S32: 0.3 | T32: =$A32*S32*$T$1 -> 0.207
A33: 1 | B33: m | D33: EXTERNAL RISER BEND | F33: Cleveland | G33: TRGV_057 | H33: 650 | I33: (__) | O33: 1 | Q33: =1.477*14.91 -> 22.02207 | R33: =$A33*Q33 -> 22.02207 | T33: =$A33*S33*$T$1 -> 0
A34: 1 | B34: m | D34: TEE | F34: Cleveland | G34: TRGV_057 | H34: 650 | I34: (__) | O34: 1 | Q34: =1.477*35.79 -> 52.86183 | R34: =$A34*Q34 -> 52.86183 | S34: 0.3 | T34: =$A34*S34*$T$1 -> 0.345
A35: =$Q$26 *(150/3) -> 2 | B35: No. | D35: Tray Earth Links | F35: Not quoted by Legrand | H35: 650 | Q35: 1.596 | R35: =$A35*Q35 -> 3.192 | S35: 0.01 | T35: =$A35*S35*$T$1 -> 0.023
A36: =$Q$26 *(150*8) -> 48 | B36: No. | D36: Tray Coupling Bolts | F36: Legrand - ESS | H36: 650 | Q36: 0.21 | R36: =$A36*Q36 -> 10.08 | T36: =$A36*S36*$T$1 -> 0
A37: =$Q$26 *(1) -> 0.04 | B37: LS | D37: SUBCONTRACTING WORKS | F37: Crane to carry the materials to the roof | G37: SUBC_001 | H37: 960 | I37: MISC | O37: 4 | P37: 38274 | Q37: 500 | R37: =$A37*Q37 -> 20 | T37: =$A37*S37*$T$1 -> 0
C38: << ==== TOTAL UNITS | R38: =$A38*Q38 -> 0 | T38: =$A38*S38*$T$1 -> 0
A39: d> | B39: =(R38+T38) -> 0 | D39: Sell_A | E39: =IF($B26=0,0,ROUND(ROUND(($R39*$S$2+($T39*$T$2))/$B26, 2)*$C$2,2)) -> 91.21 | F39: =ROUND($B26*$E39,2) -> 547.26 | K39: ITEM | L39: ITEM | R39: =SUM(R27:R38) -> 416.50919 | T39: =SUM(T27:T38) -> 4.761
Q40: Multip
A41: 150 | B41: =Elec_Est!B214 -> 6 | D41: 003# Cable Containment Support | K41: RATE | L41: RATE | Q41: =B41/A41 -> 0.04 | R41: =IF($B41=0,0,IF($S$1="R",ROUND(R108/$B41,2),R108/$B41)) -> 71.41 | T41: =IF($B41=0,0,IF($S$1="R",ROUND(T108/$B41,2),T108/$B41)) -> 0.58
D42: Based on: brackets spaced at metres intervals
...

Sheet Elec_Est
B1: CLIENT: | C1: =ML_Sum!$C1 -> 1 | D1: =ML_Sum!$D1 -> ST Microelectronics (Malta) Ltd. | F1: =ML_Sum!$F1 -> 0 | I1: 1 | J1: =ML_Sum!$J1 -> 1 | K1: =ML_Sum!$K1 -> 1 | L1: =ML_Sum!$L1 -> 1 | M1: =ML_Sum!$M1 -> 1 | N1: =ML_Sum!$N1 -> 1 | O1: =ML_Sum!$O1 -> 1 | Q1: =ML_Sum!$Q1 -> € | R1: R/Lab Cont | S1: =ML_Sum!$S1 -> R | T1: =ML_Sum!$T1 -> 1.15 | U1: =ML_Sum!W1 -> BOQ | V1: INCL | W1: MULT | X1: AREA | Y1: BOQ | Z1: TDWG | AA1: ACT | AB1: DIFF
B2: PROJECT: | C2: =ML_Sum!$C2 -> 1 | D2: =ML_Sum!$D2 -> KK2 General Exhaust Replacement | F2: =ML_Sum!$F2 -> Electrical | I2: 2 | J2: =ML_Sum!$J2 -> 1 | K2: =ML_Sum!$K2 -> 1 | L2: =ML_Sum!$L2 -> 1 | M2: =ML_Sum!$M2 -> 1 | N2: =ML_Sum!$N2 -> 1 | O2: =ML_Sum!$O2 -> 1 | Q2: =ML_Sum!$Q2 -> 0 | R2: mu_A | S2: =ML_Sum!$S2 -> 1 | T2: =ML_Sum!$T2 -> 27.46
B3: JOB DESC: | C3: =ML_Sum!$C3 -> 1 | D3: =ML_Sum!$D3 -> Electrical Supply and Installation | F3: =ML_Sum!$F3 -> Controls | I3: 3 | J3: =ML_Sum!$J3 -> 1 | K3: =ML_Sum!$K3 -> 1 | L3: =ML_Sum!$L3 -> 1 | M3: =ML_Sum!$M3 -> 1 | N3: =ML_Sum!$N3 -> 1 | O3: =ML_Sum!$O3 -> 1 | Q3: =ML_Sum!$Q3 -> 0 | R3: mu_B | S3: =ML_Sum!$S3 -> 1 | T3: =ML_Sum!$T3 -> 27.46
B4: QUOTE No: | C4: =ML_Sum!$C4 -> 1 | D4: =ML_Sum!$D4 -> ELM25-0560 | F4: =ML_Sum!$F4 -> Controls | I4: 4 | J4: =ML_Sum!$J4 -> 1 | K4: =ML_Sum!$K4 -> 1 | L4: =ML_Sum!$L4 -> 1 | M4: =ML_Sum!$M4 -> 1 | N4: =ML_Sum!$N4 -> 1 | O4: =ML_Sum!$O4 -> 1 | Q4: =ML_Sum!$Q4 -> 0 | R4: mu_C | S4: =ML_Sum!$S4 -> 1 | T4: =ML_Sum!$T4 -> 27.46
B5: CLIENTs REF: | C5: =ML_Sum!$C5 -> 1 | D5: =ML_Sum!$D5 -> Tender | F5: =ML_Sum!$F5 -> 0 | I5: 5 | J5: =ML_Sum!$J5 -> 1 | K5: =ML_Sum!$K5 -> 1 | L5: =ML_Sum!$L5 -> 1 | M5: =ML_Sum!$M5 -> 1 | N5: =ML_Sum!$N5 -> 1 | O5: =ML_Sum!$O5 -> 1 | Q5: =ML_Sum!$Q5 -> 0 | R5: mu_D | S5: =ML_Sum!$S5 -> 0 | T5: =ML_Sum!$T5 -> 0
B6: VAT/DUTIES: | C6: =ML_Sum!$C6 -> 1 | D6: =ML_Sum!$D6 -> VAT EXCL. | F6: =ML_Sum!$F6 -> 0 | I6: 6 | J6: =ML_Sum!$J6 -> 1 | K6: =ML_Sum!$K6 -> 1 | L6: =ML_Sum!$L6 -> 1 | M6: =ML_Sum!$M6 -> 1 | N6: =ML_Sum!$N6 -> 1 | O6: =ML_Sum!$O6 -> 1 | Q6: =ML_Sum!$Q6 -> 0 | R6: mu_E | S6: =ML_Sum!$S6 -> 0 | T6: =ML_Sum!$T6 -> 0
B7: SAVED ON: | C7: =ML_Sum!$C7 -> 1 | D7: 39364 | F7: =ML_Sum!$F7 -> 0 | I7: 7 | J7: =ML_Sum!$J7 -> 1 | K7: =ML_Sum!$K7 -> 1 | L7: =ML_Sum!$L7 -> 1 | M7: =ML_Sum!$M7 -> 1 | N7: =ML_Sum!$N7 -> 1 | O7: =ML_Sum!$O7 -> 0 | Q7: =ML_Sum!$Q7 -> 0 | R7: mu_F | S7: =ML_Sum!$S7 -> 0 | T7: =ML_Sum!$T7 -> 0
B8: ESTIMATOR: | C8: =ML_Sum!$C8 -> 1 | D8: =ML_Sum!$D8 -> Umut Kaymak | F8: =ML_Sum!$F8 -> 0 | I8: 8 | J8: =ML_Sum!$J8 -> 1 | K8: =ML_Sum!$K8 -> 1 | L8: =ML_Sum!$L8 -> 1 | M8: =ML_Sum!$M8 -> 1 | N8: =ML_Sum!$N8 -> 1 | O8: =ML_Sum!$O8 -> 0 | Q8: =ML_Sum!$Q8 -> 0 | R8: mu_G | S8: =ML_Sum!$S8 -> 0 | T8: =ML_Sum!$T8 -> 0
B9: LABOUR RATE: | C9: =ML_Sum!$C9 -> 1 | D9: =ML_Sum!$D9 -> 27.46 | F9: =ML_Sum!$F9 -> 0 | I9: 9 | J9: =ML_Sum!$J9 -> 1 | K9: =ML_Sum!$K9 -> 1 | L9: =ML_Sum!$L9 -> 1 | M9: =ML_Sum!$M9 -> 1 | N9: =ML_Sum!$N9 -> 1 | O9: =ML_Sum!$O9 -> 0 | Q9: =ML_Sum!$Q9 -> 0 | R9: mu_H | S9: =ML_Sum!$S9 -> 0 | T9: =ML_Sum!$T9 -> 0
C10: =ML_Sum!$C10 -> 1 | F10: =ML_Sum!$F10 -> 0 | I10: 10 | J10: =ML_Sum!$J10 -> 1 | K10: =ML_Sum!$K10 -> 1 | L10: =ML_Sum!$L10 -> 1 | M10: =ML_Sum!$M10 -> 1 | N10: =ML_Sum!$N10 -> 1 | O10: =ML_Sum!$O10 -> 1 | Q10: =ML_Sum!$Q10 -> 0 | R10: mu_I | S10: =ML_Sum!$S10 -> 0 | T10: =ML_Sum!$T10 -> 0
C11: =ML_Sum!$C11 -> 1 | F11: =ML_Sum!$F11 -> 0 | Q11: =ML_Sum!$Q11 -> 0 | R11: mu_J | S11: =ML_Sum!$S11 -> 0 | T11: =ML_Sum!$T11 -> 0
C12: =ML_Sum!$C12 -> 1 | F12: =ML_Sum!$F12 -> 0 | Q12: =ML_Sum!$Q12 -> 0 | R12: MIXED | S12: =ML_Sum!$S12 -> MAT MU | T12: =ML_Sum!$T12 -> LAB RATE
G13: ISELL | H13: C_CODE | I13: MAKE | J13: PART_NO | K13: MARKUP | L13: TYPE | M13: LIST_P | N13: P_FACT | O13: FIX | P13: DATE | Q13: %Dsct in BOQ | R13: MU TYPE | S13: MAT MU | T13: LAB RATE | AM13: Tot Mat Cost | AN13: Unit Lab phr. | AO13: Tot Lab phr. | AP13: < for ELM / MEE
K14: TB
C15: t | D15: Item:
D16: Electrical For Mechanical Works,
E18: Sell Rate | F18: Sell Total | K18: IB | AG18: U_M_Sell | AH18: T_M_Sell | AI18: U_L_Sell | AJ18: T_L_Sell | AK18: Total_Sell | AM18: T_M_Cost | AN18: T_L_Phr | AO18: Mat/Lab=1
A19: 1 | B19: L/S | D19: Item: 1.01 | E19: =IF(AND($A19=0,$A$1="DIF"),0, ROUND(ROUND(($R23*$S$2+($T23*$T$2))/A19,2)*$C$2,2)) -> 126.32 | F19: =ROUND($A19*$E19,2) -> 126.32 | G19: ISELL | K19: mu_A | L19: ITEM | T19: =IF(AND($R23=0,$T23=0),"0.00","mu :" & ROUND($F19/$C$2/($R23+$T23*$D$9),2)) -> mu :1 | AG19: =IF($E19=0,0,ROUND($R23*$S$2*$C$2/$A19,2)) -> 0 | AH19: =$AG19*$A19 -> 0 | AI19: =$E19-$AG19 -> 126.32 | AJ19: =$A19*$AI19 -> 126.32 | AK19: =ROUND(($AG19+$AI19)*$A19,2) -> 126.32 | AM19: =ROUND(R23,2) -> 0 | AN19: =ROUND(T23,2) -> 4.6 | AO19: =ROUND(AM19+AN19,2)*A19 -> 4.6
D20: Dismantling the Old AHU
A21: 1 | B21: LS | D21: LABOUR ONLY | G21: LABO_001 | H21: 900 | I21: MISC | O21: 1 | Q21: 0 | R21: =$A21*Q21 -> 0 | S21: 4 | T21: =$A21*S21*$T$1 -> 4.6
R22: =$A22*Q22 -> 0 | T22: =$A22*S22*$T$1 -> 0
A23: d> | B23: =(R22+T22) -> 0 | G23: ICOST | K23: mu_A | L23: ITEM | R23: =SUM(R20:R22) -> 0 | T23: =SUM(T20:T22) -> 4.6
E24: Sell Rate | F24: Sell Total | K24: IB | AG24: U_M_Sell | AH24: T_M_Sell | AI24: U_L_Sell | AJ24: T_L_Sell | AK24: Total_Sell | AM24: T_M_Cost | AN24: T_L_Phr | AO24: Mat/Lab=1
A25: 2 | B25: No | D25: Item: 1.02 | E25: =IF(AND($A25=0,$A$1="DIF"),0, ROUND(ROUND(($R36*$S$2+($T36*$T$2))/A25,2)*$C$2,2)) -> 803.68 | F25: =ROUND($A25*$E25,2) -> 1607.36 | G25: ISELL | K25: mu_A | L25: ITEM | T25: =IF(AND($R36=0,$T36=0),"0.00","mu :" & ROUND($F25/$C$2/($R36+$T36*$D$9),2)) -> mu :1 | AG25: =IF($E25=0,0,ROUND($R36*$S$2*$C$2/$A25,2)) -> 572.4 | AH25: =$AG25*$A25 -> 1144.8 | AI25: =$E25-$AG25 -> 231.28 | AJ25: =$A25*$AI25 -> 462.56 | AK25: =ROUND(($AG25+$AI25)*$A25,2) -> 1607.36 | AM25: =ROUND(R36,2) -> 1144.8 | AN25: =ROUND(T36,2) -> 16.85 | AO25: =ROUND(AM25+AN25,2)*A25 -> 2323.3
D26: Electrical Power for Air Conditioning Outdoor Units including connecting Up of Outdoor units
A27: 40 | B27: m | D27: 5c6.0mm FG16OR LSF Grey | F27: AJ | G27: CAMC_092 | H27: 616 | I27: (__) | J27: 6.0mm2 | K27: 05-004 | O27: 2 | P27: 38847 | Q27: 4.1 | R27: =$A27*Q27 -> 164 | S27: 0.05 | T27: =$A27*S27*$T$1 -> 2.3
A28: 2 | B28: No | D28: Surface Isolator 32A 4-Pole | F28: AJ | G28: SWLV_177 | H28: 510 | I28: KM | J28: P3-63/I/N | K28: 10 | O28: 2 | P28: 36880 | Q28: 47.67 | R28: =$A28*Q28 -> 95.34 | S28: 0.75 | T28: =$A28*S28*$T$1 -> 1.725
A29: 8 | B29: No | D29: Gland Indoor 20 BWL 4*4/6mm2 | G29: CAAC_040 | H29: 620 | I29: CMP | O29: 2 | P29: 35431 | Q29: 4.71 | R29: =$A29*Q29 -> 37.68 | S29: 0.35 | T29: =$A29*S29*$T$1 -> 3.22
A30: 40 | B30: No | D30: Cable Lug 6.0 mm2 | G30: CAAC_007 | H30: 620 | I30: CTT | O30: 2 | P30: 34669 | Q30: 0.07 | R30: =$A30*Q30 -> 2.8 | S30: 0.03 | T30: =$A30*S30*$T$1 -> 1.38
C31: h | D31: =CELL("Address",Elec_Rates!D$41) -> [ELM25_0560_ST_Electronics_Exhaust_Replacement_Est_.xlsx]Elec_Rates!$D$41 | G31: RATE_AAA
A32: 6 | B32: 1 | C32: =$A32*$B32 -> 6 | D32: =Elec_Rates!$D$41 -> 003# Cable Containment Support | E32: 100mm cable tray | F32: Local Rate | G32: RTLO_002 | Q32: =$B32*Elec_Rates!$R$41 -> 71.41 | R32: =$A32*Q32 -> 428.46 | S32: =$B32*Elec_Rates!$T$41 -> 0.58 | T32: =$A32*S32 -> 3.48
C33: h | D33: =CELL("Address",Elec_Rates!D$26) -> [ELM25_0560_ST_Electronics_Exhaust_Replacement_Est_.xlsx]Elec_Rates!$D$26 | G33: RATE_AAA
A34: 6 | B34: 1 | C34: =$A34*$B34 -> 6 | D34: =Elec_Rates!$D$26 -> 002# 200mm galvanised steel cable tray complete with cover | F34: Local Rate | G34: RTLO_002 | Q34: =$B34*Elec_Rates!$R$26 -> 69.42 | R34: =$A34*Q34 -> 416.52 | S34: =$B34*Elec_Rates!$T$26 -> 0.79 | T34: =$A34*S34 -> 4.74
R35: =$A35*Q35 -> 0 | T35: =$A35*S35*$T$1 -> 0
A36: d> | B36: =(R35+T35) -> 0 | G36: ICOST | K36: mu_A | L36: ITEM | R36: =SUM(R26:R35) -> 1144.8 | T36: =SUM(T26:T35) -> 16.845
E37: Sell Rate | F37: Sell Total | K37: IB | AG37: U_M_Sell | AH37: T_M_Sell | AI37: U_L_Sell | AJ37: T_L_Sell | AK37: Total_Sell | AM37: T_M_Cost | AN37: T_L_Phr | AO37: Mat/Lab=1
A38: 2 | B38: No | D38: Item: 1.03 | E38: =IF(AND($A38=0,$A$1="DIF"),0, ROUND(ROUND(($R46*$S$2+($T46*$T$2))/A38,2)*$C$2,2)) -> 196.27 | F38: =ROUND($A38*$E38,2) -> 392.54 | G38: ISELL | K38: mu_A | L38: ITEM | T38: =IF(AND($R46=0,$T46=0),"0.00","mu :" & ROUND($F38/$C$2/($R46+$T46*$D$9),2)) -> mu :1 | AG38: =IF($E38=0,0,ROUND($R46*$S$2*$C$2/$A38,2)) -> 81.32 | AH38: =$AG38*$A38 -> 162.64 | AI38: =$E38-$AG38 -> 114.95 | AJ38: =$A38*$AI38 -> 229.9 | AK38: =ROUND(($AG38+$AI38)*$A38,2) -> 392.54 | AM38: =ROUND(R46,2) -> 162.64 | AN38: =ROUND(T46,2) -> 8.37 | AO38: =ROUND(AM38+AN38,2)*A38 -> 342.02
D39: Electrical Power for Air Conditioning Indoor Units including connecting Up of Indoor units
A40: 10 | B40: m | D40: Conduit Galv. 25mm RATE | F40: price from quintano | G40: COGV_013 | H40: 690 | I40: BAR | J40: 25mm | O40: 1 | P40: 34669 | Q40: 3.8 | R40: =$A40*Q40 -> 38 | S40: 0.25 | T40: =$A40*S40*$T$1 -> 2.875 | AR40: 75
A41: 30 | B41: m | D41: Wiring Cable 3c 2.5 mm2 PVC Non-Arm | G41: CAMC_049 | H41: 616 | I41: CRO | J41: 2.5mm2 | K41: 03-003 | O41: 2 | P41: 40767 | Q41: 2 | R41: =$A41*Q41 -> 60 | S41: 0.03 | T41: =$A41*S41*$T$1 -> 1.035
...

Sheet E_BOQ
A1: ITEM NO. | B1: DESCRIPTION | C1: QTY | D1: UNIT | E1: RATE | F1: TOTAL | G1: Material Cost | H1: Labour (hrs)
E2: € | F2: € | G2: € | H2: €
A3: =TRIM(MID(Elec_Est!D15,6,30)) | B3: =Elec_Est!D16 -> Electrical For Mechanical Works,
A5: =TRIM(MID(Elec_Est!D19,6,30)) -> 1.01 | B5: =Elec_Est!D20 -> Dismantling the Old AHU | C5: =Elec_Est!A19 -> 1 | D5: =Elec_Est!B19 -> L/S | E5: =Elec_Est!E19 -> 126.32 | F5: =C5*E5 -> 126.32 | G5: =Elec_Est!AM19 -> 0 | H5: =Elec_Est!AN19 -> 4.6
A7: =TRIM(MID(Elec_Est!D25,6,30)) -> 1.02 | B7: =Elec_Est!D26 -> Electrical Power for Air Conditioning Outdoor Units including connecting Up of Outdoor units | C7: =Elec_Est!A25 -> 2 | D7: =Elec_Est!B25 -> No | E7: =Elec_Est!E25 -> 803.68 | F7: =C7*E7 -> 1607.36 | G7: =Elec_Est!AM25 -> 1144.8 | H7: =Elec_Est!AN25 -> 16.85
A9: =TRIM(MID(Elec_Est!D38,6,30)) -> 1.03 | B9: =Elec_Est!D39 -> Electrical Power for Air Conditioning Indoor Units including connecting Up of Indoor units | C9: =Elec_Est!A38 -> 2 | D9: =Elec_Est!B38 -> No | E9: =Elec_Est!E38 -> 196.27 | F9: =C9*E9 -> 392.54 | G9: =Elec_Est!AM38 -> 162.64 | H9: =Elec_Est!AN38 -> 8.37
A11: =TRIM(MID(Elec_Est!D48,6,30)) -> 1.04 | B11: =Elec_Est!D49 -> Flowmeter | C11: =Elec_Est!A48 -> 1 | D11: =Elec_Est!B48 -> No | E11: =Elec_Est!E48 -> 3450.94 | F11: =C11*E11 -> 3450.94 | G11: =Elec_Est!AM48 -> 3010.39 | H11: =Elec_Est!AN48 -> 16.04
A13: =TRIM(MID(Elec_Est!D69,6,30)) -> 1.05 | B13: =Elec_Est!D70 -> Delta Pressure Sensor | C13: =Elec_Est!A69 -> 1 | D13: =Elec_Est!B69 -> No | E13: =Elec_Est!E69 -> 577.92 | F13: =C13*E13 -> 577.92 | G13: =Elec_Est!AM69 -> 249.45 | H13: =Elec_Est!AN69 -> 11.96
A15: =TRIM(MID(Elec_Est!D89,6,30)) -> 1.06 | B15: =Elec_Est!D90 -> Damper | C15: =Elec_Est!A89 -> 2 | D15: =Elec_Est!B89 -> No | E15: =Elec_Est!E89 -> 386.38 | F15: =C15*E15 -> 772.76 | G15: =Elec_Est!AM89 -> 387.45 | H15: =Elec_Est!AN89 -> 14.03
A17: =TRIM(MID(Elec_Est!D109,6,30)) -> 1.07 | B17: =Elec_Est!D110 -> Dismantling the Old Extractors | C17: =Elec_Est!A109 -> 1 | D17: =Elec_Est!B109 -> LS | E17: =Elec_Est!E109 -> 505.26 | F17: =C17*E17 -> 505.26 | G17: =Elec_Est!AM109 -> 0 | H17: =Elec_Est!AN109 -> 18.4
A51: SB | B51: Total - | D51: =[16]ML_Sum!D6 -> VAT EXCL. | E51: € | F51: =SUM(F4:F50) -> 7433.1 | G51: =SUM(G5:G50) -> 4954.73 | H51: =SUM(H5:H50) -> 90.25
