Workbook
Name Access_Bathroom: Fire_Stopping_Est!#REF!
Name Access_Bathroom: Elec_Est!$A$11001
Name Access_Control: Fire_Stopping_Est!#REF!
Name Access_Control: Elec_Est!$A$10069
Name AREAS: ML_Sum!$X$1:$AD$16
Name AREAS: #REF!
Name AREAS: ML_Sum!$X$1:$AD$16
Name CCTV: Fire_Stopping_Est!#REF!
Name CCTV: Elec_Est!$A$9809
Name Data: Fire_Stopping_Est!#REF!
Name Data: Elec_Est!$A$6644
Name Electrical: Fire_Stopping_Est!#REF!
Name Electrical: Elec_Est!$A$131
Name Fire_Alarm: Fire_Stopping_Est!#REF!
Name Fire_Alarm: Elec_Est!$A$8157
Name Fire_Stopping: Fire_Stopping_Est!#REF!
Name Fire_Stopping: Elec_Est!$A$7844
Name FO: #REF!
Name Guard: #REF!
Name Intercom: Fire_Stopping_Est!#REF!
Name Intercom: Elec_Est!$A$10379
Name Intruder_Alarm: #REF!
Name LPS: Elec_Est!$A$7739
Name Preliminaries: Fire_Stopping_Est!#REF!
Name Preliminaries: Elec_Est!$A$16
Name Security: Fire_Stopping_Est!#REF!
Name Security: Elec_Est!$A$10539

Sheet ELV_Fire_Security_BOQ
B2: SECTION 3 - ELV, FIRE AND SECURITY
A4: ITEM | B4: DESCRIPTION | C4: QTY | D4: UNIT | E4: RATE Euro (Exc of VAT) | F4: TOTAL Euro (Exc of VAT)
A5: 1 | B5: PRELIMINARIES
B6: All equipment to be used within this contract is to be approved prior to delivery to site.
A7: =IFERROR(IF(OFFSET(A7,-1,0)>0,OFFSET(A7,-1,0)+0.001,ERROR.TYPE(0)),IFERROR(IF(OFFSET(A7,-2,0)>0,OFFSET(A7,-2,0)+0.001,ERROR.TYPE(0)),IFERROR(IF(OFFSET(A7,-3,0)>0,OFFSET(A7,-3,0)+0.001,ERROR.TYPE(0)),IFERROR(IF(OFFSET(A7,-4,0)>0,OFFSET(A7,-4,0)+0.001,ERROR.TYPE(0)),IFERROR(IF(OFFSET(A7,-5,0)>0,OFFSET(A7,-5,0)+0.001,ERROR.TYPE(0)),IFERROR(IF(OFFSET(A7,-6,0)>0,OFFSET(A7,-6,0)+0.001,ERROR.TYPE(0)),IFERROR(IF(OFFSET(A7,-7,0)>0,OFFSET(A7,-7,0)+0.001,ERROR.TYPE(0)),IFERROR(IF(OFFSET(A7,-8,0)>0,OFFSET(A7,-8,0)+0.001,ERROR.TYPE(0)),IFERROR(IF(OFFSET(A7,-9,0)>0,OFFSET(A7,-9,0)+0.001,ERROR.TYPE(0)),IFERROR(IF(OFFSET(A7,-10,0)>0,OFFSET(A7,-10,0)+0.001,ERROR.TYPE(0)),ERROR.TYPE(0))))))))))) -> 1.001 | B7: Mobilisation of site including the setting up of Storage facilities for materials, Sanitary facilities for the employees, Setting up of temporary site office, etc required to undertake the works | C7: 1 | D7: L.S. | E7: =Elec_Est!Q8014 -> Included with MEP preliminaries
A8: =IFERROR(IF(OFFSET(A8,-1,0)>0,OFFSET(A8,-1,0)+0.001,ERROR.TYPE(0)),IFERROR(IF(OFFSET(A8,-2,0)>0,OFFSET(A8,-2,0)+0.001,ERROR.TYPE(0)),IFERROR(IF(OFFSET(A8,-3,0)>0,OFFSET(A8,-3,0)+0.001,ERROR.TYPE(0)),IFERROR(IF(OFFSET(A8,-4,0)>0,OFFSET(A8,-4,0)+0.001,ERROR.TYPE(0)),IFERROR(IF(OFFSET(A8,-5,0)>0,OFFSET(A8,-5,0)+0.001,ERROR.TYPE(0)),IFERROR(IF(OFFSET(A8,-6,0)>0,OFFSET(A8,-6,0)+0.001,ERROR.TYPE(0)),IFERROR(IF(OFFSET(A8,-7,0)>0,OFFSET(A8,-7,0)+0.001,ERROR.TYPE(0)),IFERROR(IF(OFFSET(A8,-8,0)>0,OFFSET(A8,-8,0)+0.001,ERROR.TYPE(0)),IFERROR(IF(OFFSET(A8,-9,0)>0,OFFSET(A8,-9,0)+0.001,ERROR.TYPE(0)),IFERROR(IF(OFFSET(A8,-10,0)>0,OFFSET(A8,-10,0)+0.001,ERROR.TYPE(0)),ERROR.TYPE(0))))))))))) -> 1.002 | B8: Provision of insurance cover in the joint names of the Client and Contractor insure the Works against loss or damage by fire, storm, tempest, lightning, flood, earthquake, aircraft or anything dropped there from, aerial objects, riot and civil commotion for the full reinstatement value thereof plus 15% of all the Works executed and all unfixed materials and goods so insured until the completion of the Works. The Contractor shall affect a policy of insurance against third party risks to cover an amount of not less than Euro 500,000 (five hundred thousand Euros) for any one accident. The policy shall be in joint names of the Client and Contractor and shall include cross liability clauses. In respect of liability for the death or injury to any person employed by the Contractor and arising out of and in the course of such person's employment by the Contractor the amount insured by the Contractor shall be such as to indemnify the Client against all damages as compensation payable. The Contractor shall comply with and be subject to the terms, exclusions, exceptions, conditions and limitations of the insurance policies and shall bear the amount of the retained liabilities stated therein The Contractor shall deposit with the Client copies of the policy or policies and a copy of the receipt in respect of premiums paid before starting the Works | C8: 1 | D8: L.S. | E8: =Elec_Est!Q8024 -> Included with MEP preliminaries
A9: =IFERROR(IF(OFFSET(A9,-1,0)>0,OFFSET(A9,-1,0)+0.001,ERROR.TYPE(0)),IFERROR(IF(OFFSET(A9,-2,0)>0,OFFSET(A9,-2,0)+0.001,ERROR.TYPE(0)),IFERROR(IF(OFFSET(A9,-3,0)>0,OFFSET(A9,-3,0)+0.001,ERROR.TYPE(0)),IFERROR(IF(OFFSET(A9,-4,0)>0,OFFSET(A9,-4,0)+0.001,ERROR.TYPE(0)),IFERROR(IF(OFFSET(A9,-5,0)>0,OFFSET(A9,-5,0)+0.001,ERROR.TYPE(0)),IFERROR(IF(OFFSET(A9,-6,0)>0,OFFSET(A9,-6,0)+0.001,ERROR.TYPE(0)),IFERROR(IF(OFFSET(A9,-7,0)>0,OFFSET(A9,-7,0)+0.001,ERROR.TYPE(0)),IFERROR(IF(OFFSET(A9,-8,0)>0,OFFSET(A9,-8,0)+0.001,ERROR.TYPE(0)),IFERROR(IF(OFFSET(A9,-9,0)>0,OFFSET(A9,-9,0)+0.001,ERROR.TYPE(0)),IFERROR(IF(OFFSET(A9,-10,0)>0,OFFSET(A9,-10,0)+0.001,ERROR.TYPE(0)),ERROR.TYPE(0))))))))))) -> 1.003 | B9: Implementation of health and safety measures on site including personal safety (e.g safety shoes, helmets scaffolding, harnesses etc) as well as those to render the site safe for employees (e.g staircase handrails, closing of lift shaft openings etc) | C9: 1 | D9: L.S. | E9: =Elec_Est!Q8034 -> Included with MEP preliminaries
A10: =IFERROR(IF(OFFSET(A10,-1,0)>0,OFFSET(A10,-1,0)+0.001,ERROR.TYPE(0)),IFERROR(IF(OFFSET(A10,-2,0)>0,OFFSET(A10,-2,0)+0.001,ERROR.TYPE(0)),IFERROR(IF(OFFSET(A10,-3,0)>0,OFFSET(A10,-3,0)+0.001,ERROR.TYPE(0)),IFERROR(IF(OFFSET(A10,-4,0)>0,OFFSET(A10,-4,0)+0.001,ERROR.TYPE(0)),IFERROR(IF(OFFSET(A10,-5,0)>0,OFFSET(A10,-5,0)+0.001,ERROR.TYPE(0)),IFERROR(IF(OFFSET(A10,-6,0)>0,OFFSET(A10,-6,0)+0.001,ERROR.TYPE(0)),IFERROR(IF(OFFSET(A10,-7,0)>0,OFFSET(A10,-7,0)+0.001,ERROR.TYPE(0)),IFERROR(IF(OFFSET(A10,-8,0)>0,OFFSET(A10,-8,0)+0.001,ERROR.TYPE(0)),IFERROR(IF(OFFSET(A10,-9,0)>0,OFFSET(A10,-9,0)+0.001,ERROR.TYPE(0)),IFERROR(IF(OFFSET(A10,-10,0)>0,OFFSET(A10,-10,0)+0.001,ERROR.TYPE(0)),ERROR.TYPE(0))))))))))) -> 1.004 | B10: Prepare a risk assessment report outlining all risks involved and measures to be taken to minimise or eliminate potential risks. The report is to be prepared and signed by a competent person and to be submitted within three weeks from commencement of works. | C10: 1 | D10: L.S. | E10: =Elec_Est!Q8044 -> Included with MEP preliminaries
A11: =IFERROR(IF(OFFSET(A11,-1,0)>0,OFFSET(A11,-1,0)+0.001,ERROR.TYPE(0)),IFERROR(IF(OFFSET(A11,-2,0)>0,OFFSET(A11,-2,0)+0.001,ERROR.TYPE(0)),IFERROR(IF(OFFSET(A11,-3,0)>0,OFFSET(A11,-3,0)+0.001,ERROR.TYPE(0)),IFERROR(IF(OFFSET(A11,-4,0)>0,OFFSET(A11,-4,0)+0.001,ERROR.TYPE(0)),IFERROR(IF(OFFSET(A11,-5,0)>0,OFFSET(A11,-5,0)+0.001,ERROR.TYPE(0)),IFERROR(IF(OFFSET(A11,-6,0)>0,OFFSET(A11,-6,0)+0.001,ERROR.TYPE(0)),IFERROR(IF(OFFSET(A11,-7,0)>0,OFFSET(A11,-7,0)+0.001,ERROR.TYPE(0)),IFERROR(IF(OFFSET(A11,-8,0)>0,OFFSET(A11,-8,0)+0.001,ERROR.TYPE(0)),IFERROR(IF(OFFSET(A11,-9,0)>0,OFFSET(A11,-9,0)+0.001,ERROR.TYPE(0)),IFERROR(IF(OFFSET(A11,-10,0)>0,OFFSET(A11,-10,0)+0.001,ERROR.TYPE(0)),ERROR.TYPE(0))))))))))) -> 1.005 | B11: Allow for carrying out all surveys, setting out of works unless included elsewhere in the Bills of Quantities. | C11: 1 | D11: L.S. | E11: =Elec_Est!Q8054 -> Included with MEP preliminaries
B12: TOTAL FOR PAGE 01 | C12: Euro Exc VAT | F12: =SUM(F7:F11) -> 0
A15: ITEM | B15: DESCRIPTION | C15: QTY | D15: UNIT | E15: RATE Euro (Exc of VAT) | F15: TOTAL Euro (Exc of VAT)
A16: =IFERROR(IF(OFFSET(A16,-1,0)>0,OFFSET(A16,-1,0)+0.001,ERROR.TYPE(0)),IFERROR(IF(OFFSET(A16,-2,0)>0,OFFSET(A16,-2,0)+0.001,ERROR.TYPE(0)),IFERROR(IF(OFFSET(A16,-3,0)>0,OFFSET(A16,-3,0)+0.001,ERROR.TYPE(0)),IFERROR(IF(OFFSET(A16,-4,0)>0,OFFSET(A16,-4,0)+0.001,ERROR.TYPE(0)),IFERROR(IF(OFFSET(A16,-5,0)>0,OFFSET(A16,-5,0)+0.001,ERROR.TYPE(0)),IFERROR(IF(OFFSET(A16,-6,0)>0,OFFSET(A16,-6,0)+0.001,ERROR.TYPE(0)),IFERROR(IF(OFFSET(A16,-7,0)>0,OFFSET(A16,-7,0)+0.001,ERROR.TYPE(0)),IFERROR(IF(OFFSET(A16,-8,0)>0,OFFSET(A16,-8,0)+0.001,ERROR.TYPE(0)),IFERROR(IF(OFFSET(A16,-9,0)>0,OFFSET(A16,-9,0)+0.001,ERROR.TYPE(0)),IFERROR(IF(OFFSET(A16,-10,0)>0,OFFSET(A16,-10,0)+0.001,ERROR.TYPE(0)),ERROR.TYPE(0))))))))))) -> 1.006 | B16: Provision for attending to site to take all relevant measurements in order to ascertain the exact quantities of the individual and measured items to be procured as well as keeping of all relevant records of personnel attendance, stock control etc | C16: 1 | D16: L.S. | E16: =Elec_Est!Q8064 -> Included with MEP preliminaries
A17: =IFERROR(IF(OFFSET(A17,-1,0)>0,OFFSET(A17,-1,0)+0.001,ERROR.TYPE(0)),IFERROR(IF(OFFSET(A17,-2,0)>0,OFFSET(A17,-2,0)+0.001,ERROR.TYPE(0)),IFERROR(IF(OFFSET(A17,-3,0)>0,OFFSET(A17,-3,0)+0.001,ERROR.TYPE(0)),IFERROR(IF(OFFSET(A17,-4,0)>0,OFFSET(A17,-4,0)+0.001,ERROR.TYPE(0)),IFERROR(IF(OFFSET(A17,-5,0)>0,OFFSET(A17,-5,0)+0.001,ERROR.TYPE(0)),IFERROR(IF(OFFSET(A17,-6,0)>0,OFFSET(A17,-6,0)+0.001,ERROR.TYPE(0)),IFERROR(IF(OFFSET(A17,-7,0)>0,OFFSET(A17,-7,0)+0.001,ERROR.TYPE(0)),IFERROR(IF(OFFSET(A17,-8,0)>0,OFFSET(A17,-8,0)+0.001,ERROR.TYPE(0)),IFERROR(IF(OFFSET(A17,-9,0)>0,OFFSET(A17,-9,0)+0.001,ERROR.TYPE(0)),IFERROR(IF(OFFSET(A17,-10,0)>0,OFFSET(A17,-10,0)+0.001,ERROR.TYPE(0)),ERROR.TYPE(0))))))))))) -> 1.007 | B17: Provision of security measures on site both as regards the storage facilities as well as to safeguard the materials installed during the latter stages of the project. | C17: 1 | D17: L.S. | E17: =Elec_Est!Q8074 -> Included with MEP preliminaries
A18: =IFERROR(IF(OFFSET(A18,-1,0)>0,OFFSET(A18,-1,0)+0.001,ERROR.TYPE(0)),IFERROR(IF(OFFSET(A18,-2,0)>0,OFFSET(A18,-2,0)+0.001,ERROR.TYPE(0)),IFERROR(IF(OFFSET(A18,-3,0)>0,OFFSET(A18,-3,0)+0.001,ERROR.TYPE(0)),IFERROR(IF(OFFSET(A18,-4,0)>0,OFFSET(A18,-4,0)+0.001,ERROR.TYPE(0)),IFERROR(IF(OFFSET(A18,-5,0)>0,OFFSET(A18,-5,0)+0.001,ERROR.TYPE(0)),IFERROR(IF(OFFSET(A18,-6,0)>0,OFFSET(A18,-6,0)+0.001,ERROR.TYPE(0)),IFERROR(IF(OFFSET(A18,-7,0)>0,OFFSET(A18,-7,0)+0.001,ERROR.TYPE(0)),IFERROR(IF(OFFSET(A18,-8,0)>0,OFFSET(A18,-8,0)+0.001,ERROR.TYPE(0)),IFERROR(IF(OFFSET(A18,-9,0)>0,OFFSET(A18,-9,0)+0.001,ERROR.TYPE(0)),IFERROR(IF(OFFSET(A18,-10,0)>0,OFFSET(A18,-10,0)+0.001,ERROR.TYPE(0)),ERROR.TYPE(0))))))))))) -> 1.008 | B18: Provision for the supply and delivery to site of samples as may be requested by the client / engineer | C18: 1 | D18: L.S. | E18: =Elec_Est!Q8084 -> Included with MEP preliminaries
A19: =IFERROR(IF(OFFSET(A19,-1,0)>0,OFFSET(A19,-1,0)+0.001,ERROR.TYPE(0)),IFERROR(IF(OFFSET(A19,-2,0)>0,OFFSET(A19,-2,0)+0.001,ERROR.TYPE(0)),IFERROR(IF(OFFSET(A19,-3,0)>0,OFFSET(A19,-3,0)+0.001,ERROR.TYPE(0)),IFERROR(IF(OFFSET(A19,-4,0)>0,OFFSET(A19,-4,0)+0.001,ERROR.TYPE(0)),IFERROR(IF(OFFSET(A19,-5,0)>0,OFFSET(A19,-5,0)+0.001,ERROR.TYPE(0)),IFERROR(IF(OFFSET(A19,-6,0)>0,OFFSET(A19,-6,0)+0.001,ERROR.TYPE(0)),IFERROR(IF(OFFSET(A19,-7,0)>0,OFFSET(A19,-7,0)+0.001,ERROR.TYPE(0)),IFERROR(IF(OFFSET(A19,-8,0)>0,OFFSET(A19,-8,0)+0.001,ERROR.TYPE(0)),IFERROR(IF(OFFSET(A19,-9,0)>0,OFFSET(A19,-9,0)+0.001,ERROR.TYPE(0)),IFERROR(IF(OFFSET(A19,-10,0)>0,OFFSET(A19,-10,0)+0.001,ERROR.TYPE(0)),ERROR.TYPE(0))))))))))) -> 1.009 | B19: Allow for continuously keeping the site and building clean and in a workman type condition free from debris, surplus materials and any other type of loose matter arising from works, which will disturb the proper conditions of any internal and external areas, roads and/or adjoining structures. Site Cleaning is to take place during the whole duration of works. Client reserves the right to employ cleaning companies at the contractor's expense if the contractor fails to keep the site clean. | C19: 1 | D19: L.S. | E19: =Elec_Est!Q8094 -> Included with MEP preliminaries
A20: =IFERROR(IF(OFFSET(A20,-1,0)>0,OFFSET(A20,-1,0)+0.001,ERROR.TYPE(0)),IFERROR(IF(OFFSET(A20,-2,0)>0,OFFSET(A20,-2,0)+0.001,ERROR.TYPE(0)),IFERROR(IF(OFFSET(A20,-3,0)>0,OFFSET(A20,-3,0)+0.001,ERROR.TYPE(0)),IFERROR(IF(OFFSET(A20,-4,0)>0,OFFSET(A20,-4,0)+0.001,ERROR.TYPE(0)),IFERROR(IF(OFFSET(A20,-5,0)>0,OFFSET(A20,-5,0)+0.001,ERROR.TYPE(0)),IFERROR(IF(OFFSET(A20,-6,0)>0,OFFSET(A20,-6,0)+0.001,ERROR.TYPE(0)),IFERROR(IF(OFFSET(A20,-7,0)>0,OFFSET(A20,-7,0)+0.001,ERROR.TYPE(0)),IFERROR(IF(OFFSET(A20,-8,0)>0,OFFSET(A20,-8,0)+0.001,ERROR.TYPE(0)),IFERROR(IF(OFFSET(A20,-9,0)>0,OFFSET(A20,-9,0)+0.001,ERROR.TYPE(0)),IFERROR(IF(OFFSET(A20,-10,0)>0,OFFSET(A20,-10,0)+0.001,ERROR.TYPE(0)),ERROR.TYPE(0))))))))))) -> 1.01 | B20: Provision for hauling of equipment on site, including cranage, permits and all necessary fees. | C20: 1 | D20: L.S. | E20: =Elec_Est!Q8104 -> Included with MEP preliminaries
A21: =IFERROR(IF(OFFSET(A21,-1,0)>0,OFFSET(A21,-1,0)+0.001,ERROR.TYPE(0)),IFERROR(IF(OFFSET(A21,-2,0)>0,OFFSET(A21,-2,0)+0.001,ERROR.TYPE(0)),IFERROR(IF(OFFSET(A21,-3,0)>0,OFFSET(A21,-3,0)+0.001,ERROR.TYPE(0)),IFERROR(IF(OFFSET(A21,-4,0)>0,OFFSET(A21,-4,0)+0.001,ERROR.TYPE(0)),IFERROR(IF(OFFSET(A21,-5,0)>0,OFFSET(A21,-5,0)+0.001,ERROR.TYPE(0)),IFERROR(IF(OFFSET(A21,-6,0)>0,OFFSET(A21,-6,0)+0.001,ERROR.TYPE(0)),IFERROR(IF(OFFSET(A21,-7,0)>0,OFFSET(A21,-7,0)+0.001,ERROR.TYPE(0)),IFERROR(IF(OFFSET(A21,-8,0)>0,OFFSET(A21,-8,0)+0.001,ERROR.TYPE(0)),IFERROR(IF(OFFSET(A21,-9,0)>0,OFFSET(A21,-9,0)+0.001,ERROR.TYPE(0)),IFERROR(IF(OFFSET(A21,-10,0)>0,OFFSET(A21,-10,0)+0.001,ERROR.TYPE(0)),ERROR.TYPE(0))))))))))) -> 1.011 | B21: Provision for working at height, including scaffolding, cherry pickers etc. All equipment shall be fully certified. | C21: 1 | D21: L.S. | E21: =Elec_Est!Q8114 -> Included with MEP preliminaries
A22: =IFERROR(IF(OFFSET(A22,-1,0)>0,OFFSET(A22,-1,0)+0.001,ERROR.TYPE(0)),IFERROR(IF(OFFSET(A22,-2,0)>0,OFFSET(A22,-2,0)+0.001,ERROR.TYPE(0)),IFERROR(IF(OFFSET(A22,-3,0)>0,OFFSET(A22,-3,0)+0.001,ERROR.TYPE(0)),IFERROR(IF(OFFSET(A22,-4,0)>0,OFFSET(A22,-4,0)+0.001,ERROR.TYPE(0)),IFERROR(IF(OFFSET(A22,-5,0)>0,OFFSET(A22,-5,0)+0.001,ERROR.TYPE(0)),IFERROR(IF(OFFSET(A22,-6,0)>0,OFFSET(A22,-6,0)+0.001,ERROR.TYPE(0)),IFERROR(IF(OFFSET(A22,-7,0)>0,OFFSET(A22,-7,0)+0.001,ERROR.TYPE(0)),IFERROR(IF(OFFSET(A22,-8,0)>0,OFFSET(A22,-8,0)+0.001,ERROR.TYPE(0)),IFERROR(IF(OFFSET(A22,-9,0)>0,OFFSET(A22,-9,0)+0.001,ERROR.TYPE(0)),IFERROR(IF(OFFSET(A22,-10,0)>0,OFFSET(A22,-10,0)+0.001,ERROR.TYPE(0)),ERROR.TYPE(0))))))))))) -> 1.012 | B22: Provision for Builders Work in order to prepare all openings required to install conduits, pipework, ductwork, etc., and making good and reinstatement of all openings. | C22: 1 | D22: L.S. | E22: =Elec_Est!Q8124 -> Included with MEP preliminaries
A23: =IFERROR(IF(OFFSET(A23,-1,0)>0,OFFSET(A23,-1,0)+0.001,ERROR.TYPE(0)),IFERROR(IF(OFFSET(A23,-2,0)>0,OFFSET(A23,-2,0)+0.001,ERROR.TYPE(0)),IFERROR(IF(OFFSET(A23,-3,0)>0,OFFSET(A23,-3,0)+0.001,ERROR.TYPE(0)),IFERROR(IF(OFFSET(A23,-4,0)>0,OFFSET(A23,-4,0)+0.001,ERROR.TYPE(0)),IFERROR(IF(OFFSET(A23,-5,0)>0,OFFSET(A23,-5,0)+0.001,ERROR.TYPE(0)),IFERROR(IF(OFFSET(A23,-6,0)>0,OFFSET(A23,-6,0)+0.001,ERROR.TYPE(0)),IFERROR(IF(OFFSET(A23,-7,0)>0,OFFSET(A23,-7,0)+0.001,ERROR.TYPE(0)),IFERROR(IF(OFFSET(A23,-8,0)>0,OFFSET(A23,-8,0)+0.001,ERROR.TYPE(0)),IFERROR(IF(OFFSET(A23,-9,0)>0,OFFSET(A23,-9,0)+0.001,ERROR.TYPE(0)),IFERROR(IF(OFFSET(A23,-10,0)>0,OFFSET(A23,-10,0)+0.001,ERROR.TYPE(0)),ERROR.TYPE(0))))))))))) -> 1.013 | B23: Provision for Openings in Insulation Panelling in order to prepare all openings required to install conduits, pipework, ductwork, etc., and making good and reinstatement of all openings. | C23: 1 | D23: L.S. | E23: =Elec_Est!Q8134 -> Included with MEP preliminaries
B24: TOTAL FOR PAGE 02 | C24: Euro Exc VAT | F24: =SUM(F16:F23) -> 0
B26: TOTAL FOR PRELIMINARIES | C26: Euro Exc VAT | F26: =F24+F12 -> 0
A29: ITEM | B29: DESCRIPTION | C29: QTY | D29: UNIT | E29: RATE Euro (Exc of VAT) | F29: TOTAL Euro (Exc of VAT)
A30: 2 | B30: FIRE ALARM & DETECTION SYSTEM
B31: In general all the points except manual call points shall be wired with cables clipped directly to the wall / ceiling unless otherwise indicated. All conduit rates are none the less to be quoted for since these may be required in some instances.
B32: Basement Level -1 - FAP1
B33: Supply and install galvanised conduit surface mounted from fire alarm panel via galvanised trunking to the following fire alarm points.
A34: =IFERROR(IF(OFFSET(A34,-1,0)>0,OFFSET(A34,-1,0)+0.001,ERROR.TYPE(0)),IFERROR(IF(OFFSET(A34,-2,0)>0,OFFSET(A34,-2,0)+0.001,ERROR.TYPE(0)),IFERROR(IF(OFFSET(A34,-3,0)>0,OFFSET(A34,-3,0)+0.001,ERROR.TYPE(0)),IFERROR(IF(OFFSET(A34,-4,0)>0,OFFSET(A34,-4,0)+0.001,ERROR.TYPE(0)),IFERROR(IF(OFFSET(A34,-5,0)>0,OFFSET(A34,-5,0)+0.001,ERROR.TYPE(0)),IFERROR(IF(OFFSET(A34,-6,0)>0,OFFSET(A34,-6,0)+0.001,ERROR.TYPE(0)),IFERROR(IF(OFFSET(A34,-7,0)>0,OFFSET(A34,-7,0)+0.001,ERROR.TYPE(0)),IFERROR(IF(OFFSET(A34,-8,0)>0,OFFSET(A34,-8,0)+0.001,ERROR.TYPE(0)),IFERROR(IF(OFFSET(A34,-9,0)>0,OFFSET(A34,-9,0)+0.001,ERROR.TYPE(0)),IFERROR(IF(OFFSET(A34,-10,0)>0,OFFSET(A34,-10,0)+0.001,ERROR.TYPE(0)),ERROR.TYPE(0))))))))))) -> 2.001 | B34: Optical smoke detector | C34: 14 | D34: No | E34: =Elec_Est!E8172 -> 98.17 | F34: =IFERROR($C34*E34,E34) -> 1374.38
A35: =IFERROR(IF(OFFSET(A35,-1,0)>0,OFFSET(A35,-1,0)+0.001,ERROR.TYPE(0)),IFERROR(IF(OFFSET(A35,-2,0)>0,OFFSET(A35,-2,0)+0.001,ERROR.TYPE(0)),IFERROR(IF(OFFSET(A35,-3,0)>0,OFFSET(A35,-3,0)+0.001,ERROR.TYPE(0)),IFERROR(IF(OFFSET(A35,-4,0)>0,OFFSET(A35,-4,0)+0.001,ERROR.TYPE(0)),IFERROR(IF(OFFSET(A35,-5,0)>0,OFFSET(A35,-5,0)+0.001,ERROR.TYPE(0)),IFERROR(IF(OFFSET(A35,-6,0)>0,OFFSET(A35,-6,0)+0.001,ERROR.TYPE(0)),IFERROR(IF(OFFSET(A35,-7,0)>0,OFFSET(A35,-7,0)+0.001,ERROR.TYPE(0)),IFERROR(IF(OFFSET(A35,-8,0)>0,OFFSET(A35,-8,0)+0.001,ERROR.TYPE(0)),IFERROR(IF(OFFSET(A35,-9,0)>0,OFFSET(A35,-9,0)+0.001,ERROR.TYPE(0)),IFERROR(IF(OFFSET(A35,-10,0)>0,OFFSET(A35,-10,0)+0.001,ERROR.TYPE(0)),ERROR.TYPE(0))))))))))) -> 2.002 | B35: Combined optical smoke detector c/w internal sounder & flashing beacon | C35: 5 | D35: No | E35: =Elec_Est!E8179 -> 98.17 | F35: =IFERROR($C35*E35,E35) -> 490.85
A36: =IFERROR(IF(OFFSET(A36,-1,0)>0,OFFSET(A36,-1,0)+0.001,ERROR.TYPE(0)),IFERROR(IF(OFFSET(A36,-2,0)>0,OFFSET(A36,-2,0)+0.001,ERROR.TYPE(0)),IFERROR(IF(OFFSET(A36,-3,0)>0,OFFSET(A36,-3,0)+0.001,ERROR.TYPE(0)),IFERROR(IF(OFFSET(A36,-4,0)>0,OFFSET(A36,-4,0)+0.001,ERROR.TYPE(0)),IFERROR(IF(OFFSET(A36,-5,0)>0,OFFSET(A36,-5,0)+0.001,ERROR.TYPE(0)),IFERROR(IF(OFFSET(A36,-6,0)>0,OFFSET(A36,-6,0)+0.001,ERROR.TYPE(0)),IFERROR(IF(OFFSET(A36,-7,0)>0,OFFSET(A36,-7,0)+0.001,ERROR.TYPE(0)),IFERROR(IF(OFFSET(A36,-8,0)>0,OFFSET(A36,-8,0)+0.001,ERROR.TYPE(0)),IFERROR(IF(OFFSET(A36,-9,0)>0,OFFSET(A36,-9,0)+0.001,ERROR.TYPE(0)),IFERROR(IF(OFFSET(A36,-10,0)>0,OFFSET(A36,-10,0)+0.001,ERROR.TYPE(0)),ERROR.TYPE(0))))))))))) -> 2.003 | B36: Rate of rise heat detector | C36: 77 | D36: No | E36: =Elec_Est!E8186 -> 98.17 | F36: =IFERROR($C36*E36,E36) -> 7559.09
A37: =IFERROR(IF(OFFSET(A37,-1,0)>0,OFFSET(A37,-1,0)+0.001,ERROR.TYPE(0)),IFERROR(IF(OFFSET(A37,-2,0)>0,OFFSET(A37,-2,0)+0.001,ERROR.TYPE(0)),IFERROR(IF(OFFSET(A37,-3,0)>0,OFFSET(A37,-3,0)+0.001,ERROR.TYPE(0)),IFERROR(IF(OFFSET(A37,-4,0)>0,OFFSET(A37,-4,0)+0.001,ERROR.TYPE(0)),IFERROR(IF(OFFSET(A37,-5,0)>0,OFFSET(A37,-5,0)+0.001,ERROR.TYPE(0)),IFERROR(IF(OFFSET(A37,-6,0)>0,OFFSET(A37,-6,0)+0.001,ERROR.TYPE(0)),IFERROR(IF(OFFSET(A37,-7,0)>0,OFFSET(A37,-7,0)+0.001,ERROR.TYPE(0)),IFERROR(IF(OFFSET(A37,-8,0)>0,OFFSET(A37,-8,0)+0.001,ERROR.TYPE(0)),IFERROR(IF(OFFSET(A37,-9,0)>0,OFFSET(A37,-9,0)+0.001,ERROR.TYPE(0)),IFERROR(IF(OFFSET(A37,-10,0)>0,OFFSET(A37,-10,0)+0.001,ERROR.TYPE(0)),ERROR.TYPE(0))))))))))) -> 2.004 | B37: Combined rate of rise heat detector c/w internal sounder & flashing beacon | C37: 8 | D37: No | E37: =Elec_Est!E8193 -> 98.17 | F37: =IFERROR($C37*E37,E37) -> 785.36
A38: =IFERROR(IF(OFFSET(A38,-1,0)>0,OFFSET(A38,-1,0)+0.001,ERROR.TYPE(0)),IFERROR(IF(OFFSET(A38,-2,0)>0,OFFSET(A38,-2,0)+0.001,ERROR.TYPE(0)),IFERROR(IF(OFFSET(A38,-3,0)>0,OFFSET(A38,-3,0)+0.001,ERROR.TYPE(0)),IFERROR(IF(OFFSET(A38,-4,0)>0,OFFSET(A38,-4,0)+0.001,ERROR.TYPE(0)),IFERROR(IF(OFFSET(A38,-5,0)>0,OFFSET(A38,-5,0)+0.001,ERROR.TYPE(0)),IFERROR(IF(OFFSET(A38,-6,0)>0,OFFSET(A38,-6,0)+0.001,ERROR.TYPE(0)),IFERROR(IF(OFFSET(A38,-7,0)>0,OFFSET(A38,-7,0)+0.001,ERROR.TYPE(0)),IFERROR(IF(OFFSET(A38,-8,0)>0,OFFSET(A38,-8,0)+0.001,ERROR.TYPE(0)),IFERROR(IF(OFFSET(A38,-9,0)>0,OFFSET(A38,-9,0)+0.001,ERROR.TYPE(0)),IFERROR(IF(OFFSET(A38,-10,0)>0,OFFSET(A38,-10,0)+0.001,ERROR.TYPE(0)),ERROR.TYPE(0))))))))))) -> 2.005 | B38: Manual call point | C38: 2 | D38: No | E38: =Elec_Est!E8200 -> 98.17 | F38: =IFERROR($C38*E38,E38) -> 196.34
A39: =IFERROR(IF(OFFSET(A39,-1,0)>0,OFFSET(A39,-1,0)+0.001,ERROR.TYPE(0)),IFERROR(IF(OFFSET(A39,-2,0)>0,OFFSET(A39,-2,0)+0.001,ERROR.TYPE(0)),IFERROR(IF(OFFSET(A39,-3,0)>0,OFFSET(A39,-3,0)+0.001,ERROR.TYPE(0)),IFERROR(IF(OFFSET(A39,-4,0)>0,OFFSET(A39,-4,0)+0.001,ERROR.TYPE(0)),IFERROR(IF(OFFSET(A39,-5,0)>0,OFFSET(A39,-5,0)+0.001,ERROR.TYPE(0)),IFERROR(IF(OFFSET(A39,-6,0)>0,OFFSET(A39,-6,0)+0.001,ERROR.TYPE(0)),IFERROR(IF(OFFSET(A39,-7,0)>0,OFFSET(A39,-7,0)+0.001,ERROR.TYPE(0)),IFERROR(IF(OFFSET(A39,-8,0)>0,OFFSET(A39,-8,0)+0.001,ERROR.TYPE(0)),IFERROR(IF(OFFSET(A39,-9,0)>0,OFFSET(A39,-9,0)+0.001,ERROR.TYPE(0)),IFERROR(IF(OFFSET(A39,-10,0)>0,OFFSET(A39,-10,0)+0.001,ERROR.TYPE(0)),ERROR.TYPE(0))))))))))) -> 2.006 | B39: Interface unit for Zone Assembly Valve | C39: 1 | D39: No | E39: =Elec_Est!E8207 -> 98.17 | F39: =IFERROR($C39*E39,E39) -> 98.17
A40: =IFERROR(IF(OFFSET(A40,-1,0)>0,OFFSET(A40,-1,0)+0.001,ERROR.TYPE(0)),IFERROR(IF(OFFSET(A40,-2,0)>0,OFFSET(A40,-2,0)+0.001,ERROR.TYPE(0)),IFERROR(IF(OFFSET(A40,-3,0)>0,OFFSET(A40,-3,0)+0.001,ERROR.TYPE(0)),IFERROR(IF(OFFSET(A40,-4,0)>0,OFFSET(A40,-4,0)+0.001,ERROR.TYPE(0)),IFERROR(IF(OFFSET(A40,-5,0)>0,OFFSET(A40,-5,0)+0.001,ERROR.TYPE(0)),IFERROR(IF(OFFSET(A40,-6,0)>0,OFFSET(A40,-6,0)+0.001,ERROR.TYPE(0)),IFERROR(IF(OFFSET(A40,-7,0)>0,OFFSET(A40,-7,0)+0.001,ERROR.TYPE(0)),IFERROR(IF(OFFSET(A40,-8,0)>0,OFFSET(A40,-8,0)+0.001,ERROR.TYPE(0)),IFERROR(IF(OFFSET(A40,-9,0)>0,OFFSET(A40,-9,0)+0.001,ERROR.TYPE(0)),IFERROR(IF(OFFSET(A40,-10,0)>0,OFFSET(A40,-10,0)+0.001,ERROR.TYPE(0)),ERROR.TYPE(0))))))))))) -> 2.007 | B40: Interface unit for Fire Suppression System | C40: 3 | D40: No | E40: =Elec_Est!E8214 -> 98.17 | F40: =IFERROR($C40*E40,E40) -> 294.51
A41: =IFERROR(IF(OFFSET(A41,-1,0)>0,OFFSET(A41,-1,0)+0.001,ERROR.TYPE(0)),IFERROR(IF(OFFSET(A41,-2,0)>0,OFFSET(A41,-2,0)+0.001,ERROR.TYPE(0)),IFERROR(IF(OFFSET(A41,-3,0)>0,OFFSET(A41,-3,0)+0.001,ERROR.TYPE(0)),IFERROR(IF(OFFSET(A41,-4,0)>0,OFFSET(A41,-4,0)+0.001,ERROR.TYPE(0)),IFERROR(IF(OFFSET(A41,-5,0)>0,OFFSET(A41,-5,0)+0.001,ERROR.TYPE(0)),IFERROR(IF(OFFSET(A41,-6,0)>0,OFFSET(A41,-6,0)+0.001,ERROR.TYPE(0)),IFERROR(IF(OFFSET(A41,-7,0)>0,OFFSET(A41,-7,0)+0.001,ERROR.TYPE(0)),IFERROR(IF(OFFSET(A41,-8,0)>0,OFFSET(A41,-8,0)+0.001,ERROR.TYPE(0)),IFERROR(IF(OFFSET(A41,-9,0)>0,OFFSET(A41,-9,0)+0.001,ERROR.TYPE(0)),IFERROR(IF(OFFSET(A41,-10,0)>0,OFFSET(A41,-10,0)+0.001,ERROR.TYPE(0)),ERROR.TYPE(0))))))))))) -> 2.008 | B41: Interface unit for VCP | C41: 1 | D41: No | E41: =Elec_Est!E8221 -> 98.17 | F41: =IFERROR($C41*E41,E41) -> 98.17
A42: =IFERROR(IF(OFFSET(A42,-1,0)>0,OFFSET(A42,-1,0)+0.001,ERROR.TYPE(0)),IFERROR(IF(OFFSET(A42,-2,0)>0,OFFSET(A42,-2,0)+0.001,ERROR.TYPE(0)),IFERROR(IF(OFFSET(A42,-3,0)>0,OFFSET(A42,-3,0)+0.001,ERROR.TYPE(0)),IFERROR(IF(OFFSET(A42,-4,0)>0,OFFSET(A42,-4,0)+0.001,ERROR.TYPE(0)),IFERROR(IF(OFFSET(A42,-5,0)>0,OFFSET(A42,-5,0)+0.001,ERROR.TYPE(0)),IFERROR(IF(OFFSET(A42,-6,0)>0,OFFSET(A42,-6,0)+0.001,ERROR.TYPE(0)),IFERROR(IF(OFFSET(A42,-7,0)>0,OFFSET(A42,-7,0)+0.001,ERROR.TYPE(0)),IFERROR(IF(OFFSET(A42,-8,0)>0,OFFSET(A42,-8,0)+0.001,ERROR.TYPE(0)),IFERROR(IF(OFFSET(A42,-9,0)>0,OFFSET(A42,-9,0)+0.001,ERROR.TYPE(0)),IFERROR(IF(OFFSET(A42,-10,0)>0,OFFSET(A42,-10,0)+0.001,ERROR.TYPE(0)),ERROR.TYPE(0))))))))))) -> 2.009 | B42: Interface unit for DB-EV | C42: 1 | D42: No | E42: =Elec_Est!E8228 -> 98.17 | F42: =IFERROR($C42*E42,E42) -> 98.17
B43: Wiring of the following fire alarm points from the Fire alarm panel, using fire proof cable clipped directly to the wall / ceiling or through conduits, as per specification
A44: =IFERROR(IF(OFFSET(A44,-1,0)>0,OFFSET(A44,-1,0)+0.001,ERROR.TYPE(0)),IFERROR(IF(OFFSET(A44,-2,0)>0,OFFSET(A44,-2,0)+0.001,ERROR.TYPE(0)),IFERROR(IF(OFFSET(A44,-3,0)>0,OFFSET(A44,-3,0)+0.001,ERROR.TYPE(0)),IFERROR(IF(OFFSET(A44,-4,0)>0,OFFSET(A44,-4,0)+0.001,ERROR.TYPE(0)),IFERROR(IF(OFFSET(A44,-5,0)>0,OFFSET(A44,-5,0)+0.001,ERROR.TYPE(0)),IFERROR(IF(OFFSET(A44,-6,0)>0,OFFSET(A44,-6,0)+0.001,ERROR.TYPE(0)),IFERROR(IF(OFFSET(A44,-7,0)>0,OFFSET(A44,-7,0)+0.001,ERROR.TYPE(0)),IFERROR(IF(OFFSET(A44,-8,0)>0,OFFSET(A44,-8,0)+0.001,ERROR.TYPE(0)),IFERROR(IF(OFFSET(A44,-9,0)>0,OFFSET(A44,-9,0)+0.001,ERROR.TYPE(0)),IFERROR(IF(OFFSET(A44,-10,0)>0,OFFSET(A44,-10,0)+0.001,ERROR.TYPE(0)),ERROR.TYPE(0))))))))))) -> 2.01 | B44: Optical smoke detector | C44: 14 | D44: No | E44: =Elec_Est!E8239 -> 36.95 | F44: =IFERROR($C44*E44,E44) -> 517.3
A45: =IFERROR(IF(OFFSET(A45,-1,0)>0,OFFSET(A45,-1,0)+0.001,ERROR.TYPE(0)),IFERROR(IF(OFFSET(A45,-2,0)>0,OFFSET(A45,-2,0)+0.001,ERROR.TYPE(0)),IFERROR(IF(OFFSET(A45,-3,0)>0,OFFSET(A45,-3,0)+0.001,ERROR.TYPE(0)),IFERROR(IF(OFFSET(A45,-4,0)>0,OFFSET(A45,-4,0)+0.001,ERROR.TYPE(0)),IFERROR(IF(OFFSET(A45,-5,0)>0,OFFSET(A45,-5,0)+0.001,ERROR.TYPE(0)),IFERROR(IF(OFFSET(A45,-6,0)>0,OFFSET(A45,-6,0)+0.001,ERROR.TYPE(0)),IFERROR(IF(OFFSET(A45,-7,0)>0,OFFSET(A45,-7,0)+0.001,ERROR.TYPE(0)),IFERROR(IF(OFFSET(A45,-8,0)>0,OFFSET(A45,-8,0)+0.001,ERROR.TYPE(0)),IFERROR(IF(OFFSET(A45,-9,0)>0,OFFSET(A45,-9,0)+0.001,ERROR.TYPE(0)),IFERROR(IF(OFFSET(A45,-10,0)>0,OFFSET(A45,-10,0)+0.001,ERROR.TYPE(0)),ERROR.TYPE(0))))))))))) -> 2.011 | B45: Combined optical smoke detector c/w internal sounder & flashing beacon | C45: 5 | D45: No | E45: =Elec_Est!E8245 -> 36.95 | F45: =IFERROR($C45*E45,E45) -> 184.75
A46: =IFERROR(IF(OFFSET(A46,-1,0)>0,OFFSET(A46,-1,0)+0.001,ERROR.TYPE(0)),IFERROR(IF(OFFSET(A46,-2,0)>0,OFFSET(A46,-2,0)+0.001,ERROR.TYPE(0)),IFERROR(IF(OFFSET(A46,-3,0)>0,OFFSET(A46,-3,0)+0.001,ERROR.TYPE(0)),IFERROR(IF(OFFSET(A46,-4,0)>0,OFFSET(A46,-4,0)+0.001,ERROR.TYPE(0)),IFERROR(IF(OFFSET(A46,-5,0)>0,OFFSET(A46,-5,0)+0.001,ERROR.TYPE(0)),IFERROR(IF(OFFSET(A46,-6,0)>0,OFFSET(A46,-6,0)+0.001,ERROR.TYPE(0)),IFERROR(IF(OFFSET(A46,-7,0)>0,OFFSET(A46,-7,0)+0.001,ERROR.TYPE(0)),IFERROR(IF(OFFSET(A46,-8,0)>0,OFFSET(A46,-8,0)+0.001,ERROR.TYPE(0)),IFERROR(IF(OFFSET(A46,-9,0)>0,OFFSET(A46,-9,0)+0.001,ERROR.TYPE(0)),IFERROR(IF(OFFSET(A46,-10,0)>0,OFFSET(A46,-10,0)+0.001,ERROR.TYPE(0)),ERROR.TYPE(0))))))))))) -> 2.012 | B46: Rate of rise heat detector | C46: 77 | D46: No | E46: =Elec_Est!E8251 -> 36.95 | F46: =IFERROR($C46*E46,E46) -> 2845.15
A47: =IFERROR(IF(OFFSET(A47,-1,0)>0,OFFSET(A47,-1,0)+0.001,ERROR.TYPE(0)),IFERROR(IF(OFFSET(A47,-2,0)>0,OFFSET(A47,-2,0)+0.001,ERROR.TYPE(0)),IFERROR(IF(OFFSET(A47,-3,0)>0,OFFSET(A47,-3,0)+0.001,ERROR.TYPE(0)),IFERROR(IF(OFFSET(A47,-4,0)>0,OFFSET(A47,-4,0)+0.001,ERROR.TYPE(0)),IFERROR(IF(OFFSET(A47,-5,0)>0,OFFSET(A47,-5,0)+0.001,ERROR.TYPE(0)),IFERROR(IF(OFFSET(A47,-6,0)>0,OFFSET(A47,-6,0)+0.001,ERROR.TYPE(0)),IFERROR(IF(OFFSET(A47,-7,0)>0,OFFSET(A47,-7,0)+0.001,ERROR.TYPE(0)),IFERROR(IF(OFFSET(A47,-8,0)>0,OFFSET(A47,-8,0)+0.001,ERROR.TYPE(0)),IFERROR(IF(OFFSET(A47,-9,0)>0,OFFSET(A47,-9,0)+0.001,ERROR.TYPE(0)),IFERROR(IF(OFFSET(A47,-10,0)>0,OFFSET(A47,-10,0)+0.001,ERROR.TYPE(0)),ERROR.TYPE(0))))))))))) -> 2.013 | B47: Combined rate of rise heat detector c/w internal sounder & flashing beacon | C47: 8 | D47: No | E47: =Elec_Est!E8257 -> 36.95 | F47: =IFERROR($C47*E47,E47) -> 295.6
...

Sheet Notes
A1: NOTES | C1: Rev: 235
C2: checkdesc
A3: ELECTRICAL | C3: Elec_Rates
C4: Elec_Est
A5: Dist Boards | C5: Elv_Rates
A6: 1 | C6: ELV_Est
A7: 2 | C7: Ext_Quote
C8: Int_Quote
A9: Wiring Accessories | C9: Est_BOQ
A10: 1
A11: 2 | C11: Camilleri&Cuschieri Tenders
C12: Conduit
A13: ELV | C13: Wiring
C14: Supply
A15: Fire Alarm
A16: 1
A17: 2
A18: 3
A20: Data
A21: 1
A22: 2
A23: 3

Sheet Quote
A1: =IF(AND(UPPER(LEFT(TRIM($D$8),11))="01",UPPER(LEFT(TRIM($D$9),3))<>"ELM"),"PANTA RETAIL LTD.","PANTA CONTRACTING LIMITED") -> PANTA CONTRACTING LIMITED
A2: =IF(UPPER(LEFT(TRIM($D$9),3))="ELM","ELEC-FOR-MECH INTERNAL QUOTATION","ELECTRICAL INTERNAL QUOTATION") -> ELECTRICAL INTERNAL QUOTATION
B5: ATT: | D5: =IF(A2="Internal Quotation", "Mechanical Division","") | R5: Dated: | S5: =NOW() -> 46114.371
B6: CLIENT: | C6: Link to ML_SUM $D1 | D6: =ML_Sum!D1 -> Quintano Foods Ltd.
B7: PROJECT: | C7: Link to ML_SUM $D2 | D7: =ML_Sum!D2 -> Warehouse at tal-Handaq, Qormi
B8: JOB DESC: | C8: Link to ML_SUM $D3 | D8: =ML_Sum!D3 -> Electrical and ELV installations (Rev A)
B9: QUOTE No: | C9: Link to ML_SUM $D4 | D9: =ML_Sum!D4 -> EL25-0062A
B10: CLIENT's Ref: | C10: Link to ML_SUM $D5 | D10: =ML_Sum!D5 -> Tender
D22: Selling Price (€) : | E22: =ML_Sum!E35 -> 1478219.1 | F22: =ML_Sum!D6 -> VAT EXCL. | G22: VAT EXCLUDED. | H22: VAT EXCLUDED. | I22: VAT EXCLUDED. | J22: VAT EXCLUDED. | K22: VAT EXCLUDED. | L22: VAT EXCLUDED. | M22: VAT EXCLUDED. | N22: VAT EXCLUDED. | O22: VAT EXCLUDED. | P22: VAT EXCLUDED.
A51: Signed for and on behalf of | Q51: Signed for and on behalf of
A52: Electrical Division | Q52: Division
Q54: Records
Q55: Mr. A. Sciberras
Q57: File

Sheet ML_Sum
B1: CLIENT: | C1: 1 | D1: Quintano Foods Ltd. | G1: TRUE | H1: TRUE | I1: 1 | J1: =$Q109 -> 1 | K1: =$Q119 -> 1 | L1: =$Q129 -> 1 | M1: =$Q139 -> 1 | N1: =$Q149 -> 1 | O1: =$Q159 -> 1 | Q1: =IF(C1=1,"€","Curr?") -> € | R1: Recon /Lab.Cont >> | S1: =IF($S$39="PRINT","R","Do Not Print") -> R | T1: 0.9 | V1: {=IF(OR(X1=AREAS),1,0)} -> 1 | W1: BOQ | X1: x | Y1: x | Z1: x | AA1: x | AB1: x | AC1: x | AD1: x
B2: PROJECT: | C2: =IF($D$6="VAT INCLUDED",1.18,1)*(1-$Q2)*$C$1 -> 1 | D2: Warehouse at tal-Handaq, Qormi | F2: Electrical | G2: TRUE | I2: 2 | J2: =$Q110 -> 1 | K2: =$Q120 -> 1 | L2: =$Q130 -> 1 | M2: =$Q140 -> 1 | N2: =$Q150 -> 1 | O2: =$Q160 -> 1 | R2: ="A) " & IF($S2=0,"",ROUND($S2,2) & "-" & ROUND($T2/$D$9,2)) -> A) 1.23-1.23 | S2: =1.2*1.02*1.006 -> 1.231344 | T2: =$S2*$D$9 -> 33.812706 | U2: Note: Mark Ups include 2% measurement fee for C&C and 0.6% CAR insurance - Email from Kris Micallef dated 11th February 2025 | X2: x | Y2: x | Z2: x | AA2: x | AB2: x | AC2: x | AD2: x
B3: JOB DESC: | C3: =IF($D$6="VAT INCLUDED",1.18,1)*(1-$Q3)*$C$1 -> 1 | D3: Electrical and ELV installations (Rev A) | F3: ELV Installation (NAS Ltd) | G3: TRUE | I3: 3 | J3: =$Q111 -> 1 | K3: =$Q121 -> 1 | L3: =$Q131 -> 1 | M3: =$Q141 -> 1 | N3: =$Q151 -> 1 | O3: =$Q161 -> 1 | R3: ="B) " & IF($S3=0,"",ROUND($S3,2) & "-" & ROUND($T3/$D$9,2)) -> B) 1.13-1.13 | S3: =1.1*1.02*1.006 -> 1.128732 | T3: =$S3*$D$9 -> 30.994981 | X3: x | Y3: x | Z3: x | AA3: x | AB3: x | AC3: x | AD3: x
B4: INT. QUOT No: | C4: =IF($D$6="VAT INCLUDED",1.18,1)*(1-$Q4)*$C$1 -> 1 | D4: EL25-0062A | F4: Lightning Protection System (MCE Ltd) | G4: TRUE | I4: 4 | J4: =$Q112 -> 1 | K4: =$Q122 -> 1 | L4: =$Q132 -> 1 | M4: =$Q142 -> 1 | N4: =$Q152 -> 1 | O4: =$Q162 -> 1 | R4: ="C) " & IF($S4=0,"",ROUND($S4,2) & "-" & ROUND($T4/$D$9,2)) -> C) 1.13-1.13 | S4: =1.1*1.02*1.006 -> 1.128732 | T4: =$S4*$D$9 -> 30.994981 | X4: x | Y4: x | Z4: x | AA4: x | AB4: x | AC4: x | AD4: x
B5: CLIENTs REF: | C5: =IF($D$6="VAT INCLUDED",1.18,1)*(1-$Q5)*$C$1 -> 1 | D5: Tender | F5: Controls ECA | G5: TRUE | I5: 5 | J5: =$Q113 -> 1 | K5: =$Q123 -> 1 | L5: =$Q133 -> 1 | M5: =$Q143 -> 1 | N5: =$Q153 -> 1 | O5: =$Q163 -> 1 | R5: ="D) " & IF($S5=0,"",ROUND($S5,2) & "-" & ROUND($T5/$D$9,2)) -> D) 1.23-1.94 | S5: =1.2*1.02*1.006 -> 1.231344 | T5: =$S5*43.32 -> 53.341822 | X5: x | Y5: x | Z5: x | AA5: x | AB5: x | AC5: x | AD5: x
B6: VAT: | C6: =IF($D$6="VAT INCLUDED",1.18,1)*(1-$Q6)*$C$1 -> 1 | D6: VAT EXCL. | F6: Testing and Commissiong | G6: TRUE | I6: 6 | J6: =$Q114 -> 1 | K6: =$Q124 -> 1 | L6: =$Q134 -> 1 | M6: =$Q144 -> 1 | N6: =$Q154 -> 1 | O6: =$Q164 -> 1 | R6: ="E) " & IF($S6=0,"",ROUND($S6,2) & "-" & ROUND($T6/$D$9,2)) -> E) 1.23-2.37 | S6: =1.2*1.02*1.006 -> 1.231344 | T6: =$S6*52.92 -> 65.162724 | X6: x | Y6: x | Z6: x | AA6: x | AB6: x | AC6: x | AD6: x
B7: SAVED ON: | C7: =IF($D$6="VAT INCLUDED",1.18,1)*(1-$Q7)*$C$1 -> 1 | D7: 45694 | F7: Fire Stopping rates | G7: TRUE | I7: 7 | J7: =$Q115 -> 1 | K7: =$Q125 -> 1 | L7: =$Q135 -> 1 | M7: =$Q145 -> 1 | N7: =$Q155 -> 1 | R7: ="F) " & IF($S7=0,"",ROUND($S7,2) & "-" & ROUND($T7/$D$9,2)) -> F) 1.23-1.23 | S7: =1.2*1.02*1.006 -> 1.231344 | T7: =$S7*$D$9 -> 33.812706 | X7: x | Y7: x | Z7: x | AA7: x | AB7: x | AC7: x | AD7: x
B8: ESTIMATOR: | C8: =IF($D$6="VAT INCLUDED",1.18,1)*(1-$Q8)*$C$1 -> 1 | D8: T.Sammut | F8: Main Equipment (Gen Set / Main Switchboards) | G8: TRUE | I8: 8 | J8: =$Q116 -> 1 | K8: =$Q126 -> 1 | L8: =$Q136 -> 1 | M8: =$Q146 -> 1 | N8: =$Q156 -> 1 | R8: ="G) " & IF($S8=0,"",ROUND($S8,2) & "-" & ROUND($T8/$D$9,2)) -> G) 1.18-1.18 | S8: =1.15*1.02*1.006 -> 1.180038 | T8: =$S8*$D$9 -> 32.403843 | X8: x | Y8: x | Z8: x | AA8: x | AB8: x | AC8: x | AD8: x
B9: LAB. COST: | C9: =IF($D$6="VAT INCLUDED",1.18,1)*(1-$Q9)*$C$1 -> 1 | D9: 27.46 | E9: Cost for 2025 | F9: DBs and Changeover | G9: TRUE | I9: 9 | J9: =$Q117 -> 1 | K9: =$Q127 -> 1 | L9: =$Q137 -> 1 | M9: =$Q147 -> 1 | N9: =$Q157 -> 1 | R9: ="H) " & IF($S9=0,"",ROUND($S9,2) & "-" & ROUND($T9/$D$9,2)) -> H) 1.18-1.18 | S9: =1.15*1.02*1.006 -> 1.180038 | T9: =$S9*$D$9 -> 32.403843 | X9: x | Y9: x | Z9: x | AA9: x | AB9: x | AC9: x | AD9: x
C10: =IF($D$6="VAT INCLUDED",1.18,1)*(1-$Q10)*$C$1 -> 1 | F10: Armoured Cables | G10: TRUE | I10: 10 | J10: =$Q118 -> 1 | K10: =$Q128 -> 1 | L10: =$Q138 -> 1 | M10: =$Q148 -> 1 | N10: =$Q158 -> 1 | O10: =Q108 -> 1 | R10: =" I) " & IF($S10=0,"",ROUND($S10,2) & "-" & ROUND($T10/$D$9,2)) -> I) 1.18-1.18 | S10: =1.15*1.02*1.006 -> 1.180038 | T10: =$S10*$D$9 -> 32.403843 | X10: x | Y10: x | Z10: x | AA10: x | AB10: x | AC10: x | AD10: x
C11: =IF($D$6="VAT INCLUDED",1.18,1)*(1-$Q11)*$C$1 -> 1 | R11: ="J) " & IF($S11=0,"",ROUND($S11,2) & "-" & ROUND($T11/$D$9,2)) -> J) | X11: x | Y11: x | Z11: x | AA11: x | AB11: x | AC11: x | AD11: x
C12: =IF($D$6="VAT INCLUDED",1.18,1)*(1-$Q12)*$C$1 -> 1 | G12: SYSTEMS | H12: SYSTEMS | I12: SYSTEMS | J12: SYSTEMS | K12: SYSTEMS | L12: SYSTEMS | M12: SYSTEMS | N12: SYSTEMS | O12: SYSTEMS | P12: SYSTEMS | R12: MIXED - X,Y ) | S12: MAT MU | T12: LAB RATE | X12: x | Y12: x | Z12: x | AA12: x | AB12: x | AC12: x | AD12: x
B13: MATERIAL & LABOUR SUMMARY | G13: ItemCode | H13: CostCode | I13: MAKE | J13: PART_NO | K13: MARKUP | L13: TYPE | M13: LIST_P | N13: SET | O13: FIX | P13: DATE | Q13: %Dsct in BOQ | R13: MATMU-LABMU | S13: MAT CONT >> | T13: =SUM(Q108:Q164)/57 -> 1
B14: =IF($D$6<>"VAT EXCL.", "QUOTE ISSUED WITH VAT INCLUDED", "") | X14: x | Y14: x | Z14: x | AA14: x | AB14: x | AC14: x | AD14: x
Q15: =(C72-F35)/C72 -> 0 | R15: Average Discount applied in BOQ (Q2-Q12) | X15: x | Y15: x | Z15: x | AA15: x | AB15: x | AC15: x | AD15: x
B16: =IF($W$1<>"BOQ", "DIFF SET TO " & W1,"") | Q16: =(F35-E35)/F35 -> 0.0969519 | R16: Average Discount applied on Totals (Q23-Q32) | X16: x | Y16: x | Z16: x | AA16: x | AB16: x | AC16: x | AD16: x
Q17: =F74 -> 0.0969519 | R17: Overall Discount
B18: =IF(AND(G1,G2,G3,G4,G5,G6,G7,G8,G9,G10,H1)=TRUE, "", "CHECKLIST INCOMPLETE !" )
B19: =IF(ABS(SUM(A23:A32))>100,"[Discy A-J] are high, Check it out."," ") | Q19: =R83 -> 1.0825877 | R19: Overall Markup (Final Selling Excl.VAT/Total Cost )
E21: DISCOUNTED | F21: SELLING | Q21: % Discnt | R21: MATERIAL | T21: LABOUR
A22: Discy.A-J | B22: Markup/LRate | E22: ="SELLING " & $Q$1 -> SELLING € | F22: =$Q$1 -> € | G22: VAT/DISC | H22: MU | I22: LABRATE | J22: LABCOST | Q22: on Totals | R22: € | T22: Pair Hrs.
A23: =IF($F23=0,"",($F23/$C2)-($R23*$S2+$T23*$T2)) -> -2.7910798 | B23: =IF(F23=0,"",IF(R23=0,"A) "&"---, "&ROUND(($F23/$C2-($R23*$S2))/$T23,2),IF(T23=0,"A) "&ROUND(($F23/$C2)/$R23,2),"A) "&ROUND(($F23/$C2-($T23*$T2))/$R23,2)&", " &ROUND(($F23/$C2-($R23*$S2))/$T23,2)))) -> A) 1.23, 33.81 | D23: =IF($F2="","",$F2) -> Electrical | E23: =F23*(1-Q23) -> 593489.32 | F23: =Elec_Est!F11462+Fire_Stopping_Est!F401 -> 657206.77 | G23: =C2 -> 1 | H23: =$S2 -> 1.231344 | I23: =$T2 -> 33.812706 | J23: =$D$9 -> 27.46 | Q23: 0.0969519 | R23: =Elec_Est!R11462+Fire_Stopping_Est!R401 -> 349590.82 | T23: =Elec_Est!T11462+Fire_Stopping_Est!T401 -> 6705.852
A24: =IF($F24=0,"",($F24/$C3)-($R24*$S3+$T24*$T3)) -> -0.31921065 | B24: =IF(F24=0,"",IF(R24=0,"A) "&"---, "&ROUND(($F24/$C3-($R24*$S3))/$T24,2),IF(T24=0,"A) "&ROUND(($F24/$C3)/$R24,2),"A) "&ROUND(($F24/$C3-($T24*$T3))/$R24,2)&", " &ROUND(($F24/$C3-($R24*$S3))/$T24,2)))) -> A) 1.13, 30.96 | D24: =IF($F3="","",$F3) -> ELV Installation (NAS Ltd) | E24: =F24*(1-Q24) -> 134683.06 | F24: =Elec_Est!F11463+Fire_Stopping_Est!F402 -> 149142.73 | G24: =C3 -> 1 | H24: =$S3 -> 1.128732 | I24: =$T3 -> 30.994981 | J24: =$D$9 -> 27.46 | Q24: 0.0969519 | R24: =Elec_Est!R11463+Fire_Stopping_Est!R402 -> 131910.84 | T24: =Elec_Est!T11463+Fire_Stopping_Est!T402 -> 8.1
A25: =IF($F25=0,"",($F25/$C4)-($R25*$S4+$T25*$T4)) -> 1.7301422 | B25: =IF(F25=0,"",IF(R25=0,"A) "&"---, "&ROUND(($F25/$C4-($R25*$S4))/$T25,2),IF(T25=0,"A) "&ROUND(($F25/$C4)/$R25,2),"A) "&ROUND(($F25/$C4-($T25*$T4))/$R25,2)&", " &ROUND(($F25/$C4-($R25*$S4))/$T25,2)))) -> A) 1.13 | D25: =IF($F4="","",$F4) -> Lightning Protection System (MCE Ltd) | E25: =F25*(1-Q25) -> 47155.041 | F25: =Elec_Est!F11464+Fire_Stopping_Est!F403 -> 52217.64 | G25: =C4 -> 1 | H25: =$S4 -> 1.128732 | I25: =$T4 -> 30.994981 | J25: =$D$9 -> 27.46 | Q25: 0.0969519 | R25: =Elec_Est!R11464+Fire_Stopping_Est!R403 -> 46260.68 | T25: =Elec_Est!T11464+Fire_Stopping_Est!T403 -> 0
A26: =IF($F26=0,"",($F26/$C5)-($R26*$S5+$T26*$T5)) -> -0.006800032 | B26: =IF(F26=0,"",IF(R26=0,"A) "&"---, "&ROUND(($F26/$C5-($R26*$S5))/$T26,2),IF(T26=0,"A) "&ROUND(($F26/$C5)/$R26,2),"A) "&ROUND(($F26/$C5-($T26*$T5))/$R26,2)&", " &ROUND(($F26/$C5-($R26*$S5))/$T26,2)))) -> A) 1.23, 53.34 | D26: =IF($F5="","",$F5) -> Controls ECA | E26: =F26*(1-Q26) -> 3025.5091 | F26: =Elec_Est!F11465+Fire_Stopping_Est!F404 -> 3350.33 | G26: =C5 -> 1 | H26: =$S5 -> 1.231344 | I26: =$T5 -> 53.341822 | J26: =$D$9 -> 27.46 | Q26: 0.0969519 | R26: =Elec_Est!R11465+Fire_Stopping_Est!R404 -> 2486.95 | T26: =Elec_Est!T11465+Fire_Stopping_Est!T404 -> 5.4
A27: =IF($F27=0,"",($F27/$C6)-($R27*$S6+$T27*$T6)) -> -0.004256832 | B27: =IF(F27=0,"",IF(R27=0,"A) "&"---, "&ROUND(($F27/$C6-($R27*$S6))/$T27,2),IF(T27=0,"A) "&ROUND(($F27/$C6)/$R27,2),"A) "&ROUND(($F27/$C6-($T27*$T6))/$R27,2)&", " &ROUND(($F27/$C6-($R27*$S6))/$T27,2)))) -> A) ---, 65.16 | D27: =IF($F6="","",$F6) -> Testing and Commissiong | E27: =F27*(1-Q27) -> 7997.0418 | F27: =Elec_Est!F11466+Fire_Stopping_Est!F405 -> 8855.61 | G27: =C6 -> 1 | H27: =$S6 -> 1.231344 | I27: =$T6 -> 65.162724 | J27: =$D$9 -> 27.46 | Q27: 0.0969519 | R27: =Elec_Est!R11466+Fire_Stopping_Est!R405 -> 0 | T27: =Elec_Est!T11466+Fire_Stopping_Est!T405 -> 135.9
A28: =IF($F28=0,"",($F28/$C7)-($R28*$S7+$T28*$T7)) -> -0.03534904 | B28: =IF(F28=0,"",IF(R28=0,"A) "&"---, "&ROUND(($F28/$C7-($R28*$S7))/$T28,2),IF(T28=0,"A) "&ROUND(($F28/$C7)/$R28,2),"A) "&ROUND(($F28/$C7-($T28*$T7))/$R28,2)&", " &ROUND(($F28/$C7-($R28*$S7))/$T28,2)))) -> A) 1.23, 33.81 | D28: =IF($F7="","",$F7) -> Fire Stopping rates | E28: =F28*(1-Q28) -> 49942.985 | F28: =Elec_Est!F11467+Fire_Stopping_Est!F406 -> 55304.9 | G28: =C7 -> 1 | H28: =$S7 -> 1.231344 | I28: =$T7 -> 33.812706 | J28: =$D$9 -> 27.46 | Q28: 0.0969519 | R28: =Elec_Est!R11467+Fire_Stopping_Est!R406 -> 28788.4 | T28: =Elec_Est!T11467+Fire_Stopping_Est!T406 -> 587.25
A29: =IF($F29=0,"",($F29/$C8)-($R29*$S8+$T29*$T8)) -> 0.0037939126 | B29: =IF(F29=0,"",IF(R29=0,"A) "&"---, "&ROUND(($F29/$C8-($R29*$S8))/$T29,2),IF(T29=0,"A) "&ROUND(($F29/$C8)/$R29,2),"A) "&ROUND(($F29/$C8-($T29*$T8))/$R29,2)&", " &ROUND(($F29/$C8-($R29*$S8))/$T29,2)))) -> A) 1.18, 32.4 | D29: =IF($F8="","",$F8) -> Main Equipment (Gen Set / Main Switchboards) | E29: =F29*(1-Q29) -> 258266.88 | F29: =Elec_Est!F11468+Fire_Stopping_Est!F407 -> 285994.6 | G29: =C8 -> 1 | H29: =$S8 -> 1.180038 | I29: =$T8 -> 32.403843 | J29: =$D$9 -> 27.46 | Q29: 0.0969519 | R29: =Elec_Est!R11468+Fire_Stopping_Est!R407 -> 236420.24 | T29: =Elec_Est!T11468+Fire_Stopping_Est!T407 -> 216.324
A30: =IF($F30=0,"",($F30/$C9)-($R30*$S9+$T30*$T9)) -> -0.019634288 | B30: =IF(F30=0,"",IF(R30=0,"A) "&"---, "&ROUND(($F30/$C9-($R30*$S9))/$T30,2),IF(T30=0,"A) "&ROUND(($F30/$C9)/$R30,2),"A) "&ROUND(($F30/$C9-($T30*$T9))/$R30,2)&", " &ROUND(($F30/$C9-($R30*$S9))/$T30,2)))) -> A) 1.18, 32.4 | D30: =IF($F9="","",$F9) -> DBs and Changeover | E30: =F30*(1-Q30) -> 64335.296 | F30: =Elec_Est!F11469+Fire_Stopping_Est!F408 -> 71242.38 | G30: =C9 -> 1 | H30: =$S9 -> 1.180038 | I30: =$T9 -> 32.403843 | J30: =$D$9 -> 27.46 | Q30: 0.0969519 | R30: =Elec_Est!R11469+Fire_Stopping_Est!R408 -> 50142.734 | T30: =Elec_Est!T11469+Fire_Stopping_Est!T408 -> 372.5505
A31: =IF($F31=0,"",($F31/$C10)-($R31*$S10+$T31*$T10)) -> 1.1836456 | B31: =IF(F31=0,"",IF(R31=0,"A) "&"---, "&ROUND(($F31/$C10-($R31*$S10))/$T31,2),IF(T31=0,"A) "&ROUND(($F31/$C10)/$R31,2),"A) "&ROUND(($F31/$C10-($T31*$T10))/$R31,2)&", " &ROUND(($F31/$C10-($R31*$S10))/$T31,2)))) -> A) 1.18, 32.41 | D31: =IF($F10="","",$F10) -> Armoured Cables | E31: =F31*(1-Q31) -> 319323.99 | F31: =Elec_Est!F11470+Fire_Stopping_Est!F409 -> 353606.85 | G31: =C10 -> 1 | H31: =$S10 -> 1.180038 | I31: =$T10 -> 32.403843 | J31: =$D$9 -> 27.46 | Q31: 0.0969519 | R31: =Elec_Est!R11470+Fire_Stopping_Est!R409 -> 280841.95 | T31: =Elec_Est!T11470+Fire_Stopping_Est!T409 -> 685.15 | V31: Value of Rev A - Discounted | W31: 1615942.8
A32: =IF($F32=0,"",($F32/$C11)-($R32*$S11+$T32*$T11)) | B32: =IF(F32=0,"",IF(R32=0,"A) "&"---, "&ROUND(($F32/$C11-($R32*$S11))/$T32,2),IF(T32=0,"A) "&ROUND(($F32/$C11)/$R32,2),"A) "&ROUND(($F32/$C11-($T32*$T11))/$R32,2)&", " &ROUND(($F32/$C11-($R32*$S11))/$T32,2)))) | D32: =IF($F11="","",$F11) | E32: =F32*(1-Q32) -> 0 | F32: =Elec_Est!F11471+Fire_Stopping_Est!F410 -> 0 | G32: =C11 -> 1 | H32: =$S11 -> 0 | I32: =$T11 -> 0 | J32: =$D$9 -> 27.46 | R32: =Elec_Est!R11471+Fire_Stopping_Est!R410 -> 0 | T32: =Elec_Est!T11471+Fire_Stopping_Est!T410 -> 0
C33: MIXED
X34: changed interval of brackets from 1.2m to 1.5m
A35: Discy.L | B35: =Summary!E54 -> 1478219.1 | E35: =SUM(E23:E32) -> 1478219.1 | F35: =SUM(F23:F32) -> 1636921.8 | R35: =SUM(R23:R32) -> 1126442.6 | T35: =SUM(T23:T32) -> 8716.5265 | V35: =W31-E35 -> 137723.65 | X35: reduced labour for the stainless steel conduit
A36: =IF(A39=0,"0.00",A39-(A38*A37)) -> 0.00 | B36: BOQ TOTAL | E36: ="ESTIM TOTAL (" & $Q$1 & ")" -> ESTIM TOTAL (€) | X36: removed the 5% contingency on all cables
A37: 1.125 | B37: <1 Actual LabCont | R37: =R165 -> 1126454.5 | S37: C.C.Totals | T37: =T165 -> 8703.3967 | X37: reduced the 50% contingency to 10% on fire barriers material cost
B38: <2 Phrs @ 1.00 | X38: deducted 5% discount from NAS Ltd quote
B39: <3 Phrs @ Actual | Q39: Discy.T >> | R39: =R37-R35 -> 11.903889 | S39: PRINT | T39: =T37-T35 -> -13.129731 | X39: reduced mark ups by 5%
X40: reduced rate for galvanised conduit
B41: Values Only on : | D41: 45705 | E41: 2372471.2 | F41: 2372471.2 | R41: 1470470.4 | T41: 11882.59 | V41: =E41-E35 -> 894252.09 | W41: total cost saving | X41: Updated rate in item 7.052 - Data
...

Sheet Elec_Rates
B1: CLIENT: | C1: =ML_Sum!$C1 -> 1 | D1: =ML_Sum!$D1 -> Quintano Foods Ltd. | F1: =ML_Sum!$F1 -> 0 | I1: 1 | J1: =ML_Sum!$J1 -> 1 | K1: =ML_Sum!$K1 -> 1 | L1: =ML_Sum!$L1 -> 1 | M1: =ML_Sum!$M1 -> 1 | N1: =ML_Sum!$N1 -> 1 | O1: =ML_Sum!$O1 -> 1 | Q1: =ML_Sum!$Q1 -> € | R1: R/Lab Cont | S1: =ML_Sum!$S1 -> R | T1: =ML_Sum!$T1 -> 0.9 | U1: =ML_Sum!W1 -> BOQ | V1: INCL | W1: MULT | X1: AREA | Y1: BOQ | Z1: TDWG | AA1: ACT | AB1: DIFF | AD1: 0
B2: PROJECT: | C2: =ML_Sum!$C2 -> 1 | D2: =ML_Sum!$D2 -> Warehouse at tal-Handaq, Qormi | F2: =ML_Sum!$F2 -> Electrical | I2: 2 | J2: =ML_Sum!$J2 -> 1 | K2: =ML_Sum!$K2 -> 1 | L2: =ML_Sum!$L2 -> 1 | M2: =ML_Sum!$M2 -> 1 | N2: =ML_Sum!$N2 -> 1 | O2: =ML_Sum!$O2 -> 1 | Q2: =ML_Sum!$Q2 -> 0 | R2: mu_A | S2: =ML_Sum!$S2 -> 1.231344 | T2: =ML_Sum!$T2 -> 33.812706 | AD2: Electrical
B3: JOB DESC: | C3: =ML_Sum!$C3 -> 1 | D3: =ML_Sum!$D3 -> Electrical and ELV installations (Rev A) | F3: =ML_Sum!$F3 -> ELV Installation (NAS Ltd) | I3: 3 | J3: =ML_Sum!$J3 -> 1 | K3: =ML_Sum!$K3 -> 1 | L3: =ML_Sum!$L3 -> 1 | M3: =ML_Sum!$M3 -> 1 | N3: =ML_Sum!$N3 -> 1 | O3: =ML_Sum!$O3 -> 1 | Q3: =ML_Sum!$Q3 -> 0 | R3: mu_B | S3: =ML_Sum!$S3 -> 1.128732 | T3: =ML_Sum!$T3 -> 30.994981 | AD3: ELV Installation (NAS Ltd)
B4: QUOTE No: | C4: =ML_Sum!$C4 -> 1 | D4: =ML_Sum!$D4 -> EL25-0062A | F4: =ML_Sum!$F4 -> Lightning Protection System (MCE Ltd) | I4: 4 | J4: =ML_Sum!$J4 -> 1 | K4: =ML_Sum!$K4 -> 1 | L4: =ML_Sum!$L4 -> 1 | M4: =ML_Sum!$M4 -> 1 | N4: =ML_Sum!$N4 -> 1 | O4: =ML_Sum!$O4 -> 1 | Q4: =ML_Sum!$Q4 -> 0 | R4: mu_C | S4: =ML_Sum!$S4 -> 1.128732 | T4: =ML_Sum!$T4 -> 30.994981 | AD4: Lightning Protection System (MCE Ltd)
B5: CLIENTs REF: | C5: =ML_Sum!$C5 -> 1 | D5: =ML_Sum!$D5 -> Tender | F5: =ML_Sum!$F5 -> Controls ECA | I5: 5 | J5: =ML_Sum!$J5 -> 1 | K5: =ML_Sum!$K5 -> 1 | L5: =ML_Sum!$L5 -> 1 | M5: =ML_Sum!$M5 -> 1 | N5: =ML_Sum!$N5 -> 1 | O5: =ML_Sum!$O5 -> 1 | Q5: =ML_Sum!$Q5 -> 0 | R5: mu_D | S5: =ML_Sum!$S5 -> 1.231344 | T5: =ML_Sum!$T5 -> 53.341822 | AD5: Controls ECA
B6: VAT/DUTIES: | C6: =ML_Sum!$C6 -> 1 | D6: =ML_Sum!$D6 -> VAT EXCL. | F6: =ML_Sum!$F6 -> Testing and Commissiong | I6: 6 | J6: =ML_Sum!$J6 -> 1 | K6: =ML_Sum!$K6 -> 1 | L6: =ML_Sum!$L6 -> 1 | M6: =ML_Sum!$M6 -> 1 | N6: =ML_Sum!$N6 -> 1 | O6: =ML_Sum!$O6 -> 1 | Q6: =ML_Sum!$Q6 -> 0 | R6: mu_E | S6: =ML_Sum!$S6 -> 1.231344 | T6: =ML_Sum!$T6 -> 65.162724 | AD6: Testing and Commissiong
B7: SAVED ON: | C7: =ML_Sum!$C7 -> 1 | D7: 39364 | F7: =ML_Sum!$F7 -> Fire Stopping rates | I7: 7 | J7: =ML_Sum!$J7 -> 1 | K7: =ML_Sum!$K7 -> 1 | L7: =ML_Sum!$L7 -> 1 | M7: =ML_Sum!$M7 -> 1 | N7: =ML_Sum!$N7 -> 1 | O7: =ML_Sum!$O7 -> 0 | Q7: =ML_Sum!$Q7 -> 0 | R7: mu_F | S7: =ML_Sum!$S7 -> 1.231344 | T7: =ML_Sum!$T7 -> 33.812706 | AD7: Fire Stopping rates
B8: ESTIMATOR: | C8: =ML_Sum!$C8 -> 1 | D8: =ML_Sum!$D8 -> T.Sammut | F8: =ML_Sum!$F8 -> Main Equipment (Gen Set / Main Switchboards) | I8: 8 | J8: =ML_Sum!$J8 -> 1 | K8: =ML_Sum!$K8 -> 1 | L8: =ML_Sum!$L8 -> 1 | M8: =ML_Sum!$M8 -> 1 | N8: =ML_Sum!$N8 -> 1 | O8: =ML_Sum!$O8 -> 0 | Q8: =ML_Sum!$Q8 -> 0 | R8: mu_G | S8: =ML_Sum!$S8 -> 1.180038 | T8: =ML_Sum!$T8 -> 32.403843 | AD8: 0
B9: LABOUR RATE: | C9: =ML_Sum!$C9 -> 1 | D9: =ML_Sum!$D9 -> 27.46 | F9: =ML_Sum!$F9 -> DBs and Changeover | I9: 9 | J9: =ML_Sum!$J9 -> 1 | K9: =ML_Sum!$K9 -> 1 | L9: =ML_Sum!$L9 -> 1 | M9: =ML_Sum!$M9 -> 1 | N9: =ML_Sum!$N9 -> 1 | O9: =ML_Sum!$O9 -> 0 | Q9: =ML_Sum!$Q9 -> 0 | R9: mu_H | S9: =ML_Sum!$S9 -> 1.180038 | T9: =ML_Sum!$T9 -> 32.403843 | AD9: 0
C10: =ML_Sum!$C10 -> 1 | F10: =ML_Sum!$F10 -> Armoured Cables | I10: 10 | J10: =ML_Sum!$J10 -> 1 | K10: =ML_Sum!$K10 -> 1 | L10: =ML_Sum!$L10 -> 1 | M10: =ML_Sum!$M10 -> 1 | N10: =ML_Sum!$N10 -> 1 | O10: =ML_Sum!$O10 -> 1 | Q10: =ML_Sum!$Q10 -> 0 | R10: mu_I | S10: =ML_Sum!$S10 -> 1.180038 | T10: =ML_Sum!$T10 -> 32.403843 | AD10: 0
C11: =ML_Sum!$C11 -> 1 | F11: =ML_Sum!$F11 -> 0 | Q11: =ML_Sum!$Q11 -> 0 | R11: mu_J | S11: =ML_Sum!$S11 -> 0 | T11: =ML_Sum!$T11 -> 0 | AD11: 0
C12: =ML_Sum!$C12 -> 1 | F12: =ML_Sum!$F12 -> 0 | Q12: =ML_Sum!$Q12 -> 0 | R12: MIXED | S12: =ML_Sum!$S12 -> MAT MU | T12: =ML_Sum!$T12 -> LAB RATE | AD12: 0
G13: I_CODE | H13: C_CODE | I13: MAKE | J13: PART_NO | K13: MARKUP | L13: TYPE | M13: LIST_P | N13: P_FACT | O13: FIX | P13: DATE | Q13: %Dsct in BOQ | R13: MU TYPE | S13: MAT MU | T13: LAB RATE
C15: t | D15: Item:
D16: Start Typing Header
Q18: Multip
A19: =(1.5*2)+2.5+5.5+5.5+3.5+3.5+4.5+2.5+2.5+5 -> 38 | B19: =Elec_Est!B11547 -> 225 | D19: 001# Light Point Rate (LSZH Conduit) | F19: Remained as cost saving 1 | K19: RATE | L19: RATE | Q19: =B19/A19 -> 5.9210526 | R19: =IF($B19=0,0,IF($S$1="R",ROUND(R28/$B19,2),R28/$B19)) -> 18.48 | T19: =IF($B19=0,0,IF($S$1="R",ROUND(T28/$B19,2),T28/$B19)) -> 1.34
D20: Based on: | F20: OK | AD20: OK
A21: =$Q$19 *(40+40+18+44) -> 840.78947 | B21: m | D21: Conduit PVC 20mm HG RATE | F21: LSZH - Ramon | G21: COPV_003 | H21: 700 | I21: GEN | J21: 20mm | O21: 1 | P21: 42213 | Q21: 1.8 | R21: =$A21*Q21 -> 1513.4211 | S21: 0.13 | T21: =$A21*S21*$T$1 -> 98.372368 | AD21: LSZH - Ramon
A22: =$Q$19 *((402+455+425+420)) -> 10077.632 | B22: m | D22: Wiring Cable 1c 1.5 mm2 PVC Non-Arm | E22: AJ Electric | F22: LSZH | G22: CASC_017 | H22: 615 | I22: CRO | K22: 02-002 | O22: 2 | P22: 38988 | Q22: =0.2*0.95 -> 0.19 | R22: =$A22*Q22 -> 1914.75 | S22: 0.015 | T22: =$A22*S22*$T$1 -> 136.04803 | AD22: LSZH
A23: =$Q$19 *(4+4+12+12+8+8+8) -> 331.57895 | B23: No | D23: WHITE Ceiling Rose | G23: WACC_037 | H23: 705 | I23: (__) | J23: China | O23: 3 | P23: 39128 | Q23: 0.93 | R23: =$A23*Q23 -> 308.36842 | S23: 0.17 | T23: =$A23*S23*$T$1 -> 50.731579
A24: =$Q$19 *(4+4+12+12+8+8+8) -> 331.57895 | B24: m | D24: Wiring Cable 3c 1.0 mm2 PVC Non-Arm | G24: CAMC_047 | H24: 616 | I24: CRO | J24: 1.0mm2 | K24: 03-001 | O24: 2 | P24: 40767 | Q24: 1.1 | R24: =$A24*Q24 -> 364.73684 | S24: 0.025 | T24: =$A24*S24*$T$1 -> 7.4605263
A25: =$Q$19 *(5) -> 29.605263 | B25: No | D25: WHITE Switch 1G 2W | E25: ESS | F25: SC-CMA401 | G25: WACC_054 | H25: 705 | I25: BG | J25: 912 | O25: 3 | P25: 34669 | Q25: 1.06 | R25: =$A25*Q25 -> 31.381579 | S25: 0.17 | T25: =$A25*S25*$T$1 -> 4.5296053 | AD25: SC-CMA401
A26: =$Q$19 *(4) -> 23.684211 | B26: No | D26: WHITE Switch 2G 2W | E26: ESS | F26: SC-CMA402 | G26: WACC_055 | H26: 705 | I26: BG | J26: 942 | O26: 3 | P26: 34669 | Q26: 1.1 | R26: =$A26*Q26 -> 26.052632 | S26: 0.17 | T26: =$A26*S26*$T$1 -> 3.6236842 | AD26: SC-CMA402
C27: << ==== TOTAL UNITS | R27: =$A27*Q27 -> 0 | T27: =$A27*S27*$T$1 -> 0
A28: d> | B28: =(R27+T27) -> 0 | D28: Sell_A | E28: =IF($B19=0,0,ROUND(ROUND(($R28*$S$2+($T28*$T$2))/$B19, 2)*$C$2,2)) -> 67.96 | F28: =ROUND($B19*$E28,2) -> 15291 | K28: ITEM | L28: ITEM | R28: =SUM(R20:R27) -> 4158.7105 | T28: =SUM(T20:T27) -> 300.76579 | AD28: 17104.5
Q29: Multip
A30: 5 | B30: =Elec_Est!B11548 -> 22 | D30: 002# Maintaned Emergency Light point rate (LSZH Conduit) | F30: Remained as cost saving 1 | K30: RATE | L30: RATE | Q30: =B30/A30 -> 4.4 | R30: =IF($B30=0,0,IF($S$1="R",ROUND(R37/$B30,2),R37/$B30)) -> 12.85 | T30: =IF($B30=0,0,IF($S$1="R",ROUND(T37/$B30,2),T37/$B30)) -> 0.92
D31: Based on: | F31: OK | AD31: OK
A32: =$Q$30 *(5*2) -> 44 | B32: m | D32: Conduit PVC 20mm HG RATE | F32: LSZH - Ramon | G32: COPV_003 | H32: 700 | I32: GEN | J32: 20mm | O32: 1 | P32: 42213 | Q32: 1.8 | R32: =$A32*Q32 -> 79.2 | S32: 0.13 | T32: =$A32*S32*$T$1 -> 5.148 | AD32: LSZH - Ramon
A33: =$Q$30 *(190) -> 836 | B33: m | D33: Wiring Cable 1c 1.5 mm2 PVC Non-Arm | E33: AJ Electric | F33: LSZH | G33: CASC_017 | H33: 615 | I33: CRO | K33: 02-002 | O33: 2 | P33: 38988 | Q33: =0.2*0.95 -> 0.19 | R33: =$A33*Q33 -> 158.84 | S33: 0.015 | T33: =$A33*S33*$T$1 -> 11.286 | AD33: LSZH
A34: =$Q$30 *(5) -> 22 | B34: No | D34: WHITE Ceiling Rose | G34: WACC_037 | H34: 705 | I34: (__) | J34: China | O34: 3 | P34: 39128 | Q34: 0.93 | R34: =$A34*Q34 -> 20.46 | S34: 0.17 | T34: =$A34*S34*$T$1 -> 3.366
A35: =$Q$30 *(5) -> 22 | B35: m | D35: Wiring Cable 3c 1.0 mm2 PVC Non-Arm | G35: CAMC_047 | H35: 616 | I35: CRO | J35: 1.0mm2 | K35: 03-001 | O35: 2 | P35: 40767 | Q35: 1.1 | R35: =$A35*Q35 -> 24.2 | S35: 0.025 | T35: =$A35*S35*$T$1 -> 0.495
C36: << ==== TOTAL UNITS | R36: =$A36*Q36 -> 0 | T36: =$A36*S36*$T$1 -> 0
A37: d> | B37: =(R36+T36) -> 0 | D37: Sell_A | E37: =IF($B30=0,0,ROUND(ROUND(($R37*$S$2+($T37*$T$2))/$B30, 2)*$C$2,2)) -> 47.01 | F37: =ROUND($B30*$E37,2) -> 1034.22 | K37: ITEM | L37: ITEM | R37: =SUM(R31:R36) -> 282.7 | T37: =SUM(T31:T36) -> 20.295 | AD37: 1156.76
Q38: Multip
A39: =5+4+7+15+10+5+3 -> 49 | B39: =Elec_Est!B11549 -> 315 | D39: 003# Power Point Rate (LSZH Conduit) | F39: Updated - reduced | K39: RATE | L39: RATE | Q39: =B39/A39 -> 6.4285714 | R39: =IF($B39=0,0,IF($S$1="R",ROUND(R44/$B39,2),R44/$B39)) -> 18.92 | T39: =IF($B39=0,0,IF($S$1="R",ROUND(T44/$B39,2),T44/$B39)) -> 0.89
D40: Based on: | F40: OK | AD40: OK
A41: =$Q$39 *(22+29+55+30+30+18) -> 1182.8571 | B41: m | D41: Conduit PVC 20mm HG RATE | F41: LSZH - Ramon | G41: COPV_003 | H41: 700 | I41: GEN | J41: 20mm | O41: 1 | P41: 42213 | Q41: 1.8 | R41: =$A41*Q41 -> 2129.1429 | S41: 0.13 | T41: =$A41*S41*$T$1 -> 138.39429 | AD41: LSZH - Ramon
A42: =$Q$39 *((105+195+520+230+105+75)) -> 7907.1429 | B42: m | D42: Wiring Cable 1c 4.0 mm2 PVC Non-Arm | E42: AJ Electric | F42: LSZH | G42: CASC_019 | H42: 615 | I42: CRO | K42: 02-004 | O42: 2 | P42: 38988 | Q42: =0.51*0.95 -> 0.4845 | R42: =$A42*Q42 -> 3831.0107 | S42: 0.02 | T42: =$A42*S42*$T$1 -> 142.32857 | AD42: LSZH
...

Sheet Elec_Est
B1: CLIENT: | C1: =ML_Sum!$C1 -> 1 | D1: =ML_Sum!$D1 -> Quintano Foods Ltd. | F1: =ML_Sum!$F1 -> 0 | I1: 1 | J1: =ML_Sum!$J1 -> 1 | K1: =ML_Sum!$K1 -> 1 | L1: =ML_Sum!$L1 -> 1 | M1: =ML_Sum!$M1 -> 1 | N1: =ML_Sum!$N1 -> 1 | O1: =ML_Sum!$O1 -> 1 | Q1: =ML_Sum!$Q1 -> € | R1: R/Lab Cont | S1: =ML_Sum!$S1 -> R | T1: =ML_Sum!$T1 -> 0.9 | U1: =ML_Sum!W1 -> BOQ | V1: INCL | W1: MULT | X1: AREA | Y1: BOQ | Z1: TDWG | AA1: ACT | AB1: DIFF | AS1: 0
B2: PROJECT: | C2: =ML_Sum!$C2 -> 1 | D2: =ML_Sum!$D2 -> Warehouse at tal-Handaq, Qormi | F2: =ML_Sum!$F2 -> Electrical | I2: 2 | J2: =ML_Sum!$J2 -> 1 | K2: =ML_Sum!$K2 -> 1 | L2: =ML_Sum!$L2 -> 1 | M2: =ML_Sum!$M2 -> 1 | N2: =ML_Sum!$N2 -> 1 | O2: =ML_Sum!$O2 -> 1 | Q2: =ML_Sum!$Q2 -> 0 | R2: mu_A | S2: =ML_Sum!$S2 -> 1.231344 | T2: =ML_Sum!$T2 -> 33.812706 | AS2: Electrical
B3: JOB DESC: | C3: =ML_Sum!$C3 -> 1 | D3: =ML_Sum!$D3 -> Electrical and ELV installations (Rev A) | F3: =ML_Sum!$F3 -> ELV Installation (NAS Ltd) | I3: 3 | J3: =ML_Sum!$J3 -> 1 | K3: =ML_Sum!$K3 -> 1 | L3: =ML_Sum!$L3 -> 1 | M3: =ML_Sum!$M3 -> 1 | N3: =ML_Sum!$N3 -> 1 | O3: =ML_Sum!$O3 -> 1 | Q3: =ML_Sum!$Q3 -> 0 | R3: mu_B | S3: =ML_Sum!$S3 -> 1.128732 | T3: =ML_Sum!$T3 -> 30.994981 | AS3: ELV Installation (NAS Ltd)
B4: QUOTE No: | C4: =ML_Sum!$C4 -> 1 | D4: =ML_Sum!$D4 -> EL25-0062A | F4: =ML_Sum!$F4 -> Lightning Protection System (MCE Ltd) | I4: 4 | J4: =ML_Sum!$J4 -> 1 | K4: =ML_Sum!$K4 -> 1 | L4: =ML_Sum!$L4 -> 1 | M4: =ML_Sum!$M4 -> 1 | N4: =ML_Sum!$N4 -> 1 | O4: =ML_Sum!$O4 -> 1 | Q4: =ML_Sum!$Q4 -> 0 | R4: mu_C | S4: =ML_Sum!$S4 -> 1.128732 | T4: =ML_Sum!$T4 -> 30.994981 | AS4: Lightning Protection System (MCE Ltd)
B5: CLIENTs REF: | C5: =ML_Sum!$C5 -> 1 | D5: =ML_Sum!$D5 -> Tender | F5: =ML_Sum!$F5 -> Controls ECA | I5: 5 | J5: =ML_Sum!$J5 -> 1 | K5: =ML_Sum!$K5 -> 1 | L5: =ML_Sum!$L5 -> 1 | M5: =ML_Sum!$M5 -> 1 | N5: =ML_Sum!$N5 -> 1 | O5: =ML_Sum!$O5 -> 1 | Q5: =ML_Sum!$Q5 -> 0 | R5: mu_D | S5: =ML_Sum!$S5 -> 1.231344 | T5: =ML_Sum!$T5 -> 53.341822 | AS5: Controls ECA
B6: VAT/DUTIES: | C6: =ML_Sum!$C6 -> 1 | D6: =ML_Sum!$D6 -> VAT EXCL. | F6: =ML_Sum!$F6 -> Testing and Commissiong | I6: 6 | J6: =ML_Sum!$J6 -> 1 | K6: =ML_Sum!$K6 -> 1 | L6: =ML_Sum!$L6 -> 1 | M6: =ML_Sum!$M6 -> 1 | N6: =ML_Sum!$N6 -> 1 | O6: =ML_Sum!$O6 -> 1 | Q6: =ML_Sum!$Q6 -> 0 | R6: mu_E | S6: =ML_Sum!$S6 -> 1.231344 | T6: =ML_Sum!$T6 -> 65.162724 | AS6: Testing and Commissiong
B7: SAVED ON: | C7: =ML_Sum!$C7 -> 1 | D7: 39364 | F7: =ML_Sum!$F7 -> Fire Stopping rates | I7: 7 | J7: =ML_Sum!$J7 -> 1 | K7: =ML_Sum!$K7 -> 1 | L7: =ML_Sum!$L7 -> 1 | M7: =ML_Sum!$M7 -> 1 | N7: =ML_Sum!$N7 -> 1 | O7: =ML_Sum!$O7 -> 0 | Q7: =ML_Sum!$Q7 -> 0 | R7: mu_F | S7: =ML_Sum!$S7 -> 1.231344 | T7: =ML_Sum!$T7 -> 33.812706 | AS7: Fire Stopping rates
B8: ESTIMATOR: | C8: =ML_Sum!$C8 -> 1 | D8: =ML_Sum!$D8 -> T.Sammut | F8: =ML_Sum!$F8 -> Main Equipment (Gen Set / Main Switchboards) | I8: 8 | J8: =ML_Sum!$J8 -> 1 | K8: =ML_Sum!$K8 -> 1 | L8: =ML_Sum!$L8 -> 1 | M8: =ML_Sum!$M8 -> 1 | N8: =ML_Sum!$N8 -> 1 | O8: =ML_Sum!$O8 -> 0 | Q8: =ML_Sum!$Q8 -> 0 | R8: mu_G | S8: =ML_Sum!$S8 -> 1.180038 | T8: =ML_Sum!$T8 -> 32.403843 | AS8: Main Equipment (Gen Set / Main Switchboards)
B9: LABOUR RATE: | C9: =ML_Sum!$C9 -> 1 | D9: =ML_Sum!$D9 -> 27.46 | F9: =ML_Sum!$F9 -> DBs and Changeover | I9: 9 | J9: =ML_Sum!$J9 -> 1 | K9: =ML_Sum!$K9 -> 1 | L9: =ML_Sum!$L9 -> 1 | M9: =ML_Sum!$M9 -> 1 | N9: =ML_Sum!$N9 -> 1 | O9: =ML_Sum!$O9 -> 0 | Q9: =ML_Sum!$Q9 -> 0 | R9: mu_H | S9: =ML_Sum!$S9 -> 1.180038 | T9: =ML_Sum!$T9 -> 32.403843 | AS9: 0
C10: =ML_Sum!$C10 -> 1 | F10: =ML_Sum!$F10 -> Armoured Cables | I10: 10 | J10: =ML_Sum!$J10 -> 1 | K10: =ML_Sum!$K10 -> 1 | L10: =ML_Sum!$L10 -> 1 | M10: =ML_Sum!$M10 -> 1 | N10: =ML_Sum!$N10 -> 1 | O10: =ML_Sum!$O10 -> 1 | Q10: =ML_Sum!$Q10 -> 0 | R10: mu_I | S10: =ML_Sum!$S10 -> 1.180038 | T10: =ML_Sum!$T10 -> 32.403843 | AS10: 0
C11: =ML_Sum!$C11 -> 1 | F11: =ML_Sum!$F11 -> 0 | Q11: =ML_Sum!$Q11 -> 0 | R11: mu_J | S11: =ML_Sum!$S11 -> 0 | T11: =ML_Sum!$T11 -> 0 | AS11: 0
C12: =ML_Sum!$C12 -> 1 | F12: =ML_Sum!$F12 -> 0 | Q12: =ML_Sum!$Q12 -> 0 | R12: MIXED | S12: =ML_Sum!$S12 -> MAT MU | T12: =ML_Sum!$T12 -> LAB RATE | AS12: 0
G13: ISELL | H13: C_CODE | I13: MAKE | J13: PART_NO | K13: MARKUP | L13: TYPE | M13: LIST_P | N13: P_FACT | O13: FIX | P13: DATE | Q13: %Dsct in BOQ | R13: MU TYPE | S13: MAT MU | T13: LAB RATE | AM13: Tot Mat Cost | AN13: Unit Lab phr. | AO13: Tot Lab phr. | AP13: < for ELM / MEE
K14: TB
C15: t | D15: Item: 1
D16: PRELIMINARIES
K18: TB
C19: t
D20: All equipment to be used within this contract is to be approved prior to delivery to site.
E22: Sell Rate | F22: Sell Total | K22: IB | AG22: U_M_Sell | AH22: T_M_Sell | AI22: U_L_Sell | AJ22: T_L_Sell | AK22: Total_Sell | AM22: T_M_Cost | AN22: T_L_Phr | AO22: Mat/Lab=1 | AS22: Sell Total
A23: 1 | B23: L.S. | D23: Item: 1.001 | E23: =IF(AND($A23=0,$A$1="DIF"),0, ROUND(ROUND(($R27*$S$2+($T27*$T$2))/A23,2)*$C$2,2)) -> 2462.69 | F23: =ROUND($A23*$E23,2) -> 2462.69 | G23: ISELL | K23: mu_A | L23: ITEM | T23: =IF(AND($R27=0,$T27=0),"0.00","mu :" & ROUND($F23/$C$2/($R27+$T27*$D$9),2)) -> mu :1.23 | AG23: =IF($E23=0,0,ROUND($R27*$S$2*$C$2/$A23,2)) -> 2462.69 | AH23: =$AG23*$A23 -> 2462.69 | AI23: =$E23-$AG23 -> 0 | AJ23: =$A23*$AI23 -> 0 | AK23: =ROUND(($AG23+$AI23)*$A23,2) -> 2462.69 | AM23: =ROUND(R27,2) -> 2000 | AN23: =ROUND(T27,2) -> 0 | AO23: =ROUND(AM23+AN23,2)*A23 -> 2000 | AR23: 1 | AS23: 2462.69
D24: Mobilisation of site including the setting up of Storage facilities for materials, Sanitary facilities for the employees, Setting up of temporary site office, etc required to undertake the works
A25: 1 | B25: No | D25: Mobilisation | G25: DOCS_001 | H25: 880 | I25: (__) | O25: 3 | Q25: 2000 | R25: =$A25*Q25 -> 2000 | T25: =$A25*S25*$T$1 -> 0 | AR25: 1
R26: =$A26*Q26 -> 0 | T26: =$A26*S26*$T$1 -> 0
A27: d> | B27: =(R26+T26) -> 0 | G27: ICOST | K27: mu_A | L27: ITEM | R27: =SUM(R24:R26) -> 2000 | T27: =SUM(T24:T26) -> 0 | AR27: d>
E28: Sell Rate | F28: Sell Total | K28: IB | AG28: U_M_Sell | AH28: T_M_Sell | AI28: U_L_Sell | AJ28: T_L_Sell | AK28: Total_Sell | AM28: T_M_Cost | AN28: T_L_Phr | AO28: Mat/Lab=1 | AS28: Sell Total
A29: 1 | B29: L.S. | D29: Item: 1.002 | E29: =IF(AND($A29=0,$A$1="DIF"),0, ROUND(ROUND(($R37*$S$2+($T37*$T$2))/$A29,2)*$C$2,2)) -> 0 | F29: =ROUND($A29*$E29,2) -> 0 | G29: ISELL | K29: mu_A | L29: ITEM | Q29: Included | T29: =IF(AND($R37=0,$T37=0),"0.00","mu: "& ROUND(F29/$C$2/($R37+$T37*$D$9),2)) -> 0.00 | AG29: =IF($E29=0,0,ROUND($R37*$S$2*$C$2/$A29,2)) -> 0 | AH29: =$AG29*$A29 -> 0 | AI29: =$E29-$AG29 -> 0 | AJ29: =$A29*$AI29 -> 0 | AK29: =ROUND(($AG29+$AI29)*$A29,2) -> 0 | AM29: =ROUND(R37,2) -> 0 | AN29: =ROUND(T37,2) -> 0 | AO29: =ROUND(AM29+AN29,2)*A29 -> 0 | AR29: 1 | AS29: 0
