Workbook
Name _N: #REF!
Name _N: #REF!
Name A: #REF!
Name A: #REF!
Name Access_BMS: [2]BMS_Estimate!#REF!
Name Access_Control: [3]Elec_Est!#REF!
Name Access_Supply: [2]BMS_Estimate!#REF!
Name Access_Wiring: [2]BMS_Estimate!#REF!
Name ANS: #REF!
Name AREAS: [4]ML_Sum!$X$1:$AD$16
Name AREAS: [3]ML_Sum!$X$1:$AD$16
Name AREAS: #REF!
Name AREAS: ML_Sum!$X$1:$AD$16
Name C_: #REF!
Name C_: #REF!
Name CCTV: [3]Elec_Est!#REF!
Name Data: [3]Elec_Est!#REF!
Name DATA_SYSTEM: #REF!
Name DATA_SYSTEM: #REF!
Name DD_Head_Foot: [5]!T_HeadFoot[Head-Foot]
Name Electrical: Elec_Est!$D$16
Name FIRE_ALARM: #REF!
Name Fire_Alarm: [3]Elec_Est!#REF!
Name FireAlarm: Elec_Est!$D$750
Name FO: [3]Elec_Est!#REF!
Name Guard: [3]Elec_Est!#REF!
Name Intercom: [3]Elec_Est!#REF!
Name Intruder_Alarm: [3]Elec_Est!#REF!
Name LIGHTNING_PROTECTION: #REF!
Name LIGHTNING_PROTECTION: #REF!
Name Persons: [6]Estimate!#REF!
Name Persons: [6]Estimate!#REF!
Name RAMON: #REF!
Name RAMON: #REF!
Name RMS: Elec_Est!$D$478
Name T: #REF!
Name T: #REF!
Name Telephone: Elec_Est!$D$368
Name Traffic_Barriers: [2]BMS_Estimate!#REF!
Name Z: #REF!
Name Z: #REF!

Sheet Notes
A1: NOTES
A3: 1 | B3: BOQ Item 2.007 | C3: Push button for bathroom switch to REMS. The Push button is included in items 5.005 and 5.014
A5: 2 | B5: BOQ Item 2.020 | C5: We have allowed for HILTI Fire stop and Acoustically insulation PUTTY PADS
A7: 3 | B7: BOQ Item 2.027 | C7: The Data outlets are included in item 3.002
A9: 4 | B9: BOQ Item 2.033 | C9: We have assumed that the light fittings provided are to be assembled and marked by type. The rate is not applicable for chandeliers or sophisticated light fixtures.
A11: 5 | B11: BOQ Item 2.031 | C11: Install and connect bedroom profile. We have not quoted for this item because we do not have the details.
A13: 6 | B13: BOQ Item 3.002 | C13: We have allowed for the Cat6 U/UTP Cable including Single DATA Outlets in champagne colour finish as manufactured by Legrand.
A15: 7 | B15: BOQ Item 3.004 | C15: We have allowed for 1No Cat6 U/UTP Cable between the room network switch and the corridor. Since, there is no reference in the BOQ for the room network switch, we are assuming that it will be supplied and installed by others.
A17: 8 | B17: BOQ Item 3.005 | C17: Provisional Extend item above to closest data point in Sample room building. Since the cable length between the DATA Cabinet and the room network switch cannot be measured, we have quoted for a rate per meter for the supply and installation of Cat6 U/UTP Cable.
A19: 9 | B19: BOQ Item 10.002 | C19: Fire Alarm Cable. We have allowed for single run of fire resistant cable in conduit between the corridor above the room main door and the detector located in the sitting room.
A21: 10 | C21: AC Inhibit would be via Digital Output direct to Cassette in the case of the sample room. In the full installation this would be better accomplished using the AC central controller system.

Sheet Material_List
A1: Sunny Coast Hotel - Sample Room Material List
A2: QTY | B2: UNIT | C2: MATERIAL DESCRIPTION | D2: C/CODE
A3: 5 | B3: No | C3: 10A 2P 230VAC Coil Contactor Price included in REMS section BOQ | D3: 510
A4: =SUBTOTAL(9,A3:A3) -> 5 | B4: No | C4: 10A 2P 230VAC Coil Contactor Price included in REMS section BOQ | D4: 510
A5: 5 | B5: No | C5: 10A 2P 30mA RCBO | D5: 510
A6: =SUBTOTAL(9,A5:A5) -> 5 | B6: No | C6: 10A 2P 30mA RCBO | D6: 510
A7: 1 | B7: No | C7: 15 Module Enclosure C/W Earth and Neutral Bars | D7: 510
A8: =SUBTOTAL(9,A7:A7) -> 1 | B8: No | C8: 15 Module Enclosure C/W Earth and Neutral Bars | D8: 510
A9: 2 | B9: No | C9: 16A 2P 30mA RCBO | D9: 510
A10: =SUBTOTAL(9,A9:A9) -> 2 | B10: No | C10: 16A 2P 30mA RCBO | D10: 510
A11: 2 | B11: No | C11: 25A 2P 30mA RCBO | D11: 510
A12: =SUBTOTAL(9,A11:A11) -> 2 | B12: No | C12: 25A 2P 30mA RCBO | D12: 510
A13: 1 | B13: No | C13: 32A 2P MCB Incomer | D13: 510
A14: =SUBTOTAL(9,A13:A13) -> 1 | B14: No | C14: 32A 2P MCB Incomer | D14: 510
A15: 1 | B15: No | C15: 45 Module Enclosure C/W Earth and Neutral Bars | D15: 510
A16: =SUBTOTAL(9,A15:A15) -> 1 | B16: No | C16: 45 Module Enclosure C/W Earth and Neutral Bars | D16: 510
A17: 1 | B17: No | C17: 63A 2P 230VAC Coil Contactor | D17: 510
A18: =SUBTOTAL(9,A17:A17) -> 1 | B18: No | C18: 63A 2P 230VAC Coil Contactor | D18: 510
A19: 1 | B19: No | C19: 6A 2P 30mA RCBO | D19: 510
A20: =SUBTOTAL(9,A19:A19) -> 1 | B20: No | C20: 6A 2P 30mA RCBO | D20: 510
A21: 2 | B21: No | C21: Energy kWHr Meter with Modbus | D21: 510
A22: =SUBTOTAL(9,A21:A21) -> 2 | B22: No | C22: Energy kWHr Meter with Modbus | D22: 510
A23: 30 | B23: No | C23: Screw Terminal Block 1.5mm Grey | D23: 510
A24: =SUBTOTAL(9,A23:A23) -> 30 | B24: No | C24: Screw Terminal Block 1.5mm Grey | D24: 510
A25: 496.51724 | B25: m | C25: Wiring Cable 1c 1.5 mm2 PVC Non-Arm | D25: 615
A26: 99 | B26: m | C26: Wiring Cable 1c 1.5 mm2 PVC Non-Arm | D26: 615
A27: =SUBTOTAL(9,A25:A26) -> 595.51724 | B27: m | C27: Wiring Cable 1c 1.5 mm2 PVC Non-Arm | D27: 615
A28: 302.16667 | B28: m | C28: Wiring Cable 1c 2.5 mm2 PVC Non-Arm | D28: 615
A29: =SUBTOTAL(9,A28:A28) -> 302.16667 | B29: m | C29: Wiring Cable 1c 2.5 mm2 PVC Non-Arm | D29: 615
A30: 66.5 | B30: m | C30: Wiring Cable 1c 4.0 mm2 PVC Non-Arm | D30: 615
A31: =SUBTOTAL(9,A30:A30) -> 66.5 | B31: m | C31: Wiring Cable 1c 4.0 mm2 PVC Non-Arm | D31: 615
A32: 209.53286 | B32: m | C32: Wiring Cable 2c 0.75 mm2 LSZH | D32: 616
A33: =SUBTOTAL(9,A32:A32) -> 209.53286 | B33: m | C33: Wiring Cable 2c 0.75 mm2 LSZH | D33: 616
A34: 25 | B34: m | C34: Wiring Cable 3c 4.0 mm2 PVC/PVC Non-Arm ESS QN SQ61863 | D34: 616
A35: =SUBTOTAL(9,A34:A34) -> 25 | B35: m | C35: Wiring Cable 3c 4.0 mm2 PVC/PVC Non-Arm ESS QN SQ61863 | D35: 616
A36: 52 | B36: m | C36: Data Cable 4Pr UTP CAT6 Robert Bondin | D36: 617
A37: 5 | B37: m | C37: Data Cable 4Pr UTP CAT6 Robert Bondin | D37: 617
A38: =SUBTOTAL(9,A36:A37) -> 57 | B38: m | C38: Data Cable 4Pr UTP CAT6 Robert Bondin | D38: 617
A39: 6 | B39: No | C39: Cable Lug 4.0 mm2 | D39: 620
A40: =SUBTOTAL(9,A39:A39) -> 6 | B40: No | C40: Cable Lug 4.0 mm2 | D40: 620
...

Sheet LSZH_Conduit
A1: KOUVIDIS - MEDISOL HF CONDUIT (For MFA Project)
E2: KOUVIDS HF Conduit System
E3: FCA | F3: 0.95
A4: Item | B4: Description | C4: Unit | D4: Qty | E4: Unit Price | G4: Total Price
A5: 1 | B5: 3m x 20mm HF Medium type Conduit (Ref. 1005020) | C5: Lenghts | D5: 3600 | E5: =0.595*2.9 -> 1.7255 | F5: =E5*$F$3 -> 1.639225 | G5: =D5*F5 -> 5901.21
A6: 2 | B6: 20mm HF Coupler (Ref. 4001020) | C6: No | D6: 1000 | E6: 0.084 | F6: =E6*$F$3 -> 0.0798 | G6: =D6*F6 -> 79.8
A7: 3 | B7: 20mm HF Bend (Ref. 4015020) | C7: No | D7: 500 | E7: 0.545 | F7: =E7*$F$3 -> 0.51775 | G7: =D7*F7 -> 258.875
A8: 4 | B8: 82x82x43mm HF Watertight Box (Ref. 3001020) | C8: No | D8: 300 | E8: 1.174 | F8: =E8*$F$3 -> 1.1153 | G8: =D8*F8 -> 334.59
A9: 5 | B9: 20mm HF Adaptor for Watertight Box (Ref. 4005020) | C9: No | D9: 500 | E9: 0.074 | F9: =E9*$F$3 -> 0.0703 | G9: =D9*F9 -> 35.15
A10: 6 | B10: 20mm HF Conduit Clip (Ref. 4003020) | C10: No | D10: 700 | E10: 0.096 | F10: =E10*$F$3 -> 0.0912 | G10: =D10*F10 -> 63.84
A11: 7 | B11: 3m x 25mm HF Medium type Conduit (Ref. 1005025) | C11: Lenghts | D11: 120 | E11: =0.889*2.9 -> 2.5781 | F11: =E11*$F$3 -> 2.449195 | G11: =D11*F11 -> 293.9034
A12: 8 | B12: 25mm HF Coupler (Ref. 4001025) | C12: No | D12: 50 | E12: 0.116 | F12: =E12*$F$3 -> 0.1102 | G12: =D12*F12 -> 5.51
A13: 9 | B13: 25mm HF Bend (Ref. 4015025) | C13: No | D13: 50 | E13: 0.983 | F13: =E13*$F$3 -> 0.93385 | G13: =D13*F13 -> 46.6925
A14: 10 | B14: 101x101x51mm HF Watertight Box (Ref. 3001025) | C14: No | D14: 50 | E14: 1.916 | F14: =E14*$F$3 -> 1.8202 | G14: =D14*F14 -> 91.01
A15: 11 | B15: 25mm HF Adaptor for Watertight Box (Ref. 4005025) | C15: No | D15: 150 | E15: 0.167 | F15: =E15*$F$3 -> 0.15865 | G15: =D15*F15 -> 23.7975
A16: 12 | B16: 25mm HF Conduit Clip (Ref. 4003025) | C16: No | D16: 200 | E16: 0.148 | F16: =E16*$F$3 -> 0.1406 | G16: =D16*F16 -> 28.12
A17: 13 | B17: 20mm Flexible Conduit (MEDIFLEX HF 33442) Part No. 2005020 | C17: m | D17: 300 | E17: 0.414 | F17: =E17*$F$3 -> 0.3933 | G17: =D17*F17 -> 117.99
A18: 14 | B18: 25mm Flexible Conduit (MEDIFLEX HF 33442) Part No. 2005025 | C18: m | D18: 100 | E18: 0.616 | F18: =E18*$F$3 -> 0.5852 | G18: =D18*F18 -> 58.52
G20: =SUM(G5:G19) -> 7339.0084
D24: cost/total | E24: m | F24: cost/m
C25: 20mm HF Medium type Conduit | D25: =SUM(G5:G10) -> 6673.465 | E25: =3600*2.9 -> 10440 | F25: =D25/E25 -> 0.63922079 | G25: =F25*$G$35 -> 0.67216064 | H25: /m
C26: 25mm HF Medium type Conduit | D26: =SUM(G11:G16) -> 489.0334 | E26: =120*2.9 -> 348 | F26: =D26/E26 -> 1.4052684 | G26: =F26*$G$35 -> 1.4776836 | H26: /m
C27: 20mm Flexible Conduit (MEDIFLEX HF 33442) Part No. 2005020 | D27: =G17 -> 117.99 | E27: 300 | F27: =D27/E27 -> 0.3933 | G27: =F27*$G$35 -> 0.41356725 | H27: /m
C28: 25mm Flexible Conduit (MEDIFLEX HF 33442) Part No. 2005025 | D28: =G18 -> 58.52 | E28: 100 | F28: =D28/E28 -> 0.5852 | G28: =F28*$G$35 -> 0.61535609 | H28: /m
D30: Stock Order | G30: For MFA
C31: KOUVIDIS PO 100033 | D31: 33183.74 | G31: 7339.01 | H31: Cost excluding the shipping
C32: Shipping and Delivery Cost | D32: 1710 | G32: =G31/D31*D32 -> 378.18845 | H32: Shipping cost
C33: Total | D33: =D31+D32 -> 34893.74 | G33: =G31+G32 -> 7717.1984 | H33: Total Cost
F35: Multiplying factor for the shipping | G35: =G33/G31 -> 1.0515313

Sheet Takeoffs_PVC
A2: System: Single Phase Power PVC Conduit | B2: Circuit No.s
A3: Description | B3: R1 | C3: R2 | D3: R3 | E3: R4 | F3: R5 | G3: R6 | H3: R7 | I3: R8 | K3: Factor | L3: Total
A4: 20mm PVC Conduit | B4: =9*0.359+1.5+1.5 -> 6.231 | C4: =16*0.359+0.5+1.5 -> 7.744 | D4: =16*0.359+0.5+1.5 -> 7.744 | E4: =11*0.359+0.5+1.5 -> 5.949 | F4: =((16+8+9+9+12)*0.359)+2+6 -> 27.386 | G4: =((5+10+10+2+2)*0.359)+2+5 -> 17.411 | H4: =40*0.359+0.5+1.5 -> 16.36 | I4: =14*0.359+0.5+1.5 -> 7.026 | L4: =SUM(B4:J4) -> 95.851
A5: 20mm PVC Couplers | B5: =ROUND(B4/3,0) -> 2 | C5: =ROUND(C4/3,0) -> 3 | D5: =ROUND(D4/3,0) -> 3 | E5: =ROUND(E4/3,0) -> 2 | F5: =ROUND(F4/3,0) -> 9 | G5: =ROUND(G4/3,0) -> 6 | H5: =ROUND(H4/3,0) -> 5 | I5: =ROUND(I4/3,0) -> 2 | J5: =ROUND(J4/3,0) -> 0 | L5: =SUM(B5:J5) -> 32
A6: 20mm PVC Adaptors | B6: =B10*2 -> 2 | C6: =C10*2 -> 2 | D6: =D10*2 -> 4 | E6: =E10*2 -> 2 | F6: =F10*2 -> 0 | G6: =G10*2 -> 0 | H6: =H10*2 -> 2 | I6: =I10*2 -> 2 | J6: =J10*2 -> 0 | L6: =SUM(B6:J6) -> 14
A7: 25mm PVC Conduit | L7: =SUM(B7:J7) -> 0
A8: 25mm PVC Couplers | B8: =ROUND(B7/3,0) -> 0 | C8: =ROUND(C7/3,0) -> 0 | D8: =ROUND(D7/3,0) -> 0 | E8: =ROUND(E7/3,0) -> 0 | F8: =ROUND(F7/3,0) -> 0 | G8: =ROUND(G7/3,0) -> 0 | H8: =ROUND(H7/3,0) -> 0 | I8: =ROUND(I7/3,0) -> 0 | J8: =ROUND(J7/3,0) -> 0 | L8: =SUM(B8:J8) -> 0
A9: 25mm PVC Adaptors | B9: =B13*2 -> 0 | C9: =C13*2 -> 0 | D9: =D13*2 -> 0 | E9: =E13*2 -> 0 | F9: =F13*2 -> 0 | G9: =G13*2 -> 0 | H9: =H13*2 -> 0 | I9: =I13*2 -> 0 | J9: =J13*2 -> 0 | L9: =SUM(B9:J9) -> 0
A10: 75x75mm PVC Box | B10: =B25+B27+B28 -> 1 | C10: =C25+C27+C28 -> 1 | D10: =D25+D27+D28 -> 2 | E10: =E25+E27+E28 -> 1 | F10: =F25+F27+F28 -> 0 | G10: =G25+G27+G28 -> 0 | H10: =H25+H27+H28 -> 1 | I10: =I25+I27+I28 -> 1 | J10: =J25+J27+J28 -> 0 | L10: =SUM(B10:J10) -> 7
A11: 150x75mm PVC Box | B11: =B26 -> 0 | C11: =C26 -> 0 | D11: =D26 -> 0 | E11: =E26 -> 0 | F11: =F26 -> 6 | G11: =G26 -> 5 | H11: =H26 -> 0 | I11: =I26 -> 0 | J11: =J26 -> 0 | L11: =SUM(B11:J11) -> 11
A12: 20mm PVC Circular Terminal Box | L12: =SUM(B12:J12) -> 0
A13: 20mm PVC Circular Angle Box | L13: =SUM(B13:J13) -> 0
A14: 20mm PVC Circular Through Box | L14: =SUM(B14:J14) -> 0
A15: 20mm PVC Circular Tee Box | L15: =SUM(B15:J15) -> 0
A16: 20mm PVC. Circular Cover | L16: =SUM(B16:J16) -> 0
A17: 4mm Brass Screws | B17: =B12+B13+B14+B15+B16 -> 0 | C17: =C12+C13+C14+C15+C16 -> 0 | D17: =D12+D13+D14+D15+D16 -> 0 | E17: =E12+E13+E14+E15+E16 -> 0 | F17: =F12+F13+F14+F15+F16 -> 0 | G17: =G12+G13+G14+G15+G16 -> 0 | H17: =H12+H13+H14+H15+H16 -> 0 | I17: =I12+I13+I14+I15+I16 -> 0 | J17: =J12+J13+J14+J15+J16 -> 0 | L17: =SUM(B17:J17) -> 0
A18: 20mm PVC Spacer Saddles | B18: =B4 -> 6.231 | C18: =C4 -> 7.744 | D18: =D4 -> 7.744 | E18: =E4 -> 5.949 | F18: =F4 -> 27.386 | G18: =G4 -> 17.411 | H18: =H4 -> 16.36 | I18: =I4 -> 7.026 | J18: =J4 -> 0 | L18: =SUM(B18:J18) -> 95.851
A19: 25mm PVC Spacer Saddles | B19: =B7 -> 0 | C19: =C7 -> 0 | D19: =D7 -> 0 | E19: =E7 -> 0 | F19: =F7 -> 0 | G19: =G7 -> 0 | H19: =H7 -> 0 | I19: =I7 -> 0 | J19: =J7 -> 0 | L19: =SUM(B19:J19) -> 0
A20: Wood Screws & Rawl Plugs S6 | B20: =B18+B10+B11+B11+B12+B13+B14+B15+B19 -> 7.231 | C20: =C18+C10+C11+C11+C12+C13+C14+C15+C19 -> 8.744 | D20: =D18+D10+D11+D11+D12+D13+D14+D15+D19 -> 9.744 | E20: =E18+E10+E11+E11+E12+E13+E14+E15+E19 -> 6.949 | F20: =F18+F10+F11+F11+F12+F13+F14+F15+F19 -> 39.386 | G20: =G18+G10+G11+G11+G12+G13+G14+G15+G19 -> 27.411 | H20: =H18+H10+H11+H11+H12+H13+H14+H15+H19 -> 17.36 | I20: =I18+I10+I11+I11+I12+I13+I14+I15+I19 -> 8.026 | J20: =J18+J10+J11+J11+J12+J13+J14+J15+J19 -> 0 | L20: =SUM(B20:J20) -> 124.851
A22: 2.5sq mm PVC Cable | B22: =(B4*3)*1.1 -> 20.5623 | C22: =(C4*3)*1.1 -> 25.5552 | D22: =(D4*3)*1.1 -> 25.5552 | E22: =(E4*3)*1.1 -> 19.6317 | F22: =(F4*3)*1.1 -> 90.3738 | H22: =(H4*3)*1.1 -> 53.988 | I22: =(I4*3)*1.1 -> 23.1858 | L22: =SUM(B22:J22) -> 258.852
A23: 4sq mm PVC Cable | G23: =(G4*3)*1.1 -> 57.4563 | L23: =SUM(B23:J23) -> 57.4563
A25: 13A Twin IP65 Socket Outlet | L25: =SUM(B25:J25) -> 0
A26: 13A Twin Switched Socket Outlet | F26: 6 | G26: 5 | L26: =SUM(B26:J26) -> 11
A27: 13A DP Fused Connection Unit | B27: 1 | C27: 1 | D27: 2 | E27: 1 | H27: 1 | I27: 1 | L27: =SUM(B27:J27) -> 7
A28: 13A Flex Outlet | L28: =SUM(B28:J28) -> 0
L29: =SUM(B29:J29) -> 0
A31: Power Point | B31: =B25+B26+B27 -> 1 | C31: =C25+C26+C27 -> 1 | D31: =D25+D26+D27 -> 2 | E31: =E25+E26+E27 -> 1 | F31: =F25+F26+F27 -> 6 | G31: =G25+G26+G27 -> 5 | H31: =H25+H26+H27 -> 1 | I31: =I25+I26+I27 -> 1 | J31: =J25+J26+J27 -> 0 | K31: 1 | L31: =SUM(B31:J31)*K31 -> 18
A32: 13A Flex Outlet | B32: =B28 -> 0 | C32: =C28 -> 0 | D32: =D28 -> 0 | E32: =E28 -> 0 | F32: =F28 -> 0 | G32: =G28 -> 0 | H32: =H28 -> 0 | I32: =I28 -> 0 | J32: =J28 -> 0 | K32: 0.5 | L32: =SUM(B32:J32)*K32 -> 0
L33: =SUM(L31:L32) -> 18

Sheet Elec_Rates
B1: CLIENT: | C1: =ML_Sum!$C1 -> 1 | D1: =ML_Sum!$D1 -> SUNCREST HOTELS plc | F1: =ML_Sum!$F1 -> 0 | I1: 1 | J1: =ML_Sum!$J1 -> 1 | K1: =ML_Sum!$K1 -> 1 | L1: =ML_Sum!$L1 -> 1 | M1: =ML_Sum!$M1 -> 1 | N1: =ML_Sum!$N1 -> 1 | O1: =ML_Sum!$O1 -> 1 | Q1: =ML_Sum!$Q1 -> € | R1: R/Lab Cont | S1: =ML_Sum!$S1 -> R | T1: =ML_Sum!$T1 -> 1 | U1: =ML_Sum!W1 -> BOQ | V1: INCL | W1: MULT | X1: AREA | Y1: BOQ | Z1: TDWG | AA1: ACT | AB1: DIFF
B2: PROJECT: | C2: =ML_Sum!$C2 -> 1 | D2: =ML_Sum!$D2 -> Sunny Cost and Lido Redevelopment | F2: =ML_Sum!$F2 -> Electrical | I2: 2 | J2: =ML_Sum!$J2 -> 1 | K2: =ML_Sum!$K2 -> 1 | L2: =ML_Sum!$L2 -> 1 | M2: =ML_Sum!$M2 -> 1 | N2: =ML_Sum!$N2 -> 1 | O2: =ML_Sum!$O2 -> 1 | Q2: =ML_Sum!$Q2 -> 0 | R2: mu_A | S2: =ML_Sum!$S2 -> 1 | T2: =ML_Sum!$T2 -> 28.833
B3: JOB DESC: | C3: =ML_Sum!$C3 -> 1 | D3: =ML_Sum!$D3 -> Sample Room - Electrical | F3: =ML_Sum!$F3 -> Controls Section (Guy) | I3: 3 | J3: =ML_Sum!$J3 -> 1 | K3: =ML_Sum!$K3 -> 1 | L3: =ML_Sum!$L3 -> 1 | M3: =ML_Sum!$M3 -> 1 | N3: =ML_Sum!$N3 -> 1 | O3: =ML_Sum!$O3 -> 1 | Q3: =ML_Sum!$Q3 -> 0 | R3: mu_B | S3: =ML_Sum!$S3 -> 1 | T3: =ML_Sum!$T3 -> 33
B4: QUOTE No: | C4: =ML_Sum!$C4 -> 1 | D4: =ML_Sum!$D4 -> EL25-0700 | F4: =ML_Sum!$F4 -> Controls Section (Engineer) | I4: 4 | J4: =ML_Sum!$J4 -> 1 | K4: =ML_Sum!$K4 -> 1 | L4: =ML_Sum!$L4 -> 1 | M4: =ML_Sum!$M4 -> 1 | N4: =ML_Sum!$N4 -> 1 | O4: =ML_Sum!$O4 -> 1 | Q4: =ML_Sum!$Q4 -> 0 | R4: mu_C | S4: =ML_Sum!$S4 -> 1 | T4: =ML_Sum!$T4 -> 30
B5: CLIENTs REF: | C5: =ML_Sum!$C5 -> 1 | D5: =ML_Sum!$D5 -> Sample Room | F5: =ML_Sum!$F5 -> Fire Alarm (Josef) | I5: 5 | J5: =ML_Sum!$J5 -> 1 | K5: =ML_Sum!$K5 -> 1 | L5: =ML_Sum!$L5 -> 1 | M5: =ML_Sum!$M5 -> 1 | N5: =ML_Sum!$N5 -> 1 | O5: =ML_Sum!$O5 -> 1 | Q5: =ML_Sum!$Q5 -> 0 | R5: mu_D | S5: =ML_Sum!$S5 -> 1 | T5: =ML_Sum!$T5 -> 28.833
B6: VAT/DUTIES: | C6: =ML_Sum!$C6 -> 1 | D6: =ML_Sum!$D6 -> VAT EXCL. | F6: =ML_Sum!$F6 -> 0 | I6: 6 | J6: =ML_Sum!$J6 -> 1 | K6: =ML_Sum!$K6 -> 1 | L6: =ML_Sum!$L6 -> 1 | M6: =ML_Sum!$M6 -> 1 | N6: =ML_Sum!$N6 -> 1 | O6: =ML_Sum!$O6 -> 1 | Q6: =ML_Sum!$Q6 -> 0 | R6: mu_E | S6: =ML_Sum!$S6 -> 0 | T6: =ML_Sum!$T6 -> 0
B7: SAVED ON: | C7: =ML_Sum!$C7 -> 1 | D7: 39364 | F7: =ML_Sum!$F7 -> 0 | I7: 7 | J7: =ML_Sum!$J7 -> 1 | K7: =ML_Sum!$K7 -> 1 | L7: =ML_Sum!$L7 -> 1 | M7: =ML_Sum!$M7 -> 1 | N7: =ML_Sum!$N7 -> 1 | O7: =ML_Sum!$O7 -> 0 | Q7: =ML_Sum!$Q7 -> 0 | R7: mu_F | S7: =ML_Sum!$S7 -> 0 | T7: =ML_Sum!$T7 -> 0
B8: ESTIMATOR: | C8: =ML_Sum!$C8 -> 1 | D8: =ML_Sum!$D8 -> R.Farrugia | F8: =ML_Sum!$F8 -> 0 | I8: 8 | J8: =ML_Sum!$J8 -> 1 | K8: =ML_Sum!$K8 -> 1 | L8: =ML_Sum!$L8 -> 1 | M8: =ML_Sum!$M8 -> 1 | N8: =ML_Sum!$N8 -> 1 | O8: =ML_Sum!$O8 -> 0 | Q8: =ML_Sum!$Q8 -> 0 | R8: mu_G | S8: =ML_Sum!$S8 -> 0 | T8: =ML_Sum!$T8 -> 0
B9: LABOUR RATE: | C9: =ML_Sum!$C9 -> 1 | D9: =ML_Sum!$D9 -> 28.833 | F9: =ML_Sum!$F9 -> 0 | I9: 9 | J9: =ML_Sum!$J9 -> 1 | K9: =ML_Sum!$K9 -> 1 | L9: =ML_Sum!$L9 -> 1 | M9: =ML_Sum!$M9 -> 1 | N9: =ML_Sum!$N9 -> 1 | O9: =ML_Sum!$O9 -> 0 | Q9: =ML_Sum!$Q9 -> 0 | R9: mu_H | S9: =ML_Sum!$S9 -> 0 | T9: =ML_Sum!$T9 -> 0
C10: =ML_Sum!$C10 -> 1 | F10: =ML_Sum!$F10 -> 0 | I10: 10 | J10: =ML_Sum!$J10 -> 1 | K10: =ML_Sum!$K10 -> 1 | L10: =ML_Sum!$L10 -> 1 | M10: =ML_Sum!$M10 -> 1 | N10: =ML_Sum!$N10 -> 1 | O10: =ML_Sum!$O10 -> 1 | Q10: =ML_Sum!$Q10 -> 0 | R10: mu_I | S10: =ML_Sum!$S10 -> 0 | T10: =ML_Sum!$T10 -> 0
C11: =ML_Sum!$C11 -> 1 | F11: =ML_Sum!$F11 -> 0 | Q11: =ML_Sum!$Q11 -> 0 | R11: mu_J | S11: =ML_Sum!$S11 -> 0 | T11: =ML_Sum!$T11 -> 0
C12: =ML_Sum!$C12 -> 1 | F12: =ML_Sum!$F12 -> 0 | Q12: =ML_Sum!$Q12 -> 0 | R12: MIXED | S12: =ML_Sum!$S12 -> MAT MU | T12: =ML_Sum!$T12 -> LAB RATE
G13: I_CODE | H13: C_CODE | I13: MAKE | J13: PART_NO | K13: MARKUP | L13: TYPE | M13: LIST_P | N13: P_FACT | O13: FIX | P13: DATE | Q13: %Dsct in BOQ | R13: MU TYPE | S13: MAT MU | T13: LAB RATE
Q14: Multip
A15: 12 | B15: =Elec_Est!B893 -> 12 | D15: 001# REMS LSZH Conduit | K15: RATE | L15: RATE | Q15: =B15/A15 -> 1 | R15: =IF($B15=0,0,IF($S$1="R",ROUND(R22/$B15,2),R22/$B15)) -> 3.58 | T15: =IF($B15=0,0,IF($S$1="R",ROUND(T22/$B15,2),T22/$B15)) -> 0.5
D16: Based on:
A17: =$Q$15 *(18) -> 18 | B17: m | D17: 20mm Conduit LSZH - RATE | G17: COPV_003 | H17: 700 | I17: GEN | J17: 20mm | O17: 1 | P17: 42213 | Q17: 0.67 | R17: =$A17*Q17 -> 12.06 | S17: =0.845 *(0.13) -> 0.10985 | T17: =$A17*S17*$T$1 -> 1.9773
A18: =$Q$15 *(17) -> 17 | B18: m | D18: 25mm Conduit LSZH - RATE | G18: COPV_007 | H18: 700 | I18: GEN | J18: 25mm | O18: 1 | P18: 42213 | Q18: 1.41 | R18: =$A18*Q18 -> 23.97 | S18: =0.845 *(0.18) -> 0.1521 | T18: =$A18*S18*$T$1 -> 2.5857
A19: =$Q$15 *(12) -> 12 | B19: m | D19: 20mm Flexible Conduit LSZH - RATE | G19: COPV_003 | H19: 700 | I19: GEN | J19: 20mm | O19: 1 | P19: 42213 | Q19: 0.41 | R19: =$A19*Q19 -> 4.92 | S19: =0.845 *(0.13) -> 0.10985 | T19: =$A19*S19*$T$1 -> 1.3182
A20: =$Q$15 *(1) -> 1 | B20: No | D20: Conduit PVC Gypsum Box 75*75mm | G20: COPV_017 | H20: 700 | I20: (__) | J20: 75*75mm | O20: 1 | P20: 38146 | Q20: 1.98 | R20: =$A20*Q20 -> 1.98 | S20: =0.845 *(0.13) -> 0.10985 | T20: =$A20*S20*$T$1 -> 0.10985
C21: << ==== TOTAL UNITS | R21: =$A21*Q21 -> 0 | T21: =$A21*S21*$T$1 -> 0
A22: d> | B22: =(R22+T22)-SUM(R16:R21,T16:T21) -> 0 | D22: Sell_A | E22: =IF($B15=0,0,ROUND(ROUND(($R22*$S$2+($T22*$T$2))/$B15, 2)*$C$2,2)) -> 17.97 | F22: =ROUND($B15*$E22,2) -> 215.64 | K22: ITEM | L22: ITEM | R22: =SUM(R16:R21) -> 42.93 | T22: =SUM(T16:T21) -> 5.99105
Q23: Multip
A24: 14 | B24: =Elec_Est!B894 -> 20 | D24: 002# REMS LSZH Cable | K24: RATE | L24: RATE | Q24: =B24/A24 -> 1.4285714 | R24: =IF($B24=0,0,IF($S$1="R",ROUND(R28/$B24,2),R28/$B24)) -> 6.29 | T24: =IF($B24=0,0,IF($S$1="R",ROUND(T28/$B24,2),T28/$B24)) -> 0.18
D25: Based on:
A26: =$Q$24 *(((95+32+8+12+9+2+6+30+4+6+20+1+22)*0.359)+58) -> 209.53286 | B26: m | D26: Wiring Cable 2c 0.75 mm2 LSZH | G26: CAMC_041 | H26: 616 | I26: CRO | J26: 1.0mm2 | K26: 02-001 | O26: 2 | Q26: 0.6 | R26: =$A26*Q26 -> 125.71971 | S26: =0.845 *(0.02) -> 0.0169 | T26: =$A26*S26*$T$1 -> 3.5411053
C27: << ==== TOTAL UNITS | R27: =$A27*Q27 -> 0 | T27: =$A27*S27*$T$1 -> 0
A28: d> | B28: =(R27+T27) -> 0 | D28: Sell_A | E28: =IF($B24=0,0,ROUND(ROUND(($R28*$S$2+($T28*$T$2))/$B24, 2)*$C$2,2)) -> 11.39 | F28: =ROUND($B24*$E28,2) -> 227.8 | K28: ITEM | L28: ITEM | R28: =SUM(R25:R27) -> 125.71971 | T28: =SUM(T25:T27) -> 3.5411053
Q29: Multip
A30: 29 | B30: =Elec_Est!B895 -> 35 | D30: 003# Lighting Point in LSZH Conduit | K30: RATE | L30: RATE | Q30: =B30/A30 -> 1.2068966 | R30: =IF($B30=0,0,IF($S$1="R",ROUND(R36/$B30,2),R36/$B30)) -> 4.26 | T30: =IF($B30=0,0,IF($S$1="R",ROUND(T36/$B30,2),T36/$B30)) -> 0.48
D31: Based on:
A32: =$Q$30 *(50) -> 60.344828 | B32: m | D32: 20mm Conduit LSZH - RATE | G32: COPV_003 | H32: 700 | I32: GEN | J32: 20mm | O32: 1 | P32: 42213 | Q32: 0.67 | R32: =$A32*Q32 -> 40.431034 | S32: =0.845 *(0.13) -> 0.10985 | T32: =$A32*S32*$T$1 -> 6.6288793
A33: =$Q$30 *(29) -> 35 | B33: m | D33: 20mm Flexible Conduit LSZH - RATE | G33: COPV_003 | H33: 700 | I33: GEN | J33: 20mm | O33: 1 | P33: 42213 | Q33: 0.41 | R33: =$A33*Q33 -> 14.35 | S33: =0.845 *(0.13) -> 0.10985 | T33: =$A33*S33*$T$1 -> 3.84475
A34: =$Q$30 *((50*4+29*6)*1.1) -> 496.51724 | B34: m | D34: Wiring Cable 1c 1.5 mm2 PVC Non-Arm | G34: CASC_017 | H34: 615 | I34: CRO | K34: 02-002 | O34: 2 | P34: 38988 | Q34: 0.19 | R34: =$A34*Q34 -> 94.338276 | S34: =0.845 *(0.015) -> 0.012675 | T34: =$A34*S34*$T$1 -> 6.293356
C35: << ==== TOTAL UNITS | R35: =$A35*Q35 -> 0 | T35: =$A35*S35*$T$1 -> 0
A36: d> | B36: =(R35+T35) -> 0 | D36: Sell_A | E36: =IF($B30=0,0,ROUND(ROUND(($R36*$S$2+($T36*$T$2))/$B30, 2)*$C$2,2)) -> 18.07 | F36: =ROUND($B30*$E36,2) -> 632.45 | K36: ITEM | L36: ITEM | R36: =SUM(R31:R35) -> 149.11931 | T36: =SUM(T31:T35) -> 16.766985
Q37: Multip
A38: 18 | B38: =Elec_Est!B896 -> 21 | D38: 004# Power Point in LSZH Conduit | K38: RATE | L38: RATE | Q38: =B38/A38 -> 1.1666667 | R38: =IF($B38=0,0,IF($S$1="R",ROUND(R44/$B38,2),R44/$B38)) -> 9.52 | T38: =IF($B38=0,0,IF($S$1="R",ROUND(T44/$B38,2),T44/$B38)) -> 0.88
D39: Based on:
A40: =$Q$38 *(96) -> 112 | B40: m | D40: 20mm Conduit LSZH - RATE | G40: COPV_003 | H40: 700 | I40: GEN | J40: 20mm | O40: 1 | P40: 42213 | Q40: 0.67 | R40: =$A40*Q40 -> 75.04 | S40: =0.845 *(0.13) -> 0.10985 | T40: =$A40*S40*$T$1 -> 12.3032
...

Sheet Elec_Est
B1: CLIENT: | C1: =ML_Sum!$C1 -> 1 | D1: =ML_Sum!$D1 -> SUNCREST HOTELS plc | F1: =ML_Sum!$F1 -> 0 | I1: 1 | J1: =ML_Sum!$J1 -> 1 | K1: =ML_Sum!$K1 -> 1 | L1: =ML_Sum!$L1 -> 1 | M1: =ML_Sum!$M1 -> 1 | N1: =ML_Sum!$N1 -> 1 | O1: =ML_Sum!$O1 -> 1 | Q1: =ML_Sum!$Q1 -> € | R1: R/Lab Cont | S1: =ML_Sum!$S1 -> R | T1: =ML_Sum!$T1 -> 1 | U1: =ML_Sum!W1 -> BOQ | V1: INCL | W1: MULT | X1: AREA | Y1: BOQ | Z1: TDWG | AA1: ACT | AB1: DIFF
B2: PROJECT: | C2: =ML_Sum!$C2 -> 1 | D2: =ML_Sum!$D2 -> Sunny Cost and Lido Redevelopment | F2: =ML_Sum!$F2 -> Electrical | I2: 2 | J2: =ML_Sum!$J2 -> 1 | K2: =ML_Sum!$K2 -> 1 | L2: =ML_Sum!$L2 -> 1 | M2: =ML_Sum!$M2 -> 1 | N2: =ML_Sum!$N2 -> 1 | O2: =ML_Sum!$O2 -> 1 | Q2: =ML_Sum!$Q2 -> 0 | R2: mu_A | S2: =ML_Sum!$S2 -> 1 | T2: =ML_Sum!$T2 -> 28.833
B3: JOB DESC: | C3: =ML_Sum!$C3 -> 1 | D3: =ML_Sum!$D3 -> Sample Room - Electrical | F3: =ML_Sum!$F3 -> Controls Section (Guy) | I3: 3 | J3: =ML_Sum!$J3 -> 1 | K3: =ML_Sum!$K3 -> 1 | L3: =ML_Sum!$L3 -> 1 | M3: =ML_Sum!$M3 -> 1 | N3: =ML_Sum!$N3 -> 1 | O3: =ML_Sum!$O3 -> 1 | Q3: =ML_Sum!$Q3 -> 0 | R3: mu_B | S3: =ML_Sum!$S3 -> 1 | T3: =ML_Sum!$T3 -> 33
B4: QUOTE No: | C4: =ML_Sum!$C4 -> 1 | D4: =ML_Sum!$D4 -> EL25-0700 | F4: =ML_Sum!$F4 -> Controls Section (Engineer) | I4: 4 | J4: =ML_Sum!$J4 -> 1 | K4: =ML_Sum!$K4 -> 1 | L4: =ML_Sum!$L4 -> 1 | M4: =ML_Sum!$M4 -> 1 | N4: =ML_Sum!$N4 -> 1 | O4: =ML_Sum!$O4 -> 1 | Q4: =ML_Sum!$Q4 -> 0 | R4: mu_C | S4: =ML_Sum!$S4 -> 1 | T4: =ML_Sum!$T4 -> 30
B5: CLIENTs REF: | C5: =ML_Sum!$C5 -> 1 | D5: =ML_Sum!$D5 -> Sample Room | F5: =ML_Sum!$F5 -> Fire Alarm (Josef) | I5: 5 | J5: =ML_Sum!$J5 -> 1 | K5: =ML_Sum!$K5 -> 1 | L5: =ML_Sum!$L5 -> 1 | M5: =ML_Sum!$M5 -> 1 | N5: =ML_Sum!$N5 -> 1 | O5: =ML_Sum!$O5 -> 1 | Q5: =ML_Sum!$Q5 -> 0 | R5: mu_D | S5: =ML_Sum!$S5 -> 1 | T5: =ML_Sum!$T5 -> 28.833
B6: VAT/DUTIES: | C6: =ML_Sum!$C6 -> 1 | D6: =ML_Sum!$D6 -> VAT EXCL. | F6: =ML_Sum!$F6 -> 0 | I6: 6 | J6: =ML_Sum!$J6 -> 1 | K6: =ML_Sum!$K6 -> 1 | L6: =ML_Sum!$L6 -> 1 | M6: =ML_Sum!$M6 -> 1 | N6: =ML_Sum!$N6 -> 1 | O6: =ML_Sum!$O6 -> 1 | Q6: =ML_Sum!$Q6 -> 0 | R6: mu_E | S6: =ML_Sum!$S6 -> 0 | T6: =ML_Sum!$T6 -> 0
B7: SAVED ON: | C7: =ML_Sum!$C7 -> 1 | D7: 39364 | F7: =ML_Sum!$F7 -> 0 | I7: 7 | J7: =ML_Sum!$J7 -> 1 | K7: =ML_Sum!$K7 -> 1 | L7: =ML_Sum!$L7 -> 1 | M7: =ML_Sum!$M7 -> 1 | N7: =ML_Sum!$N7 -> 1 | O7: =ML_Sum!$O7 -> 0 | Q7: =ML_Sum!$Q7 -> 0 | R7: mu_F | S7: =ML_Sum!$S7 -> 0 | T7: =ML_Sum!$T7 -> 0
B8: ESTIMATOR: | C8: =ML_Sum!$C8 -> 1 | D8: =ML_Sum!$D8 -> R.Farrugia | F8: =ML_Sum!$F8 -> 0 | I8: 8 | J8: =ML_Sum!$J8 -> 1 | K8: =ML_Sum!$K8 -> 1 | L8: =ML_Sum!$L8 -> 1 | M8: =ML_Sum!$M8 -> 1 | N8: =ML_Sum!$N8 -> 1 | O8: =ML_Sum!$O8 -> 0 | Q8: =ML_Sum!$Q8 -> 0 | R8: mu_G | S8: =ML_Sum!$S8 -> 0 | T8: =ML_Sum!$T8 -> 0
B9: LABOUR RATE: | C9: =ML_Sum!$C9 -> 1 | D9: =ML_Sum!$D9 -> 28.833 | F9: =ML_Sum!$F9 -> 0 | I9: 9 | J9: =ML_Sum!$J9 -> 1 | K9: =ML_Sum!$K9 -> 1 | L9: =ML_Sum!$L9 -> 1 | M9: =ML_Sum!$M9 -> 1 | N9: =ML_Sum!$N9 -> 1 | O9: =ML_Sum!$O9 -> 0 | Q9: =ML_Sum!$Q9 -> 0 | R9: mu_H | S9: =ML_Sum!$S9 -> 0 | T9: =ML_Sum!$T9 -> 0
C10: =ML_Sum!$C10 -> 1 | F10: =ML_Sum!$F10 -> 0 | I10: 10 | J10: =ML_Sum!$J10 -> 1 | K10: =ML_Sum!$K10 -> 1 | L10: =ML_Sum!$L10 -> 1 | M10: =ML_Sum!$M10 -> 1 | N10: =ML_Sum!$N10 -> 1 | O10: =ML_Sum!$O10 -> 1 | Q10: =ML_Sum!$Q10 -> 0 | R10: mu_I | S10: =ML_Sum!$S10 -> 0 | T10: =ML_Sum!$T10 -> 0
C11: =ML_Sum!$C11 -> 1 | F11: =ML_Sum!$F11 -> 0 | Q11: =ML_Sum!$Q11 -> 0 | R11: mu_J | S11: =ML_Sum!$S11 -> 0 | T11: =ML_Sum!$T11 -> 0
C12: =ML_Sum!$C12 -> 1 | F12: =ML_Sum!$F12 -> 0 | Q12: =ML_Sum!$Q12 -> 0 | R12: MIXED | S12: =ML_Sum!$S12 -> MAT MU | T12: =ML_Sum!$T12 -> LAB RATE
G13: ISELL | H13: C_CODE | I13: MAKE | J13: PART_NO | K13: MARKUP | L13: TYPE | M13: LIST_P | N13: P_FACT | O13: FIX | P13: DATE | Q13: %Dsct in BOQ | R13: MU TYPE | S13: MAT MU | T13: LAB RATE | AM13: Tot Mat Cost | AN13: Unit Lab phr. | AO13: Tot Lab phr. | AP13: < for ELM / MEE
K14: TB
C15: t
D16: ELECTRICAL INSTALLATION
E18: Sell Rate | F18: Sell Total | K18: IB | AG18: U_M_Sell | AH18: T_M_Sell | AI18: U_L_Sell | AJ18: T_L_Sell | AK18: Total_Sell | AM18: T_M_Cost | AN18: T_L_Phr | AO18: Mat/Lab=1
A19: 1 | B19: LS | D19: Item: 2 | E19: =IF(AND($A19=0,$A$1="DIF"),0, ROUND(ROUND(($R24*$S$2+($T24*$T$2))/A19,2)*$C$2,2)) -> 0 | F19: =ROUND($A19*$E19,2) -> 0 | G19: ISELL | K19: mu_A | L19: ITEM | Q19: INC | T19: =IF(AND($R24=0,$T24=0),"0.00","mu :" & ROUND($F19/$C$2/($R24+$T24*$D$9),2)) -> 0.00 | AG19: =IF($E19=0,0,ROUND($R24*$S$2*$C$2/$A19,2)) -> 0 | AH19: =$AG19*$A19 -> 0 | AI19: =$E19-$AG19 -> 0 | AJ19: =$A19*$AI19 -> 0 | AK19: =ROUND(($AG19+$AI19)*$A19,2) -> 0 | AM19: =ROUND(R24,2) -> 0 | AN19: =ROUND(T24,2) -> 0 | AO19: =ROUND(AM19+AN19,2)*A19 -> 0
D20: Take over design , reengineer and produce coordinated working drawings | K20: n
R21: =$A21*Q21 -> 0 | T21: =$A21*S21*$T$1 -> 0
D22: INC | R22: =$A22*Q22 -> 0 | T22: =$A22*S22*$T$1 -> 0
R23: =$A23*Q23 -> 0 | T23: =$A23*S23*$T$1 -> 0
A24: d> | B24: =(R23+T23) -> 0 | G24: ICOST | K24: mu_A | L24: ITEM | R24: =SUM(R20:R23) -> 0 | T24: =SUM(T20:T23) -> 0
K25: TB
C26: t
D27: Power Cables
K29: TB
C30: t
D31: Supply, install and connect the following supply cables on cable tray or clipped to wall, including all cleats, brass compression glands, terminal lugs etc., for a complete system.
K33: TB
C34: t
D35: From LOCAL DB to the Sample room DB
E37: Sell Rate | F37: Sell Total | K37: IB | AG37: U_M_Sell | AH37: T_M_Sell | AI37: U_L_Sell | AJ37: T_L_Sell | AK37: Total_Sell | AM37: T_M_Cost | AN37: T_L_Phr | AO37: Mat/Lab=1
A38: 25 | B38: m | D38: Item: 2.001 | E38: =IF(AND($A38=0,$A$1="DIF"),0, ROUND(ROUND(($R46*$S$2+($T46*$T$2))/A38,2)*$C$2,2)) -> 3.56 | F38: =ROUND($A38*$E38,2) -> 89 | G38: ISELL | K38: mu_A | L38: ITEM | T38: =IF(AND($R46=0,$T46=0),"0.00","mu :" & ROUND($F38/$C$2/($R46+$T46*$D$9),2)) -> mu :1 | AG38: =IF($E38=0,0,ROUND($R46*$S$2*$C$2/$A38,2)) -> 2.07 | AH38: =$AG38*$A38 -> 51.75 | AI38: =$E38-$AG38 -> 1.49 | AJ38: =$A38*$AI38 -> 37.25 | AK38: =ROUND(($AG38+$AI38)*$A38,2) -> 89 | AM38: =ROUND(R46,2) -> 51.69 | AN38: =ROUND(T46,2) -> 1.29 | AO38: =ROUND(AM38+AN38,2)*A38 -> 1324.5
D39: 3c4mm2 FG16 | K39: n
A40: 25 | B40: m | D40: Wiring Cable 3c 4.0 mm2 PVC/PVC Non-Arm | F40: ESS QN SQ61863 | G40: CAMC_050 | H40: 616 | I40: CRO | J40: 4.0mm2 | K40: 03-006 | O40: 2 | Q40: =1.77*1.1 -> 1.947 | R40: =$A40*Q40 -> 48.675 | S40: =0.845 *(0.03) -> 0.02535 | T40: =$A40*S40*$T$1 -> 0.63375
A41: 25 | B41: No | D41: Cable Tie 225mm | G41: CONS_009 | H41: 875 | I41: (__) | K41: 01-003 | O41: 1 | P41: 34669 | Q41: 0.05 | R41: =$A41*Q41 -> 1.25 | T41: =$A41*S41*$T$1 -> 0
A42: 2 | B42: No | D42: M25 PVC Gland | G42: CAAC_027 | H42: 620 | I42: (__) | O42: 2 | P42: 35431 | Q42: 0.6 | R42: =$A42*Q42 -> 1.2 | S42: =0.845 *(0.3) -> 0.2535 | T42: =$A42*S42*$T$1 -> 0.507
A43: 6 | B43: No | D43: Cable Lug 4.0 mm2 | G43: CAAC_007 | H43: 620 | I43: CTT | O43: 2 | P43: 34669 | Q43: 0.06 | R43: =$A43*Q43 -> 0.36 | S43: =0.845 *(0.03) -> 0.02535 | T43: =$A43*S43*$T$1 -> 0.1521
A44: 2 | B44: No | D44: Cable Marker Wrap Around Type | G44: CAAC_025 | H44: 620 | I44: (__) | O44: 2 | Q44: 0.1 | R44: =$A44*Q44 -> 0.2 | T44: =$A44*S44*$T$1 -> 0
...

Sheet ML_Sum
B1: CLIENT: | C1: 1 | D1: SUNCREST HOTELS plc | G1: TRUE | H1: TRUE | I1: 1 | J1: =$Q109 -> 1 | K1: =$Q119 -> 1 | L1: =$Q129 -> 1 | M1: =$Q139 -> 1 | N1: =$Q149 -> 1 | O1: =$Q159 -> 1 | Q1: =IF(C1=1,"€","Curr?") -> € | R1: Recon /Lab.Cont >> | S1: =IF($S$39="PRINT","R","Do Not Print") -> R | T1: 1 | V1: {=IF(OR(X1=AREAS),1,0)} -> 1 | W1: BOQ | X1: x | Y1: x | Z1: x | AA1: x | AB1: x | AC1: x | AD1: x
B2: PROJECT: | C2: =IF($D$6="VAT INCLUDED",1.18,1)*(1-$Q2)*$C$1 -> 1 | D2: Sunny Cost and Lido Redevelopment | F2: Electrical | G2: TRUE | I2: 2 | J2: =$Q110 -> 1 | K2: =$Q120 -> 1 | L2: =$Q130 -> 1 | M2: =$Q140 -> 1 | N2: =$Q150 -> 1 | O2: =$Q160 -> 1 | R2: ="A) " & IF($S2=0,"",ROUND($S2,2) & "-" & ROUND($T2/$D$9,2)) -> A) 1-1 | S2: 1 | T2: =$S2*$D$9 -> 28.833 | X2: x | Y2: x | Z2: x | AA2: x | AB2: x | AC2: x | AD2: x
B3: JOB DESC: | C3: =IF($D$6="VAT INCLUDED",1.18,1)*(1-$Q3)*$C$1 -> 1 | D3: Sample Room - Electrical | F3: Controls Section (Guy) | G3: TRUE | I3: 3 | J3: =$Q111 -> 1 | K3: =$Q121 -> 1 | L3: =$Q131 -> 1 | M3: =$Q141 -> 1 | N3: =$Q151 -> 1 | O3: =$Q161 -> 1 | R3: ="B) " & IF($S3=0,"",ROUND($S3,2) & "-" & ROUND($T3/$D$9,2)) -> B) 1-1.14 | S3: 1 | T3: =$S3*$D$10 -> 33 | X3: x | Y3: x | Z3: x | AA3: x | AB3: x | AC3: x | AD3: x
B4: INT. QUOT No: | C4: =IF($D$6="VAT INCLUDED",1.18,1)*(1-$Q4)*$C$1 -> 1 | D4: EL25-0700 | F4: Controls Section (Engineer) | G4: TRUE | I4: 4 | J4: =$Q112 -> 1 | K4: =$Q122 -> 1 | L4: =$Q132 -> 1 | M4: =$Q142 -> 1 | N4: =$Q152 -> 1 | O4: =$Q162 -> 1 | R4: ="C) " & IF($S4=0,"",ROUND($S4,2) & "-" & ROUND($T4/$D$9,2)) -> C) 1-1.04 | S4: 1 | T4: =$S4*$D$11 -> 30 | X4: x | Y4: x | Z4: x | AA4: x | AB4: x | AC4: x | AD4: x
B5: CLIENTs REF: | C5: =IF($D$6="VAT INCLUDED",1.18,1)*(1-$Q5)*$C$1 -> 1 | D5: Sample Room | F5: Fire Alarm (Josef) | G5: TRUE | I5: 5 | J5: =$Q113 -> 1 | K5: =$Q123 -> 1 | L5: =$Q133 -> 1 | M5: =$Q143 -> 1 | N5: =$Q153 -> 1 | O5: =$Q163 -> 1 | R5: ="D) " & IF($S5=0,"",ROUND($S5,2) & "-" & ROUND($T5/$D$9,2)) -> D) 1-1 | S5: 1 | T5: =$S5*$D$9 -> 28.833 | X5: x | Y5: x | Z5: x | AA5: x | AB5: x | AC5: x | AD5: x
B6: VAT: | C6: =IF($D$6="VAT INCLUDED",1.18,1)*(1-$Q6)*$C$1 -> 1 | D6: VAT EXCL. | G6: TRUE | I6: 6 | J6: =$Q114 -> 1 | K6: =$Q124 -> 1 | L6: =$Q134 -> 1 | M6: =$Q144 -> 1 | N6: =$Q154 -> 1 | O6: =$Q164 -> 1 | R6: ="E) " & IF($S6=0,"",ROUND($S6,2) & "-" & ROUND($T6/$D$9,2)) -> E) | X6: x | Y6: x | Z6: x | AA6: x | AB6: x | AC6: x | AD6: x
B7: SAVED ON: | C7: =IF($D$6="VAT INCLUDED",1.18,1)*(1-$Q7)*$C$1 -> 1 | D7: 45978 | G7: TRUE | I7: 7 | J7: =$Q115 -> 1 | K7: =$Q125 -> 1 | L7: =$Q135 -> 1 | M7: =$Q145 -> 1 | N7: =$Q155 -> 1 | R7: ="F) " & IF($S7=0,"",ROUND($S7,2) & "-" & ROUND($T7/$D$9,2)) -> F) | X7: x | Y7: x | Z7: x | AA7: x | AB7: x | AC7: x | AD7: x
B8: ESTIMATOR: | C8: =IF($D$6="VAT INCLUDED",1.18,1)*(1-$Q8)*$C$1 -> 1 | D8: R.Farrugia | G8: TRUE | I8: 8 | J8: =$Q116 -> 1 | K8: =$Q126 -> 1 | L8: =$Q136 -> 1 | M8: =$Q146 -> 1 | N8: =$Q156 -> 1 | R8: ="G) " & IF($S8=0,"",ROUND($S8,2) & "-" & ROUND($T8/$D$9,2)) -> G) | X8: x | Y8: x | Z8: x | AA8: x | AB8: x | AC8: x | AD8: x
B9: LAB. COST: | C9: =IF($D$6="VAT INCLUDED",1.18,1)*(1-$Q9)*$C$1 -> 1 | D9: 28.833 | E9: Cost for 2026 | G9: TRUE | I9: 9 | J9: =$Q117 -> 1 | K9: =$Q127 -> 1 | L9: =$Q137 -> 1 | M9: =$Q147 -> 1 | N9: =$Q157 -> 1 | R9: ="H) " & IF($S9=0,"",ROUND($S9,2) & "-" & ROUND($T9/$D$9,2)) -> H) | X9: x | Y9: x | Z9: x | AA9: x | AB9: x | AC9: x | AD9: x
C10: =IF($D$6="VAT INCLUDED",1.18,1)*(1-$Q10)*$C$1 -> 1 | D10: 33 | E10: Cost BMS Pair Technician | G10: TRUE | I10: 10 | J10: =$Q118 -> 1 | K10: =$Q128 -> 1 | L10: =$Q138 -> 1 | M10: =$Q148 -> 1 | N10: =$Q158 -> 1 | O10: =Q108 -> 1 | R10: =" I) " & IF($S10=0,"",ROUND($S10,2) & "-" & ROUND($T10/$D$9,2)) -> I) | X10: x | Y10: x | Z10: x | AA10: x | AB10: x | AC10: x | AD10: x
C11: =IF($D$6="VAT INCLUDED",1.18,1)*(1-$Q11)*$C$1 -> 1 | D11: 30 | E11: Cost BMS Single Engineer | R11: ="J) " & IF($S11=0,"",ROUND($S11,2) & "-" & ROUND($T11/$D$9,2)) -> J) | X11: x | Y11: x | Z11: x | AA11: x | AB11: x | AC11: x | AD11: x
C12: =IF($D$6="VAT INCLUDED",1.18,1)*(1-$Q12)*$C$1 -> 1 | G12: SYSTEMS | H12: SYSTEMS | I12: SYSTEMS | J12: SYSTEMS | K12: SYSTEMS | L12: SYSTEMS | M12: SYSTEMS | N12: SYSTEMS | O12: SYSTEMS | P12: SYSTEMS | R12: MIXED - X,Y ) | S12: MAT MU | T12: LAB RATE | X12: x | Y12: x | Z12: x | AA12: x | AB12: x | AC12: x | AD12: x
B13: MATERIAL & LABOUR SUMMARY | G13: ItemCode | H13: CostCode | I13: MAKE | J13: PART_NO | K13: MARKUP | L13: TYPE | M13: LIST_P | N13: SET | O13: FIX | P13: DATE | Q13: %Dsct in BOQ | R13: MATMU-LABMU | S13: MAT CONT >> | T13: =SUM(Q108:Q164)/57 -> 1
B14: =IF($D$6<>"VAT EXCL.", "QUOTE ISSUED WITH VAT INCLUDED", "") | X14: x | Y14: x | Z14: x | AA14: x | AB14: x | AC14: x | AD14: x
Q15: =(C72-F35)/C72 -> 0 | R15: Average Discount applied in BOQ (Q2-Q12) | X15: x | Y15: x | Z15: x | AA15: x | AB15: x | AC15: x | AD15: x
B16: =IF($W$1<>"BOQ", "DIFF SET TO " & W1,"") | Q16: =(F35-E35)/F35 -> 0 | R16: Average Discount applied on Totals (Q23-Q32) | X16: x | Y16: x | Z16: x | AA16: x | AB16: x | AC16: x | AD16: x
Q17: =F74 -> 0 | R17: Overall Discount
B18: =IF(AND(G1,G2,G3,G4,G5,G6,G7,G8,G9,G10,H1)=TRUE, "", "CHECKLIST INCOMPLETE !" )
B19: =IF(ABS(SUM(A23:A32))>100,"[Discy A-J] are high, Check it out."," ") | Q19: =R83 -> 1.0040924 | R19: Overall Markup (Final Selling Excl.VAT/Total Cost )
E21: DISCOUNTED | F21: SELLING | Q21: % Discnt | R21: MATERIAL | T21: LABOUR
A22: Discy.A-J | B22: Markup/LRate | E22: ="SELLING " & $Q$1 -> SELLING € | F22: =$Q$1 -> € | G22: VAT/DISC | H22: MU | I22: LABRATE | J22: LABCOST | Q22: on Totals | R22: € | T22: Pair Hrs.
A23: =IF($F23=0,"",($F23/$C2)-($R23*$S2+$T23*$T2)) -> 0.072255333 | B23: =IF(F23=0,"",IF(R23=0,"A) "&"---, "&ROUND(($F23/$C2-($R23*$S2))/$T23,2),IF(T23=0,"A) "&ROUND(($F23/$C2)/$R23,2),"A) "&ROUND(($F23/$C2-($T23*$T2))/$R23,2)&", " &ROUND(($F23/$C2-($R23*$S2))/$T23,2)))) -> A) 1, 28.83 | D23: =IF($F2="","",$F2) -> Electrical | E23: =F23*(1-Q23) -> 4683.4 | F23: =Elec_Est!F808 -> 4683.4 | G23: =C2 -> 1 | H23: =$S2 -> 1 | I23: =$T2 -> 28.833 | J23: =$D$9 -> 28.833 | R23: =Elec_Est!R808 -> 1979.8909 | T23: =Elec_Est!T808 -> 93.7619
A24: =IF($F24=0,"",($F24/$C3)-($R24*$S3+$T24*$T3)) -> 0.02 | B24: =IF(F24=0,"",IF(R24=0,"A) "&"---, "&ROUND(($F24/$C3-($R24*$S3))/$T24,2),IF(T24=0,"A) "&ROUND(($F24/$C3)/$R24,2),"A) "&ROUND(($F24/$C3-($T24*$T3))/$R24,2)&", " &ROUND(($F24/$C3-($R24*$S3))/$T24,2)))) -> A) 1, 33 | D24: =IF($F3="","",$F3) -> Controls Section (Guy) | E24: =F24*(1-Q24) -> 1071.6 | F24: =Elec_Est!F809 -> 1071.6 | G24: =C3 -> 1 | H24: =$S3 -> 1 | I24: =$T3 -> 33 | J24: =$D$9 -> 28.833 | R24: =Elec_Est!R809 -> 923.08 | T24: =Elec_Est!T809 -> 4.5
A25: =IF($F25=0,"",($F25/$C4)-($R25*$S4+$T25*$T4)) -> 0 | B25: =IF(F25=0,"",IF(R25=0,"A) "&"---, "&ROUND(($F25/$C4-($R25*$S4))/$T25,2),IF(T25=0,"A) "&ROUND(($F25/$C4)/$R25,2),"A) "&ROUND(($F25/$C4-($T25*$T4))/$R25,2)&", " &ROUND(($F25/$C4-($R25*$S4))/$T25,2)))) -> A) ---, 30 | D25: =IF($F4="","",$F4) -> Controls Section (Engineer) | E25: =F25*(1-Q25) -> 120 | F25: =Elec_Est!F810 -> 120 | G25: =C4 -> 1 | H25: =$S4 -> 1 | I25: =$T4 -> 30 | J25: =$D$9 -> 28.833 | R25: =Elec_Est!R810 -> 0 | T25: =Elec_Est!T810 -> 4
A26: =IF($F26=0,"",($F26/$C5)-($R26*$S5+$T26*$T5)) -> 0 | B26: =IF(F26=0,"",IF(R26=0,"A) "&"---, "&ROUND(($F26/$C5-($R26*$S5))/$T26,2),IF(T26=0,"A) "&ROUND(($F26/$C5)/$R26,2),"A) "&ROUND(($F26/$C5-($T26*$T5))/$R26,2)&", " &ROUND(($F26/$C5-($R26*$S5))/$T26,2)))) -> A) 1 | D26: =IF($F5="","",$F5) -> Fire Alarm (Josef) | E26: =F26*(1-Q26) -> 238.46 | F26: =Elec_Est!F811 -> 238.46 | G26: =C5 -> 1 | H26: =$S5 -> 1 | I26: =$T5 -> 28.833 | J26: =$D$9 -> 28.833 | R26: =Elec_Est!R811 -> 238.46 | T26: =Elec_Est!T811 -> 0
A27: =IF($F27=0,"",($F27/$C6)-($R27*$S6+$T27*$T6)) | B27: =IF(F27=0,"",IF(R27=0,"A) "&"---, "&ROUND(($F27/$C6-($R27*$S6))/$T27,2),IF(T27=0,"A) "&ROUND(($F27/$C6)/$R27,2),"A) "&ROUND(($F27/$C6-($T27*$T6))/$R27,2)&", " &ROUND(($F27/$C6-($R27*$S6))/$T27,2)))) | D27: =IF($F6="","",$F6) | E27: =F27*(1-Q27) -> 0 | F27: =Elec_Est!F812 -> 0 | G27: =C6 -> 1 | H27: =$S6 -> 0 | I27: =$T6 -> 0 | J27: =$D$9 -> 28.833 | R27: =Elec_Est!R812 -> 0 | T27: =Elec_Est!T812 -> 0
A28: =IF($F28=0,"",($F28/$C7)-($R28*$S7+$T28*$T7)) | B28: =IF(F28=0,"",IF(R28=0,"A) "&"---, "&ROUND(($F28/$C7-($R28*$S7))/$T28,2),IF(T28=0,"A) "&ROUND(($F28/$C7)/$R28,2),"A) "&ROUND(($F28/$C7-($T28*$T7))/$R28,2)&", " &ROUND(($F28/$C7-($R28*$S7))/$T28,2)))) | D28: =IF($F7="","",$F7) | E28: =F28*(1-Q28) -> 0 | F28: =Elec_Est!F813 -> 0 | G28: =C7 -> 1 | H28: =$S7 -> 0 | I28: =$T7 -> 0 | J28: =$D$9 -> 28.833 | R28: =Elec_Est!R813 -> 0 | T28: =Elec_Est!T813 -> 0
A29: =IF($F29=0,"",($F29/$C8)-($R29*$S8+$T29*$T8)) | B29: =IF(F29=0,"",IF(R29=0,"A) "&"---, "&ROUND(($F29/$C8-($R29*$S8))/$T29,2),IF(T29=0,"A) "&ROUND(($F29/$C8)/$R29,2),"A) "&ROUND(($F29/$C8-($T29*$T8))/$R29,2)&", " &ROUND(($F29/$C8-($R29*$S8))/$T29,2)))) | D29: =IF($F8="","",$F8) | E29: =F29*(1-Q29) -> 0 | F29: =Elec_Est!F814 -> 0 | G29: =C8 -> 1 | H29: =$S8 -> 0 | I29: =$T8 -> 0 | J29: =$D$9 -> 28.833 | R29: =Elec_Est!R814 -> 0 | T29: =Elec_Est!T814 -> 0
A30: =IF($F30=0,"",($F30/$C9)-($R30*$S9+$T30*$T9)) | B30: =IF(F30=0,"",IF(R30=0,"A) "&"---, "&ROUND(($F30/$C9-($R30*$S9))/$T30,2),IF(T30=0,"A) "&ROUND(($F30/$C9)/$R30,2),"A) "&ROUND(($F30/$C9-($T30*$T9))/$R30,2)&", " &ROUND(($F30/$C9-($R30*$S9))/$T30,2)))) | D30: =IF($F9="","",$F9) | E30: =F30*(1-Q30) -> 0 | F30: =Elec_Est!F815 -> 0 | G30: =C9 -> 1 | H30: =$S9 -> 0 | I30: =$T9 -> 0 | J30: =$D$9 -> 28.833 | R30: =Elec_Est!R815 -> 0 | T30: =Elec_Est!T815 -> 0
A31: =IF($F31=0,"",($F31/$C10)-($R31*$S10+$T31*$T10)) | B31: =IF(F31=0,"",IF(R31=0,"A) "&"---, "&ROUND(($F31/$C10-($R31*$S10))/$T31,2),IF(T31=0,"A) "&ROUND(($F31/$C10)/$R31,2),"A) "&ROUND(($F31/$C10-($T31*$T10))/$R31,2)&", " &ROUND(($F31/$C10-($R31*$S10))/$T31,2)))) | D31: =IF($F10="","",$F10) | E31: =F31*(1-Q31) -> 0 | F31: =Elec_Est!F816 -> 0 | G31: =C10 -> 1 | H31: =$S10 -> 0 | I31: =$T10 -> 0 | J31: =$D$9 -> 28.833 | R31: =Elec_Est!R816 -> 0 | T31: =Elec_Est!T816 -> 0
A32: =IF($F32=0,"",($F32/$C11)-($R32*$S11+$T32*$T11)) | B32: =IF(F32=0,"",IF(R32=0,"A) "&"---, "&ROUND(($F32/$C11-($R32*$S11))/$T32,2),IF(T32=0,"A) "&ROUND(($F32/$C11)/$R32,2),"A) "&ROUND(($F32/$C11-($T32*$T11))/$R32,2)&", " &ROUND(($F32/$C11-($R32*$S11))/$T32,2)))) | D32: =IF($F11="","",$F11) | E32: =F32*(1-Q32) -> 0 | F32: =Elec_Est!F817 -> 0 | G32: =C11 -> 1 | H32: =$S11 -> 0 | I32: =$T11 -> 0 | J32: =$D$9 -> 28.833 | R32: =Elec_Est!R817 -> 0 | T32: =Elec_Est!T817 -> 0
C33: MIXED
A35: Discy.L | B35: ='MUR MEP BOQ'!F416 -> 6113.46 | D35: =B35-E35 -> 0 | E35: =SUM(E23:E32) -> 6113.46 | F35: =SUM(F23:F32) -> 6113.46 | R35: =SUM(R23:R32) -> 3141.4309 | T35: =SUM(T23:T32) -> 102.2619
A36: =IF(A39=0,"0.00",A39-(A38*A37)) -> 0.00 | B36: BOQ TOTAL | E36: ="ESTIM TOTAL (" & $Q$1 & ")" -> ESTIM TOTAL (€)
A37: 1.125 | B37: <1 Actual LabCont | R37: =R165 -> 3141.3866 | S37: C.C.Totals | T37: =T165 -> 102.21471
B38: <2 Phrs @ 1.00
B39: <3 Phrs @ Actual | Q39: Discy.T >> | R39: =R37-R35 -> -0.044308703 | S39: PRINT | T39: =T37-T35 -> -0.047192703
B41: Values Only on : | D41: 45978 | E41: 6113.46 | F41: 6113.46 | R41: 3141.4309 | T41: 102.2619
A46: REMARKS:
A47: 1) VAT and Duties as above.
...

Sheet Quote
A1: =IF(AND(UPPER(LEFT(TRIM($D$8),11))="01",UPPER(LEFT(TRIM($D$9),3))<>"ELM"),"PANTA RETAIL LTD.","PANTA CONTRACTING LIMITED") -> PANTA CONTRACTING LIMITED
A2: =IF(UPPER(LEFT(TRIM($D$9),3))="ELM","ELEC-FOR-MECH INTERNAL QUOTATION","ELECTRICAL INTERNAL QUOTATION") -> ELECTRICAL INTERNAL QUOTATION
B5: ATT: | D5: Perit Andrew Sapienza | R5: Dated: | S5: =NOW() -> 46059.471
B6: CLIENT: | C6: Link to ML_SUM $D1 | D6: =ML_Sum!D1 -> SUNCREST HOTELS plc
B7: PROJECT: | C7: Link to ML_SUM $D2 | D7: =ML_Sum!D2 -> Sunny Cost and Lido Redevelopment
B8: JOB DESC: | C8: Link to ML_SUM $D3 | D8: =ML_Sum!D3 -> Sample Room - Electrical
B9: QUOTE No: | C9: Link to ML_SUM $D4 | D9: =ML_Sum!D4 -> EL25-0700
B10: CLIENT's Ref: | C10: Link to ML_SUM $D5 | D10: =ML_Sum!D5 -> Sample Room
D22: Selling Price (€) : | E22: =ML_Sum!E35 -> 6113.46 | F22: =ML_Sum!D6 -> VAT EXCL. | G22: VAT EXCLUDED. | H22: VAT EXCLUDED. | I22: VAT EXCLUDED. | J22: VAT EXCLUDED. | K22: VAT EXCLUDED. | L22: VAT EXCLUDED. | M22: VAT EXCLUDED. | N22: VAT EXCLUDED. | O22: VAT EXCLUDED. | P22: VAT EXCLUDED.
A51: Signed for and on behalf of | Q51: Signed for and on behalf of
A52: Electrical Division | Q52: Division
Q54: Records
Q55: Mr. A. Sciberras
Q57: File

Sheet MUR MEP BOQ
B1: SUNNY COAST MOCK UP ROOM MEP Bill of Quantities | F1: REV00
B3: Preliminaries and General Conditions
A4: ITEM | B4: DESCRIPTION | C4: QTY | D4: UNIT | E4: RATE EXC. VAT | F4: TOTAL EXC. VAT
B5: The Preliminary Items included hereunder apply to the whole of the works contained in these Bills of Quantities and the rates and / or amounts inserted by the Contractor shall be deemed to apply to the whole of the works carried out under this Contract. The Contractor shall be deemed to have allowed in his tender for all costs in respect of all items described in the Preliminaries section of the Bills of Quantities. In the absence of any sum against any item or items , any monetary cost attributable thereto shall be deemed to be included elsewhere in the Preliminaries section or the unit rates for the measured works. The documents forming the Contract are to be taken as mutually explanatory to one another and any sum inserted here shall be deemed to cover the complete requirements of the Conditions of Contract, In the event of no amounts being inserted by the Contractor in respect of this Bill, no relative payment will be included in interim payments and the final All prices quoted in this tender are exclusive of V.A.T, but inclusive of all applicable Taxes and Levies. The contractor will be responsible for obtaining and incurring all expenses related to any permits that might be required by the local council and for any other fees that might become due to the local council or the competent authorities, bodies and /or agencies in relation to obstruction to traffic and pedestrians, necessary hoardings etc. Prior to submitting this tender document, the contractor is required to consult with the local council in relation to all requirements to carry out the scope of works of this tender.
B7: Health and Safety
A8: 1 | B8: Allow all costs for the employment of a licenced Health and Safety Officer for the entire duration of the Contract. The officer shall be responsible for enforcing all health and safety measures required by law, preparation of risk assessments for approval and work in conjuction with the H&S Officer appointed by the Employer. The Contractor shall also make provisions for a services of Fire Marshal during the works, in order to prevent any fires caused by Hot Works and other risks. | C8: 1 | D8: LS | E8: INC | F8: INC
B10: Regular Cleaning
A11: 1.003 | B11: Daily clean the site from any debris or material which may be intentionally or accidentally deposited during the course of works and during the transportation of material to the approariate disposal point | C11: 1 | D11: LS | E11: INC | F11: INC
B13: Preliminary Review of Project
A14: 1.004 | B14: The contractor shall obtain all the required operational information from Client, Perit and Engineers pertaining to the Risks related to Fire, so as to enable the full understanding of the design intent. The information shall include: materials, raw and finished, processes and chemicals used, quantities, packaging and storage format, shelving and stacking, ventilation requirements related to pharmaceutical industry, air pressure in rooms and corridors, safety and security, etc. | C14: 1 | D14: LS | E14: INC | F14: INC
A15: 1.005 | B15: The contractor shall review the M&E project documentation, and understand the services that will interface or clash (in terms of routing, levels and space allocation) and thus liaise with the Engineers for solutions. Any preparatory works as well as builders' works, preparation, openings, plinths, etc must be delth with at this stage. | C15: 1 | D15: LS | E15: INC | F15: INC
B17: Drawings
A18: 1.004 | B18: Provision of working drawings and reengineering as necessary including updating of drawings as required and as the works proceed. | C18: 1 | D18: LS | E18: INC | F18: INC
B20: Insurances
A21: 1.005 | B21: Contractor's Insurance CAR Policy covering the total contract value. The contractor must also take out a professional Indemnity Insurance to cover the design and therefore its warranted Engineers. | C21: 1 | D21: LS | E21: INC | F21: INC
A22: 1.006 | B22: Contractor's Insurance covering death or injury to Contractor's Personnel | C22: 1 | D22: LS | E22: INC | F22: INC
A23: 1.007 | B23: Contractor's Insurance covering loss or damage to Contractor's plant and equipment. | C23: 1 | D23: LS | E23: INC | F23: INC
B25: Builder's Works Drawings
A26: 1.008 | B26: The contractor must submit detailed builders work drawings, coordinated with the M&E drawings and the Fire compartmentation drawings issued by the Fire Engineer and Perit. The builder's work must provide clear information regarding all penetrations, holes and cores needed, the position with x & y dimensions, hole diameters, etc. The drawings must also detail whether the builder or finishes contractor will need to carry out future interventions of making good. the drawings must include additional works such as plinths (dimensions), puddle flanges, overflows and sleeves, doorways or hatches for equipment access. Where contractor may need access to lifters, cherry pickers, scaffolding, crane, etc, this must be agreed upon from this stage of the project. | C26: 1 | D26: LS | E26: INC | F26: INC
B28: Others
A29: 1.009 | B29: Provision of mobile toilets facilities on site, incl. emptying, cleaning etc | C29: 1 | D29: LS | E29: by client | F29: by client
A30: 1.01 | B30: Provision of security services on site | C30: 1 | D30: LS | E30: by client | F30: by client
A31: 1.011 | B31: Provision of CONTRACTOR MEP Project management | C31: 1 | D31: LS | E31: INC | F31: INC
A32: 1.012 | B32: Prepare coordinated drawings for all services | C32: 1 | D32: LS | E32: INC | F32: INC
A33: 1.014 | B33: Any other works, Contractor to list | C33: 1 | D33: LS | E33: INC | F33: INC
B34: TOTAL FOR PRELIMINARIES in € exc VAT | F34: INC
B35: *INC. = included, LS= lump sump, m= meters, No. =Number
B38: ELECTRICAL INSTALLATION
A39: ITEM | B39: DESCRIPTION | C39: QTY | D39: UNIT | E39: RATE EXC. VAT | F39: TOTAL EXC. VAT
A40: 2 | B40: Take over design , reengineer and produce coordinated working drawings | C40: 1 | D40: LS | E40: INC | F40: INC
B42: Power Cables
B44: Supply, install and connect the following supply cables on cable tray or clipped to wall, including all cleats, brass compression glands, terminal lugs etc., for a complete system.
B46: From LOCAL DB to the Sample room DB
A47: 2.001 | B47: 3c4mm2 FG16 | C47: 25 | D47: m | E47: =Elec_Est!E38 -> 3.56 | F47: =C47*E47 -> 89
B49: Distribution Boards
B50: Supply, install & connect the following distribution boards complete with all accessories, including any Extension din enclosures for contactors, and Surge suppression devices, earth and neutral bars, glands, timers, labelling, etc
A51: 2.002 | B51: Sample Room Consumer unit, flame-retardant, no combustible, 3 x 14 module min., complete with all accessories, and protection devices (contactors listed under REMS section) | C51: 1 | D51: LS | E51: =Elec_Est!E56 -> 528.28 | F51: =C51*E51 -> 528.28
A52: 2.003 | B52: Fire and smoke inhibiting sealing material around consumer unit using putty or alternative] | C52: 1 | D52: LS | E52: =Elec_Est!E78 -> 79.45 | F52: =C52*E52 -> 79.45
A53: 2.004 | B53: Additional energy meter (both kW and KWh) to monitor receptacle loads with modbus interface for remote BMS measurement and recording. Include for expansion of consumer unit by an extra row | C53: 2 | D53: LS | E53: =Elec_Est!E85 -> 30.8 | F53: =C53*E53 -> 61.6
F54: =C54*E54 -> 0
...
