Workbook
Name Access_Control: [1]Elec_Est!#REF!
Name AREAS: [1]ML_Sum!$X$1:$AD$16
Name AREAS: ML_Sum!$X$1:$AD$16
Name CCTV: [1]Elec_Est!#REF!
Name Data: [1]Elec_Est!#REF!
Name Fire_Alarm: [1]Elec_Est!#REF!
Name FO: [1]Elec_Est!#REF!
Name Guard: [1]Elec_Est!#REF!
Name Intercom: [1]Elec_Est!#REF!
Name Intruder_Alarm: [1]Elec_Est!#REF!

Sheet Notes
A1: NOTES
A3: 1 | B3: BOQ Item 6.001 | C3: We have allowed to connect the Fan to a 13A DP Fused Outlet included in the electrical BOQ.
A5: 2 | B5: BOQ Item 6.002 | C5: We have allowed to connect the Damper to a 13A DP Fused Outlet included in the electrical BOQ. The control wiring installation is included in the REMS BOQ.
A7: 3 | B7: BOQ Item 6.008 | C7: The wiring and programming are included within the REMS BOQ
A9: 4 | B9: BOQ Item 6.009 | C9: We have allowed to connect the Fan to a 13A DP Fused Outlet included in the electrical BOQ. The control wiring installation is included in the REMS BOQ,. Whilst, the Fan Time OFF delay can be achived by the REMS logic controller.
A11: 5 | B11: BOQ Items 7.002 & 7.005 | C11: We have allowed for an empty conduit between the AC Indoor units and the room temperature/fan speed controller.
A13: 6 | B13: BOQ Item 7.007 | C13: The AC Connecting up and control wiring installation, are excluded.

Sheet Elec_Est
B1: CLIENT: | C1: =ML_Sum!$C1 -> 1 | D1: =ML_Sum!$D1 -> SUNCREST HOTELS plc | F1: =ML_Sum!$F1 -> 0 | I1: 1 | J1: =ML_Sum!$J1 -> 1 | K1: =ML_Sum!$K1 -> 1 | L1: =ML_Sum!$L1 -> 1 | M1: =ML_Sum!$M1 -> 1 | N1: =ML_Sum!$N1 -> 1 | O1: =ML_Sum!$O1 -> 1 | Q1: =ML_Sum!$Q1 -> € | R1: R/Lab Cont | S1: =ML_Sum!$S1 -> R | T1: =ML_Sum!$T1 -> 1 | U1: =ML_Sum!W1 -> BOQ | V1: INCL | W1: MULT | X1: AREA | Y1: BOQ | Z1: TDWG | AA1: ACT | AB1: DIFF
B2: PROJECT: | C2: =ML_Sum!$C2 -> 1 | D2: =ML_Sum!$D2 -> Sunny Cost and Lido Redevelopment | F2: =ML_Sum!$F2 -> Electrical | I2: 2 | J2: =ML_Sum!$J2 -> 1 | K2: =ML_Sum!$K2 -> 1 | L2: =ML_Sum!$L2 -> 1 | M2: =ML_Sum!$M2 -> 1 | N2: =ML_Sum!$N2 -> 1 | O2: =ML_Sum!$O2 -> 1 | Q2: =ML_Sum!$Q2 -> 0 | R2: mu_A | S2: =ML_Sum!$S2 -> 1.3 | T2: =ML_Sum!$T2 -> 35.698
B3: JOB DESC: | C3: =ML_Sum!$C3 -> 1 | D3: =ML_Sum!$D3 -> Sample Room - Electrical for Mechanical | F3: =ML_Sum!$F3 -> Controls Section (Guy) | I3: 3 | J3: =ML_Sum!$J3 -> 1 | K3: =ML_Sum!$K3 -> 1 | L3: =ML_Sum!$L3 -> 1 | M3: =ML_Sum!$M3 -> 1 | N3: =ML_Sum!$N3 -> 1 | O3: =ML_Sum!$O3 -> 1 | Q3: =ML_Sum!$Q3 -> 0 | R3: mu_B | S3: =ML_Sum!$S3 -> 1.3 | T3: =ML_Sum!$T3 -> 35.698
B4: QUOTE No: | C4: =ML_Sum!$C4 -> 1 | D4: =ML_Sum!$D4 -> ELM25-0699 | F4: =ML_Sum!$F4 -> 0 | I4: 4 | J4: =ML_Sum!$J4 -> 1 | K4: =ML_Sum!$K4 -> 1 | L4: =ML_Sum!$L4 -> 1 | M4: =ML_Sum!$M4 -> 1 | N4: =ML_Sum!$N4 -> 1 | O4: =ML_Sum!$O4 -> 1 | Q4: =ML_Sum!$Q4 -> 0 | R4: mu_C | S4: =ML_Sum!$S4 -> 0 | T4: =ML_Sum!$T4 -> 0
B5: CLIENTs REF: | C5: =ML_Sum!$C5 -> 1 | D5: =ML_Sum!$D5 -> Sample Room | F5: =ML_Sum!$F5 -> 0 | I5: 5 | J5: =ML_Sum!$J5 -> 1 | K5: =ML_Sum!$K5 -> 1 | L5: =ML_Sum!$L5 -> 1 | M5: =ML_Sum!$M5 -> 1 | N5: =ML_Sum!$N5 -> 1 | O5: =ML_Sum!$O5 -> 1 | Q5: =ML_Sum!$Q5 -> 0 | R5: mu_D | S5: =ML_Sum!$S5 -> 0 | T5: =ML_Sum!$T5 -> 0
B6: VAT/DUTIES: | C6: =ML_Sum!$C6 -> 1 | D6: =ML_Sum!$D6 -> VAT EXCL. | F6: =ML_Sum!$F6 -> 0 | I6: 6 | J6: =ML_Sum!$J6 -> 1 | K6: =ML_Sum!$K6 -> 1 | L6: =ML_Sum!$L6 -> 1 | M6: =ML_Sum!$M6 -> 1 | N6: =ML_Sum!$N6 -> 1 | O6: =ML_Sum!$O6 -> 1 | Q6: =ML_Sum!$Q6 -> 0 | R6: mu_E | S6: =ML_Sum!$S6 -> 0 | T6: =ML_Sum!$T6 -> 0
B7: SAVED ON: | C7: =ML_Sum!$C7 -> 1 | D7: 39364 | F7: =ML_Sum!$F7 -> 0 | I7: 7 | J7: =ML_Sum!$J7 -> 1 | K7: =ML_Sum!$K7 -> 1 | L7: =ML_Sum!$L7 -> 1 | M7: =ML_Sum!$M7 -> 1 | N7: =ML_Sum!$N7 -> 1 | O7: =ML_Sum!$O7 -> 0 | Q7: =ML_Sum!$Q7 -> 0 | R7: mu_F | S7: =ML_Sum!$S7 -> 0 | T7: =ML_Sum!$T7 -> 0
B8: ESTIMATOR: | C8: =ML_Sum!$C8 -> 1 | D8: =ML_Sum!$D8 -> R.Farrugia | F8: =ML_Sum!$F8 -> 0 | I8: 8 | J8: =ML_Sum!$J8 -> 1 | K8: =ML_Sum!$K8 -> 1 | L8: =ML_Sum!$L8 -> 1 | M8: =ML_Sum!$M8 -> 1 | N8: =ML_Sum!$N8 -> 1 | O8: =ML_Sum!$O8 -> 0 | Q8: =ML_Sum!$Q8 -> 0 | R8: mu_G | S8: =ML_Sum!$S8 -> 0 | T8: =ML_Sum!$T8 -> 0
B9: LABOUR RATE: | C9: =ML_Sum!$C9 -> 1 | D9: =ML_Sum!$D9 -> 27.46 | F9: =ML_Sum!$F9 -> 0 | I9: 9 | J9: =ML_Sum!$J9 -> 1 | K9: =ML_Sum!$K9 -> 1 | L9: =ML_Sum!$L9 -> 1 | M9: =ML_Sum!$M9 -> 1 | N9: =ML_Sum!$N9 -> 1 | O9: =ML_Sum!$O9 -> 0 | Q9: =ML_Sum!$Q9 -> 0 | R9: mu_H | S9: =ML_Sum!$S9 -> 0 | T9: =ML_Sum!$T9 -> 0
C10: =ML_Sum!$C10 -> 1 | F10: =ML_Sum!$F10 -> 0 | I10: 10 | J10: =ML_Sum!$J10 -> 1 | K10: =ML_Sum!$K10 -> 1 | L10: =ML_Sum!$L10 -> 1 | M10: =ML_Sum!$M10 -> 1 | N10: =ML_Sum!$N10 -> 1 | O10: =ML_Sum!$O10 -> 1 | Q10: =ML_Sum!$Q10 -> 0 | R10: mu_I | S10: =ML_Sum!$S10 -> 0 | T10: =ML_Sum!$T10 -> 0
C11: =ML_Sum!$C11 -> 1 | F11: =ML_Sum!$F11 -> 0 | Q11: =ML_Sum!$Q11 -> 0 | R11: mu_J | S11: =ML_Sum!$S11 -> 0 | T11: =ML_Sum!$T11 -> 0
C12: =ML_Sum!$C12 -> 1 | F12: =ML_Sum!$F12 -> 0 | Q12: =ML_Sum!$Q12 -> 0 | R12: MIXED | S12: =ML_Sum!$S12 -> MAT MU | T12: =ML_Sum!$T12 -> LAB RATE
G13: ISELL | H13: C_CODE | I13: MAKE | J13: PART_NO | K13: MARKUP | L13: TYPE | M13: LIST_P | N13: P_FACT | O13: FIX | P13: DATE | Q13: %Dsct in BOQ | R13: MU TYPE | S13: MAT MU | T13: LAB RATE | AM13: Tot Mat Cost | AN13: Unit Lab phr. | AO13: Tot Lab phr. | AP13: < for ELM / MEE
K14: TB
C15: t | D15: Item:
D16: VENTILATION INSTALLATION
K18: TB
C19: t | D19: Item:
D20: SF 01 [Delta P to be as per selected accessories] for bedroom
E22: Sell Rate | F22: Sell Total | K22: IB | AG22: U_M_Sell | AH22: T_M_Sell | AI22: U_L_Sell | AJ22: T_L_Sell | AK22: Total_Sell | AM22: T_M_Cost | AN22: U_L_Phr | AO22: T_L_Phr | AP22: Mat/Lab=1
A23: 1 | B23: LS | D23: Item: 6.001 | E23: =IF(AND($A23=0,$A$1="DIF"),0, ROUND(ROUND(($R28*$S$2+($T28*$T$2))/A23,2)*$C$2,2)) -> 24.28 | F23: =ROUND($A23*$E23,2) -> 24.28 | G23: ISELL | K23: mu_A | L23: ITEM | T23: =IF(AND($R28=0,$T28=0),"0.00","mu :" & ROUND($F23/$C$2/($R28+$T28*$D$9),2)) -> mu :1.3 | AG23: =IF($E23=0,0,ROUND($R28*$S$2*$C$2/$A23,2)) -> 2.86 | AH23: =$AG23*$A23 -> 2.86 | AI23: =$E23-$AG23 -> 21.42 | AJ23: =$A23*$AI23 -> 21.42 | AK23: =ROUND(($AG23+$AI23)*$A23,2) -> 24.28 | AM23: =ROUND(R28,2) -> 2.2 | AN23: =IF(A23=0,0,AO23/A23) -> 0.6 | AO23: =ROUND(T28,2) -> 0.6 | AP23: =ROUND(AM23+AO23,2)*A23 -> 2.8
D24: 30 litres/sec mixed flow fan including electrical connection to double pole provided, complete. Fan to be very silent with silencers if required | K24: n
A25: 2 | B25: m | D25: Wiring Cable 3c 1.5 mm2 PVC Non-Arm | G25: CASC_017 | H25: 615 | I25: CRO | K25: 02-002 | O25: 2 | P25: 38988 | Q25: 1.1 | R25: =$A25*Q25 -> 2.2 | S25: 0.05 | T25: =$A25*S25*$T$1 -> 0.1
A26: 1 | B26: No | D26: Labour to connect Mech Equip (SF01) | G26: LABO_009 | H26: 900 | I26: MISC | O26: 1 | Q26: 0 | R26: =$A26*Q26 -> 0 | S26: 0.5 | T26: =$A26*S26*$T$1 -> 0.5
R27: =$A27*Q27 -> 0 | T27: =$A27*S27*$T$1 -> 0
A28: d> | B28: =(R27+T27) -> 0 | G28: ICOST | K28: mu_A | L28: ITEM | R28: =SUM(R24:R27) -> 2.2 | T28: =SUM(T24:T27) -> 0.6
E29: Sell Rate | F29: Sell Total | K29: IB | AG29: U_M_Sell | AH29: T_M_Sell | AI29: U_L_Sell | AJ29: T_L_Sell | AK29: Total_Sell | AM29: T_M_Cost | AN29: U_L_Phr | AO29: T_L_Phr | AP29: Mat/Lab=1
A30: 1 | B30: LS | D30: Item: 6.002 | E30: =IF(AND($A30=0,$A$1="DIF"),0, ROUND(ROUND(($R35*$S$2+($T35*$T$2))/A30,2)*$C$2,2)) -> 24.28 | F30: =ROUND($A30*$E30,2) -> 24.28 | G30: ISELL | K30: mu_A | L30: ITEM | T30: =IF(AND($R35=0,$T35=0),"0.00","mu :" & ROUND($F30/$C$2/($R35+$T35*$D$9),2)) -> mu :1.3 | AG30: =IF($E30=0,0,ROUND($R35*$S$2*$C$2/$A30,2)) -> 2.86 | AH30: =$AG30*$A30 -> 2.86 | AI30: =$E30-$AG30 -> 21.42 | AJ30: =$A30*$AI30 -> 21.42 | AK30: =ROUND(($AG30+$AI30)*$A30,2) -> 24.28 | AM30: =ROUND(R35,2) -> 2.2 | AN30: =IF(A30=0,0,AO30/A30) -> 0.6 | AO30: =ROUND(T35,2) -> 0.6 | AP30: =ROUND(AM30+AO30,2)*A30 -> 2.8
D31: Motorised 0-10V damper with leakage Class 3 to EN1751-2014 which will be connected to the RMS system for modulation control of damper by CO2 sensor feedback | K31: n
A32: 2 | B32: m | D32: Wiring Cable 3c 1.5 mm2 PVC Non-Arm | G32: CASC_017 | H32: 615 | I32: CRO | K32: 02-002 | O32: 2 | P32: 38988 | Q32: 1.1 | R32: =$A32*Q32 -> 2.2 | S32: 0.05 | T32: =$A32*S32*$T$1 -> 0.1
A33: 1 | B33: No | D33: Labour to connect Mech Equip (Motorised 0-10V damper) | G33: LABO_009 | H33: 900 | I33: MISC | O33: 1 | Q33: 0 | R33: =$A33*Q33 -> 0 | S33: 0.5 | T33: =$A33*S33*$T$1 -> 0.5
R34: =$A34*Q34 -> 0 | T34: =$A34*S34*$T$1 -> 0
A35: d> | B35: =(R34+T34) -> 0 | G35: ICOST | K35: mu_A | L35: ITEM | R35: =SUM(R31:R34) -> 2.2 | T35: =SUM(T31:T34) -> 0.6
E36: Sell Rate | F36: Sell Total | K36: IB | AG36: U_M_Sell | AH36: T_M_Sell | AI36: U_L_Sell | AJ36: T_L_Sell | AK36: Total_Sell | AM36: T_M_Cost | AN36: U_L_Phr | AO36: T_L_Phr | AP36: Mat/Lab=1
A37: 1 | B37: LS | D37: Item: 6.008 | E37: =IF(AND($A37=0,$A$1="DIF"),0, ROUND(ROUND(($R43*$S$3+($T43*$T$3))/$A37,2)*$C$3,2)) -> 234 | F37: =ROUND($A37*$E37,2) -> 234 | G37: ISELL | K37: mu_B | L37: ITEM | T37: =IF(AND($R43=0,$T43=0),"0.00","mu: "& ROUND(F37/$C$3/($R43+$T43*$D$9),2)) -> mu: 1.3 | AG37: =IF($E37=0,0,ROUND($R43*$S$3*$C$3/$A37,2)) -> 234 | AH37: =$AG37*$A37 -> 234 | AI37: =$E37-$AG37 -> 0 | AJ37: =$A37*$AI37 -> 0 | AK37: =ROUND(($AG37+$AI37)*$A37,2) -> 234 | AM37: =ROUND(R43,2) -> 180 | AN37: =IF(A37=0,0,AO37/A37) -> 0 | AO37: =ROUND(T43,2) -> 0 | AP37: =ROUND(AM37+AO37,2)*A37 -> 180
D38: Provide an indirect OA monitroing devices such as differential pressure sensor, airflow switch or current trasnducer on supply fan, complete with wiring to main door | K38: n
A39: 1 | B39: No | D39: Differential pressure sensor | G39: BMSE_007 | H39: 512 | I39: FRER | J39: 1MCOEAR | O39: 2 | P39: 38496 | Q39: 180 | R39: =$A39*Q39 -> 180 | T39: =$A39*S39*$T$1 -> 0
R40: =$A40*Q40 -> 0 | T40: =$A40*S40*$T$1 -> 0
D41: Note: The wiring and programming are included within the REMS BOQ | R41: =$A41*Q41 -> 0 | T41: =$A41*S41*$T$1 -> 0
R42: =$A42*Q42 -> 0 | T42: =$A42*S42*$T$1 -> 0
...

Sheet ML_Sum
B1: CLIENT: | C1: 1 | D1: SUNCREST HOTELS plc | G1: TRUE | H1: TRUE | I1: 1 | J1: =$Q109 -> 1 | K1: =$Q119 -> 1 | L1: =$Q129 -> 1 | M1: =$Q139 -> 1 | N1: =$Q149 -> 1 | O1: =$Q159 -> 1 | Q1: =IF(C1=1,"€","Curr?") -> € | R1: Recon /Lab.Cont >> | S1: =IF($S$39="PRINT","R","Do Not Print") -> R | T1: 1 | V1: {=IF(OR(X1=AREAS),1,0)} -> 1 | W1: BOQ | X1: x | Y1: x | Z1: x | AA1: x | AB1: x | AC1: x | AD1: x
B2: PROJECT: | C2: =IF($D$6="VAT INCLUDED",1.18,1)*(1-$Q2)*$C$1 -> 1 | D2: Sunny Cost and Lido Redevelopment | F2: Electrical | G2: TRUE | I2: 2 | J2: =$Q110 -> 1 | K2: =$Q120 -> 1 | L2: =$Q130 -> 1 | M2: =$Q140 -> 1 | N2: =$Q150 -> 1 | O2: =$Q160 -> 1 | R2: ="A) " & IF($S2=0,"",ROUND($S2,2) & "-" & ROUND($T2/$D$9,2)) -> A) 1.3-1.3 | S2: 1.3 | T2: =$S2*$D$9 -> 35.698 | X2: x | Y2: x | Z2: x | AA2: x | AB2: x | AC2: x | AD2: x
B3: JOB DESC: | C3: =IF($D$6="VAT INCLUDED",1.18,1)*(1-$Q3)*$C$1 -> 1 | D3: Sample Room - Electrical for Mechanical | F3: Controls Section (Guy) | G3: TRUE | I3: 3 | J3: =$Q111 -> 1 | K3: =$Q121 -> 1 | L3: =$Q131 -> 1 | M3: =$Q141 -> 1 | N3: =$Q151 -> 1 | O3: =$Q161 -> 1 | R3: ="B) " & IF($S3=0,"",ROUND($S3,2) & "-" & ROUND($T3/$D$9,2)) -> B) 1.3-1.3 | S3: 1.3 | T3: =$S3*$D$9 -> 35.698 | X3: x | Y3: x | Z3: x | AA3: x | AB3: x | AC3: x | AD3: x
B4: INT. QUOT No: | C4: =IF($D$6="VAT INCLUDED",1.18,1)*(1-$Q4)*$C$1 -> 1 | D4: ELM25-0699 | G4: TRUE | I4: 4 | J4: =$Q112 -> 1 | K4: =$Q122 -> 1 | L4: =$Q132 -> 1 | M4: =$Q142 -> 1 | N4: =$Q152 -> 1 | O4: =$Q162 -> 1 | R4: ="C) " & IF($S4=0,"",ROUND($S4,2) & "-" & ROUND($T4/$D$9,2)) -> C) | T4: =$S4*$D$10 -> 0 | X4: x | Y4: x | Z4: x | AA4: x | AB4: x | AC4: x | AD4: x
B5: CLIENTs REF: | C5: =IF($D$6="VAT INCLUDED",1.18,1)*(1-$Q5)*$C$1 -> 1 | D5: Sample Room | G5: TRUE | I5: 5 | J5: =$Q113 -> 1 | K5: =$Q123 -> 1 | L5: =$Q133 -> 1 | M5: =$Q143 -> 1 | N5: =$Q153 -> 1 | O5: =$Q163 -> 1 | R5: ="D) " & IF($S5=0,"",ROUND($S5,2) & "-" & ROUND($T5/$D$9,2)) -> D) | T5: =$S5*$D$9 -> 0 | X5: x | Y5: x | Z5: x | AA5: x | AB5: x | AC5: x | AD5: x
B6: VAT: | C6: =IF($D$6="VAT INCLUDED",1.18,1)*(1-$Q6)*$C$1 -> 1 | D6: VAT EXCL. | G6: TRUE | I6: 6 | J6: =$Q114 -> 1 | K6: =$Q124 -> 1 | L6: =$Q134 -> 1 | M6: =$Q144 -> 1 | N6: =$Q154 -> 1 | O6: =$Q164 -> 1 | R6: ="E) " & IF($S6=0,"",ROUND($S6,2) & "-" & ROUND($T6/$D$9,2)) -> E) | T6: =$S6*$D$9 -> 0 | X6: x | Y6: x | Z6: x | AA6: x | AB6: x | AC6: x | AD6: x
B7: SAVED ON: | C7: =IF($D$6="VAT INCLUDED",1.18,1)*(1-$Q7)*$C$1 -> 1 | D7: 45971 | G7: TRUE | I7: 7 | J7: =$Q115 -> 1 | K7: =$Q125 -> 1 | L7: =$Q135 -> 1 | M7: =$Q145 -> 1 | N7: =$Q155 -> 1 | R7: ="F) " & IF($S7=0,"",ROUND($S7,2) & "-" & ROUND($T7/$D$9,2)) -> F) | T7: =$S7*$D$9 -> 0 | X7: x | Y7: x | Z7: x | AA7: x | AB7: x | AC7: x | AD7: x
B8: ESTIMATOR: | C8: =IF($D$6="VAT INCLUDED",1.18,1)*(1-$Q8)*$C$1 -> 1 | D8: R.Farrugia | G8: TRUE | I8: 8 | J8: =$Q116 -> 1 | K8: =$Q126 -> 1 | L8: =$Q136 -> 1 | M8: =$Q146 -> 1 | N8: =$Q156 -> 1 | R8: ="G) " & IF($S8=0,"",ROUND($S8,2) & "-" & ROUND($T8/$D$9,2)) -> G) | T8: =$S8*$D$9 -> 0 | X8: x | Y8: x | Z8: x | AA8: x | AB8: x | AC8: x | AD8: x
B9: LAB. COST: | C9: =IF($D$6="VAT INCLUDED",1.18,1)*(1-$Q9)*$C$1 -> 1 | D9: 27.46 | G9: TRUE | I9: 9 | J9: =$Q117 -> 1 | K9: =$Q127 -> 1 | L9: =$Q137 -> 1 | M9: =$Q147 -> 1 | N9: =$Q157 -> 1 | R9: ="H) " & IF($S9=0,"",ROUND($S9,2) & "-" & ROUND($T9/$D$9,2)) -> H) | T9: =$S9*$D$9 -> 0 | X9: x | Y9: x | Z9: x | AA9: x | AB9: x | AC9: x | AD9: x
C10: =IF($D$6="VAT INCLUDED",1.18,1)*(1-$Q10)*$C$1 -> 1 | G10: TRUE | I10: 10 | J10: =$Q118 -> 1 | K10: =$Q128 -> 1 | L10: =$Q138 -> 1 | M10: =$Q148 -> 1 | N10: =$Q158 -> 1 | O10: =Q108 -> 1 | R10: =" I) " & IF($S10=0,"",ROUND($S10,2) & "-" & ROUND($T10/$D$9,2)) -> I) | T10: =$S10*$D$9 -> 0 | X10: x | Y10: x | Z10: x | AA10: x | AB10: x | AC10: x | AD10: x
C11: =IF($D$6="VAT INCLUDED",1.18,1)*(1-$Q11)*$C$1 -> 1 | R11: ="J) " & IF($S11=0,"",ROUND($S11,2) & "-" & ROUND($T11/$D$9,2)) -> J) | T11: =$S11*$D$9 -> 0 | X11: x | Y11: x | Z11: x | AA11: x | AB11: x | AC11: x | AD11: x
C12: =IF($D$6="VAT INCLUDED",1.18,1)*(1-$Q12)*$C$1 -> 1 | G12: SYSTEMS | H12: SYSTEMS | I12: SYSTEMS | J12: SYSTEMS | K12: SYSTEMS | L12: SYSTEMS | M12: SYSTEMS | N12: SYSTEMS | O12: SYSTEMS | P12: SYSTEMS | R12: MIXED - X,Y ) | S12: MAT MU | T12: LAB RATE | X12: x | Y12: x | Z12: x | AA12: x | AB12: x | AC12: x | AD12: x
B13: MATERIAL & LABOUR SUMMARY | G13: ItemCode | H13: CostCode | I13: MAKE | J13: PART_NO | K13: MARKUP | L13: TYPE | M13: LIST_P | N13: SET | O13: FIX | P13: DATE | Q13: %Dsct in BOQ | R13: MATMU-LABMU | S13: MAT CONT >> | T13: =SUM(Q108:Q164)/57 -> 1
B14: =IF($D$6<>"VAT EXCL.", "QUOTE ISSUED WITH VAT INCLUDED", "") | X14: x | Y14: x | Z14: x | AA14: x | AB14: x | AC14: x | AD14: x
Q15: =(C72-F35)/C72 -> 0 | R15: Average Discount applied in BOQ (Q2-Q12) | X15: x | Y15: x | Z15: x | AA15: x | AB15: x | AC15: x | AD15: x
B16: =IF($W$1<>"BOQ", "DIFF SET TO " & W1,"") | Q16: =(F35-E35)/F35 -> 0 | R16: Average Discount applied on Totals (Q23-Q32) | X16: x | Y16: x | Z16: x | AA16: x | AB16: x | AC16: x | AD16: x
Q17: =F74 -> 0 | R17: Overall Discount
B18: =IF(AND(G1,G2,G3,G4,G5,G6,G7,G8,G9,G10,H1)=TRUE, "", "CHECKLIST INCOMPLETE !" )
B19: =IF(ABS(SUM(A23:A32))>100,"[Discy A-J] are high, Check it out."," ") | Q19: =R83 -> 1.3000062 | R19: Overall Markup (Final Selling Excl.VAT/Total Cost )
E21: DISCOUNTED | F21: SELLING | Q21: % Discnt | R21: MATERIAL | T21: LABOUR
A22: Discy.A-J | B22: Markup/LRate | E22: ="SELLING " & $Q$1 -> SELLING € | F22: =$Q$1 -> € | G22: VAT/DISC | H22: MU | I22: LABRATE | J22: LABCOST | Q22: on Totals | R22: € | T22: Pair Hrs.
A23: =IF($F23=0,"",($F23/$C2)-($R23*$S2+$T23*$T2)) -> 0.00168 | B23: =IF(F23=0,"",IF(R23=0,"A) "&"---, "&ROUND(($F23/$C2-($R23*$S2))/$T23,2),IF(T23=0,"A) "&ROUND(($F23/$C2)/$R23,2),"A) "&ROUND(($F23/$C2-($T23*$T2))/$R23,2)&", " &ROUND(($F23/$C2-($R23*$S2))/$T23,2)))) -> A) 1.3, 35.7 | D23: =IF($F2="","",$F2) -> Electrical | E23: =F23*(1-Q23) -> 115.58 | F23: =Elec_Est!F86 -> 115.58 | G23: =C2 -> 1 | H23: =$S2 -> 1.3 | I23: =$T2 -> 35.698 | J23: =$D$9 -> 27.46 | R23: =Elec_Est!R86 -> 10.92 | T23: =Elec_Est!T86 -> 2.84
A24: =IF($F24=0,"",($F24/$C3)-($R24*$S3+$T24*$T3)) -> 0 | B24: =IF(F24=0,"",IF(R24=0,"A) "&"---, "&ROUND(($F24/$C3-($R24*$S3))/$T24,2),IF(T24=0,"A) "&ROUND(($F24/$C3)/$R24,2),"A) "&ROUND(($F24/$C3-($T24*$T3))/$R24,2)&", " &ROUND(($F24/$C3-($R24*$S3))/$T24,2)))) -> A) 1.3 | D24: =IF($F3="","",$F3) -> Controls Section (Guy) | E24: =F24*(1-Q24) -> 234 | F24: =Elec_Est!F87 -> 234 | G24: =C3 -> 1 | H24: =$S3 -> 1.3 | I24: =$T3 -> 35.698 | J24: =$D$9 -> 27.46 | R24: =Elec_Est!R87 -> 180 | T24: =Elec_Est!T87 -> 0
A25: =IF($F25=0,"",($F25/$C4)-($R25*$S4+$T25*$T4)) | B25: =IF(F25=0,"",IF(R25=0,"A) "&"---, "&ROUND(($F25/$C4-($R25*$S4))/$T25,2),IF(T25=0,"A) "&ROUND(($F25/$C4)/$R25,2),"A) "&ROUND(($F25/$C4-($T25*$T4))/$R25,2)&", " &ROUND(($F25/$C4-($R25*$S4))/$T25,2)))) | D25: =IF($F4="","",$F4) | E25: =F25*(1-Q25) -> 0 | F25: =Elec_Est!F88 -> 0 | G25: =C4 -> 1 | H25: =$S4 -> 0 | I25: =$T4 -> 0 | J25: =$D$9 -> 27.46 | R25: =Elec_Est!R88 -> 0 | T25: =Elec_Est!T88 -> 0
A26: =IF($F26=0,"",($F26/$C5)-($R26*$S5+$T26*$T5)) | B26: =IF(F26=0,"",IF(R26=0,"A) "&"---, "&ROUND(($F26/$C5-($R26*$S5))/$T26,2),IF(T26=0,"A) "&ROUND(($F26/$C5)/$R26,2),"A) "&ROUND(($F26/$C5-($T26*$T5))/$R26,2)&", " &ROUND(($F26/$C5-($R26*$S5))/$T26,2)))) | D26: =IF($F5="","",$F5) | E26: =F26*(1-Q26) -> 0 | F26: =Elec_Est!F89 -> 0 | G26: =C5 -> 1 | H26: =$S5 -> 0 | I26: =$T5 -> 0 | J26: =$D$9 -> 27.46 | R26: =Elec_Est!R89 -> 0 | T26: =Elec_Est!T89 -> 0
A27: =IF($F27=0,"",($F27/$C6)-($R27*$S6+$T27*$T6)) | B27: =IF(F27=0,"",IF(R27=0,"A) "&"---, "&ROUND(($F27/$C6-($R27*$S6))/$T27,2),IF(T27=0,"A) "&ROUND(($F27/$C6)/$R27,2),"A) "&ROUND(($F27/$C6-($T27*$T6))/$R27,2)&", " &ROUND(($F27/$C6-($R27*$S6))/$T27,2)))) | D27: =IF($F6="","",$F6) | E27: =F27*(1-Q27) -> 0 | F27: =Elec_Est!F90 -> 0 | G27: =C6 -> 1 | H27: =$S6 -> 0 | I27: =$T6 -> 0 | J27: =$D$9 -> 27.46 | R27: =Elec_Est!R90 -> 0 | T27: =Elec_Est!T90 -> 0
A28: =IF($F28=0,"",($F28/$C7)-($R28*$S7+$T28*$T7)) | B28: =IF(F28=0,"",IF(R28=0,"A) "&"---, "&ROUND(($F28/$C7-($R28*$S7))/$T28,2),IF(T28=0,"A) "&ROUND(($F28/$C7)/$R28,2),"A) "&ROUND(($F28/$C7-($T28*$T7))/$R28,2)&", " &ROUND(($F28/$C7-($R28*$S7))/$T28,2)))) | D28: =IF($F7="","",$F7) | E28: =F28*(1-Q28) -> 0 | F28: =Elec_Est!F91 -> 0 | G28: =C7 -> 1 | H28: =$S7 -> 0 | I28: =$T7 -> 0 | J28: =$D$9 -> 27.46 | R28: =Elec_Est!R91 -> 0 | T28: =Elec_Est!T91 -> 0
A29: =IF($F29=0,"",($F29/$C8)-($R29*$S8+$T29*$T8)) | B29: =IF(F29=0,"",IF(R29=0,"A) "&"---, "&ROUND(($F29/$C8-($R29*$S8))/$T29,2),IF(T29=0,"A) "&ROUND(($F29/$C8)/$R29,2),"A) "&ROUND(($F29/$C8-($T29*$T8))/$R29,2)&", " &ROUND(($F29/$C8-($R29*$S8))/$T29,2)))) | D29: =IF($F8="","",$F8) | E29: =F29*(1-Q29) -> 0 | F29: =Elec_Est!F92 -> 0 | G29: =C8 -> 1 | H29: =$S8 -> 0 | I29: =$T8 -> 0 | J29: =$D$9 -> 27.46 | R29: =Elec_Est!R92 -> 0 | T29: =Elec_Est!T92 -> 0
A30: =IF($F30=0,"",($F30/$C9)-($R30*$S9+$T30*$T9)) | B30: =IF(F30=0,"",IF(R30=0,"A) "&"---, "&ROUND(($F30/$C9-($R30*$S9))/$T30,2),IF(T30=0,"A) "&ROUND(($F30/$C9)/$R30,2),"A) "&ROUND(($F30/$C9-($T30*$T9))/$R30,2)&", " &ROUND(($F30/$C9-($R30*$S9))/$T30,2)))) | D30: =IF($F9="","",$F9) | E30: =F30*(1-Q30) -> 0 | F30: =Elec_Est!F93 -> 0 | G30: =C9 -> 1 | H30: =$S9 -> 0 | I30: =$T9 -> 0 | J30: =$D$9 -> 27.46 | R30: =Elec_Est!R93 -> 0 | T30: =Elec_Est!T93 -> 0
A31: =IF($F31=0,"",($F31/$C10)-($R31*$S10+$T31*$T10)) | B31: =IF(F31=0,"",IF(R31=0,"A) "&"---, "&ROUND(($F31/$C10-($R31*$S10))/$T31,2),IF(T31=0,"A) "&ROUND(($F31/$C10)/$R31,2),"A) "&ROUND(($F31/$C10-($T31*$T10))/$R31,2)&", " &ROUND(($F31/$C10-($R31*$S10))/$T31,2)))) | D31: =IF($F10="","",$F10) | E31: =F31*(1-Q31) -> 0 | F31: =Elec_Est!F94 -> 0 | G31: =C10 -> 1 | H31: =$S10 -> 0 | I31: =$T10 -> 0 | J31: =$D$9 -> 27.46 | R31: =Elec_Est!R94 -> 0 | T31: =Elec_Est!T94 -> 0
A32: =IF($F32=0,"",($F32/$C11)-($R32*$S11+$T32*$T11)) | B32: =IF(F32=0,"",IF(R32=0,"A) "&"---, "&ROUND(($F32/$C11-($R32*$S11))/$T32,2),IF(T32=0,"A) "&ROUND(($F32/$C11)/$R32,2),"A) "&ROUND(($F32/$C11-($T32*$T11))/$R32,2)&", " &ROUND(($F32/$C11-($R32*$S11))/$T32,2)))) | D32: =IF($F11="","",$F11) | E32: =F32*(1-Q32) -> 0 | F32: =Elec_Est!F95 -> 0 | G32: =C11 -> 1 | H32: =$S11 -> 0 | I32: =$T11 -> 0 | J32: =$D$9 -> 27.46 | R32: =Elec_Est!R95 -> 0 | T32: =Elec_Est!T95 -> 0
C33: MIXED
A35: Discy.L | B35: ='MUR MEP BOQ'!H255 -> 349.58 | E35: =SUM(E23:E32) -> 349.58 | F35: =SUM(F23:F32) -> 349.58 | R35: =SUM(R23:R32) -> 190.92 | T35: =SUM(T23:T32) -> 2.84
A36: =IF(A39=0,"0.00",A39-(A38*A37)) -> 0.00 | B36: BOQ TOTAL | E36: ="ESTIM TOTAL (" & $Q$1 & ")" -> ESTIM TOTAL (€)
A37: 1.125 | B37: <1 Actual LabCont | R37: =R165 -> 190.92 | S37: C.C.Totals | T37: =T165 -> 2.84
B38: <2 Phrs @ 1.00
B39: <3 Phrs @ Actual | Q39: Discy.T >> | R39: =R37-R35 -> 0 | S39: PRINT | T39: =T37-T35 -> 0
B41: Values Only on : | D41: 45971 | R41: 190.92 | T41: 2.84
A46: REMARKS:
A47: 1) VAT and Duties as above.
...

Sheet Quote
A1: =IF(AND(UPPER(LEFT(TRIM($D$8),11))="01",UPPER(LEFT(TRIM($D$9),3))<>"ELM"),"PANTA RETAIL LTD.","PANTA CONTRACTING LIMITED") -> PANTA CONTRACTING LIMITED
A2: =IF(UPPER(LEFT(TRIM($D$9),3))="ELM","ELEC-FOR-MECH INTERNAL QUOTATION","ELECTRICAL INTERNAL QUOTATION") -> ELEC-FOR-MECH INTERNAL QUOTATION
B5: ATT: | D5: Jason Camilleri | R5: Dated: | S5: =NOW() -> 45971.674
B6: CLIENT: | C6: Link to ML_SUM $D1 | D6: =ML_Sum!D1 -> SUNCREST HOTELS plc
B7: PROJECT: | C7: Link to ML_SUM $D2 | D7: =ML_Sum!D2 -> Sunny Cost and Lido Redevelopment
B8: JOB DESC: | C8: Link to ML_SUM $D3 | D8: =ML_Sum!D3 -> Sample Room - Electrical for Mechanical
B9: QUOTE No: | C9: Link to ML_SUM $D4 | D9: =ML_Sum!D4 -> ELM25-0699
B10: CLIENT's Ref: | C10: Link to ML_SUM $D5 | D10: =ML_Sum!D5 -> Sample Room
D21: Material Cost (€) : | E21: =ML_Sum!R35 -> 190.92 | F21: =ML_Sum!D6 -> VAT EXCL. | G21: VAT EXCLUDED. | H21: VAT EXCLUDED. | I21: VAT EXCLUDED. | J21: VAT EXCLUDED. | K21: VAT EXCLUDED. | L21: VAT EXCLUDED. | M21: VAT EXCLUDED. | N21: VAT EXCLUDED. | O21: VAT EXCLUDED. | P21: VAT EXCLUDED.
D22: Labour Pair Hours : | E22: =ML_Sum!T35 -> 2.84
A53: Signed for and on behalf of | Q53: Signed for and on behalf of
A54: Electrical Division | Q54: Division
Q56: Records
Q57: Mr. K. Micallef
Q59: File

Sheet MUR MEP BOQ
B1: SUNNY COAST MOCK UP ROOM MEP Bill of Quantities | H1: REV00
B3: Preliminaries and General Conditions
A4: ITEM | B4: DESCRIPTION | C4: QTY | D4: UNIT | G4: RATE EXC. VAT | H4: TOTAL EXC. VAT
B5: The Preliminary Items included hereunder apply to the whole of the works contained in these Bills of Quantities and the rates and / or amounts inserted by the Contractor shall be deemed to apply to the whole of the works carried out under this Contract. The Contractor shall be deemed to have allowed in his tender for all costs in respect of all items described in the Preliminaries section of the Bills of Quantities. In the absence of any sum against any item or items , any monetary cost attributable thereto shall be deemed to be included elsewhere in the Preliminaries section or the unit rates for the measured works. The documents forming the Contract are to be taken as mutually explanatory to one another and any sum inserted here shall be deemed to cover the complete requirements of the Conditions of Contract, In the event of no amounts being inserted by the Contractor in respect of this Bill, no relative payment will be included in interim payments and the final All prices quoted in this tender are exclusive of V.A.T, but inclusive of all applicable Taxes and Levies. The contractor will be responsible for obtaining and incurring all expenses related to any permits that might be required by the local council and for any other fees that might become due to the local council or the competent authorities, bodies and /or agencies in relation to obstruction to traffic and pedestrians, necessary hoardings etc. Prior to submitting this tender document, the contractor is required to consult with the local council in relation to all requirements to carry out the scope of works of this tender.
B7: Health and Safety
A8: 1 | B8: Allow all costs for the employment of a licenced Health and Safety Officer for the entire duration of the Contract. The officer shall be responsible for enforcing all health and safety measures required by law, preparation of risk assessments for approval and work in conjuction with the H&S Officer appointed by the Employer. The Contractor shall also make provisions for a services of Fire Marshal during the works, in order to prevent any fires caused by Hot Works and other risks. | C8: 1 | D8: LS | G8: INC | H8: INC
B10: Regular Cleaning
A11: 1.003 | B11: Daily clean the site from any debris or material which may be intentionally or accidentally deposited during the course of works and during the transportation of material to the approariate disposal point | C11: 1 | D11: LS | G11: INC | H11: INC
B13: Preliminary Review of Project
A14: 1.004 | B14: The contractor shall obtain all the required operational information from Client, Perit and Engineers pertaining to the Risks related to Fire, so as to enable the full understanding of the design intent. The information shall include: materials, raw and finished, processes and chemicals used, quantities, packaging and storage format, shelving and stacking, ventilation requirements related to pharmaceutical industry, air pressure in rooms and corridors, safety and security, etc. | C14: 1 | D14: LS | G14: INC | H14: INC
A15: 1.005 | B15: The contractor shall review the M&E project documentation, and understand the services that will interface or clash (in terms of routing, levels and space allocation) and thus liaise with the Engineers for solutions. Any preparatory works as well as builders' works, preparation, openings, plinths, etc must be delth with at this stage. | C15: 1 | D15: LS | G15: INC | H15: INC
B17: Drawings
A18: 1.004 | B18: Provision of working drawings and reengineering as necessary including updating of drawings as required and as the works proceed. | C18: 1 | D18: LS | G18: INC | H18: INC
B20: Insurances
A21: 1.005 | B21: Contractor's Insurance CAR Policy covering the total contract value. The contractor must also take out a professional Indemnity Insurance to cover the design and therefore its warranted Engineers. | C21: 1 | D21: LS | G21: INC | H21: INC
A22: 1.006 | B22: Contractor's Insurance covering death or injury to Contractor's Personnel | C22: 1 | D22: LS | G22: INC | H22: INC
A23: 1.007 | B23: Contractor's Insurance covering loss or damage to Contractor's plant and equipment. | C23: 1 | D23: LS | G23: INC | H23: INC
B25: Builder's Works Drawings
A26: 1.008 | B26: The contractor must submit detailed builders work drawings, coordinated with the M&E drawings and the Fire compartmentation drawings issued by the Fire Engineer and Perit. The builder's work must provide clear information regarding all penetrations, holes and cores needed, the position with x & y dimensions, hole diameters, etc. The drawings must also detail whether the builder or finishes contractor will need to carry out future interventions of making good. the drawings must include additional works such as plinths (dimensions), puddle flanges, overflows and sleeves, doorways or hatches for equipment access. Where contractor may need access to lifters, cherry pickers, scaffolding, crane, etc, this must be agreed upon from this stage of the project. | C26: 1 | D26: LS | G26: INC | H26: INC
B28: Others
A29: 1.009 | B29: Provision of mobile toilets facilities on site, incl. emptying, cleaning etc | C29: 1 | D29: LS | G29: by client | H29: by client
A30: 1.01 | B30: Provision of security services on site | C30: 1 | D30: LS | G30: by client | H30: by client
A31: 1.011 | B31: Provision of CONTRACTOR MEP Project management | C31: 1 | D31: LS | G31: INC | H31: INC
A32: 1.012 | B32: Prepare coordinated drawings for all services | C32: 1 | D32: LS | G32: INC | H32: INC
A33: 1.014 | B33: Any other works, Contractor to list | C33: 1 | D33: LS | G33: INC | H33: INC
B34: TOTAL FOR PRELIMINARIES in € exc VAT | H34: INC
B35: *INC. = included, LS= lump sump, m= meters, No. =Number
B38: SPRINKLER INSTALLATION
A39: ITEM | B39: DESCRIPTION | C39: QTY | D39: UNIT | G39: RATE EXC. VAT | H39: TOTAL EXC. VAT
A40: 4 | B40: Take over design , reengineer and produce coordinated working drawings | C40: 1 | D40: LS | G40: INC | H40: INC
B41: Supply, install and connect the following medium gauge galvanised steel pipework including all brackets, fittings etc
A42: =IF(ISBLANK(C42),"",(MAX($A$38:A41)+0.001)) -> 4.001 | B42: 25mm | C42: 16 | D42: m | H42: =C42*G42 -> 0
A43: =IF(ISBLANK(C43),"",(MAX($A$38:A42)+0.001)) -> 4.002 | B43: 32mm | C43: 2 | D43: m | H43: =C43*G43 -> 0
A44: =IF(ISBLANK(C44),"",(MAX($A$38:A43)+0.001)) -> 4.003 | B44: 50mm | C44: 8 | D44: m | H44: =C44*G44 -> 0
A45: =IF(ISBLANK(C45),"",(MAX($A$38:A44)+0.001)) -> 4.004 | B45: Supply, install and connect Pendent type Sprinkler Quick Response, K80, 68DegC, concealed | C45: 2 | D45: No. | H45: =C45*G45 -> 0
A46: =IF(ISBLANK(C46),"",(MAX($A$38:A45)+0.001)) -> 4.005 | B46: Supply, install and connect, Sidewall type Sprinkler Quick Response, K80, 68DegC, escutcheon plate | C46: 5 | D46: No. | H46: =C46*G46 -> 0
A47: =IF(ISBLANK(C47),"",(MAX($A$38:A46)+0.001)) -> 4.006 | B47: Flexibles, if required | C47: 2 | D47: No. | H47: =C47*G47 -> 0
A48: =IF(ISBLANK(C48),"",(MAX($A$38:A47)+0.001)) -> 4.007 | B48: White Cover plate for concealed sprinkler | C48: 2 | D48: No. | H48: =C48*G48 -> 0
A49: =IF(ISBLANK(C49),"",(MAX($A49:A$58)+0.001))
A50: =IF(ISBLANK(C50),"",(MAX($A49:A$58)+0.001)) | B50: Builder's Work
...
